Workbook
Name Print_Area_MI: 'Performance Data Sheet'!$A$10:$N$42

Sheet DesignSheet
A1: TOSHIBA INTERNATIONAL CORPORATION | I1: Calc. Code: | J1: 2-2-2-0-1-2
A2: 3-PHASE SQUIRREL CAGE INDUCTION MOTOR DESIGN SHEET | J2: B.L.-1 P.F.-1
A3: File: | B3: G:\DESPRO\RATFILE\BS2700U.rat | G3: Date: | H3: 43186 | I3: Time: | J3: 0.34641204
A4: Pole | B4: HP | C4: RPM | D4: Form | E4: Voltage | F4: Frequency | G4: Temperature | H4: FLSpeed | I4: FLSlip | J4: Frame
A5: 2 | B5: 700 | C5: 3600 | D5: FCKNW | E5: 4160 | F5: 60 | G5: 105 | H5: 3581.8 / 3577.3 | I5: 0.0051 / 0.0063 | J5: 5811/12UDZ
A6: Core Data | D6: Winding Data | E6: USA Wire Std | H6: Constant Data
B7: Primary | C7: Secondary | F7: Bar | G7: End Ring | H7: St. Slot Pitch | I7: 24.543672 | J7: LR Test Data
A8: Air Gap | B8: 3.3 | H8: Rt. Slot Pitch | I8: 30.456888 | J8: ES
A9: Space Fac. | B9: 0.93000001 | D9: Pitch | E9: 1 ~ 16 | F9: Cross Section Area | H9: Mean Value | I9: 27.50028 | J9: 634.54745
A10: Core Length | B10: 375 | C10: 375 | F10: UB: 304.0 | G10: UER: 1750.0 | H10: Eff.T.W.St. | I10: 14.338923 | J10: WS
A11: OD | B11: 670 | C11: 368.4 | D11: Coil Pitch | E11: 0.6249375 | H11: Eff.T.W.Rt. | I11: 30.038757 | J11: 20288.546
A12: ID | B12: 375 | C12: 185 | D12: Slot Fill | E12: - | F12: EBL: 50.0 | G12: ERD1: 281.0 | H12: St.Carter Fac. | I12: 1.1789163 | J12: IS
A13: Core Depth | B13: 85 | C13: 55.29 | D13: Con./Slot | E13: 16 | G13: ERT: 70.00 | H13: Rt.Carter Fac. | I13: 1.0139197 | J13: 84.037575
A14: Eff.Core L. | B14: 311.54999 | C14: 311.54999 | D14: Wire Size 1 | E14: (.114"x.204")x2 | G14: ERH: 25.00 | H14: Carter Factor | I14: 1.1953266 | J14: Volts / Turn
A15: Slot Data | D15: Wire Size 2 | E15: - | H15: Short. Factor | I15: 0.8314146 | J15: 18.764435
A16: Number | B16: 48 | C16: 38 | D16: // Circuits | E16: 1 | H16: Distrib. Factor | I16: 0.95543647 | J16: AC
A17: Kind | B17: Open | C17: Trapeze | D17: Connection | E17: Wye | H17: Wind. Factor | I17: 0.79436384 | J17: 547.84028
A18: Skew | B18: - | C18: 0 | D18: MCL | E18: 1070 | F18: 545 | H18: Reactance | I18: (Coeff.: 0.0566)
A19: Depth | B19: 62.5 | C19: 36.41 | D19: No.Cond./Ph. | E19: 256 | I19: Running | J19: Start
A20: Width | B20: 10.20 - 10.20 | D20: Res. (20°C) | E20: 0.16505932 | H20: Stator Slot | I20: 18.533136 | J20: 18.533136
A21: Opening | B21: 14.5 | C21: 3 | D21: (105°C) | E21: 0.22018718 | F21: 0.13853553 | G21: 0.02160659 | H21: Rotor Slot | I21: 16.804136 | J21: 14.805407
A22: Tip Depth | B22: 2.8299999 | C22: 3 | D22: Material | E22: CU | F22: CU | G22: CU | H22: Zigzag | I22: 4.1274877 | J22: 3.9029219
A23: T.Min.Wid. | B23: 10.043672 | C23: 10.31661 | D23: Spec.Resist. | E23: 1.742 | F23: 1.742 | G23: 1.742 | H23: Coil End | I23: 31.108683 | J23: Skew R.: 0.00
A24: Low. R. | B24: 0 | C24: 0.80000001 | D24: Spec.Gravity | E24: 8.8900003 | F24: 8.8900003 | G24: 8.8900003 | H24: Belt Leakage | I24: 7.1922227 | J24: 6.8009131
A25: Up. R. | B25: - | C25: 4.7199998 | D25: Weight (kg) | H25: Total Resist. | I25: 0.38032931 | J25: 0.95759672
A26: Wedge Dep. | B26: 2.83 - 2.00 | C26: Magnetic | D26: Wire 1 | E26: 211.19256 | F26: 63.15883 | G26: 26.449351 | H26: Total React. | I26: 4.4010611 | J26: 4.2530904
A27: Duct | B27: 4 x 10 | C27: 4 x 10 | D27: Wire 2 | E27: - | F27: - | G27: - | H27: Impedance | I27: 4.4174638 | J27: 4.3595605
A28: Effective Depth (S=1) | D28: Magnetic Circuit Data | I28: Core Loss Data
B29: Res.= | C29: 33.371993 | E29: Length | F29: Section | G29: Density | H29: AT | I29: Volume | J29: Loss | M29: =RIGHT(F$41,SEARCH("/",F$41,1)-1) -> 3572.8 | N29: 125RPM
B30: Reac.= | C30: 33.399129 | D30: Primary Core | E30: 52.621633 | F30: 529.63498 | G30: 16.741915 | H30: 760.12324 | I30: 48668.957 | J30: 3979.0583 | M30: =RIGHT(E$41,SEARCH("/",E$41,1)-1) -> 3577.3 | N30: 100RPM
A31: Excitation Data | D31: Tooth | E31: 6.25 | F31: 750.98538 | G31: 11.807292 | H31: 24.465194 | I31: 9387.3173 | J31: 435.90209 | M31: =RIGHT(D$41,SEARCH("/",D$41,1)-1) -> 3581.8 | N31: 75RPM
A32: Excit.Amps | B32: 23.493 / 19.019 | D32: Second.Core | E32: 23.214779 | F32: 536.63447 | G32: 16.523545 | H32: 317.32441 | I32: Total | J32: 4414.9604 | M32: =RIGHT(C$41,SEARCH("/",C$41,1)-1) -> 3586.3 | N32: 50RPM
A33: Core Loss | B33: 1.192 / 0.965 | C33: Flux / Pole | D33: Tooth | E33: 3.641 | F33: 610.68657 | G33: 14.519894 | H33: 28.760997 | I33: C.L.C. | J33: 1.75 / 0.66 | M33: =RIGHT(B$41,SEARCH("/",B$41,1)-1) -> 3590.7 | N33: 25RPM
A34: NoLoad | B34: 23.52 / 19.04 | C34: 8.867104 | D34: Air Gap | E34: 0.33 | F34: 1650.8553 | G34: 5.3712181 | H34: 1410.5134 | I34: S.F.C. | J34: 6.0500002
A35: Load Characteristics | D35: Temp. Rise @ 100%: | E35: 62 / 64 | G35: No Load Loss | H35: 22372.5 / 14575.8 | I35: W.Loss | J35: 7726.2 / 2921.9
A36: Load (%) | B36: 25 | C36: 50 | D36: 75 | E36: 100 | F36: 125 | G36: Primary Loss | H36: 4665.1 / 5041.2 | I36: S.Loss | J36: 873.1 / 330.2
A37: Current (A) | B37: 33.27 / 34.08 | C37: 47.96 / 49.12 | D37: 65.38 / 66.97 | E37: 84.04 / 86.08 | F37: 103.55 / 106.07 | G37: Second. Loss | H37: 2757.4 / 3406.3 | I37: Total C.Loss | J37: 8599.2 / 3252.1
A38: Efficiency | B38: 0.850 / 0.847 | C38: 0.915 / 0.911 | D38: 0.937 / 0.933 | E38: 0.947 / 0.943 | F38: 0.952 / 0.948 | G38: Frict.& Wind. | H38: 13500.0 / 11229.4 | I38: Stray Loss | J38: 8622.9355 | L38: =LEFT(E38,SEARCH("/",E38,1)-1) -> 0.947 | M38: =RIGHT(E38,SEARCH("/",E38,1)-1) -> 0.943 | N38: =M38/L38 -> 0.99577614 | O38: Eff.
A39: P.F. | B39: 0.641 / 0.628 | C39: 0.826 / 0.809 | D39: 0.887 / 0.870 | E39: 0.911 / 0.893 | F39: 0.919 / 0.901 | G39: Starting Data | I39: Slip | J39: PF | L39: =LEFT(E39,SEARCH("/",E39,1)-1) -> 0.911 | M39: =RIGHT(E39,SEARCH("/",E39,1)-1) -> 0.893 | N39: =M39/L39 -> 0.98024149 | O39: PF.
A40: Slip | B40: 0.0013 / 0.0026 | C40: 0.0026 / 0.0038 | D40: 0.0038 / 0.0050 | E40: 0.0051 / 0.0063 | F40: 0.0063 / 0.0076 | G40: LRA | H40: 550.9 / 522.9 | L40: =LEFT(E37,SEARCH("/",E37,1)-1) -> 84.04 | M40: =RIGHT(E37,SEARCH("/",E37,1)-1) -> 86.08 | N40: =M40/L40 -> 1.0242742 | O40: Current
...

Sheet Data Sheet
A1: TOSHIBA INTERNATIONAL CORPORATION
A2: INDUCTION MOTOR DATA SHEET
A3: File: | B3: BS2700U | I3: HRW / Model Number:
A4: Type: TIKE - Form: FCKNW - 2 Pole - 700 HP - 4160 V - 60 Hz - 5811/12UDZ - Class F | Q4: Motor Type Selection | T4: Electrical Steel Table
A5: Motor Parameters | F5: PERFORMANCE | J5: DESIGN | K5: TEST | Q5: EPACT | T5: M22 - 26Ga.
A6: Material | D6: M22 - 26Ga. | F6: NL & Impedance Test | K6: Q.C. 180400659 | Q6: EQP-III | T6: M36 - 26Ga.
A7: Air Gap | D7: 3.3 | F7: No load amps | J7: 19 | K7: 18.3 | Q7: Exp.Prf. | T7: NCB1 - 26Ga.
A8: Stack length | D8: 375 | F8: No load watts | J8: 14576 | K8: 12494 | Q8: Exp.Prf.-EQPIII | T8: M43 - 26Ga.
A9: Number of turns per coil | D9: 8 | F9: Impedance amps | H9: 3 | I9: f | J9: 152 | K9: 136 | Q9: Prem. Eff. | T9: M45 - 26Ga.
A10: Wire 1 (061-0023-06) | D10: (.114"x.204")x2 | F10: Impedance volts | H10: 3 | I10: f | J10: 1150 | K10: 1150 | Q10: OWP | T10: M54 - 26Ga.
A11: Wire 2 (size & number) | D11: - | F11: Impedance watts | H11: 3 | I11: f | J11: 20289 | K11: 48416 | Q11: Dry Kiln
A12: Slot fill - circle/square method (%) | D12: - | F12: Temperature Rise (°C)
A13: Connection | D13: 1 x Wye | G13: Winding | I13: 80/115 | J13: 62 / 82 | K13: -
A14: MCL | D14: 1070 | G14: Frame | J14: - | K14: -
A15: Allowance for ins. depth | D15: 10.1404 | G15: Bearing PS/OS | J15: - | K15: -
A16: Allowance for ins. width | D16: 3.7368 | G16: End Ring | J16: - | K16: -
A17: Slot/Wire arrangement | D17: 16 x 2 | F17: Nameplate Data
A18: Effective cross section for coil | D18: - | H18: FLC (A) | J18: 86 | M18: =J18*6.5 -> 559
A19: Coil grouping | D19: - | H19: RPM | J19: 3575
A20: Coil pitch (slot number) | D20: 1 ~ 16 | H20: CODE | J20: F
A21: Method of coil connection | D21: - | H21: S. F. | J21: 1.15 | Q21: Method of Connection
A22: Resistance per phase @ 20 °C | D22: 0.1634 | H22: DESIGN | J22: - | Q22: Skip
A23: Coil Weight | B23: Wire1 | D23: 484 | H23: Nom.Eff. (%): | J23: - | Q23: Adjacent
A24: (lbs.) | B24: Wire2 | D24: - | H24: Min.Eff. (%): | J24: - | Q24: -
A25: Current Densities (A/cm2) | E25: Bar / ER | H25: P.F. (%): | J25: -
A26: FL / LR | D26: 298 / 1812 | E26: 410 / 431
A27: Stator Slot Shape (Reference) | F27: Performance
H28: LRC (A) | I28: - | J28: 523 | K28: - | M28: =(J28/J18)*100 -> 608.13953
H29: LRT (%) | I29: 60 | J29: 78 | K29: -
H30: BDT (%) | I30: 175 | J30: 270 | K30: -
H31: SLIP (%) | J31: 0.63 | K31: -
G32: IEEE-B | H32: Eff. (%) | J32: 94.3 | K32: -
A33: Rotor Slot Shape (Reference) | H33: PF (%) | J33: 89.3 | K33: -
F34: Losses (Watts) | H34: Primary | J34: 5041 | K34: -
H35: Secondary | J35: 3406 | K35: -
H36: Core | J36: 3252 | K36: -
H37: F & W | J37: 11229 | K37: -
H38: Stray | J38: 8623 | K38: -
A39: End Ring (Reference) | F39: Note | G39: BASE BS2M70U
F40: LINK: | G40: BS2800U.RAT & LAB 8292.DAT
...

Sheet LoginSheet
J1: P | K1: T | L1: L | M1: T
B2: PROJECT HISTORY | J2: E | K2: D | L2: I | M2: Y | N2: H
J3: R | L3: M | M3: P
J4: F | L4: I | M4: E
K5: C | L5: T | N5: I
J6: D | K6: U | M6: T | N6: N
J7: A | K7: R | L7: R | M7: E | N7: S
I8: S | J8: T | K8: V | L8: E | M8: S | N8: U
B9: DATE | C9: PROJECT | D9: SMART NUMBER | E9: QTY | F9: CUSTOMER | G9: REMARKS | H9: LIMIT CODE | I9: F | J9: A | K9: E | L9: V | M9: T | N9: L
B53: REVISION HISTORY
B54: REV | C54: REMARKS | I54: DATE | L54: INIT

Sheet StallTime
A1: Rating: | B1: 2 Pole - 700.0 HP - 3600 RPM - 4160 V - 60 Hz
A3: Starting Performance
D4: Load Type: Compressor - 503.0 lb-ft²
A5: RPM | B5: Motor | C5: Load | D5: Accel. | E5: Line | F5: Stator | G5: Rotor
A6: Speed Increment | B6: Torque (%) | C6: Torque (%) | D6: Time (s) | E6: Amps | F6: kW / s | G6: kW / s
A7: 0~365 | B7: 60.9 | C7: 37.5 | D7: 3.209 | E7: 469.9 | F7: 469.7 | G7: 1047.2
A8: 365~731 | B8: 61.2 | C8: 34.0 | D8: 2.751 | E8: 468.2 | F8: 399.9 | G8: 809.7
A9: 731~1096 | B9: 61.8 | C9: 31.9 | D9: 2.512 | E9: 466.3 | F9: 362.4 | G9: 660.5
A10: 1096~1461 | B10: 62.8 | C10: 30.5 | D10: 2.325 | E10: 464.1 | F10: 332.5 | G10: 540.1
A11: 1461~1827 | B11: 64.4 | C11: 30.0 | D11: 2.189 | E11: 461.7 | F11: 310.0 | G11: 443.0
A12: 1827~2192 | B12: 66.9 | C12: 30.6 | D12: 2.069 | E12: 458.9 | F12: 289.6 | G12: 357.8
A13: 2192~2557 | B13: 70.9 | C13: 31.6 | D13: 1.911 | E13: 455.7 | F13: 264.1 | G13: 274.7
A14: 2557~2922 | B14: 78.4 | C14: 32.7 | D14: 1.643 | E14: 451.3 | F14: 223.8 | G14: 187.6
A15: 2922~3105 | B15: 91.3 | C15: 33.7 | D15: 0.652 | E15: 445.4 | F15: 86.6 | G15: 109.8
A16: 3105~3288 | B16: 117.0 | C16: 34.8 | D16: 0.456 | E16: 434.6 | F16: 59.0 | G16: 66.9
... A19: 3574~3582 | B19: 109.3 | C19: 38.3 | D19: 0.022 | E19: 71.6 | F19: 0.1 | G19: 3.4
D21: Acceleration Time: 20.2 s
B22: Energy | D22: First Start | F22: Second Start
A23: Stator Winding Rise | B23: 2844 kW / s | D23: 35°C | F23: 70°C
A24: Rotor Bar Rise | B24: 3943 kW / s | D24: 162°C | F24: 324°C
A25: End Ring Rise | B25: 615 kW / s | D25: 60°C | F25: 121°C
A27: Locked Rotor Thermal Capability
E28: Cold Condition
B29: Rate of Rise | D29: Power | E29: Rise Limit | F29: Max Time
A30: Stator Copper | B30: 2.5°C / s | D30: 206.4 kW | E30: 160°C | F30: 63.0 s
A31: Rotor Bar | B31: 13.9°C / s | D31: 338.8 kW | E31: 260°C | F31: 18.7 s
A32: Rotor ER | B32: 5.2°C / s | D32: 52.8 kW | E32: 180°C | F32: 34.7 s
E34: Hot Condition
B35: Hot Temp. | D35: Rise Limit | E35: Ambient | F35: Total | G35: Max.Time
A36: Stator Copper | B36: 62°C + | D36: 98°C + | E36: 40°C | F36: = 200°C | G36: 38.6 s
A37: Rotor Bar | B37: 82°C + | D37: 178°C + | E37: 40°C | F37: = 300°C | G37: 12.8 s
A38: Rotor ER | B38: 82°C + | D38: 98°C + | E38: 40°C | F38: = 220°C | G38: 19.0 s
A40: Cold Stall Time: | B40: 25.9 s | D40: Hot Stall Time: | F40: 14.2 s

Sheet Performance Data Sheet
A1: TOSHIBA INTERNATIONAL CORPORATION | J1: INDEX | L1: MPCF-1033
A2: Industrial Division / Houston Motor Plant | J2: SHEET NO. | L2: 1 of 1
J3: ISSUED | L3: 7/31/13
J4: SUPERSEDES | L4: 11/8/96
J5: REVISION | L5: 2
A6: SQUIRREL CAGE INDUCTION MOTOR | J6: WRITTEN BY | L6: MDC
A7: PERFORMANCE SPECIFICATIONS | J7: APPROVED BY | L7: PAA
B9: CUSTOMER: | C9: FS ELLIOTT CO LLC
B10: TIC SR No.: | C10: 2079542.1
A12: MOTOR NAMEPLATE DATA
B13: H.P.: | C13: 700 | E13: VOLTS: | F13: 4160 | H13: 3 PH / | I13: 60 Hz | L13: S. RPM: | M13: 3600
B14: FRAME: | C14: 5812USS | E14: ENCL: | F14: TEAAC | H14: FLAMPS: | I14: 86 | L14: FLRPM: | M14: 3575
B15: FORM: | C15: FCKNW | E15: S.F.: | F15: 1.15 | H15: NEMA DESIGN: | I15: - | L15: INSUL CLASS: | M15: F
B16: TYPE: | C16: TIKE | E16: AMB.: | F16: 40°C | H16: CODE: | I16: F | L16: DUTY: | M16: Cont.
B17: MODEL No.: | C17: TW-10009426 | H17: kW: | I17: -
B18: NOM. EFF.: | C18: - | E18: MIN. EFF.: | F18: - | H18: P.F.: | I18: -
A21: AMPERAGE | E21: TORQUES | I21: **BEARINGS:
C22: LOCKED ROTOR: | D22: 523 | G22: FULL LOAD (lb-ft.): | H22: 1028 | K22: DRIVE END: | L22: REFER TO NP
G23: LOCKED ROTOR (%): | H23: 75 | K23: OPPOSITE DRIVE END: | L23: REFER TO NP
G24: BREAK DOWN (%): | H24: 270
A28: EFFICIENCY | H28: POWER FACTOR
C29: FULL LOAD: | D29: 94.3 | J29: FULL LOAD: | K29: 89.3
C30: 3/4 LOAD: | D30: 93.3 | J30: 3/4 LOAD: | K30: 87
C31: 1/2 LOAD: | D31: 91.1 | J31: 1/2 LOAD: | K31: 80.9
A35: ALL CHARACTERISTICS ARE AVERAGE EXPECTED VALUES BASED UPON RATED VOLTAGE,
A36: FREQUENCY AND SINEWAVE POWER INPUT.
A37: THE DECLARED LOCKED ROTOR CURRENT HAS A TOLERANCE OF 20%.
A38: * TEMPERATURE RISE WILL BE CONSISTENT WITH INSULATION, AMBIENT AND SERVICE FACTOR AS
A39: DEFINED BY NEMA-MG-12 OR -20.
A40: ** BEARINGS ARE THE ONLY RECOMMENDED SPARE PART(S).
J42: CERTIFIED BY: | K42: Zichao Xie
J44: DATE: | K44: 43186
A59: - | B59: 6205ZZ | D59: 1 | E59: -
A60: TEFC | B60: 6206UU | D60: 1.15 | E60: A
A61: ODP | B61: 6207ZZ | E61: B
B62: 6208UU
B63: 6211ZZ
B64: 6211C3
B65: 6211ZZC3
B66: 6305UUC3
...

Sheet STCurve
A2: TOSHIBA INTERNATIONAL CORPORATION
A3: Speed Torque/Current Curve
A6: Model #: | B6: ='Performance Data Sheet'!C17 -> TW-10009426 | E6: FLAmps: | F6: ='Performance Data Sheet'!I14 -> 86
A7: Enclosure: | B7: ='Performance Data Sheet'!F14 -> TEAAC | C7: Voltage: | D7: ='Performance Data Sheet'!F13 & " V" -> 4160 V | E7: Frame: | F7: ='Performance Data Sheet'!C14 -> 5812USS
A8: Pole: | B8: 2 | C8: Frequency: | D8: 3 PH / 60 Hz | E8: Ins. Class: | F8: ='Performance Data Sheet'!M15 -> F
A9: HP: | B9: ='Performance Data Sheet'!C13 -> 700 | C9: Rotor Inertia: | D9: 146.4 lb-ft² | E9: Date: | F9: ='Performance Data Sheet'!K44 -> 43186
A10: FLRPM: | B10: ='Performance Data Sheet'!M14 -> 3575 | C10: Load Inertia: | D10: 503.0 lb-ft² | E10: File: | F10: BS2700U_4160V
B12: Locked Rotor Amps: | C12: ='Performance Data Sheet'!D22 & " A" -> 523 A | D12: Load Type: | E12: Compressor
B13: Locked Rotor Torque: | C13: ='Performance Data Sheet'!H23/100 -> 0.75 | D13: Starting at: | E13: FV / 0.90 (V)
B14: Breakdown Torque: | C14: 2.7 | D14: Accel. Time: | E14: 13.7 / 20.2 (s)
B15: Rated Torque: | C15: ='Performance Data Sheet'!H22 & " lb-ft" -> 1028 lb-ft
A39: Comments: | B39: PROJECT | C39: ='Performance Data Sheet'!C10 -> 2079542.1 | E39: D.E.Curve #: | F39: =F10 -> BS2700U_4160V
C43: Prepared by: | D43: ='Performance Data Sheet'!K42 -> Zichao Xie | E43: Checked by:
D53: Load | E53: Torque 90% | F53: LRA 90%
A54: 100 | B54: 0 | C54: 0.27352384 | D54: 39 | E54: 0 | F54: 21.170744
A55: 99.28 | B55: 146.34402 | C55: 161.47523 | D55: 37.560001 | E55: 118.53865 | F55: 145.32771
A56: 96.4 | B56: 270 | C56: 474.05219 | D56: 36.349998 | E56: 218.69999 | F56: 426.64694
A57: 91.326316 | B57: 166.40631 | C57: 551.46063 | D57: 35.265263 | E57: 134.7891 | F57: 496.31454
A58: 86.252631 | B58: 122.55451 | C58: 571.48907 | D58: 34.250526 | E58: 99.269149 | F58: 514.34015
A59: 81.178947 | B59: 102.89033 | C59: 579.48151 | D59: 33.23579 | E59: 83.341161 | F59: 521.53333
A60: 71.031579 | B60: 90.597309 | C60: 586.62024 | D60: 32.103157 | E60: 73.383813 | F60: 527.95819
A61: 60.88421 | B61: 84.471646 | C61: 590.99689 | D61: 31.088421 | E61: 68.422032 | F61: 531.89716
A62: 50.736842 | B62: 80.691837 | C62: 594.75958 | D62: 30.073685 | E62: 65.360382 | F62: 535.28363
A63: 40.58947 | B63: 78.276657 | C63: 598.15259 | D63: 30 | E63: 63.404089 | F63: 538.33734
A64: 30.442107 | B64: 76.76159 | C64: 601.16858 | D64: 30.95579 | E64: 62.176884 | F64: 541.0517
A65: 20.294738 | B65: 75.840145 | C65: 603.81287 | D65: 32.941051 | E65: 61.430517 | F65: 543.43158
... A67: 0 | B67: 75 | C67: 608.13953 | D67: 40 | E67: 60.749997 | F67: 547.32556

Sheet Thermdam
A2: TOSHIBA INTERNATIONAL CORPORATION
A3: Thermal Limit & Acceleration Curves
A4: Design Values (For Reference Only)
A6: Model #: | B6: ='Performance Data Sheet'!C17 -> TW-10009426 | E6: FLAmps: | F6: ='Performance Data Sheet'!I14 -> 86
A7: Enclosure: | B7: ='Performance Data Sheet'!F14 -> TEAAC | C7: Voltage: | D7: ='Performance Data Sheet'!F13 & " V" -> 4160 V | E7: Frame: | F7: ='Performance Data Sheet'!C14 -> 5812USS
A8: Pole: | B8: 2 | C8: Frequency: | D8: 3 PH / 60 Hz | E8: Ins. Class: | F8: ='Performance Data Sheet'!M15 -> F
A9: HP: | B9: ='Performance Data Sheet'!C13 -> 700 | C9: Rotor Inertia: | D9: 146.4 lb-ft² | E9: Date: | F9: ='Performance Data Sheet'!K44 -> 43186
A10: FLRPM: | B10: ='Performance Data Sheet'!M14 -> 3575 | C10: Load Inertia: | D10: 503.0 lb-ft² | E10: File: | F10: BS2700U_4160V
C12: ='Performance Data Sheet'!D22 & " A" -> 523 A
C13: ='Performance Data Sheet'!H23/100 -> 0.75
C15: ='Performance Data Sheet'!H22 & " lb-ft" -> 1028 lb-ft
A39: Comments: | B39: PROJECT | C39: ='Performance Data Sheet'!C10 -> 2079542.1 | E39: D.E.Curve #: | F39: =F10 -> BS2700U_4160V
C43: Prepared by: | D43: ='Performance Data Sheet'!K42 -> Zichao Xie | E43: Checked by:
F50: =5252.1*B50/D53 -> #DIV/0!
D66: =D65/D64 -> #DIV/0!
A67: Current (%) | B67: Cold | C67: Hot | E67: CURRENT (%) | F67: Accel. Time
A68: 608.13953 | B68: 35 | C68: 15 | E68: =A68 -> 608.13953 | F68: 0.0001
A69: 543.43283 | B69: =((A68/A69)^2)*B68 -> 43.831141 | C69: =((A68/A69)^2)*C68 -> 18.784775 | E69: 607.09302 | F69: 1.992
A70: 478.70671 | B70: =((A68/A70)^2)*B68 -> 56.485307 | C70: =((A68/A70)^2)*C68 -> 24.207989 | E70: 605 | F70: 3.7969999
A71: 414 | B71: =((A68/A71)^2)*B68 -> 75.522062 | C71: =((A68/A71)^2)*C68 -> 32.366598 | E71: 602.44186 | F71: 5.4879999
A72: =A71-100 -> 314 | B72: =((A68/A72)^2)*B68 -> 131.28503 | E72: 599.65116 | F72: 7.086
A73: =A72-100 -> 214 | B73: =((A68/A73)^2)*B68 -> 282.64869 | E73: 596.51163 | F73: 8.6059999
A74: 270 | B74: =((A68/A74)^2)*B68 -> 177.56076 | C74: =((A68/A74)^2)*C68 -> 76.097468 | E74: 592.90698 | F74: 10.05
A75: 180 | B75: =((A68/A75)^2)*B69 -> 500.31583 | C75: =((A68/A75)^2)*C68 -> 171.2193 | E75: 588.83721 | F75: 11.393001
A76: 145 | B76: =((A68/A76)^2)*B68 -> 615.65657 | C76: =((A68/A76)^2)*C68 -> 263.85281 | E76: 583.02326 | F76: 12.565001
A77: 125 | C77: =CEILING(C76*2,100) -> 600 | E77: 575.46512 | F77: 13.040001
A78: 125 | C78: =2*C77 -> 1200 | E78: 561.51163 | F78: 13.382001
A79: 125 | C79: 10000 | E79: 512.7907 | F79: 13.588001
E80: =A74 -> 270 | F80: 13.712001
E81: =A77 -> 125 | F81: 13.731001

Sheet Performance
A2: TOSHIBA INTERNATIONAL CORPORATION
A3: Performance Curve
A4: Design Values (For Reference Only)
A6: Model #: | B6: ='Performance Data Sheet'!C17 -> TW-10009426 | E6: FLAmps: | F6: ='Performance Data Sheet'!I14 -> 86
A7: Enclosure: | B7: ='Performance Data Sheet'!F14 -> TEAAC | C7: Voltage: | D7: ='Performance Data Sheet'!F13 & " V" -> 4160 V | E7: Frame: | F7: ='Performance Data Sheet'!C14 -> 5812USS
A8: Pole: | B8: 2 | C8: Frequency: | D8: 3 PH / 60 Hz | E8: Ins. Class: | F8: ='Performance Data Sheet'!M15 -> F
A9: HP: | B9: ='Performance Data Sheet'!C13 -> 700 | C9: Rotor Inertia: | D9: 146.4 lb-ft² | E9: Date: | F9: ='Performance Data Sheet'!K44 -> 43186
A10: FLRPM: | B10: ='Performance Data Sheet'!M14 -> 3575 | C10: Load Inertia: | D10: 503.0 lb-ft² | E10: File: | F10: BS2700U_4160V
B12: Locked Rotor Amps: | C12: ='Performance Data Sheet'!D22 & " A" -> 523 A | D12: Load Type: | E12: Compressor
B13: Locked Rotor Torque: | C13: ='Performance Data Sheet'!H23/100 -> 0.75 | D13: Starting at: | E13: FV / 0.90 (V)
B14: Breakdown Torque: | C14: 2.7 | D14: Accel. Time: | E14: 13.7 / 20.2 (s)
B15: Rated Torque: | C15: ='Performance Data Sheet'!H22 & " lb-ft" -> 1028 lb-ft
A39: Comments: | B39: PROJECT | C39: ='Performance Data Sheet'!C10 -> 2079542.1 | E39: D.E.Curve #: | F39: =F10 -> BS2700U_4160V
C43: Prepared by: | D43: ='Performance Data Sheet'!K42 -> Zichao Xie | E43: Checked by:
A53: Load | B53: Efficiency | C53: PF | D53: Amps | E53: RPM | F53: Input Watts
A54: 0 | D54: 24.094659 | E54: 100 | F54: =14576/14000 -> 1.0411429
A55: 25 | B55: 84.652672 | C55: 62.795696 | D55: 34.076057 | E55: 70.776667 | F55: 11.012665
A56: 50 | B56: 91.107567 | C56: 80.948448 | D56: 49.12323 | E56: 59.857567 | F56: 20.464852
A57: 75 | B57: 93.29763 | C57: 86.982155 | D57: 66.963829 | E57: 48.769466 | F57: 29.976687
A58: 100 | B58: 94.285622 | C58: 89.27578 | D58: 86.079689 | E58: 37.525159 | F58: 39.550092
A59: 125 | B59: 94.764931 | C59: 90.111336 | D59: 106.06271 | E59: 26.146873 | F59: 49.187566
