Workbook
Name Print_Area_MI: 'Circuit Param'!$A$8:$N$43
Name Print_Area_MI: 'Performance API'!$A$10:$N$18
Name Print_Area_MI: 'Performance Data Sheet'!$A$10:$N$42
Name thermal: #REF!
Name thermal: #REF!
Name transfer: #REF!
Name transfer: #REF!
Name unit_sht: "unit_sht"
Name vassvelo: #REF!
Name velcoity: #REF!
Name velcoity: #REF!
Name viscosity: #REF!
Name viscosity: #REF!
Name vollheatre: #REF!
Name vollheatre: #REF!
Name volumetri: #REF!
Name volumetri: #REF!
Name weight: #REF!
Name weight: #REF!
Name weights: #REF!
Name weights: #REF!

Sheet DesignSheet 0.80V
A1: TOSHIBA INTERNATIONAL CORPORATION | I1: Calc. Code: | J1: 2-2-2-0-1-2
A2: 3-PHASE SQUIRREL CAGE INDUCTION MOTOR DESIGN SHEET | J2: B.L.-1 P.F.-1
A3: File: | B3: N:\DESPRO\RAT FILES\BS2900U_REV1.rat | G3: Date: | H3: 45943 | I3: Time: | J3: 0.50614583
A4: Pole | B4: HP | C4: RPM | D4: Form | E4: Voltage | F4: Frequency | G4: Temperature | H4: FLSpeed | I4: FLSlip | J4: Frame
A5: 2 | B5: 900.00003 | C5: 3600 | D5: ECMNW4 | E5: 3200 | F5: 60 | G5: 105 | H5: 3569.3 / 3567.7 | I5: 0.0085 / 0.0090 | J5: 5811/12UDZ
A6: Core Data | D6: Winding Data | H6: Constant Data
B7: Primary | C7: Secondary | F7: Bar | G7: End Ring | H7: St. Slot Pitch | I7: 24.543672 | J7: LR Test Data
A8: Air Gap | B8: 3.3 | H8: Rt. Slot Pitch | I8: 30.456888 | J8: ES
A9: Space Fac. | B9: 0.93000001 | D9: Pitch | E9: 1 ~ 16 | F9: Cross Section Area | H9: Mean Value | I9: 27.50028 | J9: 767.22226
A10: Core Length | B10: 465 | C10: 465 | F10: UB: 304.0 | G10: UER: 1750.0 | H10: Eff.T.W.St. | I10: 14.338923 | J10: WS
A11: OD | B11: 670 | C11: 368.4 | D11: Coil Pitch | E11: 0.6249375 | H11: Eff.T.W.Rt. | I11: 30.038757 | J11: 41047.038
A12: ID | B12: 375 | C12: 185 | D12: Slot Fill | E12: - | F12: EBL: 50.0 | G12: ERD1: 281.0 | H12: St.Carter Fac. | I12: 1.1789163 | J12: IS
A13: Core Depth | B13: 85 | C13: 55.29 | D13: Con./Slot | E13: 26 | G13: ERT: 70.00 | H13: Rt.Carter Fac. | I13: 1.0139197 | J13: 136.1987
A14: Eff.Core L. | B14: 376.64999 | C14: 376.64999 | D14: Wire Size 1 | E14: (.064"x.204")x2 | G14: ERH: 25.00 | H14: Carter Factor | I14: 1.1953266 | J14: Volts / Turn
A15: Slot Data | D15: Wire Size 2 | E15: - | H15: Short. Factor | I15: 0.8314146 | J15: 17.765145
A16: Number | B16: 48 | C16: 38 | D16: // Circuits | E16: 2 | H16: Distrib. Factor | I16: 0.95543647 | J16: AC
A17: Kind | B17: Open | C17: Trapeze | D17: Connection | E17: Wye | H17: Wind. Factor | I17: 0.79436384 | J17: 721.40106
A18: Skew | B18: - | C18: 0 | D18: MCL | E18: 1160 | F18: 635 | H18: Reactance | I18: (Coeff.: 0.0452)
A19: Depth | B19: 62.5 | C19: 36.41 | D19: No.Cond./Ph. | E19: 208 | I19: Running | J19: Start
A20: Width | B20: 10.20 - 10.20 | D20: Res. (20°C) | E20: 0.1294985 | H20: Stator Slot | I20: 18.533136 | J20: 18.533136
A21: Opening | B21: 14.5 | C21: 3 | D21: (105°C) | E21: 0.17274947 | F21: 0.10655777 | G21: 0.014263725 | H21: Rotor Slot | I21: 16.804136 | J21: 14.805407
A22: Tip Depth | B22: 2.8299999 | C22: 3 | D22: Material | E22: CU | F22: CU | G22: CU | H22: Zigzag | I22: 4.1274877 | J22: 4.0328984
A23: T.Min.Wid. | B23: 10.043672 | C23: 10.31661 | D23: Spec.Resist. | E23: 1.742 | F23: 1.742 | G23: 1.742 | H23: Coil End | I23: 25.731874 | J23: Skew R.: 0.00
A24: Low. R. | B24: 0 | C24: 0.80000001 | D24: Spec.Gravity | E24: 8.8900003 | F24: 8.8900003 | G24: 8.8900003 | H24: Belt Leakage | I24: 7.1922227 | J24: 7.0273995
A25: Up. R. | B25: - | C25: 4.7199998 | D25: Weight (kg) | H25: Total Resist. | I25: 0.29357097 | J25: 0.73758936
A26: Wedge Dep. | B26: 2.83 - 2.00 | C26: Magnetic | D26: Wire 1 | E26: 208.85703 | F26: 72.401585 | G26: 26.449351 | H26: Total React. | I26: 3.2696266 | J26: 3.1676319
A27: Duct | B27: 6 x 10 | C27: 6 x 10 | D27: Wire 2 | E27: - | F27: - | G27: - | H27: Impedance | I27: 3.2827795 | J27: 3.252373
A28: Effective Depth (S=1) | D28: Magnetic Circuit Data | I28: Core Loss Data
B29: Res.= | C29: 33.371993 | E29: Length | F29: Section | G29: Density | H29: AT | I29: Volume | J29: Loss | M29: =RIGHT(F$41,SEARCH("/",F$41,1)-1) -> 3559.8 | N29: 125RPM | P29: Kline/in2
B30: Reac.= | C30: 33.399129 | D30: Primary Core | E30: 52.621633 | F30: 640.30499 | G30: 13.11077 | H30: 278.89257 | I30: 58838.591 | J30: 3237.3068 | M30: =RIGHT(E$41,SEARCH("/",E$41,1)-1) -> 3567.7 | N30: 100RPM | P30: =G30*6.4516 -> 84.585441
A31: Excitation Data | D31: Tooth | E31: 6.25 | F31: 907.90772 | G31: 9.2464145 | H31: 11.807148 | I31: 11348.847 | J31: 354.64391 | M31: =RIGHT(D$41,SEARCH("/",D$41,1)-1) -> 3575.8 | N31: 75RPM | P31: =G31*6.4516 -> 59.654168
A32: Excit.Amps | B32: 17.360 / 15.458 | D32: Second.Core | E32: 23.214779 | F32: 648.76706 | G32: 12.939762 | H32: 117.61719 | I32: Total | J32: 3591.9507 | M32: =RIGHT(C$41,SEARCH("/",C$41,1)-1) -> 3583.4 | N32: 50RPM | P32: =G32*6.4516 -> 83.482167
A33: Core Loss | B33: 1.241 / 1.105 | C33: Flux / Pole | D33: Tooth | E33: 3.641 | F33: 738.29273 | G33: 11.370681 | H33: 12.784158 | I33: C.L.C. | J33: 1.75 / 0.73 | M33: =RIGHT(B$41,SEARCH("/",B$41,1)-1) -> 3590.7 | N33: 25RPM | P33: =G33*6.4516 -> 73.359086
A34: NoLoad | B34: 17.40 / 15.50 | C34: 8.3948912 | D34: Air Gap | E34: 0.33 | F34: 1995.8102 | G34: 4.2062573 | H34: 1104.5879 | I34: S.F.C. | J34: 6.0500002 | P34: =G34*6.4516 -> 27.13709
A35: Load Characteristics | D35: Temp. Rise @ 100%: | E35: 88 / 80 | G35: No Load Loss | H35: 20504.5 / 18892.6 | I35: W.Loss | J35: 6285.9 / 2605.6
A36: Load (%) | B36: 25 | C36: 50 | D36: 75 | E36: 100 | F36: 125 | G36: Primary Loss | H36: 9613.6 / 9437.2 | I36: S.Loss | J36: 601.5 / 249.3
A37: Current (A) | B37: 39.61 / 40.97 | C37: 69.66 / 72.05 | D37: 101.97 / 105.47 | E37: 136.20 / 140.88 | F37: 172.59 / 178.53 | G37: Second. Loss | H37: 6173.9 / 6689.3 | I37: Total C.Loss | J37: 6887.4 / 2855.0
A38: Efficiency | B38: 0.886 / 0.871 | C38: 0.932 / 0.917 | D38: 0.946 / 0.930 | E38: 0.950 / 0.933 | F38: 0.950 / 0.933 | G38: Frict.& Wind. | H38: 13500.0 / 17384.1 | I38: Stray Loss | J38: 11566.719 | L38: =LEFT(E38,SEARCH("/",E38,1)-1) -> 0.950 | M38: =RIGHT(E38,SEARCH("/",E38,1)-1) -> 0.933 | N38: =M38/L38 -> 0.98210526 | O38: Eff.
A39: P.F. | B39: 0.863 / 0.849 | C39: 0.932 / 0.917 | D39: 0.942 / 0.927 | E39: 0.937 / 0.921 | F39: 0.924 / 0.909 | G39: Starting Data | I39: Slip | J39: PF | L39: =LEFT(E39,SEARCH("/",E39,1)-1) -> 0.937 | M39: =RIGHT(E39,SEARCH("/",E39,1)-1) -> 0.921 | N39: =M39/L39 -> 0.98292423 | O39: PF.
A40: Slip | B40: 0.0022 / 0.0026 | C40: 0.0042 / 0.0046 | D40: 0.0063 / 0.0067 | E40: 0.0085 / 0.0090 | F40: 0.0107 / 0.0112 | G40: LRA | H40: 568.1 / 582.9 | L40: =LEFT(E37,SEARCH("/",E37,1)-1) -> 136.20 | M40: =RIGHT(E37,SEARCH("/",E37,1)-1) -> 140.88 | N40: =M40/L40 -> 1.0343612 | O40: Current
...

Sheet DesignSheet
A1: TOSHIBA INTERNATIONAL CORPORATION | I1: Calc. Code: | J1: 2-2-2-0-1-2
A2: 3-PHASE SQUIRREL CAGE INDUCTION MOTOR DESIGN SHEET | J2: B.L.-1 P.F.-1
A3: File: | B3: N:\DESPRO\RAT FILES\BS2900U_REV1.rat | G3: Date: | H3: 45943 | I3: Time: | J3: 0.37597222
A4: Pole | B4: HP | C4: RPM | D4: Form | E4: Voltage | F4: Frequency | G4: Temperature | H4: FLSpeed | I4: FLSlip | J4: Frame
A5: 2 | B5: 900.00003 | C5: 3600 | D5: ECMNW4 | E5: 4000 | F5: 60 | G5: 105 | H5: 3581.0 / 3579.4 | I5: 0.0053 / 0.0057 | J5: 5811/12UDZ
A6: Core Data | D6: Winding Data | H6: Constant Data
B7: Primary | C7: Secondary | F7: Bar | G7: End Ring | H7: St. Slot Pitch | I7: 24.543672 | J7: LR Test Data
A8: Air Gap | B8: 3.3 | H8: Rt. Slot Pitch | I8: 30.456888 | J8: ES
A9: Space Fac. | B9: 0.93000001 | D9: Pitch | E9: 1 ~ 16 | F9: Cross Section Area | H9: Mean Value | I9: 27.50028 | J9: 617.27367
A10: Core Length | B10: 465 | C10: 465 | F10: UB: 304.0 | G10: UER: 1750.0 | H10: Eff.T.W.St. | I10: 14.338923 | J10: WS
A11: OD | B11: 670 | C11: 368.4 | D11: Coil Pitch | E11: 0.6249375 | H11: Eff.T.W.Rt. | I11: 30.038757 | J11: 26914.734
A12: ID | B12: 375 | C12: 185 | D12: Slot Fill | E12: - | F12: EBL: 50.0 | G12: ERD1: 281.0 | H12: St.Carter Fac. | I12: 1.1789163 | J12: IS
A13: Core Depth | B13: 85 | C13: 55.29 | D13: Con./Slot | E13: 26 | G13: ERT: 70.00 | H13: Rt.Carter Fac. | I13: 1.0139197 | J13: 110.2877
A14: Eff.Core L. | B14: 376.64999 | C14: 376.64999 | D14: Wire Size 1 | E14: (.064"x.204")x2 | G14: ERH: 25.00 | H14: Carter Factor | I14: 1.1953266 | J14: Volts / Turn
A15: Slot Data | D15: Wire Size 2 | E15: - | H15: Short. Factor | I15: 0.8314146 | J15: 22.20643
A16: Number | B16: 48 | C16: 38 | D16: // Circuits | E16: 2 | H16: Distrib. Factor | I16: 0.95543647 | J16: AC
A17: Kind | B17: Open | C17: Trapeze | D17: Connection | E17: Wye | H17: Wind. Factor | I17: 0.79436384 | J17: 584.15879
A18: Skew | B18: - | C18: 0 | D18: MCL | E18: 1160 | F18: 635 | H18: Reactance | I18: (Coeff.: 0.0452)
A19: Depth | B19: 62.5 | C19: 36.41 | D19: No.Cond./Ph. | E19: 208 | I19: Running | J19: Start
A20: Width | B20: 10.20 - 10.20 | D20: Res. (20°C) | E20: 0.1294985 | H20: Stator Slot | I20: 18.533136 | J20: 18.533136
A21: Opening | B21: 14.5 | C21: 3 | D21: (105°C) | E21: 0.17274947 | F21: 0.10655777 | G21: 0.014263725 | H21: Rotor Slot | I21: 16.804136 | J21: 14.805407
A22: Tip Depth | B22: 2.8299999 | C22: 3 | D22: Material | E22: CU | F22: CU | G22: CU | H22: Zigzag | I22: 4.1274877 | J22: 3.859771
A23: T.Min.Wid. | B23: 10.043672 | C23: 10.31661 | D23: Spec.Resist. | E23: 1.742 | F23: 1.742 | G23: 1.742 | H23: Coil End | I23: 25.731874 | J23: Skew R.: 0.00
A24: Low. R. | B24: 0 | C24: 0.80000001 | D24: Spec.Gravity | E24: 8.8900003 | F24: 8.8900003 | G24: 8.8900003 | H24: Belt Leakage | I24: 7.1922227 | J24: 6.7257219
A25: Up. R. | B25: - | C25: 4.7199998 | D25: Weight (kg) | H25: Total Resist. | I25: 0.29357097 | J25: 0.73758936
A26: Wedge Dep. | B26: 2.83 - 2.00 | C26: Magnetic | D26: Wire 1 | E26: 208.85703 | F26: 72.401585 | G26: 26.449351 | H26: Total React. | I26: 3.2696266 | J26: 3.1461861
A27: Duct | B27: 6 x 10 | C27: 6 x 10 | D27: Wire 2 | E27: - | F27: - | G27: - | H27: Impedance | I27: 3.2827795 | J27: 3.2314897
A28: Effective Depth (S=1) | D28: Magnetic Circuit Data | I28: Core Loss Data
B29: Res.= | C29: 33.371993 | E29: Length | F29: Section | G29: Density | H29: AT | I29: Volume | J29: Loss | M29: =RIGHT(F$41,SEARCH("/",F$41,1)-1) -> 3574.6 | N29: 125RPM | P29: Kline/in2
B30: Reac.= | C30: 33.399129 | D30: Primary Core | E30: 52.621633 | F30: 640.30499 | G30: 16.388461 | H30: 694.79042 | I30: 58838.591 | J30: 4647.0576 | M30: =RIGHT(E$41,SEARCH("/",E$41,1)-1) -> 3579.4 | N30: 100RPM | P30: =G30*6.4516 -> 105.7318
A31: Excitation Data | D31: Tooth | E31: 6.25 | F31: 907.90772 | G31: 11.558018 | H31: 23.007978 | I31: 11348.847 | J31: 509.08078 | M31: =RIGHT(D$41,SEARCH("/",D$41,1)-1) -> 3584.2 | N31: 75RPM | P31: =G31*6.4516 -> 74.567707
A32: Excit.Amps | B32: 27.476 / 24.466 | D32: Second.Core | E32: 23.214779 | F32: 648.76706 | G32: 16.174701 | H32: 289.93926 | I32: Total | J32: 5156.1383 | M32: =RIGHT(C$41,SEARCH("/",C$41,1)-1) -> 3588.8 | N32: 50RPM | P32: =G32*6.4516 -> 104.3527
A33: Core Loss | B33: 1.446 / 1.288 | C33: Flux / Pole | D33: Tooth | E33: 3.641 | F33: 738.29273 | G33: 14.213351 | H33: 26.328973 | I33: C.L.C. | J33: 1.75 / 0.73 | M33: =RIGHT(B$41,SEARCH("/",B$41,1)-1) -> 3593.4 | N33: 25RPM | P33: =G33*6.4516 -> 91.698854
A34: NoLoad | B34: 27.51 / 24.50 | C34: 10.493614 | D34: Air Gap | E34: 0.33 | F34: 1995.8102 | G34: 5.2578214 | H34: 1380.7348 | I34: S.F.C. | J34: 6.0500002 | P34: =G34*6.4516 -> 33.921361
A35: Load Characteristics | D35: Temp. Rise @ 100%: | E35: 56 / 56 | G35: No Load Loss | H35: 23821.5 / 21948.8 | I35: W.Loss | J35: 9023.2 / 3740.3
A36: Load (%) | B36: 25 | C36: 50 | D36: 75 | E36: 100 | F36: 125 | G36: Primary Loss | H36: 6303.7 / 6188.0 | I36: S.Loss | J36: 1004.9 / 416.6
A37: Current (A) | B37: 40.82 / 41.82 | C37: 61.31 / 62.81 | D37: 85.06 / 87.14 | E37: 110.29 / 112.99 | F37: 136.59 / 139.94 | G37: Second. Loss | H37: 3697.1 / 4005.8 | I37: Total C.Loss | J37: 10028.2 / 4156.9
A38: Efficiency | B38: 0.872 / 0.865 | C38: 0.927 / 0.920 | D38: 0.945 / 0.938 | E38: 0.953 / 0.946 | F38: 0.956 / 0.949 | G38: Frict.& Wind. | H38: 13500.0 / 17384.1 | I38: Stray Loss | J38: 6926.6001 | L38: =LEFT(E38,SEARCH("/",E38,1)-1) -> 0.953 | M38: =RIGHT(E38,SEARCH("/",E38,1)-1) -> 0.946 | N38: =M38/L38 -> 0.99265477 | O38: Eff.
A39: P.F. | B39: 0.681 / 0.669 | C39: 0.852 / 0.838 | D39: 0.904 / 0.889 | E39: 0.922 / 0.907 | F39: 0.928 / 0.912 | G39: Starting Data | I39: Slip | J39: PF | L39: =LEFT(E39,SEARCH("/",E39,1)-1) -> 0.922 | M39: =RIGHT(E39,SEARCH("/",E39,1)-1) -> 0.907 | N39: =M39/L39 -> 0.98373102 | O39: PF.
A40: Slip | B40: 0.0014 / 0.0018 | C40: 0.0027 / 0.0031 | D40: 0.0040 / 0.0044 | E40: 0.0053 / 0.0057 | F40: 0.0066 / 0.0070 | G40: LRA | H40: 714.7 / 733.3 | L40: =LEFT(E37,SEARCH("/",E37,1)-1) -> 110.29 | M40: 113 | N40: =M40/L40 -> 1.0245716 | O40: Current
...

Sheet Data Sheet
A1: TOSHIBA INTERNATIONAL CORPORATION
A2: INDUCTION MOTOR DATA SHEET
A3: File: | B3: BS2900U_REV1 | I3: HRW / Model Number: | J3: 9003TCQL11F-C
A4: Type: TIKE - Form: ECMNW4 - 2 Pole - 900 HP - 4000 V - 60 Hz - 5811/12UDZ - Class F | Q4: Motor Type Selection | T4: Electrical Steel Table
A5: Motor Parameters | F5: PERFORMANCE | J5: DESIGN | K5: TEST | Q5: EPACT | T5: M22 - 26Ga.
A6: Material | D6: NCB1 - 26Ga. | F6: NL & Impedance Test | Q6: EQP-III | T6: M36 - 26Ga.
A7: Air Gap | D7: 3.3 | F7: No load amps | J7: 25 | K7: - | Q7: Exp.Prf. | T7: NCB1 - 26Ga.
A8: Stack length | D8: 465 | F8: No load watts | J8: 21949 | K8: - | Q8: Exp.Prf.-EQPIII | T8: M43 - 26Ga.
A9: Number of turns per coil | D9: 13 | F9: Impedance amps | H9: 3 | I9: f | J9: 205 | K9: - | Q9: Prem. Eff. | T9: M45 - 26Ga.
A10: Wire 1 (size & number) | D10: (.064"x.204")x2 | F10: Impedance volts | H10: 3 | I10: f | J10: 1150 | K10: - | Q10: Standard Eff. | T10: M54 - 26Ga.
A11: Wire 2 (size & number) | D11: - | F11: Impedance watts | H11: 3 | I11: f | J11: 26915 | K11: - | Q11: OWP | T11: TIPA Lam
A12: Slot fill - circle/square method (%) | D12: - | F12: Temperature Rise (°C) | Q12: Dry Kiln
A13: Connection | D13: 2 x Wye | G13: Winding | I13: 80/115 | J13: 56 / 74 | K13: -
A14: MCL | D14: 1160 | G14: Frame | J14: - | K14: -
A15: Allowance for ins. depth | D15: 12.2044 | G15: Bearing PS/OS | J15: - | K15: -
A16: Allowance for ins. width | D16: 3.7368 | G16: End Ring | J16: - | K16: -
A17: Slot/Wire arrangement | D17: 26 x 2 | F17: Nameplate Data
A18: Effective cross section for coil | D18: - | H18: FLC (A) | J18: 113 | M18: =J18*6.5 -> 734.5
A19: Coil grouping | D19: - | H19: RPM | J19: 3575
A20: Coil pitch (slot number) | D20: 1 ~ 16 | H20: CODE | J20: G
A21: Method of coil connection | D21: - | H21: S. F. | J21: 1.15 | Q21: Method of Connection
A22: Resistance per phase @ 20 °C | D22: 0.1295 | H22: DESIGN | Q22: Skip
A23: Coil Weight | B23: Wire1 | D23: 459.5 | H23: Nom.Eff. (%): | Q23: Adjacent
A24: (lbs.) | B24: Wire2 | D24: - | H24: Min.Eff. (%): | Q24: -
A25: Current Densities (A/cm2) | E25: Bar / ER | H25: P.F. (%): | J25: 90.5
A26: FL / LR | D26: 348 / 2257 | E26: 444 / 467
A27: Stator Slot Shape (Reference) | F27: Performance
H28: LRC (A) | I28: - | J28: 733 | K28: - | M28: =(J28/J18)*100 -> 648.67257
H29: LRT (%) | I29: 60 | J29: 120 | K29: -
H30: BDT (%) | I30: 175 | J30: 298 | K30: -
H31: SLIP (%) | J31: 0.57 | K31: -
G32: IEEE-B | H32: Eff. (%) | J32: 94.6 | K32: -
A33: Rotor Slot Shape (Reference) | H33: PF (%) | J33: 90.7 | K33: -
F34: Losses (Watts) | H34: Primary | J34: 6188 | K34: -
H35: Secondary | J35: 4006 | K35: -
H36: Core | J36: 4157 | K36: -
H37: F & W | J37: 17384 | K37: -
H38: Stray | J38: 6927 | K38: -
A39: End Ring (Reference) | F39: Note
F40: LINK: BS2900U_REV1.RAT AND BS2900U REV1 5 TEST LABS.dat
...

Sheet Performance Data Sheet
A1: TOSHIBA INTERNATIONAL CORPORATION | J1: INDEX | L1: MPCF-1033
A2: Industrial Division / Houston Motor Plant | J2: SHEET NO. | L2: 1 of 1
J3: ISSUED | L3: 7/31/13
J4: SUPERSEDES | L4: 11/8/96
J5: REVISION | L5: 2
A6: SQUIRREL CAGE INDUCTION MOTOR | J6: WRITTEN BY | L6: MDC
A7: PERFORMANCE SPECIFICATIONS | J7: APPROVED BY | L7: PAA
B9: CUSTOMER: | C9: ITT INDUSTRIES
B10: TIC SR No.: | C10: 2292552.1
A12: MOTOR NAMEPLATE DATA
B13: H.P.: | C13: 900 | E13: VOLTS: | F13: 4000 | H13: 3 PH / | I13: 60 Hz | L13: S. RPM: | M13: 3600
B14: FRAME: | C14: 5812USS | E14: ENCL: | F14: TEAAC | H14: FLAMPS: | I14: 113 | L14: FLRPM: | M14: 3580
B15: FORM: | C15: FCKNW4 | E15: S.F.: | F15: 1.0 | H15: NEMA DESIGN: | I15: - | L15: INSUL CLASS: | M15: F
B16: TYPE: | C16: TIKE | E16: AMB.: | F16: 40 | H16: CODE: | I16: G | L16: DUTY: | M16: Cont.
B17: MODEL No.: | C17: A1-10130506 | H17: kW: | I17: -
B18: NOM. EFF.: | C18: 94.5 | E18: MIN. EFF.: | H18: P.F.: | I18: 90.5
A21: AMPERAGE | E21: TORQUES | I21: **BEARINGS:
C22: LOCKED ROTOR: | D22: 733 | G22: FULL LOAD (lb-ft.): | H22: 1320 | K22: DRIVE END:
G23: LOCKED ROTOR (%): | H23: 120 | K23: OPPOSITE DRIVE END:
G24: BREAK DOWN (%): | H24: 295
A28: EFFICIENCY | H28: POWER FACTOR
C29: FULL LOAD: | D29: 94.6 | J29: FULL LOAD: | K29: 90.7
C30: 3/4 LOAD: | D30: 93.8 | J30: 3/4 LOAD: | K30: 88.9
C31: 1/2 LOAD: | D31: 92 | J31: 1/2 LOAD: | K31: 83.8
A35: ALL CHARACTERISTICS ARE AVERAGE EXPECTED VALUES BASED UPON RATED VOLTAGE,
A36: FREQUENCY AND SINEWAVE POWER INPUT.
A37: THE DECLARED LOCKED ROTOR CURRENT HAS A TOLERANCE OF 20%.
A38: * TEMPERATURE RISE WILL BE CONSISTENT WITH INSULATION, AMBIENT AND SERVICE FACTOR AS
A39: DEFINED BY NEMA-MG-12 OR -20.
A40: ** BEARINGS ARE THE ONLY RECOMMENDED SPARE PART(S).
J42: CERTIFIED BY: | K42: Jerry R
J44: DATE: | K44: 45943
A59: - | B59: 6205ZZ | D59: 1 | E59: -
A60: TEFC | B60: 6206UU | D60: 1.15 | E60: A
A61: ODP | B61: 6207ZZ | E61: B
B62: 6208UU
B63: 6211ZZ
B64: 6211C3
B65: 6211ZZC3
B66: 6305UUC3
...

Sheet STCurve
A2: TOSHIBA INTERNATIONAL CORPORATION
A3: Speed Torque/Current Curve
A6: Model #: | B6: ='Performance Data Sheet'!C17 -> A1-10130506 | E6: FLAmps: | F6: ='Performance Data Sheet'!I14 & " A" -> 113 A
A7: Enclosure: | B7: ='Performance Data Sheet'!F14 -> TEAAC | C7: Voltage: | D7: ='Performance Data Sheet'!F13 & " V" -> 4000 V | E7: Frame: | F7: ='Performance Data Sheet'!C14 -> 5812USS
A8: Pole: | B8: 2 | C8: Frequency: | D8: 3 PH / 60 Hz | E8: Ins. Class: | F8: F
A9: HP: | B9: 900 | C9: Rotor Inertia: | D9: 177.0 lb-ft² | E9: Date: | F9: ='Performance Data Sheet'!K44 -> 45943
A10: FLRPM: | B10: 3580 | C10: Load Inertia: | D10: 12.0 lb-ft² | E10: File: | F10: BS2900U_REV3
B12: Locked Rotor Amps: | C12: ='Performance Data Sheet'!D22 & " A" -> 733 A | D12: Load Type: | E12: Custom
B13: Locked Rotor Torque: | C13: 1.2 | D13: Starting at: | E13: FV / 0.93 / 0.80 (V)
B14: Breakdown Torque: | C14: 2.95 | D14: Accel. Time: | E14: 2 / 2.5 / 4 (s)
B15: Rated Torque: | C15: 1320 lb-ft
A39: Comments: | B39: PROJECT | C39: ='Performance Data Sheet'!C10 -> 2292552.1 | E39: D.E.Curve #: | F39: =F10 -> BS2900U_REV3
C43: Prepared by: | D43: ='Performance Data Sheet'!K42 -> Jerry R | E43: Checked by:
D53: Load | E53: Torque 93% | F53: LRA 93% | G53: Torque 80% | H53: LRA 80% | I53: Closed Load
A54: 100 | B54: 0 | C54: 0.24348857 | D54: 97 | E54: 0 | F54: 25.588213 | G54: 0 | H54: 20.470572 | I54: 39.8
A55: 99.2 | B55: 157.04401 | C55: 168.998 | D55: 94.599998 | E55: 135.82736 | F55: 157.16814 | G55: 100.50817 | H55: 135.19841 | I55: 37.2
A56: 96 | B56: 295 | C56: 501.40765 | D56: 91 | E56: 255.1455 | F56: 466.30911 | G56: 188.80001 | H56: 401.12613 | I56: 34.6
A57: 90.857143 | B57: 193.78967 | C57: 585.61542 | D57: 81.548576 | E57: 167.60869 | F57: 544.62231 | G57: 124.02539 | H57: 468.49234 | I57: 30.7
A58: 85.714285 | B58: 151.41916 | C58: 607.59973 | D58: 71.400002 | E58: 130.96243 | F58: 565.06775 | G58: 96.908265 | H58: 486.0798 | I58: 28.8
A59: 80.571428 | B59: 134.44617 | C59: 616.39929 | D59: 63.799999 | E59: 116.28249 | F59: 573.25134 | G59: 86.045549 | H59: 493.11945 | I59: 25
A60: 70.285714 | B60: 124.13882 | C60: 624.29315 | D60: 50.371429 | E60: 107.36766 | F60: 580.59265 | G60: 79.448845 | H60: 499.43454 | I60: 19.6
A61: 59.999999 | B61: 120 | C61: 629.18439 | D61: 38 | E61: 103.788 | F61: 585.14148 | G61: 76.800002 | H61: 503.3475 | I61: 14.2
A62: 50 | B62: 120.03155 | C62: 633.42731 | D62: 25 | E62: 103.81529 | F62: 589.0874 | G62: 76.820193 | H62: 506.74185 | I62: 9.6
A63: 39.999998 | B63: 120.04209 | C63: 637.27466 | D63: 14.999999 | E63: 103.82441 | F63: 592.66547 | G63: 76.826941 | H63: 509.81973 | I63: 7.3
A64: 30.000001 | B64: 120.05619 | C64: 640.70673 | D64: 10.1 | E64: 103.8366 | F64: 595.85724 | G64: 76.835964 | H64: 512.56537 | I64: 6.5
A65: 19.999999 | B65: 120.07848 | C65: 643.72345 | D65: 9.1000004 | E65: 103.85588 | F65: 598.66284 | G65: 76.850232 | H65: 514.97876 | I65: 6.1
... A67: 0 | B67: 120 | C67: 648.67261 | D67: 11.5 | E67: 103.788 | F67: 603.2655 | G67: 76.800002 | H67: 518.93811 | I67: 11.5

Sheet Thermdam
A2: TOSHIBA INTERNATIONAL CORPORATION
A3: Thermal Limit & Acceleration Curves
A4: Design Values (For Reference Only)
A6: Model #: | B6: ='Performance Data Sheet'!C17 -> A1-10130506 | E6: FLAmps: | F6: ='Performance Data Sheet'!I14 & " A" -> 113 A
A7: Enclosure: | B7: ='Performance Data Sheet'!F14 -> TEAAC | C7: Voltage: | D7: ='Performance Data Sheet'!F13 & " V" -> 4000 V | E7: Frame: | F7: ='Performance Data Sheet'!C14 -> 5812USS
A8: Pole: | B8: 2 | C8: Frequency: | D8: 3 PH / 60 Hz | E8: Ins. Class: | F8: F
A9: HP: | B9: 900 | C9: Rotor Inertia: | D9: 177.0 lb-ft² | E9: Date: | F9: ='Performance Data Sheet'!K44 -> 45943
A10: FLRPM: | B10: 3580 | C10: Load Inertia: | D10: 12.0 lb-ft² | E10: File: | F10: BS2900U_REV3
A39: Comments: | B39: PROJECT | C39: ='Performance Data Sheet'!C10 -> 2292552.1 | E39: D.E.Curve #: | F39: =F10 -> BS2900U_REV3
C43: Prepared by: | D43: ='Performance Data Sheet'!K42 -> Jerry R | E43: Checked by:
F50: =5252.1*B50/D53 -> #DIV/0!
D66: =D65/D64 -> #DIV/0!
A67: Current (%) | B67: Cold | C67: Hot | E67: CURRENT (%) | F67: Accel. Time
A68: 648.67257 | B68: 27.518128 | C68: 15 | E68: =A68 -> 648.67257 | F68: 0.0001 | G68: =0.93*E68 -> 603.26549 | H68: =F68 -> 0.0001 | I68: =0.8*E68 -> 518.93805 | J68: =F68 -> 0.0001
A69: =FLOOR(A68,100) -> 600 | B69: =((A68/A69)^2)*B68 -> 32.163807 | C69: =((A68/A69)^2)*C68 -> 17.532337 | E69: 647.52212 | F69: 0.17674418 | G69: =0.93*E69 -> 602.19558 | H69: =1.25*F69 -> 0.22093023 | I69: =0.8*E69 -> 518.0177 | J69: =2*F69 -> 0.35348836
A70: =A69-100 -> 500 | B70: =((A68/A70)^2)*B68 -> 46.315882 | C70: =((A68/A70)^2)*C68 -> 25.246566 | E70: 645.04425 | F70: 0.35116277 | G70: =0.93*E70 -> 599.89115 | H70: =1.25*F70 -> 0.43895347 | I70: =0.8*E70 -> 516.0354 | J70: =2*F70 -> 0.70232555
A71: =A70-100 -> 400 | B71: =((A68/A71)^2)*B68 -> 72.368566 | C71: =((A68/A71)^2)*C68 -> 39.447759 | E71: 642.21239 | F71: 0.52790697 | G71: =0.93*E71 -> 597.25752 | H71: =1.25*F71 -> 0.65988372 | I71: =0.8*E71 -> 513.76991 | J71: =2*F71 -> 1.0558139
A72: =A71-100 -> 300 | B72: =((A68/A72)^2)*B68 -> 128.65523 | E72: 639.02655 | F72: 0.70930234 | G72: =0.93*E72 -> 594.29469 | H72: =1.25*F72 -> 0.88662793 | I72: =0.8*E72 -> 511.22124 | J72: =2*F72 -> 1.4186047
A73: =A72-100 -> 200 | B73: =((A68/A73)^2)*B68 -> 289.47426 | E73: 635.30973 | F73: 0.90348838 | G73: =0.93*E73 -> 590.83805 | H73: =1.25*F73 -> 1.1293605 | I73: =0.8*E73 -> 508.24779 | J73: =2*F73 -> 1.8069768
A74: 295 | B74: =((A68/A74)^2)*B68 -> 133.05338 | C74: =((A68/A74)^2)*C68 -> 72.526762 | E74: 631.32743 | F74: 1.1232558 | G74: =0.93*E74 -> 587.13451 | H74: =1.25*F74 -> 1.4040698 | I74: =0.8*E74 -> 505.06195 | J74: =2*F74 -> 2.2465117
A75: 180 | B75: =((A68/A75)^2)*B69 -> 417.70868 | C75: =((A68/A75)^2)*C68 -> 194.80375 | E75: 626.72566 | F75: 1.3662792 | G75: =0.93*E75 -> 582.85487 | H75: =1.25*F75 -> 1.7078489 | I75: =0.8*E75 -> 501.38053 | J75: =2*F75 -> 2.7325583
A76: 145 | B76: =((A68/A76)^2)*B68 -> 550.72393 | C76: =((A68/A76)^2)*C68 -> 300.19698 | E76: 620.35398 | F76: 1.6290698 | G76: =0.93*E76 -> 576.9292 | H76: =1.25*F76 -> 2.0363372 | I76: =0.8*E76 -> 496.28319 | J76: =2*F76 -> 3.2581396
A77: 125 | C77: =CEILING(C76*2,100) -> 700 | E77: 612.0354 | F77: 1.7639536 | G77: =0.93*E77 -> 569.19292 | H77: =1.25*F77 -> 2.204942 | I77: =0.8*E77 -> 489.62832 | J77: =2*F77 -> 3.5279072
A78: 125 | C78: =2*C77 -> 1400 | E78: 596.63717 | F78: 1.8697675 | G78: =0.93*E78 -> 554.87257 | H78: =1.25*F78 -> 2.3372094 | I78: =0.8*E78 -> 477.30973 | J78: =2*F78 -> 3.739535
A79: 125 | C79: 10000 | E79: 543.53982 | F79: 1.9337209 | G79: =0.93*E79 -> 505.49204 | H79: =1.25*F79 -> 2.4171511 | I79: =0.8*E79 -> 434.83186 | J79: =2*F79 -> 3.8674418
E80: 335.22124 | F80: 1.9802325 | G80: =0.93*E80 -> 311.75575 | H80: =1.25*F80 -> 2.4752906 | I80: =0.8*E80 -> 268.17699 | J80: =2*F80 -> 3.960465
E81: 120 | F81: 1.9965116 | G81: 120 | H81: =1.25*F81 -> 2.4956395 | I81: 120 | J81: =2*F81 -> 3.9930233

Sheet Performance
A2: TOSHIBA INTERNATIONAL CORPORATION
A3: Performance Curve
A4: Design Values (For Reference Only)
A6: Model #: | B6: ='Performance Data Sheet'!C17 -> A1-10130506 | E6: FLAmps: | F6: ='Performance Data Sheet'!I14 & " A" -> 113 A
A7: Enclosure: | B7: ='Performance Data Sheet'!F14 -> TEAAC | C7: Voltage: | D7: ='Performance Data Sheet'!F13 & " V" -> 4000 V | E7: Frame: | F7: ='Performance Data Sheet'!C14 -> 5812USS
A8: Pole: | B8: 2 | C8: Frequency: | D8: 3 PH / 60 Hz | E8: Ins. Class: | F8: F
A9: HP: | B9: 900 | C9: Rotor Inertia: | D9: 177.0 lb-ft² | E9: Date: | F9: ='Performance Data Sheet'!K44 -> 45943
A10: FLRPM: | B10: 3580 | C10: Load Inertia: | D10: 12.0 lb-ft² | E10: File: | F10: BS2900U_REV3
B12: Locked Rotor Amps: | C12: ='Performance Data Sheet'!D22 & " A" -> 733 A | D12: Load Type: | E12: Custom
B13: Locked Rotor Torque: | C13: 1.2 | D13: Starting at: | E13: FV / 0.93 / 0.80 (V)
B14: Breakdown Torque: | C14: 2.95 | D14: Accel. Time: | E14: 2 / 2.5 / 4 (s)
B15: Rated Torque: | C15: 1320 lb-ft
A39: Comments: | B39: PROJECT | C39: ='Performance Data Sheet'!C10 -> 2292552.1 | E39: D.E.Curve #: | F39: =F10 -> BS2900U_REV3
C43: Prepared by: | D43: ='Performance Data Sheet'!K42 -> Jerry R | E43: Checked by:
A53: Load | B53: Efficiency | C53: PF | D53: Amps | E53: RPM | F53: Input Watts
A54: 0 | D54: 28.191059 | E54: 100 | F54: 1.2193778
A55: 25 | B55: 86.568336 | C55: 66.949074 | D55: 41.82299 | E55: 79.792312 | F55: 10.776929
A56: 50 | B56: 92.044746 | C56: 83.84584 | D56: 62.815701 | E56: 64.461874 | F56: 20.271463
A57: 75 | B57: 93.825951 | C57: 88.931435 | D57: 87.148857 | E57: 48.878124 | F57: 29.829938
A58: 100 | B58: 94.58252 | C58: 90.716515 | D58: 113.00079 | E58: 33.015523 | F58: 39.455104
A59: 125 | B59: 94.908257 | C59: 91.244255 | D59: 139.95203 | E59: 17.14391 | F59: 49.14961

Sheet Circuit Param
A1: TOSHIBA INTERNATIONAL CORPORATION | J1: INDEX | L1: MPCF-1109
A2: Industrial Division / Houston Motor Plant | J2: SHEET NO. | L2: 1 of 1
J3: ISSUED | L3: 38309
A4: EQUIVALENT CIRCUIT DATA | J4: SUPERSEDES | L4: NEW
J5: REVISION | L5: REV. 0
J6: WRITTEN BY | L6: MDC
A7: All Values are Presented in Ohms/Phase, Equivalent Wye Connection. | J7: APPROVED BY | L7: Paul Anderson
B9: CUSTOMER: | C9: ITT INDUSTRIES
B10: TIC SR No.: | C10: 2292552.1
A12: MOTOR NAMEPLATE DATA
B13: H.P.: | C13: 900 | E13: VOLTS: | F13: 4000 | H13: 3 PH / | I13: 60 Hz | L13: S. RPM: | M13: 3600
B14: FRAME: | C14: 5812USS | E14: ENCL: | F14: TEAAC | H14: FLAMPS: | I14: 113 | L14: FLRPM: | M14: 3580
B15: FORM: | C15: FCKNW4 | E15: S.F.: | F15: 1.0 | H15: NEMA DESIGN: | I15: - | L15: INSUL CLASS: | M15: F
B16: TYPE: | C16: TIKE | E16: AMB.: | F16: 40 | H16: CODE: | I16: G | L16: DUTY: | M16: Cont.
B17: MODEL No.: | C17: A1-10130506 | H17: kW: | I17: -
B18: NOM. EFF.: | C18: 94.5 | E18: MIN. EFF.: | F18: - | H18: P.F.: | I18: 90.5
A21: Primary Resistance (R1) : | F21: 0.17274947
A22: Secondary Resistance (R2) : | F22: 0.1208215
A23: Starting Resistance (R3) : | F23: 0.56483989
A25: Primary Reactance (X1) : | F25: 2.09
A26: Secondary Reactance (X2) : | F26: 1.57
A27: Starting Reactance (X3) : | F27: 1.265
A29: Magnetizing Reactance (Xm) : | F29: 94.2
A31: Transient Reactance : | F31: 3.64
A32: Sub Transient Reactance : | F32: 2.79
A33: Short Circuit Time Constant : | F33: 0.079
A34: Sub Transient Time Constant : | F34: 0.01
A35: Open Circuit Time Constant : | F35: 2.104
I40: CERTIFIED BY: | J40: JERRY R
I42: DATE: | J42: 45943

Sheet Performance API
A1: TOSHIBA INTERNATIONAL CORPORATION | J1: INDEX | L1: MPCF-1082
A2: Industrial Division / Houston Motor Plant | J2: SHEET NO. | L2: 1 of 1
J3: ISSUED | L3: 2/14/02
J4: SUPERSEDES | L4: NEW
J5: REVISION | L5: 0
A6: SQUIRREL CAGE INDUCTION MOTOR | J6: WRITTEN BY | L6: M. CAMPBELL
A7: API 541 PERFORMANCE SPECIFICATIONS | J7: APPROVED BY | L7: P.A.A
B9: CUSTOMER: | C9: ITT INDUSTRIES
B10: TIC SR No.: | C10: 2292552.1
A12: MOTOR NAMEPLATE DATA
B13: H.P.: | C13: 900 | E13: VOLTS: | F13: 4000 | H13: 3 PH / | I13: 60 Hz | L13: S. RPM: | M13: 3600
B14: FRAME: | C14: 5812USS | E14: ENCL: | F14: TEAAC | H14: FLAMPS: | I14: 113 | L14: FLRPM: | M14: 3580
B15: FORM: | C15: FCKNW4 | E15: S.F.: | F15: 1.0 | H15: NEMA DESIGN: | I15: - | L15: INSUL CLASS: | M15: F
B16: TYPE: | C16: TIKE | E16: AMB.: | F16: 40 | H16: CODE: | I16: G | L16: DUTY: | M16: Cont.
B17: MODEL No.: | C17: A1-10130506 | H17: kW: | I17: -
B18: NOM. EFF.: | C18: 94.5 | E18: MIN. EFF.: | F18: - | H18: P.F.: | I18: 90.5
A20: LOCKED ROTOR DATA
D21: AMPS AT RATED VOLTAGE: | E21: 733 A | I21: POWER FACTOR: | J21: 0.189
D22: AMPS AT 80% VOLTAGE: | E22: 583 A
A24: TORQUE VALUES | H24: CURVE NUMBERS
E25: FULL LOAD (LB.FT): | F25: 1320 | J25: SPEED-TORQUE CURVE: | K25: BS2900U REV3
E26: LOCKED ROTOR TORQUE (% OF FLT): | F26: 120 | J26: SPEED-CURRENT CURVE: | K26: BS2900U REV3
E27: PULL UP TORQUE (% OF FLT): | F27: 120 | J27: ACCELERATION CURVE: | K27: BS2900U REV3
E28: BREAKDOWN TORQUE (% OF FLT): | F28: 295
A30: LOCKED ROTOR WITHSTAND TIMES
A31: COLD CONDITION | H31: HOT CONDITION
C32: 100% VOLTAGE: | D32: 28 (s) | J32: 100% VOLTAGE: | K32: 15 (s)
C33: 90% VOLTAGE: | D33: 35 (s) | J33: 90% VOLTAGE: | K33: 18 (s)
C34: 80% VOLTAGE: | D34: 44 (s) | J34: 80% VOLTAGE: | K34: 23 (s)
C35: 70% VOLTAGE: | D35: 58 (s) | J35: 70% VOLTAGE: | K35: 30 (s)
A37: DESIGN DATA
C38: MOTOR ROTOR wk2 (LB.FT2): | D38: 177.0 | J38: NO LOAD CURRENT: | K38: 24.5
C39: AIR GAP: | D39: 3.3 mm | J39: ACCELERATION TIME: | K39: 2 / 2.5 / 4.5 (s)
D40: LOAD CHARACTERISTICS
D41: LOAD | G41: 1/2 | H41: 3/4 | I41: FULL | J41: SF
D42: AMPS (A) | G42: 62.8 | H42: 87.1 | I42: 113 | J42: -
D43: EFFICIENCY (%) | G43: 92 | H43: 93.8 | I43: 94.6 | J43: -
D44: POWER FACTOR (%) | G44: 83.8 | H44: 88.9 | I44: 90.7 | J44: -
D45: GUARENTEED EFFICIENCY (%) | G45: - | H45: - | I45: - | J45: -
A46: EFFICIENCY TO BE DETERMINED BY IEEE 112, METHOD B
...

Sheet StallTime
A1: Rating: | B1: 2 Pole - 900.0 HP - 3600 RPM - 4000 V - 60 Hz
A3: Starting Performance
D4: Load Type: Custom - 12.0 lb-ft²
A5: RPM | B5: Motor | C5: Load | D5: Accel. | E5: Line | F5: Stator | G5: Rotor
A6: Speed Increment | B6: Torque (%) | C6: Torque (%) | D6: Time (s) | E6: Amps | F6: kW / s | G6: kW / s
A7: 0~360 | B7: 120.1 | C7: 9.9 | D7: 0.152 | E7: 731.7 | F7: 42.4 | G7: 202.2
A8: 360~720 | B8: 120.1 | C8: 8.8 | D8: 0.150 | E8: 728.9 | F8: 41.6 | G8: 180.2
A9: 720~1080 | B9: 120.1 | C9: 9.6 | D9: 0.152 | E9: 725.7 | F9: 41.6 | G9: 161.3
A10: 1080~1440 | B10: 120.0 | C10: 12.6 | D10: 0.156 | E10: 722.1 | F10: 42.3 | G10: 145.0
A11: 1440~1800 | B11: 120.0 | C11: 20.0 | D11: 0.167 | E11: 717.9 | F11: 45.0 | G11: 133.6
A12: 1800~2160 | B12: 120.0 | C12: 31.5 | D12: 0.189 | E12: 713.4 | F12: 50.3 | G12: 125.8
A13: 2160~2530 | B13: 122.1 | C13: 39.5 | D13: 0.209 | E13: 708.2 | F13: 54.7 | G13: 107.9
A14: 2530~2901 | B14: 129.3 | C14: 52.9 | D14: 0.226 | E14: 701.0 | F14: 58.2 | G14: 89.6
A15: 2901~3086 | B15: 142.9 | C15: 68.8 | D15: 0.116 | E15: 691.6 | F15: 29.2 | G15: 65.3
A16: 3086~3271 | B16: 172.6 | C16: 78.0 | D16: 0.091 | E16: 674.2 | F16: 22.2 | G16: 42.4
... A19: 3571~3581 | B19: 128.5 | C19: 96.0 | D19: 0.014 | E19: 111.0 | F19: 0.1 | G19: 4.7
D21: Acceleration Time: 1.7 s
B22: Energy | D22: First Start | F22: Second Start
A23: Stator Winding Rise | B23: 447 kW / s | D23: 6°C | F23: 11°C
A24: Rotor Bar Rise | B24: 1142 kW / s | D24: 41°C | F24: 82°C
A25: End Ring Rise | B25: 153 kW / s | D25: 15°C | F25: 30°C
A27: Locked Rotor Thermal Capability
E28: Cold Condition
B29: Rate of Rise | D29: Power | E29: Rise Limit | F29: Max Time
A30: Stator Copper | B30: 3.9°C / s | D30: 311.7 kW | E30: 160°C | F30: 41.3 s
A31: Rotor Bar | B31: 25.5°C / s | D31: 710.6 kW | E31: 260°C | F31: 10.2 s
A32: Rotor ER | B32: 9.3°C / s | D32: 95.1 kW | E32: 180°C | F32: 19.3 s
E34: Hot Condition
B35: Hot Temp. | D35: Rise Limit | E35: Ambient | F35: Total | G35: Max.Time
A36: Stator Copper | B36: 56°C + | D36: 104°C + | E36: 40°C | F36: = 200°C | G36: 26.8 s
A37: Rotor Bar | B37: 73°C + | D37: 187°C + | E37: 40°C | F37: = 300°C | G37: 7.4 s
A38: Rotor ER | B38: 73°C + | D38: 107°C + | E38: 40°C | F38: = 220°C | G38: 11.5 s
A40: Cold Stall Time: | B40: 19.3 s | D40: Hot Stall Time: | F40: 11.5 s

Sheet Test data
D1: LABS USED FOR CORRELATIONS.
B3: LAB | C3: 3866 | D3: 3884B | E3: 3885 | F3: 3888 | G3: 3893B | H3: 3982 | I3: AVERAGE
B4: FLA | C4: 113.04 | D4: 113.06 | E4: 113.2 | F4: 113.4 | G4: 112.74 | H4: NOT USED FOR CORRELTAIONS | I4: =AVERAGE(C4:H4) -> 113.088
B5: EFF | C5: 94.6 | D5: 94.4 | E5: 94.5 | F5: 94.5 | G5: 94.8 | I5: =AVERAGE(C5:H5) -> 94.56
B6: PF | C6: 90.7 | D6: 90.8 | E6: 90.7 | F6: 90.5 | G6: 90.9 | I6: =AVERAGE(C6:H6) -> 90.72
B7: RPM | C7: 3580 | D7: 3580 | E7: 3579 | F7: 3579 | G7: 3579 | I7: =AVERAGE(C7:H7) -> 3579.4
B8: NL AMPS | C8: 24.8 | D8: 24.2 | E8: 24.5 | F8: 25 | G8: 23.84 | I8: =AVERAGE(C8:H8) -> 24.468
B9: WATTS | C9: 21946 | D9: 23295 | E9: 21349 | F9: 21977 | G9: 21177 | I9: =AVERAGE(C9:H9) -> 21948.8
B10: LRT | C10: 125.6 | D10: 113.6 | E10: 119 | F10: 108.7 | G10: 135.9 | I10: =AVERAGE(C10:H10) -> 120.56
B11: LRA | C11: 734.8 | D11: 733.8 | E11: 734.7 | F11: 728.7 | G11: 734.4 | I11: =AVERAGE(C11:H11) -> 733.28
B12: BDT | C12: 309.3 | D12: 279.3 | E12: 316.9 | F12: 293.5 | G12: 294.5 | I12: =AVERAGE(C12:H12) -> 298.7
B13: PRI | C13: 6158.8 | D13: 6183.9 | E13: 6181 | F13: 6288.3 | G13: 6127.9 | I13: =AVERAGE(C13:H13) -> 6187.98
B14: SEC | C14: 4065.9 | D14: 3869.5 | E14: 4163.9 | F14: 3916.9 | G14: 4012.8 | I14: =AVERAGE(C14:H14) -> 4005.8
B15: CORE | C15: 4357 | D15: 4436.9 | E15: 4389 | F15: 3584.8 | G15: 4017 | I15: =AVERAGE(C15:H15) -> 4156.94
B16: F&W | C16: 17168.9 | D16: 18457.9 | E16: 16594.3 | F16: 17961.5 | G16: 16737.9 | I16: =AVERAGE(C16:H16) -> 17384.1
... B18: TEMP RISE | C18: 55.8 | D18: 55.3 | E18: 54.4 | F18: 57.7 | G18: 54.7 | I18: =AVERAGE(C18:H18) -> 55.58
