Workbook
Name Print_Area_MI: 'Performance Data Sheet'!$A$10:$N$42

Sheet DesignSheet
A1: TOSHIBA INTERNATIONAL CORPORATION | I1: Calc. Code: | J1: 2-2-2-0-1-2
A2: 3-PHASE SQUIRREL CAGE INDUCTION MOTOR DESIGN SHEET | J2: B.L.-1 P.F.-1
A3: File: | B3: N:\DESPRO\RAT FILES\BS2M25U.rat | G3: Date: | H3: 45777 | I3: Time: | J3: 0.24228009
A4: Pole | B4: HP | C4: RPM | D4: Form | E4: Voltage | F4: Frequency | G4: Temperature | H4: FLSpeed | I4: FLSlip | J4: Frame
A5: 2 | B5: 1250 | C5: 3600 | D5: FCKNW | E5: 4000 | F5: 60 | G5: 105 | H5: 3580.1 / 3579.5 | I5: 0.0055 / 0.0057 | J5: 5811/12UDZ
A6: Core Data | D6: Winding Data | H6: Constant Data
B7: Primary | C7: Secondary | F7: Bar | G7: End Ring | H7: St. Slot Pitch | I7: 24.543672 | J7: LR Test Data
A8: Air Gap | B8: 3.3 | H8: Rt. Slot Pitch | I8: 30.456888 | J8: ES
A9: Space Fac. | B9: 0.93000001 | D9: Pitch | E9: 1 ~ 16 | F9: Cross Section Area | H9: Mean Value | I9: 27.50028 | J9: 205.83874
A10: Core Length | B10: 600 | C10: 600 | F10: UB: 304.0 | G10: UER: 1750.0 | H10: Eff.T.W.St. | I10: 14.338923 | J10: WS
A11: OD | B11: 670 | C11: 368.4 | D11: Coil Pitch | E11: 0.6249375 | H11: Eff.T.W.Rt. | I11: 30.038757 | J11: 36847.193
A12: ID | B12: 375 | C12: 185 | D12: Slot Fill | E12: - | F12: EBL: 50.0 | G12: ERD1: 281.0 | H12: St.Carter Fac. | I12: 1.1789163 | J12: IS
A13: Core Depth | B13: 85 | C13: 55.29 | D13: Con./Slot | E13: 18 | G13: ERT: 70.00 | H13: Rt.Carter Fac. | I13: 1.0139197 | J13: 150.89438
A14: Eff.Core L. | B14: 465 | C14: 474.30002 | D14: Wire Size 1 | E14: (.102"x.204")x1 | G14: ERH: 25.00 | H14: Carter Factor | I14: 1.1953266 | J14: Volts / Turn
A15: Slot Data | D15: Wire Size 2 | E15: (.102"x.229")x1 | H15: Short. Factor | I15: 0.8314146 | J15: 27.777778
A16: Number | B16: 48 | C16: 38 | D16: // Circuits | E16: 1 | H16: Distrib. Factor | I16: 0.95543647 | J16: AC
A17: Kind | B17: Open | C17: Trapeze | D17: Connection | E17: Delta | H17: Wind. Factor | I17: 0.79436384 | J17: 638.93717
A18: Skew | B18: - | C18: 0 | D18: MCL | E18: 1295 | F18: 770 | H18: Reactance | I18: (Coeff.: 0.1069)
A19: Depth | B19: 62.5 | C19: 36.41 | D19: No.Cond./Ph. | E19: 288 | I19: Running | J19: Start
A20: Width | B20: 10.20 - 10.20 | D20: Res. (20°C) | E20: 0.23306587 | H20: Stator Slot | I20: 18.533136 | J20: 18.533136
A21: Opening | B21: 14.5 | C21: 3 | D21: (105°C) | E21: 0.31090712 | F21: 0.24771965 | G21: 0.02734584 | H21: Rotor Slot | I21: 16.804136 | J21: 14.805407
A22: Tip Depth | B22: 2.8299999 | C22: 3 | D22: Material | E22: CU | F22: CU | G22: CU | H22: Zigzag | I22: 4.1274877 | J22: 3.7811379
A23: T.Min.Wid. | B23: 10.043672 | C23: 10.31661 | D23: Spec.Resist. | E23: 1.742 | F23: 1.742 | G23: 1.742 | H23: Coil End | I23: 20.842818 | J23: Skew R.: 0.00
A24: Low. R. | B24: 0 | C24: 0.80000001 | D24: Spec.Gravity | E24: 8.8900003 | F24: 8.8900003 | G24: 8.8900003 | H24: Belt Leakage | I24: 7.1922227 | J24: 6.5805147
A25: Up. R. | B25: - | C25: 4.7199998 | D25: Weight (kg) | H25: Total Resist. | I25: 0.58597261 | J25: 1.6182022
A26: Wedge Dep. | B26: 2.83 - 2.00 | C26: Magnetic | D26: Wire 1 | E26: 130.45745 | F26: 86.265719 | G26: 26.449351 | H26: Total React. | I26: 7.2160945 | J26: 6.9008732
A27: Duct | B27: 10 x 10 | C27: 9 x 10 | D27: Wire 2 | E27: 146.82157 | F27: - | G27: - | H27: Impedance | I27: 7.2398467 | J27: 7.0880623
A28: Effective Depth (S=1) | D28: Magnetic Circuit Data | I28: Core Loss Data
B29: Res.= | C29: 33.371993 | E29: Length | F29: Section | G29: Density | H29: AT | I29: Volume | J29: Loss | M29: =RIGHT(F$41,SEARCH("/",F$41,1)-1) -> 3574.4 | N29: 125RPM | P29: Kline/in2
B30: Reac.= | C30: 33.399129 | D30: Primary Core | E30: 52.621633 | F30: 790.5 | G30: 16.605117 | H30: 734.36426 | I30: 72640.237 | J30: 5860.4792 | M30: =RIGHT(E$41,SEARCH("/",E$41,1)-1) -> 3579.5 | N30: 100RPM | P30: =G30*6.4516 -> 107.12957
A31: Excitation Data | D31: Tooth | E31: 6.25 | F31: 1120.8738 | G31: 11.710815 | H31: 23.895445 | I31: 14010.922 | J31: 642.00998 | M31: =RIGHT(D$41,SEARCH("/",D$41,1)-1) -> 3584.4 | N31: 75RPM | P31: =G31*6.4516 -> 75.553493
A32: Excit.Amps | B32: 20.140 / 16.814 | D32: Second.Core | E32: 23.214779 | F32: 816.96597 | G32: 16.067187 | H32: 281.84456 | I32: Total | J32: 6502.4892 | M32: =RIGHT(C$41,SEARCH("/",C$41,1)-1) -> 3589.3 | N32: 50RPM | P32: =G32*6.4516 -> 103.65906
A33: Core Loss | B33: 1.051 / 0.878 | C33: Flux / Pole | D33: Tooth | E33: 3.641 | F33: 929.70201 | G33: 14.118873 | H33: 25.621257 | I33: C.L.C. | J33: 1.75 / 0.85 | M33: =RIGHT(B$41,SEARCH("/",B$41,1)-1) -> 3594.2 | N33: 25RPM | P33: =G33*6.4516 -> 91.089324
A34: NoLoad | B34: 34.93 / 29.16 | C34: 13.126345 | D34: Air Gap | E34: 0.33 | F34: 2488.6028 | G34: 5.2745841 | H34: 1385.1368 | I34: S.F.C. | J34: 6.0500002 | P34: =G34*6.4516 -> 34.029507
A35: Load Characteristics | D35: Temp. Rise @ 100%: | E35: 72 / 67 | G35: No Load Loss | H35: 26412.7 / 23212.2 | I35: W.Loss | J35: 11379.4 / 5496.2
A36: Load (%) | B36: 25 | C36: 50 | D36: 75 | E36: 100 | F36: 125 | G36: Primary Loss | H36: 7079.5 / 6868.8 | I36: S.Loss | J36: 1249.8 / 603.6
A37: Current (A) | B37: 53.41 / 53.89 | C37: 82.49 / 83.23 | D37: 115.74 / 116.77 | E37: 150.89 / 152.24 | F37: 187.41 / 189.08 | G37: Second. Loss | H37: 5315.8 / 5521.9 | I37: Total C.Loss | J37: 12629.1 / 6099.9
A38: Efficiency | B38: 0.895 / 0.893 | C38: 0.940 / 0.938 | D38: 0.955 / 0.953 | E38: 0.961 / 0.959 | F38: 0.963 / 0.961 | G38: Frict.& Wind. | H38: 13500.0 / 17822.6 | I38: Stray Loss | J38: 3981.0195 | L38: =LEFT(E38,SEARCH("/",E38,1)-1) -> 0.961 | M38: =RIGHT(E38,SEARCH("/",E38,1)-1) -> 0.959 | N38: =M38/L38 -> 0.99791883 | O38: Eff.
A39: P.F. | B39: 0.704 / 0.699 | C39: 0.867 / 0.862 | D39: 0.913 / 0.907 | E39: 0.928 / 0.922 | F39: 0.932 / 0.926 | G39: Starting Data | I39: Slip | J39: PF | L39: =LEFT(E39,SEARCH("/",E39,1)-1) -> 0.928 | M39: =RIGHT(E39,SEARCH("/",E39,1)-1) -> 0.922 | N39: =M39/L39 -> 0.99353448 | O39: PF.
A40: Slip | B40: 0.0014 / 0.0016 | C40: 0.0028 / 0.0030 | D40: 0.0041 / 0.0043 | E40: 0.0055 / 0.0057 | F40: 0.0069 / 0.0071 | G40: LRA | H40: 977.4 / 944.6 | L40: =LEFT(E37,SEARCH("/",E37,1)-1) -> 150.89 | M40: =RIGHT(E37,SEARCH("/",E37,1)-1) -> 152.24 | N40: =M40/L40 -> 1.0089469 | O40: Current
...

Sheet Data Sheet
A1: TOSHIBA INTERNATIONAL CORPORATION
A2: INDUCTION MOTOR DATA SHEET
A3: File: | B3: BS2M25U | I3: HRW / Model Number: | J3: M253TCQL11F-C
A4: Type: TIKE - Form: FCKNW - 2 Pole - 1250 HP - 4000 V - 60 Hz - 5811/12UDZ - Class F | Q4: Motor Type Selection | T4: Electrical Steel Table
A5: Motor Parameters | F5: PERFORMANCE | J5: DESIGN | K5: TEST | Q5: EPACT | T5: M22 - 26Ga.
A6: Material | D6: M22 - 26Ga. | F6: NL & Impedance Test | Q6: EQP-III | T6: M36 - 26Ga.
A7: Air Gap | D7: 3.3 | F7: No load amps | J7: 29 | K7: 31.26 | Q7: Exp.Prf. | T7: NCB1 - 26Ga.
A8: Stack length | D8: 600 | F8: No load watts | J8: 23212 | K8: 26413 | Q8: Exp.Prf.-EQPIII | T8: M43 - 26Ga.
A9: Number of turns per coil | D9: 9 | F9: Impedance amps | H9: 3 | I9: f | J9: 843 | K9: 235 | Q9: Prem. Eff. | T9: M45 - 26Ga.
A10: Wire 1 (061-0023-04) | D10: (.102"x.204")x1 | F10: Impedance volts | H10: 3 | I10: f | J10: 1150 | K10: 1150 | Q10: Standard Eff. | T10: M54 - 26Ga.
A11: Wire 2 (061-0020-07) | D11: (.102"x.229")x1 | F11: Impedance watts | H11: 3 | I11: f | J11: 36847 | K11: 86500 | Q11: OWP | T11: TIPA Lam
A12: Slot fill - circle/square method (%) | D12: - | F12: Temperature Rise (°C) | Q12: Dry Kiln
A13: Connection | D13: 1 x Delta | G13: Winding | I13: 80/115 | J13: 72 / 95 | K13: -
A14: MCL | D14: 1295 | G14: Frame | J14: - | K14: -
A15: Allowance for ins. depth | D15: 9.4356012 | G15: Bearing PS/OS | J15: - | K15: -
A16: Allowance for ins. width | D16: 3.1018 | G16: End Ring | J16: - | K16: -
A17: Slot/Wire arrangement | D17: 18 x 2 | F17: Nameplate Data
A18: Effective cross section for coil | D18: - | H18: FLC (A) | J18: 152 | M18: =J18*6.5 -> 988 | N18: 975.4
A19: Coil grouping | D19: - | H19: RPM | J19: 3575
A20: Coil pitch (slot number) | D20: 1 ~ 16 | H20: CODE | J20: F
A21: Method of coil connection | D21: - | H21: S. F. | J21: 1.15 | Q21: Method of Connection
A22: Resistance per phase @ 20 °C | D22: 0.2331 | H22: DESIGN | Q22: Skip
A23: Coil Weight | B23: Wire1 | D23: 287 | H23: Nom.Eff. (%): | Q23: Adjacent
A24: (lbs.) | B24: Wire2 | D24: 323 | H24: Min.Eff. (%): | Q24: -
A25: Current Densities (A/cm2) | E25: Bar / ER | H25: P.F. (%): | J25: 92
A26: FL / LR | D26: 315 / 1958 | E26: 481 / 506
A27: Stator Slot Shape (Reference) | F27: Performance | K27: LAB N2501MTR47
H28: LRC (A) | I28: - | J28: 945 | K28: 1027 | M28: =J28/J18 -> 6.2171053 | N28: =K28/J18 -> 6.7565789
H29: LRT (%) | I29: 60 | J29: 94 | K29: -
H30: BDT (%) | I30: 175 | J30: 218 | K30: -
H31: SLIP (%) | J31: 0.57 | K31: -
G32: IEEE-B | H32: Eff. (%) | J32: 95.9 | K32: -
A33: Rotor Slot Shape (Reference) | H33: PF (%) | J33: 92.2 | K33: - | O33: N2501MTR47 | P33: 45924 | Q33: A1-10136700
F34: Losses (Watts) | H34: Primary | J34: 6869 | K34: -
H35: Secondary | J35: 5522 | K35: - | O35: V | P35: I | Q35: %FLA | S35: logV | T35: logI
H36: Core | J36: 6100 | K36: - | O36: 2578.14 | P36: 633.37 | Q36: =P36/$J$18 -> 4.1669079 | S36: =LOG(O36) -> 3.4113065 | T36: =LOG(P36) -> 2.8016575
H37: F & W | J37: 17823 | K37: - | O37: 2363.78 | P37: 570.11 | Q37: =P37/$J$18 -> 3.7507237 | S37: =LOG(O37) -> 3.3736071 | T37: =LOG(P37) -> 2.7559587
H38: Stray | J38: 3981 | K38: - | O38: 1918.95 | P38: 450.801 | Q38: =P38/$J$18 -> 2.9657961 | S38: =LOG(O38) -> 3.2830637 | T38: =LOG(P38) -> 2.6539849
A39: End Ring (Reference) | F39: Note | G39: RNP OF BS2M25U | O39: 1782.11 | P39: 410.326 | Q39: =P39/$J$18 -> 2.6995132 | S39: =LOG(O39) -> 3.2509345 | T39: =LOG(P39) -> 2.613129
F40: LINK: | G40: H040052.RAT & LAB 1125 & 1126.DAT | O40: 1179.32 | P40: 260.816 | Q40: =P40/$J$18 -> 1.7158947 | S40: =LOG(O40) -> 3.0716317 | T40: =LOG(P40) -> 2.4163342
...

Sheet Performance Data Sheet
A1: TOSHIBA INTERNATIONAL CORPORATION | J1: INDEX | L1: MPCF-1033
A2: Industrial Division / Houston Motor Plant | J2: SHEET NO. | L2: 1 of 1
J3: ISSUED | L3: 7/31/13
J4: SUPERSEDES | L4: 11/8/96
J5: REVISION | L5: 2
A6: SQUIRREL CAGE INDUCTION MOTOR | J6: WRITTEN BY | L6: MDC
A7: PERFORMANCE SPECIFICATIONS | J7: APPROVED BY | L7: PAA
B9: CUSTOMER: | C9: CLYDE UNION PUMPS CANADA LTD
B10: TIC SR No.: | C10: 2306938.1
A12: MOTOR NAMEPLATE DATA
B13: H.P.: | C13: 1250 | E13: VOLTS: | F13: 4000 | H13: 3 PH / | I13: 60 Hz | L13: S. RPM: | M13: 3600
B14: FRAME: | C14: 5812USS | E14: ENCL: | F14: TEAAC | H14: FLAMPS: | I14: 152 | L14: FLRPM: | M14: 3580
B15: FORM: | C15: FCKNW4 | E15: S.F.: | F15: 1.0 | H15: NEMA DESIGN: | I15: - | L15: INSUL CLASS: | M15: F
B16: TYPE: | C16: TIKE | E16: AMB.: | F16: 40°C | H16: CODE: | I16: F | L16: DUTY: | M16: Cont.
B17: MODEL No.: | C17: A1-10134386 | H17: kW: | I17: -
B18: NOM. EFF.: | C18: 95.8 | E18: MIN. EFF.: | F18: - | H18: P.F.: | I18: 92
A21: AMPERAGE | E21: TORQUES | I21: **BEARINGS:
C22: LOCKED ROTOR: | D22: 945 | G22: FULL LOAD (lb-ft.): | H22: 1834 | K22: DRIVE END: | L22: REFER TO NP
G23: LOCKED ROTOR (%): | H23: 90 | K23: OPPOSITE DRIVE END: | L23: REFER TO NP
G24: BREAK DOWN (%): | H24: 215
A28: EFFICIENCY | H28: POWER FACTOR
C29: FULL LOAD: | D29: 95.8 | J29: FULL LOAD: | K29: 92.3
C30: 3/4 LOAD: | D30: 95.2 | J30: 3/4 LOAD: | K30: 90.8
C31: 1/2 LOAD: | D31: 93.6 | J31: 1/2 LOAD: | K31: 86.1
A35: ALL CHARACTERISTICS ARE AVERAGE EXPECTED VALUES BASED UPON RATED VOLTAGE,
A36: FREQUENCY AND SINEWAVE POWER INPUT.
A37: THE DECLARED LOCKED ROTOR CURRENT HAS A TOLERANCE OF 20%.
A38: * TEMPERATURE RISE WILL BE CONSISTENT WITH INSULATION, AMBIENT AND SERVICE FACTOR AS
A39: DEFINED BY NEMA-MG-12 OR -20.
A40: ** BEARINGS ARE THE ONLY RECOMMENDED SPARE PART(S).
J42: CERTIFIED BY: | K42: Zichao Xie
J44: DATE: | K44: 45198
A59: - | B59: 6205ZZ | D59: 1 | E59: -
A60: TEFC | B60: 6206UU | D60: 1.15 | E60: A
A61: ODP | B61: 6207ZZ | E61: B
B62: 6208UU
B63: 6211ZZ
B64: 6211C3
B65: 6211ZZC3
B66: 6305UUC3
...

Sheet STCurve
A2: TOSHIBA INTERNATIONAL CORPORATION
A3: Speed Torque/Current Curve
A6: Model #: | B6: ='Performance Data Sheet'!C17 -> A1-10134386 | E6: FLAmps: | F6: ='Performance Data Sheet'!I14 -> 152
A7: Enclosure: | B7: ='Performance Data Sheet'!F14 -> TEAAC | C7: Voltage: | D7: ='Performance Data Sheet'!F13 & " V" -> 4000 V | E7: Frame: | F7: ='Performance Data Sheet'!C14 -> 5812USS
A8: Pole: | B8: 2 | C8: Frequency: | D8: 3 PH / 60 Hz | E8: Ins. Class: | F8: ='Performance Data Sheet'!M15 -> F
A9: HP: | B9: ='Performance Data Sheet'!C13 -> 1250 | C9: Rotor Inertia: | D9: 222.9 lb-ft² | E9: Date: | F9: ='Performance Data Sheet'!K44 -> 45198
A10: FLRPM: | B10: ='Performance Data Sheet'!M14 -> 3580 | C10: Load Inertia: | D10: 790.4 lb-ft² | E10: File: | F10: h040052
B12: Locked Rotor Amps: | C12: ='Performance Data Sheet'!D22 & " A" -> 945 A | D12: Load Type: | E12: Fan / Pump
B13: Locked Rotor Torque: | C13: ='Performance Data Sheet'!H23/100 -> 0.9 | D13: Starting at: | E13: FV / 0.80 (V)
B14: Breakdown Torque: | C14: 2.15 | D14: Accel. Time: | E14: 9.2 / 20.4 (s)
B15: Rated Torque: | C15: ='Performance Data Sheet'!H22 & " lb-ft" -> 1834 lb-ft
A39: Comments: | B39: PROJECT | C39: ='Performance Data Sheet'!C10 -> 2306938.1 | E39: D.E.Curve #: | F39: =F10 -> h040052
C43: Prepared by: | D43: ='Performance Data Sheet'!K42 -> Zichao Xie | E43: Checked by:
D53: Load | E53: Torque 80% | F53: LRA 80%
A54: 100 | B54: 0 | C54: 0.22980531 | D54: 100 | E54: 0 | F54: 27.944326 | H54: =E54-D54 -> -100
A55: 99.2 | B55: 109.65213 | C55: 156.70253 | D55: 98.400002 | E55: 70.17736 | F55: 125.36202 | H55: =E55-D55 -> -28.222641
A56: 96 | B56: 215 | C56: 475.23428 | D56: 89.75 | E56: 137.6 | F56: 380.18744 | H56: =E56-D56 -> 47.850004
A57: 90.947369 | B57: 146.76911 | C57: 558.69293 | D57: 76.463158 | E57: 93.932239 | F57: 446.95435 | H57: =E57-D57 -> 17.469081
A58: 85.894737 | B58: 116.85355 | C58: 580.53729 | D58: 63.326317 | E58: 74.786277 | F58: 464.42984 | H58: =E58-D58 -> 11.45996
A59: 80.842105 | B59: 104.5785 | C59: 589.25793 | D59: 51.852631 | E59: 66.930241 | F59: 471.40634 | H59: =E59-D59 -> 15.077611
A60: 70.73684 | B60: 97.672795 | C60: 597.08966 | D60: 34.252628 | E60: 62.510593 | F60: 477.67172 | H60: =E60-D60 -> 28.257964
A61: 60.631579 | B61: 94.685376 | C61: 601.99219 | D61: 22.694736 | E61: 60.598644 | F61: 481.59375 | H61: =E61-D61 -> 37.903908
A62: 50.526315 | B62: 92.860141 | C62: 606.28271 | D62: 14.421052 | E62: 59.43049 | F62: 485.02618 | H62: =E62-D62 -> 45.009438
A63: 40.421051 | B63: 91.663234 | C63: 610.1922 | D63: 8.2526302 | E63: 58.66447 | F63: 488.15378 | H63: =E63-D63 -> 50.411839
A64: 30.315793 | B64: 90.89704 | C64: 613.68884 | D64: 6.0631585 | E64: 58.174108 | F64: 490.95108 | H64: =E64-D64 -> 52.11095
A65: 20.210522 | B65: 90.427148 | C65: 616.76709 | D65: 7.9578953 | E65: 57.873376 | F65: 493.41367 | H65: =E65-D65 -> 49.91548
... A67: 0 | B67: 90 | C67: 621.71051 | D67: 30 | E67: 57.600002 | F67: 497.36841 | H67: =E67-D67 -> 27.600002

Sheet Thermdam
A2: TOSHIBA INTERNATIONAL CORPORATION
A3: Thermal Limit & Acceleration Curves
A4: Design Values (For Reference Only)
A6: Model #: | B6: ='Performance Data Sheet'!C17 -> A1-10134386 | E6: FLAmps: | F6: ='Performance Data Sheet'!I14 -> 152
A7: Enclosure: | B7: ='Performance Data Sheet'!F14 -> TEAAC | C7: Voltage: | D7: ='Performance Data Sheet'!F13 & " V" -> 4000 V | E7: Frame: | F7: ='Performance Data Sheet'!C14 -> 5812USS
A8: Pole: | B8: 2 | C8: Frequency: | D8: 3 PH / 60 Hz | E8: Ins. Class: | F8: ='Performance Data Sheet'!M15 -> F
A9: HP: | B9: ='Performance Data Sheet'!C13 -> 1250 | C9: Rotor Inertia: | D9: 222.9 lb-ft² | E9: Date: | F9: ='Performance Data Sheet'!K44 -> 45198
A10: FLRPM: | B10: ='Performance Data Sheet'!M14 -> 3580 | C10: Load Inertia: | D10: 790.4 lb-ft² | E10: File: | F10: h040052
C12: ='Performance Data Sheet'!D22 & " A" -> 945 A
C13: ='Performance Data Sheet'!H23/100 -> 0.9
C15: ='Performance Data Sheet'!H22 & " lb-ft" -> 1834 lb-ft
A39: Comments: | B39: PROJECT | C39: ='Performance Data Sheet'!C10 -> 2306938.1 | E39: D.E.Curve #: | F39: =F10 -> h040052
C43: Prepared by: | D43: ='Performance Data Sheet'!K42 -> Zichao Xie | E43: Checked by:
F50: =5252.1*B50/D53 -> #DIV/0!
D66: =D65/D64 -> #DIV/0!
A67: Current (%) | B67: Cold | C67: Hot | E67: CURRENT (%) | F67: Accel. Time | H67: CURRENT (%) | I67: Accel. Time
A68: 621.71053 | B68: 24.848042 | C68: 11.483563 | E68: =A68 -> 621.71053 | F68: 0.0001 | H68: 621.71053 | I68: 0.0001
A69: =FLOOR(A68,100) -> 600 | B69: =((A68/A69)^2)*B68 -> 26.678789 | C69: =((A68/A69)^2)*C68 -> 12.329646 | E69: 620.52632 | F69: 0.96600002 | H69: 496.44737 | I69: 1.8559999
A70: =A69-100 -> 500 | B70: =((A68/A70)^2)*B68 -> 38.417455 | C70: =((A68/A70)^2)*C68 -> 17.75469 | E70: 618.02632 | F70: 1.7950001 | H70: 494.47368 | I70: 3.267
A71: =A70-100 -> 400 | B71: =((A68/A71)^2)*B68 -> 60.027274 | C71: =((A68/A71)^2)*C68 -> 27.741703 | E71: 615.19737 | F71: 2.575 | H71: 492.17105 | I71: 4.5479999
A72: =A71-100 -> 300 | B72: =((A68/A72)^2)*B68 -> 106.71515 | E72: 611.90789 | F72: 3.352 | H72: 489.53947 | I72: 5.8209996
A73: =A72-100 -> 200 | B73: =((A68/A73)^2)*B68 -> 240.1091 | E73: 608.22368 | F73: 4.1589999 | H73: 486.57895 | I73: 7.1899996
A74: 215 | B74: =((A68/A74)^2)*B68 -> 207.77423 | C74: =((A68/A74)^2)*C68 -> 96.023201 | E74: 604.14474 | F74: 5.0279999 | H74: 483.28947 | I74: 8.7639999
A75: 180 | B75: =((A68/A75)^2)*B69 -> 318.27134 | C75: =((A68/A75)^2)*C68 -> 136.99606 | E75: 599.53947 | F75: 5.993 | H75: 479.60526 | I75: 10.737
A76: 120 | B76: =((A68/A76)^2)*B68 -> 666.96971 | C76: =((A68/A76)^2)*C68 -> 308.24114 | E76: 593.15789 | F76: 7.1170001 | H76: 474.53947 | I76: 13.747
A77: 110 | C77: =CEILING(C76*2,100) -> 700 | E77: 584.86842 | F77: 7.7319999 | H77: 467.89474 | I77: 16.202999
A78: 110 | C78: =2*C77 -> 1400 | E78: 569.60526 | F78: 8.2600002 | H78: 455.72368 | I78: 18.455
A79: 110 | C79: 10000 | E79: 516.97368 | F79: 8.5939999 | H79: 413.55263 | I79: 19.454
E80: 315.98684 | F80: 8.8970003 | H80: 0 | I80: 20.357
E81: 0 | F81: 9.1880007

Sheet Performance
A2: TOSHIBA INTERNATIONAL CORPORATION
A3: Performance Curve
A4: Design Values (For Reference Only)
A6: Model #: | B6: ='Performance Data Sheet'!C17 -> A1-10134386 | E6: FLAmps: | F6: ='Performance Data Sheet'!I14 -> 152
A7: Enclosure: | B7: ='Performance Data Sheet'!F14 -> TEAAC | C7: Voltage: | D7: ='Performance Data Sheet'!F13 & " V" -> 4000 V | E7: Frame: | F7: ='Performance Data Sheet'!C14 -> 5812USS
A8: Pole: | B8: 2 | C8: Frequency: | D8: 3 PH / 60 Hz | E8: Ins. Class: | F8: ='Performance Data Sheet'!M15 -> F
A9: HP: | B9: ='Performance Data Sheet'!C13 -> 1250 | C9: Rotor Inertia: | D9: 222.9 lb-ft² | E9: Date: | F9: ='Performance Data Sheet'!K44 -> 45198
A10: FLRPM: | B10: ='Performance Data Sheet'!M14 -> 3580 | C10: Load Inertia: | D10: 790.4 lb-ft² | E10: File: | F10: h040052
B12: Locked Rotor Amps: | C12: ='Performance Data Sheet'!D22 & " A" -> 945 A | D12: Load Type: | E12: Fan / Pump
B13: Locked Rotor Torque: | C13: ='Performance Data Sheet'!H23/100 -> 0.9 | D13: Starting at: | E13: FV / 0.80 (V)
B14: Breakdown Torque: | C14: 2.15 | D14: Accel. Time: | E14: 9.2 / 20.4 (s)
B15: Rated Torque: | C15: ='Performance Data Sheet'!H22 & " lb-ft" -> 1834 lb-ft
N36: SPEED | O36: KW
N37: =L43 - (L43-L44) / 10 * 0 -> 3600 | O37: =L45 / 10 * 10 -> 4000
N38: =L43 - (L43-L44) / 10 * 1 -> 3597 | O38: =L45 / 10 * 9 -> 3600
A39: Comments: | B39: PROJECT | C39: ='Performance Data Sheet'!C10 -> 2306938.1 | E39: D.E.Curve #: | F39: =F10 -> h040052 | N39: =L43 - (L43-L44) / 10 * 2 -> 3594 | O39: =L45 / 10 * 8 -> 3200
N40: =L43 - (L43-L44) / 10 * 3 -> 3591 | O40: =L45 / 10 * 7 -> 2800
N41: =L43 - (L43-L44) / 10 * 4 -> 3588 | O41: =L45 / 10 * 6 -> 2400
N42: =L43 - (L43-L44) / 10 * 5 -> 3585 | O42: =L45 / 10 * 5 -> 2000
C43: Prepared by: | D43: ='Performance Data Sheet'!K42 -> Zichao Xie | E43: Checked by: | K43: SYNC SPEED | L43: 3600 | N43: =L43 - (L43-L44) / 10 * 6 -> 3582 | O43: =L45 / 10 * 4 -> 1600
K44: NEW SPEED LOWER RANGE | L44: 3570 | N44: =L43 - (L43-L44) / 10 * 7 -> 3579 | O44: =L45 / 10 * 3 -> 1200
K45: NEW kW UPPER RANGE | L45: 4000 | N45: =L43 - (L43-L44) / 10 * 8 -> 3576 | O45: =L45 / 10 * 2 -> 800
N46: =L43 - (L43-L44) / 10 * 9 -> 3573 | O46: =L45 / 10 * 1 -> 400
N47: =L43 - (L43-L44) / 10 * 10 -> 3570 | O47: =L45 / 10 * 0 -> 0
A52: ADJUSTED
A53: Load | B53: Efficiency | C53: PF | D53: Amps | E53: RPM | F53: Input Watts
A54: 0 | D54: 29 | E54: 100 | F54: =23212/(L45*1000) * 100 -> 0.5803
A55: 25 | B55: 89.099998 | C55: 70.300003 | D55: 53.740002 | E55: =(1.00411199644291*B10-L44)/(L43-L44)*100 -> 82.403158 | F55: =261742.1/(L45*1000)*100 -> 6.5435525
A56: 50 | B56: 93.699997 | C56: 86.099998 | D56: 83.410004 | E56: =(1.00277911138268*B10-L44)/(L43-L44)*100 -> 66.497396 | F56: =497555.9/(L45*1000)*100 -> 12.438898
A57: 75 | B57: 95.200005 | C57: 90.699997 | D57: 116.8 | E57: =(1.00141792510475*B10-L44)/(L43-L44)*100 -> 50.253906 | F57: =733957.3/(L45*1000)*100 -> 18.348933
A58: 100 | B58: 95.800003 | C58: 92.299995 | D58: 152.12 | E58: =(1*B10-L44)/(L43-L44)*100 -> 33.333333 | F58: =972766.5/(L45*1000)*100 -> 24.319163
A59: 125 | B59: 96.100006 | C59: 92.699997 | D59: 188.92 | E59: =(0.998979042095845*B10-L44)/(L43-L44)*100 -> 21.149902 | F59: =1213328/(L45*1000)*100 -> 30.3332
A62: ORIGINAL
A63: Load | B63: Efficiency | C63: PF | D63: Amps | E63: RPM | F63: Input Watts
A64: 0 | D64: 35.209851 | E64: 100 | F64: 0.580305
A65: 25 | B65: 88.981049 | C65: 70.326042 | D65: 53.740047 | E65: 79.121608 | F65: 6.5457904
A66: 50 | B66: 93.626846 | C66: 86.121338 | D66: 83.412392 | E66: 63.443722 | F66: 12.441973
A67: 75 | B67: 95.167084 | C67: 90.751137 | D67: 116.8138 | E67: 47.329044 | F67: 18.360907
A68: 100 | B68: 95.768791 | C68: 92.326706 | D68: 152.13194 | E68: 30.632659 | F68: 24.327397
A69: 125 | B69: 96.025345 | C69: 92.67955 | D69: 188.9348 | E69: 18.796745 | F69: 30.328

Sheet StallTime
A1: Rating: | B1: 2 Pole - 1250.0 HP - 3600 RPM - 4000 V - 60 Hz
A3: Starting Performance
D4: Load Type: Fan / Pump - 790.4 lb-ft²
A5: RPM | B5: Motor | C5: Load | D5: Accel. | E5: Line | F5: Stator | G5: Rotor
A6: Speed Increment | B6: Torque (%) | C6: Torque (%) | D6: Time (s) | E6: Amps | F6: kW / s | G6: kW / s
A7: 0~364 | B7: 90.1 | C7: 22.5 | D7: 0.966 | E7: 943.2 | F7: 268.3 | G7: 834.2
A8: 364~728 | B8: 90.3 | C8: 11.4 | D8: 0.829 | E8: 939.4 | F8: 228.4 | G8: 644.4
A9: 728~1091 | B9: 90.7 | C9: 7.0 | D9: 0.780 | E9: 935.1 | F9: 213.2 | G9: 540.1
A10: 1091~1455 | B10: 91.3 | C10: 7.2 | D10: 0.777 | E10: 930.1 | F10: 210.1 | G10: 471.9
A11: 1455~1819 | B11: 92.3 | C11: 11.3 | D11: 0.807 | E11: 924.5 | F11: 215.9 | G11: 423.0
A12: 1819~2183 | B12: 93.8 | C12: 18.6 | D12: 0.869 | E12: 918.3 | F12: 229.3 | G12: 382.8
A13: 2183~2547 | B13: 96.2 | C13: 28.5 | D13: 0.965 | E13: 911.3 | F13: 251.2 | G13: 345.0
A14: 2547~2910 | B14: 101.1 | C14: 43.1 | D14: 1.124 | E14: 901.6 | F14: 287.9 | G14: 308.2
A15: 2910~3092 | B15: 110.7 | C15: 57.6 | D15: 0.615 | E15: 889.0 | F15: 153.4 | G15: 236.4
A16: 3092~3274 | B16: 131.8 | C16: 69.9 | D16: 0.528 | E16: 865.8 | F16: 127.7 | G16: 166.8
... A19: 3571~3580 | B19: 104.8 | C19: 99.2 | D19: 0.291 | E19: 145.6 | F19: 2.1 | G19: 67.3
D21: Acceleration Time: 9.2 s
B22: Energy | D22: First Start | F22: Second Start
A23: Stator Winding Rise | B23: 2312 kW / s | D23: 22°C | F23: 43°C
A24: Rotor Bar Rise | B24: 4128 kW / s | D24: 124°C | F24: 249°C
A25: End Ring Rise | B25: 456 kW / s | D25: 45°C | F25: 90°C
A27: Locked Rotor Thermal Capability
E28: Cold Condition
B29: Rate of Rise | D29: Power | E29: Rise Limit | F29: Max Time
A30: Stator Copper | B30: 3.1°C / s | D30: 327.9 kW | E30: 160°C | F30: 52.1 s
A31: Rotor Bar | B31: 22.8°C / s | D31: 755.8 kW | E31: 260°C | F31: 11.4 s
A32: Rotor ER | B32: 8.2°C / s | D32: 83.4 kW | E32: 180°C | F32: 22.0 s
E34: Hot Condition
B35: Hot Temp. | D35: Rise Limit | E35: Ambient | F35: Total | G35: Max.Time
A36: Stator Copper | B36: 72°C + | D36: 88°C + | E36: 40°C | F36: = 200°C | G36: 28.6 s
A37: Rotor Bar | B37: 97°C + | D37: 163°C + | E37: 40°C | F37: = 300°C | G37: 7.2 s
A38: Rotor ER | B38: 97°C + | D38: 83°C + | E38: 40°C | F38: = 220°C | G38: 10.2 s
A40: Cold Stall Time: | B40: 17.4 s | D40: Hot Stall Time: | F40: 8.0 s
