Workbook
Name Print_Area_MI: 'Performance Data Sheet'!$A$10:$N$43

Sheet DesignSheet
A1: TOSHIBA INTERNATIONAL CORPORATION | I1: Calc. Code: | J1: 2-2-2-0-1-2
A2: 3-PHASE SQUIRREL CAGE INDUCTION MOTOR DESIGN SHEET | J2: B.L.-1 P.F.-1
A3: File: | B3: Z:\Motor R&D\Active Projects\6810 Development\Electrical Design\TEAAC\2P\Series\BS2M30U.rat | G3: Date: | H3: 41940 | I3: Time: | J3: 0.73060185
A4: Pole | B4: HP | C4: RPM | D4: Form | E4: Voltage | F4: Frequency | G4: Temperature | H4: FLSpeed | I4: FLSlip | J4: Frame
A5: 2 | B5: 1500 | C5: 3600 | D5: FCW4 | E5: 4000 | F5: 60 | G5: 105 | H5: 3581.1 / 3581.3 | I5: 0.0053 / 0.0052 | J5: 6810USS
A6: Core Data | D6: Winding Data | H6: Constant Data
B7: Primary | C7: Secondary | F7: Bar | G7: End Ring | H7: St. Slot Pitch | I7: 26.179917 | J7: LR Test Data
A8: Air Gap | B8: 3.5 | H8: Rt. Slot Pitch | I8: 30.254878 | J8: ES
A9: Space Fac. | B9: 0.93000001 | D9: Pitch | E9: 1 ~ 18 | F9: Cross Section Area | H9: Mean Value | I9: 28.217397 | J9: 592.63297
A10: Core Length | B10: 500 | C10: 500 | F10: UB: 322.1 | G10: UER: 3768.4 | H10: Eff.T.W.St. | I10: 17.127578 | J10: WS
A11: OD | B11: 815 | C11: 443 | D11: Coil Pitch | E11: 0.62956667 | H11: Eff.T.W.Rt. | I11: 29.859305 | J11: 37826.011
A12: ID | B12: 450 | C12: 170 | D12: Slot Fill | E12: - | F12: EBL: 62.5 | G12: ERD1: 328.0 | H12: St.Carter Fac. | I12: 1.5285241 | J12: IS
A13: Core Depth | B13: 109.5 | C13: 98.09 | D13: Con./Slot | E13: 18 | G13: ERT: 65.54 | H13: Rt.Carter Fac. | I13: 1.0132479 | J13: 180.48
A14: Eff.Core L. | B14: 375.72 | C14: 431.51999 | D14: Wire Size 1 | E14: (.091"x.258")x2 | G14: ERH: 57.50 | H14: Carter Factor | I14: 1.5487738 | J14: Volts / Turn
A15: Slot Data | D15: Wire Size 2 | E15: - | H15: Short. Factor | I15: 0.835433 | J15: 28.51196
A16: Number | B16: 54 | C16: 46 | D16: // Circuits | E16: 2 | H16: Distrib. Factor | I16: 0.95529271 | J16: AC
A17: Kind | B17: Open | C17: Trapeze | D17: Connection | E17: Wye | H17: Wind. Factor | I17: 0.79808305 | J17: 620.44505
A18: Skew | B18: - | C18: 0 | D18: MCL | E18: 1367 | F18: 690.537 | H18: Reactance | I18: (Coeff.: 0.0245)
A19: Depth | B19: 73 | C19: 38.41 | D19: No.Cond./Ph. | E19: 162 | I19: Running | J19: Start
A20: Width | B20: 17.30 - 17.30 | D20: Res. (20°C) | E20: 0.064997284 | H20: Stator Slot | I20: 14.993257 | J20: 14.993257
A21: Opening | B21: 17.299999 | C21: 3 | D21: (105°C) | E21: 0.08670561 | F21: 0.055385336 | G21: 0.017881383 | H21: Rotor Slot | I21: 16.318153 | J21: 13.797791
A22: Tip Depth | B22: 13.15 | C22: 3 | D22: Material | E22: CU | F22: CU | G22: CU | H22: Zigzag | I22: 4.6907854 | J22: 4.3235888
A23: T.Min.Wid. | B23: 8.8799171 | C23: 10.888422 | D23: Spec.Resist. | E23: 1.742 | F23: 1.742 | G23: 1.742 | H23: Coil End | I23: 36.260753 | J23: Skew R.: 0.00
A24: Low. R. | B24: 0 | C24: 0.80000001 | D24: Spec.Gravity | E24: 8.8900003 | F24: 8.8900003 | G24: 8.8900003 | H24: Belt Leakage | I24: 6.7857612 | J24: 6.2545696
A25: Up. R. | B25: - | C25: 5.7199998 | D25: Weight (kg) | H25: Total Resist. | I25: 0.15997232 | J25: 0.38708928
A26: Wedge Dep. | B26: 0.80 - 2.40 | C26: Normal | D26: Wire 1 | E26: 350.5444 | F26: 99.602122 | G26: 84.531503 | H26: Total React. | I26: 1.9398286 | J26: 1.8559337
A27: Duct | B27: 16 x 6 | C27: 6 x 6 | D27: Wire 2 | E27: - | F27: - | G27: - | H27: Impedance | I27: 1.9464136 | J27: 1.8958713
A28: Effective Depth (S=1) | D28: Magnetic Circuit Data | I28: Core Loss Data
B29: Res.= | C29: 35.359193 | E29: Length | F29: Section | G29: Density | H29: AT | I29: Volume | J29: Loss
B30: Reac.= | C30: 35.395463 | D30: Primary Core | E30: 64.009896 | F30: 822.8268 | G30: 16.298076 | H30: 825.6117 | I30: 91185.327 | J30: 7137.5597
A31: Excitation Data | D31: Tooth | E31: 7.3 | F31: 900.81787 | G31: 14.88702 | H31: 64.05152 | I31: 13151.941 | J31: 889.00125
A32: Excit.Amps | B32: 42.421 / 42.486 | D32: Second.Core | E32: 28.759686 | F32: 1091.0839 | G32: 12.290983 | H32: 124.87448 | I32: Total | J32: 8026.5609
A33: Core Loss | B33: 2.732 / 2.736 | C33: Flux / Pole | D33: Tooth | E33: 3.841 | F33: 1080.6715 | G33: 12.409408 | H33: 17.11239 | I33: C.L.C. | J33: 1.75 / 0.71
A34: NoLoad | B34: 42.51 / 42.57 | C34: 13.410494 | D34: Air Gap | E34: 0.35 | F34: 1980.7687 | G34: 6.7703482 | H34: 1885.6868 | I34: S.F.C. | J34: 6.0500002
A35: Load Characteristics | D35: Temp. Rise @ 100%: | E35: 69 / 68 | G35: No Load Loss | H35: 28520.3 / 42373.2 | I35: W.Loss | J35: 14046.5 / 5721.1
A36: Load (%) | B36: 25 | C36: 50 | D36: 75 | E36: 100 | F36: 125 | G36: Primary Loss | H36: 8472.8 / 8557.6 | I36: S.Loss | J36: 4898.0 / 1994.9
A37: Current (A) | B37: 64.49 / 66.80 | C37: 98.85 / 102.39 | D37: 138.50 / 143.46 | E37: 180.48 / 186.95 | F37: 224.06 / 232.08 | G37: Second. Loss | H37: 6032.3 / 5723.3 | I37: Total C.Loss | J37: 18944.4 / 7716.0
A38: Efficiency | B38: 0.904 / 0.887 | C38: 0.946 / 0.928 | D38: 0.958 / 0.941 | E38: 0.964 / 0.946 | F38: 0.965 / 0.947 | G38: Frict.& Wind. | H38: 9225.0 / 29346.7 | I38: Stray Loss | J38: 13139.507
A39: P.F. | B39: 0.692 / 0.681 | C39: 0.864 / 0.850 | D39: 0.912 / 0.898 | E39: 0.929 / 0.914 | F39: 0.933 / 0.918 | G39: Starting Data | I39: Slip | J39: PF
A40: Slip | B40: 0.0013 / 0.0013 | C40: 0.0026 / 0.0026 | D40: 0.0039 / 0.0039 | E40: 0.0053 / 0.0052 | F40: 0.0066 / 0.0065 | G40: LRA | H40: 1218.2 / 1182.8
...

Sheet Data Sheet
A1: TOSHIBA INTERNATIONAL CORPORATION
A2: INDUCTION MOTOR DATA SHEET
A3: File: | B3: BS2M30U | I3: HRW / Model Number: | J3: M303TCQL11F-C
A4: Type: TIKE - Form: FCW4 - 2 Pole - 1500 HP - 4000 V - 60 Hz - 6810USS - Class F | Q4: Motor Type Selection | T4: Electrical Steel Table
A5: Motor Parameters | F5: PERFORMANCE | J5: DESIGN | K5: TEST | Q5: EPACT | T5: M22 - 26Ga.
A6: Material | D6: M36 - 26Ga. | F6: NL & Impedance Test | Q6: EQP-III | T6: M36 - 26Ga.
A7: Air Gap | D7: 3.5 | F7: No load amps | J7: 43 | K7: - | Q7: Exp.Prf. | T7: NCB1 - 26Ga.
A8: Stack length | D8: 500 | F8: No load watts | J8: 37432 | K8: - | Q8: Exp.Prf.-EQPIII | T8: M43 - 26Ga.
A9: Number of turns per coil | D9: 9 | F9: Impedance amps | H9: 3 | I9: f | J9: 365 | K9: - | Q9: Prem. Eff. | T9: M45 - 26Ga.
A10: Wire 1 (size & number) | D10: (.091"x.258")x2 | F10: Impedance volts | H10: 3 | I10: f | J10: 1150 | K10: - | Q10: OWP | T10: M54 - 26Ga.
A11: Wire 2 (size & number) | D11: - | F11: Impedance watts | H11: 3 | I11: f | J11: 110524 | K11: - | Q11: Dry Kiln
A12: Slot fill - circle/square method (%) | D12: - | F12: Temperature Rise (°C)
A13: Connection | D13: 2 x Wye | G13: Winding | I13: 80/115 | J13: 68 / 91 | K13: -
A14: MCL | D14: 1367 | G14: Frame | J14: - | K14: -
A15: Allowance for ins. depth | D15: 14.6448 | G15: Bearing PS/OS | J15: - | K15: -
A16: Allowance for ins. width | D16: 3.7935991 | G16: End Ring | J16: - | K16: -
A17: Slot/Wire arrangement | D17: 18 x 2 | F17: Nameplate Data
A18: Effective cross section for coil | D18: - | H18: FLC (A) | J18: 187 | M18: =J18*6.5 -> 1215.5
A19: Coil grouping | D19: - | H19: RPM | J19: 3581
A20: Coil pitch (slot number) | D20: 1 ~ 18 | H20: CODE | J20: F
A21: Method of coil connection | D21: - | H21: S. F. | J21: 1.15 | Q21: Method of Connection
A22: Resistance per phase @ 20 °C | D22: 0.0665 | H22: DESIGN | J22: - | Q22: Skip
A23: Coil Weight | B23: Wire1 | D23: 789 | H23: Nom.Eff. (%): | Q23: Adjacent
A24: (lbs.) | B24: Wire2 | D24: - | H24: Min.Eff. (%): | Q24: -
A25: Current Densities (A/cm2) | E25: Bar / ER | H25: P.F. (%): | J25: -
A26: FL / LR | D26: 315 / 1993 | E26: 449 / 281
A27: Stator Slot Shape (Reference) | F27: Performance
H28: LRC (A) | I28: - | J28: 1183 | K28: - | M28: =(J28/J18)*100 -> 632.62032
H29: LRT (%) | I29: 60 | J29: 97 | K29: -
H30: BDT (%) | I30: 175 | J30: 256 | K30: -
H31: SLIP (%) | J31: 0.52 | K31: -
G32: IEEE-B | H32: Eff. (%) | J32: 94.6 | K32: -
A33: Rotor Slot Shape (Reference) | H33: PF (%) | J33: 91.4 | K33: -
F34: Losses (Watts) | H34: Primary | J34: 8558 | K34: -
H35: Secondary | J35: 5723 | K35: -
H36: Core | J36: 7716 | K36: -
H37: F & W | J37: 29347 | K37: -
H38: Stray | J38: 13140 | K38: -
A39: End Ring (Reference) | F39: Note
G40: RSO2: 400-TA14-02P
...

Sheet Data Sheet1
A1: TOSHIBA INTERNATIONAL CORPORATION
A2: INDUCTION MOTOR DATA SHEET
A3: File: | B3: BS2M30U | I3: HRW / Model Number:
A4: Type: TIKE - Form: FCW4 - 2 Pole - 1500 HP - 2300 / 4000 V - 60 Hz - 6810USS - Class F | Q4: Motor Type Selection | T4: Electrical Steel Table
A5: Motor Parameters | F5: PERFORMANCE | J5: DESIGN | K5: TEST | Q5: EPACT | T5: M22 - 26Ga.
A6: Material | D6: NCB1 - 26Ga. | F6: NL & Impedance Test | Q6: EQP-III | T6: M36 - 26Ga.
A7: Air Gap | D7: 3.5 | F7: No load amps | J7: 74 / 43 | K7: - | Q7: Exp.Prf. | T7: NCB1 - 26Ga.
A8: Stack length | D8: 500 | F8: No load watts | J8: 42373 | K8: - | Q8: Exp.Prf.-EQPIII | T8: M43 - 26Ga.
A9: Number of turns per coil | D9: 9 | F9: Impedance amps | H9: 1 | I9: f | J9: 350 | K9: - | Q9: Prem. Eff. | T9: M45 - 26Ga.
A10: Wire 1 (size & number) | D10: (.091"x.258")x2 | F10: Impedance volts | H10: 1 | I10: f | J10: 1150 | K10: - | Q10: Standard Eff. | T10: M54 - 26Ga.
A11: Wire 2 (size & number) | D11: - | F11: Impedance watts | H11: 1 | I11: f | J11: 37826 | K11: - | Q11: OWP | T11: TIPA Lam
A12: Slot fill - circle/square method (%) | D12: - | F12: Temperature Rise (°C) | Q12: Dry Kiln
A13: Connection | D13: 2D / 2Y | G13: Winding | I13: 80/115 | J13: 69 / 91 | K13: -
A14: MCL | D14: 1367 | G14: Frame | J14: - | K14: -
A15: Allowance for ins. depth | D15: 14.6448 | G15: Bearing PS/OS | J15: - | K15: -
A16: Allowance for ins. width | D16: 3.7935991 | G16: End Ring | J16: - | K16: -
A17: Slot/Wire arrangement | D17: 18 x 2 | F17: Nameplate Data
A18: Effective cross section for coil | D18: - | H18: FLC (A) | J18: 324 / 187 | M18: =J18*6.5 -> #VALUE!
A19: Coil grouping | D19: - | H19: RPM | J19: 3580
A20: Coil pitch (slot number) | D20: 1 ~ 18 | H20: CODE | J20: F
A21: Method of coil connection | D21: - | H21: S. F. | J21: 1.15 | Q21: Method of Connection
A22: Resistance per phase @ 20 °C | D22: 0.064999998 | H22: DESIGN | J22: B | Q22: Skip
A23: Coil Weight | B23: Wire1 | D23: 771.2 | H23: Nom.Eff. (%): | Q23: Adjacent
A24: (lbs.) | B24: Wire2 | D24: - | H24: Min.Eff. (%): | Q24: -
A25: Current Densities (A/cm2) | E25: Bar / ER | H25: P.F. (%): | J25: 91
A26: FL / LR | D26: 315 / 1993 | E26: 449 / 281
A27: Stator Slot Shape (Reference) | F27: Performance
H28: LRC (A) | I28: - | J28: 2049/ 1183 | K28: - | M28: =(J28/J18)*100 -> #VALUE!
H29: LRT (%) | I29: 60 | J29: 97 | K29: -
H30: BDT (%) | I30: 175 | J30: 256 | K30: -
H31: SLIP (%) | J31: 0.52 | K31: -
G32: IEEE-B | H32: Eff. (%) | J32: 94.6 | K32: -
A33: Rotor Slot Shape (Reference) | H33: PF (%) | J33: 91.4 | K33: -
F34: Losses (Watts) | H34: Primary | J34: 8558 | K34: -
H35: Secondary | J35: 5723 | K35: -
H36: Core | J36: 7716 | K36: -
H37: F & W | J37: 29347 | K37: -
H38: Stray | J38: 13140 | K38: -
A39: End Ring (Reference) | F39: Note
A45: Approved | D45: Design | E45: Z.XIE
...

Sheet LoginSheet
J1: P | K1: T | L1: L | M1: T
B2: PROJECT HISTORY | J2: E | K2: D | L2: I | M2: Y | N2: H
J3: R | L3: M | M3: P
J4: F | L4: I | M4: E
K5: C | L5: T | N5: I
J6: D | K6: U | M6: T | N6: N
J7: A | K7: R | L7: R | M7: E | N7: S
I8: S | J8: T | K8: V | L8: E | M8: S | N8: U
B9: DATE | C9: PROJECT | D9: SMART NUMBER | E9: QTY | F9: CUSTOMER | G9: REMARKS | H9: LIMIT CODE | I9: F | J9: A | K9: E | L9: V | M9: T | N9: L
B53: REVISION HISTORY
B54: REV | C54: REMARKS | I54: DATE | L54: INIT

Sheet Form
A1: Winding Data Calculation
C2: MCL: 1367.0
A3: Coil Resistance | D3: Lead Resistance
A4: 9T: | B4: 0.0148 ~ 0.0142 | D4: AWG. (02 x 2) x 3
D5: 0.00102
A6: Coil Dimensions
A7: HM: | B7: 9T: 22.60 | C7: WM: | D7: 9T: 13.51 | E7: WT:
E8: 17.40 ~ 17.00
A9: Insulation Allowance | D9: Wire Weight
A10: Depth: | B10: 14.64 | D10: (.091"x.258")x 2: | F10: 789 lbs.
A11: Width: | B11: 3.79
A12: QC Resistance
A13: 1-2, 2-3, 3-1: | C13: 0.137 ~ 0.129

Sheet Performance Data Sheet
A1: TOSHIBA INTERNATIONAL CORPORATION | J1: INDEX | L1: MPCF-1033
A2: Industrial Division / Houston Motor Plant | J2: SHEET NO. | L2: 1 of 1
J3: ISSUED | L3: 7/31/13
J4: SUPERSEDES | L4: 11/8/96
J5: REVISION | L5: 2
A6: SQUIRREL CAGE INDUCTION MOTOR | J6: WRITTEN BY | L6: MDC
A7: PERFORMANCE SPECIFICATIONS | J7: APPROVED BY | L7: PAA
B9: CUSTOMER:
B10: TIC SR No.:
A12: MOTOR NAMEPLATE DATA
B13: H.P.: | C13: 1500 | E13: VOLTS: | F13: 4000 | H13: 3 PH / | I13: 60 Hz | L13: S. RPM: | M13: 3600
B14: FRAME: | C14: 6810USS | E14: ENCL: | F14: TEAAC | H14: FLAMPS: | I14: 187 | L14: FLRPM: | M14: 3581
B15: FORM: | C15: FCW4 | E15: S.F.: | F15: 1.15 | H15: NEMA DESIGN: | I15: - | L15: INSUL CLASS: | M15: F
B16: TYPE: | C16: TIKE | E16: AMB.: | F16: 40°C | H16: CODE: | I16: F | L16: DUTY: | M16: Cont.
B17: MODEL No.: | C17: M303TCQL11F-C | H17: kW:
B18: NOM. EFF.: | C18: - | E18: MIN. EFF.: | F18: - | H18: P.F.: | I18: -
A21: AMPERAGE | E21: TORQUES | I21: **BEARINGS:
C22: LOCKED ROTOR: | D22: 1183 | G22: FULL LOAD (lb-ft.): | H22: 2200 | K22: DRIVE END: | L22: M9-90 INS
G23: LOCKED ROTOR (%): | H23: 95 | K23: OPPOSITE DRIVE END: | L23: M9-90 INS
G24: BREAK DOWN (%): | H24: 255
A28: EFFICIENCY | H28: POWER FACTOR
C29: FULL LOAD: | D29: 94.6 | J29: FULL LOAD: | K29: 91.4
C30: 3/4 LOAD: | D30: 94.1 | J30: 3/4 LOAD: | K30: 89.8
C31: 1/2 LOAD: | D31: 92.8 | J31: 1/2 LOAD: | K31: 85
A35: ALL CHARACTERISTICS ARE AVERAGE EXPECTED VALUES BASED UPON RATED VOLTAGE,
A36: FREQUENCY AND SINEWAVE POWER INPUT.
A37: THE DECLARED LOCKED ROTOR CURRENT HAS A TOLERANCE OF 20%.
A38: * TEMPERATURE RISE WILL BE CONSISTENT WITH INSULATION, AMBIENT AND SERVICE FACTOR AS
A39: DEFINED BY NEMA-MG-12 OR -20.
A40: ** BEARINGS ARE THE ONLY RECOMMENDED SPARE PART(S).
J43: CERTIFIED BY: | K43: Mario L
J45: DATE: | K45: 41940
A60: - | B60: M9-90 INS | D60: 1 | E60: -
A61: TEFC | B61: 6206UU | D61: 1.15 | E61: A
A62: ODP | B62: 6207ZZ | E62: B
B63: 6208UU
B64: 6211ZZ
B65: 6211C3
B66: 6211ZZC3
B67: 6305UUC3
...

Sheet STCurve
A2: TOSHIBA INTERNATIONAL CORPORATION
A3: Speed Torque/Current Curve
A6: Model #: | B6: ='Performance Data Sheet'!C17 -> M303TCQL11F-C | E6: FLAmps: | F6: 187
A7: Enclosure: | B7: ='Performance Data Sheet'!F14 -> TEAAC | C7: Voltage: | D7: 4000 V | E7: Frame: | F7: ='Performance Data Sheet'!C14 -> 6810USS
A8: Pole: | B8: 2 | C8: Frequency: | D8: 3 PH / 60 Hz | E8: Ins. Class: | F8: ='Performance Data Sheet'!M15 -> F
A9: HP: | B9: 1500 | C9: Rotor Inertia: | D9: 424.1 lb-ft² | E9: Date: | F9: ='Performance Data Sheet'!K45 -> 41940
A10: FLRPM: | B10: 3581 | C10: Load Inertia: | D10: N/A | E10: File: | F10: BS2M30U
B12: Locked Rotor Amps: | C12: 1183 A | D12: Load Type: | E12: N/A
B13: Locked Rotor Torque: | C13: 0.95 | D13: Starting at: | E13: N/A
B14: Breakdown Torque: | C14: 2.55 | D14: Accel. Time: | E14: N/A
B15: Rated Torque: | C15: 2200 lb-ft
A39: Comments: | E39: D.E.Curve #: | F39: BS2M30U
C43: Prepared by: | D43: ='Performance Data Sheet'!K43 -> Mario L | E43: Checked by:
A54: 100 | B54: 0 | C54: 0.2273203
A55: 99.8 | B55: 131.84279 | C55: 160.06483
A56: 99 | B56: 255 | C56: 481.83688
A57: 93.789474 | B57: 151.79292 | C57: 565.22125
A58: 88.578947 | B58: 123.43243 | C58: 587.39368
A59: 83.368421 | B59: 111.1197 | C59: 596.70807
A60: 72.947368 | B60: 103.59652 | C60: 605.98206
A61: 62.526315 | B61: 100.03431 | C61: 612.0957
A62: 52.105263 | B62: 97.925144 | C62: 617.11993
A63: 41.68421 | B63: 96.630495 | C63: 621.35333
A64: 31.263161 | B64: 95.850063 | C64: 624.90948
A65: 20.842105 | B65: 95.393803 | C65: 627.90192
... A67: 0 | B67: 95 | C67: 632.6203

Sheet StallTime
A1: Rating: | B1: 2 Pole - 1500.0 HP - 3600 RPM - 4000 V - 60 Hz
A3: Starting Performance
D4: Load Type: Fan / Pump - 451.0 lb-ft²
A5: RPM | B5: Motor | C5: Load | D5: Accel. | E5: Line | F5: Stator | G5: Rotor
A6: Speed Increment | B6: Torque (%) | C6: Torque (%) | D6: Time (s) | E6: Amps | F6: kW / s | G6: kW / s
A7: 0~375 | B7: 95.1 | C7: 22.4 | D7: 0.667 | E7: 1181.0 | F7: 242.8 | G7: 860.4
A8: 375~750 | B8: 95.3 | C8: 11.3 | D8: 0.577 | E8: 1176.6 | F8: 208.7 | G8: 668.0
A9: 750~1125 | B9: 95.6 | C9: 7.0 | D9: 0.547 | E9: 1171.4 | F9: 196.3 | G9: 561.2
A10: 1125~1501 | B10: 96.2 | C10: 7.6 | D10: 0.547 | E10: 1165.3 | F10: 194.4 | G10: 489.6
A11: 1501~1876 | B11: 97.3 | C11: 12.3 | D11: 0.571 | E11: 1158.0 | F11: 200.6 | G11: 437.0
A12: 1876~2251 | B12: 99.0 | C12: 20.2 | D12: 0.616 | E12: 1149.3 | F12: 213.4 | G12: 392.4
A13: 2251~2626 | B13: 101.8 | C13: 31.4 | D13: 0.689 | E13: 1138.9 | F13: 234.7 | G13: 350.6
A14: 2626~3001 | B14: 107.4 | C14: 47.7 | D14: 0.814 | E14: 1124.5 | F14: 271.7 | G14: 309.6
A15: 3001~3189 | B15: 117.3 | C15: 63.9 | D15: 0.454 | E15: 1107.1 | F15: 147.0 | G15: 227.9
A16: 3189~3376 | B16: 137.6 | C16: 77.1 | D16: 0.401 | E16: 1077.7 | F16: 125.8 | G16: 153.4
... A19: 3593~3600 | B19: 115.9 | C19: 99.8 | D19: 0.058 | E19: 189.4 | F19: 0.5 | G19: 28.3
D21: Acceleration Time: 6.2 s
B22: Energy | D22: First Start | F22: Second Start
A23: Stator Winding Rise | B23: 2107 kW / s | D23: 16°C | F23: 31°C
A24: Rotor Bar Rise | B24: 3441 kW / s | D24: 90°C | F24: 179°C
A25: End Ring Rise | B25: 1111 kW / s | D25: 34°C | F25: 68°C
A27: Locked Rotor Thermal Capability
E28: Cold Condition
B29: Rate of Rise | D29: Power | E29: Rise Limit | F29: Max Time
A30: Stator Copper | B30: 3.1°C / s | D30: 424.4 kW | E30: 160°C | F30: 50.9 s
A31: Rotor Bar | B31: 21.0°C / s | D31: 803.6 kW | E31: 260°C | F31: 12.4 s
A32: Rotor ER | B32: 8.0°C / s | D32: 259.4 kW | E32: 180°C | F32: 22.6 s
E34: Hot Condition
B35: Hot Temp. | D35: Rise Limit | E35: Ambient | F35: Total | G35: Max.Time
A36: Stator Copper | B36: 68°C + | D36: 92°C + | E36: 40°C | F36: = 200°C | G36: 29.3 s
A37: Rotor Bar | B37: 91°C + | D37: 169°C + | E37: 40°C | F37: = 300°C | G37: 8.1 s
A38: Rotor ER | B38: 91°C + | D38: 89°C + | E38: 40°C | F38: = 220°C | G38: 11.2 s
A40: Cold Stall Time: | B40: 25.2 s | D40: Hot Stall Time: | F40: 12.5 s

Sheet Thermdam
A2: TOSHIBA INTERNATIONAL CORPORATION
A3: Thermal Limit & Acceleration Curves
A4: Design Values (For Reference Only)
A6: Model #: | B6: ='Performance Data Sheet'!C17 -> M303TCQL11F-C | E6: FLAmps: | F6: 187
A7: Enclosure: | B7: ='Performance Data Sheet'!F14 -> TEAAC | C7: Voltage: | D7: 4000 V | E7: Frame: | F7: ='Performance Data Sheet'!C14 -> 6810USS
A8: Pole: | B8: 2 | C8: Frequency: | D8: 3 PH / 60 Hz | E8: Ins. Class: | F8: ='Performance Data Sheet'!M15 -> F
A9: HP: | B9: 1500 | C9: Rotor Inertia: | D9: 424.1 lb-ft² | E9: Date: | F9: ='Performance Data Sheet'!K45 -> 41940
A10: FLRPM: | B10: 3581 | C10: Load Inertia: | D10: 451.0 lb-ft² | E10: File: | F10: BS2M30U
A39: Comments: | E39: D.E.Curve #: | F39: BS2M30U
C43: Prepared by: | D43: ='Performance Data Sheet'!K43 -> Mario L | E43: Checked by:
F50: =5252.1*B50/D53 -> #DIV/0!
D66: =D65/D64 -> #DIV/0!
A67: Current (%) | B67: Cold | C67: Hot | E67: CURRENT (%) | F67: Accel. Time
A68: 632.62032 | B68: 35 | C68: 15 | E68: =A68 -> 632.62032 | F68: 0.0001
A69: =FLOOR(A68,100) -> 600 | B69: =((A68/A69)^2)*B68 -> 38.909157 | C69: =((A68/A69)^2)*C68 -> 16.675353 | E69: 631.5508 | F69: 0.667
A70: =A69-100 -> 500 | B70: =((A68/A70)^2)*B68 -> 56.029186 | C70: =((A68/A70)^2)*C68 -> 24.012508 | E70: 629.19786 | F70: 1.244
A71: =A70-100 -> 400 | B71: =((A68/A71)^2)*B68 -> 87.545603 | C71: =((A68/A71)^2)*C68 -> 37.519544 | E71: 626.41711 | F71: 1.791
A72: =A71-100 -> 300 | B72: =((A68/A72)^2)*B68 -> 155.63663 | E72: 623.15508 | F72: 2.3380001
A73: =A72-100 -> 200 | B73: =((A68/A73)^2)*B68 -> 350.18241 | E73: 619.25134 | F73: 2.9090002
A74: 255 | B74: =((A68/A74)^2)*B68 -> 215.41402 | C74: =((A68/A74)^2)*C68 -> 92.320293 | E74: 614.59893 | F74: 3.5250001
A75: 180 | B75: =((A68/A75)^2)*B69 -> 480.61031 | C75: =((A68/A75)^2)*C68 -> 185.2817 | E75: 609.03743 | F75: 4.2140002
A76: 145 | B76: =((A68/A76)^2)*B68 -> 666.221 | C76: =((A68/A76)^2)*C68 -> 285.52328 | E76: 601.3369 | F76: 5.0280004
A77: 125 | C77: =CEILING(C76*2,100) -> 600 | E77: 592.03209 | F77: 5.4820004
A78: 125 | C78: =2*C77 -> 1200 | E78: 576.31016 | F78: 5.8830004
A79: 125 | C79: 10000 | E79: 523.52941 | F79: 6.0980005
E80: 320.96257 | F80: 6.1370006
E81: 0 | F81: 6.1950006

Sheet MagNoise
A1: Magnetic Noise Verification
A3: Rating: | B3: 2 Pole - 1500.0 HP - 3600 RPM - 4000 V - 60 Hz
A5: Electromagnetic Excitation Frequencies
B7: L = | C7: 0 | D7: L = | E7: + 1 | F7: L = | G7: - 1 | H7: Slip = | I7: 0 | J7: Slip = | K7: 0.005
A8: Mode A | B8: 6 | D8: 12 | F8: 0 | H8: 2880.0 Hz | J8: 2865.5 Hz
A9: Mode B | B9: 10 | D9: 16 | F9: 4 | H9: 2640.0 Hz | J9: 2625.5 Hz
A10: Mode C | B10: 8 | D10: 14 | F10: 2 | H10: 2760.0 Hz | J10: 2745.5 Hz
A12: Natural Frequencies of Stator Core
B14: Mode 0 = | D14: 1483.0 Hz | F14: Mode 6 = | H14: 4554.3 Hz
B15: Mode 2 = | D15: 354.0 Hz | F15: Mode 7 = | H15: 6268.4 Hz
B16: Mode 3 = | D16: 1001.2 Hz | F16: Mode 8 = | H16: 8246.6 Hz
B17: Mode 4 = | D17: 1919.7 Hz | F17: Mode 9 = | H17: 10488.8 Hz
B18: Mode 5 = | D18: 3104.5 Hz | F18: Mode 10 = | H18: 12995.0 Hz
A20: Analysis Results
B22: No matching frequencies detected.

Sheet Performance
A2: TOSHIBA INTERNATIONAL CORPORATION
A3: Performance Curve
A4: Design Values (For Reference Only)
A6: Model #: | B6: ='Performance Data Sheet'!C17 -> M303TCQL11F-C | E6: FLAmps: | F6: 187
A7: Enclosure: | B7: ='Performance Data Sheet'!F14 -> TEAAC | C7: Voltage: | D7: 4000 V | E7: Frame: | F7: ='Performance Data Sheet'!C14 -> 6810USS
A8: Pole: | B8: 2 | C8: Frequency: | D8: 3 PH / 60 Hz | E8: Ins. Class: | F8: ='Performance Data Sheet'!M15 -> F
A9: HP: | B9: 1500 | C9: Rotor Inertia: | D9: 424.1 lb-ft² | E9: Date: | F9: ='Performance Data Sheet'!K45 -> 41940
A10: FLRPM: | B10: 3581 | C10: Load Inertia: | D10: N/A | E10: File: | F10: BS2M30U
B12: Locked Rotor Amps: | C12: 1183 A | D12: Load Type: | E12: N/A
B13: Locked Rotor Torque: | C13: 0.95 | D13: Starting at: | E13: N/A
B14: Breakdown Torque: | C14: 2.55 | D14: Accel. Time: | E14: N/A
B15: Rated Torque: | C15: 2200 lb-ft
A39: Comments: | E39: D.E.Curve #: | F39: BS2M30U
C43: Prepared by: | D43: ='Performance Data Sheet'!K43 -> Mario L | E43: Checked by:
A53: Load | B53: Efficiency | C53: PF | D53: Amps | E53: RPM | F53: Input Watts
A54: 0 | D54: 44.032792 | E54: 100 | F54: 0.929
A55: 25 | B55: 88.730492 | C55: 68.121567 | D55: 66.806053 | E55: 84.615279 | F55: 7.8822164
A56: 50 | B56: 92.800056 | C56: 84.992737 | D56: 102.39372 | E56: 69.130834 | F56: 15.073115
A57: 75 | B57: 94.057198 | C57: 89.774216 | D57: 143.46664 | E57: 53.395529 | F57: 22.307478
A58: 100 | B58: 94.552177 | C58: 91.376884 | D58: 186.95 | E58: 37.59899 | F58: 29.587597
A59: 125 | B59: 94.734627 | C59: 91.828873 | D59: 232.08943 | E59: 21.487241 | F59: 36.913269
