Workbook
Name Print_Area_MI: 'Performance Data Sheet'!$A$10:$N$43

Sheet DesignSheet
A1: TOSHIBA INTERNATIONAL CORPORATION | I1: Calc. Code: | J1: 2-2-2-0-1-2
A2: 3-PHASE SQUIRREL CAGE INDUCTION MOTOR DESIGN SHEET | J2: B.L.-1 P.F.-1
A3: File: | B3: Z:\Motor R&D\Active Projects\6810 Development\Electrical Design\TEAAC\2P\Series\BS2M35U.rat | G3: Date: | H3: 41939 | I3: Time: | J3: 0.61385417
A4: Pole | B4: HP | C4: RPM | D4: Form | E4: Voltage | F4: Frequency | G4: Temperature | H4: FLSpeed | I4: FLSlip | J4: Frame
A5: 2 | B5: 1750 | C5: 3600 | D5: FCW4 | E5: 4000 | F5: 60 | G5: 105 | H5: 3581.0 / 3581.3 | I5: 0.0053 / 0.0052 | J5: 6810USS
A6: Core Data | D6: Winding Data | H6: Constant Data
B7: Primary | C7: Secondary | F7: Bar | G7: End Ring | H7: St. Slot Pitch | I7: 26.179917 | J7: LR Test Data
A8: Air Gap | B8: 3.5 | H8: Rt. Slot Pitch | I8: 30.254878 | J8: ES
A9: Space Fac. | B9: 0.93000001 | D9: Pitch | E9: 1 ~ 18 | F9: Cross Section Area | H9: Mean Value | I9: 28.217397 | J9: 587.46691
A10: Core Length | B10: 580 | C10: 580 | F10: UB: 322.1 | G10: UER: 3768.4 | H10: Eff.T.W.St. | I10: 17.127578 | J10: WS
A11: OD | B11: 815 | C11: 443 | D11: Coil Pitch | E11: 0.62956667 | H11: Eff.T.W.Rt. | I11: 29.859305 | J11: 43734.998
A12: ID | B12: 450 | C12: 170 | D12: Slot Fill | E12: - | F12: EBL: 62.5 | G12: ERD1: 328.0 | H12: St.Carter Fac. | I12: 1.5285241 | J12: IS
A13: Core Depth | B13: 109.5 | C13: 98.09 | D13: Con./Slot | E13: 16 | G13: ERT: 65.54 | H13: Rt.Carter Fac. | I13: 1.0132479 | J13: 208.35326
A14: Eff.Core L. | B14: 438.95999 | C14: 494.76001 | D14: Wire Size 1 | E14: (.102"x.258")x2 | G14: ERH: 57.50 | H14: Carter Factor | I14: 1.5487738 | J14: Volts / Turn
A15: Slot Data | D15: Wire Size 2 | E15: - | H15: Short. Factor | I15: 0.835433 | J15: 32.075955
A16: Number | B16: 54 | C16: 46 | D16: // Circuits | E16: 2 | H16: Distrib. Factor | I16: 0.95529271 | J16: AC
A17: Kind | B17: Open | C17: Trapeze | D17: Connection | E17: Wye | H17: Wind. Factor | I17: 0.79808305 | J17: 636.68119
A18: Skew | B18: - | C18: 0 | D18: MCL | E18: 1447 | F18: 770.537 | H18: Reactance | I18: (Coeff.: 0.0227)
A19: Depth | B19: 73 | C19: 38.41 | D19: No.Cond./Ph. | E19: 144 | I19: Running | J19: Start
A20: Width | B20: 17.30 - 17.30 | D20: Res. (20°C) | E20: 0.054438928 | H20: Stator Slot | I20: 14.993257 | J20: 14.993257
A21: Opening | B21: 17.299999 | C21: 3 | D21: (105°C) | E21: 0.072620888 | F21: 0.048831075 | G21: 0.0141285 | H21: Rotor Slot | I21: 16.318153 | J21: 13.797791
A22: Tip Depth | B22: 13.15 | C22: 3 | D22: Material | E22: CU | F22: CU | G22: CU | H22: Zigzag | I22: 4.6907854 | J22: 4.2877483
A23: T.Min.Wid. | B23: 8.8799171 | C23: 10.888422 | D23: Spec.Resist. | E23: 1.742 | F23: 1.742 | G23: 1.742 | H23: Coil End | I23: 31.036746 | J23: Skew R.: 0.00
A24: Low. R. | B24: 0 | C24: 0.80000001 | D24: Spec.Gravity | E24: 8.8900003 | F24: 8.8900003 | G24: 8.8900003 | H24: Belt Leakage | I24: 6.7857612 | J24: 6.202722
A25: Up. R. | B25: - | C25: 5.7199998 | D25: Weight (kg) | H25: Total Resist. | I25: 0.13558047 | J25: 0.33582056
A26: Wedge Dep. | B26: 0.80 - 2.40 | C26: Normal | D26: Wire 1 | E26: 370.53024 | F26: 110.141 | G26: 84.531503 | H26: Total React. | I26: 1.6723449 | J26: 1.5929139
A27: Duct | B27: 18 x 6 | C27: 8 x 6 | D27: Wire 2 | E27: - | F27: - | G27: - | H27: Impedance | I27: 1.6778319 | J27: 1.6279281
A28: Effective Depth (S=1) | D28: Magnetic Circuit Data | I28: Core Loss Data
B29: Res.= | C29: 35.359193 | E29: Length | F29: Section | G29: Density | H29: AT | I29: Volume | J29: Loss | M29: =RIGHT(F$41,SEARCH("/",F$41,1)-1) -> 3576.5 | N29: 125RPM
B30: Reac.= | C30: 35.395463 | D30: Primary Core | E30: 64.009896 | F30: 961.32238 | G30: 15.693804 | H30: 703.10113 | I30: 106533.35 | J30: 7843.8495 | M30: =RIGHT(E$41,SEARCH("/",E$41,1)-1) -> 3581.3 | N30: 100RPM
A31: Excitation Data | D31: Tooth | E31: 7.3 | F31: 1052.4407 | G31: 14.335065 | H31: 54.674367 | I31: 15365.634 | J31: 976.97145 | M31: =RIGHT(D$41,SEARCH("/",D$41,1)-1) -> 3586.1 | N31: 75RPM
A32: Excit.Amps | B32: 44.615 / 44.684 | D32: Second.Core | E32: 28.759686 | F32: 1250.9842 | G32: 12.059949 | H32: 119.22776 | I32: Total | J32: 8820.8209 | M32: =RIGHT(C$41,SEARCH("/",C$41,1)-1) -> 3590.8 | N32: 50RPM
A33: Core Loss | B33: 3.000 / 3.004 | C33: Flux / Pole | D33: Tooth | E33: 3.841 | F33: 1239.0458 | G33: 12.176148 | H33: 16.287219 | I33: C.L.C. | J33: 1.75 / 0.71 | M33: =RIGHT(B$41,SEARCH("/",B$41,1)-1) -> 3595.5 | N33: 25RPM
A34: NoLoad | B34: 44.72 / 44.78 | C34: 15.086805 | D34: Air Gap | E34: 0.35 | F34: 2291.1195 | G34: 6.5849054 | H34: 1834.037 | I34: S.F.C. | J34: 6.0500002
A35: Load Characteristics | D35: Temp. Rise @ 100%: | E35: 73 / 72 | G35: No Load Loss | H35: 30537.3 / 45369.9 | I35: W.Loss | J35: 15436.4 / 6287.2
A36: Load (%) | B36: 25 | C36: 50 | D36: 75 | E36: 100 | F36: 125 | G36: Primary Loss | H36: 9457.7 / 9552.4 | I36: S.Loss | J36: 5368.3 / 2186.5
A37: Current (A) | B37: 71.22 / 73.66 | C37: 112.47 / 116.32 | D37: 159.24 / 164.69 | E37: 208.35 / 215.49 | F37: 259.26 / 268.13 | G37: Second. Loss | H37: 7053.4 / 6692.2 | I37: Total C.Loss | J37: 20804.7 / 8473.7
A38: Efficiency | B38: 0.911 / 0.896 | C38: 0.950 / 0.934 | D38: 0.961 / 0.945 | E38: 0.966 / 0.950 | F38: 0.967 / 0.951 | G38: Frict.& Wind. | H38: 9407.5 / 29347 | I38: Stray Loss | J38: 15363.762 | L38: =LEFT(E38,SEARCH("/",E38,1)-1) -> 0.966 | M38: =RIGHT(E38,SEARCH("/",E38,1)-1) -> 0.950 | N38: =M38/L38 -> 0.98343685 | O38: Eff.
A39: P.F. | B39: 0.726 / 0.714 | C39: 0.882 / 0.868 | D39: 0.923 / 0.908 | E39: 0.936 / 0.921 | F39: 0.939 / 0.924 | G39: Starting Data | I39: Slip | J39: PF | L39: =LEFT(E39,SEARCH("/",E39,1)-1) -> 0.936 | M39: =RIGHT(E39,SEARCH("/",E39,1)-1) -> 0.921 | N39: =M39/L39 -> 0.98397436 | O39: PF.
A40: Slip | B40: 0.0013 / 0.0013 | C40: 0.0026 / 0.0026 | D40: 0.0039 / 0.0039 | E40: 0.0053 / 0.0052 | F40: 0.0066 / 0.0065 | G40: LRA | H40: 1418.7 / 1377.5 | L40: =LEFT(E37,SEARCH("/",E37,1)-1) -> 208.35 | M40: =RIGHT(E37,SEARCH("/",E37,1)-1) -> 215.49 | N40: =M40/L40 -> 1.0342693 | O40: Current
...

Sheet Data Sheet
A1: TOSHIBA INTERNATIONAL CORPORATION
A2: INDUCTION MOTOR DATA SHEET
A3: File: | B3: BS2M35U | I3: HRW / Model Number: | J3: M353TCQL11F-C
A4: Type: TIKE - Form: FCW4 - 2 Pole - 1750 HP - 4000 V - 60 Hz - 6810USS - Class F | Q4: Motor Type Selection | T4: Electrical Steel Table
A5: Motor Parameters | F5: PERFORMANCE | J5: DESIGN | K5: TEST | Q5: EPACT | T5: M22 - 26Ga.
A6: Material | D6: M36 - 26Ga. | F6: NL & Impedance Test | Q6: EQP-III | T6: M36 - 26Ga.
A7: Air Gap | D7: 3.5 | F7: No load amps | J7: 45 | K7: - | Q7: Exp.Prf. | T7: NCB1 - 26Ga.
A8: Stack length | D8: 580 | F8: No load watts | J8: 38160 | K8: - | Q8: Exp.Prf.-EQPIII | T8: M43 - 26Ga.
A9: Number of turns per coil | D9: 8 | F9: Impedance amps | H9: 3 | I9: f | J9: 398 | K9: - | Q9: Prem. Eff. | T9: M45 - 26Ga.
A10: Wire 1 (size & number) | D10: (.102"x.258")x2 | F10: Impedance volts | H10: 3 | I10: f | J10: 1150 | K10: - | Q10: OWP | T10: M54 - 26Ga.
A11: Wire 2 (size & number) | D11: - | F11: Impedance watts | H11: 3 | I11: f | J11: 120588 | K11: - | Q11: Dry Kiln
A12: Slot fill - circle/square method (%) | D12: - | F12: Temperature Rise (°C) | L12: RTD
A13: Connection | D13: 2 x Wye | G13: Winding | I13: 80/115 | J13: 72 / 96 | K13: - | L13: 79.6 / 110.1
A14: MCL | D14: 1447 | G14: Frame | J14: - | K14: -
A15: Allowance for ins. depth | D15: 15.197201 | G15: Bearing PS/OS | J15: - | K15: -
A16: Allowance for ins. width | D16: 3.7935991 | G16: End Ring | J16: - | K16: -
A17: Slot/Wire arrangement | D17: 16 x 2 | F17: Nameplate Data
A18: Effective cross section for coil | D18: - | H18: FLC (A) | J18: 215 | M18: =J18*6.5 -> 1397.5
A19: Coil grouping | D19: - | H19: RPM | J19: 3581
A20: Coil pitch (slot number) | D20: 1 ~ 18 | H20: CODE | J20: F
A21: Method of coil connection | D21: - | H21: S. F. | J21: 1.15 | Q21: Method of Connection
A22: Resistance per phase @ 20 °C | D22: 0.05575 | H22: DESIGN | J22: - | Q22: Skip
A23: Coil Weight | B23: Wire1 | D23: 832 | H23: Nom.Eff. (%): | Q23: Adjacent
A24: (lbs.) | B24: Wire2 | D24: - | H24: Min.Eff. (%): | Q24: -
A25: Current Densities (A/cm2) | E25: Bar / ER | H25: P.F. (%): | J25: -
A26: FL / LR | D26: 323 / 2070 | E26: 465 / 291
A27: Stator Slot Shape (Reference) | F27: Performance
H28: LRC (A) | I28: - | J28: 1378 | K28: - | M28: =(J28/J18)*100 -> 640.93023
H29: LRT (%) | I29: 60 | J29: 99 | K29: -
H30: BDT (%) | I30: 175 | J30: 255 | K30: -
H31: SLIP (%) | J31: 0.52 | K31: -
G32: IEEE-B | H32: Eff. (%) | J32: 95 | K32: - | V32: 78.9 | W32: 58 | X32: 53.2
A33: Rotor Slot Shape (Reference) | H33: PF (%) | J33: 92.1 | K33: - | V33: 25.3 | W33: 24.3 | X33: 24.3
F34: Losses (Watts) | H34: Primary | J34: 9552 | K34: - | V34: =V32-V33 -> 53.6 | W34: =W32-W33 -> 33.7 | X34: =X32-X33 -> 28.9
H35: Secondary | J35: 6692 | K35: - | U35: 52.8 | V35: =V34+W34-X34 -> 58.4 | Y35: =V35/U35*72 -> 79.636364
H36: Core | J36: 8474 | K36: -
H37: F & W | J37: 29347 | K37: -
H38: Stray | J38: 15364 | K38: - | V38: 90.8 | W38: 58 | X38: 53.2
A39: End Ring (Reference) | F39: Note | V39: 26.8 | W39: 24.3 | X39: 24.3
F40: LINK: | G40: P148450.rat with P148450_TEAAC_CStubes_Lab1317.dat | V40: =V38-V39 -> 64 | W40: =W38-W39 -> 33.7 | X40: =X38-X39 -> 28.9
...

Sheet LoginSheet
J1: P | K1: T | L1: L | M1: T
B2: PROJECT HISTORY | J2: E | K2: D | L2: I | M2: Y | N2: H
J3: R | L3: M | M3: P
J4: F | L4: I | M4: E
K5: C | L5: T | N5: I
J6: D | K6: U | M6: T | N6: N
J7: A | K7: R | L7: R | M7: E | N7: S
I8: S | J8: T | K8: V | L8: E | M8: S | N8: U
B9: DATE | C9: PROJECT | D9: SMART NUMBER | E9: QTY | F9: CUSTOMER | G9: REMARKS | H9: LIMIT CODE | I9: F | J9: A | K9: E | L9: V | M9: T | N9: L
B53: REVISION HISTORY
B54: REV | C54: REMARKS | I54: DATE | L54: INIT

Sheet Form
A1: Winding Data Calculation
C2: MCL: 1447.0
A3: Coil Resistance | D3: Lead Resistance
A4: 8T: | B4: 0.0124 ~ 0.0119 | D4: AWG. (02 x 2) x 3
D5: 0.00104
A6: Coil Dimensions
A7: HM: | B7: 8T: 22.33 | C7: WM: | D7: 8T: 13.51 | E7: WT:
E8: 17.40 ~ 17.00
A9: Insulation Allowance | D9: Wire Weight
A10: Depth: | B10: 15.20 | D10: (.102"x.258")x 2: | F10: 832 lbs.
A11: Width: | B11: 3.79
A12: QC Resistance
A13: 1-2, 2-3, 3-1: | C13: 0.115 ~ 0.108

Sheet STCurve
A2: TOSHIBA INTERNATIONAL CORPORATION
A3: Speed Torque/Current Curve
A6: Model #: | B6: ='Performance Data Sheet'!C17 -> M353TCQL11F-C | E6: FLAmps: | F6: 215
A7: Enclosure: | B7: ='Performance Data Sheet'!F14 -> TEAAC | C7: Voltage: | D7: 4000 V | E7: Frame: | F7: ='Performance Data Sheet'!C14 -> 6810USS
A8: Pole: | B8: 2 | C8: Frequency: | D8: 3 PH / 60 Hz | E8: Ins. Class: | F8: ='Performance Data Sheet'!M15 -> F
A9: HP: | B9: 1750 | C9: Rotor Inertia: | D9: 486.2 lb-ft² | E9: Date: | F9: ='Performance Data Sheet'!K45 -> 41939
A10: FLRPM: | B10: 3581 | C10: Load Inertia: | D10: N/A | E10: File: | F10: BS2M35U
B12: Locked Rotor Amps: | C12: 1378 A | D12: Load Type: | E12: N/A
B13: Locked Rotor Torque: | C13: 0.95 | D13: Starting at: | E13: N/A
B14: Breakdown Torque: | C14: 2.55 | D14: Accel. Time: | E14: N/A
B15: Rated Torque: | C15: 2567 lb-ft
A39: Comments: | E39: D.E.Curve #: | F39: BS2M35U
C43: Prepared by: | D43: ='Performance Data Sheet'!K43 -> Mario L | E43: Checked by:
A54: 100 | B54: 0 | C54: 0.20798191
A55: 99.8 | B55: 131.92268 | C55: 161.77812
A56: 99 | B56: 255 | C56: 487.48929
A57: 93.789474 | B57: 151.6889 | C57: 571.58704
A58: 88.578947 | B58: 123.46739 | C58: 593.9281
A59: 83.368421 | B59: 111.21422 | C59: 603.34381
A60: 72.947368 | B60: 103.72421 | C60: 612.83069
A61: 62.526315 | B61: 100.14098 | C61: 619.19537
A62: 52.105263 | B62: 98.000323 | C62: 624.47742
A63: 41.68421 | B63: 96.678291 | C63: 628.95129
A64: 31.263161 | B64: 95.877673 | C64: 632.72186
A65: 20.842105 | B65: 95.407744 | C65: 635.90222
... A67: 0 | B67: 95 | C67: 640.93024

Sheet StallTime
A1: Rating: | B1: 2 Pole - 1750.0 HP - 3600 RPM - 4000 V - 60 Hz
A3: Starting Performance
D4: Load Type: Fan / Pump - 502.0 lb-ft²
A5: RPM | B5: Motor | C5: Load | D5: Accel. | E5: Line | F5: Stator | G5: Rotor
A6: Speed Increment | B6: Torque (%) | C6: Torque (%) | D6: Time (s) | E6: Amps | F6: kW / s | G6: kW / s
A7: 0~375 | B7: 95.1 | C7: 22.4 | D7: 0.646 | E7: 1375.5 | F7: 267.1 | G7: 976.5
A8: 375~750 | B8: 95.3 | C8: 11.3 | D8: 0.559 | E8: 1370.1 | F8: 229.5 | G8: 758.2
A9: 750~1125 | B9: 95.6 | C9: 7.0 | D9: 0.530 | E9: 1363.8 | F9: 215.7 | G9: 637.0
A10: 1125~1501 | B10: 96.3 | C10: 7.6 | D10: 0.530 | E10: 1356.3 | F10: 213.6 | G10: 555.8
A11: 1501~1876 | B11: 97.3 | C11: 12.3 | D11: 0.552 | E11: 1347.4 | F11: 220.0 | G11: 495.7
A12: 1876~2251 | B12: 99.1 | C12: 20.2 | D12: 0.596 | E12: 1336.9 | F12: 233.9 | G12: 445.1
A13: 2251~2626 | B13: 101.9 | C13: 31.4 | D13: 0.666 | E13: 1324.4 | F13: 257.0 | G13: 397.8
A14: 2626~3001 | B14: 107.5 | C14: 47.7 | D14: 0.785 | E14: 1307.4 | F14: 296.8 | G14: 350.6
A15: 3001~3189 | B15: 117.3 | C15: 63.9 | D15: 0.439 | E15: 1287.1 | F15: 160.8 | G15: 258.4
A16: 3189~3376 | B16: 137.6 | C16: 77.1 | D16: 0.388 | E16: 1252.9 | F16: 137.8 | G16: 174.2
... A19: 3593~3600 | B19: 116.0 | C19: 99.8 | D19: 0.056 | E19: 222.0 | F19: 0.6 | G19: 32.1
D21: Acceleration Time: 6.0 s
B22: Energy | D22: First Start | F22: Second Start
A23: Stator Winding Rise | B23: 2311 kW / s | D23: 16°C | F23: 32°C
A24: Rotor Bar Rise | B24: 4005 kW / s | D24: 94°C | F24: 189°C
A25: End Ring Rise | B25: 1159 kW / s | D25: 36°C | F25: 71°C
A27: Locked Rotor Thermal Capability
E28: Cold Condition
B29: Rate of Rise | D29: Power | E29: Rise Limit | F29: Max Time
A30: Stator Copper | B30: 3.4°C / s | D30: 488.6 kW | E30: 160°C | F30: 46.7 s
A31: Rotor Bar | B31: 22.7°C / s | D31: 961.9 kW | E31: 260°C | F31: 11.5 s
A32: Rotor ER | B32: 8.6°C / s | D32: 278.3 kW | E32: 180°C | F32: 21.0 s
E34: Hot Condition
B35: Hot Temp. | D35: Rise Limit | E35: Ambient | F35: Total | G35: Max.Time
A36: Stator Copper | B36: 72°C + | D36: 88°C + | E36: 40°C | F36: = 200°C | G36: 25.7 s
A37: Rotor Bar | B37: 97°C + | D37: 163°C + | E37: 40°C | F37: = 300°C | G37: 7.2 s
A38: Rotor ER | B38: 97°C + | D38: 83°C + | E38: 40°C | F38: = 220°C | G38: 9.7 s
A40: Cold Stall Time: | B40: 22.6 s | D40: Hot Stall Time: | F40: 10.5 s

Sheet StallTime (2)
A1: Rating: | B1: 2 Pole - 1750.0 HP - 3600 RPM - 4000 V - 60 Hz
A3: Starting Performance
D4: Load Type: Fan / Pump - 335.0 lb-ft²
A5: RPM | B5: Motor | C5: Load | D5: Accel. | E5: Line | F5: Stator | G5: Rotor
A6: Speed Increment | B6: Torque (%) | C6: Torque (%) | D6: Time (s) | E6: Amps | F6: KJoule | G6: KJoule
A7: 0~375 | B7: 95.099998 | C7: 22.4 | D7: 0.53600001 | E7: 1378.6 | F7: 222.89999 | G7: 865.90002
A8: 375~750 | B8: 95.300003 | C8: 11.3 | D8: 0.46399999 | E8: 1373.2 | F8: 191.60001 | G8: 672.29999
A9: 750~1125 | B9: 95.599998 | C9: 7.0999999 | D9: 0.44 | E9: 1366.9 | F9: 180.10001 | G9: 564.79999
A10: 1125~1501 | B10: 96.300003 | C10: 7.6999998 | D10: 0.44100001 | E10: 1359.4 | F10: 178.8 | G10: 492.89999
A11: 1501~1876 | B11: 97.300003 | C11: 12.4 | D11: 0.45899999 | E11: 1350.5 | F11: 183.60001 | G11: 439.5
A12: 1876~2251 | B12: 99.099998 | C12: 20.299999 | D12: 0.495 | E12: 1340 | F12: 195.3 | G12: 394.70001
A13: 2251~2626 | B13: 101.9 | C13: 31.4 | D13: 0.55299997 | E13: 1327.4 | F13: 214.60001 | G13: 352.70001
A14: 2626~3001 | B14: 107.5 | C14: 47.700001 | D14: 0.65200001 | E14: 1310.4 | F14: 247.8 | G14: 310.89999
A15: 3001~3189 | B15: 117.3 | C15: 63.900002 | D15: 0.36500001 | E15: 1290 | F15: 134.60001 | G15: 229.10001
A16: 3189~3376 | B16: 137.60001 | C16: 77.099998 | D16: 0.32100001 | E16: 1255.8 | F16: 114.7 | G16: 154.39999
A17: 3376~3564 | B17: 203.3 | C17: 91 | D17: 0.17399999 | E17: 1141.1 | F17: 57.5 | G17: 55.5
A18: 3564~3593 | B18: 193.5 | C18: 98.800003 | D18: 0.032000002 | E18: 699.59998 | F18: 7.6999998 | G18: 17.799999
A19: 3593~3600 | B19: 116 | C19: 99.800003 | D19: 0.045000002 | E19: 174.5 | F19: 0.5 | G19: 28.5
D21: Acceleration Time: 5 s
B22: Energy | D22: First Start | F22: Second Start
A23: Stator Winding Rise | B23: 1930 KJoule | D23: 14°C | F23: 28°C
A24: Rotor Bar Rise | B24: 3551 KJoule | D24: 84°C | F24: 168°C
A25: End Ring Rise | B25: 1028 KJoule | D25: 32°C | F25: 64°C
A27: Locked Rotor Thermal Capability
E28: Cold Condition
B29: Rate of Rise | D29: Power | E29: Rise Limit | F29: Max Time
A30: Stator Copper | B30: 3.5°C / s | D30: 492.5 kW | E30: 160°C | F30: 46.4 s
A31: Rotor Bar | B31: 22.7°C / s | D31: 961.5 kW | E31: 260°C | F31: 11.5 s
A32: Rotor ER | B32: 8.5°C / s | D32: 278.2 kW | E32: 180°C | F32: 21.1 s
E34: Hot Condition
B35: Hot Temp. | D35: Rise Limit | E35: Ambient | F35: Total | G35: Max.Time
A36: Stator Copper | B36: 73°C + | D36: 87°C + | E36: 40°C | F36: = 200°C | G36: 25.2 s
A37: Rotor Bar | B37: 98°C + | D37: 162°C + | E37: 40°C | F37: = 300°C | G37: 7.1 s
A38: Rotor ER | B38: 98°C + | D38: 82°C + | E38: 40°C | F38: = 220°C | G38: 9.6 s
A40: Cold Stall Time: | B40: 22.6 s | D40: Hot Stall Time: | F40: 10.3 s

Sheet Thermdam
A2: TOSHIBA INTERNATIONAL CORPORATION
A3: Thermal Limit & Acceleration Curves
A4: Design Values (For Reference Only)
A6: Model #: | B6: ='Performance Data Sheet'!C17 -> M353TCQL11F-C | E6: FLAmps: | F6: 215
A7: Enclosure: | B7: ='Performance Data Sheet'!F14 -> TEAAC | C7: Voltage: | D7: 4000 V | E7: Frame: | F7: ='Performance Data Sheet'!C14 -> 6810USS
A8: Pole: | B8: 2 | C8: Frequency: | D8: 3 PH / 60 Hz | E8: Ins. Class: | F8: ='Performance Data Sheet'!M15 -> F
A9: HP: | B9: 1750 | C9: Rotor Inertia: | D9: 486.2 lb-ft² | E9: Date: | F9: ='Performance Data Sheet'!K45 -> 41939
A10: FLRPM: | B10: 3581 | C10: Load Inertia: | D10: 502.0 lb-ft² | E10: File: | F10: BS2M35U
A39: Comments: | E39: D.E.Curve #: | F39: BS2M35U
C43: Prepared by: | D43: ='Performance Data Sheet'!K43 -> Mario L | E43: Checked by:
F50: =5252.1*B50/D53 -> #DIV/0!
D66: =D65/D64 -> #DIV/0!
A67: Current (%) | B67: Cold | C67: Hot | E67: CURRENT (%) | F67: Accel. Time
A68: 640.93023 | B68: 32.342249 | C68: 14.947023 | E68: =A68 -> 640.93023 | F68: 0.0001
A69: =FLOOR(A68,100) -> 600 | B69: =((A68/A69)^2)*B68 -> 36.905341 | C69: =((A68/A69)^2)*C68 -> 17.055864 | E69: 639.76744 | F69: 0.64600003
A70: =A69-100 -> 500 | B70: =((A68/A70)^2)*B68 -> 53.143691 | C70: =((A68/A70)^2)*C68 -> 24.560444 | E70: 637.25581 | F70: 1.205
A71: =A70-100 -> 400 | B71: =((A68/A71)^2)*B68 -> 83.037018 | C71: =((A68/A71)^2)*C68 -> 38.375694 | E71: 634.32558 | F71: 1.735
A72: =A71-100 -> 300 | B72: =((A68/A72)^2)*B68 -> 147.62137 | E72: 630.83721 | F72: 2.2650001
A73: =A72-100 -> 200 | B73: =((A68/A73)^2)*B68 -> 332.14807 | E73: 626.69767 | F73: 2.8170002
A74: 255 | B74: =((A68/A74)^2)*B68 -> 204.32023 | C74: =((A68/A74)^2)*C68 -> 94.42693 | E74: 621.81395 | F74: 3.4130001
A75: 180 | B75: =((A68/A75)^2)*B69 -> 467.91367 | C75: =((A68/A75)^2)*C68 -> 189.5096 | E75: 616 | F75: 4.079
A76: 145 | B76: =((A68/A76)^2)*B68 -> 631.91072 | C76: =((A68/A76)^2)*C68 -> 292.03858 | E76: 608.09302 | F76: 4.8639998
A77: 125 | C77: =CEILING(C76*2,100) -> 600 | E77: 598.65116 | F77: 5.303
A78: 125 | C78: =2*C77 -> 1200 | E78: 582.74419 | F78: 5.691
A79: 125 | C79: 10000 | E79: 529.53488 | F79: 5.9000001
E80: 324.65116 | F80: 5.9380002
E81: 0 | F81: 5.9940004

Sheet MagNoise
A1: Magnetic Noise Verification
A3: Rating: | B3: 2 Pole - 1750.0 HP - 3600 RPM - 4000 V - 60 Hz
A5: Electromagnetic Excitation Frequencies
B7: L = | C7: 0 | D7: L = | E7: + 1 | F7: L = | G7: - 1 | H7: Slip = | I7: 0 | J7: Slip = | K7: 0.005
A8: Mode A | B8: 6 | D8: 12 | F8: 0 | H8: 2880.0 Hz | J8: 2865.5 Hz
A9: Mode B | B9: 10 | D9: 16 | F9: 4 | H9: 2640.0 Hz | J9: 2625.5 Hz
A10: Mode C | B10: 8 | D10: 14 | F10: 2 | H10: 2760.0 Hz | J10: 2745.5 Hz
A12: Natural Frequencies of Stator Core
B14: Mode 0 = | D14: 1483.0 Hz | F14: Mode 6 = | H14: 4554.3 Hz
B15: Mode 2 = | D15: 354.0 Hz | F15: Mode 7 = | H15: 6268.4 Hz
B16: Mode 3 = | D16: 1001.2 Hz | F16: Mode 8 = | H16: 8246.6 Hz
B17: Mode 4 = | D17: 1919.7 Hz | F17: Mode 9 = | H17: 10488.8 Hz
B18: Mode 5 = | D18: 3104.5 Hz | F18: Mode 10 = | H18: 12995.0 Hz
A20: Analysis Results
B22: No matching frequencies detected.

Sheet Performance
A2: TOSHIBA INTERNATIONAL CORPORATION
A3: Performance Curve
A4: Design Values (For Reference Only)
A6: Model #: | B6: ='Performance Data Sheet'!C17 -> M353TCQL11F-C | E6: FLAmps: | F6: 215
A7: Enclosure: | B7: ='Performance Data Sheet'!F14 -> TEAAC | C7: Voltage: | D7: 4000 V | E7: Frame: | F7: ='Performance Data Sheet'!C14 -> 6810USS
A8: Pole: | B8: 2 | C8: Frequency: | D8: 3 PH / 60 Hz | E8: Ins. Class: | F8: ='Performance Data Sheet'!M15 -> F
A9: HP: | B9: 1750 | C9: Rotor Inertia: | D9: 486.2 lb-ft² | E9: Date: | F9: ='Performance Data Sheet'!K45 -> 41939
A10: FLRPM: | B10: 3581 | C10: Load Inertia: | D10: N/A | E10: File: | F10: BS2M35U
B12: Locked Rotor Amps: | C12: 1378 A | D12: Load Type: | E12: N/A
B13: Locked Rotor Torque: | C13: 0.95 | D13: Starting at: | E13: N/A
B14: Breakdown Torque: | C14: 2.55 | D14: Accel. Time: | E14: N/A
B15: Rated Torque: | C15: 2567 lb-ft
A39: Comments: | E39: D.E.Curve #: | F39: BS2M35U
C43: Prepared by: | D43: ='Performance Data Sheet'!K43 -> Mario L | E43: Checked by:
A53: Load | B53: Efficiency | C53: PF | D53: Amps | E53: RPM | F53: Input Watts
A54: 0 | D54: 46.248497 | E54: 100 | F54: 0.962773
A55: 25 | B55: 89.628542 | C55: 71.410858 | D55: 73.664772 | E55: 84.999474 | F55: 9.1111247
A56: 50 | B56: 94.287804 | C56: 86.803482 | D56: 116.31978 | E56: 69.459091 | F56: 17.487938
A57: 75 | B57: 94.524644 | C57: 90.851425 | D57: 164.69853 | E57: 53.795413 | F57: 25.916084
A58: 100 | B58: 95 | C58: 92.147736 | D58: 215.49336 | E58: 37.782647 | F58: 34.392712
A59: 125 | B59: 95.117357 | C59: 92.425125 | D59: 268.14062 | E59: 21.730795 | F59: 42.924039

Sheet Performance Data Sheet
A1: TOSHIBA INTERNATIONAL CORPORATION | J1: INDEX | L1: MPCF-1033
A2: Industrial Division / Houston Motor Plant | J2: SHEET NO. | L2: 1 of 1
J3: ISSUED | L3: 11/08/96
J4: SUPERSEDES | L4: 10/06/95
J5: REVISION | L5: 1
A6: SQUIRREL CAGE INDUCTION MOTOR | J6: WRITTEN BY | L6: R. EVANS
A7: PERFORMANCE SPECIFICATIONS | J7: APPROVED BY | L7: Jay Bugbee
B9: CUSTOMER:
B10: TIC SR No.:
A12: MOTOR NAMEPLATE DATA
B13: H.P.: | C13: 1750 | E13: VOLTS: | F13: 4000 | H13: 3 PH / | I13: 60 Hz | L13: S. RPM: | M13: 3600
B14: FRAME: | C14: 6810USS | E14: ENCL: | F14: TEAAC | H14: FLAMPS: | I14: 215 | L14: FLRPM: | M14: 3581
B15: FORM: | C15: FCW4 | E15: S.F.: | F15: 1.15 | H15: NEMA DESIGN: | I15: - | L15: INSUL CLASS: | M15: F
B16: TYPE: | C16: TIKE | E16: AMB.: | F16: 40°C | H16: CODE: | I16: F | L16: DUTY: | M16: Cont.
B17: MODEL No.: | C17: M353TCQL11F-C | H17: kW:
B18: NOM. EFF.: | C18: - | E18: MIN. EFF.: | F18: - | H18: P.F.: | I18: -
A21: AMPERAGE | E21: TORQUES | I21: **BEARINGS:
C22: LOCKED ROTOR: | D22: 1378 | G22: FULL LOAD (lb-ft.): | H22: 2567 | K22: DRIVE END: | L22: M9-90 INS
G23: LOCKED ROTOR (%): | H23: 95 | K23: OPPOSITE DRIVE END: | L23: M9-90 INS
G24: BREAK DOWN (%): | H24: 255
A28: EFFICIENCY | H28: POWER FACTOR
C29: FULL LOAD: | D29: 95 | J29: FULL LOAD: | K29: 92.1
C30: 3/4 LOAD: | D30: 94.5 | J30: 3/4 LOAD: | K30: 90.9
C31: 1/2 LOAD: | D31: 93.4 | J31: 1/2 LOAD: | K31: 86.8
A35: ALL CHARACTERISTICS ARE AVERAGE EXPECTED VALUES BASED UPON RATED VOLTAGE,
A36: FREQUENCY AND SINEWAVE POWER INPUT.
A37: THE DECLARED LOCKED ROTOR CURRENT HAS A TOLERANCE OF 20%.
A38: * TEMPERATURE RISE WILL BE CONSISTENT WITH INSULATION, AMBIENT AND SERVICE FACTOR AS
A39: DEFINED BY NEMA-MG-12 OR -20.
A40: ** BEARINGS ARE THE ONLY RECOMMENDED SPARE PART(S).
J43: CERTIFIED BY: | K43: Mario L
J45: DATE: | K45: 41939
A60: - | B60: M9-90 INS | D60: 1 | E60: -
A61: TEFC | B61: 6206UU | D61: 1.15 | E61: A
A62: ODP | B62: 6207ZZ | E62: B
B63: 6208UU
B64: 6211ZZ
B65: 6211C3
B66: 6211ZZC3
B67: 6305UUC3
...
