Workbook
Name Print_Area_MI: 'Circuit Param'!$A$8:$N$43
Name Print_Area_MI: 'Performance API'!$A$10:$N$18
Name Print_Area_MI: 'Performance Data Sheet'!$A$10:$N$42
Name thermal: #REF!
Name transfer: #REF!
Name unit_sht: "unit_sht"
Name vassvelo: #REF!
Name velcoity: #REF!
Name viscosity: #REF!
Name vollheatre: #REF!
Name volumetri: #REF!
Name weight: #REF!
Name weights: #REF!

Sheet DesignSheet 80%V
A1: TOSHIBA INTERNATIONAL CORPORATION | I1: Calc. Code: | J1: 2-2-2-0-1-2
A2: 3-PHASE SQUIRREL CAGE INDUCTION MOTOR DESIGN SHEET | J2: B.L.-1 P.F.-1
A3: File: | B3: N:\DESPRO\RAT FILES\BS2M20U.rat | G3: Date: | H3: 45512 | I3: Time: | J3: 0.5577662
A4: Pole | B4: HP | C4: RPM | D4: Form | E4: Voltage | F4: Frequency | G4: Temperature | H4: FLSpeed | I4: FLSlip | J4: Frame
A5: 2 | B5: 1000 | C5: 3600 | D5: FCKNW | E5: 3200 | F5: 60 | G5: 105 | H5: 3569.1 / 3568.5 | I5: 0.0086 / 0.0088 | J5: 5811/12UDZ
A6: Core Data | D6: Winding Data | H6: Constant Data
B7: Primary | C7: Secondary | F7: Bar | G7: End Ring | H7: St. Slot Pitch | I7: 24.543672 | J7: LR Test Data
A8: Air Gap | B8: 3.3 | H8: Rt. Slot Pitch | I8: 30.456888 | J8: ES
A9: Space Fac. | B9: 0.93000001 | D9: Pitch | E9: 1 ~ 16 | F9: Cross Section Area | H9: Mean Value | I9: 27.50028 | J9: 770.41975
A10: Core Length | B10: 510 | C10: 510 | F10: UB: 304.0 | G10: UER: 1750.0 | H10: Eff.T.W.St. | I10: 14.338923 | J10: WS
A11: OD | B11: 670 | C11: 368.4 | D11: Coil Pitch | E11: 0.6249375 | H11: Eff.T.W.Rt. | I11: 30.038757 | J11: 45278.502
A12: ID | B12: 375 | C12: 185 | D12: Slot Fill | E12: - | F12: EBL: 50.0 | G12: ERD1: 281.0 | H12: St.Carter Fac. | I12: 1.1789163 | J12: IS
A13: Core Depth | B13: 85 | C13: 55.29 | D13: Con./Slot | E13: 24 | G13: ERT: 70.00 | H13: Rt.Carter Fac. | I13: 1.0139197 | J13: 150.81253
A14: Eff.Core L. | B14: 409.20001 | C14: 409.20001 | D14: Wire Size 1 | E14: (.072"x.204")x2 | G14: ERH: 25.00 | H14: Carter Factor | I14: 1.1953266 | J14: Volts / Turn
A15: Slot Data | D15: Wire Size 2 | E15: - | H15: Short. Factor | I15: 0.8314146 | J15: 19.245574
A16: Number | B16: 48 | C16: 38 | D16: // Circuits | E16: 2 | H16: Distrib. Factor | I16: 0.95543647 | J16: AC
A17: Kind | B17: Open | C17: Trapeze | D17: Connection | E17: Wye | H17: Wind. Factor | I17: 0.79436384 | J17: 737.35926
A18: Skew | B18: - | C18: 0 | D18: MCL | E18: 1225 | F18: 680 | H18: Reactance | I18: (Coeff.: 0.0418)
A19: Depth | B19: 62.5 | C19: 36.41 | D19: No.Cond./Ph. | E19: 192 | I19: Running | J19: Start
A20: Width | B20: 10.20 - 10.20 | D20: Res. (20°C) | E20: 0.11173631 | H20: Stator Slot | I20: 18.533136 | J20: 18.533136
A21: Opening | B21: 14.5 | C21: 3 | D21: (105°C) | E21: 0.14905492 | F21: 0.097229064 | G21: 0.012153707 | H21: Rotor Slot | I21: 16.804136 | J21: 14.805407
A22: Tip Depth | B22: 2.8299999 | C22: 3 | D22: Material | E22: CU | F22: CU | G22: CU | H22: Zigzag | I22: 4.1274877 | J22: 4.020915
A23: T.Min.Wid. | B23: 10.043672 | C23: 10.31661 | D23: Spec.Resist. | E23: 1.742 | F23: 1.742 | G23: 1.742 | H23: Coil End | I23: 24.366604 | J23: Skew R.: 0.00
A24: Low. R. | B24: 0 | C24: 0.80000001 | D24: Spec.Gravity | E24: 8.8900003 | F24: 8.8900003 | G24: 8.8900003 | H24: Belt Leakage | I24: 7.1922227 | J24: 7.0065178
A25: Up. R. | B25: - | C25: 4.7199998 | D25: Weight (kg) | H25: Total Resist. | I25: 0.25843769 | J25: 0.66358405
A26: Wedge Dep. | B26: 2.83 - 2.00 | C26: Magnetic | D26: Wire 1 | E26: 230.01252 | F26: 77.022963 | G26: 26.449351 | H26: Total React. | I26: 2.969631 | J26: 2.8738396
A27: Duct | B27: 7 x 10 | C27: 7 x 10 | D27: Wire 2 | E27: - | F27: - | G27: - | H27: Impedance | I27: 2.9808552 | J27: 2.9494572
A28: Effective Depth (S=1) | D28: Magnetic Circuit Data | I28: Core Loss Data
B29: Res.= | C29: 33.371993 | E29: Length | F29: Section | G29: Density | H29: AT | I29: Volume | J29: Loss | M29: =RIGHT(F$41,SEARCH("/",F$41,1)-1) -> 3560.5 | N29: 125RPM | P29: Kline/in2
B30: Reac.= | C30: 33.399129 | D30: Primary Core | E30: 52.621633 | F30: 695.64002 | G30: 13.073522 | H30: 276.13701 | I30: 63923.41 | J30: 3500.9017 | M30: =RIGHT(E$41,SEARCH("/",E$41,1)-1) -> 3568.5 | N30: 100RPM | P30: =G30*6.4516 -> 84.345137
A31: Excitation Data | D31: Tooth | E31: 6.25 | F31: 986.36893 | G31: 9.2201459 | H31: 11.703853 | I31: 12329.612 | J31: 383.52048 | M31: =RIGHT(D$41,SEARCH("/",D$41,1)-1) -> 3576.6 | N31: 75RPM | P31: =G31*6.4516 -> 59.484693
A32: Excit.Amps | B32: 18.717 / 15.626 | D32: Second.Core | E32: 23.214779 | F32: 704.83338 | G32: 12.903 | H32: 116.50579 | I32: Total | J32: 3884.4221 | M32: =RIGHT(C$41,SEARCH("/",C$41,1)-1) -> 3584.3 | N32: 50RPM | P32: =G32*6.4516 -> 83.244997
A33: Core Loss | B33: 1.342 / 1.121 | C33: Flux / Pole | D33: Tooth | E33: 3.641 | F33: 802.09584 | G33: 11.338377 | H33: 12.678971 | I33: C.L.C. | J33: 1.75 / 0.85 | M33: =RIGHT(B$41,SEARCH("/",B$41,1)-1) -> 3591.6 | N33: 25RPM | P33: =G33*6.4516 -> 73.150676
A34: NoLoad | B34: 18.77 / 15.67 | C34: 9.0944654 | D34: Air Gap | E34: 0.33 | F34: 2168.2876 | G34: 4.1943077 | H34: 1101.4498 | I34: S.F.C. | J34: 6.0500002 | P34: =G34*6.4516 -> 27.059996
A35: Load Characteristics | D35: Temp. Rise @ 100%: | E35: 107 / 83 | G35: No Load Loss | H35: 21064.4 / 18511.9 | I35: W.Loss | J35: 6797.7 / 3283.3
A36: Load (%) | B36: 25 | C36: 50 | D36: 75 | E36: 100 | F36: 125 | G36: Primary Loss | H36: 10170.5 / 9867.8 | I36: S.Loss | J36: 649.2 / 313.6
A37: Current (A) | B37: 43.42 / 44.06 | C37: 76.87 / 78.00 | D37: 112.78 / 114.43 | E37: 150.81 / 153.03 | F37: 191.25 / 194.05 | G37: Second. Loss | H37: 6875.4 / 7142.0 | I37: Total C.Loss | J37: 7447.0 / 3596.9
A38: Efficiency | B38: 0.894 / 0.887 | C38: 0.937 / 0.929 | D38: 0.949 / 0.942 | E38: 0.952 / 0.945 | F38: 0.952 / 0.945 | G38: Frict.& Wind. | H38: 13500.0 / 17822.6 | I38: Stray Loss | J38: 5148.9902 | L38: =LEFT(E38,SEARCH("/",E38,1)-1) -> 0.952 | M38: =RIGHT(E38,SEARCH("/",E38,1)-1) -> 0.945 | N38: =M38/L38 -> 0.99264706 | O38: Eff.
A39: P.F. | B39: 0.867 / 0.861 | C39: 0.934 / 0.928 | D39: 0.943 / 0.937 | E39: 0.937 / 0.931 | F39: 0.924 / 0.918 | G39: Starting Data | I39: Slip | J39: PF | L39: =LEFT(E39,SEARCH("/",E39,1)-1) -> 0.937 | M39: =RIGHT(E39,SEARCH("/",E39,1)-1) -> 0.931 | N39: =M39/L39 -> 0.99359658 | O39: PF.
A40: Slip | B40: 0.0022 / 0.0023 | C40: 0.0042 / 0.0044 | D40: 0.0063 / 0.0065 | E40: 0.0086 / 0.0088 | F40: 0.0108 / 0.0110 | G40: LRA | H40: 626.4 / 605.4 | L40: =LEFT(E37,SEARCH("/",E37,1)-1) -> 150.81 | M40: =RIGHT(E37,SEARCH("/",E37,1)-1) -> 153.03 | N40: =M40/L40 -> 1.0147205 | O40: Current
...

Sheet DesignSheet
A1: TOSHIBA INTERNATIONAL CORPORATION | I1: Calc. Code: | J1: 2-2-2-0-1-2
A2: 3-PHASE SQUIRREL CAGE INDUCTION MOTOR DESIGN SHEET | J2: B.L.-1 P.F.-1
A3: File: | B3: N:\DESPRO\RAT FILES\BS2M20U.rat | G3: Date: | H3: 45512 | I3: Time: | J3: 0.49915509
A4: Pole | B4: HP | C4: RPM | D4: Form | E4: Voltage | F4: Frequency | G4: Temperature | H4: FLSpeed | I4: FLSlip | J4: Frame
A5: 2 | B5: 1000 | C5: 3600 | D5: FCKNW | E5: 4000 | F5: 60 | G5: 105 | H5: 3581.0 / 3580.3 | I5: 0.0053 / 0.0055 | J5: 5811/12UDZ
A6: Core Data | D6: Winding Data | H6: Constant Data
B7: Primary | C7: Secondary | F7: Bar | G7: End Ring | H7: St. Slot Pitch | I7: 24.543672 | J7: LR Test Data
A8: Air Gap | B8: 3.3 | H8: Rt. Slot Pitch | I8: 30.456888 | J8: ES
A9: Space Fac. | B9: 0.93000001 | D9: Pitch | E9: 1 ~ 16 | F9: Cross Section Area | H9: Mean Value | I9: 27.50028 | J9: 618.66404
A10: Core Length | B10: 510 | C10: 510 | F10: UB: 304.0 | G10: UER: 1750.0 | H10: Eff.T.W.St. | I10: 14.338923 | J10: WS
A11: OD | B11: 670 | C11: 368.4 | D11: Coil Pitch | E11: 0.6249375 | H11: Eff.T.W.Rt. | I11: 30.038757 | J11: 29591.748
A12: ID | B12: 375 | C12: 185 | D12: Slot Fill | E12: - | F12: EBL: 50.0 | G12: ERD1: 281.0 | H12: St.Carter Fac. | I12: 1.1789163 | J12: IS
A13: Core Depth | B13: 85 | C13: 55.29 | D13: Con./Slot | E13: 24 | G13: ERT: 70.00 | H13: Rt.Carter Fac. | I13: 1.0139197 | J13: 121.92049
A14: Eff.Core L. | B14: 409.20001 | C14: 409.20001 | D14: Wire Size 1 | E14: (.072"x.204")x2 | G14: ERH: 25.00 | H14: Carter Factor | I14: 1.1953266 | J14: Volts / Turn
A15: Slot Data | D15: Wire Size 2 | E15: - | H15: Short. Factor | I15: 0.8314146 | J15: 24.056966
A16: Number | B16: 48 | C16: 38 | D16: // Circuits | E16: 2 | H16: Distrib. Factor | I16: 0.95543647 | J16: AC
A17: Kind | B17: Open | C17: Trapeze | D17: Connection | E17: Wye | H17: Wind. Factor | I17: 0.79436384 | J17: 596.09904
A18: Skew | B18: - | C18: 0 | D18: MCL | E18: 1225 | F18: 680 | H18: Reactance | I18: (Coeff.: 0.0418)
A19: Depth | B19: 62.5 | C19: 36.41 | D19: No.Cond./Ph. | E19: 192 | I19: Running | J19: Start | R19: =96.9-25.7 -> 71.2
A20: Width | B20: 10.20 - 10.20 | D20: Res. (20°C) | E20: 0.11173631 | H20: Stator Slot | I20: 18.533136 | J20: 18.533136
A21: Opening | B21: 14.5 | C21: 3 | D21: (105°C) | E21: 0.14905492 | F21: 0.097229064 | G21: 0.012153707 | H21: Rotor Slot | I21: 16.804136 | J21: 14.805407
A22: Tip Depth | B22: 2.8299999 | C22: 3 | D22: Material | E22: CU | F22: CU | G22: CU | H22: Zigzag | I22: 4.1274877 | J22: 3.8444836
A23: T.Min.Wid. | B23: 10.043672 | C23: 10.31661 | D23: Spec.Resist. | E23: 1.742 | F23: 1.742 | G23: 1.742 | H23: Coil End | I23: 24.366604 | J23: Skew R.: 0.00
A24: Low. R. | B24: 0 | C24: 0.80000001 | D24: Spec.Gravity | E24: 8.8900003 | F24: 8.8900003 | G24: 8.8900003 | H24: Belt Leakage | I24: 7.1922227 | J24: 6.6990833
A25: Up. R. | B25: - | C25: 4.7199998 | D25: Weight (kg) | H25: Total Resist. | I25: 0.25843769 | J25: 0.66358405
A26: Wedge Dep. | B26: 2.83 - 2.00 | C26: Magnetic | D26: Wire 1 | E26: 230.01252 | F26: 77.022963 | G26: 26.449351 | H26: Total React. | I26: 2.969631 | J26: 2.8536081
A27: Duct | B27: 7 x 10 | C27: 7 x 10 | D27: Wire 2 | E27: - | F27: - | G27: - | H27: Impedance | I27: 2.9808552 | J27: 2.9297481
A28: Effective Depth (S=1) | D28: Magnetic Circuit Data | I28: Core Loss Data
B29: Res.= | C29: 33.371993 | E29: Length | F29: Section | G29: Density | H29: AT | I29: Volume | J29: Loss | M29: =RIGHT(F$41,SEARCH("/",F$41,1)-1) -> 3575.4 | N29: 125RPM | P29: Kline/in2
B30: Reac.= | C30: 33.399129 | D30: Primary Core | E30: 52.621633 | F30: 695.64002 | G30: 16.341902 | H30: 686.48167 | I30: 63923.41 | J30: 5025.4402 | M30: =RIGHT(E$41,SEARCH("/",E$41,1)-1) -> 3580.3 | N30: 100RPM | P30: =G30*6.4516 -> 105.43142
A31: Excitation Data | D31: Tooth | E31: 6.25 | F31: 986.36893 | G31: 11.525182 | H31: 22.819644 | I31: 12329.612 | J31: 550.53223 | M31: =RIGHT(D$41,SEARCH("/",D$41,1)-1) -> 3585.0 | N31: 75RPM | P31: =G31*6.4516 -> 74.355863
A32: Excit.Amps | B32: 29.566 / 24.684 | D32: Second.Core | E32: 23.214779 | F32: 704.83338 | G32: 16.12875 | H32: 286.45968 | I32: Total | J32: 5575.9724 | M32: =RIGHT(C$41,SEARCH("/",C$41,1)-1) -> 3589.7 | N32: 50RPM | P32: =G32*6.4516 -> 104.05624
A33: Core Loss | B33: 1.563 / 1.305 | C33: Flux / Pole | D33: Tooth | E33: 3.641 | F33: 802.09584 | G33: 14.172971 | H33: 26.024084 | I33: C.L.C. | J33: 1.75 / 0.85 | M33: =RIGHT(B$41,SEARCH("/",B$41,1)-1) -> 3594.3 | N33: 25RPM | P33: =G33*6.4516 -> 91.438341
A34: NoLoad | B34: 29.61 / 24.72 | C34: 11.368081 | D34: Air Gap | E34: 0.33 | F34: 2168.2876 | G34: 5.2428844 | H34: 1376.8122 | I34: S.F.C. | J34: 6.0500002 | P34: =G34*6.4516 -> 33.824993
A35: Load Characteristics | D35: Temp. Rise @ 100%: | E35: 67 / 61 | G35: No Load Loss | H35: 24635.6 / 21650.4 | I35: W.Loss | J35: 9758.0 / 4713.1
A36: Load (%) | B36: 25 | C36: 50 | D36: 75 | E36: 100 | F36: 125 | G36: Primary Loss | H36: 6646.9 / 6449.1 | I36: S.Loss | J36: 1084.7 / 523.9
A37: Current (A) | B37: 44.41 / 44.82 | C37: 67.36 / 67.98 | D37: 93.83 / 94.70 | E37: 121.92 / 123.06 | F37: 151.14 / 152.55 | G37: Second. Loss | H37: 4085.3 / 4243.7 | I37: Total C.Loss | J37: 10842.6 / 5237.0
A38: Efficiency | B38: 0.880 / 0.878 | C38: 0.932 / 0.929 | D38: 0.948 / 0.946 | E38: 0.955 / 0.953 | F38: 0.958 / 0.956 | G38: Frict.& Wind. | H38: 13500.0 / 17822.6 | I38: Stray Loss | J38: 3059.4827 | L38: =LEFT(E38,SEARCH("/",E38,1)-1) -> 0.955 | M38: =RIGHT(E38,SEARCH("/",E38,1)-1) -> 0.953 | N38: =M38/L38 -> 0.99790576 | O38: Eff.
A39: P.F. | B39: 0.689 / 0.684 | C39: 0.858 / 0.852 | D39: 0.907 / 0.901 | E39: 0.924 / 0.918 | F39: 0.929 / 0.923 | G39: Starting Data | I39: Slip | J39: PF | L39: =LEFT(E39,SEARCH("/",E39,1)-1) -> 0.924 | M39: =RIGHT(E39,SEARCH("/",E39,1)-1) -> 0.918 | N39: =M39/L39 -> 0.99350649 | O39: PF.
A40: Slip | B40: 0.0014 / 0.0016 | C40: 0.0027 / 0.0029 | D40: 0.0040 / 0.0042 | E40: 0.0053 / 0.0055 | F40: 0.0066 / 0.0068 | G40: LRA | H40: 788.3 / 761.8 | L40: =LEFT(E37,SEARCH("/",E37,1)-1) -> 121.92 | M40: 123 | N40: =M40/L40 -> 1.0088583 | O40: Current
...

Sheet Data Sheet
A1: TOSHIBA INTERNATIONAL CORPORATION
A2: INDUCTION MOTOR DATA SHEET
A3: File: | B3: BS2M20U | I3: HRW / Model Number: | J3: M203TCQL11F-C
A4: Type: TIKE - Form: FCKNW - 2 Pole - 1000 HP - 4000 V - 60 Hz - 5811/12UDZ - Class F | Q4: Motor Type Selection | T4: Electrical Steel Table
A5: Motor Parameters | F5: PERFORMANCE | J5: DESIGN | K5: TEST | Q5: EPACT | T5: M22 - 26Ga.
A6: Material | D6: NCB1 - 26Ga. | F6: NL & Impedance Test | Q6: EQP-III | T6: M36 - 26Ga.
A7: Air Gap | D7: 3.3 | F7: No load amps | J7: 25 | K7: - | Q7: Exp.Prf. | T7: NCB1 - 26Ga.
A8: Stack length | D8: 510 | F8: No load watts | J8: 21650 | K8: - | Q8: Exp.Prf.-EQPIII | T8: M43 - 26Ga.
A9: Number of turns per coil | D9: 12 | F9: Impedance amps | H9: 3 | I9: f | J9: 227 | K9: - | Q9: Prem. Eff. | T9: M45 - 26Ga.
A10: Wire 1 (size & number) | D10: (.072"x.204")x2 | F10: Impedance volts | H10: 3 | I10: f | J10: 1150 | K10: - | Q10: Standard Eff. | T10: M54 - 26Ga.
A11: Wire 2 (size & number) | D11: - | F11: Impedance watts | H11: 3 | I11: f | J11: 29592 | K11: - | Q11: OWP | T11: TIPA Lam
A12: Slot fill - circle/square method (%) | D12: - | F12: Temperature Rise (°C) | Q12: Dry Kiln
A13: Connection | D13: 2 x Wye | G13: Winding | I13: 80/115 | J13: 67 / 88 | K13: -
A14: MCL | D14: 1225 | G14: Frame | J14: - | K14: -
A15: Allowance for ins. depth | D15: 10.9788 | G15: Bearing PS/OS | J15: - | K15: -
A16: Allowance for ins. width | D16: 3.7368 | G16: End Ring | J16: - | K16: -
A17: Slot/Wire arrangement | D17: 24 x 2 | F17: Nameplate Data
A18: Effective cross section for coil | D18: - | H18: FLC (A) | J18: 123 | M18: =J18*6.5 -> 799.5
A19: Coil grouping | D19: - | H19: RPM | J19: 3580
A20: Coil pitch (slot number) | D20: 1 ~ 16 | H20: CODE | J20: F
A21: Method of coil connection | D21: - | H21: S. F. | J21: 1.15 | Q21: Method of Connection
A22: Resistance per phase @ 20 °C | D22: 0.1117 | H22: DESIGN | J22: - | Q22: Skip
A23: Coil Weight | B23: Wire1 | D23: 506 | H23: Nom.Eff. (%): | J23: 95 | Q23: Adjacent
A24: (lbs.) | B24: Wire2 | D24: - | H24: Min.Eff. (%): | J24: - | Q24: -
A25: Current Densities (A/cm2) | E25: Bar / ER | H25: P.F. (%): | J25: 91.5
A26: FL / LR | D26: 336 / 2082 | E26: 446 / 469
A27: Stator Slot Shape (Reference) | F27: Performance
H28: LRC (A) | I28: - | J28: 762 | K28: - | M28: =(J28/J18)*100 -> 619.5122
H29: LRT (%) | I29: 60 | J29: 90 | K29: -
H30: BDT (%) | I30: 175 | J30: 219 | K30: -
H31: SLIP (%) | J31: 0.55 | K31: -
G32: IEEE-B | H32: Eff. (%) | J32: 95.3 | K32: -
A33: Rotor Slot Shape (Reference) | H33: PF (%) | J33: 91.8 | K33: -
F34: Losses (Watts) | H34: Primary | J34: 6449 | K34: -
H35: Secondary | J35: 4244 | K35: -
H36: Core | J36: 5237 | K36: -
H37: F & W | J37: 17823 | K37: -
H38: Stray | J38: 3059 | K38: -
A39: End Ring (Reference) | F39: Note
F40: LINK: | G40: BS2800U.rat & LAB 8292.dat | K40: H040052.rat with lab 1125 1126.dat
...

Sheet Performance Data Sheet
A1: TOSHIBA INTERNATIONAL CORPORATION | J1: INDEX | L1: MPCF-1033
A2: Industrial Division / Houston Motor Plant | J2: SHEET NO. | L2: 1 of 1
J3: ISSUED | L3: 7/31/13
J4: SUPERSEDES | L4: 11/8/96
J5: REVISION | L5: 2
A6: SQUIRREL CAGE INDUCTION MOTOR | J6: WRITTEN BY | L6: MDC
A7: PERFORMANCE SPECIFICATIONS | J7: APPROVED BY | L7: PAA
B9: CUSTOMER: | C9: ILLINOIS ELECTRIC WORKS
B10: TIC SR No.: | C10: 2338072.1
A12: MOTOR NAMEPLATE DATA
B13: H.P.: | C13: 1000 | E13: VOLTS: | F13: 4000 | H13: 3 PH / | I13: 60 Hz | L13: S. RPM: | M13: 3600
B14: FRAME: | C14: 5812USS | E14: ENCL: | F14: TEFC | H14: FLAMPS: | I14: 123 | L14: FLRPM: | M14: 3580
B15: FORM: | C15: FCKNW | E15: S.F.: | F15: 1.0 | H15: NEMA DESIGN: | I15: - | L15: INSUL CLASS: | M15: F
B16: TYPE: | C16: TIKE | E16: AMB.: | F16: 40 | H16: CODE: | I16: F | L16: DUTY: | M16: Cont.
B17: MODEL No.: | C17: A1-10138469 | H17: kW: | I17: -
B18: NOM. EFF.: | C18: 95 | E18: MIN. EFF.: | F18: - | H18: P.F.: | I18: 91.5
A21: AMPERAGE | E21: TORQUES | I21: **BEARINGS:
C22: LOCKED ROTOR: | D22: 762 | G22: FULL LOAD (lb-ft.): | H22: 1467 | K22: DRIVE END:
G23: LOCKED ROTOR (%): | H23: 90 | K23: OPPOSITE DRIVE END:
G24: BREAK DOWN (%): | H24: 215
A28: EFFICIENCY | H28: POWER FACTOR
C29: FULL LOAD: | D29: 95.3 | J29: FULL LOAD: | K29: 91.8
C30: 3/4 LOAD: | D30: 94.6 | J30: 3/4 LOAD: | K30: 90.2
C31: 1/2 LOAD: | D31: 93 | J31: 1/2 LOAD: | K31: 85.2
A35: ALL CHARACTERISTICS ARE AVERAGE EXPECTED VALUES BASED UPON RATED VOLTAGE,
A36: FREQUENCY AND SINEWAVE POWER INPUT.
A37: THE DECLARED LOCKED ROTOR CURRENT HAS A TOLERANCE OF 20%.
A38: * TEMPERATURE RISE WILL BE CONSISTENT WITH INSULATION, AMBIENT AND SERVICE FACTOR AS
A39: DEFINED BY NEMA-MG-12 OR -20.
A40: ** BEARINGS ARE THE ONLY RECOMMENDED SPARE PART(S).
J42: CERTIFIED BY: | K42: Jerry R
J44: DATE: | K44: 45512
A59: - | B59: 6205ZZ | D59: 1 | E59: -
A60: TEFC | B60: 6206UU | D60: 1.15 | E60: A
A61: ODP | B61: 6207ZZ | E61: B
B62: 6208UU
B63: 6211ZZ
B64: 6211C3
B65: 6211ZZC3
B66: 6305UUC3
...

Sheet STCurve
A2: TOSHIBA INTERNATIONAL CORPORATION
A3: Speed Torque/Current Curve
A6: Model #: | B6: ='Performance Data Sheet'!C17 -> A1-10138469 | E6: FLAmps: | F6: ='Performance Data Sheet'!I14 & " A" -> 123 A
A7: Enclosure: | B7: ='Performance Data Sheet'!F14 -> TEFC | C7: Voltage: | D7: ='Performance Data Sheet'!F13 & " V" -> 4000 V | E7: Frame: | F7: ='Performance Data Sheet'!C14 -> 5812USS
A8: Pole: | B8: 2 | C8: Frequency: | D8: 3 PH / 60 Hz | E8: Ins. Class: | F8: F
A9: HP: | B9: 1000 | C9: Rotor Inertia: | D9: 192.3 lb-ft² | E9: Date: | F9: ='Performance Data Sheet'!K44 -> 45512
A10: FLRPM: | B10: 3580 | C10: Load Inertia: | D10: 222.0 lb-ft² | E10: File: | F10: BS2M20U
B12: Locked Rotor Amps: | C12: ='Performance Data Sheet'!D22 & " A" -> 762 A | D12: Load Type: | E12: Fan / Pump
B13: Locked Rotor Torque: | C13: 0.9 | D13: Starting at: | E13: FV / 0.80 (V)
B14: Breakdown Torque: | C14: 2.15 | D14: Accel. Time: | E14: 5 / 12 (s)
B15: Rated Torque: | C15: 1467 lb-ft
A39: Comments: | B39: PROJECT | C39: ='Performance Data Sheet'!C10 -> 2338072.1 | E39: D.E.Curve #: | F39: =F10 -> BS2M20U
C43: Prepared by: | D43: ='Performance Data Sheet'!K42 -> Jerry R | E43: Checked by:
D53: Load | E53: Torque 80% | F53: LRA 80%
A54: 100 | B54: 0 | C54: 0.24071087 | D54: 100 | E54: 0 | F54: 23.685949
A55: 99.2 | B55: 114.6071 | C55: 161.61099 | D55: 98.400002 | E55: 73.348547 | F55: 129.2888
A56: 96 | B56: 215 | C56: 479.38034 | D56: 89.75 | E56: 137.6 | F56: 383.50427
A57: 90.857143 | B57: 142.31579 | C57: 559.43774 | D57: 76.228569 | E57: 91.082112 | F57: 447.5502
A58: 85.714285 | B58: 112.00328 | C58: 580.26404 | D58: 62.85714 | E58: 71.682097 | F58: 464.21124
A59: 80.571428 | B59: 100.00378 | C59: 588.59351 | D59: 51.257141 | E59: 64.002424 | F59: 470.87482
A60: 70.285714 | B60: 92.83088 | C60: 596.08807 | D60: 33.485714 | E60: 59.411764 | F60: 476.87045
A61: 59.999999 | B61: 90 | C61: 600.76459 | D61: 22 | E61: 57.600002 | F61: 480.61166
A62: 50 | B62: 90.020785 | C62: 604.83752 | D62: 14 | E62: 57.613302 | F62: 483.87003
A63: 39.999998 | B63: 90.028458 | C63: 608.53705 | D63: 7.9999995 | E63: 57.618215 | F63: 486.82965
A64: 30.000001 | B64: 90.037954 | C64: 611.8399 | D64: 5.9999995 | E64: 57.624294 | F64: 489.47192
A65: 19.999999 | B65: 90.050673 | C65: 614.74451 | D65: 8.000001 | E65: 57.632433 | F65: 491.79562
... A67: 0 | B67: 90 | C67: 619.51221 | D67: 30 | E67: 57.600002 | F67: 495.60977

Sheet Thermdam
A2: TOSHIBA INTERNATIONAL CORPORATION
A3: Thermal Limit & Acceleration Curves
A4: Design Values (For Reference Only)
A6: Model #: | B6: ='Performance Data Sheet'!C17 -> A1-10138469 | E6: FLAmps: | F6: ='Performance Data Sheet'!I14 & " A" -> 123 A
A7: Enclosure: | B7: ='Performance Data Sheet'!F14 -> TEFC | C7: Voltage: | D7: ='Performance Data Sheet'!F13 & " V" -> 4000 V | E7: Frame: | F7: ='Performance Data Sheet'!C14 -> 5812USS
A8: Pole: | B8: 2 | C8: Frequency: | D8: 3 PH / 60 Hz | E8: Ins. Class: | F8: F
A9: HP: | B9: 1000 | C9: Rotor Inertia: | D9: 192.3 lb-ft² | E9: Date: | F9: ='Performance Data Sheet'!K44 -> 45512
A10: FLRPM: | B10: 3580 | C10: Load Inertia: | D10: 222.0 lb-ft² | E10: File: | F10: BS2M20U
A39: Comments: | B39: PROJECT | C39: ='Performance Data Sheet'!C10 -> 2338072.1 | E39: D.E.Curve #: | F39: =F10 -> BS2M20U
C43: Prepared by: | D43: ='Performance Data Sheet'!K42 -> Jerry R | E43: Checked by:
F50: =5252.1*B50/D53 -> #DIV/0!
D66: =D65/D64 -> #DIV/0!
A67: Current (%) | B67: Cold | C67: Hot | E67: CURRENT (%) | F67: Accel. Time
A68: 619.5122 | B68: 30 | C68: 15 | E68: =A68 -> 619.5122 | F68: 0.0001 | G68: =0.8*E68 -> 495.60976 | H68: =F68 -> 0.0001
A69: =FLOOR(A68,100) -> 600 | B69: =((A68/A69)^2)*B68 -> 31.982947 | C69: =((A68/A69)^2)*C68 -> 15.991473 | E69: 618.37398 | F69: 0.50548254 | G69: =0.8*E69 -> 494.69919 | H69: =2.4094*F69 -> 1.2179096
A70: =A69-100 -> 500 | B70: =((A68/A70)^2)*B68 -> 46.055443 | C70: =((A68/A70)^2)*C68 -> 23.027722 | E70: 616.01626 | F70: 0.9387533 | G70: =0.8*E70 -> 492.81301 | H70: =2.4094*F70 -> 2.2618322
A71: =A70-100 -> 400 | B71: =((A68/A71)^2)*B68 -> 71.96163 | C71: =((A68/A71)^2)*C68 -> 35.980815 | E71: 613.25203 | F71: 1.3493288 | G71: =0.8*E71 -> 490.60163 | H71: =2.4094*F71 -> 3.2510729
A72: =A71-100 -> 300 | B72: =((A68/A72)^2)*B68 -> 127.93179 | E72: 610.1626 | F72: 1.7599045 | G72: =0.8*E72 -> 488.13008 | H72: =2.4094*F72 -> 4.2403138
A73: =A72-100 -> 200 | B73: =((A68/A73)^2)*B68 -> 287.84652 | E73: 606.66667 | F73: 2.1911121 | G73: =0.8*E73 -> 485.33333 | H73: =2.4094*F73 -> 5.2792655
A74: 215 | B74: =((A68/A74)^2)*B68 -> 249.08298 | C74: =((A68/A74)^2)*C68 -> 124.54149 | E74: 602.76423 | F74: 2.6646152 | G74: =0.8*E74 -> 482.21138 | H74: =2.4094*F74 -> 6.420124
A75: 180 | B75: =((A68/A75)^2)*B69 -> 378.85514 | C75: =((A68/A75)^2)*C68 -> 177.68304 | E75: 598.45528 | F75: 3.215488 | G75: =0.8*E75 -> 478.76423 | H75: =2.4094*F75 -> 7.7473967
A76: 145 | B76: =((A68/A76)^2)*B68 -> 547.62715 | C76: =((A68/A76)^2)*C68 -> 273.81357 | E76: 592.35772 | F76: 3.8643624 | G76: =0.8*E76 -> 473.88618 | H76: =2.4094*F76 -> 9.3107948
A77: 125 | C77: =CEILING(C76*2,100) -> 600 | E77: 584.39024 | F77: 4.223358 | G77: =0.8*E77 -> 467.5122 | H77: =2.4094*F77 -> 10.175759
A78: 125 | C78: =2*C77 -> 1200 | E78: 569.8374 | F78: 4.5276792 | G78: =0.8*E78 -> 455.86992 | H78: =2.4094*F78 -> 10.90899
A79: 125 | C79: 10000 | E79: 519.43089 | F79: 4.7113034 | G79: =0.8*E79 -> 415.54472 | H79: =2.4094*F79 -> 11.351414
E80: 320.4878 | F80: 4.8660431 | G80: =0.8*E80 -> 256.39024 | H80: =2.4094*F80 -> 11.724244
E81: 120 | F81: 4.9805504 | G81: 120 | H81: =2.4094*F81 -> 12.000138

Sheet Performance
A2: TOSHIBA INTERNATIONAL CORPORATION
A3: Performance Curve
A4: Design Values (For Reference Only)
A6: Model #: | B6: ='Performance Data Sheet'!C17 -> A1-10138469 | E6: FLAmps: | F6: ='Performance Data Sheet'!I14 & " A" -> 123 A
A7: Enclosure: | B7: ='Performance Data Sheet'!F14 -> TEFC | C7: Voltage: | D7: ='Performance Data Sheet'!F13 & " V" -> 4000 V | E7: Frame: | F7: ='Performance Data Sheet'!C14 -> 5812USS
A8: Pole: | B8: 2 | C8: Frequency: | D8: 3 PH / 60 Hz | E8: Ins. Class: | F8: F
A9: HP: | B9: 1000 | C9: Rotor Inertia: | D9: 192.3 lb-ft² | E9: Date: | F9: ='Performance Data Sheet'!K44 -> 45512
A10: FLRPM: | B10: 3580 | C10: Load Inertia: | D10: 222.0 lb-ft² | E10: File: | F10: BS2M20U
B12: Locked Rotor Amps: | C12: ='Performance Data Sheet'!D22 & " A" -> 762 A | D12: Load Type: | E12: Fan / Pump
B13: Locked Rotor Torque: | C13: 0.9 | D13: Starting at: | E13: FV / 0.80 (V)
B14: Breakdown Torque: | C14: 2.15 | D14: Accel. Time: | E14: 5 / 12 (s)
B15: Rated Torque: | C15: 1467 lb-ft
A39: Comments: | B39: PROJECT | C39: ='Performance Data Sheet'!C10 -> 2338072.1 | E39: D.E.Curve #: | F39: =F10 -> BS2M20U
C43: Prepared by: | D43: ='Performance Data Sheet'!K42 -> Jerry R | E43: Checked by:
A53: Load | B53: Efficiency | C53: PF | D53: Amps | E53: RPM | F53: Input Watts
A54: 0 | D54: 29.870944 | E54: 100 | F54: 1.08252
A55: 25 | B55: 87.793777 | C55: 68.451653 | D55: 44.801907 | E55: 79.827754 | F55: 10.623272
A56: 50 | B56: 92.974388 | C56: 85.228569 | D56: 67.955658 | E56: 64.40478 | F56: 20.06267
A57: 75 | B57: 94.641098 | C57: 90.157829 | D57: 94.663429 | E57: 48.720072 | F57: 29.564026
A58: 100 | B58: 95.338387 | C58: 91.835693 | D58: 123.00559 | E58: 33.003736 | F58: 39.130398
A59: 125 | B59: 95.631561 | C59: 92.317261 | D59: 152.48601 | E59: 16.833001 | F59: 48.763045

Sheet StallTime
A1: Rating: | B1: 2 Pole - 1000.0 HP - 3600 RPM - 4000 V - 60 Hz
A3: Starting Performance
D4: Load Type: Fan / Pump - 222.0 lb-ft²
A5: RPM | B5: Motor | C5: Load | D5: Accel. | E5: Line | F5: Stator | G5: Rotor
A6: Speed Increment | B6: Torque (%) | C6: Torque (%) | D6: Time (s) | E6: Amps | F6: kW / s | G6: kW / s
A7: 0~360 | B7: 90.0 | C7: 22.5 | D7: 0.490 | E7: 760.6 | F7: 127.1 | G7: 409.9
A8: 360~720 | B8: 90.1 | C8: 11.5 | D8: 0.420 | E8: 757.7 | F8: 108.4 | G8: 317.1
A9: 720~1080 | B9: 90.0 | C9: 7.0 | D9: 0.398 | E9: 754.3 | F9: 101.8 | G9: 266.9
A10: 1080~1440 | B10: 90.0 | C10: 7.0 | D10: 0.398 | E10: 750.5 | F10: 100.8 | G10: 233.5
A11: 1440~1800 | B11: 90.0 | C11: 11.0 | D11: 0.418 | E11: 746.2 | F11: 104.8 | G11: 210.2
A12: 1800~2160 | B12: 90.0 | C12: 18.0 | D12: 0.459 | E12: 741.4 | F12: 113.6 | G12: 192.2
A13: 2160~2530 | B13: 91.4 | C13: 27.7 | D13: 0.534 | E13: 736.1 | F13: 130.3 | G13: 173.8
A14: 2530~2901 | B14: 96.4 | C14: 42.4 | D14: 0.629 | E14: 728.6 | F14: 151.3 | G14: 157.1
A15: 2901~3086 | B15: 106.0 | C15: 57.1 | D15: 0.348 | E15: 718.8 | F15: 81.4 | G15: 122.2
A16: 3086~3271 | B16: 127.2 | C16: 69.5 | D16: 0.295 | E16: 700.9 | F16: 67.2 | G16: 85.4
... A19: 3571~3581 | B19: 107.3 | C19: 99.2 | D19: 0.111 | E19: 117.6 | F19: 0.7 | G19: 23.0
D21: Acceleration Time: 4.8 s
B22: Energy | D22: First Start | F22: Second Start
A23: Stator Winding Rise | B23: 1148 kW / s | D23: 13°C | F23: 26°C
A24: Rotor Bar Rise | B24: 2018 kW / s | D24: 68°C | F24: 136°C
A25: End Ring Rise | B25: 252 kW / s | D25: 25°C | F25: 50°C
A27: Locked Rotor Thermal Capability
E28: Cold Condition
B29: Rate of Rise | D29: Power | E29: Rise Limit | F29: Max Time
A30: Stator Copper | B30: 3.4°C / s | D30: 301.7 kW | E30: 160°C | F30: 47.0 s
A31: Rotor Bar | B31: 20.1°C / s | D31: 596.8 kW | E31: 260°C | F31: 12.9 s
A32: Rotor ER | B32: 7.3°C / s | D32: 74.6 kW | E32: 180°C | F32: 24.6 s
E34: Hot Condition
B35: Hot Temp. | D35: Rise Limit | E35: Ambient | F35: Total | G35: Max.Time
A36: Stator Copper | B36: 67°C + | D36: 93°C + | E36: 40°C | F36: = 200°C | G36: 27.3 s
A37: Rotor Bar | B37: 89°C + | D37: 171°C + | E37: 40°C | F37: = 300°C | G37: 8.5 s
A38: Rotor ER | B38: 89°C + | D38: 91°C + | E38: 40°C | F38: = 220°C | G38: 12.4 s
A40: Cold Stall Time: | B40: 20.6 s | D40: Hot Stall Time: | F40: 10.4 s

Sheet Circuit Param
A1: TOSHIBA INTERNATIONAL CORPORATION | J1: INDEX | L1: MPCF-1109
A2: Industrial Division / Houston Motor Plant | J2: SHEET NO. | L2: 1 of 1
J3: ISSUED | L3: 38309
A4: EQUIVALENT CIRCUIT DATA | J4: SUPERSEDES | L4: NEW
J5: REVISION | L5: REV. 0
J6: WRITTEN BY | L6: MDC
A7: All Values are Presented in Ohms/Phase, Equivalent Wye Connection. | J7: APPROVED BY | L7: Paul Anderson
B9: CUSTOMER: | C9: ILLINOIS ELECTRIC WORKS
B10: TIC SR No.: | C10: 2338072.1
A12: MOTOR NAMEPLATE DATA
B13: H.P.: | C13: 1000 | E13: VOLTS: | F13: 4000 | H13: 3 PH / | I13: 60 Hz | L13: S. RPM: | M13: 3600
B14: FRAME: | C14: 5812USS | E14: ENCL: | F14: TEFC | H14: FLAMPS: | I14: 123 | L14: FLRPM: | M14: 3580
B15: FORM: | C15: FCKNW | E15: S.F.: | F15: 1.0 | H15: NEMA DESIGN: | I15: - | L15: INSUL CLASS: | M15: F
B16: TYPE: | C16: TIKE | E16: AMB.: | F16: 40 | H16: CODE: | I16: F | L16: DUTY: | M16: Cont.
B17: MODEL No.: | C17: A1-10138469 | H17: kW: | I17: -
B18: NOM. EFF.: | C18: 95 | E18: MIN. EFF.: | F18: - | H18: P.F.: | I18: 91.5
A21: Primary Resistance (R1) : | F21: 0.14905492
A22: Secondary Resistance (R2) : | F22: 0.10938277
A23: Starting Resistance (R3) : | F23: 0.51452913
A25: Primary Reactance (X1) : | F25: 2.53
A26: Secondary Reactance (X2) : | F26: 1.91
A27: Starting Reactance (X3) : | F27: 1.152
A29: Magnetizing Reactance (Xm) : | F29: 74.5
A31: Transient Reactance : | F31: 4.39
A32: Sub Transient Reactance : | F32: 3.24
A33: Short Circuit Time Constant : | F33: 0.106
A34: Sub Transient Time Constant : | F34: 0.011
A35: Open Circuit Time Constant : | F35: 1.853
I40: CERTIFIED BY: | J40: JERRY R
I42: DATE: | J42: 45512

Sheet Performance API
A1: TOSHIBA INTERNATIONAL CORPORATION | J1: INDEX | L1: MPCF-1082
A2: Industrial Division / Houston Motor Plant | J2: SHEET NO. | L2: 1 of 1
J3: ISSUED | L3: 2/14/02
J4: SUPERSEDES | L4: NEW
J5: REVISION | L5: 0
A6: SQUIRREL CAGE INDUCTION MOTOR | J6: WRITTEN BY | L6: M. CAMPBELL
A7: API 541 PERFORMANCE SPECIFICATIONS | J7: APPROVED BY | L7: P.A.A
B9: CUSTOMER: | C9: ILLINOIS ELECTRIC WORKS
B10: TIC SR No.: | C10: 2338072.1
A12: MOTOR NAMEPLATE DATA
B13: H.P.: | C13: 1000 | E13: VOLTS: | F13: 4000 | H13: 3 PH / | I13: 60 Hz | L13: S. RPM: | M13: 3600
B14: FRAME: | C14: 5812USS | E14: ENCL: | F14: TEFC | H14: FLAMPS: | I14: 123 | L14: FLRPM: | M14: 3580
B15: FORM: | C15: FCKNW | E15: S.F.: | F15: 1.0 | H15: NEMA DESIGN: | I15: - | L15: INSUL CLASS: | M15: F
B16: TYPE: | C16: TIKE | E16: AMB.: | F16: 40 | H16: CODE: | I16: F | L16: DUTY: | M16: Cont.
B17: MODEL No.: | C17: A1-10138469 | H17: kW: | I17: -
B18: NOM. EFF.: | C18: 95 | E18: MIN. EFF.: | F18: - | H18: P.F.: | I18: 91.5
A20: LOCKED ROTOR DATA
D21: AMPS AT RATED VOLTAGE: | E21: 762 A | I21: POWER FACTOR: | J21: 0.142
D22: AMPS AT 80% VOLTAGE: | E22: 605 A
A24: TORQUE VALUES | H24: CURVE NUMBERS
E25: FULL LOAD (LB.FT): | F25: 1467 | J25: SPEED-TORQUE CURVE: | K25: BS2M20U
E26: LOCKED ROTOR TORQUE (% OF FLT): | F26: 90 | J26: SPEED-CURRENT CURVE: | K26: BS2M20U
E27: PULL UP TORQUE (% OF FLT): | F27: 90 | J27: ACCELERATION CURVE: | K27: BS2M20U
E28: BREAKDOWN TORQUE (% OF FLT): | F28: 215
A30: LOCKED ROTOR WITHSTAND TIMES
A31: COLD CONDITION | H31: HOT CONDITION
C32: 100% VOLTAGE: | D32: 30 (s) | J32: 100% VOLTAGE: | K32: 15 (s)
C33: 90% VOLTAGE: | D33: 37 (s) | J33: 90% VOLTAGE: | K33: 19 (s)
C34: 80% VOLTAGE: | D34: 47 (s) | J34: 80% VOLTAGE: | K34: 23 (s)
C35: 70% VOLTAGE: | D35: 62 (s) | J35: 70% VOLTAGE: | K35: 31 (s)
A37: DESIGN DATA
C38: MOTOR ROTOR wk2 (LB.FT2): | D38: 192.3 | J38: NO LOAD CURRENT: | K38: 25 A
C39: AIR GAP: | D39: 3.3 mm | J39: ACCELERATION TIME: | K39: 5 / 12 (s)
D40: LOAD CHARACTERISTICS
D41: LOAD | G41: 1/2 | H41: 3/4 | I41: FULL | J41: SF
D42: AMPS (A) | G42: 67.9 | H42: 94.7 | I42: 123 | J42: -
D43: EFFICIENCY (%) | G43: 92.9 | H43: 94.6 | I43: 95.3 | J43: -
D44: POWER FACTOR (%) | G44: 85.2 | H44: 90.1 | I44: 91.8 | J44: -
D45: GUARENTEED EFFICIENCY (%) | G45: - | H45: - | I45: - | J45: -
A46: EFFICIENCY TO BE DETERMINED BY IEEE 112, METHOD B
...
