Workbook
Name _CPL2: #REF!
Name _LGD2: #REF!
Name _pip54: #REF!
Name _pip55: #REF!
Name _SF1: #REF!
Name _SH1: #REF!
Name _SH2: #REF!
Name _TH103550: [2]許容ｽﾗｽﾄ!$H$38:$J$41
Name _TH103550: [2]許容ｽﾗｽﾄ!$H$38:$J$41
Name _TH103560: [2]許容ｽﾗｽﾄ!$H$43:$J$46
Name _TH103560: [2]許容ｽﾗｽﾄ!$H$43:$J$46
Name _TH104050: [2]許容ｽﾗｽﾄ!$H$78:$J$81
Name _TH104050: [2]許容ｽﾗｽﾄ!$H$78:$J$81
Name _TH104060: [2]許容ｽﾗｽﾄ!$H$83:$J$86
Name _TH104060: [2]許容ｽﾗｽﾄ!$H$83:$J$86
Name _TH104550: [2]許容ｽﾗｽﾄ!$H$122:$J$127
Name _TH104550: [2]許容ｽﾗｽﾄ!$H$122:$J$127
Name _TH104560: [2]許容ｽﾗｽﾄ!$H$129:$J$134
Name _TH104560: [2]許容ｽﾗｽﾄ!$H$129:$J$134
Name _TH43550: [2]許容ｽﾗｽﾄ!$H$8:$J$11
Name _TH43550: [2]許容ｽﾗｽﾄ!$H$8:$J$11
Name _TH43560: [2]許容ｽﾗｽﾄ!$H$13:$J$16
Name _TH43560: [2]許容ｽﾗｽﾄ!$H$13:$J$16
Name _TH44050: [2]許容ｽﾗｽﾄ!$H$48:$J$51
Name _TH44050: [2]許容ｽﾗｽﾄ!$H$48:$J$51
Name _TH44060: [2]許容ｽﾗｽﾄ!$H$53:$J$56
Name _TH44060: [2]許容ｽﾗｽﾄ!$H$53:$J$56
Name _TH44550: [2]許容ｽﾗｽﾄ!$H$88:$J$92
Name _TH44550: [2]許容ｽﾗｽﾄ!$H$88:$J$92
Name _TH44560: [2]許容ｽﾗｽﾄ!$H$93:$J$97
Name _TH44560: [2]許容ｽﾗｽﾄ!$H$93:$J$97
Name _TH63550: [2]許容ｽﾗｽﾄ!$H$18:$J$21
Name _TH63550: [2]許容ｽﾗｽﾄ!$H$18:$J$21
Name _TH63560: [2]許容ｽﾗｽﾄ!$H$23:$J$26
Name _TH63560: [2]許容ｽﾗｽﾄ!$H$23:$J$26
Name _TH64050: [2]許容ｽﾗｽﾄ!$H$58:$J$61
Name _TH64050: [2]許容ｽﾗｽﾄ!$H$58:$J$61
Name _TH64060: [2]許容ｽﾗｽﾄ!$H$63:$J$66
Name _TH64060: [2]許容ｽﾗｽﾄ!$H$63:$J$66
Name _TH64550: [2]許容ｽﾗｽﾄ!$H$98:$J$102
Name _TH64550: [2]許容ｽﾗｽﾄ!$H$98:$J$102
Name _TH64560: [2]許容ｽﾗｽﾄ!$H$103:$J$107
Name _TH64560: [2]許容ｽﾗｽﾄ!$H$103:$J$107
Name _TH83550: [2]許容ｽﾗｽﾄ!$H$28:$J$31
Name _TH83550: [2]許容ｽﾗｽﾄ!$H$28:$J$31
Name _TH83560: [2]許容ｽﾗｽﾄ!$H$33:$J$36
Name _TH83560: [2]許容ｽﾗｽﾄ!$H$33:$J$36
Name _TH84050: [2]許容ｽﾗｽﾄ!$H$68:$J$71
Name _TH84050: [2]許容ｽﾗｽﾄ!$H$68:$J$71
Name _TH84060: [2]許容ｽﾗｽﾄ!$H$73:$J$76
Name _TH84060: [2]許容ｽﾗｽﾄ!$H$73:$J$76
Name _TH84550: [2]許容ｽﾗｽﾄ!$H$108:$J$114
Name _TH84550: [2]許容ｽﾗｽﾄ!$H$108:$J$114
Name _TH84560: [2]許容ｽﾗｽﾄ!$H$115:$J$121
Name _TH84560: [2]許容ｽﾗｽﾄ!$H$115:$J$121
Name _UMU1: #REF!
Name _UMU2: #REF!
Name _VIB1: #REF!
Name _VIB2: #REF!
Name A: #REF!

Sheet DesignSheet
A1: TOSHIBA INTERNATIONAL CORPORATION | I1: Calc. Code: | J1: 2-2-2-0-1-2
A2: 3-PHASE SQUIRREL CAGE INDUCTION MOTOR DESIGN SHEET | J2: B.L.-1 P.F.-1
A3: File: | B3: N:\Motor R&D\Active Projects\New 5011_5811 TEFC\Electric\Series Design\4P\5000\CuBar\CS4350.rat | G3: Date: | H3: 40056 | I3: Time: | J3: 0.4175463
A4: Pole | B4: HP | C4: RPM | D4: Form | E4: Voltage | F4: Frequency | G4: Temperature | H4: FLSpeed | I4: FLSlip | J4: Frame
A5: 4 | B5: 350.00001 | C5: 1800 | D5: FCW4 | E5: 4000 | F5: 60 | G5: 105 | H5: 1781.8 / 1781.8 | I5: 0.0101 / 0.0101 | J5: 5011US
A6: Core Data | D6: Winding Data | H6: Constant Data
B7: Primary | C7: Secondary | F7: Bar | G7: End Ring | H7: St. Slot Pitch | I7: 18.430661 | J7: LR Test Data
A8: Air Gap | B8: 1.8 | H8: Rt. Slot Pitch | I8: 21.890599 | J8: ES
A9: Space Fac. | B9: 0.93000001 | D9: Pitch | E9: 1 ~ 14 | F9: Cross Section Area | H9: Mean Value | I9: 20.16063 | J9: 829.16182
A10: Core Length | B10: 520 | C10: 520 | F10: UB: 240.0 | G10: UER: 1575.0 | H10: Eff.T.W.St. | I10: 11.353491 | J10: WS
A11: OD | B11: 550 | C11: 348.4 | D11: Coil Pitch | E11: 0.86658 | H11: Eff.T.W.Rt. | I11: 21.171258 | J11: 13665.422
A12: ID | B12: 352 | C12: 140 | D12: Slot Fill | E12: - | F12: EBL: 63.5 | G12: ERD1: 278.4 | H12: St.Carter Fac. | I12: 1.1944753 | J12: IS
A13: Core Depth | B13: 48.5 | C13: 72.150001 | D13: Con./Slot | E13: 19 | G13: ERT: 45.00 | H13: Rt.Carter Fac. | I13: 1.0339772 | J13: 43.059921
A14: Eff.Core L. | B14: 483.60001 | C14: 483.60001 | D14: Wire Size 1 | E14: (.064"x.258")x1 | F14: (8 x 30) | G14: ERH: 35.00 | H14: Carter Factor | I14: 1.2350602 | J14: Volts / Turn
A15: Slot Data | D15: Wire Size 2 | E15: - | H15: Short. Factor | I15: 0.97811905 | J15: 12.155099
A16: Number | B16: 60 | C16: 50 | D16: // Circuits | E16: 1 | H16: Distrib. Factor | I16: 0.956506 | J16: AC
A17: Kind | B17: Open | C17: Rectang | D17: Connection | E17: Wye | H17: Wind. Factor | I17: 0.93557674 | J17: 443.90079
A18: Skew | B18: - | C18: 0 | D18: MCL | E18: 977 | F18: 692 | H18: Reactance | I18: (Coeff.: 0.2027)
A19: Depth | B19: 50.5 | C19: 32.049999 | D19: No.Cond./Ph. | E19: 380 | I19: Running | J19: Start
A20: Width | B20: 7.08 - 7.08 | C20: 8.0500002 | D20: Res. (20°C) | E20: 0.62523589 | H20: Stator Slot | I20: 22.258333 | J20: 22.258333
A21: Opening | B21: 10.1 | C21: 3 | D21: (105°C) | E21: 0.83405731 | F21: 0.51162529 | G21: 0.067444959 | H21: Rotor Slot | I21: 18.094044 | J21: 12.169863
A22: Tip Depth | B22: 2.8299999 | C22: 2 | D22: Material | E22: CU | F22: Special | G22: Special | H22: Zigzag | I22: 5.5395637 | J22: 5.1792436
A23: T.Min.Wid. | B23: 8.3306608 | C23: 9.817214 | D23: Spec.Resist. | E23: 1.742 | F23: 1.724 | G23: 1.724 | H23: Coil End | I23: 9.5634814 | J23: Skew R.: 0.00
A24: Low. R. | B24: 0 | C24: 0.80000001 | D24: Spec.Gravity | E24: 8.8900003 | F24: 8.8900003 | G24: 8.8900003 | H24: Belt Leakage | I24: 4.6158724 | J24: 4.3803971
A25: Up. R. | B25: - | C25: 0.80000001 | D25: Weight (kg) | H25: Total Resist. | I25: 1.4131275 | J25: 2.4567182
A26: Wedge Dep. | B26: 2.83 - 2.00 | C26: Magnetic | D26: Wire 1 | E26: 102.41972 | F26: 78.623163 | G26: 27.655104 | H26: Total React. | I26: 12.17783 | J26: 10.842953
A27: Duct | B27: - | C27: - | D27: Wire 2 | E27: - | F27: - | G27: - | H27: Impedance | I27: 12.259546 | J27: 11.117783
A28: Effective Depth (S=1) | D28: Magnetic Circuit Data | I28: Core Loss Data
B29: Res.= | C29: 30.027266 | E29: Length | F29: Section | G29: Density | H29: AT | I29: Volume | J29: Loss
B30: Reac.= | C30: 30.043499 | D30: Primary Core | E30: 21.598431 | F30: 469.09201 | G30: 10.396492 | H30: 77.331534 | I30: 36952.896 | J30: 1396.2689
A31: Excitation Data | D31: Tooth | E31: 5.05 | F31: 604.30614 | G31: 8.0702659 | H31: 10.210193 | I31: 12206.984 | J31: 306.00648
A32: Excit.Amps | B32: 7.940 / 8.407 | D32: Second.Core | E32: 11.164426 | F32: 697.83482 | G32: 6.9886328 | H32: 20.654187 | I32: Total | J32: 1702.2754
A33: Core Loss | B33: 0.479 / 0.507 | C33: Flux / Pole | D33: Tooth | E33: 3.2049999 | F33: 593.45059 | G33: 8.2178893 | H33: 6.6423243 | I33: C.L.C. | J33: 1.75 / 0.73
A34: NoLoad | B34: 7.95 / 8.42 | C34: 4.8769113 | D34: Air Gap | E34: 0.18 | F34: 1163.985 | G34: 4.1898402 | H34: 600.1509 | I34: S.F.C. | J34: 6.0500002
A35: Load Characteristics | D35: Temp. Rise @ 100%: | E35: 71 / 64 | G35: No Load Loss | H35: 6941.3 / 5601.7 | I35: W.Loss | J35: 2979.0 / 1238.4
A36: Load (%) | B36: 25 | C36: 50 | D36: 75 | E36: 100 | F36: 125 | G36: Primary Loss | H36: 4639.4 / 4483.2 | I36: S.Loss | J36: 344.1 / 143.0
A37: Current (A) | B37: 13.74 / 13.92 | C37: 22.57 / 22.86 | D37: 32.47 / 32.89 | E37: 43.06 / 43.62 | F37: 54.34 / 55.05 | G37: Second. Loss | H37: 2837.9 / 2836.1 | I37: Total C.Loss | J37: 3323.0 / 1381.5
A38: Efficiency | B38: 0.897 / 0.884 | C38: 0.937 / 0.924 | D38: 0.947 / 0.934 | E38: 0.949 / 0.935 | F38: 0.947 / 0.933 | G38: Frict.& Wind. | H38: 3500.0 / 4989.0 | I38: Stray Loss | J38: 4427.4668
A39: P.F. | B39: 0.764 / 0.766 | C39: 0.891 / 0.892 | D39: 0.919 / 0.920 | E39: 0.922 / 0.924 | F39: 0.915 / 0.917 | G39: Starting Data | I39: Slip | J39: PF
A40: Slip | B40: 0.0025 / 0.0025 | C40: 0.0049 / 0.0049 | D40: 0.0074 / 0.0074 | E40: 0.0101 / 0.0101 | F40: 0.0128 / 0.0128 | G40: LRA | H40: 207.7 / 277.8
...

Sheet Data Sheet
A1: TOSHIBA INTERNATIONAL CORPORATION
A2: INDUCTION MOTOR DATA SHEET
A3: File: | B3: CS4350 | I3: HRW / Model Number: | J3: 3504FTQL11E-C
A4: Type: TIKE - Form: FCW4 - 4 Pole - 350 HP - 4000 V - 60 Hz - 5011US - Class F | Q4: Motor Type Selection | T4: Electrical Steel Table
A5: Motor Parameters | F5: PERFORMANCE | J5: DESIGN | K5: TEST | Q5: EPACT | T5: M22 - 26Ga.
A6: Material | D6: M36 - 26Ga. | F6: NL & Impedance Test | Q6: EQP-III | T6: M36 - 26Ga.
A7: Air Gap | D7: 1.8 | F7: No load amps | J7: 8.4 | K7: - | Q7: Exp.Prf. | T7: NCB1 - 26Ga.
A8: Stack length | D8: 520 | F8: No load watts | J8: 4784 | K8: - | Q8: Exp.Prf.-EQPIII | T8: M43 - 26Ga.
A9: Number of turns per coil | D9: 9, 10 | F9: Impedance amps | H9: 3 | I9: f | J9: 60 | K9: - | Q9: Prem. Eff. | T9: M45 - 26Ga.
A10: Wire 1 (size & number) | D10: (.064"x.258")x1 | F10: Impedance volts | H10: 3 | I10: f | J10: 1150 | K10: - | Q10: OWP | T10: M54 - 26Ga.
A11: Wire 2 (size & number) | D11: - | F11: Impedance watts | H11: 3 | I11: f | J11: 13665 | K11: - | Q11: Dry Kiln
A12: Slot fill - circle/square method (%) | D12: - | F12: Temperature Rise (°C)
A13: Connection | D13: 1 x Wye | G13: Winding | I13: 80/115 | J13: 74 / 98 | K13: -
A14: MCL | D14: 977 | G14: Frame | J14: - | K14: -
A15: Allowance for ins. depth | D15: 12.9836 | G15: Bearing PS/OS | J15: - | K15: -
A16: Allowance for ins. width | D16: 3.3468003 | G16: End Ring | J16: - | K16: -
A17: Slot/Wire arrangement | D17: 19 x 1 | F17: Nameplate Data
A18: Effective cross section for coil | D18: - | H18: FLC (A) | J18: 44
A19: Coil grouping | D19: 5 | H19: RPM | J19: 1780
A20: Coil pitch (slot number) | D20: 1 ~ 14 | H20: CODE | J20: F
A21: Method of coil connection | D21: - | H21: S. F. | J21: 1.15 | Q21: Method of Connection
A22: Resistance per phase @ 20 °C | D22: 0.638 | H22: DESIGN | J22: B | Q22: Skip
A23: Coil Weight | B23: Wire1 | D23: 233 | H23: Nom.Eff. (%): | Q23: Adjacent
A24: (lbs.) | B24: Wire2 | D24: - | H24: Min.Eff. (%): | Q24: -
A25: Current Densities (A/cm2) | E25: Bar / ER | H25: P.F. (%):
A26: FL / LR | D26: 422 / 2666 | E26: 364 / 221
A27: Stator Slot Shape (Reference) | F27: Performance
H28: LRC (A) | I28: 293 | J28: 278 | K28: -
H29: LRT (%) | I29: 80 | J29: 170 | K29: -
H30: BDT (%) | I30: 175 | J30: 270 | K30: -
H31: SLIP (%) | J31: 1.01 | K31: -
G32: IEEE-B | H32: Eff. (%) | J32: 93.7 | K32: -
A33: Rotor Slot Shape (Reference) | H33: PF (%) | J33: 92.4 | K33: -
F34: Losses (Watts) | H34: Primary | J34: 5183 | K34: -
H35: Secondary | J35: 3279 | K35: -
H36: Core | J36: 1382 | K36: -
H37: F & W | J37: 3267 | K37: -
H38: Stray | J38: 4427 | K38: -
A39: End Ring (Reference) | F39: Note
G40: Q.C. Limits CS4350
...

Sheet LoginSheet
J1: P | K1: T | L1: L | M1: T
B2: PROJECT HISTORY | J2: E | K2: D | L2: I | M2: Y | N2: H
J3: R | L3: M | M3: P
J4: F | L4: I | M4: E
K5: C | L5: T | N5: I
J6: D | K6: U | M6: T | N6: N
J7: A | K7: R | L7: R | M7: E | N7: S
I8: S | J8: T | K8: V | L8: E | M8: S | N8: U
B9: DATE | C9: PROJECT | D9: SMART NUMBER | E9: QTY | F9: CUSTOMER | G9: REMARKS | H9: LIMIT CODE | I9: F | J9: A | K9: E | L9: V | M9: T | N9: L
B53: REVISION HISTORY
B54: REV | C54: REMARKS | I54: DATE | L54: INIT

Sheet Form
A1: Winding Data Calculation
C2: MCL: 977.0
A3: Coil Resistance | D3: Lead Resistance
A4: 9T: | B4: 0.0306 ~ 0.0294 | D4: AWG. 06 x 3
A5: 10T: | B5: 0.0340 ~ 0.0327 | D5: 0.00440
A6: Coil Dimensions
A7: HM: | B7: 9T: 16.43 | C7: WM: | D7: 9T: 6.75 | E7: WT:
B8: 10T: 18.26 | D8: 10T: 6.75 | E8: 10.20 ~ 9.80
A9: Insulation Allowance | D9: Wire Weight
A10: Depth: | B10: 12.98 | D10: (.064"x.258")x 1: | F10: 233 lbs.
A11: Width: | B11: 3.35
A12: QC Resistance
A13: 1-2, 2-3, 3-1: | C13: 1.314 ~ 1.238

Sheet StallTime
A1: Rating: | B1: 4 Pole - 350.0 HP - 1800 RPM - 4000 V - 60 Hz
A3: Starting Performance
D4: Load Type: Fan / Pump - 1373.0 lb-ft²
A5: RPM | B5: Motor | C5: Load | D5: Accel. | E5: Line | F5: Stator | G5: Rotor
A6: Speed Increment | B6: Torque (%) | C6: Torque (%) | D6: Time (s) | E6: Amps | F6: kW / s | G6: kW / s
A7: 0~180 | B7: 175.1 | C7: 22.5 | D7: 0.574 | E7: 276.6 | F7: 110.9 | G7: 249.7
A8: 180~360 | B8: 175.1 | C8: 11.5 | D8: 0.536 | E8: 274.1 | F8: 101.7 | G8: 209.8
A9: 360~540 | B9: 175.1 | C9: 7.0 | D9: 0.521 | E9: 271.2 | F9: 97.0 | G9: 181.5
A10: 540~720 | B10: 175.0 | C10: 7.0 | D10: 0.522 | E10: 267.7 | F10: 94.8 | G10: 158.8
A11: 720~900 | B11: 175.0 | C11: 11.0 | D11: 0.534 | E11: 263.6 | F11: 94.5 | G11: 139.4
A12: 900~1096 | B12: 175.0 | C12: 18.5 | D12: 0.610 | E12: 258.8 | F12: 104.2 | G12: 121.7
A13: 1096~1292 | B13: 175.4 | C13: 29.5 | D13: 0.654 | E13: 253.0 | F13: 107.4 | G13: 102.2
A14: 1292~1488 | B14: 178.4 | C14: 45.9 | D14: 0.720 | E14: 245.5 | F14: 112.5 | G14: 81.5
A15: 1488~1586 | B15: 186.6 | C15: 62.5 | D15: 0.384 | E15: 237.1 | F15: 55.9 | G15: 55.1
A16: 1586~1684 | B16: 205.0 | C16: 76.2 | D16: 0.370 | E16: 225.1 | F16: 50.3 | G16: 38.6
... A19: 1796~1800 | B19: 102.1 | C19: 99.8 | D19: 0.762 | E19: 26.1 | F19: 3.6 | G19: 99.9
D21: Acceleration Time: 6.6 s
B22: Energy | D22: First Start | F22: Second Start
A23: Stator Winding Rise | B23: 975 kW / s | D23: 25°C | F23: 49°C
A24: Rotor Bar Rise | B24: 1294 kW / s | D24: 43°C | F24: 86°C
A25: End Ring Rise | B25: 171 kW / s | D25: 16°C | F25: 32°C
A27: Locked Rotor Thermal Capability
E28: Cold Condition
B29: Rate of Rise | D29: Power | E29: Rise Limit | F29: Max Time
A30: Stator Copper | B30: 5.8°C / s | D30: 227.3 kW | E30: 160°C | F30: 27.8 s
A31: Rotor Bar | B31: 13.3°C / s | D31: 403.7 kW | E31: 260°C | F31: 19.5 s
A32: Rotor ER | B32: 5.0°C / s | D32: 53.2 kW | E32: 180°C | F32: 36.0 s
E34: Hot Condition
B35: Hot Temp. | D35: Rise Limit | E35: Ambient | F35: Total | G35: Max.Time
A36: Stator Copper | B36: 71°C + | D36: 89°C + | E36: 40°C | F36: = 200°C | G36: 15.4 s
A37: Rotor Bar | B37: 95°C + | D37: 165°C + | E37: 40°C | F37: = 300°C | G37: 12.4 s
A38: Rotor ER | B38: 95°C + | D38: 85°C + | E38: 40°C | F38: = 220°C | G38: 17.0 s
A40: Cold Stall Time: | B40: 51.1 s | D40: Hot Stall Time: | F40: 24.0 s

Sheet MagNoise
A1: Magnetic Noise Verification
A3: Rating: | B3: 4 Pole - 350.0 HP - 1800 RPM - 4000 V - 60 Hz
A5: Electromagnetic Excitation Frequencies
B7: L = | C7: 0 | D7: L = | E7: + 1 | F7: L = | G7: - 1 | H7: Slip = | I7: 0 | J7: Slip = | K7: 0.01
A8: Mode A | B8: 6 | D8: 18 | F8: 6 | H8: 1620.0 Hz | J8: 1604.8 Hz
A9: Mode B | B9: 14 | D9: 26 | F9: 2 | H9: 1380.0 Hz | J9: 1364.8 Hz
A10: Mode C | B10: 10 | D10: 22 | F10: 2 | H10: 1500.0 Hz | J10: 1484.8 Hz
A12: Natural Frequencies of Stator Core
B14: Mode 0 = | D14: 2754.5 Hz | F14: Mode 6 = | H14: 5271.0 Hz
B15: Mode 2 = | D15: 409.7 Hz | F15: Mode 7 = | H15: 7254.8 Hz
B16: Mode 3 = | D16: 1158.7 Hz | F16: Mode 8 = | H16: 9544.4 Hz
B17: Mode 4 = | D17: 2221.8 Hz | F17: Mode 9 = | H17: 12139.4 Hz
B18: Mode 5 = | D18: 3593.1 Hz | F18: Mode 10 = | H18: 15040.0 Hz
A20: Analysis Results
B22: No matching frequencies detected.

Sheet Performance Data Sheet
A1: TOSHIBA INTERNATIONAL CORPORATION | J1: INDEX | L1: MPCF-1033
A2: Industrial Division / Houston Motor Plant | J2: SHEET NO. | L2: 1 of 1
J3: ISSUED | L3: 7/31/13
J4: SUPERSEDES | L4: 11/8/96
J5: REVISION | L5: 2
A6: SQUIRREL CAGE INDUCTION MOTOR | J6: WRITTEN BY | L6: MDC
A7: PERFORMANCE SPECIFICATIONS | J7: APPROVED BY | L7: PAA
B9: CUSTOMER: | C9: HOWDEN FAN
B10: TIC SR No.: | C10: 2174794.1
A12: MOTOR NAMEPLATE DATA
B13: H.P.: | C13: 350 | E13: VOLTS: | F13: 4000 | H13: 3 PH / | I13: 60 Hz | L13: S. RPM: | M13: 1800
B14: FRAME: | C14: 5011US | E14: ENCL: | F14: TEFC | H14: FLAMPS: | I14: 44 | L14: FLRPM: | M14: 1780
B15: FORM: | C15: FCW4 | E15: S.F.: | F15: 1.0 | H15: NEMA DESIGN: | I15: B | L15: INSUL CLASS: | M15: F
B16: TYPE: | C16: TIKE | E16: AMB.: | F16: 40°C | H16: CODE: | I16: F | L16: DUTY: | M16: Cont.
B17: MODEL No.: | C17: A1-10032388 | H17: kW: | I17: -
B18: NOM. EFF.: | C18: - | E18: MIN. EFF.: | F18: - | H18: P.F.: | I18: -
A21: AMPERAGE | E21: TORQUES | I21: **BEARINGS:
A22: LOCKED ROTOR: | D22: 278 | G22: FULL LOAD (lb-ft.): | H22: 1033 | K22: DRIVE END:
G23: LOCKED ROTOR (%): | H23: 170 | K23: OPPOSITE DRIVE END:
G24: BREAK DOWN (%): | H24: 270
A28: EFFICIENCY | H28: POWER FACTOR
C29: FULL LOAD: | D29: 93.5 | J29: FULL LOAD: | K29: 92.4
C30: 3/4 LOAD: | D30: 93.3 | J30: 3/4 LOAD: | K30: 92.1
C31: 1/2 LOAD: | D31: 92.3 | J31: 1/2 LOAD: | K31: 89.3
A35: ALL CHARACTERISTICS ARE AVERAGE EXPECTED VALUES BASED UPON RATED VOLTAGE,
A36: FREQUENCY AND SINEWAVE POWER INPUT.
A37: THE DECLARED LOCKED ROTOR CURRENT HAS A TOLERANCE OF 20%
A38: * TEMPERATURE RISE WILL BE CONSISTENT WITH INSULATION, AMBIENT AND SERVICE FACTOR AS
A39: DEFINED BY NEMA-MG-12 OR -20
A40: ** BEARINGS ARE THE ONLY RECOMMENDED SPARE PART(S).
J42: CERTIFIED BY: | K42: JERRY R
J44: DATE: | K44: 43977
A59: - | B59: 6205ZZ | D59: 1 | E59: -
A60: TEFC | B60: 6206UU | D60: 1.15 | E60: A
A61: ODP | B61: 6207ZZ | E61: B
B62: 6208UU
B63: 6211ZZ
B64: 6211C3
B65: 6211ZZC3
B66: 6305UUC3
...

Sheet STCurve
A2: TOSHIBA INTERNATIONAL CORPORATION
A3: Speed Torque/Current Curve
A6: Model #: | B6: ='Performance Data Sheet'!C17 -> A1-10032388 | E6: FLAmps: | F6: ='Performance Data Sheet'!I14 & " A" -> 44 A
A7: Enclosure: | B7: ='Performance Data Sheet'!F14 -> TEFC | C7: Voltage: | D7: ='Performance Data Sheet'!F13 & " V" -> 4000 V | E7: Frame: | F7: ='Performance Data Sheet'!C14 -> 5011US
A8: Pole: | B8: 4 | C8: Frequency: | D8: 3 PH / 60 Hz | E8: Ins. Class: | F8: F
A9: HP: | B9: 350 | C9: Rotor Inertia: | D9: 172.7 lb-ft² | E9: Date: | F9: ='Performance Data Sheet'!K44 -> 43977
A10: FLRPM: | B10: 1780 | C10: Load Inertia: | D10: 2214.0 lb-ft² | E10: File: | F10: CS4350
B12: Locked Rotor Amps: | C12: ='Performance Data Sheet'!D22 & "A" -> 278A | D12: Load Type: | E12: Fan / Pump
B13: Locked Rotor Torque: | C13: 1.7 | D13: Starting at: | E13: FV / 0.80 (V)
B14: Breakdown Torque: | C14: 2.7 | D14: Accel. Time: | E14: 13 / 16 (s)
B15: Rated Torque: | C15: 1033 lb-ft
A39: Comments: | B39: PROJECT | C39: ='Performance Data Sheet'!C10 -> 2174794.1 | E39: D.E.Curve #: | F39: =F10 -> CS4350
C43: Prepared by: | D43: ='Performance Data Sheet'!K42 -> JERRY R | E43: Checked by:
D53: Load | E53: Torque 80% | F53: LRA 80%
A54: 100 | B54: 0 | C54: 0.18077993 | D54: 100 | E54: 0 | F54: 6.3634543
A55: 99.2 | B55: 104.13111 | C55: 110.78911 | D55: 98.400002 | E55: 66.643913 | F55: 88.631287
A56: 96 | B56: 270 | C56: 384.92624 | D56: 89.75 | E56: 172.80001 | F56: 307.94101
A57: 90.857143 | B57: 229.86392 | C57: 493.72348 | D57: 76.228569 | E57: 147.11291 | F57: 394.97879
A58: 85.714285 | B58: 194.24652 | C58: 530.29669 | D58: 62.85714 | E58: 124.31778 | F58: 424.23737
A59: 80.571428 | B59: 179.10743 | C59: 548.10925 | D59: 51.257141 | E59: 114.62875 | F59: 438.4874
A60: 70.285714 | B60: 171.23513 | C60: 568.42871 | D60: 33.485714 | E60: 109.59049 | F60: 454.74298
A61: 59.999999 | B61: 170 | C61: 582.61725 | D61: 22 | E61: 108.8 | F61: 466.09381
A62: 50 | B62: 170.00001 | C62: 594.48126 | D62: 14 | E62: 108.80001 | F62: 475.58502
A63: 39.999998 | B63: 170.00005 | C63: 604.55157 | D63: 7.9999995 | E63: 108.80004 | F63: 483.64127
A64: 30.000001 | B64: 170.04347 | C64: 613.13995 | D64: 5.9999995 | E64: 108.82783 | F64: 490.51196
A65: 19.999999 | B65: 170.05945 | C65: 620.3667 | D65: 8.000001 | E65: 108.83805 | F65: 496.29337
... A67: 0 | B67: 170 | C67: 631.81818 | D67: 30 | E67: 108.8 | F67: 505.45456

Sheet Thermdam
A2: TOSHIBA INTERNATIONAL CORPORATION
A3: Thermal Limit & Acceleration Curves
A4: Design Values (For Reference Only)
A6: Model #: | B6: ='Performance Data Sheet'!C17 -> A1-10032388 | E6: FLAmps: | F6: ='Performance Data Sheet'!I14 & " A" -> 44 A
A7: Enclosure: | B7: ='Performance Data Sheet'!F14 -> TEFC | C7: Voltage: | D7: ='Performance Data Sheet'!F13 & " V" -> 4000 V | E7: Frame: | F7: ='Performance Data Sheet'!C14 -> 5011US
A8: Pole: | B8: 4 | C8: Frequency: | D8: 3 PH / 60 Hz | E8: Ins. Class: | F8: F
A9: HP: | B9: 350 | C9: Rotor Inertia: | D9: 172.7 lb-ft² | E9: Date: | F9: ='Performance Data Sheet'!K44 -> 43977
A10: FLRPM: | B10: 1780 | C10: Load Inertia: | D10: 2214.0 lb-ft² | E10: File: | F10: CS4350
A39: Comments: | B39: PROJECT | C39: ='Performance Data Sheet'!C10 -> 2174794.1 | E39: D.E.Curve #: | F39: =F10 -> CS4350
C43: Prepared by: | D43: ='Performance Data Sheet'!K42 -> JERRY R | E43: Checked by:
F50: =5252.1*B50/D53 -> #DIV/0!
D66: =D65/D64 -> #DIV/0!
A67: Current (%) | B67: Cold | C67: Hot | E67: CURRENT (%) | F67: Accel. Time
A68: 631.81818 | B68: 35 | C68: 15 | E68: =A68 -> 631.81818 | F68: 0.0001 | G68: =0.8*E68 -> 505.45455 | H68: =F68 -> 0.0001
A69: 559.21938 | B69: =((A68/A69)^2)*B68 -> 44.677396 | C69: =((A68/A69)^2)*C68 -> 19.147455 | E69: 629.09091 | F69: 0.917 | G69: =0.8*E69 -> 503.27273 | H69: =1.23*F69 -> 1.12791
A70: 486.5988 | B70: =((A68/A70)^2)*B68 -> 59.007908 | C70: =((A68/A70)^2)*C68 -> 25.289103 | E70: 623.40909 | F70: 1.77 | G70: =0.8*E70 -> 498.72727 | H70: =1.23*F70 -> 2.1771
A71: 414 | B71: =((A68/A71)^2)*B68 -> 81.517641 | C71: =((A68/A71)^2)*C68 -> 34.936132 | E71: 616.81818 | F71: 2.5999999 | G71: =0.8*E71 -> 493.45455 | H71: =1.23*F71 -> 3.1979999
A72: =A71-100 -> 314 | B72: =((A68/A72)^2)*B68 -> 141.70755 | E72: 608.86364 | F72: 3.4299998 | G72: =0.8*E72 -> 487.09091 | H72: =1.23*F72 -> 4.2188998
A73: =A72-100 -> 214 | B73: =((A68/A73)^2)*B68 -> 305.08773 | E73: 599.54545 | F73: 4.2809997 | G73: =0.8*E73 -> 479.63636 | H73: =1.23*F73 -> 5.2656296
A74: 270 | B74: =((A68/A74)^2)*B68 -> 191.65703 | C74: =((A68/A74)^2)*C68 -> 82.138727 | E74: 588.63636 | F74: 5.5 | G74: =0.8*E74 -> 470.90909 | H74: =1.23*F74 -> 6.765
A75: 180 | B75: =((A68/A75)^2)*B69 -> 550.46167 | C75: =((A68/A75)^2)*C68 -> 184.81214 | E75: 575.45455 | F75: 7.2 | G75: =0.8*E75 -> 460.36364 | H75: =1.23*F75 -> 8.856
A76: 145 | B76: =((A68/A76)^2)*B68 -> 664.53258 | C76: =((A68/A76)^2)*C68 -> 284.79968 | E76: 558.18182 | F76: 8.7 | G76: =0.8*E76 -> 446.54545 | H76: =1.23*F76 -> 10.701
A77: 125 | C77: =CEILING(C76*2,100) -> 600 | E77: 539.09091 | F77: 10 | G77: =0.8*E77 -> 431.27273 | H77: =1.23*F77 -> 12.3
A78: 125 | C78: =2*C77 -> 1200 | E78: 512.04545 | F78: 10.8 | G78: =0.8*E78 -> 409.63636 | H78: =1.23*F78 -> 13.284
A79: 125 | C79: 10000 | E79: 439.31818 | F79: 11.5 | G79: =0.8*E79 -> 351.45455 | H79: =1.23*F79 -> 14.145
E80: 247.95455 | F80: 12 | G80: =0.8*E80 -> 198.36364 | H80: =1.23*F80 -> 14.76
E81: 120 | F81: 13 | G81: 120 | H81: =1.23*F81 -> 15.99

Sheet Performance
A2: TOSHIBA INTERNATIONAL CORPORATION
A3: Performance Curve
A4: Design Values (For Reference Only)
A6: Model #: | B6: ='Performance Data Sheet'!C17 -> A1-10032388 | E6: FLAmps: | F6: ='Performance Data Sheet'!I14 & " A" -> 44 A
A7: Enclosure: | B7: ='Performance Data Sheet'!F14 -> TEFC | C7: Voltage: | D7: ='Performance Data Sheet'!F13 & " V" -> 4000 V | E7: Frame: | F7: ='Performance Data Sheet'!C14 -> 5011US
A8: Pole: | B8: 4 | C8: Frequency: | D8: 3 PH / 60 Hz | E8: Ins. Class: | F8: F
A9: HP: | B9: 350 | C9: Rotor Inertia: | D9: 172.7 lb-ft² | E9: Date: | F9: ='Performance Data Sheet'!K44 -> 43977
A10: FLRPM: | B10: 1780 | C10: Load Inertia: | D10: 2214.0 lb-ft² | E10: File: | F10: CS4350
B12: Locked Rotor Amps: | C12: ='Performance Data Sheet'!D22 & "A" -> 278A | D12: Load Type: | E12: Fan / Pump
B13: Locked Rotor Torque: | C13: 1.7 | D13: Starting at: | E13: FV / 0.80 (V)
B14: Breakdown Torque: | C14: 2.7 | D14: Accel. Time: | E14: 13 / 16 (s)
B15: Rated Torque: | C15: 1033 lb-ft
A39: Comments: | B39: PROJECT | C39: ='Performance Data Sheet'!C10 -> 2174794.1 | E39: D.E.Curve #: | F39: =F10 -> CS4350
C43: Prepared by: | D43: ='Performance Data Sheet'!K42 -> JERRY R | E43: Checked by:
A53: Load | B53: Efficiency | C53: PF | D53: Amps | E53: RPM | F53: Input Watts
A54: 0 | D54: 8.1277218 | E54: 100 | F54: 7.1082174
A55: 25 | B55: 88.418854 | C55: 76.590118 | D55: 14.035774 | E55: 78.890041 | F55: 9.3095135
A56: 50 | B56: 92.347733 | C56: 89.274544 | D56: 23.058451 | E56: 64.438926 | F56: 17.826892
A57: 75 | B57: 93.33902 | C57: 92.077576 | D57: 33.1786 | E57: 49.582287 | F57: 26.456345
A58: 100 | B58: 93.491844 | C58: 92.42746 | D58: 43.998631 | E58: 33.255477 | F58: 35.217463
A59: 125 | B59: 93.315025 | C59: 91.718742 | D59: 55.528278 | E59: 17.568489 | F59: 44.105242

Sheet Circuit Param.
A1: TOSHIBA INTERNATIONAL CORPORATION | J1: INDEX | L1: MPCF-1109
A2: Industrial Division / Houston Motor Plant | J2: SHEET NO. | L2: 1 of 1
J3: ISSUED | L3: 38309
A4: EQUIVALENT CIRCUIT DATA | J4: SUPERSEDES | L4: NEW
J5: REVISION | L5: REV. 0
J6: WRITTEN BY | L6: MDC
A7: All Values are Presented in Ohms/Phase, Equivalent Wye Connection. | J7: APPROVED BY | L7: Paul Anderson
B9: CUSTOMER: | C9: HOWDEN FAN
B10: TIC SR No.: | C10: 2174794.1
A12: MOTOR NAMEPLATE DATA
B13: H.P.: | C13: 350 | E13: VOLTS: | F13: 4000 | H13: 3 PH / | I13: 60 Hz | L13: S. RPM: | M13: 1800
B14: FRAME: | C14: 5011US | E14: ENCL: | F14: TEFC | H14: FLAMPS: | I14: 44 | L14: FLRPM: | M14: 1780
B15: FORM: | C15: FCW4 | E15: S.F.: | F15: 1.0 | H15: NEMA DESIGN: | I15: B | L15: INSUL CLASS: | M15: F
B16: TYPE: | C16: TIKE | E16: AMB.: | F16: 40°C | H16: CODE: | I16: F | L16: DUTY: | M16: Cont.
B17: MODEL No.: | C17: A1-10032388 | H17: kW: | I17: -
B18: NOM. EFF.: | C18: - | E18: MIN. EFF.: | F18: - | H18: P.F.: | I18: -
A21: Primary Resistance (R1) : | F21: 0.834
A22: Secondary Resistance (R2) : | F22: 0.579
A23: Starting Resistance (R3) : | F23: 1.62
A25: Primary Reactance (X1) : | F25: 5.64
A26: Secondary Reactance (X2) : | F26: 4.41
A27: Starting Reactance (X3) : | F27: 3.95
A29: Magnetizing Reactance (Xm) : | F29: 274.9
A31: Transient Reactance : | F31: 9.98
A32: Sub Transient Reactance : | F32: 7.71
A33: Short Circuit Time Constant : | F33: 4.41
A34: Sub Transient Time Constant : | F34: 0.0105
A35: Open Circuit Time Constant : | F35: 1.27
I40: CERTIFIED BY: | J40: =[11]PerfData!K43 -> JERRY R
I42: DATE: | J42: 43977

Sheet PERFORMANCE data
A1: TOSHIBA INTERNATIONAL CORPORATION | J1: INDEX | L1: MPCF-1082
A2: Industrial Division / Houston Motor Plant | J2: SHEET NO. | L2: 1 of 1
J3: ISSUED | L3: 2/14/02
J4: SUPERSEDES | L4: NEW
J5: REVISION | L5: 0
A6: SQUIRREL CAGE INDUCTION MOTOR | J6: WRITTEN BY | L6: M. CAMPBELL
A7: API 541 PERFORMANCE SPECIFICATIONS | J7: APPROVED BY | L7: P.A.A
B9: CUSTOMER: | C9: HOWDEN FAN
B10: TIC SR No.: | C10: 2174794.1
A12: MOTOR NAMEPLATE DATA
B13: H.P.: | C13: 350 | E13: VOLTS: | F13: 4000 | H13: 3 PH / | I13: 60 Hz | L13: S. RPM: | M13: 1800
B14: FRAME: | C14: 5011US | E14: ENCL: | F14: TEFC | H14: FLAMPS: | I14: 44 | L14: FLRPM: | M14: 1780
B15: FORM: | C15: FCW4 | E15: S.F.: | F15: 1.0 | H15: NEMA DESIGN: | I15: B | L15: INSUL CLASS: | M15: F
B16: TYPE: | C16: TIKE | E16: AMB.: | F16: 40°C | H16: CODE: | I16: F | L16: DUTY: | M16: Cont.
B17: MODEL No.: | C17: A1-10032388 | H17: kW: | I17: -
B18: NOM. EFF.: | C18: - | E18: MIN. EFF.: | F18: - | H18: P.F.: | I18: -
A20: LOCKED ROTOR DATA
D21: AMPS AT RATED VOLTAGE: | E21: 278 | I21: POWER FACTOR: | J21: 30.7
D22: AMPS AT 80% VOLTAGE: | E22: 221
A24: TORQUE VALUES | H24: CURVE NUMBERS
E25: FULL LOAD (LB.FT): | F25: 1033 | J25: SPEED-TORQUE CURVE: | K25: CS4350
E26: LOCKED ROTOR TORQUE (% OF FLT): | F26: 170 | J26: SPEED-CURRENT CURVE: | K26: CS4350
E27: PULL UP TORQUE (% OF FLT): | F27: 170 | J27: ACCELERATION CURVE: | K27: CS4350
E28: BREAKDOWN TORQUE (% OF FLT): | F28: 270
A30: LOCKED ROTOR WITHSTAND TIMES
A31: COLD CONDITION | H31: HOT CONDITION
C32: 100% VOLTAGE: | D32: 35 | J32: 100% VOLTAGE: | K32: 15
C33: 90% VOLTAGE: | D33: 43 | J33: 90% VOLTAGE: | K33: 19
C34: 80% VOLTAGE: | D34: 55 | J34: 80% VOLTAGE: | K34: 23
C35: 70% VOLTAGE: | D35: 71 | J35: 70% VOLTAGE: | K35: 30
A37: DESIGN DATA
C38: MOTOR ROTOR wk2 (LB.FT2): | D38: 172.7 | J38: NO LOAD CURRENT: | K38: 8.4
C39: AIR GAP: | D39: 1.8 | J39: ACCELERATION TIME: | K39: 13/16
D40: LOAD CHARACTERISTICS
D41: LOAD | G41: 1/2 | H41: 3/4 | I41: FULL | J41: SF
D42: AMPS (A) | G42: 22.8 | H42: 33 | I42: 44 | J42: -
D43: EFFICIENCY (%) | G43: 92.4 | H43: 93.4 | I43: 93.5 | J43: -
D44: POWER FACTOR (%) | G44: 89.2 | H44: 92 | I44: 92.4 | J44: -
D45: GUARENTEED EFFICIENCY (%) | G45: - | H45: - | I45: - | J45: -
A46: EFFICIENCY TO BE DETERMINED BY IEEE 112, METHOD B
...

Sheet MPCF-1202 SOUND
A1: TOSHIBA INTERNATIONAL CORPORATION | J1: INDEX | L1: MPCF-1085
A2: Industrial Division / Houston Motor Plant | J2: SHEET NO. | L2: 1 of 1
J3: ISSUED | L3: 37432
J4: SUPERSEDES | L4: NEW
J5: REVISION | L5: 0
A6: INDUCTION MOTOR CERTIFIED SOUND TEST RESULTS | J6: WRITTEN BY | L6: MDC
A7: (PER ANSI S12.34) | J7: APPROVED BY | L7: Paul Anderson
B9: CUSTOMER :
B10: REF: | C10: H402112
B11: TIC SR No.: | G11: TERMINAL BOX LOCATION: | L11: F-1 | Z11: REFERENCE LAB 9896
B12: DATE of TEST: | C12: 39961 | K12: MOTOR SERIAL NUMBER: | L12: 081204611 | Z12: TEFC 4P 500HP
A13: READINGS TAKEN AT NO-LOAD IN A FREE FIELD AND REPORTED IN PRESSURE | Z13: H402112
R14: =SUMIF(P20:P36,">1",P20:P36) -> 1.6738842e+09 | S14: =COUNTIF(P20:P36,">1") -> 12 | T14: =R14/S14 -> 1.3949035e+08 | Z14: MOTOR COVER ONLY
A15: OVERALL dBA SUMMARY
A17: Ambient | B17: 58.5 | C17: dBA
P18: LOG VALUES | R18: AVERAGE
A19: Position
A20: 1) | B20: 85.7 | C20: dBA | P20: =10^(B20/10) -> 3.7153523e+08 | R20: =R14/S14 -> 1.3949035e+08
A21: 2) | B21: - | C21: dBA | P21: =10^(B21/10) -> 1
A22: 3) | B22: 81.8 | C22: dBA | P22: =10^(B22/10) -> 1.5135612e+08
A23: 4) | B23: - | C23: dBA | P23: =10^(B23/10) -> 1
A24: 5) | B24: - | C24: dBA | P24: =10^(B24/10) -> 1
A25: 6) | B25: - | C25: dBA | P25: =10^(B25/10) -> 1 | U25: =IF(R37=56,R35+9.2,IF(AND(OR(R37=143,R37=145),R38="TEFC"),R35+9.1,IF(AND(OR(R37=182,R37=184),R38="TEFC"),R35+9.3,IF(AND(OR(R37=213,R37=215),R38="TEFC"),R35+9.6,IF(AND(OR(R37=254,R37=256),R38="TEFC"),R35+9.9,IF(AND(OR(R37=284,R37=286),R38="TEFC"),R35+10.1,U26)))))) -> 92.745442
A26: 7) | B26: 81.3 | C26: dBA | P26: =10^(B26/10) -> 1.3489629e+08 | U26: =IF(AND(OR(R37=324,R37=326),R38="TEFC"),R35+10.3,IF(AND(OR(R37=364,R37=365),R38="TEFC"),R35+10.6,IF(AND(OR(R37=404,R37=405),R38="TEFC"),R35+10.9,IF(AND(OR(R37=444,R37=445),R38="TEFC"),R35+11.3,IF(AND(R37=447,R38="TEFC"),R35+11.4,IF(AND(R37=449,R38="TEFC"),R35+11.7,U27)))))) -> 92.745442
A27: 8) | B27: - | C27: dBA | P27: =10^(B27/10) -> 1 | U27: =IF(AND(R37="N449",R38="TEFC"),R35+11.9,IF(AND(R37=505,R38="TEFC"),R35+11.6,IF(AND(R37="N587",R38="TEFC"),R35+12,IF(AND(R37=5010,R38="TEFC"),R35+12.1,IF(AND(R37=5810,R38="TEFC"),R35+12.7,IF(AND(OR(R37=143,R37=145),R38="ODP"),R35+9,U28)))))) -> ERROR
A28: 9) | B28: 82.4 | C28: dBA | P28: =10^(B28/10) -> 1.7378008e+08 | U28: =IF(AND(OR(R37=182,R37=184),R38="ODP"),R35+9.2,IF(AND(OR(R37=213,R37=215),R38="ODP"),R35+9.5,IF(AND(OR(R37=254,R37=256),R38="ODP"),R35+9.9,IF(AND(OR(R37=284,R37=286),R38="ODP"),R35+10,IF(AND(OR(R37=324,R37=326),R38="ODP"),R35+10.2,U29))))) -> ERROR
A29: 10) | B29: 79.9 | C29: dBA | P29: =10^(B29/10) -> 97723722 | U29: =IF(AND(OR(R37=364,R37=365),R38="ODP"),R35+10.4,IF(AND(R37=404,R38="ODP"),R35+10.6,IF(AND(R37=405,R38="ODP"),R35+10.7,IF(AND(R37=444,R38="ODP"),R35+10.9,IF(AND(R37=445,R38="ODP"),R35+11,U30))))) -> ERROR
A30: 11) | B30: 77.1 | C30: dBA | P30: =10^(B30/10) -> 51286138 | U30: =IF(AND(R37=447,R38="ODP"),R35+11.1,IF(AND(OR(R37=449,R37=505),R38="ODP"),R35+11.3,IF(AND(R37=507,R38="ODP"),R35+11.4,IF(AND(R37=509,R38="ODP"),R35+11.8,"ERROR")))) -> ERROR
A31: 13) | B31: 81.6 | C31: dBA | P31: =10^(B31/10) -> 1.4454398e+08 | R31: overall sound:
A32: 14) | B32: 80.6 | C32: dBA | P32: =10^(B32/10) -> 1.1481536e+08
A33: 15) | B33: 80.5 | C33: dBA | P33: =10^(B33/10) -> 1.1220185e+08 | R33: =LOG10(R20) -> 8.1445442
A34: 16) | B34: 78.7 | C34: dBA | P34: =10^(B34/10) -> 74131024
A35: 17) | B35: 82 | C35: dBA | P35: =10^(B35/10) -> 1.5848932e+08 | R35: =R33*10 -> 81.445442
A36: 18) | B36: 79.5 | C36: dBA | P36: =10^(B36/10) -> 89125094
P37: FRAME | R37: 445
A38: Overall Sound : | C38: =R35 -> 81.445442 | P38: ENCL | R38: TEFC
P39: SOUND POWER | R39: =ROUNDUP(U25,0) -> 93
A53: NOTE: Data on Test From | F53: This | H53: Motor.
E54: (This or Duplicate)
A56: LAB NO.: | D56: 9896
...
