Workbook
Name Print_Area_MI: 'Circuit Param.'!$A$8:$N$43
Name Print_Area_MI: 'PERFORMANCE data'!$A$10:$N$18
Name Print_Area_MI: 'Performance Data Sheet'!$A$10:$N$42
Name thermal: #REF!
Name transfer: #REF!
Name unit_sht: "unit_sht"
Name vassvelo: #REF!
Name velcoity: #REF!
Name viscosity: #REF!
Name vollheatre: #REF!
Name volumetri: #REF!
Name weight: #REF!
Name weights: #REF!

Sheet DesignSheet
A1: TOSHIBA INTERNATIONAL CORPORATION | I1: Calc. Code: | J1: 2-2-2-0-1-2
A2: 3-PHASE SQUIRREL CAGE INDUCTION MOTOR DESIGN SHEET | J2: B.L.-1 P.F.-1
A3: File: | B3: N:\DESPRO\RAT FILES\CS4450.rat | G3: Date: | H3: 45707 | I3: Time: | J3: 0.29195602
A4: Pole | B4: HP | C4: RPM | D4: Form | E4: Voltage | F4: Frequency | G4: Temperature | H4: FLSpeed | I4: FLSlip | J4: Frame
A5: 4 | B5: 450.00002 | C5: 1800 | D5: FCW4 | E5: 4000 | F5: 60 | G5: 105 | H5: 1782.2 / 1780.0 | I5: 0.0099 / 0.0111 | J5: 5011US
A6: Core Data | D6: Winding Data | H6: Constant Data
B7: Primary | C7: Secondary | F7: Bar | G7: End Ring | H7: St. Slot Pitch | I7: 18.430661 | J7: LR Test Data
A8: Air Gap | B8: 1.8 | H8: Rt. Slot Pitch | I8: 21.890599 | J8: ES
A9: Space Fac. | B9: 0.93000001 | D9: Pitch | E9: 1 ~ 14 | F9: Cross Section Area | H9: Mean Value | I9: 20.16063 | J9: 818.63783
A10: Core Length | B10: 580 | C10: 580 | F10: UB: 240.0 | G10: UER: 1575.0 | H10: Eff.T.W.St. | I10: 11.353491 | J10: WS
A11: OD | B11: 550 | C11: 348.4 | D11: Coil Pitch | E11: 0.86658 | H11: Eff.T.W.Rt. | I11: 21.171258 | J11: 16655.125
A12: ID | B12: 352 | C12: 140 | D12: Slot Fill | E12: - | F12: EBL: 63.5 | G12: ERD1: 278.4 | H12: St.Carter Fac. | I12: 1.1944753 | J12: IS
A13: Core Depth | B13: 48.5 | C13: 72.150001 | D13: Con./Slot | E13: 16 | G13: ERT: 45.00 | H13: Rt.Carter Fac. | I13: 1.0339772 | J13: 55.053875
A14: Eff.Core L. | B14: 539.40002 | C14: 539.40002 | D14: Wire Size 1 | E14: (.081"x.258")x1 | F14: (8 x 30) | G14: ERH: 35.00 | H14: Carter Factor | I14: 1.2350602 | J14: Volts / Turn
A15: Slot Data | D15: Wire Size 2 | E15: - | H15: Short. Factor | I15: 0.97811905 | J15: 14.43418
A16: Number | B16: 60 | C16: 50 | D16: // Circuits | E16: 1 | H16: Distrib. Factor | I16: 0.956506 | J16: AC
A17: Kind | B17: Open | C17: Rectang | D17: Connection | E17: Wye | H17: Wind. Factor | I17: 0.93557674 | J17: 477.93293
A18: Skew | B18: - | C18: 0 | D18: MCL | E18: 1037 | F18: 752 | H18: Reactance | I18: (Coeff.: 0.1603)
A19: Depth | B19: 50.5 | C19: 32.049999 | D19: No.Cond./Ph. | E19: 320 | I19: Running | J19: Start
A20: Width | B20: 7.08 - 7.08 | C20: 8.0500002 | D20: Res. (20°C) | E20: 0.43880833 | H20: Stator Slot | I20: 22.258333 | J20: 22.258333
A21: Opening | B21: 10.1 | C21: 3 | D21: (105°C) | E21: 0.58536514 | F21: 0.39427251 | G21: 0.047828004 | H21: Rotor Slot | I21: 18.094044 | J21: 12.169863
A22: Tip Depth | B22: 2.8299999 | C22: 2 | D22: Material | E22: CU | F22: Special | G22: Special | H22: Zigzag | I22: 5.5395637 | J22: 5.0767641
A23: T.Min.Wid. | B23: 8.3306608 | C23: 9.817214 | D23: Spec.Resist. | E23: 1.742 | F23: 1.724 | G23: 1.724 | H23: Coil End | I23: 8.5741557 | J23: Skew R.: 0.00
A24: Low. R. | B24: 0 | C24: 0.80000001 | D24: Spec.Gravity | E24: 8.8900003 | F24: 8.8900003 | G24: 8.8900003 | H24: Belt Leakage | I24: 4.6158724 | J24: 4.3039802
A25: Up. R. | B25: - | C25: 0.80000001 | D25: Weight (kg) | H25: Total Resist. | I25: 1.0274657 | J25: 1.8316853
A26: Wedge Dep. | B26: 2.83 - 2.00 | C26: Magnetic | D26: Wire 1 | E26: 116.58798 | F26: 85.023963 | G26: 27.655104 | H26: Total React. | I26: 9.4736052 | J26: 8.387639
A27: Duct | B27: - | C27: - | D27: Wire 2 | E27: - | F27: - | G27: - | H27: Impedance | I27: 9.5291595 | J27: 8.5853109
A28: Effective Depth (S=1) | D28: Magnetic Circuit Data | I28: Core Loss Data
B29: Res.= | C29: 30.027266 | E29: Length | F29: Section | G29: Density | H29: AT | I29: Volume | J29: Loss | M29: =RIGHT(F$41,SEARCH("/",F$41,1)-1) -> 1775.4 | N29: 125RPM | P29: Kline/in2
B30: Reac.= | C30: 30.043499 | D30: Primary Core | E30: 21.598431 | F30: 523.21802 | G30: 11.068679 | H30: 93.588633 | I30: 41216.693 | J30: 1723.7419 | M30: =RIGHT(E$41,SEARCH("/",E$41,1)-1) -> 1780.0 | N30: 100RPM | P30: =G30*6.4516 -> 71.410687
A31: Excitation Data | D31: Tooth | E31: 5.05 | F31: 674.0338 | G31: 8.5920501 | H31: 11.262477 | I31: 13615.483 | J31: 377.77551 | M31: =RIGHT(D$41,SEARCH("/",D$41,1)-1) -> 1784.8 | N31: 75RPM | P31: =G31*6.4516 -> 55.43247
A32: Excit.Amps | B32: 10.183 / 11.356 | D32: Second.Core | E32: 11.164426 | F32: 778.35424 | G32: 7.4404838 | H32: 20.979115 | I32: Total | J32: 2101.5174 | M32: =RIGHT(C$41,SEARCH("/",C$41,1)-1) -> 1789.1 | N32: 50RPM | P32: =G32*6.4516 -> 48.003025
A33: Core Loss | B33: 0.594 / 0.663 | C33: Flux / Pole | D33: Tooth | E33: 3.2049999 | F33: 661.92568 | G33: 8.749218 | H33: 7.4002312 | I33: C.L.C. | J33: 1.75 / 0.81 | M33: =RIGHT(B$41,SEARCH("/",B$41,1)-1) -> 1793.4 | N33: 25RPM | P33: =G33*6.4516 -> 56.446455
A34: NoLoad | B34: 10.20 / 11.38 | C34: 5.7913321 | D34: Air Gap | E34: 0.18 | F34: 1298.291 | G34: 4.4607351 | H34: 638.95376 | I34: S.F.C. | J34: 6.0500002 | P34: =G34*6.4516 -> 28.778878
A35: Load Characteristics | D35: Temp. Rise @ 100%: | E35: 74 / 74 | G35: No Load Loss | H35: 7757.4 / 6810.0 | I35: W.Loss | J35: 3677.7 / 1692.3
A36: Load (%) | B36: 25 | C36: 50 | D36: 75 | E36: 100 | F36: 125 | G36: Primary Loss | H36: 5322.6 / 5490.0 | I36: S.Loss | J36: 443.2 / 204.0
A37: Current (A) | B37: 17.49 / 17.78 | C37: 28.81 / 29.29 | D37: 41.50 / 42.19 | E37: 55.05 / 55.97 | F37: 69.48 / 70.63 | G37: Second. Loss | H37: 3543.9 / 3829.6 | I37: Total C.Loss | J37: 4120.9 / 1896.3
A38: Efficiency | B38: 0.909 / 0.899 | C38: 0.945 / 0.934 | D38: 0.953 / 0.942 | E38: 0.954 / 0.943 | F38: 0.952 / 0.941 | G38: Frict.& Wind. | H38: 3500.0 / 4732.4 | I38: Stray Loss | J38: 4348.4004 | L38: =LEFT(E38,SEARCH("/",E38,1)-1) -> 0.954 | M38: =RIGHT(E38,SEARCH("/",E38,1)-1) -> 0.943 | N38: =M38/L38 -> 0.9884696 | O38: Eff.
A39: P.F. | B39: 0.762 / 0.758 | C39: 0.890 / 0.886 | D39: 0.919 / 0.914 | E39: 0.922 / 0.918 | F39: 0.916 / 0.911 | G39: Starting Data | I39: Slip | J39: PF | L39: =LEFT(E39,SEARCH("/",E39,1)-1) -> 0.922 | M39: =RIGHT(E39,SEARCH("/",E39,1)-1) -> 0.918 | N39: =M39/L39 -> 0.99566161 | O39: PF.
A40: Slip | B40: 0.0024 / 0.0037 | C40: 0.0048 / 0.0060 | D40: 0.0072 / 0.0085 | E40: 0.0099 / 0.0111 | F40: 0.0125 / 0.0137 | G40: LRA | H40: 269.0 / 355.5 | L40: =LEFT(E37,SEARCH("/",E37,1)-1) -> 55.05 | M40: 56 | N40: =M40/L40 -> 1.017257 | O40: Current
...

Sheet DesignSheet 0.8V
A1: TOSHIBA INTERNATIONAL CORPORATION | I1: Calc. Code: | J1: 2-2-2-0-1-2
A2: 3-PHASE SQUIRREL CAGE INDUCTION MOTOR DESIGN SHEET | J2: B.L.-1 P.F.-1
A3: File: | B3: N:\DESPRO\RAT FILES\CS4450.rat | G3: Date: | H3: 45707 | I3: Time: | J3: 0.4253125
A4: Pole | B4: HP | C4: RPM | D4: Form | E4: Voltage | F4: Frequency | G4: Temperature | H4: FLSpeed | I4: FLSlip | J4: Frame
A5: 4 | B5: 450.00002 | C5: 1800 | D5: FCW4 | E5: 3200 | F5: 60 | G5: 105 | H5: 1770.5 / 1768.3 | I5: 0.0164 / 0.0176 | J5: 5011US
A6: Core Data | D6: Winding Data | H6: Constant Data
B7: Primary | C7: Secondary | F7: Bar | G7: End Ring | H7: St. Slot Pitch | I7: 18.430661 | J7: LR Test Data
A8: Air Gap | B8: 1.8 | H8: Rt. Slot Pitch | I8: 21.890599 | J8: ES
A9: Space Fac. | B9: 0.93000001 | D9: Pitch | E9: 1 ~ 14 | F9: Cross Section Area | H9: Mean Value | I9: 20.16063 | J9: 1077.3526
A10: Core Length | B10: 580 | C10: 580 | F10: UB: 240.0 | G10: UER: 1575.0 | H10: Eff.T.W.St. | I10: 11.353491 | J10: WS
A11: OD | B11: 550 | C11: 348.4 | D11: Coil Pitch | E11: 0.86658 | H11: Eff.T.W.Rt. | I11: 21.171258 | J11: 28358.745
A12: ID | B12: 352 | C12: 140 | D12: Slot Fill | E12: - | F12: EBL: 63.5 | G12: ERD1: 278.4 | H12: St.Carter Fac. | I12: 1.1944753 | J12: IS
A13: Core Depth | B13: 48.5 | C13: 72.150001 | D13: Con./Slot | E13: 16 | G13: ERT: 45.00 | H13: Rt.Carter Fac. | I13: 1.0339772 | J13: 71.838531
A14: Eff.Core L. | B14: 539.40002 | C14: 539.40002 | D14: Wire Size 1 | E14: (.081"x.258")x1 | F14: (8 x 30) | G14: ERH: 35.00 | H14: Carter Factor | I14: 1.2350602 | J14: Volts / Turn
A15: Slot Data | D15: Wire Size 2 | E15: - | H15: Short. Factor | I15: 0.97811905 | J15: 11.547344
A16: Number | B16: 60 | C16: 50 | D16: // Circuits | E16: 1 | H16: Distrib. Factor | I16: 0.956506 | J16: AC
A17: Kind | B17: Open | C17: Rectang | D17: Connection | E17: Wye | H17: Wind. Factor | I17: 0.93557674 | J17: 623.64366
A18: Skew | B18: - | C18: 0 | D18: MCL | E18: 1037 | F18: 752 | H18: Reactance | I18: (Coeff.: 0.1603)
A19: Depth | B19: 50.5 | C19: 32.049999 | D19: No.Cond./Ph. | E19: 320 | I19: Running | J19: Start
A20: Width | B20: 7.08 - 7.08 | C20: 8.0500002 | D20: Res. (20°C) | E20: 0.43880833 | H20: Stator Slot | I20: 22.258333 | J20: 22.258333
A21: Opening | B21: 10.1 | C21: 3 | D21: (105°C) | E21: 0.58536514 | F21: 0.39427251 | G21: 0.047828004 | H21: Rotor Slot | I21: 18.094044 | J21: 12.169863
A22: Tip Depth | B22: 2.8299999 | C22: 2 | D22: Material | E22: CU | F22: Special | G22: Special | H22: Zigzag | I22: 5.5395637 | J22: 5.3322468
A23: T.Min.Wid. | B23: 8.3306608 | C23: 9.817214 | D23: Spec.Resist. | E23: 1.742 | F23: 1.724 | G23: 1.724 | H23: Coil End | I23: 8.5741557 | J23: Skew R.: 0.00
A24: Low. R. | B24: 0 | C24: 0.80000001 | D24: Spec.Gravity | E24: 8.8900003 | F24: 8.8900003 | G24: 8.8900003 | H24: Belt Leakage | I24: 4.6158724 | J24: 4.5042093
A25: Up. R. | B25: - | C25: 0.80000001 | D25: Weight (kg) | H25: Total Resist. | I25: 1.0274657 | J25: 1.8316853
A26: Wedge Dep. | B26: 2.83 - 2.00 | C26: Magnetic | D26: Wire 1 | E26: 116.58798 | F26: 85.023963 | G26: 27.655104 | H26: Total React. | I26: 9.4736052 | J26: 8.4627399
A27: Duct | B27: - | C27: - | D27: Wire 2 | E27: - | F27: - | G27: - | H27: Impedance | I27: 9.5291595 | J27: 8.6586971
A28: Effective Depth (S=1) | D28: Magnetic Circuit Data | I28: Core Loss Data
B29: Res.= | C29: 30.027266 | E29: Length | F29: Section | G29: Density | H29: AT | I29: Volume | J29: Loss | M29: =RIGHT(F$41,SEARCH("/",F$41,1)-1) -> 1758.8 | N29: 125RPM | P29: Kline/in2
B30: Reac.= | C30: 30.043499 | D30: Primary Core | E30: 21.598431 | F30: 523.21802 | G30: 8.8549432 | H30: 51.104527 | I30: 41216.693 | J30: 1200.8204 | M30: =RIGHT(E$41,SEARCH("/",E$41,1)-1) -> 1768.3 | N30: 100RPM | P30: =G30*6.4516 -> 57.128552
A31: Excitation Data | D31: Tooth | E31: 5.05 | F31: 674.0338 | G31: 6.8736403 | H31: 9.3425 | I31: 13615.483 | J31: 263.17195 | M31: =RIGHT(D$41,SEARCH("/",D$41,1)-1) -> 1776.5 | N31: 75RPM | P31: =G31*6.4516 -> 44.345978
A32: Excit.Amps | B32: 7.888 / 8.797 | D32: Second.Core | E32: 11.164426 | F32: 778.35424 | G32: 5.9523873 | H32: 20.654187 | I32: Total | J32: 1463.9923 | M32: =RIGHT(C$41,SEARCH("/",C$41,1)-1) -> 1784.1 | N32: 50RPM | P32: =G32*6.4516 -> 38.402422
A33: Core Loss | B33: 0.510 / 0.568 | C33: Flux / Pole | D33: Tooth | E33: 3.2049999 | F33: 661.92568 | G33: 6.9993747 | H33: 5.9292499 | I33: C.L.C. | J33: 1.75 / 0.81 | M33: =RIGHT(B$41,SEARCH("/",B$41,1)-1) -> 1790.9 | N33: 25RPM | P33: =G33*6.4516 -> 45.157166
A34: NoLoad | B34: 7.90 / 8.82 | C34: 4.6330659 | D34: Air Gap | E34: 0.18 | F34: 1298.291 | G34: 3.5685882 | H34: 511.16303 | I34: S.F.C. | J34: 6.0500002 | P34: =G34*6.4516 -> 23.023104
A35: Load Characteristics | D35: Temp. Rise @ 100%: | E35: 129 / 120 | G35: No Load Loss | H35: 6409.2 / 5626.5 | I35: W.Loss | J35: 2562.0 / 1178.9
A36: Load (%) | B36: 25 | C36: 50 | D36: 75 | E36: 100 | F36: 125 | G36: Primary Loss | H36: 9062.8 / 9347.8 | I36: S.Loss | J36: 265.3 / 122.1
A37: Current (A) | B37: 19.01 / 19.59 | C37: 34.70 / 35.76 | D37: 52.14 / 53.73 | E37: 71.84 / 74.03 | F37: 95.70 / 98.62 | G37: Second. Loss | H37: 6237.8 / 6740.6 | I37: Total C.Loss | J37: 2827.3 / 1301.0
A38: Efficiency | B38: 0.920 / 0.897 | C38: 0.945 / 0.922 | D38: 0.947 / 0.924 | E38: 0.942 / 0.919 | F38: 0.932 / 0.909 | G38: Frict.& Wind. | H38: 3500.0 / 4732.4 | I38: Stray Loss | J38: 7653.8125 | L38: =LEFT(E38,SEARCH("/",E38,1)-1) -> 0.942 | M38: =RIGHT(E38,SEARCH("/",E38,1)-1) -> 0.919 | N38: =M38/L38 -> 0.97558386 | O38: Eff.
A39: P.F. | B39: 0.866 / 0.862 | C39: 0.923 / 0.919 | D39: 0.920 / 0.915 | E39: 0.895 / 0.891 | F39: 0.849 / 0.845 | G39: Starting Data | I39: Slip | J39: PF | L39: =LEFT(E39,SEARCH("/",E39,1)-1) -> 0.895 | M39: =RIGHT(E39,SEARCH("/",E39,1)-1) -> 0.891 | N39: =M39/L39 -> 0.99553073 | O39: PF.
A40: Slip | B40: 0.0038 / 0.0050 | C40: 0.0076 / 0.0088 | D40: 0.0118 / 0.0130 | E40: 0.0164 / 0.0176 | F40: 0.0217 / 0.0229 | G40: LRA | H40: 213.4 / 281.9 | L40: =LEFT(E37,SEARCH("/",E37,1)-1) -> 71.84 | M40: =RIGHT(E37,SEARCH("/",E37,1)-1) -> 74.03 | N40: =M40/L40 -> 1.0304844 | O40: Current
...

Sheet Data Sheet
A1: TOSHIBA INTERNATIONAL CORPORATION
A2: INDUCTION MOTOR DATA SHEET
A3: File: | B3: CS4450 | I3: HRW / Model Number: | J3: 4504FTQL11E-C
A4: Type: TIKE - Form: FCW4 - 4 Pole - 450 HP - 4000 V - 60 Hz - 5011US - Class F | Q4: Motor Type Selection | T4: Electrical Steel Table
A5: Motor Parameters | F5: PERFORMANCE | J5: DESIGN | K5: TEST | Q5: EPACT | T5: M22 - 26Ga.
A6: Material | D6: NCB1 - 26Ga. | F6: NL & Impedance Test | Q6: EQP-III | T6: M36 - 26Ga.
A7: Air Gap | D7: 1.8 | F7: No load amps | J7: 11.4 | K7: - | Q7: Exp.Prf. | T7: NCB1 - 26Ga.
A8: Stack length | D8: 580 | F8: No load watts | J8: 6810 | K8: - | Q8: Exp.Prf.-EQPIII | T8: M43 - 26Ga.
A9: Number of turns per coil | D9: 8 | F9: Impedance amps | H9: 3 | I9: f | J9: 77 | K9: - | Q9: Prem. Eff. | T9: M45 - 26Ga.
A10: Wire 1 (size & number) | D10: (.081"x.258")x1 | F10: Impedance volts | H10: 3 | I10: f | J10: 1150 | K10: - | Q10: Standard Eff. | T10: M54 - 26Ga.
A11: Wire 2 (size & number) | D11: - | F11: Impedance watts | H11: 3 | I11: f | J11: 16655 | K11: - | Q11: OWP | T11: TIPA Lam
A12: Slot fill - circle/square method (%) | D12: - | F12: Temperature Rise (°C) | Q12: Dry Kiln
A13: Connection | D13: 1 x Wye | G13: Winding | I13: 80/115 | J13: 74 / 98 | K13: -
A14: MCL | D14: 1037 | G14: Frame | J14: - | K14: -
A15: Allowance for ins. depth | D15: 11.5516 | G15: Bearing PS/OS | J15: - | K15: -
A16: Allowance for ins. width | D16: 3.3468003 | G16: End Ring | J16: - | K16: -
A17: Slot/Wire arrangement | D17: 16 x 1 | F17: Nameplate Data
A18: Effective cross section for coil | D18: - | H18: FLC (A) | J18: 56 | M18: =J18*6.5 -> 364
A19: Coil grouping | D19: - | H19: RPM | J19: 1780
A20: Coil pitch (slot number) | D20: 1 ~ 14 | H20: CODE | J20: F
A21: Method of coil connection | D21: - | H21: S. F. | J21: 1.15 | Q21: Method of Connection
A22: Resistance per phase @ 20 °C | D22: 0.43880001 | H22: DESIGN | Q22: Skip
A23: Coil Weight | B23: Wire1 | D23: 256.5 | H23: Nom.Eff. (%): | Q23: Adjacent
A24: (lbs.) | B24: Wire2 | D24: - | H24: Min.Eff. (%): | Q24: -
A25: Current Densities (A/cm2) | E25: Bar / ER | H25: P.F. (%): | J25: 91.5
A26: FL / LR | D26: 425 / 2702 | E26: 393 / 239
A27: Stator Slot Shape (Reference) | F27: Performance
H28: LRC (A) | I28: 409 | J28: 356 | K28: - | M28: =(J28/J18)*100 -> 635.71429
H29: LRT (%) | I29: 80 | J29: 118 | K29: -
H30: BDT (%) | I30: 175 | J30: 253 | K30: -
H31: SLIP (%) | J31: 1.11 | K31: -
G32: IEEE-B | H32: Eff. (%) | J32: 94.3 | K32: -
A33: Rotor Slot Shape (Reference) | H33: PF (%) | J33: 91.8 | K33: -
F34: Losses (Watts) | H34: Primary | J34: 5490 | K34: -
H35: Secondary | J35: 3830 | K35: -
H36: Core | J36: 1896 | K36: -
H37: F & W | J37: 4732 | K37: -
H38: Stray | J38: 4348 | K38: -
A39: End Ring (Reference) | F39: Note
G40: Q.C. Limits: CS4450
...

Sheet LoginSheet
J1: P | K1: T | L1: L | M1: T
B2: PROJECT HISTORY | J2: E | K2: D | L2: I | M2: Y | N2: H
J3: R | L3: M | M3: P
J4: F | L4: I | M4: E
K5: C | L5: T | N5: I
J6: D | K6: U | M6: T | N6: N
J7: A | K7: R | L7: R | M7: E | N7: S
I8: S | J8: T | K8: V | L8: E | M8: S | N8: U
B9: DATE | C9: PROJECT | D9: SMART NUMBER | E9: QTY | F9: CUSTOMER | G9: REMARKS | H9: LIMIT CODE | I9: F | J9: A | K9: E | L9: V | M9: T | N9: L
B53: REVISION HISTORY
B54: REV | C54: REMARKS | I54: DATE | L54: INIT

Sheet Performance Data Sheet
A1: TOSHIBA INTERNATIONAL CORPORATION | J1: INDEX | L1: MPCF-1033
A2: Industrial Division / Houston Motor Plant | J2: SHEET NO. | L2: 1 of 1
J3: ISSUED | L3: 7/31/13
J4: SUPERSEDES | L4: 11/8/96
J5: REVISION | L5: 2
A6: SQUIRREL CAGE INDUCTION MOTOR | J6: WRITTEN BY | L6: MDC
A7: PERFORMANCE SPECIFICATIONS | J7: APPROVED BY | L7: PAA
B9: CUSTOMER:
B10: TIC SR No.:
A12: MOTOR NAMEPLATE DATA
B13: H.P.: | C13: 450 | E13: VOLTS: | F13: 4000 | H13: 3 PH / | I13: 60 Hz | L13: S. RPM: | M13: 1800
B14: FRAME: | C14: 5011US | E14: ENCL: | F14: TEFC | H14: FLAMPS: | I14: 56 | L14: FLRPM: | M14: 1780
B15: FORM: | C15: FCW4 | E15: S.F.: | F15: 1.0 | H15: NEMA DESIGN: | I15: - | L15: INSUL CLASS: | M15: F
B16: TYPE: | C16: TIKE | E16: AMB.: | F16: 40 | H16: CODE: | I16: F | L16: DUTY: | M16: Cont.
B17: MODEL No.: | H17: kW: | I17: -
B18: NOM. EFF.: | C18: 94 | E18: MIN. EFF.: | F18: - | H18: P.F.: | I18: 91.5
A21: AMPERAGE | E21: TORQUES | I21: **BEARINGS:
C22: LOCKED ROTOR: | D22: 356 | G22: FULL LOAD (lb-ft.): | H22: 1328 | K22: DRIVE END:
G23: LOCKED ROTOR (%): | H23: 115 | K23: OPPOSITE DRIVE END:
G24: BREAK DOWN (%): | H24: 250
A28: EFFICIENCY | H28: POWER FACTOR
C29: FULL LOAD: | D29: 94.3 | J29: FULL LOAD: | K29: 91.8
C30: 3/4 LOAD: | D30: 94.2 | J30: 3/4 LOAD: | K30: 91.5
C31: 1/2 LOAD: | D31: 93.4 | J31: 1/2 LOAD: | K31: 88.7
A35: ALL CHARACTERISTICS ARE AVERAGE EXPECTED VALUES BASED UPON RATED VOLTAGE,
A36: FREQUENCY AND SINEWAVE POWER INPUT.
A37: THE DECLARED LOCKED ROTOR CURRENT HAS A TOLERANCE OF 20%.
A38: * TEMPERATURE RISE WILL BE CONSISTENT WITH INSULATION, AMBIENT AND SERVICE FACTOR AS
A39: DEFINED BY NEMA-MG-12 OR -20.
A40: ** BEARINGS ARE THE ONLY RECOMMENDED SPARE PART(S).
J42: CERTIFIED BY: | K42: Jerry R
J44: DATE: | K44: 45707
A59: - | B59: 6205ZZ | D59: 1 | E59: -
A60: TEFC | B60: 6206UU | D60: 1.15 | E60: A
A61: ODP | B61: 6207ZZ | E61: B
B62: 6208UU
B63: 6211ZZ
B64: 6211C3
B65: 6211ZZC3
B66: 6305UUC3
...

Sheet STCurve
A2: TOSHIBA INTERNATIONAL CORPORATION
A3: Speed Torque/Current Curve
A6: Model #: | B6: ='Performance Data Sheet'!C17 -> 0 | E6: FLAmps: | F6: ='Performance Data Sheet'!I14 & " A" -> 56 A
A7: Enclosure: | B7: ='Performance Data Sheet'!F14 -> TEFC | C7: Voltage: | D7: ='Performance Data Sheet'!F13 & " V" -> 4000 V | E7: Frame: | F7: ='Performance Data Sheet'!C14 -> 5011US
A8: Pole: | B8: 4 | C8: Frequency: | D8: 3 PH / 60 Hz | E8: Ins. Class: | F8: F
A9: HP: | B9: 450 | C9: Rotor Inertia: | D9: 192.6 lb-ft² | E9: Date: | F9: ='Performance Data Sheet'!K44 -> 45707
A10: FLRPM: | B10: 1780 | C10: Load Inertia: | D10: 1714.4 lb-ft² | E10: File: | F10: CS4450
B12: Locked Rotor Amps: | C12: ='Performance Data Sheet'!D22 & " A" -> 356 A | D12: Load Type: | E12: Fan / Pump
B13: Locked Rotor Torque: | C13: 1.15 | D13: Starting at: | E13: FV / 0.80 (V)
B14: Breakdown Torque: | C14: 2.5 | D14: Accel. Time: | E14: 9 / 17 (s)
B15: Rated Torque: | C15: 1328 lb-ft
A39: Comments: | B39: PROJECT | C39: ='Performance Data Sheet'!C10 -> 0 | E39: D.E.Curve #: | F39: =F10 -> CS4450
C43: Prepared by: | D43: ='Performance Data Sheet'!K42 -> Jerry R | E43: Checked by:
D53: Load | E53: Torque 80% | F53: LRA 80%
A54: 100 | B54: 0 | C54: 0.18214563 | D54: 100 | E54: 0 | F54: 8.1601248
A55: 99.2 | B55: 97.323438 | C55: 112.6515 | D55: 98.400002 | E55: 62.287004 | F55: 90.121201
A56: 96 | B56: 250 | C56: 390.02216 | D56: 89.75 | E56: 160 | F56: 312.01773
A57: 90.857143 | B57: 190.20346 | C57: 497.94376 | D57: 76.228569 | E57: 121.73022 | F57: 398.35501
A58: 85.714285 | B58: 149.15354 | C58: 533.81915 | D58: 62.85714 | E58: 95.458274 | F58: 427.05533
A59: 80.571428 | B59: 130.42966 | C59: 551.2995 | D59: 51.257141 | E59: 83.474983 | F59: 441.03961
A60: 70.285714 | B60: 118.82094 | C60: 571.43225 | D60: 33.485714 | E60: 76.045403 | F60: 457.14581
A61: 59.999999 | B61: 115 | C61: 585.79126 | D61: 22 | E61: 73.600002 | F61: 468.63303
A62: 50 | B62: 115.00002 | C62: 597.71289 | D62: 14 | E62: 73.600012 | F62: 478.17032
A63: 39.999998 | B63: 115.00005 | C63: 608.00775 | D63: 7.9999995 | E63: 73.600031 | F63: 486.40622
A64: 30.000001 | B64: 115.00218 | C64: 616.74298 | D64: 5.9999995 | E64: 73.601399 | F64: 493.39438
A65: 19.999999 | B65: 115.00301 | C65: 624.08252 | D65: 8.000001 | E65: 73.601931 | F65: 499.26602
... A67: 0 | B67: 115 | C67: 635.71429 | D67: 30 | E67: 73.600002 | F67: 508.57144

Sheet Thermdam
A2: TOSHIBA INTERNATIONAL CORPORATION
A3: Thermal Limit & Acceleration Curves
A4: Design Values (For Reference Only)
A6: Model #: | B6: ='Performance Data Sheet'!C17 -> 0 | E6: FLAmps: | F6: ='Performance Data Sheet'!I14 & " A" -> 56 A
A7: Enclosure: | B7: ='Performance Data Sheet'!F14 -> TEFC | C7: Voltage: | D7: ='Performance Data Sheet'!F13 & " V" -> 4000 V | E7: Frame: | F7: ='Performance Data Sheet'!C14 -> 5011US
A8: Pole: | B8: 4 | C8: Frequency: | D8: 3 PH / 60 Hz | E8: Ins. Class: | F8: F
A9: HP: | B9: 450 | C9: Rotor Inertia: | D9: 192.6 lb-ft² | E9: Date: | F9: ='Performance Data Sheet'!K44 -> 45707
A10: FLRPM: | B10: 1780 | C10: Load Inertia: | D10: 1714.4 lb-ft² | E10: File: | F10: CS4450
A39: Comments: | B39: PROJECT | C39: ='Performance Data Sheet'!C10 -> 0 | E39: D.E.Curve #: | F39: =F10 -> CS4450
C43: Prepared by: | D43: ='Performance Data Sheet'!K42 -> Jerry R | E43: Checked by:
F50: =5252.1*B50/D53 -> #DIV/0!
D66: =D65/D64 -> #DIV/0!
A67: Current (%) | B67: Cold | C67: Hot | E67: CURRENT (%) | F67: Accel. Time
A68: 635.71429 | B68: 35 | C68: 15 | E68: =A68 -> 635.71429 | F68: 0.0001 | G68: =0.8*E68 -> 508.57143 | H68: =F68 -> 0.0001
A69: =FLOOR(A68,100) -> 600 | B69: =((A68/A69)^2)*B68 -> 39.290675 | C69: =((A68/A69)^2)*C68 -> 16.838861 | E69: 633.03571 | F69: 0.9557244 | G69: =0.8*E69 -> 506.42857 | H69: 1.8052583
A70: =A69-100 -> 500 | B70: =((A68/A70)^2)*B68 -> 56.578571 | C70: =((A68/A70)^2)*C68 -> 24.247959 | E70: 627.14286 | F70: 1.8105142 | G70: =0.8*E70 -> 501.71429 | H70: 3.4198623
A71: =A70-100 -> 400 | B71: =((A68/A71)^2)*B68 -> 88.404018 | C71: =((A68/A71)^2)*C68 -> 37.887436 | E71: 620.35714 | F71: 2.6295563 | G71: =0.8*E71 -> 496.28571 | H71: 4.9669426
A72: =A71-100 -> 300 | B72: =((A68/A72)^2)*B68 -> 157.1627 | E72: 612.32143 | F72: 3.4485985 | G72: =0.8*E72 -> 489.85714 | H72: 6.5140233
A73: =A72-100 -> 200 | B73: =((A68/A73)^2)*B68 -> 353.61607 | E73: 602.85714 | F73: 4.2991825 | G73: =0.8*E73 -> 482.28571 | H73: 8.1206829
A74: 250 | B74: =((A68/A74)^2)*B68 -> 226.31429 | C74: =((A68/A74)^2)*C68 -> 96.991837 | E74: 591.78571 | F74: 5.2107482 | G74: =0.8*E74 -> 473.42857 | H74: 9.8425301
A75: 180 | B75: =((A68/A75)^2)*B69 -> 490.08162 | C75: =((A68/A75)^2)*C68 -> 187.09845 | E75: 578.57143 | F75: 6.2306079 | G75: =0.8*E75 -> 462.85714 | H75: 11.768933
A76: 145 | B76: =((A68/A76)^2)*B68 -> 672.75352 | C76: =((A68/A76)^2)*C68 -> 288.32294 | E76: 561.42857 | F76: 7.3356315 | G76: =0.8*E76 -> 449.14286 | H76: 13.856201
A77: 125 | C77: =CEILING(C76*2,100) -> 600 | E77: 542.5 | F77: 7.8855145 | G77: =0.8*E77 -> 434 | H77: 14.894869
A78: 125 | C78: =2*C77 -> 1200 | E78: 515.89286 | F78: 8.3397203 | G78: =0.8*E78 -> 412.71429 | H78: 15.752814
A79: 125 | C79: 10000 | E79: 443.92857 | F79: 8.670912 | G79: =0.8*E79 -> 355.14286 | H79: 16.378399
E80: 120 | F80: 9.0000006 | G80: 120 | H80: 17.000011

Sheet Performance
A2: TOSHIBA INTERNATIONAL CORPORATION
A3: Performance Curve
A4: Design Values (For Reference Only)
A6: Model #: | B6: ='Performance Data Sheet'!C17 -> 0 | E6: FLAmps: | F6: ='Performance Data Sheet'!I14 & " A" -> 56 A
A7: Enclosure: | B7: ='Performance Data Sheet'!F14 -> TEFC | C7: Voltage: | D7: ='Performance Data Sheet'!F13 & " V" -> 4000 V | E7: Frame: | F7: ='Performance Data Sheet'!C14 -> 5011US
A8: Pole: | B8: 4 | C8: Frequency: | D8: 3 PH / 60 Hz | E8: Ins. Class: | F8: F
A9: HP: | B9: 450 | C9: Rotor Inertia: | D9: 192.6 lb-ft² | E9: Date: | F9: ='Performance Data Sheet'!K44 -> 45707
A10: FLRPM: | B10: 1780 | C10: Load Inertia: | D10: 1714.4 lb-ft² | E10: File: | F10: CS4450
B12: Locked Rotor Amps: | C12: ='Performance Data Sheet'!D22 & " A" -> 356 A | D12: Load Type: | E12: Fan / Pump
B13: Locked Rotor Torque: | C13: 1.15 | D13: Starting at: | E13: FV / 0.80 (V)
B14: Breakdown Torque: | C14: 2.5 | D14: Accel. Time: | E14: 9 / 17 (s)
B15: Rated Torque: | C15: 1328 lb-ft
A39: Comments: | B39: PROJECT | C39: ='Performance Data Sheet'!C10 -> 0 | E39: D.E.Curve #: | F39: =F10 -> CS4450
C43: Prepared by: | D43: ='Performance Data Sheet'!K42 -> Jerry R | E43: Checked by:
A53: Load | B53: Efficiency | C53: PF | D53: Amps | E53: RPM | F53: Input Watts
A54: 0 | D54: 10.376618 | E54: 100 | F54: 0.681
A55: 25 | B55: 89.896645 | C55: 75.835022 | D55: 17.790764 | E55: 78.147805 | F55: 9.347001
A56: 50 | B56: 93.365456 | C56: 88.66069 | D56: 29.303574 | E56: 63.979895 | F56: 17.999464
A57: 75 | B57: 94.208466 | C57: 91.484406 | D57: 42.217464 | E57: 49.427963 | F57: 26.757597
A58: 100 | B58: 94.30957 | C58: 91.849159 | D58: 56.006306 | E58: 33.499334 | F58: 35.638549
A59: 125 | B59: 94.119583 | C59: 91.161888 | D59: 70.678055 | E59: 18.185114 | F59: 44.63811

Sheet Circuit Param.
A1: TOSHIBA INTERNATIONAL CORPORATION | J1: INDEX | L1: MPCF-1109
A2: Industrial Division / Houston Motor Plant | J2: SHEET NO. | L2: 1 of 1
J3: ISSUED | L3: 38309
A4: EQUIVALENT CIRCUIT DATA | J4: SUPERSEDES | L4: NEW
J5: REVISION | L5: REV. 0
J6: WRITTEN BY | L6: MDC
A7: All Values are Presented in Ohms/Phase, Equivalent Wye Connection. | J7: APPROVED BY | L7: Paul Anderson
B9: CUSTOMER:
B10: TIC SR No.:
A12: MOTOR NAMEPLATE DATA
B13: H.P.: | C13: 450 | E13: VOLTS: | F13: 4000 | H13: 3 PH / | I13: 60 Hz | L13: S. RPM: | M13: 1800
B14: FRAME: | C14: 5011US | E14: ENCL: | F14: TEFC | H14: FLAMPS: | I14: 56 | L14: FLRPM: | M14: 1780
B15: FORM: | C15: FCW4 | E15: S.F.: | F15: 1.0 | H15: NEMA DESIGN: | I15: - | L15: INSUL CLASS: | M15: F
B16: TYPE: | C16: TIKE | E16: AMB.: | F16: 40 | H16: CODE: | I16: F | L16: DUTY: | M16: Cont.
B17: MODEL No.: | H17: kW: | I17: -
B18: NOM. EFF.: | C18: 94 | E18: MIN. EFF.: | F18: - | H18: P.F.: | I18: 91.5
A21: Primary Resistance (R1) : | F21: .585
A22: Secondary Resistance (R2) : | F22: .442
A23: Starting Resistance (R3) : | F23: 1.24
A25: Primary Reactance (X1) : | F25: 4.759
A26: Secondary Reactance (X2) : | F26: 3.748
A27: Starting Reactance (X3) : | F27: 3.06
A29: Magnetizing Reactance (Xm) : | F29: 202.579
A31: Transient Reactance : | F31: 8.439
A32: Sub Transient Reactance : | F32: 6.431
A33: Short Circuit Time Constant : | F33: 0.05
A34: Sub Transient Time Constant : | F34: 0.011
A35: Open Circuit Time Constant : | F35: 1.238
I40: CERTIFIED BY: | J40: JERRY R
I42: DATE: | J42: 45707

Sheet PERFORMANCE data
A1: TOSHIBA INTERNATIONAL CORPORATION | J1: INDEX | L1: MPCF-1082
A2: Industrial Division / Houston Motor Plant | J2: SHEET NO. | L2: 1 of 1
J3: ISSUED | L3: 2/14/02
J4: SUPERSEDES | L4: NEW
J5: REVISION | L5: 0
A6: SQUIRREL CAGE INDUCTION MOTOR | J6: WRITTEN BY | L6: M. CAMPBELL
A7: API 541 PERFORMANCE SPECIFICATIONS | J7: APPROVED BY | L7: P.A.A
B9: CUSTOMER:
B10: TIC SR No.:
A12: MOTOR NAMEPLATE DATA
B13: H.P.: | C13: 450 | E13: VOLTS: | F13: 4000 | H13: 3 PH / | I13: 60 Hz | L13: S. RPM: | M13: 1800
B14: FRAME: | C14: 5011US | E14: ENCL: | F14: TEFC | H14: FLAMPS: | I14: 56 | L14: FLRPM: | M14: 1780
B15: FORM: | C15: FCW4 | E15: S.F.: | F15: 1.0 | H15: NEMA DESIGN: | I15: - | L15: INSUL CLASS: | M15: F
B16: TYPE: | C16: TIKE | E16: AMB.: | F16: 40 | H16: CODE: | I16: F | L16: DUTY: | M16: Cont.
B17: MODEL No.: | H17: kW: | I17: -
B18: NOM. EFF.: | C18: 94 | E18: MIN. EFF.: | F18: - | H18: P.F.: | I18: 91.5
A20: LOCKED ROTOR DATA
D21: AMPS AT RATED VOLTAGE: | E21: 356 | I21: POWER FACTOR: | J21: 29.8
D22: AMPS AT 80% VOLTAGE: | E22: 282
A24: TORQUE VALUES | H24: CURVE NUMBERS
E25: FULL LOAD (LB.FT): | F25: 1328 | J25: SPEED-TORQUE CURVE: | K25: CS4450
E26: LOCKED ROTOR TORQUE (% OF FLT): | F26: 115 | J26: SPEED-CURRENT CURVE: | K26: CS4450
E27: PULL UP TORQUE (% OF FLT): | F27: 115 | J27: ACCELERATION CURVE: | K27: -
E28: BREAKDOWN TORQUE (% OF FLT): | F28: 250
A30: LOCKED ROTOR WITHSTAND TIMES
A31: COLD CONDITION | H31: HOT CONDITION
C32: 100% VOLTAGE: | D32: 35 | J32: 100% VOLTAGE: | K32: 15
C33: 90% VOLTAGE: | D33: 43 | J33: 90% VOLTAGE: | K33: 19
C34: 80% VOLTAGE: | D34: 55 | J34: 80% VOLTAGE: | K34: 24
C35: 70% VOLTAGE: | D35: 71 | J35: 70% VOLTAGE: | K35: 30
A37: DESIGN DATA
C38: MOTOR ROTOR wk2 (LB.FT2): | D38: 192.6 | J38: NO LOAD CURRENT: | K38: 11.4
C39: AIR GAP: | D39: 1.8 | J39: ACCELERATION TIME: | K39: 9 / 17
D40: LOAD CHARACTERISTICS
D41: LOAD | G41: 1/2 | H41: 3/4 | I41: FULL | J41: SF
D42: AMPS (A) | G42: 29.2 | H42: 42.2 | I42: 56 | J42: -
D43: EFFICIENCY (%) | G43: 93.4 | H43: 94.2 | I43: 94.3 | J43: -
D44: POWER FACTOR (%) | G44: 88.6 | H44: 91.4 | I44: 91.8 | J44: -
D45: GUARENTEED EFFICIENCY (%) | G45: - | H45: - | I45: - | J45: -
A46: EFFICIENCY TO BE DETERMINED BY IEEE 112, METHOD B
...

Sheet StallTime
A1: Rating: | B1: 4 Pole - 450.0 HP - 1800 RPM - 4000 V - 60 Hz
A3: Starting Performance
D4: Load Type: Fan / Pump - 1714.4 lb-ft²
A5: RPM | B5: Motor | C5: Load | D5: Accel. | E5: Line | F5: Stator | G5: Rotor
A6: Speed Increment | B6: Torque (%) | C6: Torque (%) | D6: Time (s) | E6: Amps | F6: kW / s | G6: kW / s
A7: 0~180 | B7: 115.0 | C7: 22.5 | D7: 0.909 | E7: 354.5 | F7: 202.4 | G7: 330.8
A8: 180~360 | B8: 115.0 | C8: 11.5 | D8: 0.813 | E8: 351.2 | F8: 177.8 | G8: 266.1
A9: 360~540 | B9: 115.0 | C9: 7.0 | D9: 0.779 | E9: 347.4 | F9: 167.0 | G9: 226.6
A10: 540~720 | B10: 115.0 | C10: 7.0 | D10: 0.779 | E10: 342.9 | F10: 163.1 | G10: 198.3
A11: 720~900 | B11: 115.0 | C11: 11.0 | D11: 0.809 | E11: 337.6 | F11: 164.6 | G11: 176.5
A12: 900~1080 | B12: 115.0 | C12: 18.0 | D12: 0.867 | E12: 331.4 | F12: 170.6 | G12: 157.7
A13: 1080~1265 | B13: 116.9 | C13: 27.7 | D13: 0.970 | E13: 324.0 | F13: 183.3 | G13: 137.2
A14: 1265~1450 | B14: 124.6 | C14: 42.4 | D14: 1.051 | E14: 314.4 | F14: 189.0 | G14: 114.1
A15: 1450~1543 | B15: 139.8 | C15: 57.1 | D15: 0.523 | E15: 303.8 | F15: 87.5 | G15: 81.5
A16: 1543~1635 | B16: 169.7 | C16: 69.5 | D16: 0.432 | E16: 288.9 | F16: 67.8 | G16: 56.6
... A18: 1728~1782 | B18: 175.0 | C18: 94.1 | D18: 0.313 | E18: 140.7 | F18: 1.7 | G18: 8.1
D21: Acceleration Time: 8.6 s
B22: Energy | D22: First Start | F22: Second Start
A23: Stator Winding Rise | B23: 1618 kW / s | D23: 36°C | F23: 72°C
A24: Rotor Bar Rise | B24: 1594 kW / s | D24: 49°C | F24: 97°C
A25: End Ring Rise | B25: 193 kW / s | D25: 18°C | F25: 36°C
A27: Locked Rotor Thermal Capability
E28: Cold Condition
B29: Rate of Rise | D29: Power | E29: Rise Limit | F29: Max Time
A30: Stator Copper | B30: 5.9°C / s | D30: 264.6 kW | E30: 160°C | F30: 27.1 s
A31: Rotor Bar | B31: 10.5°C / s | D31: 344.3 kW | E31: 260°C | F31: 24.7 s
A32: Rotor ER | B32: 3.9°C / s | D32: 41.8 kW | E32: 180°C | F32: 45.9 s
E34: Hot Condition
B35: Hot Temp. | D35: Rise Limit | E35: Ambient | F35: Total | G35: Max.Time
A36: Stator Copper | B36: 74°C + | D36: 86°C + | E36: 40°C | F36: = 200°C | G36: 14.6 s
A37: Rotor Bar | B37: 100°C + | D37: 160°C + | E37: 40°C | F37: = 300°C | G37: 15.2 s
A38: Rotor ER | B38: 100°C + | D38: 80°C + | E38: 40°C | F38: = 220°C | G38: 20.4 s
A40: Cold Stall Time: | B40: 43.2 s | D40: Hot Stall Time: | F40: 19.2 s
