Workbook
Name Print_Area_MI: 'Performance Data Sheet'!$A$10:$N$42

Sheet DesignSheet
A1: TOSHIBA INTERNATIONAL CORPORATION | I1: Calc. Code: | J1: 2-2-2-0-1-2
A2: 3-PHASE SQUIRREL CAGE INDUCTION MOTOR DESIGN SHEET | J2: B.L.-1 P.F.-1
A3: File: | B3: G:\DESPRO\RAT FILES\CS4800.rat | G3: Date: | H3: 43864 | I3: Time: | J3: 0.38600694
A4: Pole | B4: HP | C4: RPM | D4: Form | E4: Voltage | F4: Frequency | G4: Temperature | H4: FLSpeed | I4: FLSlip | J4: Frame
A5: 4 | B5: 799.99998 | C5: 1800 | D5: FCW4 | E5: 4000 | F5: 60 | G5: 115 | H5: 1788.0 / 1789.0 | I5: 0.0067 / 0.0061 | J5: 5811US
A6: Core Data | D6: Winding Data | H6: Constant Data
B7: Primary | C7: Secondary | F7: Bar | G7: End Ring | H7: St. Slot Pitch | I7: 20.996293 | J7: LR Test Data
A8: Air Gap | B8: 2.3 | H8: Rt. Slot Pitch | I8: 24.906526 | J8: ES
A9: Space Fac. | B9: 0.93000001 | D9: Pitch | E9: 1 ~ 14 | F9: Cross Section Area | H9: Mean Value | I9: 22.951409 | J9: 849.48732
A10: Core Length | B10: 760 | C10: 760 | F10: UB: 350.0 | G10: UER: 1978.0 | H10: Eff.T.W.St. | I10: 12.10131 | J10: WS
A11: OD | B11: 610 | C11: 396.4 | D11: Coil Pitch | E11: 0.86658 | H11: Eff.T.W.Rt. | I11: 24.324496 | J11: 22118.195 | R11: =21/4000*575 * 2 -> 6.0375
A12: ID | B12: 401 | C12: 155 | D12: Slot Fill | E12: - | F12: EBL: 63.5 | G12: ERD1: 308.4 | H12: St.Carter Fac. | I12: 1.2154351 | J12: IS
A13: Core Depth | B13: 51.5 | C13: 80.650001 | D13: Con./Slot | E13: 21 | G13: ERT: 46.00 | H13: Rt.Carter Fac. | I13: 1.0239277 | J13: 98.574318
A14: Eff.Core L. | B14: 706.79999 | C14: 706.79999 | D14: Wire Size 1 | E14: (.064"x.182")x2 | F14: (10 x 35) | G14: ERH: 43.00 | H14: Carter Factor | I14: 1.2445176 | J14: Volts / Turn
A15: Slot Data | D15: Wire Size 2 | E15: - | H15: Short. Factor | I15: 0.97811905 | J15: 21.99494
A16: Number | B16: 60 | C16: 50 | D16: // Circuits | E16: 2 | H16: Distrib. Factor | I16: 0.956506 | J16: AC
A17: Kind | B17: Open | C17: Rectang | D17: Connection | E17: Wye | H17: Wind. Factor | I17: 0.93557674 | J17: 492.9586
A18: Skew | B18: - | C18: 0 | D18: MCL | E18: 1265 | F18: 933 | H18: Reactance | I18: (Coeff.: 0.0905)
A19: Depth | B19: 53 | C19: 40.049999 | D19: No.Cond./Ph. | E19: 210 | I19: Running | J19: Start
A20: Width | B20: 8.89 - 8.89 | C20: 10.05 | D20: Res. (20°C) | E20: 0.1605521 | H20: Stator Slot | I20: 18.431889 | J20: 18.431889
A21: Opening | B21: 13 | C21: 3 | D21: (115°C) | E21: 0.22048314 | F21: 0.14914271 | G21: 0.0189196 | H21: Rotor Slot | I21: 26.793095 | J21: 20.531019
A22: Tip Depth | B22: 2.8299999 | C22: 5 | D22: Material | E22: CU | F22: Special | G22: Special | H22: Zigzag | I22: 4.5227981 | J22: 4.2829299
A23: T.Min.Wid. | B23: 7.9962931 | C23: 9.8304558 | D23: Spec.Resist. | E23: 1.742 | F23: 1.724 | G23: 1.724 | H23: Coil End | I23: 7.23071 | J23: Skew R.: 0.00
A24: Low. R. | B24: 0 | C24: 0.80000001 | D24: Spec.Gravity | E24: 8.8900003 | F24: 8.8900003 | G24: 8.8900003 | H24: Belt Leakage | I24: 4.0840142 | J24: 3.9320205
A25: Up. R. | B25: - | C25: 0.80000001 | D25: Weight (kg) | H25: Total Resist. | I25: 0.38854545 | J25: 0.75875378
A26: Wedge Dep. | B26: 2.80 - 2.00 | C26: Magnetic | D26: Wire 1 | E26: 204.20898 | F26: 152.30793 | G26: 38.819284 | H26: Total React. | I26: 5.5253425 | J26: 4.9174042
A27: Duct | B27: - | C27: - | D27: Wire 2 | E27: - | F27: - | G27: - | H27: Impedance | I27: 5.5389867 | J27: 4.9755974
A28: Effective Depth (S=1) | D28: Magnetic Circuit Data | I28: Core Loss Data
B29: Res.= | C29: 35.003788 | E29: Length | F29: Section | G29: Density | H29: AT | I29: Volume | J29: Loss | M29: =RIGHT(F$41,SEARCH("/",F$41,1)-1) -> 1785.9 | N29: 125RPM
B30: Reac.= | C30: 35.036779 | D30: Primary Core | E30: 23.954624 | F30: 728.00399 | G30: 12.122031 | H30: 138.58422 | I30: 63866.99 | J30: 3094.7996 | M30: =RIGHT(E$41,SEARCH("/",E$41,1)-1) -> 1789.0 | N30: 100RPM
A31: Excitation Data | D31: Tooth | E31: 5.3 | F31: 847.76698 | G31: 10.409567 | H31: 19.046991 | I31: 17972.66 | J31: 680.48288 | M31: =RIGHT(D$41,SEARCH("/",D$41,1)-1) -> 1792.2 | N31: 75RPM
A32: Excit.Amps | B32: 19.805 / 22.048 | D32: Second.Core | E32: 12.421062 | F32: 1140.0684 | G32: 7.7406646 | H32: 24.001063 | I32: Total | J32: 3775.2825 | M32: =RIGHT(C$41,SEARCH("/",C$41,1)-1) -> 1795.1 | N32: 50RPM
A33: Core Loss | B33: 1.067 / 1.188 | C33: Flux / Pole | D33: Tooth | E33: 4.0049999 | F33: 868.52075 | G33: 10.160825 | H33: 13.41123 | I33: C.L.C. | J33: 1.75 / 0.69 | M33: =RIGHT(B$41,SEARCH("/",B$41,1)-1) -> 1798.0 | N33: 25RPM
A34: NoLoad | B34: 19.83 / 22.08 | C34: 8.8248871 | D34: Air Gap | E34: 0.23 | F34: 1923.2973 | G34: 4.5884155 | H34: 839.81005 | I34: S.F.C. | J34: 6.0500002
A35: Load Characteristics | D35: Temp. Rise @ 100%: | E35: 74 / 74 | G35: No Load Loss | H35: 16889.1 / 11580.0 | I35: W.Loss | J35: 6606.7 / 2590.1
A36: Load (%) | B36: 25 | C36: 50 | D36: 75 | E36: 100 | F36: 125 | G36: Primary Loss | H36: 6427.2 / 6166.9 | I36: S.Loss | J36: 793.4 / 311.0
A37: Current (A) | B37: 32.62 / 33.05 | C37: 52.37 / 53.06 | D37: 74.72 / 75.70 | E37: 98.57 / 99.87 | F37: 123.99 / 125.62 | G37: Second. Loss | H37: 4217.5 / 3779.9 | I37: Total C.Loss | J37: 7400.2 / 2901.1
A38: Efficiency | B38: 0.894 / 0.893 | C38: 0.939 / 0.937 | D38: 0.952 / 0.950 | E38: 0.957 / 0.955 | F38: 0.958 / 0.956 | G38: Frict.& Wind. | H38: 9300.0 / 8444.6 | I38: Stray Loss | J38: 6731.6001 | L38: =LEFT(E38,SEARCH("/",E38,1)-1) -> 0.957 | M38: =RIGHT(E38,SEARCH("/",E38,1)-1) -> 0.955 | N38: =M38/L38 -> 0.99791014 | O38: Eff.
A39: P.F. | B39: 0.738 / 0.730 | C39: 0.876 / 0.866 | D39: 0.908 / 0.898 | E39: 0.913 / 0.903 | F39: 0.907 / 0.896 | G39: Starting Data | I39: Slip | J39: PF | L39: =LEFT(E39,SEARCH("/",E39,1)-1) -> 0.913 | M39: =RIGHT(E39,SEARCH("/",E39,1)-1) -> 0.903 | N39: =M39/L39 -> 0.9890471 | O39: PF.
A40: Slip | B40: 0.0017 / 0.0011 | C40: 0.0033 / 0.0027 | D40: 0.0049 / 0.0044 | E40: 0.0067 / 0.0061 | F40: 0.0084 / 0.0078 | G40: LRA | H40: 464.2 / 675.9 | L40: =LEFT(E37,SEARCH("/",E37,1)-1) -> 98.57 | M40: =RIGHT(E37,SEARCH("/",E37,1)-1) -> 99.87 | N40: =M40/L40 -> 1.0131886 | O40: Current
...

Sheet Data Sheet
A1: TOSHIBA INTERNATIONAL CORPORATION
A2: INDUCTION MOTOR DATA SHEET
A3: File: | B3: CS4800 | I3: HRW / Model Number: | J3: 8004FTQL11E-C
A4: Type: TIKE - Form: FCW4 - 4 Pole - 800 HP - 4000 V - 60 Hz - 5811US - Class F | Q4: Motor Type Selection | T4: Electrical Steel Table
A5: Motor Parameters | F5: PERFORMANCE | J5: DESIGN | K5: TEST | Q5: EPACT | T5: M22 - 26Ga.
A6: Material | D6: M36 - 26Ga. | F6: NL & Impedance Test | Q6: EQP-III | T6: M36 - 26Ga.
A7: Air Gap | D7: 2.3 | F7: No load amps | J7: 22 | K7: - | Q7: Exp.Prf. | T7: NCB1 - 26Ga.
A8: Stack length | D8: 760 | F8: No load watts | J8: 11580 | K8: - | Q8: Exp.Prf.-EQPIII | T8: M43 - 26Ga.
A9: Number of turns per coil | D9: 10.5 | F9: Impedance amps | H9: 3 | I9: f | J9: 133 | K9: - | Q9: Prem. Eff. | T9: M45 - 26Ga.
A10: Wire 1 (size & number) | D10: (.064"x.182")x2 | F10: Impedance volts | H10: 3 | I10: f | J10: 1150 | K10: - | Q10: Standard Eff. | T10: M54 - 26Ga.
A11: Wire 2 (size & number) | D11: - | F11: Impedance watts | H11: 3 | I11: f | J11: 22118 | K11: - | Q11: OWP | T11: TIPA Lam
A12: Slot fill - circle/square method (%) | D12: - | F12: Temperature Rise (°C) | Q12: Dry Kiln
A13: Connection | D13: 2 x Wye | G13: Winding | I13: 80/115 | J13: 74 / 98 | K13: -
A14: MCL | D14: 1265 | G14: Frame | J14: - | K14: -
A15: Allowance for ins. depth | D15: 11.8324 | G15: Bearing PS/OS | J15: - | K15: -
A16: Allowance for ins. width | D16: 3.3543999 | G16: End Ring | J16: - | K16: -
A17: Slot/Wire arrangement | D17: 21 x 2 | F17: Nameplate Data
A18: Effective cross section for coil | D18: - | H18: FLC (A) | J18: 100 | M18: =J18*6.5 -> 650
A19: Coil grouping | D19: - | H19: RPM | J19: 1785
A20: Coil pitch (slot number) | D20: 1 ~ 14 | H20: CODE | J20: G
A21: Method of coil connection | D21: - | H21: S. F. | J21: 1.15 | Q21: Method of Connection
A22: Resistance per phase @ 20 °C | D22: 0.16060001 | H22: DESIGN | J22: - | Q22: Skip
A23: Coil Weight | B23: Wire1 | D23: 449.3 | H23: Nom.Eff. (%): | Q23: Adjacent
A24: (lbs.) | B24: Wire2 | D24: - | H24: Min.Eff. (%): | Q24: -
A25: Current Densities (A/cm2) | E25: Bar / ER | H25: P.F. (%):
A26: FL / LR | D26: 346 / 2339 | E26: 312 / 220
A27: Stator Slot Shape (Reference) | F27: Performance
H28: LRC (A) | I28: - | J28: 676 | K28: - | M28: =(J28/J18)*100 -> 676
H29: LRT (%) | I29: 60 | J29: 80 | K29: -
H30: BDT (%) | I30: 175 | J30: 234 | K30: -
H31: SLIP (%) | J31: 0.61 | K31: -
G32: IEEE-B | H32: Eff. (%) | J32: 95.5 | K32: -
A33: Rotor Slot Shape (Reference) | H33: PF (%) | J33: 90.3 | K33: -
F34: Losses (Watts) | H34: Primary | J34: 6167 | K34: -
H35: Secondary | J35: 3780 | K35: -
H36: Core | J36: 2901 | K36: -
H37: F & W | J37: 8445 | K37: -
H38: Stray | J38: 6732 | K38: -
A39: End Ring (Reference) | F39: Note | G39: TEFC-4P-800HP CuBar, Sleeve Brgs.
F40: LINK: | G40: CS4800_EXP2.rat with CS4800_EXP2_Fan550_Lab324.dat
...

Sheet LoginSheet
J1: P | K1: T | L1: L | M1: T
B2: PROJECT HISTORY | J2: E | K2: D | L2: I | M2: Y | N2: H
J3: R | L3: M | M3: P
J4: F | L4: I | M4: E
K5: C | L5: T | N5: I
J6: D | K6: U | M6: T | N6: N
J7: A | K7: R | L7: R | M7: E | N7: S
I8: S | J8: T | K8: V | L8: E | M8: S | N8: U
B9: DATE | C9: PROJECT | D9: SMART NUMBER | E9: QTY | F9: CUSTOMER | G9: REMARKS | H9: LIMIT CODE | I9: F | J9: A | K9: E | L9: V | M9: T | N9: L
B53: REVISION HISTORY
B54: REV | C54: REMARKS | I54: DATE | L54: INIT

Sheet StallTime
A1: Rating: | B1: 4 Pole - 800.0 HP - 1800 RPM - 4000 V - 60 Hz
A3: Starting Performance
D4: Load Type: Fan / Pump - 2815.4 lb-ft²
A5: RPM | B5: Motor | C5: Load | D5: Accel. | E5: Line | F5: Stator | G5: Rotor
A6: Speed Increment | B6: Torque (%) | C6: Torque (%) | D6: Time (s) | E6: Amps | F6: kW / s | G6: kW / s
A7: 0~188 | B7: 80.0 | C7: 22.4 | D7: 1.456 | E7: 674.0 | F7: 440.0 | G7: 643.2
A8: 188~375 | B8: 80.2 | C8: 11.3 | D8: 1.219 | E8: 669.6 | F8: 364.1 | G8: 483.1
A9: 375~563 | B9: 80.4 | C9: 7.0 | D9: 1.144 | E9: 664.2 | F9: 336.9 | G9: 401.6
A10: 563~750 | B10: 80.8 | C10: 7.6 | D10: 1.147 | E10: 657.7 | F10: 332.0 | G10: 351.0
A11: 750~938 | B11: 81.5 | C11: 12.3 | D11: 1.214 | E11: 649.7 | F11: 343.5 | G11: 317.0
A12: 938~1125 | B12: 82.7 | C12: 20.2 | D12: 1.346 | E12: 639.6 | F12: 370.6 | G12: 291.8
A13: 1125~1313 | B13: 84.7 | C13: 31.4 | D13: 1.576 | E13: 627.2 | F13: 419.0 | G13: 272.0
A14: 1313~1501 | B14: 89.1 | C14: 47.7 | D14: 2.029 | E14: 611.7 | F14: 516.3 | G14: 260.6
A15: 1501~1594 | B15: 97.5 | C15: 63.9 | D15: 1.250 | E15: 597.0 | F15: 300.6 | G15: 211.6
A16: 1594~1688 | B16: 115.6 | C16: 77.1 | D16: 1.091 | E16: 580.2 | F16: 252.0 | G16: 141.4
... A19: 1796~1800 | B19: 119.9 | C19: 99.8 | D19: 0.080 | E19: 99.2 | F19: 0.5 | G19: 21.5
D21: Acceleration Time: 14.1 s
B22: Energy | D22: First Start | F22: Second Start | H22: Third Start
A23: Stator Winding Rise | B23: 3790 kW / s | D23: 48°C | F23: 96°C | H23: 144°C
A24: Rotor Bar Rise | B24: 3061 kW / s | D24: 52°C | F24: 104°C | H24: 156°C
A25: End Ring Rise | B25: 388 kW / s | D25: 26°C | F25: 52°C | H25: 78°C
A27: Locked Rotor Thermal Capability
E28: Cold Condition
B29: Rate of Rise | D29: Power | E29: Rise Limit | F29: Max Time
A30: Stator Copper | B30: 4.6°C / s | D30: 359.3 kW | E30: 160°C | F30: 35.0 s
A31: Rotor Bar | B31: 7.2°C / s | D31: 423.7 kW | E31: 260°C | F31: 36.0 s
A32: Rotor ER | B32: 3.6°C / s | D32: 53.7 kW | E32: 180°C | F32: 50.1 s
E34: Hot Condition
B35: Hot Temp. | D35: Rise Limit | E35: Ambient | F35: Total | G35: Max.Time
A36: Stator Copper | B36: 74°C + | D36: 86°C + | E36: 40°C | F36: = 200°C | G36: 18.8 s
A37: Rotor Bar | B37: 100°C + | D37: 160°C + | E37: 40°C | F37: = 300°C | G37: 22.2 s
A38: Rotor ER | B38: 100°C + | D38: 80°C + | E38: 40°C | F38: = 220°C | G38: 22.3 s
A40: Cold Stall Time: | B40: 46.8 s | D40: Hot Stall Time: | F40: 20.8 s

Sheet Performance Data Sheet
A1: TOSHIBA INTERNATIONAL CORPORATION | J1: INDEX | L1: MPCF-1033
A2: Industrial Division / Houston Motor Plant | J2: SHEET NO. | L2: 1 of 1
J3: ISSUED | L3: 7/31/13
J4: SUPERSEDES | L4: 11/8/96
J5: REVISION | L5: 2
A6: SQUIRREL CAGE INDUCTION MOTOR | J6: WRITTEN BY | L6: MDC
A7: PERFORMANCE SPECIFICATIONS | J7: APPROVED BY | L7: PAA
B9: CUSTOMER: | C9: JCI INDUSTRIES
B10: TIC SR No.: | C10: 2210056.1
A12: MOTOR NAMEPLATE DATA
B13: H.P.: | C13: 800 | E13: VOLTS: | F13: 4000 | H13: 3 PH / | I13: 60 Hz | L13: S. RPM: | M13: 1800
B14: FRAME: | C14: 5811UZ | E14: ENCL: | F14: TEFC | H14: FLAMPS: | I14: 100 | L14: FLRPM: | M14: 1785
B15: FORM: | C15: FCW4 | E15: S.F.: | F15: 1.15 | H15: NEMA DESIGN: | I15: - | L15: INSUL CLASS: | M15: F
B16: TYPE: | C16: TIKE | E16: AMB.: | F16: 40°C | H16: CODE: | I16: G | L16: DUTY: | M16: Cont.
B17: MODEL No.: | C17: GP-10035342 | H17: kW: | I17: -
B18: NOM. EFF.: | C18: - | E18: MIN. EFF.: | F18: - | H18: P.F.: | I18: -
A21: AMPERAGE | E21: TORQUES | I21: **BEARINGS:
C22: LOCKED ROTOR: | D22: 676 | G22: FULL LOAD (lb-ft.): | H22: 2349 | K22: DRIVE END:
G23: LOCKED ROTOR (%): | H23: 80 | K23: OPPOSITE DRIVE END:
G24: BREAK DOWN (%): | H24: 230
A28: EFFICIENCY | H28: POWER FACTOR
C29: FULL LOAD: | D29: 95.5 | J29: FULL LOAD: | K29: 90.3
C30: 3/4 LOAD: | D30: 95 | J30: 3/4 LOAD: | K30: 89.8
C31: 1/2 LOAD: | D31: 93.7 | J31: 1/2 LOAD: | K31: 86.6
A35: ALL CHARACTERISTICS ARE AVERAGE EXPECTED VALUES BASED UPON RATED VOLTAGE,
A36: FREQUENCY AND SINEWAVE POWER INPUT.
A37: THE DECLARED LOCKED ROTOR CURRENT HAS A TOLERANCE OF 20%
A38: * TEMPERATURE RISE WILL BE CONSISTENT WITH INSULATION, AMBIENT AND SERVICE FACTOR AS
A39: DEFINED BY NEMA-MG-12 OR -20
A40: ** BEARINGS ARE THE ONLY RECOMMENDED SPARE PART(S).
J42: CERTIFIED BY: | K42: JERRY R
J44: DATE: | K44: 44265
A59: - | B59: 6205ZZ | D59: 1 | E59: -
A60: TEFC | B60: 6206UU | D60: 1.15 | E60: A
A61: ODP | B61: 6207ZZ | E61: B
B62: 6208UU
B63: 6211ZZ
B64: 6211C3
B65: 6211ZZC3
B66: 6305UUC3
...

Sheet STCurve
A2: TOSHIBA INTERNATIONAL CORPORATION
A3: Speed Torque/Current Curve
A6: Model #: | B6: ='Performance Data Sheet'!C17 -> GP-10035342 | E6: FLAmps: | F6: ='Performance Data Sheet'!I14 & " A" -> 100 A
A7: Enclosure: | B7: ='Performance Data Sheet'!F14 -> TEFC | C7: Voltage: | D7: ='Performance Data Sheet'!F13 & " V" -> 4000 V | E7: Frame: | F7: ='Performance Data Sheet'!C14 -> 5811UZ
A8: Pole: | B8: 4 | C8: Frequency: | D8: 3 PH / 60 Hz | E8: Ins. Class: | F8: ='Performance Data Sheet'!M15 -> F
A9: HP: | B9: ='Performance Data Sheet'!C13 -> 800 | C9: Rotor Inertia: | D9: 423.0 lb-ft² | E9: Date: | F9: ='Performance Data Sheet'!K44 -> 44265
A10: FLRPM: | B10: ='Performance Data Sheet'!M14 -> 1785 | C10: Load Inertia: | D10: 2815.4 lb-ft² | E10: File: | F10: CS4800
B12: Locked Rotor Amps: | C12: ='Performance Data Sheet'!D22 & " A" -> 676 A | D12: Load Type: | E12: N/A
B13: Locked Rotor Torque: | C13: ='Performance Data Sheet'!H23/100 -> 0.8 | D13: Starting at: | E13: N/A
B14: Breakdown Torque: | C14: 2.3 | D14: Accel. Time: | E14: N/A
B15: Rated Torque: | C15: ='Performance Data Sheet'!H22 & " lb-ft" -> 2349 lb-ft
A39: Comments: | B39: PROJECT | C39: ='Performance Data Sheet'!C10 -> 2210056.1 | E39: D.E.Curve #: | F39: =F10 -> CS4800
C43: Prepared by: | D43: ='Performance Data Sheet'!K42 -> JERRY R | E43: Checked by:
D53: Load
A54: 100 | B54: 0 | C54: 0.19833413 | D54: 100
A55: 99.8 | B55: 139.73128 | C55: 178.58975 | D55: 99.599998
A56: 99 | B56: 230 | C56: 497.51584 | D56: 98
A57: 93.789474 | B57: 128.46791 | C57: 569.45868 | D57: 83.852631
A58: 88.578947 | B58: 102.74786 | C58: 590.96307 | D58: 70.30526
A59: 83.368421 | B59: 92.156776 | C59: 603.01086 | D59: 57.410526
A60: 72.947368 | B60: 85.971928 | C60: 620.29199 | D60: 38.010525
A61: 62.526315 | B61: 83.390428 | C61: 634.01422 | D61: 24.778948
A62: 52.105263 | B62: 81.959909 | C62: 645.19153 | D62: 15.68421
A63: 41.68421 | B63: 81.094327 | C63: 654.13739 | D63: 9.0105257
A64: 31.263161 | B64: 80.572129 | C64: 661.34125 | D64: 6.2526321
A65: 20.842105 | B65: 80.264888 | C65: 667.14807 | D65: 7.8315787
... A67: 0 | B67: 80 | C67: 676 | D67: 30

Sheet Thermdam
A2: TOSHIBA INTERNATIONAL CORPORATION
A3: Thermal Limit & Acceleration Curves
A4: Design Values (For Reference Only)
A6: Model #: | B6: ='Performance Data Sheet'!C17 -> GP-10035342 | E6: FLAmps: | F6: ='Performance Data Sheet'!I14 & " A" -> 100 A
A7: Enclosure: | B7: ='Performance Data Sheet'!F14 -> TEFC | C7: Voltage: | D7: ='Performance Data Sheet'!F13 & " V" -> 4000 V | E7: Frame: | F7: ='Performance Data Sheet'!C14 -> 5811UZ
A8: Pole: | B8: 4 | C8: Frequency: | D8: 3 PH / 60 Hz | E8: Ins. Class: | F8: ='Performance Data Sheet'!M15 -> F
A9: HP: | B9: ='Performance Data Sheet'!C13 -> 800 | C9: Rotor Inertia: | D9: 423.0 lb-ft² | E9: Date: | F9: ='Performance Data Sheet'!K44 -> 44265
A10: FLRPM: | B10: ='Performance Data Sheet'!M14 -> 1785 | C10: Load Inertia: | D10: 2815.4 lb-ft² | E10: File: | F10: CS4800
C12: ='Performance Data Sheet'!D22 & " A" -> 676 A
C13: ='Performance Data Sheet'!H23/100 -> 0.8
C15: ='Performance Data Sheet'!H22 & " lb-ft" -> 2349 lb-ft
A39: Comments: | B39: PROJECT | C39: ='Performance Data Sheet'!C10 -> 2210056.1 | E39: D.E.Curve #: | F39: =F10 -> CS4800
C43: Prepared by: | D43: ='Performance Data Sheet'!K42 -> JERRY R | E43: Checked by:
F50: =5252.1*B50/D53 -> #DIV/0!
D66: =D65/D64 -> #DIV/0!
A67: Current (%) | B67: Cold | C67: Hot | E67: CURRENT (%) | F67: Accel. Time
A68: 676 | B68: 35 | C68: 15 | E68: =A68 -> 676 | F68: 0.0001
A69: =FLOOR(A68,100) -> 600 | B69: =((A68/A69)^2)*B68 -> 44.428222 | C69: =((A68/A69)^2)*C68 -> 19.040667 | E69: 674 | F69: 1.456
A70: =A69-100 -> 500 | B70: =((A68/A70)^2)*B68 -> 63.97664 | C70: =((A68/A70)^2)*C68 -> 27.41856 | E70: 669.6 | F70: 2.675
A71: =A70-100 -> 400 | B71: =((A68/A71)^2)*B68 -> 99.9635 | C71: =((A68/A71)^2)*C68 -> 42.8415 | E71: 664.2 | F71: 3.819
A72: =A71-100 -> 300 | B72: =((A68/A72)^2)*B68 -> 177.71289 | E72: 657.7 | F72: 4.9660001
A73: =A72-100 -> 200 | B73: =((A68/A73)^2)*B68 -> 399.854 | E73: 649.7 | F73: 6.1800003
A74: 230 | B74: =((A68/A74)^2)*B68 -> 302.34707 | C74: =((A68/A74)^2)*C68 -> 129.57732 | E74: 639.6 | F74: 7.5260005
A75: 180 | B75: =((A68/A75)^2)*B69 -> 626.62442 | C75: =((A68/A75)^2)*C68 -> 211.56296 | E75: 627.2 | F75: 9.1020002
A76: 145 | B76: =((A68/A76)^2)*B68 -> 760.72105 | C76: =((A68/A76)^2)*C68 -> 326.02331 | E76: 611.7 | F76: 11.131001
A77: 125 | C77: =CEILING(C76*2,100) -> 700 | E77: 597 | F77: 12.381001
A78: 125 | C78: =2*C77 -> 1400 | E78: 580.2 | F78: 13.472
A79: 125 | C79: 10000 | E79: 533.5 | F79: 13.948
E80: =A74 -> 230 | F80: 14.023
E81: =A77 -> 125 | F81: 14.103

Sheet Performance
A2: TOSHIBA INTERNATIONAL CORPORATION
A3: Performance Curve
A4: Design Values (For Reference Only)
A6: Model #: | B6: ='Performance Data Sheet'!C17 -> GP-10035342 | E6: FLAmps: | F6: ='Performance Data Sheet'!I14 & " A" -> 100 A
A7: Enclosure: | B7: ='Performance Data Sheet'!F14 -> TEFC | C7: Voltage: | D7: ='Performance Data Sheet'!F13 & " V" -> 4000 V | E7: Frame: | F7: ='Performance Data Sheet'!C14 -> 5811UZ
A8: Pole: | B8: 4 | C8: Frequency: | D8: 3 PH / 60 Hz | E8: Ins. Class: | F8: ='Performance Data Sheet'!M15 -> F
A9: HP: | B9: ='Performance Data Sheet'!C13 -> 800 | C9: Rotor Inertia: | D9: 423.0 lb-ft² | E9: Date: | F9: ='Performance Data Sheet'!K44 -> 44265
A10: FLRPM: | B10: ='Performance Data Sheet'!M14 -> 1785 | C10: Load Inertia: | D10: 2815.4 lb-ft² | E10: File: | F10: CS4800
B12: Locked Rotor Amps: | C12: ='Performance Data Sheet'!D22 & " A" -> 676 A | D12: Load Type: | E12: N/A
B13: Locked Rotor Torque: | C13: ='Performance Data Sheet'!H23/100 -> 0.8 | D13: Starting at: | E13: N/A
B14: Breakdown Torque: | C14: 2.3 | D14: Accel. Time: | E14: N/A
B15: Rated Torque: | C15: ='Performance Data Sheet'!H22 & " lb-ft" -> 2349 lb-ft
N36: SPEED | O36: KW
N37: =L43 - (L43-L44) / 10 * 0 -> 1800 | O37: =L45 / 10 * 10 -> 1600
N38: =L43 - (L43-L44) / 10 * 1 -> 1798 | O38: =L45 / 10 * 9 -> 1440
A39: Comments: | B39: PROJECT | C39: ='Performance Data Sheet'!C10 -> 2210056.1 | E39: D.E.Curve #: | F39: =F10 -> CS4800 | N39: =L43 - (L43-L44) / 10 * 2 -> 1796 | O39: =L45 / 10 * 8 -> 1280
N40: =L43 - (L43-L44) / 10 * 3 -> 1794 | O40: =L45 / 10 * 7 -> 1120
N41: =L43 - (L43-L44) / 10 * 4 -> 1792 | O41: =L45 / 10 * 6 -> 960
N42: =L43 - (L43-L44) / 10 * 5 -> 1790 | O42: =L45 / 10 * 5 -> 800
C43: Prepared by: | D43: ='Performance Data Sheet'!K42 -> JERRY R | E43: Checked by: | K43: SYNC SPEED | L43: 1800 | N43: =L43 - (L43-L44) / 10 * 6 -> 1788 | O43: =L45 / 10 * 4 -> 640
K44: NEW SPEED LOWER RANGE | L44: 1780 | N44: =L43 - (L43-L44) / 10 * 7 -> 1786 | O44: =L45 / 10 * 3 -> 480
K45: NEW kW UPPER RANGE | L45: 1600 | N45: =L43 - (L43-L44) / 10 * 8 -> 1784 | O45: =L45 / 10 * 2 -> 320
N46: =L43 - (L43-L44) / 10 * 9 -> 1782 | O46: =L45 / 10 * 1 -> 160
N47: =L43 - (L43-L44) / 10 * 10 -> 1780 | O47: =L45 / 10 * 0 -> 0
A52: ADJUSTED
A53: Load | B53: Efficiency | C53: PF | D53: Amps | E53: RPM | F53: Input Watts
A54: 0 | D54: 22 | E54: 100 | F54: =11580/(L45*1000) * 100 -> 0.72375
A55: 25 | B55: 89.300003 | C55: 73 | D55: 33.049999 | E55: =(1.004611*B10-L44)/(L43-L44)*100 -> 66.153175 | F55: =167153.3/(L45*1000)*100 -> 10.447081
A56: 50 | B56: 93.699997 | C56: 86.599998 | D56: 53.060001 | E56: =(1.003126*B10-L44)/(L43-L44)*100 -> 52.89955 | F56: =318350.7/(L45*1000)*100 -> 19.896919
A57: 75 | B57: 95 | C57: 89.800003 | D57: 75.699997 | E57: =(1.00164*B10-L44)/(L43-L44)*100 -> 39.637 | F57: =470969.5/(L45*1000)*100 -> 29.435594
A58: 100 | B58: 95.5 | C58: 90.300003 | D58: 99.870003 | E58: =(1*B10-L44)/(L43-L44)*100 -> 25 | F58: =624803.4/(L45*1000)*100 -> 39.050213
A59: 125 | B59: 95.599998 | C59: 89.600006 | D59: 125.62 | E59: =(0.9984116*B10-L44)/(L43-L44)*100 -> 10.82353 | F59: =779807.6/(L45*1000)*100 -> 48.737975
A62: ORIGINAL
A63: Load | B63: Efficiency | C63: PF | D63: Amps | E63: RPM | F63: Input Watts
A64: 0 | D64: 20.095214 | E64: 100 | F64: 16.923791
A65: 25 | B65: 89.223648 | C65: 73.010368 | D65: 33.055603 | E65: 90.256841 | F65: 10.450029
A66: 50 | B66: 93.684074 | C66: 86.629387 | D66: 53.065052 | E66: 75.892535 | F66: 19.90498
A67: 75 | B67: 95.013802 | C67: 89.81102 | D67: 75.703262 | E67: 61.233349 | F67: 29.439614
A68: 100 | B68: 95.485138 | C68: 90.318123 | D68: 99.875504 | E68: 45.463074 | F68: 39.059058
A69: 125 | B69: 95.591133 | C69: 89.656006 | D69: 125.62691 | E69: 29.853232 | F69: 48.769686
