Workbook
Name Print_Area_MI: 'Performance Data Sheet'!$A$10:$N$42

Sheet DesignSheet
A1: TOSHIBA INTERNATIONAL CORPORATION | I1: Calc. Code: | J1: 2-2-2-0-1-2
A2: 3-PHASE SQUIRREL CAGE INDUCTION MOTOR DESIGN SHEET | J2: B.L.-1 P.F.-1
A3: File: | B3: K:\Active Projects\6800 Frame TEFC\Electrical Design\4P\Cu_SERIES\CS4900U.rat | G3: Date: | H3: 41800 | I3: Time: | J3: 0.5584375
A4: Pole | B4: HP | C4: RPM | D4: Form | E4: Voltage | F4: Frequency | G4: Temperature | H4: FLSpeed | I4: FLSlip | J4: Frame
A5: 4 | B5: 900.00003 | C5: 1800 | D5: FCW4 | E5: 4000 | F5: 60 | G5: 115 | H5: 1789.3 / 1788.9 | I5: 0.0060 / 0.0062 | J5: 6811US
A6: Core Data | D6: Winding Data | H6: Constant Data
B7: Primary | C7: Secondary | F7: Bar | G7: End Ring | H7: St. Slot Pitch | I7: 26.860594 | J7: LR Test Data
A8: Air Gap | B8: 3 | H8: Rt. Slot Pitch | I8: 31.855723 | J8: ES
A9: Space Fac. | B9: 0.93000001 | D9: Pitch | E9: 1 ~ 14 | F9: Cross Section Area | H9: Mean Value | I9: 29.358159 | J9: 917.96476
A10: Core Length | B10: 580 | C10: 580 | F10: UB: 420.0 | G10: UER: 1978.0 | H10: Eff.T.W.St. | I10: 15.276446 | J10: WS
A11: OD | B11: 770 | C11: 507 | D11: Coil Pitch | E11: 0.86658 | H11: Eff.T.W.Rt. | I11: 31.398656 | J11: 19712.23
A12: ID | B12: 513 | C12: 200 | D12: Slot Fill | E12: - | F12: EBL: 50.5 | G12: ERD1: 416.0 | H12: St.Carter Fac. | I12: 1.2197491 | J12: IS
A13: Core Depth | B13: 63.5 | C13: 112.45 | D13: Con./Slot | E13: 22 | G13: ERT: 46.00 | H13: Rt.Carter Fac. | I13: 1.0145569 | J13: 111.52526
A14: Eff.Core L. | B14: 539.40002 | C14: 539.40002 | D14: Wire Size 1 | E14: (.081"x.258")x2 | F14: (12 x 35) | G14: ERH: 43.00 | H14: Carter Factor | I14: 1.2375048 | J14: Volts / Turn
A15: Slot Data | D15: Wire Size 2 | E15: - | H15: Short. Factor | I15: 0.97811905 | J15: 20.99517
A16: Number | B16: 60 | C16: 50 | D16: // Circuits | E16: 2 | H16: Distrib. Factor | I16: 0.956506 | J16: AC
A17: Kind | B17: Open | C17: Rectang | D17: Connection | E17: Wye | H17: Wind. Factor | I17: 0.93557674 | J17: 456.7203
A18: Skew | B18: - | C18: 0 | D18: MCL | E18: 1296 | F18: 727 | H18: Reactance | I18: (Coeff.: 0.0758)
A19: Depth | B19: 65 | C19: 41.049999 | D19: No.Cond./Ph. | E19: 220 | I19: Running | J19: Start
A20: Width | B20: 11.58 - 11.58 | C20: 12.05 | D20: Res. (20°C) | E20: 0.094257045 | H20: Stator Slot | I20: 17.640198 | J20: 17.640198
A21: Opening | B21: 17 | C21: 3 | D21: (115°C) | E21: 0.1294414 | F21: 0.10708015 | G21: 0.027309999 | H21: Rotor Slot | I21: 28.128721 | J21: 22.920938
A22: Tip Depth | B22: 3.6500001 | C22: 6 | D22: Material | E22: CU | F22: CU | G22: CU | H22: Zigzag | I22: 4.4773202 | J22: 4.3803091
A23: T.Min.Wid. | B23: 9.8605947 | C23: 14.653447 | D23: Spec.Resist. | E23: 1.742 | F23: 1.742 | G23: 1.742 | H23: Coil End | I23: 13.433469 | J23: Skew R.: 0.00
A24: Low. R. | B24: 0 | C24: 0.80000001 | D24: Spec.Gravity | E24: 8.8900003 | F24: 8.8900003 | G24: 8.8900003 | H24: Belt Leakage | I24: 4.0282923 | J24: 3.9800587
A25: Up. R. | B25: - | C25: 0.80000001 | D25: Weight (kg) | H25: Total Resist. | I25: 0.26383156 | J25: 0.52828467
A26: Wedge Dep. | B26: 3.65 - 2.00 | C26: Magnetic | D26: Wire 1 | E26: 400.69389 | F26: 144.31138 | G26: 50.818073 | H26: Total React. | I26: 5.1315165 | J26: 4.722857
A27: Duct | B27: - | C27: - | D27: Wire 2 | E27: - | F27: - | G27: - | H27: Impedance | I27: 5.1382942 | J27: 4.7523112
A28: Effective Depth (S=1) | D28: Magnetic Circuit Data | I28: Core Loss Data
B29: Res.= | C29: 35.004476 | E29: Length | F29: Section | G29: Density | H29: AT | I29: Volume | J29: Loss
B30: Reac.= | C30: 35.036976 | D30: Primary Core | E30: 30.237804 | F30: 685.03803 | G30: 12.296771 | H30: 183.19173 | I30: 76023.237 | J30: 3770.2648
A31: Excitation Data | D31: Tooth | E31: 6.5 | F31: 797.82076 | G31: 10.558457 | H31: 24.371048 | I31: 20743.34 | J31: 803.6655
A32: Excit.Amps | B32: 23.975 / 26.685 | D32: Second.Core | E32: 16.68577 | F32: 1213.1107 | G32: 6.9439302 | H32: 30.868674 | I32: Total | J32: 4573.9303
A33: Core Loss | B33: 1.289 / 1.435 | C33: Flux / Pole | D33: Tooth | E33: 4.1049999 | F33: 988.00872 | G33: 8.5259934 | H33: 9.0281197 | I33: C.L.C. | J33: 1.75 / 0.73
A34: NoLoad | B34: 24.01 / 26.72 | C34: 8.4237558 | D34: Air Gap | E34: 0.3 | F34: 1888.3739 | G34: 4.4608518 | H34: 1064.9508 | I34: S.F.C. | J34: 6.0500002
A35: Load Characteristics | D35: Temp. Rise @ 100%: | E35: 64 / 61 | G35: No Load Loss | H35: 18405.4 / 13635.2 | I35: W.Loss | J35: 8004.4 / 3327.6
A36: Load (%) | B36: 25 | C36: 50 | D36: 75 | E36: 100 | F36: 125 | G36: Primary Loss | H36: 4829.9 / 4754.9 | I36: S.Loss | J36: 938.5 / 390.1
A37: Current (A) | B37: 37.91 / 38.94 | C37: 59.74 / 61.37 | D37: 84.73 / 87.05 | E37: 111.53 / 114.57 | F37: 140.19 / 144.03 | G37: Second. Loss | H37: 4231.2 / 4386.2 | I37: Total C.Loss | J37: 8942.9 / 3717.7
A38: Efficiency | B38: 0.898 / 0.884 | C38: 0.942 / 0.927 | D38: 0.956 / 0.941 | E38: 0.962 / 0.947 | F38: 0.964 / 0.948 | G38: Frict.& Wind. | H38: 9300.0 / 10813.0 | I38: Stray Loss | J38: 14268.414
A39: P.F. | B39: 0.712 / 0.704 | C39: 0.861 / 0.851 | D39: 0.897 / 0.887 | E39: 0.904 / 0.894 | F39: 0.897 / 0.887 | G39: Starting Data | I39: Slip | J39: PF
A40: Slip | B40: 0.0015 / 0.0017 | C40: 0.0029 / 0.0032 | D40: 0.0044 / 0.0046 | E40: 0.0060 / 0.0062 | F40: 0.0075 / 0.0078 | G40: LRA | H40: 486.0 / 742.0
...

Sheet Data Sheet
A1: TOSHIBA INTERNATIONAL CORPORATION
A2: INDUCTION MOTOR DATA SHEET
A3: File: | B3: CS4900U | I3: HRW / Model Number: | J3: 9004FTQL11E-C
A4: Type: TIKE - Form: FCW4 - 4 Pole - 900 HP - 2300/4000 V - 60 Hz - 6811US - Class F | Q4: Motor Type Selection | T4: Electrical Steel Table
A5: Motor Parameters | F5: PERFORMANCE | J5: DESIGN | K5: TEST | Q5: EPACT | T5: M22 - 26Ga.
A6: Material | D6: M36 - 26Ga. | F6: NL & Impedance Test | Q6: EQP-III | T6: M36 - 26Ga.
A7: Air Gap | D7: 3 | F7: No load amps | J7: 27 | K7: 26.5 | M7: =K7*1.732 -> 45.898 | Q7: Exp.Prf. | T7: NCB1 - 26Ga.
A8: Stack length | D8: 580 | F8: No load watts | J8: 14743 | K8: 10951 | Q8: Exp.Prf.-EQPIII | T8: M43 - 26Ga.
A9: Number of turns per coil | D9: 11 | F9: Impedance amps | H9: 3 | I9: f | J9: 109.68 | K9: 153.9 | M9: =K9/M10*1150 -> 256.5 | Q9: Prem. Eff. | T9: M45 - 26Ga.
A10: Wire 1 (size & number) | D10: (.081"x.258")x2 | F10: Impedance volts | H10: 3 | I10: f | J10: 1150 | K10: 1150 | M10: 690 | Q10: OWP | T10: M54 - 26Ga.
A11: Wire 2 (size & number) | D11: - | F11: Impedance watts | H11: 3 | I11: f | J11: 24003 | K11: 32761 | M11: =K11*690^2/660^2 -> 35806.961 | Q11: Dry Kiln
A12: Slot fill - circle/square method (%) | D12: - | F12: Temperature Rise (°C)
A13: Connection | D13: 2x Delta / 2 x Wye | G13: Winding | I13: 80/115 | J13: 64 / 84 | K13: -
A14: MCL | D14: 1296 | G14: Frame | J14: - | K14: -
A15: Allowance for ins. depth | D15: 11.6872 | G15: Bearing PS/OS | J15: - | K15: -
A16: Allowance for ins. width | D16: 3.4935999 | G16: End Ring | J16: - | K16: -
A17: Slot/Wire arrangement | D17: 22 x 2 | F17: Nameplate Data
A18: Effective cross section for coil | D18: - | H18: FLC (A) | J18: 199 / 115 | M18: =J18*6.5 -> #VALUE!
A19: Coil grouping | D19: - | H19: RPM | J19: 1789
A20: Coil pitch (slot number) | D20: 1 ~ 14 | H20: CODE | J20: G
A21: Method of coil connection | D21: - | H21: S. F. | J21: 1.15 | Q21: Method of Connection
A22: Resistance per phase @ 20 °C | D22: 0.097 | H22: DESIGN | J22: - | Q22: Skip
A23: Coil Weight | B23: Wire1 | D23: 904 | H23: Nom.Eff. (%): | Q23: Adjacent
A24: (lbs.) | B24: Wire2 | D24: - | H24: Min.Eff. (%): | Q24: -
A25: Current Densities (A/cm2) | E25: Bar / ER | H25: P.F. (%):
A26: FL / LR | D26: 217 / 1400 | E26: 309 / 262
A27: Stator Slot Shape (Reference) | F27: Performance
H28: LRC (A) | I28: - | J28: 1280 / 742 | K28: - | M28: =(J28/J18)*100 -> #VALUE!
H29: LRT (%) | I29: 60 | J29: 115 | K29: -
H30: BDT (%) | I30: 175 | J30: 220 | K30: -
H31: SLIP (%) | J31: 0.62 | K31: -
G32: IEEE-B | H32: Eff. (%) | J32: 94.7 | K32: -
A33: Rotor Slot Shape (Reference) | H33: PF (%) | J33: 89.4 | K33: -
F34: Losses (Watts) | H34: Primary | J34: 4755 | K34: -
H35: Secondary | J35: 4386 | K35: -
H36: Core | J36: 3718 | K36: -
H37: F & W | J37: 10813 | K37: -
H38: Stray | J38: 14268 | K38: -
A39: End Ring (Reference) | F39: Note
F40: LINK: | G40: H402126_Rev1.rat with TestData_H402126_fan550_lab1473.dat
...

Sheet Data Sheet_2300V
A1: TOSHIBA INTERNATIONAL CORPORATION
A2: INDUCTION MOTOR DATA SHEET
A3: File: | B3: CS4900U | I3: HRW / Model Number:
A4: Type: TIKE - Form: FCW4 - 4 Pole - 900 HP - 2300 V - 60 Hz - 6811US - Class F | Q4: Motor Type Selection | T4: Electrical Steel Table
A5: Motor Parameters | F5: PERFORMANCE | J5: DESIGN | K5: TEST | Q5: EPACT | T5: M22 - 26Ga.
A6: Material | D6: M36 - 26Ga. | F6: NL & Impedance Test | Q6: EQP-III | T6: M36 - 26Ga.
A7: Air Gap | D7: 3 | F7: No load amps | J7: 46 | K7: 45.4 | M7: =O7/N7*J7 -> 47.115152 | N7: 33 | O7: 33.8 | Q7: Exp.Prf. | T7: NCB1 - 26Ga.
A8: Stack length | D8: 580 | F8: No load watts | J8: 13588 | K8: 17122 | M8: =O8/N8*J8 -> 16788.138 | N8: 11337 | O8: 14007 | Q8: Exp.Prf.-EQPIII | T8: M43 - 26Ga.
A9: Number of turns per coil | D9: 11 | F9: Impedance amps | H9: 3 | I9: f | J9: 503 | K9: 169.6 | M9: =O9/N9*J9 -> 170.27392 | N9: 418 | O9: 141.5 | Q9: Prem. Eff. | T9: M45 - 26Ga.
A10: Wire 1 (size & number) | D10: (.081"x.258")x2 | F10: Impedance volts | H10: 3 | I10: f | J10: 460 | K10: 460 | M10: =O10/N10*J10 -> 460 | N10: 460 | O10: 460 | Q10: Standard Eff. | T10: M54 - 26Ga.
A11: Wire 2 (size & number) | D11: - | F11: Impedance watts | H11: 3 | I11: f | J11: 19874 | K11: 13327 | M11: =O11/N11*J11 -> 16796.774 | N11: 20034 | O11: 16932 | Q11: OWP | T11: TIPA Lam
A12: Slot fill - circle/square method (%) | D12: - | F12: Temperature Rise (°C) | Q12: Dry Kiln
A13: Connection | D13: 2 x Delta | G13: Winding | I13: 80/115 | J13: 65 / 86 | K13: -
A14: MCL | D14: 1296 | G14: Frame | J14: - | K14: -
A15: Allowance for ins. depth | D15: 11.6872 | G15: Bearing PS/OS | J15: - | K15: -
A16: Allowance for ins. width | D16: 3.4935999 | G16: End Ring | J16: - | K16: -
A17: Slot/Wire arrangement | D17: 22 x 2 | F17: Nameplate Data
A18: Effective cross section for coil | D18: - | H18: FLC (A) | J18: 199 | M18: =J18*6.5 -> 1293.5
A19: Coil grouping | D19: - | H19: RPM | J19: 1785
A20: Coil pitch (slot number) | D20: 1 ~ 14 | H20: CODE | J20: G
A21: Method of coil connection | D21: - | H21: S. F. | J21: 1.15 | Q21: Method of Connection
A22: Resistance per phase @ 20 °C | D22: 0.094300002 | H22: DESIGN | J22: - | Q22: Skip
A23: Coil Weight | B23: Wire1 | D23: 881.5 | H23: Nom.Eff. (%): | Q23: Adjacent
A24: (lbs.) | B24: Wire2 | D24: - | H24: Min.Eff. (%): | Q24: -
A25: Current Densities (A/cm2) | E25: Bar / ER | H25: P.F. (%):
A26: FL / LR | D26: 218 / 1402 | E26: 311 / 264
A27: Stator Slot Shape (Reference) | F27: Performance
H28: LRC (A) | I28: - | J28: 1280 | K28: - | M28: =(J28/J18)*100 -> 643.21608
H29: LRT (%) | I29: 60 | J29: 113 | K29: -
H30: BDT (%) | I30: 175 | J30: 220 | K30: -
H31: SLIP (%) | J31: 0.62 | K31: -
G32: IEEE-B | H32: Eff. (%) | J32: 94.6 | K32: -
A33: Rotor Slot Shape (Reference) | H33: PF (%) | J33: 89.4 | K33: -
F34: Losses (Watts) | H34: Primary | J34: 4794 | K34: -
H35: Secondary | J35: 4431 | K35: -
H36: Core | J36: 3692 | K36: -
H37: F & W | J37: 10813 | K37: -
H38: Stray | J38: 14415 | K38: -
A39: End Ring (Reference) | F39: Note
F40: LINK: | G40: H402126_Rev1.rat with TestData_H402126_fan550_lab1473.dat
...

Sheet StallTime
A1: Rating: | B1: 4 Pole - 900.0 HP - 1800 RPM - 4000 V - 60 Hz
A3: Starting Performance
D4: Load Type: Fan / Pump - 3108.0 lb-ft²
A5: RPM | B5: Motor | C5: Load | D5: Accel. | E5: Line | F5: Stator | G5: Rotor
A6: Speed Increment | B6: Torque (%) | C6: Torque (%) | D6: Time (s) | E6: Amps | F6: kW / s | G6: kW / s
A7: 0~188 | B7: 115.0 | C7: 22.4 | D7: 0.990 | E7: 740.4 | F7: 211.6 | G7: 761.0
A8: 188~375 | B8: 115.0 | C8: 11.3 | D8: 0.884 | E8: 737.0 | F8: 187.3 | G8: 608.7
A9: 375~563 | B9: 115.0 | C9: 7.0 | D9: 0.848 | E9: 732.9 | F9: 178.1 | G9: 516.6
A10: 563~750 | B10: 115.1 | C10: 7.6 | D10: 0.853 | E10: 727.8 | F10: 176.8 | G10: 451.1
A11: 750~938 | B11: 115.1 | C11: 12.3 | D11: 0.892 | E11: 721.4 | F11: 182.1 | G11: 400.3
A12: 938~1125 | B12: 115.1 | C12: 20.2 | D12: 0.966 | E12: 713.3 | F12: 193.2 | G12: 355.9
A13: 1125~1313 | B13: 115.2 | C13: 31.4 | D13: 1.093 | E13: 703.3 | F13: 213.4 | G13: 315.5
A14: 1313~1501 | B14: 116.4 | C14: 47.7 | D14: 1.334 | E14: 690.5 | F14: 252.1 | G14: 278.0
A15: 1501~1594 | B15: 120.6 | C15: 63.9 | D15: 0.807 | E15: 678.4 | F15: 146.3 | G15: 211.0
A16: 1594~1688 | B16: 133.3 | C16: 77.1 | D16: 0.815 | E16: 664.3 | F16: 143.5 | G16: 154.0
... A19: 1796~1800 | B19: 130.5 | C19: 99.8 | D19: 0.057 | E19: 129.8 | F19: 0.3 | G19: 19.2
D21: Acceleration Time: 10.1 s
B22: Energy | D22: First Start | F22: Second Start
A23: Stator Winding Rise | B23: 1980 kW / s | D23: 13°C | F23: 26°C
A24: Rotor Bar Rise | B24: 3304 kW / s | D24: 59°C | F24: 119°C
A25: End Ring Rise | B25: 843 kW / s | D25: 43°C | F25: 86°C
A27: Locked Rotor Thermal Capability
E28: Cold Condition
B29: Rate of Rise | D29: Power | E29: Rise Limit | F29: Max Time
A30: Stator Copper | B30: 1.6°C / s | D30: 243.5 kW | E30: 160°C | F30: 101.4 s
A31: Rotor Bar | B31: 11.1°C / s | D31: 615.2 kW | E31: 260°C | F31: 23.5 s
A32: Rotor ER | B32: 8.0°C / s | D32: 156.9 kW | E32: 180°C | F32: 22.4 s
E34: Hot Condition
B35: Hot Temp. | D35: Rise Limit | E35: Ambient | F35: Total | G35: Max.Time
A36: Stator Copper | B36: 61°C + | D36: 99°C + | E36: 40°C | F36: = 200°C | G36: 62.7 s
A37: Rotor Bar | B37: 80°C + | D37: 180°C + | E37: 40°C | F37: = 300°C | G37: 16.3 s
A38: Rotor ER | B38: 80°C + | D38: 100°C + | E38: 40°C | F38: = 220°C | G38: 12.5 s
A40: Cold Stall Time: | B40: 54.6 s | D40: Hot Stall Time: | F40: 30.3 s

Sheet Performance Data Sheet
A1: TOSHIBA INTERNATIONAL CORPORATION | J1: INDEX | L1: MPCF-1033
A2: Industrial Division / Houston Motor Plant | J2: SHEET NO. | L2: 1 of 1
J3: ISSUED | L3: 7/31/13
J4: SUPERSEDES | L4: 11/8/96
J5: REVISION | L5: 2
A6: SQUIRREL CAGE INDUCTION MOTOR | J6: WRITTEN BY | L6: MDC
A7: PERFORMANCE SPECIFICATIONS | J7: APPROVED BY | L7: PAA
B9: CUSTOMER:
B10: TIC SR No.:
A12: MOTOR NAMEPLATE DATA
B13: H.P.: | C13: 900 | E13: VOLTS: | F13: 4000 | H13: 3 PH / | I13: 60 Hz | L13: S. RPM: | M13: 1800
B14: FRAME: | C14: 6811US | E14: ENCL: | F14: TEFC | H14: FLAMPS: | I14: 115 | L14: FLRPM: | M14: 1789
B15: FORM: | C15: FCW4 | E15: S.F.: | F15: 1.15 | H15: NEMA DESIGN: | I15: - | L15: INSUL CLASS: | M15: F
B16: TYPE: | C16: TIKE | E16: AMB.: | F16: 40°C | H16: CODE: | I16: G | L16: DUTY: | M16: Cont.
B17: MODEL No.: | H17: kW: | I17: -
B18: NOM. EFF.: | C18: - | E18: MIN. EFF.: | F18: - | H18: P.F.: | I18: -
A21: AMPERAGE | E21: TORQUES | I21: **BEARINGS:
A22: LOCKED ROTOR: | D22: 742 | G22: FULL LOAD (lb-ft.): | H22: 2642 | K22: DRIVE END:
G23: LOCKED ROTOR (%): | H23: 115 | K23: OPPOSITE DRIVE END:
G24: BREAK DOWN (%): | H24: 220
A28: EFFICIENCY | H28: POWER FACTOR
C29: FULL LOAD: | D29: 94.7 | J29: FULL LOAD: | K29: 89.4
C30: 3/4 LOAD: | D30: 94.1 | J30: 3/4 LOAD: | K30: 88.7
C31: 1/2 LOAD: | D31: 92.8 | J31: 1/2 LOAD: | K31: 85.1
A35: ALL CHARACTERISTICS ARE AVERAGE EXPECTED VALUES BASED UPON RATED VOLTAGE,
A36: FREQUENCY AND SINEWAVE POWER INPUT.
A37: THE DECLARED LOCKED ROTOR CURRENT HAS A TOLERANCE OF 20%
A38: * TEMPERATURE RISE WILL BE CONSISTENT WITH INSULATION, AMBIENT AND SERVICE FACTOR AS
A39: DEFINED BY NEMA-MG-12 OR -20
A40: ** BEARINGS ARE THE ONLY RECOMMENDED SPARE PART(S).
J42: CERTIFIED BY: | K42: JERRY R
J44: DATE: | K44: 43973
A59: - | B59: 6205ZZ | D59: 1 | E59: -
A60: TEFC | B60: 6206UU | D60: 1.15 | E60: A
A61: ODP | B61: 6207ZZ | E61: B
B62: 6208UU
B63: 6211ZZ
B64: 6211C3
B65: 6211ZZC3
B66: 6305UUC3
...

Sheet STCurve
A2: TOSHIBA INTERNATIONAL CORPORATION
A3: Speed Torque/Current Curve
A6: Model #: | B6: ='Performance Data Sheet'!C17 -> 0 | E6: FLAmps: | F6: ='Performance Data Sheet'!I14 & " A" -> 115 A
A7: Enclosure: | B7: ='Performance Data Sheet'!F14 -> TEFC | C7: Voltage: | D7: ='Performance Data Sheet'!F13 & " V" -> 4000 V | E7: Frame: | F7: ='Performance Data Sheet'!C14 -> 6811US
A8: Pole: | B8: 4 | C8: Frequency: | D8: 3 PH / 60 Hz | E8: Ins. Class: | F8: F
A9: HP: | B9: 900 | C9: Rotor Inertia: | D9: 863.9 lb-ft² | E9: Date: | F9: ='Performance Data Sheet'!K44 -> 43973
A10: FLRPM: | B10: 1785 | C10: Load Inertia: | D10: N/A | E10: File: | F10: CS4900U
B12: Locked Rotor Amps: | C12: ='Performance Data Sheet'!D22 & "A" -> 742A | D12: Load Type: | E12: N/A
B13: Locked Rotor Torque: | C13: 1.15 | D13: Starting at: | E13: N/A
B14: Breakdown Torque: | C14: 2.2 | D14: Accel. Time: | E14: N/A
B15: Rated Torque: | C15: 2648 lb-ft
A39: Comments: | B39: PROJECT | C39: ='Performance Data Sheet'!C10 -> 0 | E39: D.E.Curve #: | F39: =F10 -> CS4900U
C43: Prepared by: | D43: ='Performance Data Sheet'!K42 -> JERRY R | E43: Checked by:
D53: Load
A54: 100 | B54: 0 | C54: 0.20877804 | D54: 100
A55: 99.2 | B55: 160.97573 | C55: 201.68808 | D55: 98.400002
A56: 96 | B56: 220 | C56: 513.16125 | D56: 89.75
A57: 90.857143 | B57: 152.13391 | C57: 569.70233 | D57: 76.228569
A58: 85.714285 | B58: 126.39542 | C58: 585.53333 | D58: 62.85714
A59: 80.571428 | B59: 118.27974 | C59: 594.27234 | D59: 51.257141
A60: 70.285714 | B60: 115.10002 | C60: 606.65344 | D60: 33.485714
A61: 59.999999 | B61: 115 | C61: 616.40698 | D61: 22
A62: 50 | B62: 115.0097 | C62: 624.1991 | D62: 14
A63: 39.999998 | B63: 115.01294 | C63: 630.39929 | D63: 7.9999995
A64: 30.000001 | B64: 115.01731 | C64: 635.29382 | D64: 5.9999995
A65: 19.999999 | B65: 115.02586 | C65: 639.24609 | D65: 8.000001
... A67: 0 | B67: 115 | C67: 645.21741 | D67: 30

Sheet Thermdam
A2: TOSHIBA INTERNATIONAL CORPORATION
A3: Thermal Limit Curve
A4: Design Values (For Reference Only)
A6: Model #: | B6: ='Performance Data Sheet'!C17 -> 0 | E6: FLAmps: | F6: ='Performance Data Sheet'!I14 & " A" -> 115 A
A7: Enclosure: | B7: ='Performance Data Sheet'!F14 -> TEFC | C7: Voltage: | D7: ='Performance Data Sheet'!F13 & " V" -> 4000 V | E7: Frame: | F7: ='Performance Data Sheet'!C14 -> 6811US
A8: Pole: | B8: 4 | C8: Frequency: | D8: 3 PH / 60 Hz | E8: Ins. Class: | F8: F
A9: HP: | B9: 900 | C9: Rotor Inertia: | D9: 863.9 lb-ft² | E9: Date: | F9: ='Performance Data Sheet'!K44 -> 43973
A10: FLRPM: | B10: 1785 | C10: Load Inertia: | D10: N/A | E10: File: | F10: CS4900U
A39: Comments: | B39: PROJECT | C39: ='Performance Data Sheet'!C10 -> 0 | E39: D.E.Curve #: | F39: =F10 -> CS4900U
C43: Prepared by: | D43: ='Performance Data Sheet'!K42 -> JERRY R | E43: Checked by:
F50: =5252.1*B50/D53 -> #DIV/0!
D66: =D65/D64 -> #DIV/0!
A67: Current (%) | B67: Cold | C67: Hot | E67: CURRENT (%) | F67: Accel. Time
A68: 645.21739 | B68: 35 | C68: 15 | E68: =A68 -> 645.21739 | F68: 0.0001
A69: =FLOOR(A68,100) -> 600 | B69: =((A68/A69)^2)*B68 -> 40.474144 | C69: =((A68/A69)^2)*C68 -> 17.346062 | E69: 643.82609 | F69: 0.95099998
A70: =A69-100 -> 500 | B70: =((A68/A70)^2)*B68 -> 58.282767 | C70: =((A68/A70)^2)*C68 -> 24.978329 | E70: 640.86957 | F70: 1.801
A71: =A70-100 -> 400 | B71: =((A68/A71)^2)*B68 -> 91.066824 | C71: =((A68/A71)^2)*C68 -> 39.028639 | E71: 637.30435 | F71: 2.615
A72: =A71-100 -> 300 | B72: =((A68/A72)^2)*B68 -> 161.89658 | E72: 632.86957 | F72: 3.4289999
A73: =A72-100 -> 200 | B73: =((A68/A73)^2)*B68 -> 364.2673 | E73: 627.30435 | F73: 4.2750001
A74: 220 | B74: =((A68/A74)^2)*B68 -> 301.04735 | C74: =((A68/A74)^2)*C68 -> 129.02029 | E74: 620.26087 | F74: 5.1820002
A75: 180 | B75: =((A68/A75)^2)*B69 -> 520.04963 | C75: =((A68/A75)^2)*C68 -> 192.73402 | E75: 611.56522 | F75: 6.2179999
A76: 145 | B76: =((A68/A76)^2)*B68 -> 693.01745 | C76: =((A68/A76)^2)*C68 -> 297.00748 | E76: 600.43478 | F76: 7.4349999
A77: 125 | C77: =CEILING(C76*2,100) -> 600 | E77: 589.91304 | F77: 8.1280003
A78: 125 | C78: =2*C77 -> 1200 | E78: 577.65217 | F78: 8.7770004
A79: 125 | C79: 10000 | E79: 541.3913 | F79: 9.2160006
E80: 357.3913 | F80: 9.5080004
E81: 0 | F81: 9.5650005

Sheet Performance 4000V
A2: TOSHIBA INTERNATIONAL CORPORATION
A3: Performance Curve
A4: Design Values (For Reference Only)
A6: Model #: | B6: ='Performance Data Sheet'!C17 -> 0 | E6: FLAmps: | F6: ='Performance Data Sheet'!I14 & " A" -> 115 A
A7: Enclosure: | B7: ='Performance Data Sheet'!F14 -> TEFC | C7: Voltage: | D7: ='Performance Data Sheet'!F13 & " V" -> 4000 V | E7: Frame: | F7: ='Performance Data Sheet'!C14 -> 6811US
A8: Pole: | B8: 4 | C8: Frequency: | D8: 3 PH / 60 Hz | E8: Ins. Class: | F8: F
A9: HP: | B9: 900 | C9: Rotor Inertia: | D9: 863.9 lb-ft² | E9: Date: | F9: ='Performance Data Sheet'!K44 -> 43973
A10: FLRPM: | B10: 1785 | C10: Load Inertia: | D10: N/A | E10: File: | F10: CS4900U
B12: Locked Rotor Amps: | C12: ='Performance Data Sheet'!D22 & "A" -> 742A | D12: Load Type: | E12: N/A
B13: Locked Rotor Torque: | C13: 1.15 | D13: Starting at: | E13: N/A
B14: Breakdown Torque: | C14: 2.2 | D14: Accel. Time: | E14: N/A
B15: Rated Torque: | C15: 2648 lb-ft
A39: Comments: | B39: PROJECT | C39: ='Performance Data Sheet'!C10 -> 0 | E39: D.E.Curve #: | F39: =F10 -> CS4900U
C43: Prepared by: | D43: ='Performance Data Sheet'!K42 -> JERRY R | E43: Checked by:
A53: Load | B53: Efficiency | C53: PF | D53: Amps | E53: RPM | F53: Input Watts
A54: 0 | D54: 24.75617 | E54: 100 | F54: 2
A55: 25 | B55: 88.413521 | C55: 70.369446 | D55: 39.084595 | E55: 84.677674 | F55: 10.585835
A56: 50 | B56: 92.758469 | C56: 85.121925 | D56: 61.594711 | E56: 71.803995 | F56: 20.179956
A57: 75 | B57: 94.115341 | C57: 88.719437 | D57: 87.367622 | E57: 58.689596 | F57: 29.833529
A58: 100 | B58: 94.660614 | C58: 89.356277 | D58: 114.9937 | E58: 44.5591 | F58: 39.548907
A59: 125 | B59: 94.851318 | C59: 88.676323 | D59: 144.5531 | E59: 30.470279 | F59: 49.336739

Sheet Performance 2300V
A2: TOSHIBA INTERNATIONAL CORPORATION
A3: Performance Curve
A4: Design Values (For Reference Only)
A6: Model #: | B6: =STCurve!B6 -> 0 | E6: FLAmps: | F6: 199
A7: Enclosure: | B7: =STCurve!B7 -> TEFC | C7: Voltage: | D7: 2300 V | E7: Frame: | F7: =STCurve!F7 -> 6811US
A8: Pole: | B8: 4 | C8: Frequency: | D8: 3 PH / 60 Hz | E8: Ins. Class: | F8: F
A9: HP: | B9: 900 | C9: Rotor Inertia: | D9: 863.9 lb-ft² | E9: Date: | F9: =STCurve!F9 -> 43973
A10: FLRPM: | B10: 1785 | C10: Load Inertia: | D10: N/A | E10: File: | F10: CS4900U
B12: Locked Rotor Amps: | C12: 1280 A | D12: Load Type: | E12: N/A
B13: Locked Rotor Torque: | C13: 1.15 | D13: Starting at: | E13: N/A
B14: Breakdown Torque: | C14: 2.2 | D14: Accel. Time: | E14: N/A
B15: Rated Torque: | C15: 2648 lb-ft
A39: Comments: | B39: PROJECT | C39: ='Performance Data Sheet'!C10 -> 0 | E39: D.E.Curve #: | F39: =F10 -> CS4900U
C43: Prepared by: | D43: ='Performance Data Sheet'!K42 -> JERRY R | E43: Checked by:
A53: Load | B53: Efficiency | C53: PF | D53: Amps | E53: RPM | F53: Input Watts
A54: 0 | D54: 42.433787 | E54: 100 | F54: 2
A55: 25 | B55: 88.352592 | C55: 70.662415 | D55: 67.334557 | E55: 85.464979 | F55: 10.530032
A56: 50 | B56: 92.676598 | C56: 85.256386 | D56: 106.40909 | E56: 72.479812 | F56: 20.077465
A57: 75 | B57: 94.024376 | C57: 88.775612 | D57: 151.08902 | E57: 59.243705 | F57: 29.684505
A58: 100 | B58: 94.562943 | C58: 89.36042 | D58: 198.99379 | E58: 44.955691 | F58: 39.353917
A59: 125 | B59: 94.748421 | C59: 88.63604 | D59: 250.28418 | E59: 30.742624 | F59: 49.096098
