Workbook
Name Print_Area_MI: 'Performance Data Sheet'!$A$10:$N$42

Sheet DesignSheet
A1: TOSHIBA INTERNATIONAL CORPORATION | I1: Calc. Code: | J1: 2-2-2-0-1-2
A2: 3-PHASE SQUIRREL CAGE INDUCTION MOTOR DESIGN SHEET | J2: B.L.-1 P.F.-1
A3: File: | B3: K:\Active Projects\6800 Frame TEFC\Electrical Design\4P\Cu_SERIES\CS4M20U.rat | G3: Date: | H3: 41800 | I3: Time: | J3: 0.46498843
A4: Pole | B4: HP | C4: RPM | D4: Form | E4: Voltage | F4: Frequency | G4: Temperature | H4: FLSpeed | I4: FLSlip | J4: Frame
A5: 4 | B5: 1000 | C5: 1800 | D5: FCW4 | E5: 4000 | F5: 60 | G5: 115 | H5: 1789.4 / 1789.0 | I5: 0.0059 / 0.0061 | J5: 6811US
A6: Core Data | D6: Winding Data | H6: Constant Data
B7: Primary | C7: Secondary | F7: Bar | G7: End Ring | H7: St. Slot Pitch | I7: 26.860594 | J7: LR Test Data
A8: Air Gap | B8: 3 | H8: Rt. Slot Pitch | I8: 31.855723 | J8: ES
A9: Space Fac. | B9: 0.93000001 | D9: Pitch | E9: 1 ~ 14 | F9: Cross Section Area | H9: Mean Value | I9: 29.358159 | J9: 918.21289
A10: Core Length | B10: 650 | C10: 650 | F10: UB: 420.0 | G10: UER: 1978.0 | H10: Eff.T.W.St. | I10: 15.276446 | J10: WS
A11: OD | B11: 770 | C11: 507 | D11: Coil Pitch | E11: 0.86658 | H11: Eff.T.W.Rt. | I11: 31.398656 | J11: 21421.565
A12: ID | B12: 513 | C12: 200 | D12: Slot Fill | E12: - | F12: EBL: 50.5 | G12: ERD1: 416.0 | H12: St.Carter Fac. | I12: 1.2197491 | J12: IS
A13: Core Depth | B13: 63.5 | C13: 112.45 | D13: Con./Slot | E13: 20 | G13: ERT: 46.00 | H13: Rt.Carter Fac. | I13: 1.0145569 | J13: 123.34966
A14: Eff.Core L. | B14: 604.5 | C14: 604.5 | D14: Wire Size 1 | E14: (.091"x.258")x2 | F14: (12 x 35) | G14: ERH: 43.00 | H14: Carter Factor | I14: 1.2375048 | J14: Volts / Turn
A15: Slot Data | D15: Wire Size 2 | E15: - | H15: Short. Factor | I15: 0.97811905 | J15: 23.094687
A16: Number | B16: 60 | C16: 50 | D16: // Circuits | E16: 2 | H16: Distrib. Factor | I16: 0.956506 | J16: AC
A17: Kind | B17: Open | C17: Rectang | D17: Connection | E17: Wye | H17: Wind. Factor | I17: 0.93557674 | J17: 459.22164
A18: Skew | B18: - | C18: 0 | D18: MCL | E18: 1366 | F18: 797 | H18: Reactance | I18: (Coeff.: 0.0702)
A19: Depth | B19: 65 | C19: 41.049999 | D19: No.Cond./Ph. | E19: 200 | I19: Running | J19: Start
A20: Width | B20: 11.58 - 11.58 | C20: 12.05 | D20: Res. (20°C) | E20: 0.08018486 | H20: Stator Slot | I20: 17.640198 | J20: 17.640198
A21: Opening | B21: 17 | C21: 3 | D21: (115°C) | E21: 0.11011634 | F21: 0.097016931 | G21: 0.022570247 | H21: Rotor Slot | I21: 28.128721 | J21: 22.920938
A22: Tip Depth | B22: 3.6500001 | C22: 6 | D22: Material | E22: CU | F22: CU | G22: CU | H22: Zigzag | I22: 4.4773202 | J22: 4.3765616
A23: T.Min.Wid. | B23: 9.8605947 | C23: 14.653447 | D23: Spec.Resist. | E23: 1.742 | F23: 1.742 | G23: 1.742 | H23: Coil End | I23: 11.986788 | J23: Skew R.: 0.00
A24: Low. R. | B24: 0 | C24: 0.80000001 | D24: Spec.Gravity | E24: 8.8900003 | F24: 8.8900003 | G24: 8.8900003 | H24: Belt Leakage | I24: 4.0282923 | J24: 3.9780207
A25: Up. R. | B25: - | C25: 0.80000001 | D25: Weight (kg) | H25: Total Resist. | I25: 0.22970352 | J25: 0.46930373
A26: Wedge Dep. | B26: 3.65 - 2.00 | C26: Magnetic | D26: Wire 1 | E26: 432.45428 | F26: 157.37968 | G26: 50.818073 | H26: Total React. | I26: 4.6512084 | J26: 4.2722125
A27: Duct | B27: - | C27: - | D27: Wire 2 | E27: - | F27: - | G27: - | H27: Impedance | I27: 4.656877 | J27: 4.2979121
A28: Effective Depth (S=1) | D28: Magnetic Circuit Data | I28: Core Loss Data
B29: Res.= | C29: 35.004476 | E29: Length | F29: Section | G29: Density | H29: AT | I29: Volume | J29: Loss
B30: Reac.= | C30: 35.036976 | D30: Primary Core | E30: 30.237804 | F30: 767.715 | G30: 12.069754 | H30: 172.51759 | I30: 85198.452 | J30: 4099.653
A31: Excitation Data | D31: Tooth | E31: 6.5 | F31: 894.10943 | G31: 10.363532 | H31: 23.055512 | I31: 23246.845 | J31: 873.87751
A32: Excit.Amps | B32: 25.731 / 28.639 | D32: Second.Core | E32: 16.68577 | F32: 1359.5205 | G32: 6.8157349 | H32: 30.868674 | I32: Total | J32: 4973.5305
A33: Core Loss | B33: 1.400 / 1.559 | C33: Flux / Pole | D33: Tooth | E33: 4.1049999 | F33: 1107.2511 | G33: 8.3685908 | H33: 8.7475748 | I33: C.L.C. | J33: 1.75 / 0.73
A34: NoLoad | B34: 25.77 / 28.68 | C34: 9.2661314 | D34: Air Gap | E34: 0.3 | F34: 2116.281 | G34: 4.3784976 | H34: 1045.2902 | I34: S.F.C. | J34: 6.0500002
A35: Load Characteristics | D35: Temp. Rise @ 100%: | E35: 65 / 63 | G35: No Load Loss | H35: 19170.6 / 14202.1 | I35: W.Loss | J35: 8703.7 / 3618.3
A36: Load (%) | B36: 25 | C36: 50 | D36: 75 | E36: 100 | F36: 125 | G36: Primary Loss | H36: 5026.3 / 4948.3 | I36: S.Loss | J36: 1007.6 / 418.9
A37: Current (A) | B37: 41.30 / 42.42 | C37: 65.73 / 67.50 | D37: 93.56 / 96.09 | E37: 123.35 / 126.69 | F37: 155.20 / 159.40 | G37: Second. Loss | H37: 4640.5 / 4810.6 | I37: Total C.Loss | J37: 9711.3 / 4037.2
A38: Efficiency | B38: 0.904 / 0.890 | C38: 0.946 / 0.931 | D38: 0.959 / 0.944 | E38: 0.964 / 0.949 | F38: 0.965 / 0.951 | G38: Frict.& Wind. | H38: 9300.0 / 10813.0 | I38: Stray Loss | J38: 15648.788
A39: P.F. | B39: 0.721 / 0.713 | C39: 0.866 / 0.857 | D39: 0.901 / 0.891 | E39: 0.906 / 0.896 | F39: 0.898 / 0.888 | G39: Starting Data | I39: Slip | J39: PF
A40: Slip | B40: 0.0015 / 0.0017 | C40: 0.0029 / 0.0031 | D40: 0.0043 / 0.0046 | E40: 0.0059 / 0.0061 | F40: 0.0074 / 0.0077 | G40: LRA | H40: 537.3 / 820.5
...

Sheet Data Sheet
A1: TOSHIBA INTERNATIONAL CORPORATION
A2: INDUCTION MOTOR DATA SHEET
A3: File: | B3: CS4M20U | I3: HRW / Model Number: | J3: M204FTQL11E-C
A4: Type: TIKE - Form: FCW4 - 4 Pole - 1000 HP -2300/4000 V - 60 Hz - 6811US - Class F | Q4: Motor Type Selection | T4: Electrical Steel Table
A5: Motor Parameters | F5: PERFORMANCE | J5: DESIGN | K5: TEST | L5: 2300V | Q5: EPACT | T5: M22 - 26Ga.
A6: Material | D6: M36 - 26Ga. | F6: NL & Impedance Test | K6: QC# 180102584 | L6: 240800579 | Q6: EQP-III | T6: M36 - 26Ga.
A7: Air Gap | D7: 3 | F7: No load amps | J7: 29 | K7: 28.9 | L7: 51.5 | Q7: Exp.Prf. | T7: NCB1 - 26Ga.
A8: Stack length | D8: 650 | F8: No load watts | J8: 15058 | K8: 19017.7 | L8: 16300 | Q8: Exp.Prf.-EQPIII | T8: M43 - 26Ga.
A9: Number of turns per coil | D9: 10 | F9: Impedance amps | H9: 3 | I9: f | J9: 132.72 | K9: 158 | L9: 188.5 | Q9: Prem. Eff. | T9: M45 - 26Ga.
A10: Wire 1 (size & number) | D10: (.091"x.258")x2 | F10: Impedance volts | H10: 3 | I10: f | J10: 1150 | K10: - | L10: 460 | Q10: OWP | T10: M54 - 26Ga.
A11: Wire 2 (size & number) | D11: - | F11: Impedance watts | H11: 3 | I11: f | J11: 26079 | K11: 32000 | L11: 14679 | Q11: Dry Kiln
A12: Slot fill - circle/square method (%) | D12: - | F12: Temperature Rise (°C)
A13: Connection | D13: 2D / 2Y | G13: Winding | I13: 80/115 | J13: 65 / 86 | K13: -
A14: MCL | D14: 1366 | G14: Frame | J14: - | K14: -
A15: Allowance for ins. depth | D15: 11.122 | G15: Bearing PS/OS | J15: - | K15: -
A16: Allowance for ins. width | D16: 3.4935999 | G16: End Ring | J16: - | K16: -
A17: Slot/Wire arrangement | D17: 20 x 2 | F17: Nameplate Data
A18: Effective cross section for coil | D18: - | H18: FLC (A) | J18: 220 / 127 | M18: =J18*6.5 -> #VALUE!
A19: Coil grouping | D19: - | H19: RPM | J19: 1789
A20: Coil pitch (slot number) | D20: 1 ~ 14 | H20: CODE | J20: G
A21: Method of coil connection | D21: - | H21: S. F. | J21: 1.15 | Q21: Method of Connection
A22: Resistance per phase @ 20 °C | D22: 0.0807 | H22: DESIGN | J22: - | Q22: Skip
A23: Coil Weight | B23: Wire1 | D23: 973 | H23: Nom.Eff. (%): | Q23: Adjacent
A24: (lbs.) | B24: Wire2 | D24: - | H24: Min.Eff. (%): | Q24: -
A25: Current Densities (A/cm2) | E25: Bar / ER | H25: P.F. (%):
A26: FL / LR | D26: 213 / 1377 | E26: 312 / 264
A27: Stator Slot Shape (Reference) | F27: Performance
H28: LRC (A) | I28: - | J28: 1422 / 821 | K28: - | M28: =(J28/J18)*100 -> #VALUE!
H29: LRT (%) | I29: 60 | J29: 115 | K29: -
H30: BDT (%) | I30: 175 | J30: 220 | K30: -
H31: SLIP (%) | J31: 0.61 | K31: -
G32: IEEE-B | H32: Eff. (%) | J32: 94.9 | K32: -
A33: Rotor Slot Shape (Reference) | H33: PF (%) | J33: 89.6 | K33: - | M33: =821*SQRT(3) -> 1422.0137
F34: Losses (Watts) | H34: Primary | J34: 4948 | K34: -
H35: Secondary | J35: 4811 | K35: -
H36: Core | J36: 4037 | K36: -
H37: F & W | J37: 10813 | K37: -
H38: Stray | J38: 15649 | K38: -
A39: End Ring (Reference) | F39: Note
G40: QC Limits: CS4M20U
...

Sheet LoginSheet
J1: P | K1: T | L1: L | M1: T
B2: PROJECT HISTORY | J2: E | K2: D | L2: I | M2: Y | N2: H
J3: R | L3: M | M3: P
J4: F | L4: I | M4: E
K5: C | L5: T | N5: I
J6: D | K6: U | M6: T | N6: N
J7: A | K7: R | L7: R | M7: E | N7: S
I8: S | J8: T | K8: V | L8: E | M8: S | N8: U
B9: DATE | C9: PROJECT | D9: SMART NUMBER | E9: QTY | F9: CUSTOMER | G9: REMARKS | H9: LIMIT CODE | I9: F | J9: A | K9: E | L9: V | M9: T | N9: L
B53: REVISION HISTORY
B54: REV | C54: REMARKS | I54: DATE | L54: INIT

Sheet Performance Data Sheet
A1: TOSHIBA INTERNATIONAL CORPORATION | J1: INDEX | L1: MPCF-1033
A2: Industrial Division / Houston Motor Plant | J2: SHEET NO. | L2: 1 of 1
J3: ISSUED | L3: 7/31/13
J4: SUPERSEDES | L4: 11/8/96
J5: REVISION | L5: 2
A6: SQUIRREL CAGE INDUCTION MOTOR | J6: WRITTEN BY | L6: MDC
A7: PERFORMANCE SPECIFICATIONS | J7: APPROVED BY | L7: PAA
B9: CUSTOMER:
B10: TIC SR No.:
A12: MOTOR NAMEPLATE DATA
B13: H.P.: | C13: 1000 | E13: VOLTS: | F13: 2300/4000 | H13: 3 PH / | I13: 60 Hz | L13: S. RPM: | M13: 1800
B14: FRAME: | C14: 6811US | E14: ENCL: | F14: TEFC | H14: FLAMPS: | I14: 220/127 | L14: FLRPM: | M14: 1789
B15: FORM: | C15: FCW4 | E15: S.F.: | F15: 1.15 | H15: NEMA DESIGN: | I15: - | L15: INSUL CLASS: | M15: F
B16: TYPE: | C16: TIKE | E16: AMB.: | F16: 40 | H16: CODE: | I16: G | L16: DUTY: | M16: Cont.
B17: MODEL No.: | C17: M204FTQL11E-C | H17: kW: | I17: -
B18: NOM. EFF.: | C18: - | E18: MIN. EFF.: | F18: - | H18: P.F.: | I18: -
A21: AMPERAGE | E21: TORQUES | I21: **BEARINGS:
C22: LOCKED ROTOR: | D22: 1422/821 | G22: FULL LOAD (lb-ft.): | H22: 2936 | K22: DRIVE END:
G23: LOCKED ROTOR (%): | H23: 115 | K23: OPPOSITE DRIVE END:
G24: BREAK DOWN (%): | H24: 220
A28: EFFICIENCY | H28: POWER FACTOR
C29: FULL LOAD: | D29: 94.9 | J29: FULL LOAD: | K29: 89.6
C30: 3/4 LOAD: | D30: 94.4 | J30: 3/4 LOAD: | K30: 89.1
C31: 1/2 LOAD: | D31: 93.1 | J31: 1/2 LOAD: | K31: 85.7
A35: ALL CHARACTERISTICS ARE AVERAGE EXPECTED VALUES BASED UPON RATED VOLTAGE,
A36: FREQUENCY AND SINEWAVE POWER INPUT.
A37: THE DECLARED LOCKED ROTOR CURRENT HAS A TOLERANCE OF 20%.
A38: * TEMPERATURE RISE WILL BE CONSISTENT WITH INSULATION, AMBIENT AND SERVICE FACTOR AS
A39: DEFINED BY NEMA-MG-12 OR -20.
A40: ** BEARINGS ARE THE ONLY RECOMMENDED SPARE PART(S).
J42: CERTIFIED BY: | K42: Jerry R
J44: DATE: | K44: 45306
A59: - | B59: 6205ZZ | D59: 1 | E59: -
A60: TEFC | B60: 6206UU | D60: 1.15 | E60: A
A61: ODP | B61: 6207ZZ | E61: B
B62: 6208UU
B63: 6211ZZ
B64: 6211C3
B65: 6211ZZC3
B66: 6305UUC3
...

Sheet STCurve
A2: TOSHIBA INTERNATIONAL CORPORATION
A3: Speed Torque/Current Curve
A6: Model #: | B6: ='Performance Data Sheet'!C17 -> M204FTQL11E-C | E6: FLAmps: | F6: ='Performance Data Sheet'!I14 & " A" -> 220/127 A
A7: Enclosure: | B7: ='Performance Data Sheet'!F14 -> TEFC | C7: Voltage: | D7: ='Performance Data Sheet'!F13 & " V" -> 2300/4000 V | E7: Frame: | F7: ='Performance Data Sheet'!C14 -> 6811US
A8: Pole: | B8: 4 | C8: Frequency: | D8: 3 PH / 60 Hz | E8: Ins. Class: | F8: F
A9: HP: | B9: 1000 | C9: Rotor Inertia: | D9: 968.2 lb-ft² | E9: Date: | F9: ='Performance Data Sheet'!K44 -> 45306
A10: FLRPM: | B10: 1789 | C10: Load Inertia: | D10: N/A | E10: File: | F10: CS4M20U
B12: Locked Rotor Amps: | C12: ='Performance Data Sheet'!D22 & " A" -> 1422/821 A | D12: Load Type: | E12: N/A
B13: Locked Rotor Torque: | C13: 1.15 | D13: Starting at: | E13: N/A
B14: Breakdown Torque: | C14: 2.2 | D14: Accel. Time: | E14: N/A
B15: Rated Torque: | C15: 2942 lb-ft
A39: Comments: | B39: PROJECT | C39: ='Performance Data Sheet'!C10 -> 0 | E39: D.E.Curve #: | F39: =F10 -> CS4M20U
C43: Prepared by: | D43: ='Performance Data Sheet'!K42 -> Jerry R | E43: Checked by: | F43: AG
D53: Load
A54: 100 | B54: 0 | C54: 0.20290348 | D54: 100
A55: 99.8 | B55: 164.54852 | C55: 204.70439 | D55: 99.599998
A56: 99 | B56: 220 | C56: 515.55176 | D56: 98
A57: 93.789474 | B57: 142.44674 | C57: 570.6424 | D57: 83.852631
A58: 88.578947 | B58: 123.37755 | C58: 586.11072 | D58: 70.30526
A59: 83.368421 | B59: 117.44139 | C59: 594.76471 | D59: 57.410526
A60: 72.947368 | B60: 115.21028 | C60: 607.20667 | D60: 38.010525
A61: 62.526315 | B61: 115.15471 | C61: 617.09943 | D61: 24.778948
A62: 52.105263 | B62: 115.09873 | C62: 625.02704 | D62: 15.68421
A63: 41.68421 | B63: 115.06491 | C63: 631.34479 | D63: 9.0105257
A64: 31.263161 | B64: 115.03695 | C64: 636.33325 | D64: 6.2526321
A65: 20.842105 | B65: 115.02076 | C65: 640.36371 | D65: 7.8315787
... A67: 0 | B67: 115 | C67: 646.45667 | D67: 30

Sheet Thermdam
A2: TOSHIBA INTERNATIONAL CORPORATION
A3: Thermal Limit & Acceleration Curves
A4: Design Values (For Reference Only)
A6: Model #: | B6: ='Performance Data Sheet'!C17 -> M204FTQL11E-C | E6: FLAmps: | F6: ='Performance Data Sheet'!I14 & " A" -> 220/127 A
A7: Enclosure: | B7: ='Performance Data Sheet'!F14 -> TEFC | C7: Voltage: | D7: ='Performance Data Sheet'!F13 & " V" -> 2300/4000 V | E7: Frame: | F7: ='Performance Data Sheet'!C14 -> 6811US
A8: Pole: | B8: 4 | C8: Frequency: | D8: 3 PH / 60 Hz | E8: Ins. Class: | F8: F
A9: HP: | B9: 1000 | C9: Rotor Inertia: | D9: 968.2 lb-ft² | E9: Date: | F9: ='Performance Data Sheet'!K44 -> 45306
A10: FLRPM: | B10: 1789 | C10: Load Inertia: | D10: N/A | E10: File: | F10: CS4M20U
A39: Comments: | B39: PROJECT | C39: ='Performance Data Sheet'!C10 -> 0 | E39: D.E.Curve #: | F39: =F10 -> CS4M20U
C43: Prepared by: | D43: ='Performance Data Sheet'!K42 -> Jerry R | E43: Checked by: | F43: AG
F50: =5252.1*B50/D53 -> #DIV/0!
D66: =D65/D64 -> #DIV/0!
A67: Current (%) | B67: Cold | C67: Hot | E67: CURRENT (%) | F67: Accel. Time
A68: 646.45669 | B68: 35 | C68: 15 | E68: =A68 -> 646.45669 | F68: 0.0001
A69: =FLOOR(A68,100) -> 600 | B69: =((A68/A69)^2)*B68 -> 40.629775 | C69: =((A68/A69)^2)*C68 -> 17.412761 | E69: 645.03937 | F69: 0.97799999
A70: =A69-100 -> 500 | B70: =((A68/A70)^2)*B68 -> 58.506876 | C70: =((A68/A70)^2)*C68 -> 25.074375 | E70: 642.04724 | F70: 1.851
A71: =A70-100 -> 400 | B71: =((A68/A71)^2)*B68 -> 91.416993 | C71: =((A68/A71)^2)*C68 -> 39.178711 | E71: 638.34646 | F71: 2.6900001
A72: =A71-100 -> 300 | B72: =((A68/A72)^2)*B68 -> 162.5191 | E72: 633.85827 | F72: 3.533
A73: =A72-100 -> 200 | B73: =((A68/A73)^2)*B68 -> 365.66797 | E73: 628.18898 | F73: 4.415
A74: 220 | B74: =((A68/A74)^2)*B68 -> 302.20494 | C74: =((A68/A74)^2)*C68 -> 129.5164 | E74: 621.10236 | F74: 5.369
A75: 180 | B75: =((A68/A75)^2)*B69 -> 524.0567 | C75: =((A68/A75)^2)*C68 -> 193.47512 | E75: 612.12598 | F75: 6.4499998
A76: 120 | B76: =((A68/A76)^2)*B68 -> 1015.7444 | C76: =((A68/A76)^2)*C68 -> 435.31902 | E76: 601.02362 | F76: 7.77
A77: 110 | C77: =CEILING(C76*2,100) -> 900 | E77: 590.47244 | F77: 8.5699997
A78: 110 | C78: =2*C77 -> 1800 | E78: 578.34646 | F78: 9.3809996
A79: 110 | C79: 10000 | E79: 543.07087 | F79: 9.882
E80: 360.15748 | F80: 9.9560003
E81: 0 | F81: 10.009001

Sheet Performance 4000V
A2: TOSHIBA INTERNATIONAL CORPORATION
A3: Performance Curve
A4: Design Values (For Reference Only)
A6: Model #: | B6: ='Performance Data Sheet'!C17 -> M204FTQL11E-C | E6: FLAmps: | F6: 127 A
A7: Enclosure: | B7: ='Performance Data Sheet'!F14 -> TEFC | C7: Voltage: | D7: 4000 V | E7: Frame: | F7: ='Performance Data Sheet'!C14 -> 6811US
A8: Pole: | B8: 4 | C8: Frequency: | D8: 3 PH / 60 Hz | E8: Ins. Class: | F8: F
A9: HP: | B9: 1000 | C9: Rotor Inertia: | D9: 968.2 lb-ft² | E9: Date: | F9: ='Performance Data Sheet'!K44 -> 45306
A10: FLRPM: | B10: 1789 | C10: Load Inertia: | D10: N/A | E10: File: | F10: CS4M20U
B12: Locked Rotor Amps: | C12: 821 A | D12: Load Type: | E12: N/A
B13: Locked Rotor Torque: | C13: 1.15 | D13: Starting at: | E13: N/A
B14: Breakdown Torque: | C14: 2.2 | D14: Accel. Time: | E14: N/A
B15: Rated Torque: | C15: 2942 lb-ft
A39: Comments: | B39: PROJECT | C39: ='Performance Data Sheet'!C10 -> 0 | E39: D.E.Curve #: | F39: =F10 -> CS4M20U
C43: Prepared by: | D43: ='Performance Data Sheet'!K42 -> Jerry R | E43: Checked by: | F43: AG
A53: Load | B53: Efficiency | C53: PF | D53: Amps | E53: RPM | F53: Input Watts
A54: 0 | D54: 26.531497 | E54: 100 | F54: 0.710105
A55: 25 | B55: 88.979111 | C55: 71.312149 | D55: 42.523209 | E55: 84.90703 | F55: 10.504307
A56: 50 | B56: 93.084282 | C56: 85.667862 | D56: 67.672668 | E56: 72.178726 | F56: 20.082099
A57: 75 | B57: 94.356819 | C57: 89.059517 | D57: 96.326378 | E57: 59.203631 | F57: 29.716895
A58: 100 | B58: 94.862709 | C58: 89.58506 | D58: 127.00082 | E58: 45.208388 | F58: 39.411229
A59: 125 | B59: 95.034225 | C59: 88.838379 | D59: 159.79639 | E59: 31.32187 | F59: 49.175122

Sheet Performance 2300V
A2: TOSHIBA INTERNATIONAL CORPORATION
A3: Performance Curve
A4: Design Values (For Reference Only)
A6: Model #: | B6: ='Performance Data Sheet'!C17 -> M204FTQL11E-C | E6: FLAmps: | F6: 220 A
A7: Enclosure: | B7: ='Performance Data Sheet'!F14 -> TEFC | C7: Voltage: | D7: 2300 V | E7: Frame: | F7: ='Performance Data Sheet'!C14 -> 6811US
A8: Pole: | B8: 4 | C8: Frequency: | D8: 3 PH / 60 Hz | E8: Ins. Class: | F8: F
A9: HP: | B9: 1000 | C9: Rotor Inertia: | D9: 968.2 lb-ft² | E9: Date: | F9: ='Performance Data Sheet'!K44 -> 45306
A10: FLRPM: | B10: 1789 | C10: Load Inertia: | D10: N/A | E10: File: | F10: CS4M20U
B12: Locked Rotor Amps: | C12: 1422 A | D12: Load Type: | E12: N/A
B13: Locked Rotor Torque: | C13: 1.15 | D13: Starting at: | E13: N/A
B14: Breakdown Torque: | C14: 2.2 | D14: Accel. Time: | E14: N/A
B15: Rated Torque: | C15: 2942 lb-ft
A39: Comments: | B39: PROJECT | C39: ='Performance Data Sheet'!C10 -> 0 | E39: D.E.Curve #: | F39: =F10 -> CS4M20U
C43: Prepared by: | D43: ='Performance Data Sheet'!K42 -> Jerry R | E43: Checked by: | F43: AG
A53: Load | B53: Efficiency | C53: PF | D53: Amps | E53: RPM | F53: Input Watts
A54: 0 | D54: 45.953901 | E54: 100 | F54: 0.710105
A55: 25 | B55: 88.979111 | C55: 71.312149 | D55: 73.652358 | E55: 84.90703 | F55: 10.504307
A56: 50 | B56: 93.084282 | C56: 85.667862 | D56: 117.2125 | E56: 72.178726 | F56: 20.082099
A57: 75 | B57: 94.356819 | C57: 89.059517 | D57: 166.84218 | E57: 59.203631 | F57: 29.716895
A58: 100 | B58: 94.862709 | C58: 89.58506 | D58: 219.97187 | E58: 45.208388 | F58: 39.411229
A59: 125 | B59: 95.034225 | C59: 88.838379 | D59: 276.77546 | E59: 31.32187 | F59: 49.175122

Sheet Form
A1: Winding Data Calculation
C2: MCL: 1366.0
A3: Coil Resistance | D3: Lead Resistance
A4: 10T: | B4: 0.0165 ~ 0.0158 | D4: AWG. 02 x 3
D5: 0.00200
A6: Coil Dimensions
A7: HM: | B7: 10T: 25.11 | C7: WM: | D7: 10T: 13.51 | E7: WT:
E8: 17.10 ~ 16.70
A9: Insulation Allowance | D9: Wire Weight
A10: Depth: | B10: 11.12 | D10: (.091"x.258")x 2: | F10: 973 lbs.
A11: Width: | B11: 3.49
A12: QC Resistance
A13: 1-2, 2-3, 3-1: | C13: 0.170 ~ 0.160

Sheet StallTime
A1: Rating: | B1: 4 Pole - 1000.0 HP - 1800 RPM - 4000 V - 60 Hz
A3: Starting Performance
D4: Load Type: Fan / Pump - 3393.0 lb-ft²
A5: RPM | B5: Motor | C5: Load | D5: Accel. | E5: Line | F5: Stator | G5: Rotor
A6: Speed Increment | B6: Torque (%) | C6: Torque (%) | D6: Time (s) | E6: Amps | F6: kW / s | G6: kW / s
A7: 0~188 | B7: 115.0 | C7: 22.4 | D7: 0.978 | E7: 819.2 | F7: 217.8 | G7: 838.6
A8: 188~375 | B8: 115.0 | C8: 11.3 | D8: 0.873 | E8: 815.4 | F8: 192.8 | G8: 670.8
A9: 375~563 | B9: 115.0 | C9: 7.0 | D9: 0.839 | E9: 810.7 | F9: 183.2 | G9: 569.3
A10: 563~750 | B10: 115.1 | C10: 7.6 | D10: 0.843 | E10: 805.0 | F10: 181.9 | G10: 497.2
A11: 750~938 | B11: 115.1 | C11: 12.3 | D11: 0.882 | E11: 797.8 | F11: 187.3 | G11: 441.2
A12: 938~1125 | B12: 115.1 | C12: 20.2 | D12: 0.954 | E12: 788.8 | F12: 198.6 | G12: 392.3
A13: 1125~1313 | B13: 115.2 | C13: 31.4 | D13: 1.081 | E13: 777.4 | F13: 219.3 | G13: 347.7
A14: 1313~1501 | B14: 116.3 | C14: 47.7 | D14: 1.320 | E14: 763.3 | F14: 259.3 | G14: 306.8
A15: 1501~1594 | B15: 120.4 | C15: 63.9 | D15: 0.800 | E15: 749.9 | F15: 150.8 | G15: 233.0
A16: 1594~1688 | B16: 132.9 | C16: 77.1 | D16: 0.811 | E16: 734.5 | F16: 148.5 | G16: 170.5
... A19: 1796~1800 | B19: 132.3 | C19: 99.8 | D19: 0.053 | E19: 146.4 | F19: 0.3 | G19: 20.1
D21: Acceleration Time: 10.0 s
B22: Energy | D22: First Start | F22: Second Start
A23: Stator Winding Rise | B23: 2037 kW / s | D23: 12°C | F23: 24°C
A24: Rotor Bar Rise | B24: 3707 kW / s | D24: 61°C | F24: 122°C
A25: End Ring Rise | B25: 862 kW / s | D25: 44°C | F25: 88°C
A27: Locked Rotor Thermal Capability
E28: Cold Condition
B29: Rate of Rise | D29: Power | E29: Rise Limit | F29: Max Time
A30: Stator Copper | B30: 1.5°C / s | D30: 255.3 kW | E30: 160°C | F30: 104.4 s
A31: Rotor Bar | B31: 11.5°C / s | D31: 696.0 kW | E31: 260°C | F31: 22.6 s
A32: Rotor ER | B32: 8.3°C / s | D32: 161.9 kW | E32: 180°C | F32: 21.8 s
E34: Hot Condition
B35: Hot Temp. | D35: Rise Limit | E35: Ambient | F35: Total | G35: Max.Time
A36: Stator Copper | B36: 63°C + | D36: 97°C + | E36: 40°C | F36: = 200°C | G36: 63.3 s
A37: Rotor Bar | B37: 83°C + | D37: 177°C + | E37: 40°C | F37: = 300°C | G37: 15.4 s
A38: Rotor ER | B38: 83°C + | D38: 97°C + | E38: 40°C | F38: = 220°C | G38: 11.7 s
A40: Cold Stall Time: | B40: 53.2 s | D40: Hot Stall Time: | F40: 28.7 s

Sheet MagNoise
A1: Magnetic Noise Verification
A3: Rating: | B3: 4 Pole - 1000.0 HP - 1800 RPM - 4000 V - 60 Hz
A5: Electromagnetic Excitation Frequencies
B7: L = | C7: 0 | D7: L = | E7: + 1 | F7: L = | G7: - 1 | H7: Slip = | I7: 0 | J7: Slip = | K7: 0.006
A8: Mode A | B8: 6 | D8: 18 | F8: 6 | H8: 1620.0 Hz | J8: 1611.2 Hz
A9: Mode B | B9: 14 | D9: 26 | F9: 2 | H9: 1380.0 Hz | J9: 1371.2 Hz
A10: Mode C | B10: 10 | D10: 22 | F10: 2 | H10: 1500.0 Hz | J10: 1491.2 Hz
A12: Natural Frequencies of Stator Core
B14: Mode 0 = | D14: 1384.7 Hz | F14: Mode 6 = | H14: 2462.6 Hz
B15: Mode 2 = | D15: 191.4 Hz | F15: Mode 7 = | H15: 3389.4 Hz
B16: Mode 3 = | D16: 541.4 Hz | F16: Mode 8 = | H16: 4459.0 Hz
B17: Mode 4 = | D17: 1038.0 Hz | F17: Mode 9 = | H17: 5671.4 Hz
B18: Mode 5 = | D18: 1678.7 Hz | F18: Mode 10 = | H18: 7026.5 Hz
A20: Analysis Results
B22: No matching frequencies detected.
