Workbook

Sheet EqCircut
B1: .
A2: What is the % BDT before Correlation ? | E2: =LEFT(J6,SEARCH("/",J6,1)-1) -> 191.5 | H2: Voltage : | J2: ='[1]DesignSheet 4000V'!E5 -> 4000 | L2: First Cycle Inrush
A3: What is the % BDT after Correlation ? | E3: =RIGHT(J6,SEARCH("/",J6,1)-2) -> 262.5 | H3: Frequency : | J3: ='[1]DesignSheet 4000V'!F5 -> 60 | L3: =1.25*SQRT(2)*(1+EXP((-PI()*D16)/D19)) -> 2.3805513
H4: No-Load Current: | J4: ='[1]DesignSheet 4000V'!B34 -> 12.67 / 12.99
A5: what are the No Load Amps? | D5: =RIGHT(J4,SEARCH("/",J4,1)-2) -> 12.99 | H5: Full Load Current: | J5: ='[1]DesignSheet 4000V'!E37 -> 62.95 / 65.49
H6: Breakdown Torque: | J6: ='[1]DesignSheet 4000V'!H45 -> 191.5 / 262.5
A7: What are the Full load Amps? | D7: =RIGHT(J5,SEARCH("/",J5,1)-2) -> 65.49 | H7: Wc: | J7: ='[1]DesignSheet 4000V'!J37 -> 7984.1 / 2779.8
H8: Wf: | J8: ='[1]DesignSheet 4000V'!H38 -> 6000.0 / 5171.6
A9: TOSHIBA INTERNATIONAL CORPORATION
A10: ALL VALUES ARE IN EQULIVALENT Y
D12: VALUE (OHMS) | F12: PER UNIT
A13: BASE IMPEDANCE PER UNIT | D13: =B49 -> 35.263415 | F13: =D13/B49 -> 1
A14: PRIMARY REISTANCE (R1) | D14: =B50 -> 0.21116658 | F14: =D14/B49 -> 0.0059882622
A15: SECONDARY RESISTANCE (R2) | D15: =B51 -> 0.21178557 | F15: =D15/B49 -> 0.0060058157 | I15: Project or Lab:
A16: STARTING RESISTANCE (R3) | D16: =B52 -> 1.4362432 | F16: =D16/B49 -> 0.040728988 | I16: RF2500
A17: PRIMARY REACTANCE (X1) | D17: =B56 -> 2.0468747 | F17: =D17/B49 -> 0.058045277
A18: SECONDARY REACTANCE (X2) | D18: =B57 -> 5.4736736 | F18: =D18/B49 -> 0.15522244
A19: STARTING REACTANCE (X3) | D19: =B60 -> 4.2588621 | F19: =D19/B49 -> 0.12077282
A20: MAGNETIZING REACTANCE (XM) | D20: =B61 -> 177.78299 | F20: =D20/B49 -> 5.0415704
A22: TRANSIENT REACTANCE (Xd') | D22: =B62 -> 7.3570557 | F22: =D22/B49 -> 0.2086314
A23: SUB TRANSIENT REACTANCE (Xd") | D23: =B63 -> 4.4102593 | F23: =D23/B49 -> 0.12506614
A24: SHORT CIRCUIT TIME CONSTANT | D24: =B64 -> 0.093901928 | F24: =D24/B49 -> 0.0026628711
A25: SUB TRANSIENT TIME CONSTANT | D25: =B65 -> 0.010594232 | F25: =D25/B49 -> 0.00030043125
A26: OPEN CIRCUIT TIME CONSTANT | D26: =B66 -> 2.2952621 | F26: =D26/B49 -> 0.065089048
A28: INDUCTANCES (HENRIES)
A29: STATOR INDUCTANCE (L1) | D29: =B67 -> 0.0054295038 | F29: =D29/B49 -> 0.00015396988
A30: ROTOR INDUCTANCE (L2) | D30: =B68 -> 0.01451937 | F30: =D30/B49 -> 0.00041174032
A31: STARTING INDUCTANCE (L3) | D31: =B69 -> 0.011296983 | F31: =D31/B49 -> 0.00032035986
A34: Rev.1 Added Starting Reactance. 11/18/04 MDC
A35: Rev.2 Corrections to calculations & added first cycle inrush 1/28/09 JR & MDC
A36: Rev.3 Corrected Calculation for R3 MDC 12/9/09
A37: Rev.4 Correction to short circuit time constant. | F37: Used to be "=(B57+((B56*B61)/(B56 * B61))/(B51*E41))" | L37: Z.X 10/25/2019
A38: Rev.5 Correction to short circuit time contstant. Used to be "=(B57+((B56*B61)/(B56+B61))/(B51*E41))" Z.X 12/14/2021
E40: 2*pi*f
B41: Jcon = | C41: =IF('[1]DesignSheet 4000V'!E17= "Delta", "3", "1") -> 1 | D41: Wo = | E41: =2*PI()*'[1]DesignSheet 4000V'!F5 -> 376.99112 | F41: Xcorr = | G41: =IF('[1]DesignSheet 4000V'!A5>4, ".5",".666666666666666666666666") -> .666666666666666666666666
B43: X BDT = | C43: =E3/E2 -> 1.3707572
A45: pacop = | B45: ='[1]DesignSheet 4000V'!I23*EqCircut!G41 -> 9.3816875 | D45: Xcorr * Coil End Reactance
A46: pacop2= | B46: ='[1]DesignSheet 4000V'!I23*(1-EqCircut!G41) -> 4.6908437 | D46: (1-Xcorr) * Coil End Reactance
A47: pac11p = | B47: ='[1]DesignSheet 4000V'!I23*EqCircut!G41 -> 9.3816875 | D47: Xcorr * Coil End Reactance
A48: pac12p = | B48: =B46 -> 4.6908437 | D48: (1-Xcorr) * Coil End Reactance
...
