Workbook
Name Print_Area_MI: 'Performance Data Sheet'!$A$10:$N$43

Sheet DesignSheet
A1: TOSHIBA INTERNATIONAL CORPORATION | I1: Calc. Code: | J1: 2-2-2-0-1-2
A2: 3-PHASE SQUIRREL CAGE INDUCTION MOTOR DESIGN SHEET | J2: B.L.-1 P.F.-1
A3: File: | B3: Z:\Motor R&D\Active Projects\6810 Development\Electrical Design\TEAAC\6P\Series\BS6800U.rat | G3: Date: | H3: 41992 | I3: Time: | J3: 0.37134259
A4: Pole | B4: HP | C4: RPM | D4: Form | E4: Voltage | F4: Frequency | G4: Temperature | H4: FLSpeed | I4: FLSlip | J4: Frame
A5: 6 | B5: 799.99998 | C5: 1200 | D5: FCCW4 | E5: 4000 | F5: 60 | G5: 105 | H5: 1191.6 / 1191.7 | I5: 0.0070 / 0.0069 | J5: 6810US
A6: Core Data | D6: Winding Data | H6: Constant Data
B7: Primary | C7: Secondary | F7: Bar | G7: End Ring | H7: St. Slot Pitch | I7: 24.652755 | J7: LR Test Data
A8: Air Gap | B8: 2.0999999 | H8: Rt. Slot Pitch | I8: 30.375925 | J8: ES
A9: Space Fac. | B9: 0.93000001 | D9: Pitch | E9: 1 ~ 11 | F9: Cross Section Area | H9: Mean Value | I9: 27.51434 | J9: 705.60135
A10: Core Length | B10: 654 | C10: 654 | F10: UB: 420.0 | G10: UER: 1500.0 | H10: Eff.T.W.St. | I10: 15.415946 | J10: WS
A11: OD | B11: 815 | C11: 560.8 | D11: Coil Pitch | E11: 0.83325 | H11: Eff.T.W.Rt. | I11: 29.536695 | J11: 24155.686
A12: ID | B12: 565 | C12: 300 | D12: Slot Fill | E12: - | F12: EBL: 50.5 | G12: ERD1: 460.8 | H12: St.Carter Fac. | I12: 1.2038174 | J12: IS
A13: Core Depth | B13: 63 | C13: 93.850001 | D13: Con./Slot | E13: 23 | G13: ERT: 30.00 | H13: Rt.Carter Fac. | I13: 1.0284132 | J13: 99.25592
A14: Eff.Core L. | B14: 491.04001 | C14: 491.04001 | D14: Wire Size 1 | E14: (.064"x.182")x2 | F14: (12 x 35) | G14: ERH: 50.00 | H14: Carter Factor | I14: 1.2380216 | J14: Volts / Turn
A15: Slot Data | D15: Wire Size 2 | E15: - | H15: Short. Factor | I15: 0.96589165 | J15: 16.735281
A16: Number | B16: 72 | C16: 58 | D16: // Circuits | E16: 2 | H16: Distrib. Factor | I16: 0.95749474 | J16: AC
A17: Kind | B17: Open | C17: Rectang | D17: Connection | E17: Wye | H17: Wind. Factor | I17: 0.92483618 | J17: 463.00833
A18: Skew | B18: - | C18: 0 | D18: MCL | E18: 1189 | F18: 785 | H18: Reactance | I18: (Coeff.: 0.0880)
A19: Depth | B19: 62 | C19: 36.549999 | D19: No.Cond./Ph. | E19: 276 | I19: Running | J19: Start
A20: Width | B20: 9.24 - 9.24 | C20: 12.05 | D20: Res. (20°C) | E20: 0.19833397 | H20: Stator Slot | I20: 19.990599 | J20: 19.990599
A21: Opening | B21: 13.2 | C21: 3.5 | D21: (105°C) | E21: 0.26457518 | F21: 0.14889331 | G21: 0.028750562 | H21: Rotor Slot | I21: 13.686986 | J21: 8.2394533
A22: Tip Depth | B22: 2.8299999 | C22: 1.5 | D22: Material | E22: CU | F22: CU | G22: CU | H22: Zigzag | I22: 6.9207907 | J22: 5.6412368
A23: T.Min.Wid. | B23: 11.452755 | C23: 14.371196 | D23: Spec.Resist. | E23: 1.742 | F23: 1.742 | G23: 1.742 | H23: Coil End | I23: 8.7004672 | J23: Skew R.: 0.00
A24: Low. R. | B24: 0 | C24: 0.80000001 | D24: Spec.Gravity | E24: 8.8900003 | F24: 8.8900003 | G24: 8.8900003 | H24: Belt Leakage | I24: 3.8615827 | J24: 3.3448887
A25: Up. R. | B25: - | C25: 0.80000001 | D25: Weight (kg) | H25: Total Resist. | I25: 0.44221905 | J25: 0.81730711
A26: Wedge Dep. | B26: 2.83 - 3.20 | C26: Magnetic | D26: Wire 1 | E26: 252.26439 | F26: 176.49673 | G26: 43.799241 | H26: Total React. | I26: 4.6768947 | J26: 4.0222545
A27: Duct | B27: 21 x 6 | C27: 21 x 6 | D27: Wire 2 | E27: - | F27: - | G27: - | H27: Impedance | I27: 4.6977549 | J27: 4.1044512
A28: Effective Depth (S=1) | D28: Magnetic Circuit Data | I28: Core Loss Data
B29: Res.= | C29: 35.001719 | E29: Length | F29: Section | G29: Density | H29: AT | I29: Volume | J29: Loss
B30: Reac.= | C30: 35.036186 | D30: Primary Core | E30: 21.336632 | F30: 618.71041 | G30: 10.97859 | H30: 104.61862 | I30: 73084.415 | J30: 3016.2971
A31: Excitation Data | D31: Tooth | E31: 6.2 | F31: 674.85131 | G31: 10.06528 | H31: 25.000947 | I31: 25104.469 | J31: 900.10442
A32: Excit.Amps | B32: 23.633 / 20.965 | D32: Second.Core | E32: 12.767945 | F32: 921.6821 | G32: 7.369751 | H32: 25.792899 | I32: Total | J32: 3916.4015
A33: Core Loss | B33: 1.147 / 1.017 | C33: Flux / Pole | D33: Tooth | E33: 3.6549999 | F33: 682.16044 | G33: 9.9574342 | H33: 14.472697 | I33: C.L.C. | J33: 1.75 / 0.66
A34: NoLoad | B34: 23.66 / 20.99 | C34: 6.7925676 | D34: Air Gap | E34: 0.20999999 | F34: 1261.6892 | G34: 5.3837091 | H34: 899.68683 | I34: S.F.C. | J34: 6.0500002
A35: Load Characteristics | D35: Temp. Rise @ 100%: | E35: 44 / 43 | G35: No Load Loss | H35: 18401.2 / 12973.6 | I35: W.Loss | J35: 6853.7 / 2597.1
A36: Load (%) | B36: 25 | C36: 50 | D36: 75 | E36: 100 | F36: 125 | G36: Primary Loss | H36: 7819.6 / 7082.0 | I36: S.Loss | J36: 1099.2 / 416.5
A37: Current (A) | B37: 35.50 / 36.12 | C37: 54.24 / 55.19 | D37: 75.97 / 77.30 | E37: 99.26 / 100.99 | F37: 123.85 / 126.02 | G37: Second. Loss | H37: 4380.9 / 4312.5 | I37: Total C.Loss | J37: 7952.9 / 3013.7
A38: Efficiency | B38: 0.885 / 0.882 | C38: 0.933 / 0.929 | D38: 0.947 / 0.943 | E38: 0.952 / 0.948 | F38: 0.953 / 0.949 | G38: Frict.& Wind. | H38: 10116.0 / 9343.1 | I38: Stray Loss | J38: 8806.7305
A39: P.F. | B39: 0.685 / 0.676 | C39: 0.851 / 0.840 | D39: 0.898 / 0.886 | E39: 0.911 / 0.899 | F39: 0.912 / 0.900 | G39: Starting Data | I39: Slip | J39: PF
A40: Slip | B40: 0.0018 / 0.0017 | C40: 0.0035 / 0.0034 | D40: 0.0052 / 0.0051 | E40: 0.0070 / 0.0069 | F40: 0.0088 / 0.0087 | G40: LRA | H40: 562.7 / 536.0
...

Sheet Data Sheet
A1: TOSHIBA INTERNATIONAL CORPORATION
A2: INDUCTION MOTOR DATA SHEET
A3: File: | B3: BS6800U | I3: HRW / Model Number: | J3: 8007TCQL11E-C
A4: Type: TIKE - Form: FCW4 - 6 Pole - 800 HP - 4000 V - 60 Hz - 6810US - Class F | Q4: Motor Type Selection | T4: Electrical Steel Table
A5: Motor Parameters | F5: PERFORMANCE | J5: DESIGN | K5: TEST | Q5: EPACT | T5: M22 - 26Ga.
A6: Material | D6: M36 - 26Ga. | F6: NL & Impedance Test | Q6: EQP-III | T6: M36 - 26Ga.
A7: Air Gap | D7: 2.0999999 | F7: No load amps | J7: 21 | K7: - | Q7: Exp.Prf. | T7: NCB1 - 26Ga.
A8: Stack length | D8: 654 | F8: No load watts | J8: 12616 | K8: - | Q8: Exp.Prf.-EQPIII | T8: M43 - 26Ga.
A9: Number of turns per coil | D9: 11, 12 | F9: Impedance amps | H9: 3 | I9: f | J9: 161 | K9: - | Q9: Prem. Eff. | T9: M45 - 26Ga.
A10: Wire 1 (size & number) | D10: (.064"x.182")x2 | F10: Impedance volts | H10: 3 | I10: f | J10: 1150 | K10: - | Q10: OWP | T10: M54 - 26Ga.
A11: Wire 2 (size & number) | D11: - | F11: Impedance watts | H11: 3 | I11: f | J11: 49632 | K11: - | Q11: Dry Kiln
A12: Slot fill - circle/square method (%) | D12: - | F12: Temperature Rise (°C)
A13: Connection | D13: 2 x Delta / 2 x Wye | G13: Winding | I13: 80/115 | J13: 43 / 58 | K13: -
A14: MCL | D14: 1189 | G14: Frame | J14: - | K14: -
A15: Allowance for ins. depth | D15: 17.1812 | G15: Bearing PS/OS | J15: - | K15: -
A16: Allowance for ins. width | D16: 3.5543997 | G16: End Ring | J16: - | K16: -
A17: Slot/Wire arrangement | D17: 23 x 2 | F17: Nameplate Data
A18: Effective cross section for coil | D18: - | H18: FLC (A) | J18: 176 / 101 | M18: =J18*6.5 -> #VALUE!
A19: Coil grouping | D19: - | H19: RPM | J19: 1190
A20: Coil pitch (slot number) | D20: 1 ~ 11 | H20: CODE | J20: E
A21: Method of coil connection | D21: - | H21: S. F. | J21: 1.15 | Q21: Method of Connection
A22: Resistance per phase @ 20 °C | D22: 0.1955 | H22: DESIGN | J22: - | Q22: Skip
A23: Coil Weight | B23: Wire1 | D23: 580 | H23: Nom.Eff. (%): | Q23: Adjacent
A24: (lbs.) | B24: Wire2 | D24: - | H24: Min.Eff. (%): | Q24: -
A25: Current Densities (A/cm2) | E25: Bar / ER | H25: P.F. (%): | J25: -
A26: FL / LR | D26: 350 / 1857 | E26: 290 / 251
A27: Stator Slot Shape (Reference) | F27: Performance
H28: LRC (A) | I28: - | J28: 924 / 536 | K28: - | M28: =(J28/J18)*100 -> #VALUE!
H29: LRT (%) | I29: 60 | J29: 75 | K29: -
H30: BDT (%) | I30: 175 | J30: 226 | K30: -
H31: SLIP (%) | J31: 0.69 | K31: -
G32: IEEE-B | H32: Eff. (%) | J32: 94.8 | K32: -
A33: Rotor Slot Shape (Reference) | H33: PF (%) | J33: 89.9 | K33: -
F34: Losses (Watts) | H34: Primary | J34: 7082 | K34: -
H35: Secondary | J35: 4313 | K35: -
H36: Core | J36: 3014 | K36: -
H37: F & W | J37: 9343 | K37: -
H38: Stray | J38: 8807 | K38: -
A39: End Ring (Reference) | F39: Note
F40: LINK: P149087. RAT & DAT
...

Sheet LoginSheet
J1: P | K1: T | L1: L | M1: T
B2: PROJECT HISTORY | J2: E | K2: D | L2: I | M2: Y | N2: H
J3: R | L3: M | M3: P
J4: F | L4: I | M4: E
K5: C | L5: T | N5: I
J6: D | K6: U | M6: T | N6: N
J7: A | K7: R | L7: R | M7: E | N7: S
I8: S | J8: T | K8: V | L8: E | M8: S | N8: U
B9: DATE | C9: PROJECT | D9: SMART NUMBER | E9: QTY | F9: CUSTOMER | G9: REMARKS | H9: LIMIT CODE | I9: F | J9: A | K9: E | L9: V | M9: T | N9: L
B53: REVISION HISTORY
B54: REV | C54: REMARKS | I54: DATE | L54: INIT

Sheet Form
A1: Winding Data Calculation
C2: MCL: 1189.0
A3: Coil Resistance | D3: Lead Resistance
A4: 11T: | B4: 0.0315 ~ 0.0303 | D4: AWG. 02 x 3
A5: 12T: | B5: 0.0344 ~ 0.0330 | D5: 0.00183
A6: Coil Dimensions
A7: HM: | B7: 11T: 20.08 | C7: WM: | D7: 11T: 9.65 | E7: WT:
B8: 12T: 21.91 | D8: 12T: 9.65 | E8: 13.30 ~ 12.90
A9: Insulation Allowance | D9: Wire Weight
A10: Depth: | B10: 17.18 | D10: (.064"x.182")x 2: | F10: 580 lbs.
A11: Width: | B11: 3.55
A12: QC Resistance
A13: 1-2, 2-3, 3-1: | C13: 0.403 ~ 0.379

Sheet Performance Data Sheet
A1: TOSHIBA INTERNATIONAL CORPORATION | J1: INDEX | L1: MPCF-1033
A2: Industrial Division / Houston Motor Plant | J2: SHEET NO. | L2: 1 of 1
J3: ISSUED | L3: 11/08/96
J4: SUPERSEDES | L4: 10/06/95
J5: REVISION | L5: 1
A6: SQUIRREL CAGE INDUCTION MOTOR | J6: WRITTEN BY | L6: R. EVANS
A7: PERFORMANCE SPECIFICATIONS | J7: APPROVED BY | L7: Jay Bugbee
B9: CUSTOMER:
B10: TIC SR No.:
A12: MOTOR NAMEPLATE DATA
B13: H.P.: | C13: 800 | E13: VOLTS: | F13: 4000 | H13: 3 PH / | I13: 60 Hz | L13: S. RPM: | M13: 1200
B14: FRAME: | C14: 6810US | E14: ENCL: | F14: TEAAC | H14: FLAMPS: | I14: 101 | L14: FLRPM: | M14: 1192
B15: FORM: | C15: FCW4 | E15: S.F.: | F15: 1.15 | H15: NEMA DESIGN: | I15: - | L15: INSUL CLASS: | M15: F
B16: TYPE: | C16: TIKE | E16: AMB.: | F16: 40°C | H16: CODE: | I16: E | L16: DUTY: | M16: Cont.
B17: MODEL No.: | C17: 8007TCQL11E-C | H17: kW:
B18: NOM. EFF.: | C18: - | E18: MIN. EFF.: | F18: - | H18: P.F.: | I18: -
A21: AMPERAGE | E21: TORQUES | I21: **BEARINGS:
C22: LOCKED ROTOR: | D22: 536 | G22: FULL LOAD (lb-ft.): | H22: 3525 | K22: DRIVE END: | L22: M11-125 INS
G23: LOCKED ROTOR (%): | H23: 75 | K23: OPPOSITE DRIVE END: | L23: M11-125 INS
G24: BREAK DOWN (%): | H24: 225
A28: EFFICIENCY | H28: POWER FACTOR
C29: FULL LOAD: | D29: 94.8 | J29: FULL LOAD: | K29: 89.9
C30: 3/4 LOAD: | D30: 94.3 | J30: 3/4 LOAD: | K30: 88.6
C31: 1/2 LOAD: | D31: 92.9 | J31: 1/2 LOAD: | K31: 84
A35: ALL CHARACTERISTICS ARE AVERAGE EXPECTED VALUES BASED UPON RATED VOLTAGE,
A36: FREQUENCY AND SINEWAVE POWER INPUT.
A37: THE DECLARED LOCKED ROTOR CURRENT HAS A TOLERANCE OF 20%.
A38: * TEMPERATURE RISE WILL BE CONSISTENT WITH INSULATION, AMBIENT AND SERVICE FACTOR AS
A39: DEFINED BY NEMA-MG-12 OR -20.
A40: ** BEARINGS ARE THE ONLY RECOMMENDED SPARE PART(S).
J43: CERTIFIED BY: | K43: Mario L
J45: DATE: | K45: 41992
A60: - | B60: M11-125 INS | D60: 1 | E60: -
A61: TEFC | B61: 6206UU | D61: 1.15 | E61: A
A62: ODP | B62: 6207ZZ | E62: B
B63: 6208UU
B64: 6211ZZ
B65: 6211C3
B66: 6211ZZC3
B67: 6305UUC3
...

Sheet STCurve
A2: TOSHIBA INTERNATIONAL CORPORATION
A3: Speed Torque/Current Curve
A6: Model #: | B6: ='Performance Data Sheet'!C17 -> 8007TCQL11E-C | E6: FLAmps: | F6: ='Performance Data Sheet'!I14 & " A" -> 101 A
A7: Enclosure: | B7: ='Performance Data Sheet'!F14 -> TEAAC | C7: Voltage: | D7: ='Performance Data Sheet'!F13 & " V" -> 4000 V | E7: Frame: | F7: ='Performance Data Sheet'!C14 -> 6810US
A8: Pole: | B8: 6 | C8: Frequency: | D8: 3 PH / 60 Hz | E8: Ins. Class: | F8: ='Performance Data Sheet'!M15 -> F
A9: HP: | B9: 800 | C9: Rotor Inertia: | D9: 1115.3 lb-ft² | E9: Date: | F9: ='Performance Data Sheet'!K45 -> 41992
A10: FLRPM: | B10: 1192 | C10: Load Inertia: | D10: N/A | E10: File: | F10: BS6800U
B12: Locked Rotor Amps: | C12: ='Performance Data Sheet'!D22 & " A" -> 536 A | D12: Load Type: | E12: N/A
B13: Locked Rotor Torque: | C13: 0.75 | D13: Starting at: | E13: N/A
B14: Breakdown Torque: | C14: 2.25 | D14: Accel. Time: | E14: N/A
B15: Rated Torque: | C15: 3525 lb-ft
A39: Comments: | B39: PROJECT | C39: ='Performance Data Sheet'!C10 -> 0 | E39: D.E.Curve #: | F39: =F10 -> BS6800U
C43: Prepared by: | D43: ='Performance Data Sheet'!K43 -> Mario L | E43: Checked by:
A54: 100 | B54: 0 | C54: 0.23426344
A55: 99.8 | B55: 104.79072 | C55: 111.31685
A56: 99 | B56: 225 | C56: 351.87314
A57: 93.789474 | B57: 132.83447 | C57: 426.37747
A58: 88.578947 | B58: 105.12559 | C58: 450.25037
A59: 83.368421 | B59: 92.293974 | C59: 462.9967
A60: 72.947368 | B60: 84.176582 | C60: 479.96704
A61: 62.526315 | B61: 80.353139 | C61: 492.7876
A62: 52.105263 | B62: 78.135971 | C62: 503.16144
A63: 41.68421 | B63: 76.767941 | C63: 511.27805
A64: 31.263161 | B64: 75.936081 | C64: 517.80957
A65: 20.842105 | B65: 75.438486 | C65: 522.91144
... A67: 0 | B67: 75 | C67: 530.69305

Sheet Thermdam
A2: TOSHIBA INTERNATIONAL CORPORATION
A3: Thermal Limit & Acceleration Curves
A4: Design Values (For Reference Only)
A6: Model #: | B6: ='Performance Data Sheet'!C17 -> 8007TCQL11E-C | E6: FLAmps: | F6: ='Performance Data Sheet'!I14 & " A" -> 101 A
A7: Enclosure: | B7: ='Performance Data Sheet'!F14 -> TEAAC | C7: Voltage: | D7: ='Performance Data Sheet'!F13 & " V" -> 4000 V | E7: Frame: | F7: ='Performance Data Sheet'!C14 -> 6810US
A8: Pole: | B8: 6 | C8: Frequency: | D8: 3 PH / 60 Hz | E8: Ins. Class: | F8: ='Performance Data Sheet'!M15 -> F
A9: HP: | B9: 800 | C9: Rotor Inertia: | D9: 1115.3 lb-ft² | E9: Date: | F9: ='Performance Data Sheet'!K45 -> 41992
A10: FLRPM: | B10: 1192 | C10: Load Inertia: | D10: N/A | E10: File: | F10: BS6800U
A39: Comments: | B39: PROJECT | C39: ='Performance Data Sheet'!C10 -> 0 | E39: D.E.Curve #: | F39: =F10 -> BS6800U
C43: Prepared by: | D43: ='Performance Data Sheet'!K42 -> 0 | E43: Checked by: | F43: AG
F50: =5252.1*B50/D53 -> #DIV/0!
D66: =D65/D64 -> #DIV/0!
A67: Current (%) | B67: Cold | C67: Hot | E67: CURRENT (%) | F67: Accel. Time
A68: 530.69307 | B68: 35 | C68: 15 | E68: =A68 -> 530.69307 | F68: 0.0001
A69: 468.46827 | B69: =((A68/A69)^2)*B68 -> 44.915322 | C69: =((A68/A69)^2)*C68 -> 19.249424 | E69: 528.91089 | F69: 1.9400001
A70: 406.2248 | B70: =((A68/A70)^2)*B68 -> 59.734057 | C70: =((A68/A70)^2)*C68 -> 25.60031 | E70: 525.0495 | F70: 3.5380001
A71: 344 | B71: =((A68/A71)^2)*B68 -> 83.298655 | C71: =((A68/A71)^2)*C68 -> 35.699424 | E71: 520.39604 | F71: 5.0279999
A72: =A71-100 -> 244 | B72: =((A68/A72)^2)*B68 -> 165.56755 | E72: 514.55446 | F72: 6.5159998
A73: =A72-100 -> 144 | B73: =((A68/A73)^2)*B68 -> 475.36794 | E73: 507.22772 | F73: 8.0869999
A74: 225 | B74: =((A68/A74)^2)*B68 -> 194.71071 | C74: =((A68/A74)^2)*C68 -> 83.447447 | E74: 498.0198 | F74: 9.8199997
A75: 180 | B75: =((A68/A75)^2)*B69 -> 390.42385 | C75: =((A68/A75)^2)*C68 -> 130.38664 | E75: 486.33663 | F75: 11.829
A76: 145 | B76: =((A68/A76)^2)*B68 -> 468.83375 | C76: =((A68/A76)^2)*C68 -> 200.92875 | E76: 471.48515 | F76: 14.353
A77: 125 | C77: =CEILING(C76*2,100) -> 500 | E77: 456.63366 | F77: 15.818
A78: 125 | C78: =2*C77 -> 1000 | E78: 438.31683 | F78: 17.038
A79: 125 | C79: 10000 | E79: 389.10891 | F79: 17.618999
E80: 231.58416 | F80: 17.737999
E81: 0 | F81: 18.492998

Sheet Performance 4000V
A2: TOSHIBA INTERNATIONAL CORPORATION
A3: Performance Curve
A4: Design Values (For Reference Only)
A6: Model #: | B6: ='Performance Data Sheet'!C17 -> 8007TCQL11E-C | E6: FLAmps: | F6: 101 A
A7: Enclosure: | B7: ='Performance Data Sheet'!F14 -> TEAAC | C7: Voltage: | D7: 4000 V | E7: Frame: | F7: ='Performance Data Sheet'!C14 -> 6810US
A8: Pole: | B8: 6 | C8: Frequency: | D8: 3 PH / 60 Hz | E8: Ins. Class: | F8: ='Performance Data Sheet'!M15 -> F
A9: HP: | B9: 800 | C9: Rotor Inertia: | D9: 1115.3 lb-ft² | E9: Date: | F9: ='Performance Data Sheet'!K45 -> 41992
A10: FLRPM: | B10: 1192 | C10: Load Inertia: | D10: N/A | E10: File: | F10: BS6800U
B12: Locked Rotor Amps: | C12: 536 A | D12: Load Type: | E12: N/A
B13: Locked Rotor Torque: | C13: 0.75 | D13: Starting at: | E13: N/A
B14: Breakdown Torque: | C14: 2.25 | D14: Accel. Time: | E14: N/A
B15: Rated Torque: | C15: 3525 lb-ft
A39: Comments: | B39: PROJECT | C39: ='Performance Data Sheet'!C10 -> 0 | E39: D.E.Curve #: | F39: =F10 -> BS6800U
C43: Prepared by: | D43: ='Performance Data Sheet'!K42 -> 0 | E43: Checked by: | F43: AG
A53: Load | B53: Efficiency | C53: PF | D53: Amps | E53: RPM | F53: Input Watts
A54: 0 | D54: 24.072988 | E54: 100 | F54: 0.7885
A55: 25 | B55: 88.166595 | C55: 67.614967 | D55: 36.116104 | E55: 89.753736 | F55: 10.573813
A56: 50 | B56: 92.921783 | C56: 83.969681 | D56: 55.18713 | E56: 79.660183 | F56: 20.065419
A57: 75 | B57: 94.339417 | C57: 88.574242 | D57: 77.29805 | E57: 69.314258 | F57: 29.645847
A58: 100 | B58: 94.834358 | C58: 89.925255 | D58: 100.98585 | E58: 58.655933 | F58: 39.321502
A59: 125 | B59: 94.941147 | C59: 89.98172 | D59: 126.0112 | E59: 47.947318 | F59: 49.096592

Sheet Performance 2300V
A2: TOSHIBA INTERNATIONAL CORPORATION
A3: Performance Curve
A4: Design Values (For Reference Only)
A6: Model #: | B6: ='Performance Data Sheet'!C17 -> 8007TCQL11E-C | E6: FLAmps: | F6: 176 A
A7: Enclosure: | B7: ='Performance Data Sheet'!F14 -> TEAAC | C7: Voltage: | D7: 2300 V | E7: Frame: | F7: ='Performance Data Sheet'!C14 -> 6810US
A8: Pole: | B8: 6 | C8: Frequency: | D8: 3 PH / 60 Hz | E8: Ins. Class: | F8: ='Performance Data Sheet'!M15 -> F
A9: HP: | B9: 800 | C9: Rotor Inertia: | D9: 1115.3 lb-ft² | E9: Date: | F9: ='Performance Data Sheet'!K45 -> 41992
A10: FLRPM: | B10: 1192 | C10: Load Inertia: | D10: N/A | E10: File: | F10: BS6800U
B12: Locked Rotor Amps: | C12: 924 A | D12: Load Type: | E12: N/A
B13: Locked Rotor Torque: | C13: 0.75 | D13: Starting at: | E13: N/A
B14: Breakdown Torque: | C14: 2.25 | D14: Accel. Time: | E14: N/A
B15: Rated Torque: | C15: 3525 lb-ft
A39: Comments: | E39: D.E.Curve #: | F39: BS6800U
C43: Prepared by: | D43: ='Performance Data Sheet'!K43 -> Mario L | E43: Checked by: | F43: AG
A53: Load | B53: Efficiency | C53: PF | D53: Amps | E53: RPM | F53: Input Watts
A54: 0 | D54: 41.695638 | E54: 100 | F54: 0.7885
A55: 25 | B55: 88.166595 | C55: 67.614967 | D55: 62.554927 | E55: 89.753736 | F55: 10.573813
A56: 50 | B56: 92.921783 | C56: 83.969681 | D56: 95.586913 | E56: 79.660183 | F56: 20.065419
A57: 75 | B57: 94.339417 | C57: 88.574242 | D57: 133.88415 | E57: 69.314258 | F57: 29.645847
A58: 100 | B58: 94.834358 | C58: 89.925255 | D58: 176 | E58: 58.655933 | F58: 39.321502
A59: 125 | B59: 94.941147 | C59: 89.98172 | D59: 218.2578 | E59: 47.947318 | F59: 49.096592

Sheet MagNoise
A1: Magnetic Noise Verification
A3: Rating: | B3: 6 Pole - 800.0 HP - 1200 RPM - 4000 V - 60 Hz
A5: Electromagnetic Excitation Frequencies
B7: L = | C7: 0 | D7: L = | E7: + 1 | F7: L = | G7: - 1 | H7: Slip = | I7: 0 | J7: Slip = | K7: 0.007
A8: Mode A | B8: 8 | D8: 26 | F8: 10 | H8: 1280.0 Hz | J8: 1271.9 Hz
A9: Mode B | B9: 20 | D9: 38 | F9: 2 | H9: 1040.0 Hz | J9: 1031.9 Hz
A10: Mode C | B10: 14 | D10: 32 | F10: 4 | H10: 1160.0 Hz | J10: 1151.9 Hz
A12: Natural Frequencies of Stator Core
B14: Mode 0 = | D14: 1849.2 Hz | F14: Mode 6 = | H14: 3065.4 Hz
B15: Mode 2 = | D15: 238.2 Hz | F15: Mode 7 = | H15: 4219.1 Hz
B16: Mode 3 = | D16: 673.9 Hz | F16: Mode 8 = | H16: 5550.6 Hz
B17: Mode 4 = | D17: 1292.1 Hz | F17: Mode 9 = | H17: 7059.8 Hz
B18: Mode 5 = | D18: 2089.6 Hz | F18: Mode 10 = | H18: 8746.6 Hz
A20: Analysis Results
B22: Matching frequencies detected!!!
B23: Please check slot combination!!!

Sheet StallTime
A1: Rating: | B1: 6 Pole - 800.0 HP - 1200 RPM - 4000 V - 60 Hz
A3: Starting Performance
D4: Load Type: Fan / Pump - 7757.0 lb-ft²
A5: RPM | B5: Motor | C5: Load | D5: Accel. | E5: Line | F5: Stator | G5: Rotor
A6: Speed Increment | B6: Torque (%) | C6: Torque (%) | D6: Time (s) | E6: Amps | F6: kW / s | G6: kW / s
A7: 0~125 | B7: 75.1 | C7: 22.4 | D7: 1.940 | E7: 534.2 | F7: 442.4 | G7: 800.4
A8: 125~250 | B8: 75.3 | C8: 11.3 | D8: 1.598 | E8: 530.3 | F8: 359.4 | G8: 591.6
A9: 250~375 | B9: 75.7 | C9: 7.0 | D9: 1.490 | E9: 525.6 | F9: 330.0 | G9: 489.6
A10: 375~500 | B10: 76.4 | C10: 7.6 | D10: 1.488 | E10: 519.7 | F10: 323.1 | G10: 427.3
A11: 500~625 | B11: 77.5 | C11: 12.3 | D11: 1.571 | E11: 512.3 | F11: 332.4 | G11: 386.8
A12: 625~750 | B12: 79.2 | C12: 20.2 | D12: 1.733 | E12: 503.0 | F12: 355.2 | G12: 356.8
A13: 750~875 | B13: 82.3 | C13: 31.4 | D13: 2.009 | E13: 491.2 | F13: 394.9 | G13: 332.7
A14: 875~1000 | B14: 88.2 | C14: 47.7 | D14: 2.524 | E14: 476.2 | F14: 470.9 | G14: 316.2
A15: 1000~1063 | B15: 98.7 | C15: 63.9 | D15: 1.465 | E15: 461.2 | F15: 254.2 | G15: 247.4
A16: 1063~1125 | B16: 119.0 | C16: 77.1 | D16: 1.220 | E16: 442.7 | F16: 200.3 | G16: 161.2
... A19: 1198~1200 | B19: 102.4 | C19: 99.8 | D19: 0.755 | E19: 68.2 | F19: 6.1 | G19: 158.1
D21: Acceleration Time: 18.5 s
B22: Energy | D22: First Start | F22: Second Start
A23: Stator Winding Rise | B23: 3566 kW / s | D23: 37°C | F23: 73°C
A24: Rotor Bar Rise | B24: 3638 kW / s | D24: 54°C | F24: 107°C
A25: End Ring Rise | B25: 702 kW / s | D25: 42°C | F25: 83°C
A27: Locked Rotor Thermal Capability
E28: Cold Condition
B29: Rate of Rise | D29: Power | E29: Rise Limit | F29: Max Time
A30: Stator Copper | B30: 2.5°C / s | D30: 243.9 kW | E30: 160°C | F30: 63.7 s
A31: Rotor Bar | B31: 5.5°C / s | D31: 375.2 kW | E31: 260°C | F31: 47.1 s
A32: Rotor ER | B32: 4.3°C / s | D32: 72.4 kW | E32: 180°C | F32: 41.9 s
E34: Hot Condition
B35: Hot Temp. | D35: Rise Limit | E35: Ambient | F35: Total | G35: Max.Time
A36: Stator Copper | B36: 43°C + | D36: 117°C + | E36: 40°C | F36: = 200°C | G36: 46.6 s
A37: Rotor Bar | B37: 54°C + | D37: 206°C + | E37: 40°C | F37: = 300°C | G37: 37.4 s
A38: Rotor ER | B38: 54°C + | D38: 126°C + | E38: 40°C | F38: = 220°C | G38: 29.4 s
A40: Cold Stall Time: | B40: 85.4 s | D40: Hot Stall Time: | F40: 60.0 s
