Workbook
Name Print_Area_MI: 'Performance Data Sheet'!$A$10:$N$43

Sheet DesignSheet
A1: TOSHIBA INTERNATIONAL CORPORATION | I1: Calc. Code: | J1: 2-2-2-0-1-2
A2: 3-PHASE SQUIRREL CAGE INDUCTION MOTOR DESIGN SHEET | J2: B.L.-1 P.F.-1
A3: File: | B3: Z:\Motor R&D\Active Projects\6810 Development\Electrical Design\TEAAC\6P\Series\BS6M25U.rat | G3: Date: | H3: 41992 | I3: Time: | J3: 0.57586806
A4: Pole | B4: HP | C4: RPM | D4: Form | E4: Voltage | F4: Frequency | G4: Temperature | H4: FLSpeed | I4: FLSlip | J4: Frame
A5: 6 | B5: 1250 | C5: 1200 | D5: FCCW4 | E5: 4000 | F5: 60 | G5: 105 | H5: 1191.8 / 1191.9 | I5: 0.0069 / 0.0068 | J5: 6810US
A6: Core Data | D6: Winding Data | H6: Constant Data
B7: Primary | C7: Secondary | F7: Bar | G7: End Ring | H7: St. Slot Pitch | I7: 24.652755 | J7: LR Test Data
A8: Air Gap | B8: 2.0999999 | H8: Rt. Slot Pitch | I8: 30.375925 | J8: ES
A9: Space Fac. | B9: 0.93000001 | D9: Pitch | E9: 1 ~ 11 | F9: Cross Section Area | H9: Mean Value | I9: 27.51434 | J9: 693.39807
A10: Core Length | B10: 804 | C10: 804 | F10: UB: 420.0 | G10: UER: 1500.0 | H10: Eff.T.W.St. | I10: 15.415946 | J10: WS
A11: OD | B11: 815 | C11: 560.8 | D11: Coil Pitch | E11: 0.83325 | H11: Eff.T.W.Rt. | I11: 29.536695 | J11: 36192.888
A12: ID | B12: 565 | C12: 300 | D12: Slot Fill | E12: - | F12: EBL: 50.5 | G12: ERD1: 460.8 | H12: St.Carter Fac. | I12: 1.2038174 | J12: IS
A13: Core Depth | B13: 63 | C13: 93.850001 | D13: Con./Slot | E13: 17 | G13: ERT: 30.00 | H13: Rt.Carter Fac. | I13: 1.0284132 | J13: 153.86337
A14: Eff.Core L. | B14: 602.64001 | C14: 602.64001 | D14: Wire Size 1 | E14: (.091"x.182")x2 | F14: (12 x 35) | G14: ERH: 50.00 | H14: Carter Factor | I14: 1.2380216 | J14: Volts / Turn
A15: Slot Data | D15: Wire Size 2 | E15: - | H15: Short. Factor | I15: 0.96589165 | J15: 22.64185
A16: Number | B16: 72 | C16: 58 | D16: // Circuits | E16: 2 | H16: Distrib. Factor | I16: 0.95749474 | J16: AC
A17: Kind | B17: Open | C17: Rectang | D17: Connection | E17: Wye | H17: Wind. Factor | I17: 0.92483618 | J17: 530.50407
A18: Skew | B18: - | C18: 0 | D18: MCL | E18: 1339 | F18: 935 | H18: Reactance | I18: (Coeff.: 0.0590)
A19: Depth | B19: 62 | C19: 36.549999 | D19: No.Cond./Ph. | E19: 204 | I19: Running | J19: Start
A20: Width | B20: 9.24 - 9.24 | C20: 12.05 | D20: Res. (20°C) | E20: 0.11464741 | H20: Stator Slot | I20: 19.990599 | J20: 19.990599
A21: Opening | B21: 13.2 | C21: 3.5 | D21: (105°C) | E21: 0.1529383 | F21: 0.096885614 | G21: 0.015706829 | H21: Rotor Slot | I21: 13.686986 | J21: 8.2394533
A22: Tip Depth | B22: 2.8299999 | C22: 1.5 | D22: Material | E22: CU | F22: CU | G22: CU | H22: Zigzag | I22: 6.9207907 | J22: 5.094717
A23: T.Min.Wid. | B23: 11.452755 | C23: 14.371196 | D23: Spec.Resist. | E23: 1.742 | F23: 1.742 | G23: 1.742 | H23: Coil End | I23: 7.0892695 | J23: Skew R.: 0.00
A24: Low. R. | B24: 0 | C24: 0.80000001 | D24: Spec.Gravity | E24: 8.8900003 | F24: 8.8900003 | G24: 8.8900003 | H24: Belt Leakage | I24: 3.8615827 | J24: 3.031186
A25: Up. R. | B25: - | C25: 0.80000001 | D25: Weight (kg) | H25: Total Resist. | I25: 0.26553074 | J25: 0.50960243
A26: Wedge Dep. | B26: 2.83 - 3.20 | C26: Magnetic | D26: Wire 1 | E26: 302.36283 | F26: 208.98079 | G26: 43.799241 | H26: Total React. | I26: 3.0407066 | J26: 2.5515616
A27: Duct | B27: 26 x 6 | C27: 26 x 6 | D27: Wire 2 | E27: - | F27: - | G27: - | H27: Impedance | I27: 3.0522785 | J27: 2.6019533
A28: Effective Depth (S=1) | D28: Magnetic Circuit Data | I28: Core Loss Data
B29: Res.= | C29: 35.001719 | E29: Length | F29: Section | G29: Density | H29: AT | I29: Volume | J29: Loss
B30: Reac.= | C30: 35.036186 | D30: Primary Core | E30: 21.336632 | F30: 759.32642 | G30: 12.102759 | H30: 150.31167 | I30: 89694.51 | J30: 4335.1336
A31: Excitation Data | D31: Tooth | E31: 6.2 | F31: 828.22661 | G31: 11.09593 | H31: 31.443917 | I31: 30810.03 | J31: 1293.6633
A32: Excit.Amps | B32: 36.565 / 32.438 | D32: Second.Core | E32: 12.767945 | F32: 1131.1553 | G32: 8.1243878 | H32: 31.6902 | I32: Total | J32: 5628.7969
A33: Core Loss | B33: 1.664 / 1.476 | C33: Flux / Pole | D33: Tooth | E33: 3.6549999 | F33: 837.19691 | G33: 10.977041 | H33: 17.913531 | I33: C.L.C. | J33: 1.75 / 0.66
A34: NoLoad | B34: 36.60 / 32.47 | C34: 9.1899445 | D34: Air Gap | E34: 0.20999999 | F34: 1548.4368 | G34: 5.9349821 | H34: 991.81162 | I34: S.F.C. | J34: 6.0500002
A35: Load Characteristics | D35: Temp. Rise @ 100%: | E35: 57 / 57 | G35: No Load Loss | H35: 22114.3 / 15591.5 | I35: W.Loss | J35: 9850.4 / 3732.7
A36: Load (%) | B36: 25 | C36: 50 | D36: 75 | E36: 100 | F36: 125 | G36: Primary Loss | H36: 10862.0 / 9837.4 | I36: S.Loss | J36: 1688.1 / 639.7
A37: Current (A) | B37: 54.41 / 55.41 | C37: 83.61 / 85.15 | D37: 117.56 / 119.72 | E37: 153.86 / 156.69 | F37: 192.24 / 195.78 | G37: Second. Loss | H37: 6698.1 / 6593.6 | I37: Total C.Loss | J37: 11538.5 / 4372.4
A38: Efficiency | B38: 0.909 / 0.904 | C38: 0.947 / 0.942 | D38: 0.957 / 0.952 | E38: 0.960 / 0.955 | F38: 0.960 / 0.955 | G38: Frict.& Wind. | H38: 10116.0 / 9343.1 | I38: Stray Loss | J38: 13464.982
A39: P.F. | B39: 0.680 / 0.672 | C39: 0.850 / 0.839 | D39: 0.897 / 0.886 | E39: 0.911 / 0.899 | F39: 0.911 / 0.899 | G39: Starting Data | I39: Slip | J39: PF
A40: Slip | B40: 0.0017 / 0.0016 | C40: 0.0034 / 0.0033 | D40: 0.0051 / 0.0050 | E40: 0.0069 / 0.0068 | F40: 0.0086 / 0.0085 | G40: LRA | H40: 887.6 / 845.4
...

Sheet Data Sheet
A1: TOSHIBA INTERNATIONAL CORPORATION
A2: INDUCTION MOTOR DATA SHEET
A3: File: | B3: BW6M25U | I3: HRW / Model Number: | J3: M257TCAL11E-C
A4: Type: TIKE - Form: FCW4 - 6 Pole - 1250 HP - 4000 V - 60 Hz - 6810US - Class F | Q4: Motor Type Selection | T4: Electrical Steel Table
A5: Motor Parameters | F5: PERFORMANCE | J5: DESIGN | K5: TEST | Q5: EPACT | T5: M22 - 26Ga.
A6: Material | D6: M36 - 26Ga. | F6: NL & Impedance Test | Q6: EQP-III | T6: M36 - 26Ga.
A7: Air Gap | D7: 2.0999999 | F7: No load amps | J7: 33 | K7: - | Q7: Exp.Prf. | T7: NCB1 - 26Ga.
A8: Stack length | D8: 804 | F8: No load watts | J8: 14099 | K8: - | Q8: Exp.Prf.-EQPIII | T8: M43 - 26Ga.
A9: Number of turns per coil | D9: 8, 9 | F9: Impedance amps | H9: 3 | I9: f | J9: 239 | K9: - | Q9: Prem. Eff. | T9: M45 - 26Ga.
A10: Wire 1 (size & number) | D10: (.091"x.182")x2 | F10: Impedance volts | H10: 3 | I10: f | J10: 1150 | K10: - | Q10: OWP | T10: M54 - 26Ga.
A11: Wire 2 (size & number) | D11: - | F11: Impedance watts | H11: 3 | I11: f | J11: 73899 | K11: - | Q11: Dry Kiln
A12: Slot fill - circle/square method (%) | D12: - | F12: Temperature Rise (°C)
A13: Connection | D13: 2 x Wye | G13: Winding | I13: 80/115 | J13: 57 / 75 | K13: -
A14: MCL | D14: 1339 | G14: Frame | J14: - | K14: -
A15: Allowance for ins. depth | D15: 16.4762 | G15: Bearing PS/OS | J15: - | K15: -
A16: Allowance for ins. width | D16: 3.5543997 | G16: End Ring | J16: - | K16: -
A17: Slot/Wire arrangement | D17: 17 x 2 | F17: Nameplate Data
A18: Effective cross section for coil | D18: - | H18: FLC (A) | J18: 157 | M18: =J18*6.5 -> 1020.5
A19: Coil grouping | D19: - | H19: RPM | J19: 1192
A20: Coil pitch (slot number) | D20: 1 ~ 11 | H20: CODE | J20: E
A21: Method of coil connection | D21: - | H21: S. F. | J21: 1.15 | Q21: Method of Connection
A22: Resistance per phase @ 20 °C | D22: 0.1175 | H22: DESIGN | J22: - | Q22: Skip
A23: Coil Weight | B23: Wire1 | D23: 686 | H23: Nom.Eff. (%): | Q23: Adjacent
A24: (lbs.) | B24: Wire2 | D24: - | H24: Min.Eff. (%): | Q24: -
A25: Current Densities (A/cm2) | E25: Bar / ER | H25: P.F. (%): | J25: -
A26: FL / LR | D26: 378 / 2034 | E26: 333 / 288
A27: Stator Slot Shape (Reference) | F27: Performance
H28: LRC (A) | I28: - | J28: 845 | K28: - | M28: =(J28/J18)*100 -> 538.21656
H29: LRT (%) | I29: 60 | J29: 77 | K29: -
H30: BDT (%) | I30: 175 | J30: 223 | K30: -
H31: SLIP (%) | J31: 0.68 | K31: -
G32: IEEE-B | H32: Eff. (%) | J32: 95.5 | K32: -
A33: Rotor Slot Shape (Reference) | H33: PF (%) | J33: 89.9 | K33: -
F34: Losses (Watts) | H34: Primary | J34: 9837 | K34: -
H35: Secondary | J35: 6594 | K35: -
H36: Core | J36: 4372 | K36: -
H37: F & W( Ball Brg) | J37: 8700 | K37: -
H38: Stray | J38: 13465 | K38: -
A39: End Ring (Reference) | F39: Note
G43: Outer Fan: 550OD
...

Sheet LoginSheet
J1: P | K1: T | L1: L | M1: T
B2: PROJECT HISTORY | J2: E | K2: D | L2: I | M2: Y | N2: H
J3: R | L3: M | M3: P
J4: F | L4: I | M4: E
K5: C | L5: T | N5: I
J6: D | K6: U | M6: T | N6: N
J7: A | K7: R | L7: R | M7: E | N7: S
I8: S | J8: T | K8: V | L8: E | M8: S | N8: U
B9: DATE | C9: PROJECT | D9: SMART NUMBER | E9: QTY | F9: CUSTOMER | G9: REMARKS | H9: LIMIT CODE | I9: F | J9: A | K9: E | L9: V | M9: T | N9: L
B53: REVISION HISTORY
B54: REV | C54: REMARKS | I54: DATE | L54: INIT

Sheet Form
A1: Winding Data Calculation
C2: MCL: 1339.0
A3: Coil Resistance | D3: Lead Resistance
A4: 8T: | B4: 0.0186 ~ 0.0179 | D4: AWG. 1/0 x 3
A5: 9T: | B5: 0.0209 ~ 0.0201 | D5: 0.00115
A6: Coil Dimensions
A7: HM: | B7: 8T: 20.09 | C7: WM: | D7: 8T: 9.65 | E7: WT:
B8: 9T: 22.60 | D8: 9T: 9.65 | E8: 13.30 ~ 12.90
A9: Insulation Allowance | D9: Wire Weight
A10: Depth: | B10: 16.48 | D10: (.091"x.182")x 2: | F10: 686 lbs.
A11: Width: | B11: 3.55
A12: QC Resistance
A13: 1-2, 2-3, 3-1: | C13: 0.242 ~ 0.228

Sheet STCurve
A2: TOSHIBA INTERNATIONAL CORPORATION
A3: Speed Torque/Current Curve
A6: Model #: | B6: ='Performance Data Sheet'!C17 -> M257TCAL11E-C | E6: FLAmps: | F6: 157
A7: Enclosure: | B7: ='Performance Data Sheet'!F14 -> TEAAC | C7: Voltage: | D7: 4000 V | E7: Frame: | F7: ='Performance Data Sheet'!C14 -> 6810US
A8: Pole: | B8: 6 | C8: Frequency: | D8: 3 PH / 60 Hz | E8: Ins. Class: | F8: ='Performance Data Sheet'!M15 -> F
A9: HP: | B9: 1250 | C9: Rotor Inertia: | D9: 1368.8 lb-ft² | E9: Date: | F9: ='Performance Data Sheet'!K45 -> 41992
A10: FLRPM: | B10: 1192 | C10: Load Inertia: | D10: N/A | E10: File: | F10: BW6M25U
B12: Locked Rotor Amps: | C12: 845 A | D12: Load Type: | E12: N/A
B13: Locked Rotor Torque: | C13: 0.75 | D13: Starting at: | E13: N/A
B14: Breakdown Torque: | C14: 2.2 | D14: Accel. Time: | E14: N/A
B15: Rated Torque: | C15: 5508 lb-ft
A39: Comments: | E39: D.E.Curve #: | F39: BW6M25U
C43: Prepared by: | D43: ='Performance Data Sheet'!K43 -> Mario L | E43: Checked by: | F43: AG
A54: 100 | B54: 0 | C54: 0.23314211
A55: 99.8 | B55: 103.25578 | C55: 113.30344
A56: 99 | B56: 220 | C56: 357.04791
A57: 93.789474 | B57: 130.24754 | C57: 431.34027
A58: 88.578947 | B58: 103.58031 | C58: 455.08939
A59: 83.368421 | B59: 91.359498 | C59: 467.90286
A60: 72.947368 | B60: 83.694734 | C60: 485.24722
A61: 62.526315 | B61: 80.094597 | C61: 498.49313
A62: 52.105263 | B62: 77.991461 | C62: 509.16916
A63: 41.68421 | B63: 76.698181 | C63: 517.84528
A64: 31.263161 | B64: 75.901585 | C64: 524.68475
A65: 20.842105 | B65: 75.423086 | C65: 530.03888
... A67: 0 | B67: 75 | C67: 538.21655

Sheet StallTime
A1: Rating: | B1: 6 Pole - 1250.0 HP - 1200 RPM - 4000 V - 60 Hz
A3: Starting Performance
D4: Load Type: Fan / Pump - 11379.0 lb-ft²
A5: RPM | B5: Motor | C5: Load | D5: Accel. | E5: Line | F5: Stator | G5: Rotor
A6: Speed Increment | B6: Torque (%) | C6: Torque (%) | D6: Time (s) | E6: Amps | F6: kW / s | G6: kW / s
A7: 0~125 | B7: 75.1 | C7: 22.4 | D7: 1.784 | E7: 842.1 | F7: 584.5 | G7: 1131.4
A8: 125~250 | B8: 75.3 | C8: 11.3 | D8: 1.469 | E8: 835.6 | F8: 474.6 | G8: 836.2
A9: 250~375 | B9: 75.7 | C9: 7.0 | D9: 1.371 | E9: 828.0 | F9: 435.5 | G9: 691.9
A10: 375~500 | B10: 76.3 | C10: 7.6 | D10: 1.369 | E10: 818.4 | F10: 426.1 | G10: 603.7
A11: 500~625 | B11: 77.3 | C11: 12.3 | D11: 1.447 | E11: 806.2 | F11: 438.7 | G11: 547.0
A12: 625~750 | B12: 79.0 | C12: 20.2 | D12: 1.599 | E12: 791.0 | F12: 468.8 | G12: 505.0
A13: 750~875 | B13: 81.9 | C13: 31.4 | D13: 1.862 | E13: 772.2 | F13: 523.3 | G13: 472.5
A14: 875~1000 | B14: 87.5 | C14: 47.7 | D14: 2.362 | E14: 748.2 | F14: 629.1 | G14: 452.2
A15: 1000~1063 | B15: 97.5 | C15: 63.9 | D15: 1.399 | E15: 724.5 | F15: 346.4 | G15: 359.5
A16: 1063~1125 | B16: 116.9 | C16: 77.1 | D16: 1.181 | E16: 695.8 | F16: 276.7 | G16: 236.3
... A19: 1198~1200 | B19: 101.6 | C19: 99.8 | D19: 1.003 | E19: 117.7 | F19: 11.3 | G19: 313.1
D21: Acceleration Time: 17.5 s
B22: Energy | D22: First Start | F22: Second Start
A23: Stator Winding Rise | B23: 4749 kW / s | D23: 41°C | F23: 82°C
A24: Rotor Bar Rise | B24: 5381 kW / s | D24: 67°C | F24: 134°C
A25: End Ring Rise | B25: 872 kW / s | D25: 52°C | F25: 103°C
A27: Locked Rotor Thermal Capability
E28: Cold Condition
B29: Rate of Rise | D29: Power | E29: Rise Limit | F29: Max Time
A30: Stator Copper | B30: 3.2°C / s | D30: 368.0 kW | E30: 160°C | F30: 50.6 s
A31: Rotor Bar | B31: 7.5°C / s | D31: 601.8 kW | E31: 260°C | F31: 34.8 s
A32: Rotor ER | B32: 5.8°C / s | D32: 97.6 kW | E32: 180°C | F32: 31.1 s
E34: Hot Condition
B35: Hot Temp. | D35: Rise Limit | E35: Ambient | F35: Total | G35: Max.Time
A36: Stator Copper | B36: 57°C + | D36: 103°C + | E36: 40°C | F36: = 200°C | G36: 32.6 s
A37: Rotor Bar | B37: 74°C + | D37: 186°C + | E37: 40°C | F37: = 300°C | G37: 24.9 s
A38: Rotor ER | B38: 74°C + | D38: 106°C + | E38: 40°C | F38: = 220°C | G38: 18.3 s
A40: Cold Stall Time: | B40: 61.8 s | D40: Hot Stall Time: | F40: 36.4 s

Sheet Thermdam
A2: TOSHIBA INTERNATIONAL CORPORATION
A3: Thermal Limit & Acceleration Curves
A4: Design Values (For Reference Only)
A6: Model #: | B6: ='Performance Data Sheet'!C17 -> M257TCAL11E-C | E6: FLAmps: | F6: 157
A7: Enclosure: | B7: ='Performance Data Sheet'!F14 -> TEAAC | C7: Voltage: | D7: 4000 V | E7: Frame: | F7: ='Performance Data Sheet'!C14 -> 6810US
A8: Pole: | B8: 6 | C8: Frequency: | D8: 3 PH / 60 Hz | E8: Ins. Class: | F8: ='Performance Data Sheet'!M15 -> F
A9: HP: | B9: 1250 | C9: Rotor Inertia: | D9: 1368.8 lb-ft² | E9: Date: | F9: ='Performance Data Sheet'!K45 -> 41992
A10: FLRPM: | B10: 1192 | C10: Load Inertia: | D10: 11379.0 lb-ft² | E10: File: | F10: BW6M25U
A39: Comments: | E39: D.E.Curve #: | F39: BW6M25U
C43: Prepared by: | D43: ='Performance Data Sheet'!K43 -> Mario L | E43: Checked by: | F43: AG
F50: =5252.1*B50/D53 -> #DIV/0!
D66: =D65/D64 -> #DIV/0!
A67: Current (%) | B67: Cold | C67: Hot | E67: CURRENT (%) | F67: Accel. Time
A68: 538.21656 | B68: 35 | C68: 15 | E68: =A68 -> 538.21656 | F68: 0.0001
A69: 471.48438 | B69: =((A68/A69)^2)*B68 -> 45.608684 | C69: =((A68/A69)^2)*C68 -> 19.546579 | E69: 536.36943 | F69: 1.784
A70: 404.73218 | B70: =((A68/A70)^2)*B68 -> 61.893734 | C70: =((A68/A70)^2)*C68 -> 26.525886 | E70: 532.2293 | F70: 3.253
A71: 338 | B71: =((A68/A71)^2)*B68 -> 88.745994 | C71: =((A68/A71)^2)*C68 -> 38.033997 | E71: 527.38854 | F71: 4.6240001
A72: =A71-100 -> 238 | B72: =((A68/A72)^2)*B68 -> 178.98978 | E72: 521.27389 | F72: 5.993
A73: =A72-100 -> 138 | B73: =((A68/A73)^2)*B68 -> 532.38276 | E73: 513.50318 | F73: 7.4400001
A74: 220 | B74: =((A68/A74)^2)*B68 -> 209.47722 | C74: =((A68/A74)^2)*C68 -> 89.77595 | E74: 503.82166 | F74: 9.0390005
A75: 180 | B75: =((A68/A75)^2)*B69 -> 407.77129 | C75: =((A68/A75)^2)*C68 -> 134.10975 | E75: 491.84713 | F75: 10.901001
A76: 145 | B76: =((A68/A76)^2)*B68 -> 482.22104 | C76: =((A68/A76)^2)*C68 -> 206.66616 | E76: 476.56051 | F76: 13.263001
A77: 125 | C77: =CEILING(C76*2,100) -> 500 | E77: 461.46497 | F77: 14.662002
A78: 125 | C78: =2*C77 -> 1000 | E78: 443.18471 | F78: 15.843001
A79: 125 | C79: 10000 | E79: 394.20382 | F79: 16.401001
E80: 235.15924 | F80: 16.516001
E81: 0 | F81: 17.519001

Sheet MagNoise
A1: Magnetic Noise Verification
A3: Rating: | B3: 6 Pole - 1250.0 HP - 1200 RPM - 4000 V - 60 Hz
A5: Electromagnetic Excitation Frequencies
B7: L = | C7: 0 | D7: L = | E7: + 1 | F7: L = | G7: - 1 | H7: Slip = | I7: 0 | J7: Slip = | K7: 0.007
A8: Mode A | B8: 8 | D8: 26 | F8: 10 | H8: 1280.0 Hz | J8: 1272.0 Hz
A9: Mode B | B9: 20 | D9: 38 | F9: 2 | H9: 1040.0 Hz | J9: 1032.0 Hz
A10: Mode C | B10: 14 | D10: 32 | F10: 4 | H10: 1160.0 Hz | J10: 1152.0 Hz
A12: Natural Frequencies of Stator Core
B14: Mode 0 = | D14: 1849.2 Hz | F14: Mode 6 = | H14: 3065.4 Hz
B15: Mode 2 = | D15: 238.2 Hz | F15: Mode 7 = | H15: 4219.1 Hz
B16: Mode 3 = | D16: 673.9 Hz | F16: Mode 8 = | H16: 5550.6 Hz
B17: Mode 4 = | D17: 1292.1 Hz | F17: Mode 9 = | H17: 7059.8 Hz
B18: Mode 5 = | D18: 2089.6 Hz | F18: Mode 10 = | H18: 8746.6 Hz
A20: Analysis Results
B22: Matching frequencies detected!!!
B23: Please check slot combination!!!

Sheet Performance
A2: TOSHIBA INTERNATIONAL CORPORATION
A3: Performance Curve
A4: Design Values (For Reference Only)
A6: Model #: | B6: ='Performance Data Sheet'!C17 -> M257TCAL11E-C | E6: FLAmps: | F6: 157
A7: Enclosure: | B7: ='Performance Data Sheet'!F14 -> TEAAC | C7: Voltage: | D7: 4000 V | E7: Frame: | F7: ='Performance Data Sheet'!C14 -> 6810US
A8: Pole: | B8: 6 | C8: Frequency: | D8: 3 PH / 60 Hz | E8: Ins. Class: | F8: ='Performance Data Sheet'!M15 -> F
A9: HP: | B9: 1250 | C9: Rotor Inertia: | D9: 1368.8 lb-ft² | E9: Date: | F9: ='Performance Data Sheet'!K45 -> 41992
A10: FLRPM: | B10: 1192 | C10: Load Inertia: | D10: N/A | E10: File: | F10: BW6M25U
B12: Locked Rotor Amps: | C12: 845 A | D12: Load Type: | E12: N/A
B13: Locked Rotor Torque: | C13: 0.75 | D13: Starting at: | E13: N/A
B14: Breakdown Torque: | C14: 2.2 | D14: Accel. Time: | E14: N/A
B15: Rated Torque: | C15: 5508 lb-ft
A39: Comments: | E39: D.E.Curve #: | F39: BW6M25U
C43: Prepared by: | D43: ='Performance Data Sheet'!K43 -> Mario L | E43: Checked by: | F43: AG
A53: Load | B53: Efficiency | C53: PF | D53: Amps | E53: RPM | F53: Input Watts
A54: 0 | D54: 37.276569 | E54: 100 | F54: 0.352475
A55: 25 | B55: 90.41246 | C55: 67.146065 | D55: 55.410404 | E55: 90.108564 | F55: 6.4440631
A56: 50 | B56: 94.161346 | C56: 83.909058 | D56: 85.150795 | E56: 80.1129 | F56: 12.375007
A57: 75 | B57: 95.208435 | C57: 88.534492 | D57: 119.72187 | E57: 69.955941 | F57: 18.35836
A58: 100 | B58: 95.527069 | C58: 89.892387 | D58: 156.69344 | E58: 59.30843 | F58: 24.396168
A59: 125 | B59: 95.537903 | C59: 89.922775 | D59: 195.77841 | E59: 48.775788 | F59: 30.491753

Sheet Performance Data Sheet
A1: TOSHIBA INTERNATIONAL CORPORATION | J1: INDEX | L1: MPCF-1033
A2: Industrial Division / Houston Motor Plant | J2: SHEET NO. | L2: 1 of 1
J3: ISSUED | L3: 11/08/96
J4: SUPERSEDES | L4: 10/06/95
J5: REVISION | L5: 1
A6: SQUIRREL CAGE INDUCTION MOTOR | J6: WRITTEN BY | L6: R. EVANS
A7: PERFORMANCE SPECIFICATIONS | J7: APPROVED BY | L7: Jay Bugbee
B9: CUSTOMER:
B10: TIC SR No.:
A12: MOTOR NAMEPLATE DATA
B13: H.P.: | C13: 1250 | E13: VOLTS: | F13: 4000 | H13: 3 PH / | I13: 60 Hz | L13: S. RPM: | M13: 1200
B14: FRAME: | C14: 6810US | E14: ENCL: | F14: TEAAC | H14: FLAMPS: | I14: 157 | L14: FLRPM: | M14: 1192
B15: FORM: | C15: FCW4 | E15: S.F.: | F15: 1.15 | H15: NEMA DESIGN: | I15: - | L15: INSUL CLASS: | M15: F
B16: TYPE: | C16: TIKE | E16: AMB.: | F16: 40°C | H16: CODE: | I16: E | L16: DUTY: | M16: Cont.
B17: MODEL No.: | C17: M257TCAL11E-C | H17: kW:
B18: NOM. EFF.: | C18: - | E18: MIN. EFF.: | F18: - | H18: P.F.: | I18: -
A21: AMPERAGE | E21: TORQUES | I21: **BEARINGS:
C22: LOCKED ROTOR: | D22: 845 | G22: FULL LOAD (lb-ft.): | H22: 5508 | K22: DRIVE END: | L22: M11-125 INS
G23: LOCKED ROTOR (%): | H23: 75 | K23: OPPOSITE DRIVE END: | L23: M11-125 INS
G24: BREAK DOWN (%): | H24: 220
A28: EFFICIENCY | H28: POWER FACTOR
C29: FULL LOAD: | D29: 95.5 | J29: FULL LOAD: | K29: 89.9
C30: 3/4 LOAD: | D30: 95.2 | J30: 3/4 LOAD: | K30: 88.6
C31: 1/2 LOAD: | D31: 94.2 | J31: 1/2 LOAD: | K31: 83.9
A35: ALL CHARACTERISTICS ARE AVERAGE EXPECTED VALUES BASED UPON RATED VOLTAGE,
A36: FREQUENCY AND SINEWAVE POWER INPUT.
A37: THE DECLARED LOCKED ROTOR CURRENT HAS A TOLERANCE OF 20%.
A38: * TEMPERATURE RISE WILL BE CONSISTENT WITH INSULATION, AMBIENT AND SERVICE FACTOR AS
A39: DEFINED BY NEMA-MG-12 OR -20.
A40: ** BEARINGS ARE THE ONLY RECOMMENDED SPARE PART(S).
J43: CERTIFIED BY: | K43: Mario L
J45: DATE: | K45: 41992
A60: - | B60: M11-125 INS | D60: 1 | E60: -
A61: TEFC | B61: 6206UU | D61: 1.15 | E61: A
A62: ODP | B62: 6207ZZ | E62: B
B63: 6208UU
B64: 6211ZZ
B65: 6211C3
B66: 6211ZZC3
B67: 6305UUC3
...
