Workbook
Name Print_Area_MI: 'Performance Data Sheet'!$A$10:$N$42

Sheet DesignSheet
A1: TOSHIBA INTERNATIONAL CORPORATION | I1: Calc. Code: | J1: 2-2-2-0-1-2
A2: 3-PHASE SQUIRREL CAGE INDUCTION MOTOR DESIGN SHEET | J2: B.L.-1 P.F.-1
A3: File: | B3: N:\DESPRO\TESTDAT\By Rating\RF2450.rat | G3: Date: | H3: 40312 | I3: Time: | J3: 0.42236111
A4: Pole | B4: HP | C4: RPM | D4: Form | E4: Voltage | F4: Frequency | G4: Temperature | H4: FLSpeed | I4: FLSlip | J4: Frame
A5: 2 | B5: 450.00002 | C5: 3600 | D5: FCKW | E5: 4000 | F5: 60 | G5: 105 | H5: 3582.8 / 3578.0 | I5: 0.0048 / 0.0061 | J5: 5011
A6: Core Data | D6: Winding Data | H6: Constant Data
B7: Primary | C7: Secondary | F7: Bar | G7: End Ring | H7: St. Slot Pitch | I7: 23.935924 | J7: LR Test Data
A8: Air Gap | B8: 2.5 | H8: Rt. Slot Pitch | I8: 29.105907 | J8: ES
A9: Space Fac. | B9: 0.93000001 | D9: Pitch | E9: 1 ~ 14 | F9: Cross Section Area | H9: Mean Value | I9: 26.520916 | J9: 673.00827
A10: Core Length | B10: 530 | C10: 530 | F10: UB: 452.3 | G10: UER: 2340.0 | H10: Eff.T.W.St. | I10: 14.249204 | J10: WS
A11: OD | B11: 550 | C11: 315 | D11: Coil Pitch | E11: 0.61898571 | G11: ERT: 45.0 | H11: Eff.T.W.Rt. | I11: 29.105907 | J11: 16836.703
A12: ID | B12: 320 | C12: 135 | D12: Slot Fill | E12: - | G12: ERD1: 205.0 | H12: St.Carter Fac. | I12: 1.2045253 | J12: IS
A13: Core Depth | B13: 59 | C13: 46.700001 | D13: Con./Slot | E13: 16 | G13: ERD2: 315.0 | H13: Rt.Carter Fac. | I13: 1 | J13: 58.060497
A14: Eff.Core L. | B14: 492.89999 | C14: 492.89999 | D14: Wire Size 1 | E14: (.091"x.204")x2 | H14: Carter Factor | I14: 1.2045253 | J14: Volts / Turn
A15: Slot Data | D15: Wire Size 2 | E15: - | H15: Short. Factor | I15: 0.82618353 | J15: 20.620257
A16: Number | B16: 42 | C16: 34 | D16: // Circuits | E16: 1 | H16: Distrib. Factor | I16: 0.95564622 | J16: AC
A17: Kind | B17: Open | C17: Dbl - Closed | D17: Connection | E17: Wye | H17: Wind. Factor | I17: 0.78953916 | J17: 388.10616
A18: Skew | B18: - | C18: 0 | D18: MCL | E18: 1127 | F18: 575 | H18: Reactance | I18: (Coeff.: 0.0773)
A19: Depth | B19: 56 | C19: 43.299999 | D19: No.Cond./Ph. | E19: 224 | I19: Running | J19: Start
A20: Width | B20: 9.69 - 9.69 | D20: Res. (20°C) | E20: 0.18845341 | H20: Stator Slot | I20: 17.757233 | J20: 17.757233
A21: Opening | B21: 14 | C21: 0 | D21: (105°C) | E21: 0.25139462 | F21: 0.15288754 | G21: 0.065311626 | H21: Rotor Slot | I21: 61.406036 | J21: 36.963287
A22: Tip Depth | B22: 2.8299999 | C22: 0.80000001 | D22: Material | E22: CU | F22: AL | G22: AL | H22: Zigzag | I22: 5.6205907 | J22: 5.4504204
A23: T.Min.Wid. | B23: 9.9359236 | C23: 10 | D23: Spec.Resist. | E23: 1.742 | F23: 3.25 | G23: 3.25 | H23: Coil End | I23: 14.745592 | J23: Skew R.: 0.00
A24: Low. R. | B24: 0 | C24: 1.5 | D24: Spec.Gravity | E24: 8.8900003 | F24: 2.6700001 | G24: 2.6700001 | H24: Belt Leakage | I24: 7.4034846 | J24: 7.2646515
A25: Up. R. | B25: - | C25: 1.5 | D25: Weight (kg) | H25: Total Resist. | I25: 0.46959379 | J25: 1.6648469
A26: Wedge Dep. | B26: 2.83 - 2.00 | C26: Magnetic | D26: Wire 1 | E26: 157.11261 | F26: 21.761343 | G26: 10.634465 | H26: Total React. | I26: 8.2688046 | J26: 6.3482285
A27: Duct | B27: - | C27: - | D27: Wire 2 | E27: - | F27: - | G27: - | H27: Impedance | I27: 8.2821283 | J27: 6.5629048
A28: Effective Depth (S=1) | D28: Magnetic Circuit Data | I28: Core Loss Data
B29: Res.= | C29: 42.463138 | E29: Length | F29: Section | G29: Density | H29: AT | I29: Volume | J29: Loss
B30: Reac.= | C30: 42.489459 | D30: Primary Core | E30: 43.196863 | F30: 581.62199 | G30: 16.855644 | H30: 641.9345 | I30: 44858.198 | J30: 3707.9445
A31: Excitation Data | D31: Tooth | E31: 5.6 | F31: 1028.4575 | G31: 9.5323465 | H31: 11.617872 | I31: 11518.724 | J31: 378.15689
A32: Excit.Amps | B32: 17.940 / 16.516 | D32: Second.Core | E32: 17.938479 | F32: 682.1736 | G32: 14.371141 | H32: 135.75758 | I32: Total | J32: 4086.1014
A33: Core Loss | B33: 1.145 / 1.054 | C33: Flux / Pole | D33: Tooth | E33: 4.3299999 | F33: 837.92999 | G33: 11.6998 | H33: 16.510019 | I33: C.L.C. | J33: 1.75 / 0.72
A34: NoLoad | B34: 17.98 / 16.55 | C34: 9.8036132 | D34: Air Gap | E34: 0.25 | F34: 2211.7163 | G34: 4.4325817 | H34: 881.83485 | I34: S.F.C. | J34: 6.0500002
A35: Load Characteristics | D35: Temp. Rise @ 100%: | E35: 79 / 78 | G35: No Load Loss | H35: 13622.8 / 9334.8 | I35: W.Loss | J35: 7150.7 / 2959.7
A36: Load (%) | B36: 25 | C36: 50 | D36: 75 | E36: 100 | F36: 125 | G36: Primary Loss | H36: 2542.4 / 2749.7 | I36: S.Loss | J36: 790.2 / 327.0
A37: Current (A) | B37: 24.64 / 25.13 | C37: 34.00 / 34.67 | D37: 45.51 / 46.41 | E37: 58.06 / 59.21 | F37: 71.32 / 72.73 | G37: Second. Loss | H37: 1667.8 / 2141.3 | I37: Total C.Loss | J37: 7940.8 / 3286.7
A38: Efficiency | B38: 0.857 / 0.854 | C38: 0.919 / 0.916 | D38: 0.941 / 0.937 | E38: 0.950 / 0.947 | F38: 0.955 / 0.952 | G38: Frict.& Wind. | H38: 5500.0 / 5885.4 | I38: Stray Loss | J38: 4655.1997
A39: P.F. | B39: 0.574 / 0.565 | C39: 0.775 / 0.763 | D39: 0.849 / 0.835 | E39: 0.878 / 0.864 | F39: 0.889 / 0.875 | G39: Starting Data | I39: Slip | J39: PF
A40: Slip | B40: 0.0012 / 0.0026 | C40: 0.0024 / 0.0037 | D40: 0.0036 / 0.0049 | E40: 0.0048 / 0.0061 | F40: 0.0060 / 0.0073 | G40: LRA | H40: 351.9 / 412.1
...

Sheet Data Sheet
A1: TOSHIBA INTERNATIONAL CORPORATION
A2: INDUCTION MOTOR DATA SHEET
A3: File: | B3: RF2450 | I3: HRW / Model Number: | J3: 4503FTAL11F-A
A4: Type: TIKK - Form: FCKW - 2 Pole - 450 HP - 4000 V - 60 Hz - 5010 - Class F | Q4: Motor Type Selection | T4: Electrical Steel Table
A5: Motor Parameters | F5: PERFORMANCE | J5: DESIGN | K5: TEST | Q5: EPACT | T5: M22 - 26Ga.
A6: Material | D6: M36 - 26Ga. | F6: NL & Impedance Test | M6: 2300V | Q6: EQP-III | T6: M36 - 26Ga.
A7: Air Gap | D7: 2.5 | F7: No load amps | J7: 16.6 | K7: - | M7: 30 | Q7: Exp.Prf. | T7: NCB1 - 26Ga.
A8: Stack length | D8: 530 | F8: No load watts | J8: 9330 | K8: - | M8: 9303 | Q8: Exp.Prf.-EQPIII | T8: M43 - 26Ga.
A9: Number of turns per coil | D9: 8 | F9: Impedance amps | H9: 3 | I9: f | J9: 99 | K9: - | M9: 104 | Q9: Prem. Eff. | T9: M45 - 26Ga.
A10: Wire 1 (size & number) | D10: (.091"x.204")x2 | F10: Impedance volts | H10: 3 | I10: f | J10: 1150 | K10: - | M10: 460 | Q10: OWP | T10: M54 - 26Ga.
A11: Wire 2 (size & number) | D11: - | F11: Impedance watts | H11: 3 | I11: f | J11: 16837 | K11: - | M11: 19700 | Q11: Dry Kiln
A12: Slot fill - circle/square method (%) | D12: - | F12: Temperature Rise (°C)
A13: Connection | D13: 1 x Delta / 1 x Wye | G13: Winding | I13: 80/115 | J13: 79 / 103 | K13: -
A14: MCL | D14: 1127 | G14: Frame | J14: - | K14: -
A15: Allowance for ins. depth | D15: 12.9876 | G15: Bearing PS/OS | J15: - | K15: -
A16: Allowance for ins. width | D16: 3.2368 | G16: End Ring | J16: - | K16: -
A17: Slot/Wire arrangement | D17: 16 x 2 | F17: Nameplate Data
A18: Effective cross section for coil | D18: - | H18: FLC (A) | J18: 103 / 59
A19: Coil grouping | D19: - | H19: RPM | J19: 3575
A20: Coil pitch (slot number) | D20: 1 ~ 14 | H20: CODE | J20: H
A21: Method of coil connection | D21: - | H21: S. F. | J21: 1.15 | Q21: Method of Connection
A22: Resistance per phase @ 20 °C | D22: 0.1918 | H22: DESIGN | J22: - | Q22: Skip
A23: Coil Weight | B23: Wire1 | D23: 356 | H23: Nom.Eff. (%): | Q23: Adjacent
A24: (lbs.) | B24: Wire2 | D24: - | H24: Min.Eff. (%): | Q24: -
A25: Current Densities (A/cm2) | E25: Bar / ER | H25: P.F. (%):
A26: FL / LR | D26: 253 / 1792 | E26: 177 / 186
A27: Stator Slot Shape (Reference) | F27: Performance
H28: LRC (A) | I28: 374 | J28: 714 / 412 | K28: -
H29: LRT (%) | I29: 70 | J29: 200 | K29: -
H30: BDT (%) | I30: 175 | J30: 250 | K30: -
H31: SLIP (%) | J31: 0.61 | K31: -
G32: IEEE-B | H32: Eff. (%) | J32: 94.7 | K32: -
A33: Rotor Slot Shape (Reference) | H33: PF (%) | J33: 86.4 | K33: -
F34: Losses (Watts) | H34: Primary | J34: 2750 | K34: -
H35: Secondary | J35: 2141 | K35: -
H36: Core | J36: 3287 | K36: -
H37: F & W | J37: 5885 | K37: -
H38: Stray | J38: 4655 | K38: -
A39: End Ring (Reference) | F39: Note | G39: Outer Fan OD: 360T Unidirectional
G40: RS02: 400-V110-01CL REF
...

Sheet LoginSheet
J1: P | K1: T | L1: L | M1: T
B2: PROJECT HISTORY | J2: E | K2: D | L2: I | M2: Y | N2: H
J3: R | L3: M | M3: P
J4: F | L4: I | M4: E
K5: C | L5: T | N5: I
J6: D | K6: U | M6: T | N6: N
J7: A | K7: R | L7: R | M7: E | N7: S
I8: S | J8: T | K8: V | L8: E | M8: S | N8: U
B9: DATE | C9: PROJECT | D9: SMART NUMBER | E9: QTY | F9: CUSTOMER | G9: REMARKS | H9: LIMIT CODE | I9: F | J9: A | K9: E | L9: V | M9: T | N9: L
B53: REVISION HISTORY
B54: REV | C54: REMARKS | I54: DATE | L54: INIT

Sheet Form
A1: Winding Data Calculation
C2: MCL: 1127.0
A3: Coil Resistance | D3: Lead Resistance
A4: 8T: | B4: 0.0139 ~ 0.0133 | D4: AWG. 02 x 3
D5: 0.00131
A6: Coil Dimensions
A7: HM: | B7: 8T: 20.09 | C7: WM: | D7: 8T: 10.76 | E7: WT:
E8: 14.10 ~ 13.70
A9: Insulation Allowance | D9: Wire Weight
A10: Depth: | B10: 12.99 | D10: (.091"x.204")x 2: | F10: 356 lbs.
A11: Width: | B11: 3.24
A12: QC Resistance
A13: 1-2, 2-3, 3-1: | C13: 0.395 ~ 0.372

Sheet StallTime
A1: Rating: | B1: 2 Pole - 450.0 HP - 3600 RPM - 4000 V - 60 Hz
A3: Starting Performance
D4: Load Type: Fan / Pump - 175.0 lb-ft²
A5: RPM | B5: Motor | C5: Load | D5: Accel. | E5: Line | F5: Stator | G5: Rotor
A6: Speed Increment | B6: Torque (%) | C6: Torque (%) | D6: Time (s) | E6: Amps | F6: kW / s | G6: kW / s
A7: 0~360 | B7: 194.3 | C7: 22.5 | D7: 0.308 | E7: 416.9 | F7: 40.6 | G7: 255.6
A8: 360~720 | B8: 177.6 | C8: 11.5 | D8: 0.319 | E8: 414.2 | F8: 41.6 | G8: 213.1
A9: 720~1080 | B9: 168.3 | C9: 7.0 | D9: 0.329 | E9: 410.8 | F9: 42.2 | G9: 182.3
A10: 1080~1440 | B10: 163.3 | C10: 7.0 | D10: 0.339 | E10: 406.7 | F10: 42.8 | G10: 158.3
A11: 1440~1800 | B11: 160.8 | C11: 11.0 | D11: 0.354 | E11: 401.9 | F11: 43.6 | G11: 138.6
A12: 1800~2160 | B12: 160.4 | C12: 18.0 | D12: 0.372 | E12: 396.5 | F12: 44.8 | G12: 120.3
A13: 2160~2520 | B13: 161.1 | C13: 27.5 | D13: 0.397 | E13: 390.5 | F13: 46.4 | G13: 103.1
A14: 2520~2880 | B14: 161.8 | C14: 41.5 | D14: 0.440 | E14: 383.1 | F14: 49.8 | G14: 86.2
A15: 2880~3060 | B15: 164.9 | C15: 55.5 | D15: 0.242 | E15: 375.9 | F15: 26.2 | G15: 63.5
A16: 3060~3240 | B16: 179.4 | C16: 67.5 | D16: 0.237 | E16: 366.2 | F16: 24.8 | G16: 48.1
... A19: 3564~3583 | B19: 126.1 | C19: 99.0 | D19: 0.102 | E19: 61.1 | F19: 0.3 | G19: 5.7
D21: Acceleration Time: 3.8 s
B22: Energy | D22: First Start | F22: Second Start
A23: Stator Winding Rise | B23: 435 kW / s | D23: 7°C | F23: 14°C
A24: Rotor Bar Rise | B24: 1001 kW / s | D24: 51°C | F24: 103°C
A25: End Ring Rise | B25: 427 kW / s | D25: 45°C | F25: 90°C
A27: Locked Rotor Thermal Capability
E28: Cold Condition
B29: Rate of Rise | D29: Power | E29: Rise Limit | F29: Max Time
A30: Stator Copper | B30: 2.6°C / s | D30: 158.2 kW | E30: 160°C | F30: 61.2 s
A31: Rotor Bar | B31: 24.7°C / s | D31: 482.2 kW | E31: 260°C | F31: 10.5 s
A32: Rotor ER | B32: 21.6°C / s | D32: 206.0 kW | E32: 180°C | F32: 8.3 s
E34: Hot Condition
B35: Hot Temp. | D35: Rise Limit | E35: Ambient | F35: Total | G35: Max.Time
A36: Stator Copper | B36: 77°C + | D36: 83°C + | E36: 40°C | F36: = 200°C | G36: 31.7 s
A37: Rotor Bar | B37: 105°C + | D37: 155°C + | E37: 40°C | F37: = 300°C | G37: 6.3 s
A38: Rotor ER | B38: 105°C + | D38: 75°C + | E38: 40°C | F38: = 220°C | G38: 3.5 s
A40: Cold Stall Time: | B40: 10.1 s | D40: Hot Stall Time: | F40: 4.2 s

Sheet Performance Data Sheet
A1: TOSHIBA INTERNATIONAL CORPORATION | J1: INDEX | L1: MPCF-1033
A2: Industrial Division / Houston Motor Plant | J2: SHEET NO. | L2: 1 of 1
J3: ISSUED | L3: 7/31/13
J4: SUPERSEDES | L4: 11/8/96
J5: REVISION | L5: 2
A6: SQUIRREL CAGE INDUCTION MOTOR | J6: WRITTEN BY | L6: MDC
A7: PERFORMANCE SPECIFICATIONS | J7: APPROVED BY | L7: PAA
B9: CUSTOMER: | C9: -
B10: TIC SR No.: | C10: -
A12: MOTOR NAMEPLATE DATA
B13: H.P.: | C13: 450 | E13: VOLTS: | F13: 2300 | H13: 3 PH / | I13: 60 Hz | L13: S. RPM: | M13: 3600
B14: FRAME: | C14: 5011USS | E14: ENCL: | F14: TEFC | H14: FLAMPS: | I14: 103 | L14: FLRPM: | M14: 3575
B15: FORM: | C15: FCKW | E15: S.F.: | F15: 1.15 | H15: NEMA DESIGN: | I15: - | L15: INSUL CLASS: | M15: F
B16: TYPE: | C16: TIKK | E16: AMB.: | F16: 40°C | H16: CODE: | I16: H | L16: DUTY: | M16: Cont.
B17: MODEL No.: | C17: 4503FTAL11F-A | H17: kW: | I17: -
B18: NOM. EFF.: | C18: - | E18: MIN. EFF.: | F18: - | H18: P.F.: | I18: -
A21: AMPERAGE | E21: TORQUES | I21: **BEARINGS:
C22: LOCKED ROTOR: | D22: 714 | G22: FULL LOAD (lb-ft.): | H22: 661 | K22: DRIVE END: | L22: REFER TO NP
G23: LOCKED ROTOR (%): | H23: 200 | K23: OPPOSITE DRIVE END: | L23: REFER TO NP
G24: BREAK DOWN (%): | H24: 250
A28: EFFICIENCY | H28: POWER FACTOR
C29: FULL LOAD: | D29: 94.7 | J29: FULL LOAD: | K29: 86.4
C30: 3/4 LOAD: | D30: 93.8 | J30: 3/4 LOAD: | K30: 83.5
C31: 1/2 LOAD: | D31: 91.6 | J31: 1/2 LOAD: | K31: 76.3
A35: ALL CHARACTERISTICS ARE AVERAGE EXPECTED VALUES BASED UPON RATED VOLTAGE,
A36: FREQUENCY AND SINEWAVE POWER INPUT.
A37: THE DECLARED LOCKED ROTOR CURRENT HAS A TOLERANCE OF 20%.
A38: * TEMPERATURE RISE WILL BE CONSISTENT WITH INSULATION, AMBIENT AND SERVICE FACTOR AS
A39: DEFINED BY NEMA-MG-12 OR -20.
A40: ** BEARINGS ARE THE ONLY RECOMMENDED SPARE PART(S).
J42: CERTIFIED BY: | K42: Zichao Xie
J44: DATE: | K44: 42747
A59: - | B59: 6205ZZ | D59: 1 | E59: -
A60: TEFC | B60: 6206UU | D60: 1.15 | E60: A
A61: ODP | B61: 6207ZZ | E61: B
B62: 6208UU
B63: 6211ZZ
B64: 6211C3
B65: 6211ZZC3
B66: 6305UUC3
...

Sheet STCurve
A2: TOSHIBA INTERNATIONAL CORPORATION
A3: Speed Torque/Current Curve
A6: Model #: | B6: ='Performance Data Sheet'!C17 -> 4503FTAL11F-A | E6: FLAmps: | F6: ='Performance Data Sheet'!I14 -> 103
A7: Enclosure: | B7: ='Performance Data Sheet'!F14 -> TEFC | C7: Voltage: | D7: ='Performance Data Sheet'!F13 & " V" -> 2300 V | E7: Frame: | F7: ='Performance Data Sheet'!C14 -> 5011USS
A8: Pole: | B8: 2 | C8: Frequency: | D8: 3 PH / 60 Hz | E8: Ins. Class: | F8: ='Performance Data Sheet'!M15 -> F
A9: HP: | B9: ='Performance Data Sheet'!C13 -> 450 | C9: Rotor Inertia: | D9: 123.8 lb-ft² | E9: Date: | F9: ='Performance Data Sheet'!K44 -> 42747
A10: FLRPM: | B10: ='Performance Data Sheet'!M14 -> 3575 | C10: Load Inertia: | D10: 175.0 lb-ft² | E10: File: | F10: RF2450
B12: Locked Rotor Amps: | C12: ='Performance Data Sheet'!D22 & " A" -> 714 A | D12: Load Type: | E12: Fan / Pump
B13: Locked Rotor Torque: | C13: 2 | D13: Starting at: | E13: FV (V)
B14: Breakdown Torque: | C14: 2.5 | D14: Accel. Time: | E14: 3.8 (s)
B15: Rated Torque: | C15: 661 lb-ft
A39: Comments: | B39: PROJECT | C39: ='Performance Data Sheet'!C10 -> - | E39: D.E.Curve #:
C43: Prepared by: | D43: ='Performance Data Sheet'!K42 -> Zichao Xie | E43: Checked by:
D53: Load
A54: 100 | B54: 0 | C54: 0.30468458 | D54: 100
A55: 99 | B55: 149.24866 | C55: 186.4827 | D55: 98
A56: 95 | B56: 250 | C56: 524.08502 | D56: 87
A57: 90 | B57: 182.56008 | C57: 601.06641 | D57: 74
A58: 84.999999 | B58: 157.26922 | C58: 622.55176 | D58: 61
A59: 80 | B59: 150.57366 | C59: 633.28186 | D59: 50
A60: 69.999999 | B60: 150.30893 | C60: 646.88513 | D60: 33
A61: 59.999999 | B61: 150 | C61: 657.76349 | D61: 22
A62: 50 | B62: 150.41434 | C62: 667.12347 | D62: 14
A63: 39.999998 | B63: 152.24764 | C63: 675.67401 | D63: 7.9999995
A64: 30.000001 | B64: 156.14762 | C64: 683.13196 | D64: 5.9999995
A65: 19.999999 | B65: 163.43494 | C65: 689.41553 | D65: 8.000001
... A67: 0 | B67: 200 | C67: 698.30505 | D67: 30

Sheet Thermdam
A2: TOSHIBA INTERNATIONAL CORPORATION
A3: Thermal Limit & Acceleration Curves
A4: Design Values (For Reference Only)
A6: Model #: | B6: ='Performance Data Sheet'!C17 -> 4503FTAL11F-A | E6: FLAmps: | F6: ='Performance Data Sheet'!I14 -> 103
A7: Enclosure: | B7: ='Performance Data Sheet'!F14 -> TEFC | C7: Voltage: | D7: ='Performance Data Sheet'!F13 & " V" -> 2300 V | E7: Frame: | F7: ='Performance Data Sheet'!C14 -> 5011USS
A8: Pole: | B8: 2 | C8: Frequency: | D8: 3 PH / 60 Hz | E8: Ins. Class: | F8: ='Performance Data Sheet'!M15 -> F
A9: HP: | B9: ='Performance Data Sheet'!C13 -> 450 | C9: Rotor Inertia: | D9: 123.8 lb-ft² | E9: Date: | F9: ='Performance Data Sheet'!K44 -> 42747
A10: FLRPM: | B10: ='Performance Data Sheet'!M14 -> 3575 | C10: Load Inertia: | D10: 175.0 lb-ft² | E10: File: | F10: RF2450
C12: ='Performance Data Sheet'!D22 & " A" -> 714 A
E14: 3.8 (s)
A39: Comments: | B39: PROJECT | C39: ='Performance Data Sheet'!C10 -> - | E39: D.E.Curve #:
C43: Prepared by: | D43: ='Performance Data Sheet'!K42 -> Zichao Xie | E43: Checked by:
F50: =5252.1*B50/D53 -> #DIV/0!
D66: =D65/D64 -> #DIV/0!
A67: Current (%) | B67: Cold | C67: Hot | E67: CURRENT (%) | F67: Accel. Time
A68: 708.47458 | B68: 14.445968 | C68: 6.0525574 | E68: 708.47458 | F68: 0.0001
A69: 700 | B69: 14.797867 | C69: 6.1999955 | E69: 706.61017 | F69: 0.24188472
A70: 600 | B70: 20.141541 | C70: 8.4388828 | E70: 702.0339 | F70: 0.49240816
A71: 500 | B71: 29.003819 | C71: 12.151991 | E71: 696.27119 | F71: 0.75078502
A72: 400 | B72: 45.318468 | E72: 689.32203 | F72: 1.0170153
A73: 300 | B73: 80.566165 | E73: 681.18644 | F73: 1.2950256
A74: 255 | B74: 111.51026 | C74: 46.720459 | E74: 672.0339 | F74: 1.5871721
A75: 180 | B75: 229.24647 | C75: 93.765365 | E75: 661.86441 | F75: 1.8989521
A76: 120 | B76: 503.53853 | C76: 210.97207 | E76: 649.32203 | F76: 2.2445018
A77: 110 | C77: 500 | E77: 637.11864 | F77: 2.4345541
A78: 110 | C78: 1000 | E78: 620.67797 | F78: 2.6206797
A79: 110 | C79: 10000 | E79: 570.84746 | F79: 2.766753
E80: 360.50847 | F80: 2.9167529
E81: =A77 -> 110 | F81: 2.9968576

Sheet Performance 4000V
A2: TOSHIBA INTERNATIONAL CORPORATION
A3: Performance Curve
A4: Design Values (For Reference Only)
A6: Model #: | B6: ='Performance Data Sheet'!C17 -> 4503FTAL11F-A | E6: FLAmps: | F6: 59 A
A7: Enclosure: | B7: ='Performance Data Sheet'!F14 -> TEFC | C7: Voltage: | D7: 4000 V | E7: Frame: | F7: ='Performance Data Sheet'!C14 -> 5011USS
A8: Pole: | B8: 2 | C8: Frequency: | D8: 3 PH / 60 Hz | E8: Ins. Class: | F8: ='Performance Data Sheet'!M15 -> F
A9: HP: | B9: ='Performance Data Sheet'!C13 -> 450 | C9: Rotor Inertia: | D9: 123.8 lb-ft² | E9: Date: | F9: ='Performance Data Sheet'!K44 -> 42747
A10: FLRPM: | B10: ='Performance Data Sheet'!M14 -> 3575 | C10: Load Inertia: | D10: 175.0 lb-ft² | E10: File: | F10: RF2450
B12: Locked Rotor Amps: | C12: 412 A | D12: Load Type: | E12: Fan / Pump
B13: Locked Rotor Torque: | C13: 2 | D13: Starting at: | E13: FV (V)
B14: Breakdown Torque: | C14: 2.5 | D14: Accel. Time: | E14: 3.8 (s)
B15: Rated Torque: | C15: 661 lb-ft
A39: Comments: | B39: PROJECT | C39: ='Performance Data Sheet'!C10 -> - | E39: D.E.Curve #:
C43: Prepared by: | D43: ='Performance Data Sheet'!K42 -> Zichao Xie | E43: Checked by:
A53: Load | B53: Efficiency | C53: PF | D53: Amps | E53: RPM | F53: Input Watts
A54: 0 | D54: 18.332451 | E54: 100 | F54: =9330/10000 -> 0.933
A55: 25 | B55: 85.411461 | C55: 56.45425 | D55: 25.130697 | E55: 69.197728 | F55: 9.828994
A56: 50 | B56: 91.649429 | C56: 76.265099 | D56: 34.673027 | E56: 58.866101 | F56: 18.319999
A57: 75 | B57: 93.773727 | C57: 83.521492 | D57: 46.415085 | E57: 48.323519 | F57: 26.857481
A58: 100 | B58: 94.744537 | C58: 86.4021 | D58: 59.210506 | E58: 37.578915 | F58: 35.443041
A59: 125 | B59: 95.228584 | C59: 87.474609 | D59: 72.734085 | E59: 26.521486 | F59: 44.078605

Sheet Performance 2300V
A2: TOSHIBA INTERNATIONAL CORPORATION
A3: Performance Curve
A4: Design Values (For Reference Only)
A6: Model #: | B6: ='Performance Data Sheet'!C17 -> 4503FTAL11F-A | E6: FLAmps: | F6: 103 A
A7: Enclosure: | B7: ='Performance Data Sheet'!F14 -> TEFC | C7: Voltage: | D7: 2300 V | E7: Frame: | F7: ='Performance Data Sheet'!C14 -> 5011USS
A8: Pole: | B8: 2 | C8: Frequency: | D8: 3 PH / 60 Hz | E8: Ins. Class: | F8: ='Performance Data Sheet'!M15 -> F
A9: HP: | B9: ='Performance Data Sheet'!C13 -> 450 | C9: Rotor Inertia: | D9: 123.8 lb-ft² | E9: Date: | F9: ='Performance Data Sheet'!K44 -> 42747
A10: FLRPM: | B10: ='Performance Data Sheet'!M14 -> 3575 | C10: Load Inertia: | D10: 9.56 lb-ft² | E10: File: | F10: RF2450
B12: Locked Rotor Amps: | C12: 714 A | D12: Load Type: | E12: Fan / Pump
B13: Locked Rotor Torque: | C13: 2 | D13: Starting at: | E13: FV (V)
B14: Breakdown Torque: | C14: 2.5 | D14: Accel. Time: | E14: 2 (s)
B15: Rated Torque: | C15: 661 lb-ft
A39: Comments: | B39: PROJECT | C39: ='Performance Data Sheet'!C10 -> - | E39: D.E.Curve #:
C43: Prepared by: | D43: ='Performance Data Sheet'!K42 -> Zichao Xie | E43: Checked by:
A53: Load | B53: Efficiency | C53: PF | D53: Amps | E53: RPM | F53: Input Watts
A54: 0 | D54: 31.752737 | E54: 100 | F54: =9330/10000 -> 0.933
A55: 25 | B55: 85.411461 | C55: 56.45425 | D55: 43.527644 | E55: 69.197728 | F55: 9.828994
A56: 50 | B56: 91.649429 | C56: 76.265099 | D56: 60.055444 | E56: 58.866101 | F56: 18.319999
A57: 75 | B57: 93.773727 | C57: 83.521492 | D57: 80.393285 | E57: 48.323519 | F57: 26.857481
A58: 100 | B58: 94.744537 | C58: 86.4021 | D58: 102.55561 | E58: 37.578915 | F58: 35.443041
A59: 125 | B59: 95.228584 | C59: 87.474609 | D59: 125.97913 | E59: 26.521486 | F59: 44.078605
