Workbook
Name Print_Area_MI: 'PERFORMANCE SPEC'!$A$10:$N$18
Name Print_Area_MI: 'Rev. 1'!$A$8:$N$45
Name Print_Area_MI: 'Performance Data Sheet'!$A$10:$N$42

Sheet DesignSheet
A1: TOSHIBA INTERNATIONAL CORPORATION | I1: Calc. Code: | J1: 2-1-2-0-1-2
A2: 3-PHASE SQUIRREL CAGE INDUCTION MOTOR DESIGN SHEET | J2: B.L.-1 P.F.-1
A3: File: | B3: G:\DESPRO\RATFILE\RF2400.rat | G3: Date: | H3: 43350 | I3: Time: | J3: 0.33887731
A4: Pole | B4: HP | C4: RPM | D4: Form | E4: Voltage | F4: Frequency | G4: Temperature | H4: FLSpeed | I4: FLSlip | J4: Frame
A5: 2 | B5: 400 | C5: 3600 | D5: FCKW | E5: 4000 | F5: 60 | G5: 105 | H5: 3581.3 / 3576.4 | I5: 0.0052 / 0.0066 | J5: 5011
A6: Core Data | D6: Winding Data | E6: USA Wire Std | H6: Constant Data
B7: Primary | C7: Secondary | F7: Bar | G7: End Ring | H7: St. Slot Pitch | I7: 23.935924 | J7: LR Test Data
A8: Air Gap | B8: 2.5 | H8: Rt. Slot Pitch | I8: 29.105907 | J8: ES
A9: Space Fac. | B9: 0.93000001 | D9: Pitch | E9: 1 ~ 14 | F9: Cross Section Area | H9: Mean Value | I9: 26.520916 | J9: 706.83909
A10: Core Length | B10: 500 | C10: 500 | F10: UB: 452.3 | G10: UER: 2340.0 | H10: Eff.T.W.St. | I10: 14.249204 | J10: WS
A11: OD | B11: 550 | C11: 315 | D11: Coil Pitch | E11: 0.61898571 | G11: ERT: 45.0 | H11: Eff.T.W.Rt. | I11: 29.105907 | J11: 15500.084
A12: ID | B12: 320 | C12: 135 | D12: Slot Fill | E12: - | G12: ERD1: 205.0 | H12: St.Carter Fac. | I12: 1.2045253 | J12: IS
A13: Core Depth | B13: 59 | C13: 46.700001 | D13: Con./Slot | E13: 18 | G13: ERD2: 315.0 | H13: Rt.Carter Fac. | I13: 1 | J13: 50.697895
A14: Eff.Core L. | B14: 465 | C14: 465 | D14: Wire Size 1 | E14: (.081"x.204")x2 | H14: Carter Factor | I14: 1.2045253 | J14: Volts / Turn
A15: Slot Data | D15: Wire Size 2 | E15: - | H15: Short. Factor | I15: 0.82618353 | J15: 18.329117
A16: Number | B16: 42 | C16: 34 | D16: // Circuits | E16: 1 | H16: Distrib. Factor | I16: 0.95564622 | J16: AC
A17: Kind | B17: Open | C17: Dbl - Closed | D17: Connection | E17: Wye | H17: Wind. Factor | I17: 0.78953916 | J17: 381.2521
A18: Skew | B18: - | C18: 0 | D18: MCL | E18: 1097 | F18: 545 | H18: Reactance | I18: (Coeff.: 0.0923)
A19: Depth | B19: 56 | C19: 43.299999 | D19: No.Cond./Ph. | E19: 252 | I19: Running | J19: Start
A20: Width | B20: 9.69 - 9.69 | D20: Res. (20°C) | E20: 0.23260443 | H20: Stator Slot | I20: 17.757233 | J20: 17.757233
A21: Opening | B21: 14 | C21: 0 | D21: (105°C) | E21: 0.31029157 | F21: 0.18340273 | G21: 0.082660027 | H21: Rotor Slot | I21: 61.295113 | J21: 37.178459
A22: Tip Depth | B22: 2.8299999 | C22: 0.80000001 | D22: Material | E22: CU | F22: AL | G22: AL | H22: Zigzag | I22: 5.6205907 | J22: 5.5190763
A23: T.Min.Wid. | B23: 12.728445 | C23: 10 | D23: Spec.Resist. | E23: 1.742 | F23: 3.25 | G23: 3.25 | H23: Coil End | I23: 15.630328 | J23: Skew R.: 0.00
A24: Low. R. | B24: 0 | C24: 1.5 | D24: Spec.Gravity | E24: 8.8900003 | F24: 2.6700001 | G24: 2.6700001 | H24: Belt Leakage | I24: 7.4034846 | J24: 7.3476533
A25: Up. R. | B25: - | C25: 1.5 | D25: Weight (kg) | H25: Total Resist. | I25: 0.57635432 | J25: 2.0101707
A26: Wedge Dep. | B26: 2.83 - 2.00 | C26: Magnetic | D26: Wire 1 | E26: 152.63971 | F26: 20.529569 | G26: 10.634465 | H26: Total React. | I26: 9.9442797 | J26: 7.6959352
A27: Duct | B27: - | C27: - | D27: Wire 2 | E27: - | F27: - | G27: - | H27: Impedance | I27: 9.960968 | J27: 7.9541311
A28: Effective Depth (S=1) | D28: Magnetic Circuit Data | I28: Core Loss Data
B29: Res.= | C29: 42.463138 | E29: Length | F29: Section | G29: Density | H29: AT | I29: Volume | J29: Loss | M29: =RIGHT(F$41,SEARCH("/",F$41,1)-1) -> 3571.6 | N29: 125RPM
B30: Reac.= | C30: 42.489459 | D30: Primary Core | E30: 43.196863 | F30: 548.7 | G30: 15.881762 | H30: 499.17645 | I30: 42319.055 | J30: 3176.5506 | M30: =RIGHT(E$41,SEARCH("/",E$41,1)-1) -> 3576.4 | N30: 100RPM
A31: Excitation Data | D31: Tooth | E31: 5.6 | F31: 1242.9327 | G31: 7.0110982 | H31: 4.4317955 | I31: 13920.846 | J31: 277.84524 | M31: =RIGHT(D$41,SEARCH("/",D$41,1)-1) -> 3581.1 | N31: 75RPM
A32: Excit.Amps | B32: 13.265 / 12.706 | D32: Second.Core | E32: 17.938479 | F32: 800.49751 | G32: 10.886134 | H32: 55.457238 | I32: Total | J32: 3454.3958 | M32: =RIGHT(C$41,SEARCH("/",C$41,1)-1) -> 3585.7 | N32: 50RPM
A33: Core Loss | B33: 0.965 / 0.925 | C33: Flux / Pole | D33: Tooth | E33: 4.3299999 | F33: 790.5 | G33: 11.023811 | H33: 13.889666 | I33: C.L.C. | J33: 1.75 / 0.73 | M33: =RIGHT(B$41,SEARCH("/",B$41,1)-1) -> 3590.2 | N33: 25RPM
A34: NoLoad | B34: 13.30 / 12.74 | C34: 8.7143229 | D34: Air Gap | E34: 0.25 | F34: 2086.5248 | G34: 4.176477 | H34: 830.88439 | I34: S.F.C. | J34: 6.0500002
A35: Load Characteristics | D35: Temp. Rise @ 100%: | E35: 78 / 78 | G35: No Load Loss | H35: 12318.0 / 8503.0 | I35: W.Loss | J35: 6045.2 / 2532.3
A36: Load (%) | B36: 25 | C36: 50 | D36: 75 | E36: 100 | F36: 125 | G36: Primary Loss | H36: 2392.6 / 2614.7 | I36: S.Loss | J36: 650.1 / 272.3
A37: Current (A) | B37: 19.67 / 20.20 | C37: 28.66 / 29.43 | D37: 39.28 / 40.34 | E37: 50.70 / 52.06 | F37: 62.73 / 64.42 | G37: Second. Loss | H37: 1628.8 / 2090.8 | I37: Total C.Loss | J37: 6695.3 / 2804.6
A38: Efficiency | B38: 0.855 / 0.850 | C38: 0.918 / 0.912 | D38: 0.939 / 0.934 | E38: 0.949 / 0.943 | F38: 0.954 / 0.948 | G38: Frict.& Wind. | H38: 5500.0 / 5885.4 | I38: Stray Loss | J38: 4545.3999 | L38: =LEFT(E38,SEARCH("/",E38,1)-1) -> 0.949 | M38: =RIGHT(E38,SEARCH("/",E38,1)-1) -> 0.943 | N38: =M38/L38 -> 0.99367756 | O38: Eff.
A39: P.F. | B39: 0.640 / 0.627 | C39: 0.819 / 0.802 | D39: 0.875 / 0.858 | E39: 0.8953 / 0.8770 | F39: 0.900 / 0.882 | G39: Starting Data | I39: Slip | J39: PF | L39: =LEFT(E39,SEARCH("/",E39,1)-1) -> 0.8953 | M39: =RIGHT(E39,SEARCH("/",E39,1)-1) -> 0.8770 | N39: =M39/L39 -> 0.97955992 | O39: PF.
A40: Slip | B40: 0.0014 / 0.0027 | C40: 0.0026 / 0.0040 | D40: 0.0039 / 0.0052 | E40: 0.0052 / 0.0066 | F40: 0.0065 / 0.0079 | G40: LRA | H40: 290.3 / 340.0 | L40: =LEFT(E37,SEARCH("/",E37,1)-1) -> 50.70 | M40: =RIGHT(E37,SEARCH("/",E37,1)-1) -> 52.06 | N40: =M40/L40 -> 1.0268245 | O40: Current
...

Sheet Data Sheet
A1: TOSHIBA INTERNATIONAL CORPORATION
A2: INDUCTION MOTOR DATA SHEET
A3: File: | B3: RF2400 | I3: HRW / Model Number: | J3: 4003FTAL11F-A
A4: Type: TIKK - Form: FCKW - 2 Pole - 400 HP - 2300/4000 V - 60 Hz - 5011 - Class F | N4: TEST PREDICT | Q4: Motor Type Selection | T4: Electrical Steel Table
A5: Motor Parameters | F5: PERFORMANCE | J5: DESIGN | K5: TEST | M5: DESPRO | N5: QC LIMIT | Q5: EPACT | T5: M22 - 26Ga.
A6: Material | D6: M36 - 26Ga. | F6: NL & Impedance Test | M6: 2300V | N6: 2300V | Q6: EQP-III | T6: M36 - 26Ga.
A7: Air Gap | D7: 2.5 | F7: No load amps | J7: 12.7 | K7: 13.4 | M7: 22 | N7: 23.212598 | Q7: Exp.Prf. | T7: NCB1 - 26Ga.
A8: Stack length | D8: 500 | F8: No load watts | J8: 8503 | K8: 11039 | M8: 8470 | N8: 10996.158 | Q8: Exp.Prf.-EQPIII | T8: M43 - 26Ga.
A9: Number of turns per coil | D9: 9 | F9: Impedance amps | H9: 3 | I9: f | J9: 82 | K9: 76.3 | M9: 99 | N9: 92.118293 | Q9: Prem. Eff. | T9: M45 - 26Ga.
A10: Wire 1 (size & number) | D10: (.081"x.204")x2 | F10: Impedance volts | H10: 3 | I10: f | J10: 1150 | K10: 1150 | M10: 460 | N10: 460 | Q10: OWP | T10: M54 - 26Ga.
A11: Wire 2 (size & number) | D11: - | F11: Impedance watts | H11: 3 | I11: f | J11: 15500 | K11: 39513 | M11: 15611 | N11: 39795.964 | Q11: Dry Kiln
A12: Slot fill - circle/square method (%) | D12: - | F12: Temperature Rise (°C)
A13: Connection | D13: 1 Delta / 1 x Wye | G13: Winding | I13: 80/115 | J13: 78 / 103 | K13: -
A14: MCL | D14: 1097 | G14: Frame | J14: - | K14: -
A15: Allowance for ins. depth | D15: 12.5368 | G15: Bearing PS/OS | J15: - | K15: -
A16: Allowance for ins. width | D16: 3.2368 | G16: End Ring | J16: - | K16: -
A17: Slot/Wire arrangement | D17: 18 x 2 | F17: Nameplate Data
A18: Effective cross section for coil | D18: - | H18: FLC (A) | J18: 90 / 52
A19: Coil grouping | D19: - | H19: RPM | J19: 3575
A20: Coil pitch (slot number) | D20: 1 ~ 14 | H20: CODE | J20: G
A21: Method of coil connection | D21: - | H21: S. F. | J21: 1.15 | Q21: Method of Connection
A22: Resistance per phase @ 20 °C | D22: 0.2326 | H22: DESIGN | J22: B | Q22: Skip
A23: Coil Weight | B23: Wire1 | D23: 335.8 | H23: Nom.Eff. (%): | J23: - | Q23: Adjacent
A24: (lbs.) | B24: Wire2 | D24: - | H24: Min.Eff. (%): | J24: - | Q24: -
A25: Current Densities (A/cm2) | E25: Bar / ER | H25: P.F. (%): | J25: -
A26: FL / LR | D26: 251 / 1641 | E26: 180 / 189
A27: Stator Slot Shape (Reference) | F27: Performance
H28: LRC (A) | I28: 334 | J28: 589 / 340 | K28: - | M28: =J28/J18 -> #VALUE!
H29: LRT (%) | I29: 70 | J29: 185 | K29: -
H30: BDT (%) | I30: 175 | J30: 237 | K30: -
H31: SLIP (%) | J31: 0.66 | K31: -
G32: IEEE-B | H32: Eff. (%) | J32: 94.3 | K32: -
A33: Rotor Slot Shape (Reference) | H33: PF (%) | J33: 87.7 | K33: -
F34: Losses (Watts) | H34: Primary | J34: 2615 | K34: -
H35: Secondary | J35: 2091 | K35: -
H36: Core | J36: 2805 | K36: -
H37: F & W | J37: 5885 | K37: -
H38: Stray | J38: 4545 | K38: -
A39: End Ring (Reference) | F39: Note | G39: Outer Fan OD: 360T Unidirectional
G40: 361-V120-3L1Y, 361-V120-3L1D, 361-V120-6L1DY
...

Sheet LoginSheet
J1: P | K1: T | L1: L | M1: T
B2: PROJECT HISTORY | J2: E | K2: D | L2: I | M2: Y | N2: H
J3: R | L3: M | M3: P
J4: F | L4: I | M4: E
K5: C | L5: T | N5: I
J6: D | K6: U | M6: T | N6: N
J7: A | K7: R | L7: R | M7: E | N7: S
I8: S | J8: T | K8: V | L8: E | M8: S | N8: U
B9: DATE | C9: PROJECT | D9: SMART NUMBER | E9: QTY | F9: CUSTOMER | G9: REMARKS | H9: LIMIT CODE | I9: F | J9: A | K9: E | L9: V | M9: T | N9: L
B53: REVISION HISTORY
B54: REV | C54: REMARKS | I54: DATE | L54: INIT

Sheet StallTime
A1: Rating: | B1: 2 Pole - 400.0 HP - 3600 RPM - 4000 V - 60 Hz
A3: Starting Performance
D4: Load Type: Fan / Pump - 315.0 lb-ft²
A5: RPM | B5: Motor | C5: Load | D5: Accel. | E5: Line | F5: Stator | G5: Rotor
A6: Speed Increment | B6: Torque (%) | C6: Torque (%) | D6: Time (s) | E6: Amps | F6: kW / s | G6: kW / s
A7: 0~360 | B7: 176.6 | C7: 22.5 | D7: 0.559 | E7: 339.1 | F7: 60.1 | G7: 333.8
A8: 360~720 | B8: 163.6 | C8: 11.5 | D8: 0.566 | E8: 336.9 | F8: 60.3 | G8: 276.8
A9: 720~1080 | B9: 156.3 | C9: 7.0 | D9: 0.577 | E9: 334.2 | F9: 60.5 | G9: 236.7
A10: 1080~1440 | B10: 152.5 | C10: 7.0 | D10: 0.592 | E10: 330.8 | F10: 61.0 | G10: 205.7
A11: 1440~1800 | B11: 150.6 | C11: 11.0 | D11: 0.617 | E11: 327.0 | F11: 62.2 | G11: 180.6
A12: 1800~2160 | B12: 150.4 | C12: 18.0 | D12: 0.650 | E12: 322.6 | F12: 63.9 | G12: 157.5
A13: 2160~2520 | B13: 151.0 | C13: 27.5 | D13: 0.697 | E13: 317.7 | F13: 66.6 | G13: 135.8
A14: 2520~2880 | B14: 151.6 | C14: 41.5 | D14: 0.782 | E14: 311.8 | F14: 72.3 | G14: 114.7
A15: 2880~3060 | B15: 154.3 | C15: 55.5 | D15: 0.436 | E15: 305.8 | F15: 38.6 | G15: 85.5
A16: 3060~3240 | B16: 167.3 | C16: 67.5 | D16: 0.431 | E16: 297.9 | F16: 36.9 | G16: 65.5
... A19: 3564~3581 | B19: 119.6 | C19: 99.0 | D19: 0.200 | E19: 48.5 | F19: 0.5 | G19: 9.8
D21: Acceleration Time: 6.8 s
B22: Energy | D22: First Start | F22: Second Start
A23: Stator Winding Rise | B23: 632 kW / s | D23: 11°C | F23: 22°C
A24: Rotor Bar Rise | B24: 1293 kW / s | D24: 70°C | F24: 141°C
A25: End Ring Rise | B25: 583 kW / s | D25: 61°C | F25: 122°C
A27: Locked Rotor Thermal Capability
E28: Cold Condition
B29: Rate of Rise | D29: Power | E29: Rise Limit | F29: Max Time
A30: Stator Copper | B30: 2.2°C / s | D30: 129.6 kW | E30: 160°C | F30: 72.6 s
A31: Rotor Bar | B31: 20.7°C / s | D31: 380.5 kW | E31: 260°C | F31: 12.6 s
A32: Rotor ER | B32: 18.0°C / s | D32: 171.5 kW | E32: 180°C | F32: 10.0 s
E34: Hot Condition
B35: Hot Temp. | D35: Rise Limit | E35: Ambient | F35: Total | G35: Max.Time
A36: Stator Copper | B36: 78°C + | D36: 82°C + | E36: 40°C | F36: = 200°C | G36: 37.2 s
A37: Rotor Bar | B37: 106°C + | D37: 154°C + | E37: 40°C | F37: = 300°C | G37: 7.4 s
A38: Rotor ER | B38: 106°C + | D38: 74°C + | E38: 40°C | F38: = 220°C | G38: 4.1 s
A40: Cold Stall Time: | B40: 12.1 s | D40: Hot Stall Time: | F40: 5.0 s

Sheet Form
A1: Winding Data Calculation
C2: MCL: 1097.0
A3: Coil Resistance | D3: Lead Resistance
A4: 9T: | B4: 0.0172 ~ 0.0165 | D4: AWG. 06 x 3
D5: 0.00090
A6: Coil Dimensions
A7: HM: | B7: 9T: 20.32 | C7: WM: | D7: 9T: 10.76 | E7: WT:
E8: 14.10 ~ 13.70
A9: Insulation Allowance | D9: Wire Weight
A10: Depth: | B10: 12.54 | D10: (.081"x.204")x 2: | F10: 347 lbs.
A11: Width: | B11: 3.24
A12: QC Resistance
A13: 1-2, 2-3, 3-1: | C13: 0.487 ~ 0.459

Sheet Performance Data Sheet
A1: TOSHIBA INTERNATIONAL CORPORATION | J1: INDEX | L1: MPCF-1033
A2: Industrial Division / Houston Motor Plant | J2: SHEET NO. | L2: 1 of 1
J3: ISSUED | L3: 7/31/13
J4: SUPERSEDES | L4: 11/8/96
J5: REVISION | L5: 2
A6: SQUIRREL CAGE INDUCTION MOTOR | J6: WRITTEN BY | L6: MDC
A7: PERFORMANCE SPECIFICATIONS | J7: APPROVED BY | L7: PAA
B9: CUSTOMER: | C9: DYKMAN ELECTRICAL INC
B10: TIC SR No.: | C10: 2103004.1
A12: MOTOR NAMEPLATE DATA
B13: H.P.: | C13: 400 | E13: VOLTS: | F13: 4000 | H13: 3 PH / | I13: 60 Hz | L13: S. RPM: | M13: 3600
B14: FRAME: | C14: 5011UZ | E14: ENCL: | F14: TEFC | H14: FLAMPS: | I14: 52 | L14: FLRPM: | M14: 3575
B15: FORM: | C15: FCKW | E15: S.F.: | F15: 1.15 | H15: NEMA DESIGN: | I15: B | L15: INSUL CLASS: | M15: F
B16: TYPE: | C16: TIKK | E16: AMB.: | F16: 40°C | H16: CODE: | I16: G | L16: DUTY: | M16: Cont.
B17: MODEL No.: | C17: GP-10011492 | H17: kW: | I17: -
B18: NOM. EFF.: | C18: - | E18: MIN. EFF.: | F18: - | H18: P.F.: | I18: -
A21: AMPERAGE | E21: TORQUES | I21: **BEARINGS:
C22: LOCKED ROTOR: | D22: 340 | G22: FULL LOAD (lb-ft.): | H22: 588 | K22: DRIVE END: | L22: REFER TO NP
G23: LOCKED ROTOR (%): | H23: 185 | K23: OPPOSITE DRIVE END: | L23: REFER TO NP
G24: BREAK DOWN (%): | H24: 235
A28: EFFICIENCY | H28: POWER FACTOR
C29: FULL LOAD: | D29: 94.3 | J29: FULL LOAD: | K29: 87.7
C30: 3/4 LOAD: | D30: 93.3 | J30: 3/4 LOAD: | K30: 85.8
C31: 1/2 LOAD: | D31: 91.2 | J31: 1/2 LOAD: | K31: 80.2
A35: ALL CHARACTERISTICS ARE AVERAGE EXPECTED VALUES BASED UPON RATED VOLTAGE,
A36: FREQUENCY AND SINEWAVE POWER INPUT.
A37: THE DECLARED LOCKED ROTOR CURRENT HAS A TOLERANCE OF 20%.
A38: * TEMPERATURE RISE WILL BE CONSISTENT WITH INSULATION, AMBIENT AND SERVICE FACTOR AS
A39: DEFINED BY NEMA-MG-12 OR -20.
A40: ** BEARINGS ARE THE ONLY RECOMMENDED SPARE PART(S).
J42: CERTIFIED BY: | K42: Zichao Xie
J44: DATE: | K44: 45012
A59: - | B59: 6205ZZ | D59: 1 | E59: -
A60: TEFC | B60: 6206UU | D60: 1.15 | E60: A
A61: ODP | B61: 6207ZZ | E61: B
B62: 6208UU
B63: 6211ZZ
B64: 6211C3
B65: 6211ZZC3
B66: 6305UUC3
...

Sheet STCurve
A2: TOSHIBA INTERNATIONAL CORPORATION
A3: Speed Torque/Current Curve
A6: Model #: | B6: ='Performance Data Sheet'!C17 -> GP-10011492 | E6: FLAmps: | F6: ='Performance Data Sheet'!I14 & " A" -> 52 A
A7: Enclosure: | B7: ='Performance Data Sheet'!F14 -> TEFC | C7: Voltage: | D7: ='Performance Data Sheet'!F13 & " V" -> 4000 V | E7: Frame: | F7: ='Performance Data Sheet'!C14 -> 5011UZ
A8: Pole: | B8: 2 | C8: Frequency: | D8: 3 PH / 60 Hz | E8: Ins. Class: | F8: ='Performance Data Sheet'!M15 -> F
A9: HP: | B9: ='Performance Data Sheet'!C13 -> 400 | C9: Rotor Inertia: | D9: 116.8 lb-ft² | E9: Date: | F9: ='Performance Data Sheet'!K44 -> 45012
A10: FLRPM: | B10: ='Performance Data Sheet'!M14 -> 3575 | C10: Load Inertia: | D10: 315.0 lb-ft² | E10: File: | F10: RF2400
B12: Locked Rotor Amps: | C12: ='Performance Data Sheet'!D22 & " A" -> 340 A | D12: Load Type: | E12: Fan / Pump
B13: Locked Rotor Torque: | C13: ='Performance Data Sheet'!H23/100 -> 1.85 | D13: Starting at: | E13: FV (V)
B14: Breakdown Torque: | C14: 2.35 | D14: Accel. Time: | E14: 6.8 (s)
B15: Rated Torque: | C15: ='Performance Data Sheet'!H22 & " lb-ft" -> 588 lb-ft
A39: Comments: | B39: PROJECT | C39: ='Performance Data Sheet'!C10 -> 2103004.1 | E39: D.E.Curve #: | F39: =F10 -> RF2400
C43: Prepared by: | D43: ='Performance Data Sheet'!K42 -> Zichao Xie | E43: Checked by:
D53: Load
A54: 100 | B54: 0 | C54: 0.2557672 | D54: 100
A55: 99 | B55: 139.2841 | C55: 173.28055 | D55: 98
A56: 95 | B56: 235 | C56: 489.89398 | D56: 87
A57: 90 | B57: 177.80559 | C57: 562.69684 | D57: 74
A58: 84.999999 | B58: 156.69784 | C58: 583.04358 | D58: 61
A59: 80 | B59: 151.90871 | C59: 593.17407 | D59: 50
A60: 69.999999 | B60: 151.32392 | C60: 605.94244 | D60: 33
A61: 59.999999 | B61: 150.73166 | C61: 616.10248 | D61: 22
A62: 50 | B62: 150 | C62: 624.82233 | D62: 14
A63: 39.999998 | B63: 151.12655 | C63: 632.78021 | D63: 7.9999995
A64: 30.000001 | B64: 153.77378 | C64: 639.716 | D64: 5.9999995
A65: 19.999999 | B65: 158.87231 | C65: 645.55896 | D65: 8.000001
... A67: 0 | B67: 185 | C67: 653.84619 | D67: 30

Sheet Thermdam
A2: TOSHIBA INTERNATIONAL CORPORATION
A3: Thermal Limit & Acceleration Curves
A4: Design Values (For Reference Only)
A6: Model #: | B6: ='Performance Data Sheet'!C17 -> GP-10011492 | E6: FLAmps: | F6: ='Performance Data Sheet'!I14 -> 52
A7: Enclosure: | B7: ='Performance Data Sheet'!F14 -> TEFC | C7: Voltage: | D7: ='Performance Data Sheet'!F13 & " V" -> 4000 V | E7: Frame: | F7: ='Performance Data Sheet'!C14 -> 5011UZ
A8: Pole: | B8: 2 | C8: Frequency: | D8: 3 PH / 60 Hz | E8: Ins. Class: | F8: ='Performance Data Sheet'!M15 -> F
A9: HP: | B9: ='Performance Data Sheet'!C13 -> 400 | C9: Rotor Inertia: | D9: 116.8 lb-ft² | E9: Date: | F9: ='Performance Data Sheet'!K44 -> 45012
A10: FLRPM: | B10: ='Performance Data Sheet'!M14 -> 3575 | C10: Load Inertia: | D10: 315.0 lb-ft² | E10: File: | F10: RF2400
C12: ='Performance Data Sheet'!D22 & " A" -> 340 A
C13: ='Performance Data Sheet'!H23/100 -> 1.85
C15: ='Performance Data Sheet'!H22 & " lb-ft" -> 588 lb-ft
A39: Comments: | B39: PROJECT | C39: ='Performance Data Sheet'!C10 -> 2103004.1 | E39: D.E.Curve #: | F39: =F10 -> RF2400
C43: Prepared by: | D43: ='Performance Data Sheet'!K42 -> Zichao Xie | E43: Checked by:
F50: =5252.1*B50/D53 -> #DIV/0!
D66: =D65/D64 -> #DIV/0!
A67: Current (%) | B67: Cold | C67: Hot | E67: CURRENT (%) | F67: Accel. Time
A68: 653.84615 | B68: 17 | C68: 7 | E68: =A68 -> 653.84615 | F68: 0.0001
A69: =FLOOR(A68,100) -> 600 | B69: =((A68/A69)^2)*B68 -> 20.188199 | C69: =((A68/A69)^2)*C68 -> 8.3127876 | E69: 652.11538 | F69: 0.55900002
A70: =A69-100 -> 500 | B70: =((A68/A70)^2)*B68 -> 29.071006 | C70: =((A68/A70)^2)*C68 -> 11.970414 | E70: 647.88462 | F70: 1.125
A71: =A70-100 -> 400 | B71: =((A68/A71)^2)*B68 -> 45.423447 | C71: =((A68/A71)^2)*C68 -> 18.703772 | E71: 642.69231 | F71: 1.702
A72: =A71-100 -> 300 | B72: =((A68/A72)^2)*B68 -> 80.752794 | E72: 636.15385 | F72: 2.2939999
A73: =A72-100 -> 200 | B73: =((A68/A73)^2)*B68 -> 181.69379 | E73: 628.84615 | F73: 2.911
A74: 235 | B74: =((A68/A74)^2)*B68 -> 131.60256 | C74: =((A68/A74)^2)*C68 -> 54.18929 | E74: 620.38462 | F74: 3.5610001
A75: 180 | B75: =((A68/A75)^2)*B69 -> 266.38128 | C75: =((A68/A75)^2)*C68 -> 92.364307 | E75: 610.96154 | F75: 4.2579999
A76: 145 | B76: =((A68/A76)^2)*B68 -> 345.67189 | C76: =((A68/A76)^2)*C68 -> 142.33548 | E76: 599.61538 | F76: 5.04
A77: 125 | C77: =CEILING(C76*2,100) -> 300 | E77: 588.07692 | F77: 5.4759998
A78: 125 | C78: =2*C77 -> 600 | E78: 572.88462 | F78: 5.9070001
A79: 125 | C79: 10000 | E79: 526.34615 | F79: 6.2490001
E80: =A74 -> 235 | F80: 6.6129999
E81: =A77 -> 125 | F81: 6.8129997

Sheet Performance 4000V
A2: TOSHIBA INTERNATIONAL CORPORATION
A3: Performance Curve
A4: Design Values (For Reference Only)
A6: Model #: | B6: ='Performance Data Sheet'!C17 -> GP-10011492 | E6: FLAmps: | F6: 52 A
A7: Enclosure: | B7: ='Performance Data Sheet'!F14 -> TEFC | C7: Voltage: | D7: 4000 V | E7: Frame: | F7: ='Performance Data Sheet'!C14 -> 5011UZ
A8: Pole: | B8: 2 | C8: Frequency: | D8: 3 PH / 60 Hz | E8: Ins. Class: | F8: ='Performance Data Sheet'!M15 -> F
A9: HP: | B9: ='Performance Data Sheet'!C13 -> 400 | C9: Rotor Inertia: | D9: 116.8 lb-ft² | E9: Date: | F9: ='Performance Data Sheet'!K44 -> 45012
A10: FLRPM: | B10: ='Performance Data Sheet'!M14 -> 3575 | C10: Load Inertia: | D10: 315.0 lb-ft² | E10: File: | F10: RF2400
B12: Locked Rotor Amps: | C12: 340 A | D12: Load Type: | E12: Fan / Pump
B13: Locked Rotor Torque: | C13: ='Performance Data Sheet'!H23/100 -> 1.85 | D13: Starting at: | E13: FV (V)
B14: Breakdown Torque: | C14: 2.35 | D14: Accel. Time: | E14: 6.8 (s)
B15: Rated Torque: | C15: ='Performance Data Sheet'!H22 & " lb-ft" -> 588 lb-ft
A39: Comments: | B39: PROJECT | C39: ='Performance Data Sheet'!C10 -> 2103004.1 | E39: D.E.Curve #: | F39: =F10 -> RF2400
C43: Prepared by: | D43: ='Performance Data Sheet'!K42 -> Zichao Xie | E43: Checked by:
A53: Load | B53: Efficiency | C53: PF | D53: Amps | E53: RPM | F53: Input Watts
A54: 0 | D54: 13.656333 | E54: 100 | F54: =12246/8000 -> 1.53075
A55: 25 | B55: 84.950012 | C55: 62.719051 | D55: 20.198917 | E55: 71.602259 | F55: 10.970981
A56: 50 | B56: 91.210098 | C56: 80.183479 | D56: 29.430199 | E56: 60.355559 | F56: 20.436005
A57: 75 | B57: 93.333199 | C57: 85.758766 | D57: 40.336445 | E57: 48.855819 | F57: 29.956705
A58: 100 | B58: 94.292061 | C58: 87.700119 | D58: 52.056599 | E58: 37.04591 | F58: 39.536104
A59: 125 | B59: 94.753044 | C59: 88.165855 | D59: 64.412109 | E59: 25.029435 | F59: 49.179696

Sheet Performance 2300v
A2: TOSHIBA INTERNATIONAL CORPORATION
A3: Performance Curve
A4: Design Values (For Reference Only)
A6: Model #: | B6: ='Performance Data Sheet'!C17 -> GP-10011492 | E6: FLAmps: | F6: 90 A
A7: Enclosure: | B7: ='Performance Data Sheet'!F14 -> TEFC | C7: Voltage: | D7: 2300 V | E7: Frame: | F7: ='Performance Data Sheet'!C14 -> 5011UZ
A8: Pole: | B8: 2 | C8: Frequency: | D8: 3 PH / 60 Hz | E8: Ins. Class: | F8: ='Performance Data Sheet'!M15 -> F
A9: HP: | B9: ='Performance Data Sheet'!C13 -> 400 | C9: Rotor Inertia: | D9: 116.8 lb-ft² | E9: Date: | F9: ='Performance Data Sheet'!K44 -> 45012
A10: FLRPM: | B10: ='Performance Data Sheet'!M14 -> 3575 | C10: Load Inertia: | D10: 315.0 lb-ft² | E10: File: | F10: RF2400
B12: Locked Rotor Amps: | C12: 589 A | D12: Load Type: | E12: Fan / Pump
B13: Locked Rotor Torque: | C13: ='Performance Data Sheet'!H23/100 -> 1.85 | D13: Starting at: | E13: FV (V)
B14: Breakdown Torque: | C14: 2.35 | D14: Accel. Time: | E14: 6.8 (s)
B15: Rated Torque: | C15: ='Performance Data Sheet'!H22 & " lb-ft" -> 588 lb-ft
A39: Comments: | B39: PROJECT | C39: ='Performance Data Sheet'!C10 -> 2103004.1 | E39: D.E.Curve #: | F39: =F10 -> RF2400
C43: Prepared by: | D43: ='Performance Data Sheet'!K42 -> Zichao Xie | E43: Checked by:
A53: Load | B53: Efficiency | C53: PF | D53: Amps | E53: RPM | F53: Input Watts
A54: 0 | D54: 23.653462 | E54: 100 | F54: =12246/8000 -> 1.53075
A55: 25 | B55: 84.950012 | C55: 62.719051 | D55: 34.985551 | E55: 71.602259 | F55: 10.970981
A56: 50 | B56: 91.210098 | C56: 80.183479 | D56: 50.974599 | E56: 60.355559 | F56: 20.436005
A57: 75 | B57: 93.333199 | C57: 85.758766 | D57: 69.864772 | E57: 48.855819 | F57: 29.956705
A58: 100 | B58: 94.292061 | C58: 87.700119 | D58: 90 | E58: 37.04591 | F58: 39.536104
A59: 125 | B59: 94.753044 | C59: 88.165855 | D59: 111.56505 | E59: 25.029435 | F59: 49.179696

Sheet Rev. 1
A1: TOSHIBA INTERNATIONAL CORPORATION | J1: INDEX | L1: MPCF-1109
A2: Industrial Division / Houston Motor Plant | J2: SHEET NO. | L2: 1 of 1
J3: ISSUED | L3: 38309
A4: EQUIVALENT CIRCUIT DATA | J4: SUPERSEDES | L4: NEW
J5: REVISION | L5: REV. 0
J6: WRITTEN BY | L6: MDC
A7: All Values are Presented in Ohms/Phase, Equivalent Wye Connection. | J7: APPROVED BY | L7: Paul Anderson
B9: CUSTOMER: | C9: DYKMAN ELECTRICAL INC
B10: TIC SR No.: | C10: 2103004.1
A12: MOTOR NAMEPLATE DATA
B13: H.P.: | C13: 400 | E13: VOLTS: | F13: 4000 | H13: 3 PH / | I13: 60 Hz | L13: S. RPM: | M13: 3600
B14: FRAME: | C14: 5011UZ | E14: ENCL: | F14: TEFC | H14: FLAMPS: | I14: 52 | L14: FLRPM: | M14: 3575
B15: FORM: | C15: FCKW | E15: S.F.: | F15: 1.15 | H15: NEMA DESIGN: | I15: B | L15: INSUL CLASS: | M15: F
B16: TYPE: | C16: TIKK | E16: AMB.: | F16: 40°C | H16: CODE: | I16: G | L16: DUTY: | M16: Cont.
B17: MODEL No.: | C17: GP-10011492 | H17: kW: | I17: -
B18: NOM. EFF.: | C18: - | E18: MIN. EFF.: | F18: - | H18: P.F.: | I18: -
A23: Primary Resistance (R1) : | F23: 0.310
A24: Secondary Resistance (R2) : | F24: 0.266
A25: Starting Resistance (R3) : | F25: 1.70
A27: Primary Reactance (X1) : | F27: 3.31
A28: Secondary Reactance (X2) : | F28: 6.96
A29: Starting Reactance (X3) : | F29: 4.57
A31: Magnetizing Reactance (Xm) : | F31: 181.8
A33: Transient Reactance : | F33: 10.1
A34: Sub Transient Reactance : | F34: 6.03
A35: Short Circuit Time Constant : | F35: 0.102
A36: Sub Transient Time Constant : | F36: 0.011
A37: Open Circuit Time Constant : | F37: 1.88
I42: CERTIFIED BY: | J42: =[1]Thermdam!D43 -> JERRY R
I44: DATE: | J44: 45012

Sheet PERFORMANCE SPEC
A1: TOSHIBA INTERNATIONAL CORPORATION | J1: INDEX | L1: MPCF-1082
A2: Industrial Division / Houston Motor Plant | J2: SHEET NO. | L2: 1 of 1
J3: ISSUED | L3: 2/14/02
J4: SUPERSEDES | L4: NEW
J5: REVISION | L5: 0
A6: SQUIRREL CAGE INDUCTION MOTOR | J6: WRITTEN BY | L6: M. CAMPBELL
A7: API 541 PERFORMANCE SPECIFICATIONS | J7: APPROVED BY | L7: P.A.A
B9: CUSTOMER: | C9: DYKMAN ELECTRICAL INC
B10: TIC SR No.: | C10: 2103004.1
A12: MOTOR NAMEPLATE DATA
B13: H.P.: | C13: 400 | E13: VOLTS: | F13: 4000 | H13: 3 PH / | I13: 60 Hz | L13: S. RPM: | M13: 3600
B14: FRAME: | C14: 5011UZ | E14: ENCL: | F14: TEFC | H14: FLAMPS: | I14: 52 | L14: FLRPM: | M14: 3575
B15: FORM: | C15: FCKW | E15: S.F.: | F15: 1.15 | H15: NEMA DESIGN: | I15: B | L15: INSUL CLASS: | M15: F
B16: TYPE: | C16: TIKK | E16: AMB.: | F16: 40°C | H16: CODE: | I16: G | L16: DUTY: | M16: Cont.
B17: MODEL No.: | C17: GP-10011492 | H17: kW: | I17: -
B18: NOM. EFF.: | C18: - | E18: MIN. EFF.: | F18: - | H18: P.F.: | I18: -
A20: LOCKED ROTOR DATA
D21: AMPS AT RATED VOLTAGE: | E21: 340 | I21: POWER FACTOR: | J21: 26.8
D22: AMPS AT 80% VOLTAGE: | E22: 272
A24: TORQUE VALUES | H24: CURVE NUMBERS
E25: FULL LOAD (LB.FT): | F25: 588 | J25: SPEED-TORQUE CURVE: | K25: RF2400
E26: LOCKED ROTOR TORQUE (% OF FLT): | F26: 185 | J26: SPEED-CURRENT CURVE: | K26: RF2400
E27: PULL UP TORQUE (% OF FLT): | F27: 150 | J27: ACCELERATION CURVE: | K27: RF2400
E28: BREAKDOWN TORQUE (% OF FLT): | F28: 235
A30: LOCKED ROTOR WITHSTAND TIMES
A31: COLD CONDITION | H31: HOT CONDITION
C32: 100% VOLTAGE: | D32: 17 | J32: 100% VOLTAGE: | K32: 7
C33: 90% VOLTAGE: | D33: 21 | J33: 90% VOLTAGE: | K33: 9
C34: 80% VOLTAGE: | D34: 27 | J34: 80% VOLTAGE: | K34: 11
C35: 70% VOLTAGE: | D35: 35 | J35: 70% VOLTAGE: | K35: 14
A37: DESIGN DATA
C38: MOTOR ROTOR wk2 (LB.FT2): | D38: 116.8 | J38: NO LOAD CURRENT: | K38: 13
C39: AIR GAP: | D39: 2.5 | J39: ACCELERATION TIME: | K39: 7/11
D40: LOAD CHARACTERISTICS
D41: LOAD | G41: 1/2 | H41: 3/4 | I41: FULL | J41: 1.15
D42: AMPS (A) | G42: 29.4 | H42: 40.3 | I42: 52
D43: EFFICIENCY (%) | G43: 91.2 | H43: 93.4 | I43: 94.3
D44: POWER FACTOR (%) | G44: 80.2 | H44: 85.8 | I44: 87.4
D45: GUARENTEED EFFICIENCY (%) | G45: - | H45: - | I45: - | J45: -
A46: EFFICIENCY TO BE DETERMINED BY IEEE 112, METHOD B
...
