Workbook
Name Print_Area_MI: 'Performance Data Sheet'!$A$10:$N$42

Sheet DesignSheet
A1: TOSHIBA INTERNATIONAL CORPORATION | I1: Calc. Code: | J1: 2-2-2-0-1-2
A2: 3-PHASE SQUIRREL CAGE INDUCTION MOTOR DESIGN SHEET | J2: B.L.-1 P.F.-1
A3: File: | B3: N:\DESPRO\RAT FILES\CS2600.rat | G3: Date: | H3: 43945 | I3: Time: | J3: 0.47903935
A4: Pole | B4: HP | C4: RPM | D4: Form | E4: Voltage | F4: Frequency | G4: Temperature | H4: FLSpeed | I4: FLSlip | J4: Frame
A5: 2 | B5: 600.00001 | C5: 3600 | D5: FCW4 | E5: 4000 | F5: 60 | G5: 105 | H5: 3577.6 / 3575.6 | I5: 0.0062 / 0.0068 | J5: 5811USS
A6: Core Data | D6: Winding Data | H6: Constant Data
B7: Primary | C7: Secondary | F7: Bar | G7: End Ring | H7: St. Slot Pitch | I7: 25.431919 | J7: LR Test Data
A8: Air Gap | B8: 2.9000001 | H8: Rt. Slot Pitch | I8: 30.879982 | J8: ES
A9: Space Fac. | B9: 0.93000001 | D9: Pitch | E9: 1 ~ 14 | F9: Cross Section Area | H9: Mean Value | I9: 28.15595 | J9: 601.53367
A10: Core Length | B10: 600 | C10: 600 | F10: UB: 304.0 | G10: UER: 1958.0 | H10: Eff.T.W.St. | I10: 18.247458 | J10: WS
A11: OD | B11: 610 | C11: 334.2 | D11: Coil Pitch | E11: 0.61898571 | H11: Eff.T.W.Rt. | I11: 30.408333 | J11: 17659.009
A12: ID | B12: 340 | C12: 155 | D12: Slot Fill | E12: - | F12: EBL: 70.5 | G12: ERD1: 246.0 | H12: St.Carter Fac. | I12: 1.3937239 | J12: IS
A13: Core Depth | B13: 70 | C13: 53.19 | D13: Con./Slot | E13: 32 | G13: ERT: 44.50 | H13: Rt.Carter Fac. | I13: 1.0155105 | J13: 71.808922
A14: Eff.Core L. | B14: 558 | C14: 558 | D14: Wire Size 1 | E14: (.057"x.204")x2 | G14: ERH: 44.00 | H14: Carter Factor | I14: 1.4153413 | J14: Volts / Turn
A15: Slot Data | D15: Wire Size 2 | E15: - | H15: Short. Factor | I15: 0.82618353 | J15: 20.620257
A16: Number | B16: 42 | C16: 34 | D16: // Circuits | E16: 2 | H16: Distrib. Factor | I16: 0.95564622 | J16: AC
A17: Kind | B17: Open | C17: Trapeze | D17: Connection | E17: Wye | H17: Wind. Factor | I17: 0.78953916 | J17: 451.77194
A18: Skew | B18: - | C18: 0 | D18: MCL | E18: 1245 | F18: 785.5 | H18: Reactance | I18: (Coeff.: 0.0875)
A19: Depth | B19: 65 | C19: 36.41 | D19: No.Cond./Ph. | E19: 224 | I19: Running | J19: Start
A20: Width | B20: 14.00 - 14.00 | D20: Res. (20°C) | E20: 0.16885033 | H20: Stator Slot | I20: 13.29081 | J20: 13.29081
A21: Opening | B21: 14 | C21: 3 | D21: (105°C) | E21: 0.22524435 | F21: 0.16750412 | G21: 0.046836926 | H21: Rotor Slot | I21: 16.433411 | J21: 14.468875
A22: Tip Depth | B22: 2.8299999 | C22: 3 | D22: Material | E22: CU | F22: Special | G22: Special | H22: Zigzag | I22: 6.767972 | J22: 6.3993587
A23: T.Min.Wid. | B23: 11.431919 | C23: 10.031435 | D23: Spec.Resist. | E23: 1.742 | F23: 1.724 | G23: 1.724 | H23: Coil End | I23: 14.072531 | J23: Skew R.: 0.00
A24: Low. R. | B24: 0 | C24: 0.80000001 | D24: Spec.Gravity | E24: 8.8900003 | F24: 8.8900003 | G24: 8.8900003 | H24: Belt Leakage | I24: 5.7711436 | J24: 5.4568221
A25: Up. R. | B25: - | C25: 4.7199998 | D25: Weight (kg) | H25: Total Resist. | I25: 0.43958539 | J25: 1.1415324
A26: Wedge Dep. | B26: 1.20 - 2.40 | C26: Normal | D26: Wire 1 | E26: 213.99519 | F26: 76.266246 | G26: 32.240867 | H26: Total React. | I26: 4.931643 | J26: 4.6998835
A27: Duct | B27: - | C27: - | D27: Wire 2 | E27: - | F27: - | G27: - | H27: Impedance | I27: 4.9511957 | J27: 4.8365273
A28: Effective Depth (S=1) | D28: Magnetic Circuit Data | I28: Core Loss Data
B29: Res.= | C29: 33.371402 | E29: Length | F29: Section | G29: Density | H29: AT | I29: Volume | J29: Loss | M29: =RIGHT(F$41,SEARCH("/",F$41,1)-1) -> 3569.9 | N29: 125RPM
B30: Reac.= | C30: 33.398959 | D30: Primary Core | E30: 47.909247 | F30: 781.2 | G30: 12.549428 | H30: 220.38265 | I30: 66263.673 | J30: 3396.3326 | M30: =RIGHT(E$41,SEARCH("/",E$41,1)-1) -> 3575.6 | N30: 100RPM
A31: Excitation Data | D31: Tooth | E31: 6.5 | F31: 1339.5923 | G31: 7.318356 | H31: 5.8841836 | I31: 17414.7 | J31: 372.58885 | M31: =RIGHT(D$41,SEARCH("/",D$41,1)-1) -> 3581.2 | N31: 75RPM
A32: Excit.Amps | B32: 13.847 / 13.987 | D32: Second.Core | E32: 20.52872 | F32: 881.9004 | G32: 11.116463 | H32: 67.484909 | I32: Total | J32: 3768.9215 | M32: =RIGHT(C$41,SEARCH("/",C$41,1)-1) -> 3586.7 | N32: 50RPM
A33: Core Loss | B33: 0.996 / 1.006 | C33: Flux / Pole | D33: Tooth | E33: 3.641 | F33: 951.58193 | G33: 10.302437 | H33: 9.5575664 | I33: C.L.C. | J33: 1.50 / 0.70 | M33: =RIGHT(B$41,SEARCH("/",B$41,1)-1) -> 3592.1 | N33: 25RPM
A34: NoLoad | B34: 13.88 / 14.02 | C34: 9.8036132 | D34: Air Gap | E34: 0.29000001 | F34: 2264.063 | G34: 4.3300973 | H34: 999.27765 | I34: S.F.C. | J34: 6.0500002
A35: Load Characteristics | D35: Temp. Rise @ 100%: | E35: 76 / 76 | G35: No Load Loss | H35: 15355.7 / 10289.6 | I35: W.Loss | J35: 5653.4 / 2624.5
A36: Load (%) | B36: 25 | C36: 50 | D36: 75 | E36: 100 | F36: 125 | G36: Primary Loss | H36: 3484.4 / 3573.8 | I36: S.Loss | J36: 1255.2 / 582.7
A37: Current (A) | B37: 23.96 / 24.56 | C37: 38.59 / 39.56 | D37: 54.84 / 56.22 | E37: 71.81 / 73.62 | F37: 89.37 / 91.62 | G37: Second. Loss | H37: 2892.8 / 3196.8 | I37: Total C.Loss | J37: 6908.5 / 3207.2
A38: Efficiency | B38: 0.876 / 0.871 | C38: 0.930 / 0.924 | D38: 0.947 / 0.941 | E38: 0.954 / 0.948 | F38: 0.957 / 0.951 | G38: Frict.& Wind. | H38: 8350.0 / 7057.6 | I38: Stray Loss | J38: 7353.7144 | L38: =LEFT(E38,SEARCH("/",E38,1)-1) -> 0.954 | M38: =RIGHT(E38,SEARCH("/",E38,1)-1) -> 0.948 | N38: =M38/L38 -> 0.99371069 | O38: Eff.
A39: P.F. | B39: 0.770 / 0.755 | C39: 0.900 / 0.884 | D39: 0.933 / 0.916 | E39: 0.943 / 0.925 | F39: 0.944 / 0.926 | G39: Starting Data | I39: Slip | J39: PF | L39: =LEFT(E39,SEARCH("/",E39,1)-1) -> 0.943 | M39: =RIGHT(E39,SEARCH("/",E39,1)-1) -> 0.925 | N39: =M39/L39 -> 0.98091198 | O39: PF.
A40: Slip | B40: 0.0016 / 0.0022 | C40: 0.0031 / 0.0037 | D40: 0.0047 / 0.0052 | E40: 0.0062 / 0.0068 | F40: 0.0078 / 0.0084 | G40: LRA | H40: 477.5 / 498.0 | L40: =LEFT(E37,SEARCH("/",E37,1)-1) -> 71.81 | M40: 74 | N40: =M40/L40 -> 1.0304971 | O40: Current
...

Sheet Data Sheet
A1: TOSHIBA INTERNATIONAL CORPORATION
A2: INDUCTION MOTOR DATA SHEET
A3: File: | B3: CS2600 | I3: HRW / Model Number: | J3: 6003FTQL11F-C | M3: 6003FTQL11F-C
A4: Type: TIKE - Form: FCW4 - 2 Pole - 600 HP -2300 / 4000 V - 60 Hz - 5811USS - Class F | Q4: Motor Type Selection | T4: Electrical Steel Table
A5: Motor Parameters | F5: PERFORMANCE | J5: DESIGN | K5: TEST | Q5: EPACT | T5: M22 - 26Ga.
A6: Material | D6: M36 - 26Ga. | F6: NL & Impedance Test | Q6: EQP-III | T6: M36 - 26Ga.
A7: Air Gap | D7: 2.9000001 | F7: No load amps | J7: 14 | K7: - | Q7: Exp.Prf. | T7: NCB1 - 26Ga.
A8: Stack length | D8: 600 | F8: No load watts | J8: 10290 | K8: - | Q8: Exp.Prf.-EQPIII | T8: M43 - 26Ga.
A9: Number of turns per coil | D9: 16 | F9: Impedance amps | H9: 3 | I9: f | J9: 137 | K9: - | Q9: Prem. Eff. | T9: M45 - 26Ga.
A10: Wire 1 (size & number) | D10: (.057"x.204")x2 | F10: Impedance volts | H10: 3 | I10: f | J10: 1150 | K10: - | Q10: Standard Eff. | T10: M54 - 26Ga.
A11: Wire 2 (size & number) | D11: - | F11: Impedance watts | H11: 3 | I11: f | J11: 17659 | K11: - | Q11: OWP | T11: TIPA Lam
A12: Slot fill - circle/square method (%) | D12: - | F12: Temperature Rise (°C) | Q12: Dry Kiln
A13: Connection | D13: 2x Delta / 2 x Wye | G13: Winding | I13: 80/115 | J13: 76 / 100 | K13: -
A14: MCL | D14: 1245 | G14: Frame | J14: - | K14: -
A15: Allowance for ins. depth | D15: 9.4404001 | G15: Bearing PS/OS | J15: - | K15: -
A16: Allowance for ins. width | D16: 3.2368 | G16: End Ring | J16: - | K16: -
A17: Slot/Wire arrangement | D17: 32 x 2 | F17: Nameplate Data
A18: Effective cross section for coil | D18: - | H18: FLC (A) | J18: 128 / 74 | M18: =J18*6.5 -> #VALUE!
A19: Coil grouping | D19: - | H19: RPM | J19: 3575
A20: Coil pitch (slot number) | D20: 1 ~ 14 | H20: CODE | J20: G
A21: Method of coil connection | D21: - | H21: S. F. | J21: 1.15 | Q21: Method of Connection
A22: Resistance per phase @ 20 °C | D22: 0.1689 | H22: DESIGN | J22: - | Q22: Skip
A23: Coil Weight | B23: Wire1 | D23: 470.8 | H23: Nom.Eff. (%): | J23: - | Q23: Adjacent
A24: (lbs.) | B24: Wire2 | D24: - | H24: Min.Eff. (%): | J24: - | Q24: -
A25: Current Densities (A/cm2) | E25: Bar / ER | H25: P.F. (%): | J25: -
A26: FL / LR | D26: 256 / 1723 | E26: 353 / 297
A27: Stator Slot Shape (Reference) | F27: Performance
H28: LRC (A) | I28: - | J28: 859 / 498 | K28: - | M28: =(J28/J18)*100 -> #VALUE!
H29: LRT (%) | I29: 60 | J29: 97 | K29: -
H30: BDT (%) | I30: 175 | J30: 272 | K30: -
H31: SLIP (%) | J31: 0.68 | K31: -
G32: IEEE-B | H32: Eff. (%) | J32: 94.8 | K32: -
A33: Rotor Slot Shape (Reference) | H33: PF (%) | J33: 92.5 | K33: -
F34: Losses (Watts) | H34: Primary | J34: 3574 | K34: -
H35: Secondary | J35: 3197 | K35: -
H36: Core | J36: 3207 | K36: -
H37: F & W | J37: 7058 | K37: -
H38: Stray | J38: 7354 | K38: -
A39: End Ring (Reference) | F39: Note | G39: Outer Fan OD: 360T, 140-4646-02
F40: LINK: | G40: CS2600.rat with CS2600_Corr from lab 9725 (H402088)_LRA 3065.dat | Q40: FOR 85 dBA
...

Sheet LoginSheet
J1: P | K1: T | L1: L | M1: T
B2: PROJECT HISTORY | J2: E | K2: D | L2: I | M2: Y | N2: H
J3: R | L3: M | M3: P
J4: F | L4: I | M4: E
K5: C | L5: T | N5: I
J6: D | K6: U | M6: T | N6: N
J7: A | K7: R | L7: R | M7: E | N7: S
I8: S | J8: T | K8: V | L8: E | M8: S | N8: U
B9: DATE | C9: PROJECT | D9: SMART NUMBER | E9: QTY | F9: CUSTOMER | G9: REMARKS | H9: LIMIT CODE | I9: F | J9: A | K9: E | L9: V | M9: T | N9: L
B53: REVISION HISTORY
B54: REV | C54: REMARKS | I54: DATE | L54: INIT

Sheet Performance Data Sheet
A1: TOSHIBA INTERNATIONAL CORPORATION | J1: INDEX | L1: MPCF-1033
A2: Industrial Division / Houston Motor Plant | J2: SHEET NO. | L2: 1 of 1
J3: ISSUED | L3: 7/31/13
J4: SUPERSEDES | L4: 11/8/96
J5: REVISION | L5: 2
A6: SQUIRREL CAGE INDUCTION MOTOR | J6: WRITTEN BY | L6: MDC
A7: PERFORMANCE SPECIFICATIONS | J7: APPROVED BY | L7: PAA
B9: CUSTOMER: | C9: SABRE SYSTEM
B10: TIC SR No.: | C10: 2174962.1
A12: MOTOR NAMEPLATE DATA
B13: H.P.: | C13: 600 | E13: VOLTS: | F13: 4000 | H13: 3 PH / | I13: 60 Hz | L13: S. RPM: | M13: 3600
B14: FRAME: | C14: 5811USS | E14: ENCL: | F14: TEFC | H14: FLAMPS: | I14: 74 | L14: FLRPM: | M14: 3575
B15: FORM: | C15: FCW4 | E15: S.F.: | F15: 1.0 | H15: NEMA DESIGN: | I15: B | L15: INSUL CLASS: | M15: F
B16: TYPE: | C16: TIKE | E16: AMB.: | F16: 40°C | H16: CODE: | I16: G | L16: DUTY: | M16: Cont.
B17: MODEL No.: | C17: GP-10032399 | H17: kW: | I17: -
B18: NOM. EFF.: | C18: - | E18: MIN. EFF.: | F18: - | H18: P.F.: | I18: -
A21: AMPERAGE | E21: TORQUES | I21: **BEARINGS:
A22: LOCKED ROTOR: | D22: 498 | G22: FULL LOAD (lb-ft.): | H22: 881 | K22: DRIVE END:
G23: LOCKED ROTOR (%): | H23: 95 | K23: OPPOSITE DRIVE END:
G24: BREAK DOWN (%): | H24: 270
A28: EFFICIENCY | H28: POWER FACTOR
C29: FULL LOAD: | D29: 94.8 | J29: FULL LOAD: | K29: 92.5
C30: 3/4 LOAD: | D30: 94.1 | J30: 3/4 LOAD: | K30: 91.5
C31: 1/2 LOAD: | D31: 92.4 | J31: 1/2 LOAD: | K31: 88.3
A35: ALL CHARACTERISTICS ARE AVERAGE EXPECTED VALUES BASED UPON RATED VOLTAGE,
A36: FREQUENCY AND SINEWAVE POWER INPUT.
A37: THE DECLARED LOCKED ROTOR CURRENT HAS A TOLERANCE OF 20%
A38: * TEMPERATURE RISE WILL BE CONSISTENT WITH INSULATION, AMBIENT AND SERVICE FACTOR AS
A39: DEFINED BY NEMA-MG-12 OR -20
A40: ** BEARINGS ARE THE ONLY RECOMMENDED SPARE PART(S).
J42: CERTIFIED BY: | K42: JERRY R
J44: DATE: | K44: 43945
A59: - | B59: 6205ZZ | D59: 1 | E59: -
A60: TEFC | B60: 6206UU | D60: 1.15 | E60: A
A61: ODP | B61: 6207ZZ | E61: B
B62: 6208UU
B63: 6211ZZ
B64: 6211C3
B65: 6211ZZC3
B66: 6305UUC3
...

Sheet STCurve
A2: TOSHIBA INTERNATIONAL CORPORATION
A3: Speed Torque/Current Curve
A6: Model #: | B6: ='Performance Data Sheet'!C17 -> GP-10032399 | E6: FLAmps: | F6: ='Performance Data Sheet'!I14& " A" -> 74 A
A7: Enclosure: | B7: ='Performance Data Sheet'!F14 -> TEFC | C7: Voltage: | D7: ='Performance Data Sheet'!F13 & " V" -> 4000 V | E7: Frame: | F7: ='Performance Data Sheet'!C14 -> 5811USS
A8: Pole: | B8: 2 | C8: Frequency: | D8: 3 PH / 60 Hz | E8: Ins. Class: | F8: F
A9: HP: | B9: 600 | C9: Rotor Inertia: | D9: 177.6 lb-ft² | E9: Date: | F9: ='Performance Data Sheet'!K44 -> 43945
A10: FLRPM: | B10: 3575 | C10: Load Inertia: | D10: N/A | E10: File: | F10: CS2600
B12: Locked Rotor Amps: | C12: ='Performance Data Sheet'!D22 & "A" -> 498A | D12: Load Type: | E12: N/A
B13: Locked Rotor Torque: | C13: 0.95 | D13: Starting at: | E13: N/A
B14: Breakdown Torque: | C14: 2.7 | D14: Accel. Time: | E14: N/A
B15: Rated Torque: | C15: 881 lb-ft
A39: Comments: | B39: PROJECT | C39: ='Performance Data Sheet'!C10 -> 2174962.1 | E39: D.E.Curve #: | F39: =F10 -> CS2600
C43: Prepared by: | D43: ='Performance Data Sheet'!K42 -> JERRY R | E43: Checked by:
D53: Load
A54: 100 | B54: 0 | C54: 0.18759969 | D54: 100
A55: 99.2 | B55: 120.81393 | C55: 149.72696 | D55: 98.400002
A56: 96 | B56: 270 | C56: 485.60083 | D56: 89.75
A57: 90.857143 | B57: 178.7277 | C57: 589.1134 | D57: 76.228569
A58: 85.714285 | B58: 133.81423 | C58: 618.08624 | D58: 62.85714
A59: 80.571428 | B59: 113.91774 | C59: 630.0282 | D59: 51.257141
A60: 70.285714 | B60: 100.68842 | C60: 640.99036 | D60: 33.485714
A61: 59.999999 | B61: 95 | C61: 647.72217 | D61: 22
A62: 50 | B62: 95.093442 | C62: 653.3891 | D62: 14
A63: 39.999998 | B63: 95.181514 | C63: 658.41296 | D63: 7.9999995
A64: 30.000001 | B64: 95.242875 | C64: 662.83301 | D64: 5.9999995
A65: 19.999999 | B65: 95.326992 | C65: 666.68677 | D65: 8.000001
... A67: 0 | B67: 95 | C67: 672.97296 | D67: 30

Sheet Thermdam
A2: TOSHIBA INTERNATIONAL CORPORATION
A3: Thermal Limit & Acceleration Curves
A4: Design Values (For Reference Only)
A6: Model #: | B6: ='Performance Data Sheet'!C17 -> GP-10032399 | E6: FLAmps: | F6: ='Performance Data Sheet'!I14& " A" -> 74 A
A7: Enclosure: | B7: ='Performance Data Sheet'!F14 -> TEFC | C7: Voltage: | D7: ='Performance Data Sheet'!F13 & " V" -> 4000 V | E7: Frame: | F7: ='Performance Data Sheet'!C14 -> 5811USS
A8: Pole: | B8: 2 | C8: Frequency: | D8: 3 PH / 60 Hz | E8: Ins. Class: | F8: F
A9: HP: | B9: 600 | C9: Rotor Inertia: | D9: 177.6 lb-ft² | E9: Date: | F9: ='Performance Data Sheet'!K44 -> 43945
A10: FLRPM: | B10: 3575 | C10: Load Inertia: | D10: N/A | E10: File: | F10: CS2600
A39: Comments: | B39: PROJECT | C39: ='Performance Data Sheet'!C10 -> 2174962.1 | E39: D.E.Curve #: | F39: =F10 -> CS2600
C43: Prepared by: | D43: ='Performance Data Sheet'!K42 -> JERRY R | E43: Checked by:
F50: =5252.1*B50/D53 -> #DIV/0!
D66: =D65/D64 -> #DIV/0!
A67: Current (%) | B67: Cold | C67: Hot | E67: CURRENT (%) | F67: Accel. Time
A68: 672.97297 | B68: 35 | C68: 15 | E68: =A68 -> 672.97297 | F68: 0.0001
A69: 625.98668 | B69: =((A68/A69)^2)*B68 -> 40.451358 | C69: =((A68/A69)^2)*C68 -> 17.336296 | E69: 671.48649 | F69: 1.1339999
A70: 578.98629 | B70: =((A68/A70)^2)*B68 -> 47.285363 | C70: =((A68/A70)^2)*C68 -> 20.265156 | E70: 668.37838 | F70: 2.1159999
A71: 532 | B71: =((A68/A71)^2)*B68 -> 56.006705 | C71: =((A68/A71)^2)*C68 -> 24.002874 | E71: 664.72973 | F71: 3.049
A72: =A71-100 -> 432 | B72: =((A68/A72)^2)*B68 -> 84.936781 | E72: 660.67568 | F72: 3.983
A73: =A72-100 -> 332 | B73: =((A68/A73)^2)*B68 -> 143.80935 | E73: 655.94595 | F73: 4.9629998
A74: 270 | B74: =((A68/A74)^2)*B68 -> 217.43816 | C74: =((A68/A74)^2)*C68 -> 93.187782 | E74: 650.54054 | F74: 6.033
A75: 180 | B75: =((A68/A75)^2)*B69 -> 565.43585 | C75: =((A68/A75)^2)*C68 -> 209.67251 | E75: 644.32432 | F75: 7.2420001
A76: 145 | B76: =((A68/A76)^2)*B68 -> 753.92351 | C76: =((A68/A76)^2)*C68 -> 323.11008 | E76: 635.54054 | F76: 8.5480003
A77: 125 | C77: =CEILING(C76*2,100) -> 700 | E77: 624.05405 | F77: 9.1820002
A78: 125 | C78: =2*C77 -> 1400 | E78: 603.64865 | F78: 9.6710005
A79: 125 | C79: 10000 | E79: 537.2973 | F79: 9.9710007
E80: 317.7027 | F80: 10.231001
E81: 0 | F81: 10.362

Sheet Performance 4000V
A2: TOSHIBA INTERNATIONAL CORPORATION
A3: Performance Curve
A4: Design Values (For Reference Only)
A6: Model #: | B6: ='Performance Data Sheet'!C17 -> GP-10032399 | E6: FLAmps: | F6: ='Performance Data Sheet'!I14 & " A" -> 74 A
A7: Enclosure: | B7: ='Performance Data Sheet'!F14 -> TEFC | C7: Voltage: | D7: ='Performance Data Sheet'!F13 & " V" -> 4000 V | E7: Frame: | F7: ='Performance Data Sheet'!C14 -> 5811USS
A8: Pole: | B8: 2 | C8: Frequency: | D8: 3 PH / 60 Hz | E8: Ins. Class: | F8: F
A9: HP: | B9: 600 | C9: Rotor Inertia: | D9: 177.6 lb-ft² | E9: Date: | F9: ='Performance Data Sheet'!K44 -> 43945
A10: FLRPM: | B10: 3575 | C10: Load Inertia: | D10: N/A | E10: File: | F10: CS2600
B12: Locked Rotor Amps: | C12: ='Performance Data Sheet'!D22 & "A" -> 498A | D12: Load Type: | E12: N/A
B13: Locked Rotor Torque: | C13: 0.95 | D13: Starting at: | E13: N/A
B14: Breakdown Torque: | C14: 2.7 | D14: Accel. Time: | E14: N/A
B15: Rated Torque: | C15: 881 lb-ft
A39: Comments: | B39: PROJECT | C39: ='Performance Data Sheet'!C10 -> 2174962.1 | E39: D.E.Curve #: | F39: =F10 -> CS2600
C43: Prepared by: | D43: ='Performance Data Sheet'!K42 -> JERRY R | E43: Checked by:
A53: Load | B53: Efficiency | C53: PF | D53: Amps | E53: RPM | F53: Input Watts
A54: 0 | D54: 14.30579 | E54: 100 | F54: 2
A55: 25 | B55: 87.037048 | C55: 75.494896 | D55: 24.68873 | E55: 79.09997 | F55: 10.760761
A56: 50 | B56: 92.365669 | C56: 88.323227 | D56: 39.770863 | E56: 65.487353 | F56: 20.279935
A57: 75 | B57: 94.081223 | C57: 91.533386 | D57: 56.514412 | E57: 51.790842 | F57: 29.865197
A58: 100 | B58: 94.814026 | C58: 92.48716 | D58: 73.9991 | E58: 37.714608 | F58: 39.512499
A59: 125 | B59: 95.125923 | C59: 92.58622 | D59: 92.096947 | E59: 23.580244 | F59: 49.228684

Sheet  Performance 2300V
A2: TOSHIBA INTERNATIONAL CORPORATION
A3: Performance Curve
A4: Design Values (For Reference Only)
A6: Model #: | B6: ='Performance Data Sheet'!C17 -> GP-10032399 | E6: FLAmps: | F6: 128 A
A7: Enclosure: | B7: ='Performance Data Sheet'!F14 -> TEFC | C7: Voltage: | D7: 2300 V | E7: Frame: | F7: ='Performance Data Sheet'!C14 -> 5811USS
A8: Pole: | B8: 2 | C8: Frequency: | D8: 3 PH / 60 Hz | E8: Ins. Class: | F8: F
A9: HP: | B9: 600 | C9: Rotor Inertia: | D9: 177.6 lb-ft² | E9: Date: | F9: ='Performance Data Sheet'!K44 -> 43945
A10: FLRPM: | B10: 3575 | C10: Load Inertia: | D10: N/A | E10: File: | F10: CS2600
B12: Locked Rotor Amps: | C12: 859 A | D12: Load Type: | E12: Fan / Pump
B13: Locked Rotor Torque: | C13: 0.95 | D13: Starting at: | E13: FV (V)
B14: Breakdown Torque: | C14: 2.7 | D14: Accel. Time: | E14: 6 (s)
B15: Rated Torque: | C15: 881 lb-ft
A39: Comments: | E39: D.E.Curve #:
C43: Prepared by: | E43: Checked by:
A53: Load | B53: Efficiency | C53: PF | D53: Amps | E53: RPM | F53: Input Watts
A54: 0 | D54: 24.504626 | E54: 100 | F54: 2
A55: 25 | B55: 87.070282 | C55: 75.859802 | D55: 42.542042 | E55: 78.980739 | F55: 10.713331
A56: 50 | B56: 92.380379 | C56: 88.543701 | D56: 68.705673 | E56: 65.252539 | F56: 20.19504
A57: 75 | B57: 94.087326 | C57: 91.693665 | D57: 97.712631 | E57: 51.436804 | F57: 29.742984
A58: 100 | B58: 94.813828 | C58: 92.61573 | D58: 127.9981 | E58: 37.225778 | F58: 39.353444
A59: 125 | B59: 95.120628 | C59: 92.691849 | D59: 159.3506 | E59: 22.974406 | F59: 49.033143

Sheet StallTime
A1: Rating: | B1: 2 Pole - 600.0 HP - 3600 RPM - 4000 V - 60 Hz
A3: Starting Performance
D4: Load Type: Fan / Pump - 443.0 lb-ft²
A5: RPM | B5: Motor | C5: Load | D5: Accel. | E5: Line | F5: Stator | G5: Rotor
A6: Speed Increment | B6: Torque (%) | C6: Torque (%) | D6: Time (s) | E6: Amps | F6: kW / s | G6: kW / s
A7: 0~360 | B7: 95.2 | C7: 22.5 | D7: 1.134 | E7: 496.9 | F7: 190.0 | G7: 528.7
A8: 360~720 | B8: 95.4 | C8: 11.5 | D8: 0.982 | E8: 494.6 | F8: 163.2 | G8: 414.2
A9: 720~1080 | B9: 95.3 | C9: 7.0 | D9: 0.933 | E9: 491.9 | F9: 153.5 | G9: 349.4
A10: 1080~1440 | B10: 95.2 | C10: 7.0 | D10: 0.934 | E10: 488.9 | F10: 151.9 | G10: 305.8
A11: 1440~1800 | B11: 95.1 | C11: 11.0 | D11: 0.980 | E11: 485.4 | F11: 157.2 | G11: 274.7
A12: 1800~2160 | B12: 95.0 | C12: 18.0 | D12: 1.070 | E12: 481.4 | F12: 169.1 | G12: 249.8
A13: 2160~2530 | B13: 97.8 | C13: 27.7 | D13: 1.209 | E13: 476.8 | F13: 187.7 | G13: 219.3
A14: 2530~2901 | B14: 107.3 | C14: 42.4 | D14: 1.306 | E14: 470.3 | F14: 198.6 | G14: 186.5
A15: 2901~3086 | B15: 123.9 | C15: 57.1 | D15: 0.634 | E15: 461.8 | F15: 93.2 | G15: 134.0
A16: 3086~3271 | B16: 156.3 | C16: 69.5 | D16: 0.489 | E16: 446.7 | F16: 69.1 | G16: 89.2
... A19: 3571~3578 | B19: 110.4 | C19: 99.2 | D19: 0.131 | E19: 60.5 | F19: 0.5 | G19: 27.2
D21: Acceleration Time: 10.4 s
B22: Energy | D22: First Start | F22: Second Start
A23: Stator Winding Rise | B23: 1595 kW / s | D23: 19°C | F23: 39°C
A24: Rotor Bar Rise | B24: 2242 kW / s | D24: 76°C | F24: 153°C
A25: End Ring Rise | B25: 627 kW / s | D25: 50°C | F25: 101°C
A27: Locked Rotor Thermal Capability
E28: Cold Condition
B29: Rate of Rise | D29: Power | E29: Rise Limit | F29: Max Time
A30: Stator Copper | B30: 2.6°C / s | D30: 215.4 kW | E30: 160°C | F30: 61.2 s
A31: Rotor Bar | B31: 11.3°C / s | D31: 332.3 kW | E31: 260°C | F31: 23.0 s
A32: Rotor ER | B32: 7.5°C / s | D32: 92.9 kW | E32: 180°C | F32: 24.0 s
E34: Hot Condition
B35: Hot Temp. | D35: Rise Limit | E35: Ambient | F35: Total | G35: Max.Time
A36: Stator Copper | B36: 99°C + | D36: 61°C + | E36: 40°C | F36: = 200°C | G36: 23.3 s
A37: Rotor Bar | B37: 140°C + | D37: 120°C + | E37: 40°C | F37: = 300°C | G37: 10.6 s
A38: Rotor ER | B38: 140°C + | D38: 40°C + | E38: 40°C | F38: = 220°C | G38: 5.4 s
A40: Cold Stall Time: | B40: 28.3 s | D40: Hot Stall Time: | F40: 6.3 s
