Workbook
Name Print_Area_MI: 'Performance Data Sheet'!$A$10:$N$42

Sheet DesignSheet
A1: TOSHIBA INTERNATIONAL CORPORATION | I1: Calc. Code: | J1: 2-2-2-0-1-2
A2: 3-PHASE SQUIRREL CAGE INDUCTION MOTOR DESIGN SHEET | J2: B.L.-1 P.F.-1
A3: File: | B3: M:\Active Projects\6800 Frame TEFC\Electrical Design\2P\SERIES\CS2700U.rat | G3: Date: | H3: 41655 | I3: Time: | J3: 0.60755787
A4: Pole | B4: HP | C4: RPM | D4: Form | E4: Voltage | F4: Frequency | G4: Temperature | H4: FLSpeed | I4: FLSlip | J4: Frame
A5: 2 | B5: 700.00002 | C5: 3600 | D5: FCW4 | E5: 4000 | F5: 60 | G5: 105 | H5: 3580.7 / 3579.6 | I5: 0.0054 / 0.0057 | J5: 6811USS
A6: Core Data | D6: Winding Data | H6: Constant Data
B7: Primary | C7: Secondary | F7: Bar | G7: End Ring | H7: St. Slot Pitch | I7: 24.143701 | J7: LR Test Data
A8: Air Gap | B8: 3.5 | H8: Rt. Slot Pitch | I8: 27.864537 | J8: ES
A9: Space Fac. | B9: 0.93000001 | D9: Pitch | E9: 1 ~ 18 | F9: Cross Section Area | H9: Mean Value | I9: 26.004119 | J9: 659.24163
A10: Core Length | B10: 470 | C10: 470 | F10: UB: 322.1 | G10: UER: 2640.0 | H10: Eff.T.W.St. | I10: 17.419318 | J10: WS
A11: OD | B11: 770 | C11: 408 | D11: Coil Pitch | E11: 0.62956667 | H11: Eff.T.W.Rt. | I11: 27.468965 | J11: 16866.162
A12: ID | B12: 415 | C12: 170 | D12: Slot Fill | E12: - | F12: EBL: 62.5 | G12: ERD1: 318.0 | H12: St.Carter Fac. | I12: 1.3860302 | J12: IS
A13: Core Depth | B13: 112.5 | C13: 77.59 | D13: Con./Slot | E13: 26 | G13: ERT: 60.00 | H13: Rt.Carter Fac. | I13: 1.0144007 | J13: 83.028214
A14: Eff.Core L. | B14: 437.10001 | C14: 437.10001 | D14: Wire Size 1 | E14: (.064"x.204")x2 | G14: ERH: 44.00 | H14: Carter Factor | I14: 1.40599 | J14: Volts / Turn
A15: Slot Data | D15: Wire Size 2 | E15: - | H15: Short. Factor | I15: 0.835433 | J15: 19.739049
A16: Number | B16: 54 | C16: 46 | D16: // Circuits | E16: 2 | H16: Distrib. Factor | I16: 0.95529271 | J16: AC
A17: Kind | B17: Open | C17: Trapeze | D17: Connection | E17: Wye | H17: Wind. Factor | I17: 0.79808305 | J17: 447.05937
A18: Skew | B18: - | C18: 0 | D18: MCL | E18: 1240 | F18: 655 | H18: Reactance | I18: (Coeff.: 0.0596)
A19: Depth | B19: 65 | C19: 41.41 | D19: No.Cond./Ph. | E19: 234 | I19: Running | J19: Start
A20: Width | B20: 14.30 - 14.30 | D20: Res. (20°C) | E20: 0.15573311 | H20: Stator Slot | I20: 12.93648 | J20: 12.93648
A21: Opening | B21: 14.3 | C21: 3 | D21: (105°C) | E21: 0.20774613 | F21: 0.10962377 | G21: 0.048636126 | H21: Rotor Slot | I21: 25.592066 | J21: 23.071703
A22: Tip Depth | B22: 3.6500001 | C22: 6 | D22: Material | E22: CU | F22: CU | G22: CU | H22: Zigzag | I22: 5.1524181 | J22: 5.1524181
A23: T.Min.Wid. | B23: 9.8437004 | C23: 8.0883093 | D23: Spec.Resist. | E23: 1.742 | F23: 1.742 | G23: 1.742 | H23: Coil End | I23: 27.681648 | J23: Skew R.: 0.00
A24: Low. R. | B24: 0 | C24: 0.80000001 | D24: Spec.Gravity | E24: 8.8900003 | F24: 8.8900003 | G24: 8.8900003 | H24: Belt Leakage | I24: 6.8935024 | J24: 6.8935024
A25: Up. R. | B25: - | C25: 5.7199998 | D25: Weight (kg) | H25: Total Resist. | I25: 0.36600605 | J25: 0.81553692
A26: Wedge Dep. | B26: 0.80 - 3.65 | C26: Normal | D26: Wire 1 | E26: 251.16858 | F26: 94.179501 | G26: 53.173945 | H26: Total React. | I26: 4.6612782 | J26: 4.5111547
A27: Duct | B27: - | C27: - | D27: Wire 2 | E27: - | F27: - | G27: - | H27: Impedance | I27: 4.6756258 | J27: 4.5842791
A28: Effective Depth (S=1) | D28: Magnetic Circuit Data | I28: Core Loss Data
B29: Res.= | C29: 35.359193 | E29: Length | F29: Section | G29: Density | H29: AT | I29: Volume | J29: Loss
B30: Reac.= | C30: 35.395463 | D30: Primary Core | E30: 60.475608 | F30: 983.47501 | G30: 9.4401868 | H30: 121.78108 | I30: 101573.07 | J30: 3282.548
A31: Excitation Data | D31: Tooth | E31: 6.5 | F31: 1161.724 | G31: 7.9917328 | H31: 7.7745027 | I31: 15102.412 | J31: 372.63925
A32: Excit.Amps | B32: 14.020 / 15.872 | D32: Second.Core | E32: 25.539556 | F32: 925.98179 | G32: 10.026318 | H32: 61.783347 | I32: Total | J32: 3655.1873
A33: Core Loss | B33: 0.981 / 1.110 | C33: Flux / Pole | D33: Tooth | E33: 4.141 | F33: 813.14201 | G33: 11.417671 | H33: 14.714726 | I33: C.L.C. | J33: 1.50 / 0.62
A34: NoLoad | B34: 14.05 / 15.91 | C34: 9.2841878 | D34: Air Gap | E34: 0.35 | F34: 2179.1305 | G34: 4.260501 | H34: 1186.6407 | I34: S.F.C. | J34: 6.0500002
A35: Load Characteristics | D35: Temp. Rise @ 100%: | E35: 70 / 67 | G35: No Load Loss | H35: 15243.2 / 13067.6 | I35: W.Loss | J35: 5482.8 / 2259.2
A36: Load (%) | B36: 25 | C36: 50 | D36: 75 | E36: 100 | F36: 125 | G36: Primary Loss | H36: 4296.4 / 4700.9 | I36: S.Loss | J36: 1318.5 / 543.3
A37: Current (A) | B37: 26.23 / 27.02 | C37: 43.84 / 45.16 | D37: 63.03 / 64.93 | E37: 83.03 / 85.53 | F37: 103.74 / 106.87 | G37: Second. Loss | H37: 2918.5 / 3091.9 | I37: Total C.Loss | J37: 6801.3 / 2802.5
A38: Efficiency | B38: 0.892 / 0.881 | C38: 0.939 / 0.927 | D38: 0.953 / 0.942 | E38: 0.959 / 0.947 | F38: 0.961 / 0.950 | G38: Frict.& Wind. | H38: 8350.0 / 10961.2 | I38: Stray Loss | J38: 7400.9805
A39: P.F. | B39: 0.805 / 0.791 | C39: 0.916 / 0.900 | D39: 0.941 / 0.925 | E39: 0.946 / 0.930 | F39: 0.945 / 0.928 | G39: Starting Data | I39: Slip | J39: PF
A40: Slip | B40: 0.0014 / 0.0017 | C40: 0.0027 / 0.0030 | D40: 0.0040 / 0.0043 | E40: 0.0054 / 0.0057 | F40: 0.0067 / 0.0070 | G40: LRA | H40: 503.8 / 548.2
...

Sheet Data Sheet
A1: TOSHIBA INTERNATIONAL CORPORATION
A2: INDUCTION MOTOR DATA SHEET
A3: File: | B3: CS2700U | I3: HRW / Model Number: | J3: 7003FTQL11F-C
A4: Type: TIKE - Form: FCW4 - 2 Pole - 700 HP - 2300 / 4000 V - 60 Hz - 6811USS - Class F | Q4: Motor Type Selection | T4: Electrical Steel Table
A5: Motor Parameters | F5: PERFORMANCE | J5: DESIGN | K5: TEST | Q5: EPACT | T5: M22 - 26Ga.
A6: Material | D6: M36 - 26Ga. | F6: NL & Impedance Test | Q6: EQP-III | T6: M36 - 26Ga.
A7: Air Gap | D7: 3.5 | F7: No load amps | J7: 15.9 | K7: - | Q7: Exp.Prf. | T7: NCB1 - 26Ga.
A8: Stack length | D8: 470 | F8: No load watts | J8: 13886 | K8: - | Q8: Exp.Prf.-EQPIII | T8: M43 - 26Ga.
A9: Number of turns per coil | D9: 13 | F9: Impedance amps | H9: 3 | I9: f | J9: 145 | K9: - | Q9: Prem. Eff. | T9: M45 - 26Ga.
A10: Wire 1 (size & number) | D10: (.064"x.204")x2 | F10: Impedance volts | H10: 3 | I10: f | J10: 1150 | K10: - | Q10: OWP | T10: M54 - 26Ga.
A11: Wire 2 (size & number) | D11: - | F11: Impedance watts | H11: 3 | I11: f | J11: 16866 | K11: - | Q11: Dry Kiln
A12: Slot fill - circle/square method (%) | D12: - | F12: Temperature Rise (°C)
A13: Connection | D13: 2D / 2Y | G13: Winding | I13: 80/115 | J13: 70 / 92 | K13: -
A14: MCL | D14: 1240 | G14: Frame | J14: - | K14: -
A15: Allowance for ins. depth | D15: 13.8844 | G15: Bearing PS/OS | J15: - | K15: -
A16: Allowance for ins. width | D16: 3.5368001 | G16: End Ring | J16: - | K16: -
A17: Slot/Wire arrangement | D17: 26 x 2 | F17: Nameplate Data
A18: Effective cross section for coil | D18: - | H18: FLC (A) | J18: 149 / 86 | M18: =J18*6.5 -> #VALUE!
A19: Coil grouping | D19: Interspersed | H19: RPM | J19: 3580
A20: Coil pitch (slot number) | D20: 1 ~ 18 | H20: CODE | J20: F
A21: Method of coil connection | D21: - | H21: S. F. | J21: 1.15 | Q21: Method of Connection
A22: Resistance per phase @ 20 °C | D22: 0.16025 | H22: DESIGN | Q22: Skip
A23: Coil Weight | B23: Wire1 | D23: 575 | H23: Nom.Eff. (%): | Q23: Adjacent
A24: (lbs.) | B24: Wire2 | D24: - | H24: Min.Eff. (%): | Q24: -
A25: Current Densities (A/cm2) | E25: Bar / ER | H25: P.F. (%):
A26: FL / LR | D26: 264 / 1682 | E26: 305 / 273
A27: Stator Slot Shape (Reference) | F27: Performance
H28: LRC (A) | I28: - | J28: 946 / 548 | K28: - | M28: =(J28/J18)*100 -> #VALUE!
H29: LRT (%) | I29: 60 | J29: 78 | K29: -
H30: BDT (%) | I30: 175 | J30: 280 | K30: -
H31: SLIP (%) | J31: 0.57 | K31: -
G32: IEEE-B | H32: Eff. (%) | J32: 94.7 | K32: -
A33: Rotor Slot Shape (Reference) | H33: PF (%) | J33: 93 | K33: -
F34: Losses (Watts) | H34: Primary | J34: 4701 | K34: -
H35: Secondary | J35: 3092 | K35: -
H36: Core | J36: 2803 | K36: -
H37: F & W | J37: 10961 | K37: -
H38: Stray | J38: 7401 | K38: -
A39: End Ring (Reference) | F39: Note
H40: QC Limits: CS2700U
...

Sheet LoginSheet
J1: P | K1: T | L1: L | M1: T
B2: PROJECT HISTORY | J2: E | K2: D | L2: I | M2: Y | N2: H
J3: R | L3: M | M3: P
J4: F | L4: I | M4: E
K5: C | L5: T | N5: I
J6: D | K6: U | M6: T | N6: N
J7: A | K7: R | L7: R | M7: E | N7: S
I8: S | J8: T | K8: V | L8: E | M8: S | N8: U
B9: DATE | C9: PROJECT | D9: SMART NUMBER | E9: QTY | F9: CUSTOMER | G9: REMARKS | H9: LIMIT CODE | I9: F | J9: A | K9: E | L9: V | M9: T | N9: L
B53: REVISION HISTORY
B54: REV | C54: REMARKS | I54: DATE | L54: INIT

Sheet Form
A1: Winding Data Calculation
C2: MCL: 1240.0
A3: Coil Resistance | D3: Lead Resistance
A4: 13T: | B4: 0.0360 ~ 0.0346 | D4: AWG. 02 x 3
D5: 0.00173
A6: Coil Dimensions
A7: HM: | B7: 13T: 24.84 | C7: WM: | D7: 13T: 10.93 | E7: WT:
E8: 13.79 ~ 13.59
A9: Insulation Allowance | D9: Wire Weight
A10: Depth: | B10: 7.27 | D10: (.064"x.204")x 2: | F10: 575 lbs.
A11: Width: | B11: 3.37
A12: QC Resistance
A13: 1-2, 2-3, 3-1: | C13: 0.331 ~ 0.311

Sheet MagNoise
A1: Magnetic Noise Verification
A3: Rating: | B3: 2 Pole - 700.0 HP - 3600 RPM - 4000 V - 60 Hz
A5: Electromagnetic Excitation Frequencies
B7: L = | C7: 0 | D7: L = | E7: + 1 | F7: L = | G7: - 1 | H7: Slip = | I7: 0 | J7: Slip = | K7: 0.005
A8: Mode A | B8: 6 | D8: 12 | F8: 0 | H8: 2880.0 Hz | J8: 2865.2 Hz
A9: Mode B | B9: 10 | D9: 16 | F9: 4 | H9: 2640.0 Hz | J9: 2625.2 Hz
A10: Mode C | B10: 8 | D10: 14 | F10: 2 | H10: 2760.0 Hz | J10: 2745.2 Hz
A12: Natural Frequencies of Stator Core
B14: Mode 0 = | D14: 2288.2 Hz | F14: Mode 6 = | H14: 7747.0 Hz
B15: Mode 2 = | D15: 602.1 Hz | F15: Mode 7 = | H15: 10662.8 Hz
B16: Mode 3 = | D16: 1703.1 Hz | F16: Mode 8 = | H16: 14027.8 Hz
B17: Mode 4 = | D17: 3265.4 Hz | F17: Mode 9 = | H17: 17841.9 Hz
B18: Mode 5 = | D18: 5280.9 Hz | F18: Mode 10 = | H18: 22105.0 Hz
A20: Analysis Results
B22: No matching frequencies detected.

Sheet StallTime
A1: Rating: | B1: 2 Pole - 700.0 HP - 3600 RPM - 4000 V - 60 Hz
A3: Starting Performance
D4: Load Type: Fan / Pump - 251.5 lb-ft²
A5: RPM | B5: Motor | C5: Load | D5: Accel. | E5: Line | F5: Stator | G5: Rotor
A6: Speed Increment | B6: Torque (%) | C6: Torque (%) | D6: Time (s) | E6: Amps | F6: kW / s | G6: kW / s
A7: 0~360 | B7: 79.0 | C7: 22.5 | D7: 1.130 | E7: 547.2 | F7: 211.5 | G7: 616.3
A8: 360~720 | B8: 79.0 | C8: 11.5 | D8: 0.946 | E8: 545.3 | F8: 176.0 | G8: 464.3
A9: 720~1080 | B9: 79.0 | C9: 7.0 | D9: 0.887 | E9: 543.2 | F9: 163.8 | G9: 386.9
A10: 1080~1440 | B10: 79.0 | C10: 7.0 | D10: 0.887 | E10: 540.7 | F10: 162.4 | G10: 338.5
A11: 1440~1800 | B11: 79.0 | C11: 11.0 | D11: 0.939 | E11: 537.6 | F11: 170.2 | G11: 307.2
A12: 1800~2192 | B12: 80.1 | C12: 18.5 | D12: 1.129 | E12: 534.0 | F12: 202.1 | G12: 282.6
A13: 2192~2584 | B13: 83.4 | C13: 29.5 | D13: 1.290 | E13: 529.7 | F13: 227.6 | G13: 259.7
A14: 2584~2976 | B14: 90.4 | C14: 45.9 | D14: 1.563 | E14: 523.6 | F14: 270.7 | G14: 239.2
A15: 2976~3172 | B15: 102.6 | C15: 62.5 | D15: 0.865 | E15: 516.6 | F15: 145.8 | G15: 181.0
A16: 3172~3368 | B16: 127.2 | C16: 76.2 | D16: 0.682 | E16: 504.9 | F16: 111.9 | G16: 113.0
... A19: 3593~3600 | B19: 132.6 | C19: 99.8 | D19: 0.039 | E19: 82.4 | F19: 0.2 | G19: 11.9
D21: Acceleration Time: 10.7 s
B22: Energy | D22: First Start | F22: Second Start
A23: Stator Winding Rise | B23: 1891 kW / s | D23: 20°C | F23: 39°C
A24: Rotor Bar Rise | B24: 2247 kW / s | D24: 62°C | F24: 124°C
A25: End Ring Rise | B25: 997 kW / s | D25: 49°C | F25: 97°C
A27: Locked Rotor Thermal Capability
E28: Cold Condition
B29: Rate of Rise | D29: Power | E29: Rise Limit | F29: Max Time
A30: Stator Copper | B30: 2.2°C / s | D30: 217.5 kW | E30: 160°C | F30: 71.2 s
A31: Rotor Bar | B31: 7.9°C / s | D31: 285.8 kW | E31: 260°C | F31: 33.0 s
A32: Rotor ER | B32: 6.2°C / s | D32: 126.8 kW | E32: 180°C | F32: 29.1 s
E34: Hot Condition
B35: Hot Temp. | D35: Rise Limit | E35: Ambient | F35: Total | G35: Max.Time
A36: Stator Copper | B36: 67°C + | D36: 93°C + | E36: 40°C | F36: = 200°C | G36: 41.4 s
A37: Rotor Bar | B37: 89°C + | D37: 171°C + | E37: 40°C | F37: = 300°C | G37: 21.7 s
A38: Rotor ER | B38: 89°C + | D38: 91°C + | E38: 40°C | F38: = 220°C | G38: 14.7 s
A40: Cold Stall Time: | B40: 46.2 s | D40: Hot Stall Time: | F40: 23.3 s

Sheet Performance Data Sheet
A1: TOSHIBA INTERNATIONAL CORPORATION | J1: INDEX | L1: MPCF-1033
A2: Industrial Division / Houston Motor Plant | J2: SHEET NO. | L2: 1 of 1
J3: ISSUED | L3: 7/31/13
J4: SUPERSEDES | L4: 11/8/96
J5: REVISION | L5: 2
A6: SQUIRREL CAGE INDUCTION MOTOR | J6: WRITTEN BY | L6: MDC
A7: PERFORMANCE SPECIFICATIONS | J7: APPROVED BY | L7: PAA
B9: CUSTOMER:
B10: TIC SR No.: | C10: QUOTE 33791
A12: MOTOR NAMEPLATE DATA
B13: H.P.: | C13: 700 | E13: VOLTS: | F13: 2300 | H13: 3 PH / | I13: 60 Hz | L13: S. RPM: | M13: 3600
B14: FRAME: | C14: 6811USS | E14: ENCL: | F14: TEFC | H14: FLAMPS: | I14: 149 | L14: FLRPM: | M14: 3580
B15: FORM: | C15: FCW4 | E15: S.F.: | F15: 1.0 | H15: NEMA DESIGN: | I15: - | L15: INSUL CLASS: | M15: F
B16: TYPE: | C16: TIKE | E16: AMB.: | F16: 40 | H16: CODE: | I16: F | L16: DUTY: | M16: Cont.
B17: MODEL No.: | C17: QUOTE 33791 | H17: kW: | I17: -
B18: NOM. EFF.: | C18: - | E18: MIN. EFF.: | F18: - | H18: P.F.: | I18: -
A21: AMPERAGE | E21: TORQUES | I21: **BEARINGS:
C22: LOCKED ROTOR: | D22: 946 | G22: FULL LOAD (lb-ft.): | H22: 1027 | K22: DRIVE END:
G23: LOCKED ROTOR (%): | H23: 75 | K23: OPPOSITE DRIVE END:
G24: BREAK DOWN (%): | H24: 280
A28: EFFICIENCY | H28: POWER FACTOR
C29: FULL LOAD: | D29: 94.7 | J29: FULL LOAD: | K29: 93
C30: 3/4 LOAD: | D30: 94.1 | J30: 3/4 LOAD: | K30: 92.5
C31: 1/2 LOAD: | D31: 92.7 | J31: 1/2 LOAD: | K31: 90
A35: ALL CHARACTERISTICS ARE AVERAGE EXPECTED VALUES BASED UPON RATED VOLTAGE,
A36: FREQUENCY AND SINEWAVE POWER INPUT.
A37: THE DECLARED LOCKED ROTOR CURRENT HAS A TOLERANCE OF 20%.
A38: * TEMPERATURE RISE WILL BE CONSISTENT WITH INSULATION, AMBIENT AND SERVICE FACTOR AS
A39: DEFINED BY NEMA-MG-12 OR -20.
A40: ** BEARINGS ARE THE ONLY RECOMMENDED SPARE PART(S).
J42: CERTIFIED BY: | K42: JERRY R
J44: DATE: | K44: 44908
A59: - | B59: 6205ZZ | D59: 1 | E59: -
A60: TEFC | B60: 6206UU | D60: 1.15 | E60: A
A61: ODP | B61: 6207ZZ | E61: B
B62: 6208UU
B63: 6211ZZ
B64: 6211C3
B65: 6211ZZC3
B66: 6305UUC3
...

Sheet STCurve
A2: TOSHIBA INTERNATIONAL CORPORATION
A3: Speed Torque/Current Curve
A6: Model #: | B6: ='Performance Data Sheet'!C17 -> QUOTE 33791 | E6: FLAmps: | F6: ='Performance Data Sheet'!I14 & " A" -> 149 A
A7: Enclosure: | B7: ='Performance Data Sheet'!F14 -> TEFC | C7: Voltage: | D7: ='Performance Data Sheet'!F13 & " V" -> 2300 V | E7: Frame: | F7: ='Performance Data Sheet'!C14 -> 6811USS
A8: Pole: | B8: 2 | C8: Frequency: | D8: 3 PH / 60 Hz | E8: Ins. Class: | F8: F
A9: HP: | B9: 700 | C9: Rotor Inertia: | D9: 309.1 lb-ft² | E9: Date: | F9: ='Performance Data Sheet'!K44 -> 44908
A10: FLRPM: | B10: 3575 | C10: Load Inertia: | D10: N/A | E10: File: | F10: CS2700U
B12: Locked Rotor Amps: | C12: ='Performance Data Sheet'!D22 & " A" -> 946 A | D12: Load Type: | E12: N/A
B13: Locked Rotor Torque: | C13: 0.75 | D13: Starting at: | E13: N/A
B14: Breakdown Torque: | C14: 2.8 | D14: Accel. Time: | E14: N/A
B15: Rated Torque: | C15: 1028 lb-ft
A39: Comments: | B39: PROJECT | C39: ='Performance Data Sheet'!C10 -> QUOTE 33791 | E39: D.E.Curve #: | F39: =F10 -> CS2700U
C43: Prepared by: | D43: ='Performance Data Sheet'!K42 -> JERRY R | E43: Checked by:
D53: Load
A54: 100 | B54: 0 | C54: 0.16342223 | D54: 100
A55: 99.2 | B55: 165.11165 | C55: 177.64209 | D55: 98.400002
A56: 96 | B56: 280 | C56: 504.12836 | D56: 89.75
A57: 90.857143 | B57: 161.5788 | C57: 577.6391 | D57: 76.228569
A58: 85.714285 | B58: 114.61271 | C58: 596.61542 | D58: 62.85714
A59: 80.571428 | B59: 94.461174 | C59: 604.71429 | D59: 51.257141
A60: 70.285714 | B60: 80.898237 | C60: 613.06976 | D60: 33.485714
A61: 59.999999 | B61: 75 | C61: 618.67914 | D61: 22
A62: 50 | B62: 75.000014 | C62: 623.25818 | D62: 14
A63: 39.999998 | B63: 75.000022 | C63: 627.08502 | D63: 7.9999995
A64: 30.000001 | B64: 75.001536 | C64: 630.28387 | D64: 5.9999995
A65: 19.999999 | B65: 75.003142 | C65: 632.9704 | D65: 8.000001
... A67: 0 | B67: 75 | C67: 637.20929 | D67: 30

Sheet Thermdam
A2: TOSHIBA INTERNATIONAL CORPORATION
A3: Thermal Limit Curve
A4: Design Values (For Reference Only)
A6: Model #: | B6: ='Performance Data Sheet'!C17 -> QUOTE 33791 | E6: FLAmps: | F6: ='Performance Data Sheet'!I14 & " A" -> 149 A
A7: Enclosure: | B7: ='Performance Data Sheet'!F14 -> TEFC | C7: Voltage: | D7: ='Performance Data Sheet'!F13 & " V" -> 2300 V | E7: Frame: | F7: ='Performance Data Sheet'!C14 -> 6811USS
A8: Pole: | B8: 2 | C8: Frequency: | D8: 3 PH / 60 Hz | E8: Ins. Class: | F8: F
A9: HP: | B9: 700 | C9: Rotor Inertia: | D9: 309.1 lb-ft² | E9: Date: | F9: ='Performance Data Sheet'!K44 -> 44908
A10: FLRPM: | B10: 3575 | C10: Load Inertia: | D10: N/A | E10: File: | F10: CS2700U
A39: Comments: | B39: PROJECT | C39: ='Performance Data Sheet'!C10 -> QUOTE 33791 | E39: D.E.Curve #: | F39: =F10 -> CS2700U
C43: Prepared by: | D43: ='Performance Data Sheet'!K42 -> JERRY R | E43: Checked by:
F50: =5252.1*B50/D53 -> #DIV/0!
D66: =D65/D64 -> #DIV/0!
A67: Current (%) | B67: Cold | C67: Hot | E67: CURRENT (%) | F67: Accel. Time
A68: 637.2093 | B68: 35 | C68: 15 | E68: =A68 -> 637.2093 | F68: 0.0001
A69: 567.47984 | B69: =((A68/A69)^2)*B68 -> 44.129741 | C69: =((A68/A69)^2)*C68 -> 18.912746 | E69: 636.27907 | F69: 1.763
A70: 497.72946 | B70: =((A68/A70)^2)*B68 -> 57.364811 | C70: =((A68/A70)^2)*C68 -> 24.584919 | E70: 634.06977 | F70: 3.22
A71: 428 | B71: =((A68/A71)^2)*B68 -> 77.579097 | C71: =((A68/A71)^2)*C68 -> 33.248184 | E71: 631.62791 | F71: 4.5809999
A72: =A71-100 -> 328 | B72: =((A68/A72)^2)*B68 -> 132.09445 | E72: 628.72093 | F72: 5.9419999
A73: =A72-100 -> 228 | B73: =((A68/A73)^2)*B68 -> 273.37737 | E73: 625.11628 | F73: 7.388
A74: 280 | B74: =((A68/A74)^2)*B68 -> 181.26594 | C74: =((A68/A74)^2)*C68 -> 77.685401 | E74: 620.93023 | F74: 9.0109997
A75: 180 | B75: =((A68/A75)^2)*B69 -> 553.03241 | C75: =((A68/A75)^2)*C68 -> 187.97949 | E75: 615.93023 | F75: 10.907
A76: 145 | B76: =((A68/A76)^2)*B68 -> 675.92149 | C76: =((A68/A76)^2)*C68 -> 289.68064 | E76: 608.83721 | F76: 13.007999
A77: 125 | C77: =CEILING(C76*2,100) -> 600 | E77: 600.69767 | F77: 14.009999
A78: 125 | C78: =2*C77 -> 1200 | E78: 587.09302 | F78: 14.704
A79: 125 | C79: 10000 | E79: 540.93023 | F79: 15.049
E80: 340.93023 | F80: 15.278999
E81: 0 | F81: 15.351999

Sheet Performance 4000V
A2: TOSHIBA INTERNATIONAL CORPORATION
A3: Performance Curve
A4: Design Values (For Reference Only)
A6: Model #: | B6: ='Performance Data Sheet'!C17 -> QUOTE 33791 | E6: FLAmps: | F6: 86 A
A7: Enclosure: | B7: ='Performance Data Sheet'!F14 -> TEFC | C7: Voltage: | D7: 4000V | E7: Frame: | F7: ='Performance Data Sheet'!C14 -> 6811USS
A8: Pole: | B8: 2 | C8: Frequency: | D8: 3 PH / 60 Hz | E8: Ins. Class: | F8: F
A9: HP: | B9: 700 | C9: Rotor Inertia: | D9: 309.1 lb-ft² | E9: Date: | F9: ='Performance Data Sheet'!K44 -> 44908
A10: FLRPM: | B10: 3575 | C10: Load Inertia: | D10: N/A | E10: File: | F10: CS2700U
B12: Locked Rotor Amps: | C12: 548 A | D12: Load Type: | E12: N/A
B13: Locked Rotor Torque: | C13: 0.75 | D13: Starting at: | E13: N/A
B14: Breakdown Torque: | C14: 2.8 | D14: Accel. Time: | E14: N/A
B15: Rated Torque: | C15: 1028 lb-ft
A39: Comments: | B39: PROJECT | C39: ='Performance Data Sheet'!C10 -> QUOTE 33791 | E39: D.E.Curve #: | F39: =F10 -> CS2700U
C43: Prepared by: | D43: ='Performance Data Sheet'!K42 -> JERRY R | E43: Checked by:
A53: Load | B53: Efficiency | C53: PF | D53: Amps | E53: RPM | F53: Input Watts
A54: 0 | D54: 14.557455 | E54: 100 | F54: 0.9334
A55: 25 | B55: 88.098824 | C55: 79.168526 | D55: 27.166101 | E55: 81.012546 | F55: 10.642894
A56: 50 | B56: 92.68663 | C56: 90.031738 | D56: 45.41164 | E56: 65.422078 | F56: 20.23218
A57: 75 | B57: 94.135864 | C57: 92.489166 | D57: 65.286774 | E57: 49.532888 | F57: 29.881054
A58: 100 | B58: 94.720894 | C58: 93.038452 | D58: 86.000626 | E58: 33.141108 | F58: 39.595326
A59: 125 | B59: 94.944618 | C59: 92.855339 | D59: 107.45897 | E59: 16.991327 | F59: 49.377533

Sheet Performance 2300V
A2: TOSHIBA INTERNATIONAL CORPORATION
A3: Performance Curve
A4: Design Values (For Reference Only)
A6: Model #: | B6: ='Performance Data Sheet'!C17 -> QUOTE 33791 | E6: FLAmps: | F6: 149 A
A7: Enclosure: | B7: ='Performance Data Sheet'!F14 -> TEFC | C7: Voltage: | D7: 2300V | E7: Frame: | F7: ='Performance Data Sheet'!C14 -> 6811USS
A8: Pole: | B8: 2 | C8: Frequency: | D8: 3 PH / 60 Hz | E8: Ins. Class: | F8: F
A9: HP: | B9: 700 | C9: Rotor Inertia: | D9: 309.1 lb-ft² | E9: Date: | F9: ='Performance Data Sheet'!K44 -> 44908
A10: FLRPM: | B10: 3575 | C10: Load Inertia: | D10: N/A | E10: File: | F10: CS2700U
B12: Locked Rotor Amps: | C12: 946 A | D12: Load Type: | E12: N/A
B13: Locked Rotor Torque: | C13: 0.75 | D13: Starting at: | E13: N/A
B14: Breakdown Torque: | C14: 2.8 | D14: Accel. Time: | E14: N/A
B15: Rated Torque: | C15: 1028 lb-ft
A39: Comments: | B39: PROJECT | C39: ='Performance Data Sheet'!C10 -> QUOTE 33791 | E39: D.E.Curve #: | F39: =F10 -> CS2700U
C43: Prepared by: | D43: ='Performance Data Sheet'!K42 -> JERRY R | E43: Checked by:
A53: Load | B53: Efficiency | C53: PF | D53: Amps | E53: RPM | F53: Input Watts
A54: 0 | D54: 25 | E54: 100 | F54: 0.9334
A55: 25 | B55: 88.098824 | C55: 79.168526 | D55: 47 | E55: 81.012546 | F55: 10.642894
A56: 50 | B56: 92.68663 | C56: 90.031738 | D56: 78.6 | E56: 65.422078 | F56: 20.23218
A57: 75 | B57: 94.135864 | C57: 92.489166 | D57: 113 | E57: 49.532888 | F57: 29.881054
A58: 100 | B58: 94.720894 | C58: 93.038452 | D58: 149 | E58: 33.141108 | F58: 39.595326
A59: 125 | B59: 94.944618 | C59: 92.855339 | D59: 186 | E59: 16.991327 | F59: 49.377533
