Workbook
Name Print_Area_MI: 'Performance Data Sheet'!$A$10:$N$43
Name Print_Area_MI: #REF!

Sheet DesignSheet
A1: TOSHIBA INTERNATIONAL CORPORATION | I1: Calc. Code: | J1: 2-2-2-0-1-2
A2: 3-PHASE SQUIRREL CAGE INDUCTION MOTOR DESIGN SHEET | J2: B.L.-1 P.F.-1
A3: File: | B3: M:\Active Projects\6800 Frame TEFC\Electrical Design\2P\SERIES\CS2900U.rat | G3: Date: | H3: 41654 | I3: Time: | J3: 0.46287037
A4: Pole | B4: HP | C4: RPM | D4: Form | E4: Voltage | F4: Frequency | G4: Temperature | H4: FLSpeed | I4: FLSlip | J4: Frame
A5: 2 | B5: 900.00003 | C5: 3600 | D5: FCW4 | E5: 4000 | F5: 60 | G5: 105 | H5: 3580.7 / 3579.6 | I5: 0.0054 / 0.0057 | J5: 6811USS
A6: Core Data | D6: Winding Data | H6: Constant Data
B7: Primary | C7: Secondary | F7: Bar | G7: End Ring | H7: St. Slot Pitch | I7: 24.143701 | J7: LR Test Data
A8: Air Gap | B8: 3.5 | H8: Rt. Slot Pitch | I8: 27.864537 | J8: ES
A9: Space Fac. | B9: 0.93000001 | D9: Pitch | E9: 1 ~ 18 | F9: Cross Section Area | H9: Mean Value | I9: 26.004119 | J9: 666.59158
A10: Core Length | B10: 550 | C10: 550 | F10: UB: 322.1 | G10: UER: 2640.0 | H10: Eff.T.W.St. | I10: 17.419318 | J10: WS
A11: OD | B11: 770 | C11: 408 | D11: Coil Pitch | E11: 0.62956667 | H11: Eff.T.W.Rt. | I11: 27.468965 | J11: 21225.543
A12: ID | B12: 415 | C12: 170 | D12: Slot Fill | E12: - | F12: EBL: 62.5 | G12: ERD1: 318.0 | H12: St.Carter Fac. | I12: 1.3860302 | J12: IS
A13: Core Depth | B13: 112.5 | C13: 77.59 | D13: Con./Slot | E13: 22 | G13: ERT: 60.00 | H13: Rt.Carter Fac. | I13: 1.0144007 | J13: 105.91154
A14: Eff.Core L. | B14: 511.5 | C14: 511.5 | D14: Wire Size 1 | E14: (.081"x.204")x2 | G14: ERH: 44.00 | H14: Carter Factor | I14: 1.40599 | J14: Volts / Turn
A15: Slot Data | D15: Wire Size 2 | E15: - | H15: Short. Factor | I15: 0.835433 | J15: 23.327967
A16: Number | B16: 54 | C16: 46 | D16: // Circuits | E16: 2 | H16: Distrib. Factor | I16: 0.95529271 | J16: AC
A17: Kind | B17: Open | C17: Trapeze | D17: Connection | E17: Wye | H17: Wind. Factor | I17: 0.79808305 | J17: 482.53869
A18: Skew | B18: - | C18: 0 | D18: MCL | E18: 1320 | F18: 735 | H18: Reactance | I18: (Coeff.: 0.0499)
A19: Depth | B19: 65 | C19: 41.41 | D19: No.Cond./Ph. | E19: 198 | I19: Running | J19: Start
A20: Width | B20: 14.30 - 14.30 | D20: Res. (20°C) | E20: 0.10995626 | H20: Stator Slot | I20: 12.93648 | J20: 12.93648
A21: Opening | B21: 14.3 | C21: 3 | D21: (105°C) | E21: 0.14668035 | F21: 0.088074356 | G21: 0.034822315 | H21: Rotor Slot | I21: 25.592066 | J21: 23.071703
A22: Tip Depth | B22: 3.6500001 | C22: 6 | D22: Material | E22: CU | F22: CU | G22: CU | H22: Zigzag | I22: 5.1524181 | J22: 5.1524181
A23: T.Min.Wid. | B23: 9.8437004 | C23: 8.0883093 | D23: Spec.Resist. | E23: 1.742 | F23: 1.742 | G23: 1.742 | H23: Coil End | I23: 23.655227 | J23: Skew R.: 0.00
A24: Low. R. | B24: 0 | C24: 0.80000001 | D24: Spec.Gravity | E24: 8.8900003 | F24: 8.8900003 | G24: 8.8900003 | H24: Belt Leakage | I24: 6.8935024 | J24: 6.8935024
A25: Up. R. | B25: - | C25: 5.7199998 | D25: Weight (kg) | H25: Total Resist. | I25: 0.26957703 | J25: 0.63074082
A26: Wedge Dep. | B26: 0.80 - 3.65 | C26: Normal | D26: Wire 1 | E26: 288.62203 | F26: 104.71707 | G26: 53.173945 | H26: Total React. | I26: 3.7044857 | J26: 3.5787053
A27: Duct | B27: - | C27: - | D27: Wire 2 | E27: - | F27: - | G27: - | H27: Impedance | I27: 3.7142813 | J27: 3.6338637
A28: Effective Depth (S=1) | D28: Magnetic Circuit Data | I28: Core Loss Data
B29: Res.= | C29: 35.359193 | E29: Length | F29: Section | G29: Density | H29: AT | I29: Volume | J29: Loss
B30: Reac.= | C30: 35.395463 | D30: Primary Core | E30: 60.475608 | F30: 1150.875 | G30: 9.5338086 | H30: 125.52285 | I30: 118862.11 | J30: 3903.1836
A31: Excitation Data | D31: Tooth | E31: 6.5 | F31: 1359.4642 | G31: 8.0709897 | H31: 8.0212282 | I31: 17673.035 | J31: 443.09463
A32: Excit.Amps | B32: 16.784 / 19.000 | D32: Second.Core | E32: 25.539556 | F32: 1083.5957 | G32: 10.125753 | H32: 63.648634 | I32: Total | J32: 4346.2782
A33: Core Loss | B33: 1.168 / 1.322 | C33: Flux / Pole | D33: Tooth | E33: 4.141 | F33: 951.54915 | G33: 11.530904 | H33: 15.141089 | I33: C.L.C. | J33: 1.50 / 0.62
A34: NoLoad | B34: 16.82 / 19.05 | C34: 10.972222 | D34: Air Gap | E34: 0.35 | F34: 2550.0463 | G34: 4.302754 | H34: 1198.409 | I34: S.F.C. | J34: 6.0500002
A35: Load Characteristics | D35: Temp. Rise @ 100%: | E35: 77 / 77 | G35: No Load Loss | H35: 16540.7 / 14180.0 | I35: W.Loss | J35: 6519.4 / 2686.3
A36: Load (%) | B36: 25 | C36: 50 | D36: 75 | E36: 100 | F36: 125 | G36: Primary Loss | H36: 4936.1 / 5400.8 | I36: S.Loss | J36: 1578.4 / 650.4
A37: Current (A) | B37: 32.56 / 33.52 | C37: 55.43 / 57.06 | D37: 80.17 / 82.54 | E37: 105.91 / 109.03 | F37: 132.55 / 136.45 | G37: Second. Loss | H37: 3726.9 / 3948.4 | I37: Total C.Loss | J37: 8097.8 / 3336.7
A38: Efficiency | B38: 0.907 / 0.897 | C38: 0.947 / 0.936 | D38: 0.959 / 0.948 | E38: 0.964 / 0.953 | F38: 0.966 / 0.955 | G38: Frict.& Wind. | H38: 8350.0 / 10961.2 | I38: Stray Loss | J38: 9451.0234
A39: P.F. | B39: 0.820 / 0.806 | C39: 0.923 / 0.907 | D39: 0.945 / 0.929 | E39: 0.949 / 0.933 | F39: 0.946 / 0.930 | G39: Starting Data | I39: Slip | J39: PF
A40: Slip | B40: 0.0014 / 0.0017 | C40: 0.0027 / 0.0030 | D40: 0.0040 / 0.0043 | E40: 0.0054 / 0.0057 | F40: 0.0067 / 0.0070 | G40: LRA | H40: 635.5 / 691.6
...

Sheet Data Sheet
A1: TOSHIBA INTERNATIONAL CORPORATION
A2: INDUCTION MOTOR DATA SHEET
A3: File: | B3: CS2900U | I3: HRW / Model Number: | J3: 9003FTQL11F-C
A4: Type: TIKE - Form: FCW4 - 2 Pole - 900 HP - 4000 V - 60 Hz - 6811USS - Class F | Q4: Motor Type Selection | T4: Electrical Steel Table
A5: Motor Parameters | F5: PERFORMANCE | J5: DESIGN | K5: TEST | Q5: EPACT | T5: M22 - 26Ga.
A6: Material | D6: M36 - 26Ga. | F6: NL & Impedance Test | Q6: EQP-III | T6: M36 - 26Ga.
A7: Air Gap | D7: 3.5 | F7: No load amps | J7: 19.1 | K7: - | Q7: Exp.Prf. | T7: NCB1 - 26Ga.
A8: Stack length | D8: 550 | F8: No load watts | J8: 14421 | K8: - | Q8: Exp.Prf.-EQPIII | T8: M43 - 26Ga.
A9: Number of turns per coil | D9: 11 | F9: Impedance amps | H9: 3 | I9: f | J9: 183 | K9: - | Q9: Prem. Eff. | T9: M45 - 26Ga.
A10: Wire 1 (size & number) | D10: (.081"x.204")x2 | F10: Impedance volts | H10: 3 | I10: f | J10: 1150 | K10: - | Q10: OWP | T10: M54 - 26Ga.
A11: Wire 2 (size & number) | D11: - | F11: Impedance watts | H11: 3 | I11: f | J11: 21226 | K11: - | Q11: Dry Kiln
A12: Slot fill - circle/square method (%) | D12: - | F12: Temperature Rise (°C)
A13: Connection | D13: 2 x Wye | G13: Winding | I13: 80/115 | J13: 77 / 102 | K13: -
A14: MCL | D14: 1320 | G14: Frame | J14: - | K14: -
A15: Allowance for ins. depth | D15: 7.49 | G15: Bearing PS/OS | J15: - | K15: -
A16: Allowance for ins. width | D16: 3.34 | G16: End Ring | J16: - | K16: -
A17: Slot/Wire arrangement | D17: 22 x 2 | F17: Nameplate Data
A18: Effective cross section for coil | D18: - | H18: FLC (A) | J18: 109 | M18: =J18*6.5 -> 708.5
A19: Coil grouping | D19: Interspersed | H19: RPM | J19: 3580
A20: Coil pitch (slot number) | D20: 1 ~ 18 | H20: CODE | J20: F
A21: Method of coil connection | D21: - | H21: S. F. | J21: 1.15 | Q21: Method of Connection
A22: Resistance per phase @ 20 °C | D22: 0.1125 | H22: DESIGN | Q22: Skip
A23: Coil Weight | B23: Wire1 | D23: 655 | H23: Nom.Eff. (%): | Q23: Adjacent
A24: (lbs.) | B24: Wire2 | D24: - | H24: Min.Eff. (%): | Q24: -
A25: Current Densities (A/cm2) | E25: Bar / ER | H25: P.F. (%):
A26: FL / LR | D26: 263 / 1670 | E26: 331 / 296
A27: Stator Slot Shape (Reference) | F27: Performance
H28: LRC (A) | I28: - | J28: 692 | K28: - | M28: =(J28/J18)*100 -> 634.86239
H29: LRT (%) | I29: 60 | J29: 77 | K29: -
H30: BDT (%) | I30: 175 | J30: 276 | K30: -
H31: SLIP (%) | J31: 0.57 | K31: -
G32: IEEE-B | H32: Eff. (%) | J32: 95.3 | K32: -
A33: Rotor Slot Shape (Reference) | H33: PF (%) | J33: 93.3 | K33: -
F34: Losses (Watts) | H34: Primary | J34: 5401 | K34: -
H35: Secondary | J35: 3948 | K35: -
H36: Core | J36: 3337 | K36: -
H37: F & W | J37: 10961 | K37: -
H38: Stray | J38: 9451 | K38: -
A39: End Ring (Reference) | F39: Note
F40: LINK: | G40: FW2M20U.rat with FW2M20U_Lab1329A.dat
...

Sheet LoginSheet
J1: P | K1: T | L1: L | M1: T
B2: PROJECT HISTORY | J2: E | K2: D | L2: I | M2: Y | N2: H
J3: R | L3: M | M3: P
J4: F | L4: I | M4: E
K5: C | L5: T | N5: I
J6: D | K6: U | M6: T | N6: N
J7: A | K7: R | L7: R | M7: E | N7: S
I8: S | J8: T | K8: V | L8: E | M8: S | N8: U
B9: DATE | C9: PROJECT | D9: SMART NUMBER | E9: QTY | F9: CUSTOMER | G9: REMARKS | H9: LIMIT CODE | I9: F | J9: A | K9: E | L9: V | M9: T | N9: L
B53: REVISION HISTORY
B54: REV | C54: REMARKS | I54: DATE | L54: INIT

Sheet Performance Data Sheet
A1: TOSHIBA INTERNATIONAL CORPORATION | J1: INDEX | L1: MPCF-1033
A2: Industrial Division / Houston Motor Plant | J2: SHEET NO. | L2: 1 of 1
J3: ISSUED | L3: 7/31/13
J4: SUPERSEDES | L4: 11/8/96
J5: REVISION | L5: 2
A6: SQUIRREL CAGE INDUCTION MOTOR | J6: WRITTEN BY | L6: MDC
A7: PERFORMANCE SPECIFICATIONS | J7: APPROVED BY | L7: PAA
B9: CUSTOMER:
B10: TIC SR No.:
A12: MOTOR NAMEPLATE DATA
B13: H.P.: | C13: 900 | E13: VOLTS: | F13: 4000 | H13: 3 PH / | I13: 60 Hz | L13: S. RPM: | M13: 3600
B14: FRAME: | C14: 6811USS | E14: ENCL: | F14: TEFC | H14: FLAMPS: | I14: 109 | L14: FLRPM: | M14: 3580
B15: FORM: | C15: FCW4 | E15: S.F.: | F15: 1.15 | H15: NEMA DESIGN: | I15: - | L15: INSUL CLASS: | M15: F
B16: TYPE: | C16: TIKE | E16: AMB.: | F16: 40°C | H16: CODE: | I16: F | L16: DUTY: | M16: Cont.
B17: MODEL No.: | C17: 9003FTQL11E-C | H17: kW: | I17: -
B18: NOM. EFF.: | C18: - | E18: MIN. EFF.: | F18: - | H18: P.F.: | I18: -
A21: AMPERAGE | E21: TORQUES | I21: **BEARINGS:
C22: LOCKED ROTOR: | D22: 692 | G22: FULL LOAD (lb-ft): | H22: 1322 | K22: DRIVE END:
G23: LOCKED ROTOR (%): | H23: 75 | K23: OPPOSITE DRIVE END:
G24: BREAK DOWN (%): | H24: 275
A28: EFFICIENCY | H28: POWER FACTOR
C29: FULL LOAD: | D29: 95.3 | J29: FULL LOAD: | K29: 93.3
C30: 3/4 LOAD: | D30: 94.8 | J30: 3/4 LOAD: | K30: 92.9
C31: 1/2 LOAD: | D31: 93.6 | J31: 1/2 LOAD: | K31: 90.7
A35: ALL CHARACTERISTICS ARE AVERAGE EXPECTED VALUES BASED UPON RATED VOLTAGE,
A36: FREQUENCY AND SINEWAVE POWER INPUT.
A37: THE DECLARED LOCKED ROTOR CURRENT HAS A TOLERANCE OF 20%.
A38: * TEMPERATURE RISE WILL BE CONSISTENT WITH INSULATION, AMBIENT AND SERVICE FACTOR AS
A39: DEFINED BY NEMA-MG-12 OR -20.
A40: ** BEARINGS ARE THE ONLY RECOMMENDED SPARE PART(S).
J43: CERTIFIED BY: | K43: JERRY R
J45: DATE: | K45: 43273
A60: - | B60: 6205ZZ | D60: 1 | E60: -
A61: TEFC | B61: 6206UU | D61: 1.15 | E61: A
A62: ODP | B62: 6207ZZ | E62: B
B63: 6208UU
B64: 6211ZZ
B65: 6211C3
B66: 6211ZZC3
B67: 6305UUC3
...

Sheet STCurve
A2: TOSHIBA INTERNATIONAL CORPORATION
A3: Speed Torque/Current Curve
A6: Model #: | B6: ='Performance Data Sheet'!C17 -> 9003FTQL11E-C | E6: FLAmps: | F6: ='Performance Data Sheet'!I14 & " A" -> 109 A
A7: Enclosure: | B7: ='Performance Data Sheet'!F14 -> TEFC | C7: Voltage: | D7: ='Performance Data Sheet'!F13 & " V" -> 4000 V | E7: Frame: | F7: ='Performance Data Sheet'!C14 -> 6811USS
A8: Pole: | B8: 2 | C8: Frequency: | D8: 3 PH / 60 Hz | E8: Ins. Class: | F8: F
A9: HP: | B9: 900 | C9: Rotor Inertia: | D9: 361.7 lb-ft² | E9: Date: | F9: ='Performance Data Sheet'!K44 -> 0
A10: FLRPM: | B10: 3580 | C10: Load Inertia: | D10: N/A | E10: File: | F10: CS2900U
B12: Locked Rotor Amps: | C12: ='Performance Data Sheet'!D22 & " A" -> 692 A | D12: Load Type: | E12: N/A
B13: Locked Rotor Torque: | C13: 0.75 | D13: Starting at: | E13: N/A
B14: Breakdown Torque: | C14: 2.75 | D14: Accel. Time: | E14: N/A
B15: Rated Torque: | C15: 1322 lb-ft
A39: Comments: | B39: PROJECT | C39: ='Performance Data Sheet'!C10 -> 0 | E39: D.E.Curve #: | F39: =F10 -> CS2900U
C43: Prepared by: | D43: ='Performance Data Sheet'!K42 -> 0 | E43: Checked by: | F43: AG
A54: 100 | B54: 0 | C54: 0.15435272
A55: 99.8 | B55: 166.78826 | C55: 180.35881
A56: 99 | B56: 276 | C56: 505.79517
A57: 93.555555 | B57: 141.42678 | C57: 576.56549
A58: 88.11111 | B58: 108.02772 | C58: 594.63208
A59: 82.666667 | B59: 93.722334 | C59: 602.36859
A60: 71.777776 | B60: 84.38481 | C60: 610.49298
A61: 60.888889 | B61: 80.163222 | C61: 616.07507
A62: 50 | B62: 78 | C62: 620.6842
A63: 39.999998 | B63: 78.001745 | C63: 624.55719
A64: 30.000001 | B64: 78.003523 | C64: 627.80487
A65: 19.999999 | B65: 78.004773 | C65: 630.53833
... A67: 0 | B67: 78 | C67: 634.86237

Sheet Thermdam
A2: TOSHIBA INTERNATIONAL CORPORATION
A3: Thermal Limit & Acceleration Curves
A4: Design Values (For Reference Only)
A6: Model #: | B6: ='Performance Data Sheet'!C17 -> 9003FTQL11E-C | E6: FLAmps: | F6: ='Performance Data Sheet'!I14 & " A" -> 109 A
A7: Enclosure: | B7: ='Performance Data Sheet'!F14 -> TEFC | C7: Voltage: | D7: ='Performance Data Sheet'!F13 & " V" -> 4000 V | E7: Frame: | F7: ='Performance Data Sheet'!C14 -> 6811USS
A8: Pole: | B8: 2 | C8: Frequency: | D8: 3 PH / 60 Hz | E8: Ins. Class: | F8: F
A9: HP: | B9: 900 | C9: Rotor Inertia: | D9: 361.7 lb-ft² | E9: Date: | F9: ='Performance Data Sheet'!K44 -> 0
A10: FLRPM: | B10: 3580 | C10: Load Inertia: | D10: N/A | E10: File: | F10: CS2900U
A39: Comments: | B39: PROJECT | C39: ='Performance Data Sheet'!C10 -> 0 | E39: D.E.Curve #: | F39: =F10 -> CS2900U
C43: Prepared by: | D43: ='Performance Data Sheet'!K42 -> 0 | E43: Checked by: | F43: AG
F50: =5252.1*B50/D53 -> #DIV/0!
D66: =D65/D64 -> #DIV/0!
A67: Current (%) | B67: Cold | C67: Hot | E67: CURRENT (%) | F67: Accel. Time
A68: 634.86239 | B68: 35 | C68: 15 | E68: =A68 -> 634.86239 | F68: 0.0001
A69: 563.91535 | B69: =((A68/A69)^2)*B68 -> 44.360803 | C69: =((A68/A69)^2)*C68 -> 19.011773 | E69: 633.85321 | F69: 1.068
A70: 492.94703 | B70: =((A68/A70)^2)*B68 -> 58.053275 | C70: =((A68/A70)^2)*C68 -> 24.879975 | E70: 631.74312 | F70: 1.9599999
A71: 422 | B71: =((A68/A71)^2)*B68 -> 79.214071 | C71: =((A68/A71)^2)*C68 -> 33.948888 | E71: 629.17431 | F71: 2.7949998
A72: =A71-100 -> 322 | B72: =((A68/A72)^2)*B68 -> 136.05531 | E72: 626.14679 | F72: 3.6299999
A73: =A72-100 -> 222 | B73: =((A68/A73)^2)*B68 -> 286.23405 | E73: 622.66055 | F73: 4.5149999
A74: 276 | B74: =((A68/A74)^2)*B68 -> 185.18639 | C74: =((A68/A74)^2)*C68 -> 79.365597 | E74: 618.34862 | F74: 5.5799999
A75: 180 | B75: =((A68/A75)^2)*B69 -> 551.84052 | C75: =((A68/A75)^2)*C68 -> 186.59734 | E75: 613.30275 | F75: 6.803
A76: 120 | B76: =((A68/A76)^2)*B68 -> 979.63602 | C76: =((A68/A76)^2)*C68 -> 419.84401 | E76: 606.42202 | F76: 8.3009996
A77: 110 | C77: =CEILING(C76*2,100) -> 900 | E77: 598.53211 | F77: 9.1419992
A78: 110 | C78: =2*C77 -> 1800 | E78: 585.59633 | F78: 9.8059988
A79: 110 | C79: 10000 | E79: 541.19266 | F79: 10.078999
E80: 343.11927 | F80: 10.117998
E81: 0 | F81: 10.152998

Sheet Performance
A2: TOSHIBA INTERNATIONAL CORPORATION
A3: Performance Curve
A4: Design Values (For Reference Only)
A6: Model #: | B6: ='Performance Data Sheet'!C17 -> 9003FTQL11E-C | E6: FLAmps: | F6: ='Performance Data Sheet'!I14 & " A" -> 109 A
A7: Enclosure: | B7: ='Performance Data Sheet'!F14 -> TEFC | C7: Voltage: | D7: ='Performance Data Sheet'!F13 & " V" -> 4000 V | E7: Frame: | F7: ='Performance Data Sheet'!C14 -> 6811USS
A8: Pole: | B8: 2 | C8: Frequency: | D8: 3 PH / 60 Hz | E8: Ins. Class: | F8: F
A9: HP: | B9: 900 | C9: Rotor Inertia: | D9: 361.7 lb-ft² | E9: Date: | F9: ='Performance Data Sheet'!K44 -> 0
A10: FLRPM: | B10: 3580 | C10: Load Inertia: | D10: N/A | E10: File: | F10: CS2900U
B12: Locked Rotor Amps: | C12: ='Performance Data Sheet'!D22 & " A" -> 692 A | D12: Load Type: | E12: N/A
B13: Locked Rotor Torque: | C13: 0.75 | D13: Starting at: | E13: N/A
B14: Breakdown Torque: | C14: 2.75 | D14: Accel. Time: | E14: N/A
B15: Rated Torque: | C15: 1322 lb-ft
A39: Comments: | B39: PROJECT | C39: ='Performance Data Sheet'!C10 -> 0 | E39: D.E.Curve #: | F39: =F10 -> CS2900U
C43: Prepared by: | D43: ='Performance Data Sheet'!K42 -> 0 | E43: Checked by: | F43: AG
I52: 25 | J52: 50 | K52: 75 | L52: 100 | M52: 125
A53: Load | B53: Efficiency | C53: PF | D53: Amps | E53: RPM | F53: Input Watts | I53: 32.56 / 33.52 | J53: 55.43 / 57.06 | K53: 80.17 / 82.54 | L53: 105.91 / 109.03 | M53: 132.55 / 136.45
A54: 0 | D54: 19.1 | E54: 100 | F54: 2 | I54: 0.907 / 0.897 | J54: 0.947 / 0.936 | K54: 0.959 / 0.948 | L54: 0.964 / 0.953 | M54: 0.966 / 0.955
A55: 25 | B55: 89.7 | C55: 80.840988 | D55: 33.5 | E55: 84.953781 | F55: 10.400191 | I55: 0.820 / 0.806 | J55: 0.923 / 0.907 | K55: 0.945 / 0.929 | L55: 0.949 / 0.933 | M55: 0.946 / 0.930
A56: 50 | B56: 93.6 | C56: 90.806557 | D56: 57 | E56: 73.173275 | F56: 19.926361 | I56: 0.0014 / 0.0017 | J56: 0.0027 / 0.0030 | K56: 0.0040 / 0.0043 | L56: 0.0054 / 0.0057 | M56: 0.0067 / 0.0070
A57: 75 | B57: 94.8 | C57: 92.914452 | D57: 82.5 | E57: 61.163878 | F57: 29.509159 | I57: 3595.1 / 3594.0 | J57: 3590.4 / 3589.3 | K57: 3585.7 / 3584.6 | L57: 3580.7 / 3579.6 | M57: 3575.9 / 3574.8
A58: 100 | B58: 95.3 | C58: 93.291389 | D58: 109 | E58: 48.739248 | F58: 39.153878
A59: 125 | B59: 95.5 | C59: 93.000137 | D59: 136 | E59: 36.621944 | F59: 48.862134

Sheet Form
A1: Winding Data Calculation
C2: MCL: 1320.0
A3: Coil Resistance | D3: Lead Resistance
A4: 11T: | B4: 0.0253 ~ 0.0243 | D4: AWG. 1/0 x 3
D5: 0.00099
A6: Coil Dimensions
A7: HM: | B7: 11T: 25.93 | C7: WM: | D7: 11T: 10.96 | E7: WT:
E8: 13.82 ~ 13.62
A9: Insulation Allowance | D9: Wire Weight
A10: Depth: | B10: 7.49 | D10: (.081"x.204")x 2: | F10: 655 lbs.
A11: Width: | B11: 3.34
A12: QC Resistance
A13: 1-2, 2-3, 3-1: | C13: 0.232 ~ 0.218

Sheet StallTime
A1: Rating: | B1: 2 Pole - 900.0 HP - 3600 RPM - 4000 V - 60 Hz
A3: Starting Performance
D4: Load Type: Fan / Pump - 307.5 lb-ft²
A5: RPM | B5: Motor | C5: Load | D5: Accel. | E5: Line | F5: Stator | G5: Rotor
A6: Speed Increment | B6: Torque (%) | C6: Torque (%) | D6: Time (s) | E6: Amps | F6: kW / s | G6: kW / s
A7: 0~360 | B7: 78.0 | C7: 22.5 | D7: 1.068 | E7: 690.9 | F7: 225.1 | G7: 734.2
A8: 360~720 | B8: 78.0 | C8: 11.5 | D8: 0.892 | E8: 688.6 | F8: 186.7 | G8: 551.6
A9: 720~1080 | B9: 78.0 | C9: 7.0 | D9: 0.835 | E9: 685.8 | F9: 173.6 | G9: 459.2
A10: 1080~1440 | B10: 78.0 | C10: 7.0 | D10: 0.835 | E10: 682.5 | F10: 172.1 | G10: 401.8
A11: 1440~1800 | B11: 78.0 | C11: 11.0 | D11: 0.885 | E11: 678.7 | F11: 180.5 | G11: 364.9
A12: 1800~2192 | B12: 79.1 | C12: 18.5 | D12: 1.065 | E12: 674.0 | F12: 214.6 | G12: 336.2
A13: 2192~2584 | B13: 82.3 | C13: 29.5 | D13: 1.223 | E13: 668.5 | F13: 242.6 | G13: 310.2
A14: 2584~2976 | B14: 89.1 | C14: 45.9 | D14: 1.498 | E14: 661.0 | F14: 291.9 | G14: 288.7
A15: 2976~3172 | B15: 100.9 | C15: 62.5 | D15: 0.841 | E15: 652.4 | F15: 159.5 | G15: 221.0
A16: 3172~3368 | B16: 124.7 | C16: 76.2 | D16: 0.664 | E16: 638.3 | F16: 122.8 | G16: 138.1
... A19: 3593~3600 | B19: 133.4 | C19: 99.8 | D19: 0.035 | E19: 107.5 | F19: 0.2 | G19: 13.9
D21: Acceleration Time: 10.2 s
B22: Energy | D22: First Start | F22: Second Start
A23: Stator Winding Rise | B23: 2022 kW / s | D23: 18°C | F23: 36°C
A24: Rotor Bar Rise | B24: 2775 kW / s | D24: 69°C | F24: 138°C
A25: End Ring Rise | B25: 1097 kW / s | D25: 54°C | F25: 107°C
A27: Locked Rotor Thermal Capability
E28: Cold Condition
B29: Rate of Rise | D29: Power | E29: Rise Limit | F29: Max Time
A30: Stator Copper | B30: 2.3°C / s | D30: 252.9 kW | E30: 160°C | F30: 70.3 s
A31: Rotor Bar | B31: 9.3°C / s | D31: 375.3 kW | E31: 260°C | F31: 27.9 s
A32: Rotor ER | B32: 7.2°C / s | D32: 148.4 kW | E32: 180°C | F32: 24.8 s
E34: Hot Condition
B35: Hot Temp. | D35: Rise Limit | E35: Ambient | F35: Total | G35: Max.Time
A36: Stator Copper | B36: 77°C + | D36: 83°C + | E36: 40°C | F36: = 200°C | G36: 36.5 s
A37: Rotor Bar | B37: 105°C + | D37: 155°C + | E37: 40°C | F37: = 300°C | G37: 16.7 s
A38: Rotor ER | B38: 105°C + | D38: 75°C + | E38: 40°C | F38: = 220°C | G38: 10.4 s
A40: Cold Stall Time: | B40: 39.3 s | D40: Hot Stall Time: | F40: 16.5 s

Sheet MagNoise
A1: Magnetic Noise Verification
A3: Rating: | B3: 2 Pole - 900.0 HP - 3600 RPM - 4000 V - 60 Hz
A5: Electromagnetic Excitation Frequencies
B7: L = | C7: 0 | D7: L = | E7: + 1 | F7: L = | G7: - 1 | H7: Slip = | I7: 0 | J7: Slip = | K7: 0.005
A8: Mode A | B8: 6 | D8: 12 | F8: 0 | H8: 2880.0 Hz | J8: 2865.2 Hz
A9: Mode B | B9: 10 | D9: 16 | F9: 4 | H9: 2640.0 Hz | J9: 2625.2 Hz
A10: Mode C | B10: 8 | D10: 14 | F10: 2 | H10: 2760.0 Hz | J10: 2745.2 Hz
A12: Natural Frequencies of Stator Core
B14: Mode 0 = | D14: 2288.2 Hz | F14: Mode 6 = | H14: 7747.0 Hz
B15: Mode 2 = | D15: 602.1 Hz | F15: Mode 7 = | H15: 10662.8 Hz
B16: Mode 3 = | D16: 1703.1 Hz | F16: Mode 8 = | H16: 14027.8 Hz
B17: Mode 4 = | D17: 3265.4 Hz | F17: Mode 9 = | H17: 17841.9 Hz
B18: Mode 5 = | D18: 5280.9 Hz | F18: Mode 10 = | H18: 22105.0 Hz
A20: Analysis Results
B22: No matching frequencies detected.
