Workbook
Name Print_Area_MI: 'Performance Data Sheet'!$A$10:$N$42

Sheet DesignSheet
A1: TOSHIBA INTERNATIONAL CORPORATION | I1: Calc. Code: | J1: 2-2-2-0-1-2
A2: 3-PHASE SQUIRREL CAGE INDUCTION MOTOR DESIGN SHEET | J2: B.L.-1 P.F.-1
A3: File: | B3: N:\DESPRO\RAT FILES\1T4450K REV1.rat | G3: Date: | H3: 45797 | I3: Time: | J3: 0.29847222
A4: Pole | B4: HP | C4: RPM | D4: Form | E4: Voltage | F4: Frequency | G4: Temperature | H4: FLSpeed | I4: FLSlip | J4: Frame
A5: 4 | B5: 450.00002 | C5: 1800 | D5: DCKW | E5: 4000 | F5: 60 | G5: 105 | H5: 1776.3 / 1770.6 | I5: 0.0131 / 0.0163 | J5: 5012
A6: Core Data | D6: Winding Data | H6: Constant Data
B7: Primary | C7: Secondary | F7: Bar | G7: End Ring | H7: St. Slot Pitch | I7: 20.420335 | J7: LR Test Data
A8: Air Gap | B8: 1.7 | H8: Rt. Slot Pitch | I8: 27.603152 | J8: ES
A9: Space Fac. | B9: 0.93000001 | D9: Pitch | E9: 1 ~ 14 | F9: Cross Section Area | H9: Mean Value | I9: 24.011744 | J9: 558.28775
A10: Core Length | B10: 395 | C10: 395 | F10: UB: 264.6 | G10: UER: 2000.0 | H10: Eff.T.W.St. | I10: 12.416524 | J10: WS
A11: OD | B11: 590 | C11: 386.6 | D11: Coil Pitch | E11: 0.86658 | G11: ERT: 50.0 | H11: Eff.T.W.Rt. | I11: 27.603152 | J11: 20793.029
A12: ID | B12: 390 | C12: 220 | D12: Slot Fill | E12: - | G12: ERD1: 299.0 | H12: St.Carter Fac. | I12: 1.2245199 | J12: IS
A13: Core Depth | B13: 54 | C13: 55.500001 | D13: Con./Slot | E13: 17 | G13: ERD2: 385.0 | H13: Rt.Carter Fac. | I13: 1 | J13: 59.428177
A14: Eff.Core L. | B14: 292.95001 | C14: 292.95001 | D14: Wire Size 1 | E14: (.064"x.162")x1 | H14: Carter Factor | I14: 1.2245199 | J14: Volts / Turn
A15: Slot Data | D15: Wire Size 2 | E15: (.064"x.144")x1 | H15: Short. Factor | I15: 0.97811905 | J15: 13.58511
A16: Number | B16: 60 | C16: 44 | D16: // Circuits | E16: 1 | H16: Distrib. Factor | I16: 0.956506 | J16: AC
A17: Kind | B17: Open | C17: Dbl - Closed | D17: Connection | E17: Wye | H17: Wind. Factor | I17: 0.93557674 | J17: 494.74164
A18: Skew | B18: - | C18: 0 | D18: MCL | E18: 900 | F18: 445 | H18: Reactance | I18: (Coeff.: 0.0983)
A19: Depth | B19: 46 | C19: 27.799999 | D19: No.Cond./Ph. | E19: 340 | I19: Running | J19: Start
A20: Width | B20: 8.00 - 8.00 | D20: Res. (20°C) | E20: 0.44359049 | H20: Stator Slot | I20: 18.694345 | J20: 18.694345
A21: Opening | B21: 11.6 | C21: 0 | D21: (105°C) | E21: 0.59174449 | F21: 0.50559175 | G21: 0.090697716 | H21: Rotor Slot | I21: 31.934114 | J21: 18.105618
A22: Tip Depth | B22: 2.8299999 | C22: 0.80000001 | D22: Material | E22: CU | F22: AL | G22: AL | H22: Zigzag | I22: 8.255125 | J22: 5.8281155
A23: T.Min.Wid. | B23: 8.8203344 | C23: 12 | D23: Spec.Resist. | E23: 1.742 | F23: 3.25 | G23: 3.25 | H23: Coil End | I23: 17.445523 | J23: Skew R.: 0.00
A24: Low. R. | B24: 0 | C24: 2 | D24: Spec.Gravity | E24: 8.8900003 | F24: 2.6700001 | G24: 2.6700001 | H24: Belt Leakage | I24: 5.4616211 | J24: 3.8559028
A25: Up. R. | B25: - | C25: 2 | D25: Weight (kg) | H25: Total Resist. | I25: 1.1880339 | J25: 1.9625092
A26: Wedge Dep. | B26: 2.83 - 0.50 | C26: Magnetic | D26: Wire 1 | E26: 52.067241 | F26: 12.278477 | G26: 12.011681 | H26: Total React. | I26: 8.040904 | J26: 6.2849541
A27: Duct | B27: 8 x 10 | C27: 8 x 10 | D27: Wire 2 | E27: 46.001771 | F27: - | G27: - | H27: Impedance | I27: 8.1281948 | J27: 6.5842304
A28: Effective Depth (S=1) | D28: Magnetic Circuit Data | I28: Core Loss Data
B29: Res.= | C29: 26.996181 | E29: Length | F29: Section | G29: Density | H29: AT | I29: Volume | J29: Loss | M29: =RIGHT(F$41,SEARCH("/",F$41,1)-1) -> 1764.5 | N29: 125RPM | P29: Kline/in2
B30: Reac.= | C30: 26.998908 | D30: Primary Core | E30: 23.169226 | F30: 316.38601 | G30: 17.227897 | H30: 531.28765 | I30: 26637.998 | J30: 2281.1916 | M30: =RIGHT(E$41,SEARCH("/",E$41,1)-1) -> 1770.6 | N30: 100RPM | P30: =G30*6.4516 -> 111.1475
A31: Excitation Data | D31: Tooth | E31: 4.6 | F31: 387.58756 | G31: 14.063056 | H31: 40.545021 | I31: 7131.6111 | J31: 439.58282 | M31: =RIGHT(D$41,SEARCH("/",D$41,1)-1) -> 1776.7 | N31: 75RPM | P31: =G31*6.4516 -> 90.729211
A32: Excit.Amps | B32: 21.179 / 18.799 | D32: Second.Core | E32: 12.998329 | F32: 325.17452 | G32: 16.762278 | H32: 259.41767 | I32: Total | J32: 2720.7745 | M32: =RIGHT(C$41,SEARCH("/",C$41,1)-1) -> 1782.6 | N32: 50RPM | P32: =G32*6.4516 -> 108.14351
A33: Core Loss | B33: 0.735 / 0.652 | C33: Flux / Pole | D33: Tooth | E33: 2.7799999 | F33: 386.69402 | G33: 14.095552 | H33: 24.704487 | I33: C.L.C. | J33: 1.50 / 1.10 | M33: =RIGHT(B$41,SEARCH("/",B$41,1)-1) -> 1787.0 | N33: 25RPM | P33: =G33*6.4516 -> 90.938862
A34: NoLoad | B34: 21.19 / 18.81 | C34: 5.4506655 | D34: Air Gap | E34: 0.17 | F34: 787.95028 | G34: 6.9175247 | H34: 935.81533 | I34: S.F.C. | J34: 6.0500002 | P34: =G34*6.4516 -> 44.629102
A35: Load Characteristics | D35: Temp. Rise @ 100%: | E35: 63 / 62 | G35: No Load Loss | H35: 7293.2 / 7401.1 | I35: W.Loss | J35: 4081.2 / 2994.0
A36: Load (%) | B36: 25 | C36: 50 | D36: 75 | E36: 100 | F36: 125 | G36: Primary Loss | H36: 6269.6 / 7096.9 | I36: S.Loss | J36: 1015.1 / 744.7
A37: Current (A) | B37: 23.24 / 23.77 | C37: 35.36 / 36.16 | D37: 46.71 / 47.76 | E37: 59.43 / 60.77 | F37: 73.13 / 74.78 | G37: Second. Loss | H37: 4633.4 / 5622.9 | I37: Total C.Loss | J37: 5096.3 / 3738.7
A38: Efficiency | B38: 0.914 / 0.895 | C38: 0.945 / 0.925 | D38: 0.952 / 0.932 | E38: 0.952 / 0.932 | F38: 0.949 / 0.929 | G38: Frict.& Wind. | H38: 1600.0 / 3440.4 | I38: Stray Loss | J38: 4527.4238 | L38: =LEFT(E38,SEARCH("/",E38,1)-1) -> 0.952 | M38: =RIGHT(E38,SEARCH("/",E38,1)-1) -> 0.932 | N38: =M38/L38 -> 0.9789916 | O38: Eff.
A39: P.F. | B39: 0.570 / 0.569 | C39: 0.725 / 0.724 | D39: 0.817 / 0.816 | E39: 0.856 / 0.855 | F39: 0.873 / 0.872 | G39: Starting Data | I39: Slip | J39: PF | L39: =LEFT(E39,SEARCH("/",E39,1)-1) -> 0.856 | M39: =RIGHT(E39,SEARCH("/",E39,1)-1) -> 0.855 | N39: =M39/L39 -> 0.99883178 | O39: PF.
A40: Slip | B40: 0.0040 / 0.0072 | C40: 0.0065 / 0.0097 | D40: 0.0098 / 0.0129 | E40: 0.0131 / 0.0163 | F40: 0.0166 / 0.0197 | G40: LRA | H40: 350.8 / 368.1 | L40: =LEFT(E37,SEARCH("/",E37,1)-1) -> 59.43 | M40: 61 | N40: =M40/L40 -> 1.0264176 | O40: Current
...

Sheet Data Sheet
A1: TOSHIBA INTERNATIONAL CORPORATION
A2: INDUCTION MOTOR DATA SHEET
A3: File: | B3: 1T4450K REV1 | I3: HRW / Model Number: | J3: 4504WTAK11F-A
A4: Type: TIKK - Form: DCKW - 4 Pole - 450 HP - 2300 / 4000 V - 60 Hz - 5012 - Class F | Q4: Motor Type Selection | T4: Electrical Steel Table
A5: Motor Parameters | F5: PERFORMANCE | J5: DESIGN | K5: TEST | Q5: EPACT | T5: M22 - 26Ga.
A6: Material | D6: NCB1 - 26Ga. | F6: NL & Impedance Test | Q6: EQP-III | T6: M36 - 26Ga.
A7: Air Gap | D7: 1.7 | F7: No load amps | J7: 33 / 18.8 | K7: - | Q7: Exp.Prf. | T7: NCB1 - 26Ga.
A8: Stack length | D8: 395 | F8: No load watts | J8: 7401 | K8: - | Q8: Exp.Prf.-EQPIII | T8: M43 - 26Ga.
A9: Number of turns per coil | D9: 8,9 | F9: Impedance amps | H9: 3 | I9: f | J9: 122 | K9: - | Q9: Prem. Eff. | T9: M45 - 26Ga.
A10: Wire 1 (size & number) | D10: (.064"x.162")x1 | F10: Impedance volts | H10: 3 | I10: f | J10: 1150 | K10: - | Q10: Standard Eff. | T10: M54 - 26Ga.
A11: Wire 2 (size & number) | D11: (.064"x.144")x1 | F11: Impedance watts | H11: 3 | I11: f | J11: 20793 | K11: - | Q11: OWP | T11: TIPA Lam
A12: Slot fill - circle/square method (%) | D12: - | F12: Temperature Rise (°C) | Q12: Dry Kiln
A13: Connection | D13: 1D / 1Y | G13: Winding | I13: 80/115 | J13: 63 / 83 | K13: -
A14: MCL | D14: 900 | G14: Frame | J14: - | K14: -
A15: Allowance for ins. depth | D15: 12.134799 | G15: Bearing PS/OS | J15: - | K15: -
A16: Allowance for ins. width | D16: 3.4276006 | G16: End Ring | J16: - | K16: -
A17: Slot/Wire arrangement | D17: 17 x 2 | F17: Nameplate Data
A18: Effective cross section for coil | D18: - | H18: FLC (A) | J18: 106 / 61
A19: Coil grouping | D19: - | H19: RPM | J19: 1770
A20: Coil pitch (slot number) | D20: 1 ~ 14 | H20: CODE | J20: G
A21: Method of coil connection | D21: - | H21: S. F. | J21: 1.15 | Q21: Method of Connection
A22: Resistance per phase @ 20 °C | D22: 0.4436 | H22: DESIGN | J22: - | Q22: Skip
A23: Coil Weight | B23: Wire1 | D23: 114.5 | H23: Nom.Eff. (%): | J23: - | Q23: Adjacent
A24: (lbs.) | B24: Wire2 | D24: 101.2 | H24: Min.Eff. (%): | J24: - | Q24: -
A25: Current Densities (A/cm2) | E25: Bar / ER | H25: P.F. (%): | J25: -
A26: FL / LR | D26: 506 / 3053 | E26: 427 / 198
A27: Stator Slot Shape (Reference) | F27: Performance
H28: LRC (A) | I28: 708 / 409 | J28: 637/ 368 | K28: -
H29: LRT (%) | I29: 80 | J29: 150 | K29: -
H30: BDT (%) | I30: 175 | J30: 284 | K30: -
H31: SLIP (%) | J31: 1.63 | K31: -
G32: IEEE-B | H32: Eff. (%) | J32: 93.2 | K32: -
A33: Rotor Slot Shape (Reference) | H33: PF (%) | J33: 85.5 | K33: -
F34: Losses (Watts) | H34: Primary | J34: 7097 | K34: -
H35: Secondary | J35: 5623 | K35: -
H36: Core | J36: 3739 | K36: -
H37: F & W | J37: 3440 | K37: -
H38: Stray | J38: 4527 | K38: -
A39: End Ring (Reference) | F39: Note
F40: LINK: 1T4450K.RAT AND DAT
...

Sheet Performance Data Sheet
A1: TOSHIBA INTERNATIONAL CORPORATION | J1: INDEX | L1: MPCF-1033
A2: Industrial Division / Houston Motor Plant | J2: SHEET NO. | L2: 1 of 1
J3: ISSUED | L3: 7/31/13
J4: SUPERSEDES | L4: 11/8/96
J5: REVISION | L5: 2
A6: SQUIRREL CAGE INDUCTION MOTOR | J6: WRITTEN BY | L6: MDC
A7: PERFORMANCE SPECIFICATIONS | J7: APPROVED BY | L7: PAA
B9: CUSTOMER:
B10: TIC SR No.:
A12: MOTOR NAMEPLATE DATA
B13: H.P.: | C13: 450 | E13: VOLTS: | F13: 4000 | H13: 3 PH / | I13: 60 Hz | L13: S. RPM: | M13: 1800
B14: FRAME: | C14: 5012US | E14: ENCL: | F14: WP-II | H14: FLAMPS: | I14: 61 | L14: FLRPM: | M14: 1770
B15: FORM: | C15: DCKW | E15: S.F.: | F15: 1.15 | H15: NEMA DESIGN: | I15: - | L15: INSUL CLASS: | M15: F
B16: TYPE: | C16: TIKK | E16: AMB.: | F16: 40 | H16: CODE: | I16: G | L16: DUTY: | M16: Cont.
B17: MODEL No.: | H17: kW: | I17: -
B18: NOM. EFF.: | C18: - | E18: MIN. EFF.: | F18: - | H18: P.F.: | I18: -
A21: AMPERAGE | E21: TORQUES | I21: **BEARINGS:
C22: LOCKED ROTOR: | D22: 368 | G22: FULL LOAD (lb-ft.): | H22: 1335 | K22: DRIVE END:
G23: LOCKED ROTOR (%): | H23: 150 | K23: OPPOSITE DRIVE END:
G24: BREAK DOWN (%): | H24: 280
A28: EFFICIENCY | H28: POWER FACTOR
C29: FULL LOAD: | D29: 93.2 | J29: FULL LOAD: | K29: 85.5
C30: 3/4 LOAD: | D30: 93.2 | J30: 3/4 LOAD: | K30: 81.6
C31: 1/2 LOAD: | D31: 92.5 | J31: 1/2 LOAD: | K31: 72.4
A35: ALL CHARACTERISTICS ARE AVERAGE EXPECTED VALUES BASED UPON RATED VOLTAGE,
A36: FREQUENCY AND SINEWAVE POWER INPUT.
A37: THE DECLARED LOCKED ROTOR CURRENT HAS A TOLERANCE OF 20%.
A38: * TEMPERATURE RISE WILL BE CONSISTENT WITH INSULATION, AMBIENT AND SERVICE FACTOR AS
A39: DEFINED BY NEMA-MG-12 OR -20.
A40: ** BEARINGS ARE THE ONLY RECOMMENDED SPARE PART(S).
J42: CERTIFIED BY: | K42: Jerry R
J44: DATE: | K44: 45797
A59: - | B59: 6205ZZ | D59: 1 | E59: -
A60: TEFC | B60: 6206UU | D60: 1.15 | E60: A
A61: ODP | B61: 6207ZZ | E61: B
B62: 6208UU
B63: 6211ZZ
B64: 6211C3
B65: 6211ZZC3
B66: 6305UUC3
...

Sheet STCurve
A2: TOSHIBA INTERNATIONAL CORPORATION
A3: Speed Torque/Current Curve
A6: Model #: | B6: ='Performance Data Sheet'!C17 -> 0 | E6: FLAmps: | F6: ='Performance Data Sheet'!I14 & " A" -> 61 A
A7: Enclosure: | B7: ='Performance Data Sheet'!F14 -> WP-II | C7: Voltage: | D7: ='Performance Data Sheet'!F13 & " V" -> 4000 V | E7: Frame: | F7: ='Performance Data Sheet'!C14 -> 5012US
A8: Pole: | B8: 4 | C8: Frequency: | D8: 3 PH / 60 Hz | E8: Ins. Class: | F8: F
A9: HP: | B9: 450 | C9: Rotor Inertia: | D9: 158.6 lb-ft² | E9: Date: | F9: ='Performance Data Sheet'!K44 -> 45797
A10: FLRPM: | B10: 1770 | C10: Load Inertia: | D10: N/A | E10: File: | F10: 1T4450K REV1
B12: Locked Rotor Amps: | C12: ='Performance Data Sheet'!D22 & " A" -> 368 A | D12: Load Type: | E12: N/A
B13: Locked Rotor Torque: | C13: 1.5 | D13: Starting at: | E13: N/A
B14: Breakdown Torque: | C14: 2.8 | D14: Accel. Time: | E14: N/A
B15: Rated Torque: | C15: 1335 lb-ft
A39: Comments: | B39: PROJECT | C39: ='Performance Data Sheet'!C10 -> 0 | E39: D.E.Curve #: | F39: =F10 -> 1T4450K REV1
B40: ASSUMED 1/2 NEMA
C43: Prepared by: | D43: ='Performance Data Sheet'!K42 -> Jerry R | E43: Checked by:
A54: 100 | B54: 0 | C54: 0.34741074
A55: 99.6 | B55: 60.590668 | C55: 70.554398
A56: 98 | B56: 229.88257 | C56: 266.98489
A57: 96 | B57: 280 | C57: 411.84152
A58: 90 | B58: 185.59793 | C58: 482.46722
A59: 84 | B59: 148.13775 | C59: 519.28949
A60: 72 | B60: 117.66236 | C60: 553.9834
A61: 59.999999 | B61: 105 | C61: 569.90985
A62: 50 | B62: 105.27217 | C62: 579.31757
A63: 39.999998 | B63: 106.7749 | C63: 585.94666
A64: 30.000001 | B64: 110.32032 | C64: 591.20007
A65: 19.999999 | B65: 117.19705 | C65: 595.67755
... A67: 0 | B67: 150 | C67: 603.27869

Sheet Thermdam
A2: TOSHIBA INTERNATIONAL CORPORATION
A3: Thermal Limit & Acceleration Curves
A4: Design Values (For Reference Only)
A6: Model #: | B6: ='Performance Data Sheet'!C17 -> 0 | E6: FLAmps: | F6: ='Performance Data Sheet'!I14 & " A" -> 61 A
A7: Enclosure: | B7: ='Performance Data Sheet'!F14 -> WP-II | C7: Voltage: | D7: ='Performance Data Sheet'!F13 & " V" -> 4000 V | E7: Frame: | F7: ='Performance Data Sheet'!C14 -> 5012US
A8: Pole: | B8: 4 | C8: Frequency: | D8: 3 PH / 60 Hz | E8: Ins. Class: | F8: F
A9: HP: | B9: 450 | C9: Rotor Inertia: | D9: 158.6 lb-ft² | E9: Date: | F9: ='Performance Data Sheet'!K44 -> 45797
A10: FLRPM: | B10: 1770 | C10: Load Inertia: | D10: N/A | E10: File: | F10: 1T4450K REV1
A39: Comments: | B39: PROJECT | C39: ='Performance Data Sheet'!C10 -> 0 | E39: D.E.Curve #: | F39: =F10 -> 1T4450K REV1
B40: ASSUMED 1/2 NEMA
C43: Prepared by: | D43: ='Performance Data Sheet'!K42 -> Jerry R | E43: Checked by:
F50: =5252.1*B50/D53 -> #DIV/0!
D66: =D65/D64 -> #DIV/0!
A67: Current (%) | B67: Cold | C67: Hot | E67: CURRENT (%) | F67: Accel. Time
A68: 603.27869 | B68: 14.3683 | C68: 7.740422 | E68: =A68 -> 603.27869 | F68: 0.0001
A69: =FLOOR(A68,100) -> 600 | B69: =((A68/A69)^2)*B68 -> 14.525759 | C69: =((A68/A69)^2)*C68 -> 7.8252479 | E69: 601.47541 | F69: 0.38100001
A70: =A69-100 -> 500 | B70: =((A68/A70)^2)*B68 -> 20.917094 | C70: =((A68/A70)^2)*C68 -> 11.268357 | E70: 597.70492 | F70: 0.78000003
A71: =A70-100 -> 400 | B71: =((A68/A71)^2)*B68 -> 32.682959 | C71: =((A68/A71)^2)*C68 -> 17.606808 | E71: 593.44262 | F71: 1.1980001
A72: =A71-100 -> 300 | B72: =((A68/A72)^2)*B68 -> 58.103038 | E72: 588.52459 | F72: 1.6380001
A73: =A72-100 -> 200 | B73: =((A68/A73)^2)*B68 -> 130.73183 | E73: 582.62295 | F73: 2.108
A74: 280 | B74: =((A68/A74)^2)*B68 -> 66.699916 | C74: =((A68/A74)^2)*C68 -> 35.932261 | E74: 574.59016 | F74: 2.6210001
A75: 180 | B75: =((A68/A75)^2)*B69 -> 163.16605 | C75: =((A68/A75)^2)*C68 -> 86.947199 | E75: 561.96721 | F75: 3.2740002
A76: 145 | B76: =((A68/A76)^2)*B68 -> 248.71693 | C76: =((A68/A76)^2)*C68 -> 133.9876 | E76: 536.55738 | F76: 3.9020002
A77: 125 | C77: =CEILING(C76*2,100) -> 300 | E77: 500.81967 | F77: 4.1690001
A78: 125 | C78: =2*C77 -> 600 | E78: 447.21311 | F78: 4.3470001
A79: 125 | C79: 10000 | E79: 339.34426 | F79: 4.402
E80: 0 | F80: 4.447

Sheet Performance 4000V
A2: TOSHIBA INTERNATIONAL CORPORATION
A3: Performance Curve
A4: Design Values (For Reference Only)
A6: Model #: | B6: ='Performance Data Sheet'!C17 -> 0 | E6: FLAmps: | F6: ='Performance Data Sheet'!I14 & " A" -> 61 A
A7: Enclosure: | B7: ='Performance Data Sheet'!F14 -> WP-II | C7: Voltage: | D7: ='Performance Data Sheet'!F13 & " V" -> 4000 V | E7: Frame: | F7: ='Performance Data Sheet'!C14 -> 5012US
A8: Pole: | B8: 4 | C8: Frequency: | D8: 3 PH / 60 Hz | E8: Ins. Class: | F8: F
A9: HP: | B9: 450 | C9: Rotor Inertia: | D9: 158.6 lb-ft² | E9: Date: | F9: ='Performance Data Sheet'!K44 -> 45797
A10: FLRPM: | B10: 1770 | C10: Load Inertia: | D10: N/A | E10: File: | F10: 1T4450K REV1
B12: Locked Rotor Amps: | C12: ='Performance Data Sheet'!D22 & " A" -> 368 A | D12: Load Type: | E12: N/A
B13: Locked Rotor Torque: | C13: 1.5 | D13: Starting at: | E13: N/A
B14: Breakdown Torque: | C14: 2.8 | D14: Accel. Time: | E14: N/A
B15: Rated Torque: | C15: 1335 lb-ft
A39: Comments: | B39: PROJECT | C39: ='Performance Data Sheet'!C10 -> 0 | E39: D.E.Curve #: | F39: =F10 -> 1T4450K REV1
B40: ASSUMED 1/2 NEMA
C43: Prepared by: | D43: ='Performance Data Sheet'!K42 -> Jerry R | E43: Checked by:
A53: Load | B53: Efficiency | C53: PF | D53: Amps | E53: RPM | F53: Input Watts
A54: 0 | D54: 21.751524 | E54: 100 | F54: 0.74011
A55: 25 | B55: 89.51255 | C55: 56.932983 | D55: 23.85523 | E55: 66.295523 | F55: 9.4092596
A56: 50 | B56: 92.518555 | C56: 72.416573 | D56: 36.290646 | E56: 55.205841 | F56: 18.20709
A57: 75 | B57: 93.205276 | C57: 81.621056 | D57: 47.941334 | E57: 40.44862 | F57: 27.109417
A58: 100 | B58: 93.202438 | C58: 85.537231 | D58: 60.997078 | E58: 25.325668 | F58: 36.146987
A59: 125 | B59: 92.905251 | C59: 87.166992 | D59: 75.060104 | E59: 9.8962972 | F59: 45.328265

Sheet Performance 2300V
A2: TOSHIBA INTERNATIONAL CORPORATION
A3: Performance Curve
A4: Design Values (For Reference Only)
A6: Model #: | B6: ='Performance Data Sheet'!C17 -> 0 | E6: FLAmps: | F6: 106 A
A7: Enclosure: | B7: ='Performance Data Sheet'!F14 -> WP-II | C7: Voltage: | D7: 2300 V | E7: Frame: | F7: ='Performance Data Sheet'!C14 -> 5012US
A8: Pole: | B8: 4 | C8: Frequency: | D8: 3 PH / 60 Hz | E8: Ins. Class: | F8: F
A9: HP: | B9: 450 | C9: Rotor Inertia: | D9: 158.6 lb-ft² | E9: Date: | F9: ='Performance Data Sheet'!K44 -> 45797
A10: FLRPM: | B10: 1770 | C10: Load Inertia: | D10: N/A | E10: File: | F10: 1T4450K REV1
B12: Locked Rotor Amps: | C12: 637 A | D12: Load Type: | E12: N/A
B13: Locked Rotor Torque: | C13: 1.5 | D13: Starting at: | E13: N/A
B14: Breakdown Torque: | C14: 2.8 | D14: Accel. Time: | E14: N/A
B15: Rated Torque: | C15: 1335 lb-ft
A39: Comments: | B39: PROJECT | C39: ='Performance Data Sheet'!C10 -> 0 | E39: D.E.Curve #: | F39: =F10 -> 1T4450K REV1
B40: ASSUMED 1/2 NEMA
C43: Prepared by: | D43: ='Performance Data Sheet'!K42 -> Jerry R | E43: Checked by:
A53: Load | B53: Efficiency | C53: PF | D53: Amps | E53: RPM | F53: Input Watts
A54: 0 | D54: 37.674744 | E54: 100 | F54: 0.74011
A55: 25 | B55: 89.51255 | C55: 56.932983 | D55: 41.318471 | E55: 66.295523 | F55: 9.4092596
A56: 50 | B56: 92.518555 | C56: 72.416573 | D56: 62.857242 | E56: 55.205841 | F56: 18.20709
A57: 75 | B57: 93.205276 | C57: 81.621056 | D57: 83.036826 | E57: 40.44862 | F57: 27.109417
A58: 100 | B58: 93.202438 | C58: 85.537231 | D58: 106 | E58: 25.325668 | F58: 36.146987
A59: 125 | B59: 92.905251 | C59: 87.166992 | D59: 130.00791 | E59: 9.8962972 | F59: 45.328265

Sheet StallTime
A1: Rating: | B1: 4 Pole - 450.0 HP - 1800 RPM - 4000 V - 60 Hz
A3: Starting Performance
D4: Load Type: Fan / Pump - 857.0 lb-ft²
A5: RPM | B5: Motor | C5: Load | D5: Accel. | E5: Line | F5: Stator | G5: Rotor
A6: Speed Increment | B6: Torque (%) | C6: Torque (%) | D6: Time (s) | E6: Amps | F6: kW / s | G6: kW / s
A7: 0~180 | B7: 139.7 | C7: 22.5 | D7: 0.381 | E7: 366.9 | F7: 91.6 | G7: 190.4
A8: 180~360 | B8: 123.3 | C8: 11.5 | D8: 0.399 | E8: 364.6 | F8: 94.9 | G8: 155.0
A9: 360~540 | B9: 113.8 | C9: 7.0 | D9: 0.418 | E9: 362.0 | F9: 98.0 | G9: 130.6
A10: 540~720 | B10: 108.5 | C10: 7.0 | D10: 0.440 | E10: 359.0 | F10: 101.5 | G10: 113.2
A11: 720~900 | B11: 106.0 | C11: 11.0 | D11: 0.470 | E11: 355.4 | F11: 106.6 | G11: 100.3
A12: 900~1080 | B12: 105.1 | C12: 18.0 | D12: 0.513 | E12: 350.5 | F12: 113.6 | G12: 89.9
A13: 1080~1296 | B13: 111.3 | C13: 29.2 | D13: 0.653 | E13: 342.8 | F13: 140.0 | G13: 76.1
A14: 1296~1512 | B14: 132.9 | C14: 47.6 | D14: 0.628 | E14: 327.3 | F14: 127.3 | G14: 57.5
A15: 1512~1620 | B15: 166.9 | C15: 66.4 | D15: 0.267 | E15: 305.5 | F15: 47.5 | G15: 35.1
A16: 1620~1728 | B16: 232.8 | C16: 81.9 | D16: 0.178 | E16: 272.8 | F16: 27.3 | G16: 18.3
... A18: 1764~1776 | B18: 164.9 | C18: 97.2 | D18: 0.045 | E18: 102.9 | F18: 0.3 | G18: 6.6
D21: Acceleration Time: 4.4 s
B22: Energy | D22: First Start | F22: Second Start
A23: Stator Winding Rise | B23: 955 kW / s | D23: 25°C | F23: 51°C
A24: Rotor Bar Rise | B24: 834 kW / s | D24: 76°C | F24: 152°C
A25: End Ring Rise | B25: 150 kW / s | D25: 14°C | F25: 28°C
A27: Locked Rotor Thermal Capability
E28: Cold Condition
B29: Rate of Rise | D29: Power | E29: Rise Limit | F29: Max Time
A30: Stator Copper | B30: 7.3°C / s | D30: 275.6 kW | E30: 160°C | F30: 21.9 s
A31: Rotor Bar | B31: 38.8°C / s | D31: 427.0 kW | E31: 260°C | F31: 6.7 s
A32: Rotor ER | B32: 7.1°C / s | D32: 76.6 kW | E32: 180°C | F32: 25.3 s
E34: Hot Condition
B35: Hot Temp. | D35: Rise Limit | E35: Ambient | F35: Total | G35: Max.Time
A36: Stator Copper | B36: 63°C + | D36: 97°C + | E36: 40°C | F36: = 200°C | G36: 13.3 s
A37: Rotor Bar | B37: 83°C + | D37: 177°C + | E37: 40°C | F37: = 300°C | G37: 4.6 s
A38: Rotor ER | B38: 83°C + | D38: 97°C + | E38: 40°C | F38: = 220°C | G38: 13.6 s
A40: Cold Stall Time: | B40: 10.1 s | D40: Hot Stall Time: | F40: 5.4 s
