Workbook
Name Print_Area_MI: 'Performance Data Sheet'!$A$10:$N$42

Sheet DesignSheet
A1: TOSHIBA INTERNATIONAL CORPORATION | I1: Calc. Code: | J1: 2-2-2-0-1-2
A2: 3-PHASE SQUIRREL CAGE INDUCTION MOTOR DESIGN SHEET | J2: B.L.-1 P.F.-1
A3: File: | B3: G:\DESPRO\RATFILE\RF6400.rat | G3: Date: | H3: 43416 | I3: Time: | J3: 0.42935185
A4: Pole | B4: HP | C4: RPM | D4: Form | E4: Voltage | F4: Frequency | G4: Temperature | H4: FLSpeed | I4: FLSlip | J4: Frame
A5: 6 | B5: 400 | C5: 1200 | D5: FCKW | E5: 4000 | F5: 60 | G5: 105 | H5: 1190.3 / 1182.1 | I5: 0.0081 / 0.0149 | J5: 5011
A6: Core Data | D6: Winding Data | E6: USA Wire Std | H6: Constant Data
B7: Primary | C7: Secondary | F7: Bar | G7: End Ring | H7: St. Slot Pitch | I7: 15.926116 | J7: LR Test Data
A8: Air Gap | B8: 1.2 | H8: Rt. Slot Pitch | I8: 19.640354 | J8: ES
A9: Space Fac. | B9: 0.93000001 | D9: Pitch | E9: 1 ~ 11 | F9: Cross Section Area | H9: Mean Value | I9: 17.783235 | J9: 801.67181
A10: Core Length | B10: 600 | C10: 600 | F10: UB: 221.9 | G10: UER: 1650.0 | H10: Eff.T.W.St. | I10: 9.8880913 | J10: WS
A11: OD | B11: 550 | C11: 362.6 | D11: Coil Pitch | E11: 0.83325 | G11: ERT: 30.0 | H11: Eff.T.W.Rt. | I11: 19.640354 | J11: 25112.368
A12: ID | B12: 365 | C12: 140 | D12: Slot Fill | E12: - | G12: ERD1: 246.0 | H12: St.Carter Fac. | I12: 1.2251186 | J12: IS
A13: Core Depth | B13: 42.5 | C13: 76.3 | D13: Con./Slot | E13: 11 | G13: ERD2: 360.0 | H13: Rt.Carter Fac. | I13: 1 | J13: 61.058483
A14: Eff.Core L. | B14: 558 | C14: 558 | D14: Wire Size 1 | E14: (.114"x.204")x1 | H14: Carter Factor | I14: 1.2251186 | J14: Volts / Turn
A15: Slot Data | D15: Wire Size 2 | E15: - | H15: Short. Factor | I15: 0.96589165 | J15: 17.495975
A16: Number | B16: 72 | C16: 58 | D16: // Circuits | E16: 1 | H16: Distrib. Factor | I16: 0.95749474 | J16: AC
A17: Kind | B17: Open | C17: Dbl - Closed | D17: Connection | E17: Wye | H17: Wind. Factor | I17: 0.92483618 | J17: 421.72449
A18: Skew | B18: - | C18: 0 | D18: MCL | E18: 939 | F18: 630 | H18: Reactance | I18: (Coeff.: 0.0915)
A19: Depth | B19: 50 | C19: 35 | D19: No.Cond./Ph. | E19: 264 | I19: Running | J19: Start
A20: Width | B20: 6.04 - 6.04 | D20: Res. (20°C) | E20: 0.29875544 | H20: Stator Slot | I20: 25.870934 | J20: 25.870934
A21: Opening | B21: 8.6999998 | C21: 0 | D21: (105°C) | E21: 0.39853623 | F21: 0.3814944 | G21: 0.031986632 | H21: Rotor Slot | I21: 61.550865 | J21: 35.225563
A22: Tip Depth | B22: 2.8299999 | C22: 0.69999999 | D22: Material | E22: CU | F22: AL | G22: AL | H22: Zigzag | I22: 8.5007124 | J22: 7.1432681
A23: T.Min.Wid. | B23: 7.2261162 | C23: 8.5 | D23: Spec.Resist. | E23: 1.742 | F23: 3.25 | G23: 3.25 | H23: Coil End | I23: 4.8514455 | J23: Skew R.: 0.00
A24: Low. R. | B24: 0 | C24: 2 | D24: Spec.Gravity | E24: 8.8900003 | F24: 2.6700001 | G24: 2.6700001 | H24: Belt Leakage | I24: 4.4116178 | J24: 3.8479046
A25: Up. R. | B25: - | C25: 2 | D25: Weight (kg) | H25: Total Resist. | I25: 0.81201726 | J25: 2.2453001
A26: Wedge Dep. | B26: 2.83 - 2.00 | C26: Magnetic | D26: Wire 1 | E26: 95.564018 | F26: 20.616351 | G26: 9.0487719 | H26: Total React. | I26: 9.6212683 | J26: 7.0247045
A27: Duct | B27: - | C27: - | D27: Wire 2 | E27: - | F27: - | G27: - | H27: Impedance | I27: 9.6554737 | J27: 7.3748116
A28: Effective Depth (S=1) | D28: Magnetic Circuit Data | I28: Core Loss Data
B29: Res.= | C29: 34.28737 | E29: Length | F29: Section | G29: Density | H29: AT | I29: Volume | J29: Loss | M29: =RIGHT(F$41,SEARCH("/",F$41,1)-1) -> 1179.6 | N29: 125RPM
B30: Reac.= | C30: 34.29639 | D30: Primary Core | E30: 14.398954 | F30: 474.3 | G30: 14.972213 | H30: 257.20344 | I30: 37810.174 | J30: 2579.5024 | M30: =RIGHT(E$41,SEARCH("/",E$41,1)-1) -> 1182.1 | N30: 100RPM
A31: Excitation Data | D31: Tooth | E31: 5 | F31: 483.86074 | G31: 14.676373 | H31: 81.958815 | I31: 14515.822 | J31: 958.79981 | M31: =RIGHT(D$41,SEARCH("/",D$41,1)-1) -> 1184.6 | N31: 75RPM
A32: Excit.Amps | B32: 31.542 / 29.982 | D32: Second.Core | E32: 7.6602436 | F32: 851.508 | G32: 8.3396994 | H32: 20.142299 | I32: Total | J32: 3538.3023 | M32: =RIGHT(C$41,SEARCH("/",C$41,1)-1) -> 1186.9 | N32: 50RPM
A33: Core Loss | B33: 1.084 / 1.030 | C33: Flux / Pole | D33: Tooth | E33: 3.5 | F33: 458.49 | G33: 15.488496 | H33: 83.245402 | I33: C.L.C. | J33: 1.75 / 0.78 | M33: =RIGHT(B$41,SEARCH("/",B$41,1)-1) -> 1189.2 | N33: 25RPM
A34: NoLoad | B34: 31.56 / 30.00 | C34: 7.1013207 | D34: Air Gap | E34: 0.12 | F34: 935.97497 | G34: 7.587084 | H34: 724.51379 | I34: S.F.C. | J34: 6.0500002
A35: Load Characteristics | D35: Temp. Rise @ 100%: | E35: 72 / 72 | G35: No Load Loss | H35: 10106.7 / 6105.0 | I35: W.Loss | J35: 6192.0 / 2765.2
A36: Load (%) | B36: 25 | C36: 50 | D36: 75 | E36: 100 | F36: 125 | G36: Primary Loss | H36: 4457.4 / 4636.4 | I36: S.Loss | J36: 1322.9 / 590.8
A37: Current (A) | B37: 36.60 / 36.70 | C37: 42.33 / 42.44 | D37: 50.86 / 50.99 | E37: 61.06 / 61.22 | F37: 72.54 / 72.73 | G37: Second. Loss | H37: 2525.8 / 4227.6 | I37: Total C.Loss | J37: 7515.0 / 3356.0
A38: Efficiency | B38: 0.872 / 0.870 | C38: 0.927 / 0.925 | D38: 0.944 / 0.942 | E38: 0.950 / 0.948 | F38: 0.952 / 0.950 | G38: Frict.& Wind. | H38: 1700.0 / 1939.1 | I38: Stray Loss | J38: 2172.8 | L38: =LEFT(E38,SEARCH("/",E38,1)-1) -> 0.950 | M38: =RIGHT(E38,SEARCH("/",E38,1)-1) -> 0.948 | N38: =M38/L38 -> 0.99789474 | O38: Eff.
A39: P.F. | B39: 0.337 / 0.337 | C39: 0.549 / 0.549 | D39: 0.673 / 0.673 | E39: 0.7422 / 0.7420 | F39: 0.779 / 0.779 | G39: Starting Data | I39: Slip | J39: PF | L39: =LEFT(E39,SEARCH("/",E39,1)-1) -> 0.7422 | M39: =RIGHT(E39,SEARCH("/",E39,1)-1) -> 0.7420 | N39: =M39/L39 -> 0.99973053 | O39: PF.
A40: Slip | B40: 0.0021 / 0.0090 | C40: 0.0040 / 0.0109 | D40: 0.0060 / 0.0129 | E40: 0.0081 / 0.0149 | F40: 0.0102 / 0.0170 | G40: LRA | H40: 313.2 / 369.7 | L40: =LEFT(E37,SEARCH("/",E37,1)-1) -> 61.06 | M40: =RIGHT(E37,SEARCH("/",E37,1)-1) -> 61.22 | N40: =M40/L40 -> 1.0026204 | O40: Current
...

Sheet Data Sheet
A1: TOSHIBA INTERNATIONAL CORPORATION
A2: INDUCTION MOTOR DATA SHEET
A3: File: | B3: RF6400 | I3: HRW / Model Number: | J3: 4006FTAL11E-A
A4: Type: TIKK - Form: FCKW - 6 Pole - 400 HP - 2300 / 4000 V - 60 Hz - 5011 - Class F | Q4: Motor Type Selection | T4: Electrical Steel Table
A5: Motor Parameters | F5: PERFORMANCE | J5: DESIGN | K5: TEST | Q5: EPACT | T5: M22 - 26Ga.
A6: Material | D6: M36 - 26Ga. | F6: NL & Impedance Test | Q6: EQP-III | T6: M36 - 26Ga.
A7: Air Gap | D7: 1.2 | F7: No load amps | J7: 52 / 30 | K7: - | Q7: Exp.Prf. | T7: NCB1 - 26Ga.
A8: Stack length | D8: 600 | F8: No load watts | J8: 6105 | K8: - | Q8: Exp.Prf.-EQPIII | T8: M43 - 26Ga.
A9: Number of turns per coil | D9: 5,6 | F9: Impedance amps | H9: 3 | I9: f | J9: 88 | K9: - | Q9: Prem. Eff. | T9: M45 - 26Ga.
A10: Wire 1 (size & number) | D10: (.114"x.204")x1 | F10: Impedance volts | H10: 3 | I10: f | J10: 1150 | K10: - | Q10: OWP | T10: M54 - 26Ga.
A11: Wire 2 (size & number) | D11: - | F11: Impedance watts | H11: 3 | I11: f | J11: 25112 | K11: - | Q11: Dry Kiln
A12: Slot fill - circle/square method (%) | D12: - | F12: Temperature Rise (°C)
A13: Connection | D13: 1D / 1Y | G13: Winding | I13: 80/115 | J13: 72 / 95 | K13: -
A14: MCL | D14: 939 | G14: Frame | J14: - | K14: -
A15: Allowance for ins. depth | D15: 13.1184 | G15: Bearing PS/OS | J15: - | K15: -
A16: Allowance for ins. width | D16: 3.3183999 | G16: End Ring | J16: - | K16: -
A17: Slot/Wire arrangement | D17: 11 x 1 | F17: Nameplate Data
A18: Effective cross section for coil | D18: - | H18: FLC (A) | J18: 106 / 61
A19: Coil grouping | D19: - | H19: RPM | J19: 1180
A20: Coil pitch (slot number) | D20: 1 ~ 11 | H20: CODE | J20: H
A21: Method of coil connection | D21: - | H21: S. F. | J21: 1.15 | Q21: Method of Connection
A22: Resistance per phase @ 20 °C | D22: 0.29879999 | H22: DESIGN | J22: - | Q22: Skip
A23: Coil Weight | B23: Wire1 | D23: 210.2 | H23: Nom.Eff. (%): | J23: - | Q23: Adjacent
A24: (lbs.) | B24: Wire2 | D24: - | H24: Min.Eff. (%): | J24: - | Q24: -
A25: Current Densities (A/cm2) | E25: Bar / ER | H25: P.F. (%): | J25: -
A26: FL / LR | D26: 424 / 2572 | E26: 258 / 107
A27: Stator Slot Shape (Reference) | F27: Performance
H28: LRC (A) | I28: 578 / 334 | J28: 641/ 370 | K28: - | M28: =370/61 -> 6.0655738 | N28: =370/334 -> 1.1077844
H29: LRT (%) | I29: 60 | J29: 227 | K29: - | M29: =641/106 -> 6.0471698 | N29: =641/578 -> 1.1089965
H30: BDT (%) | I30: 175 | J30: 277 | K30: -
H31: SLIP (%) | J31: 1.49 | K31: -
G32: IEEE-B | H32: Eff. (%) | J32: 94.8 | K32: -
A33: Rotor Slot Shape (Reference) | H33: PF (%) | J33: 74.2 | K33: -
F34: Losses (Watts) | H34: Primary | J34: 4636 | K34: -
H35: Secondary | J35: 4228 | K35: -
H36: Core | J36: 3356 | K36: -
H37: F & W | J37: 1939 | K37: -
H38: Stray | J38: 2173 | K38: -
A39: End Ring (Reference) | F39: Note | G39: OUTER FAN OD: 550mmRADIAL W/PLATE
G40: ref 6DL250L1A4CJDK01 lab 9889a (83.7 dBA)
...

Sheet LoginSheet
J1: P | K1: T | L1: L | M1: T
B2: PROJECT HISTORY | J2: E | K2: D | L2: I | M2: Y | N2: H
J3: R | L3: M | M3: P
J4: F | L4: I | M4: E
K5: C | L5: T | N5: I
J6: D | K6: U | M6: T | N6: N
J7: A | K7: R | L7: R | M7: E | N7: S
I8: S | J8: T | K8: V | L8: E | M8: S | N8: U
B9: DATE | C9: PROJECT | D9: SMART NUMBER | E9: QTY | F9: CUSTOMER | G9: REMARKS | H9: LIMIT CODE | I9: F | J9: A | K9: E | L9: V | M9: T | N9: L
B53: REVISION HISTORY
B54: REV | C54: REMARKS | I54: DATE | L54: INIT

Sheet StallTime
A1: Rating: | B1: 6 Pole - 400.0 HP - 1200 RPM - 4000 V - 60 Hz
A3: Starting Performance
D4: Load Type: Fan / Pump - 2099.0 lb-ft²
A5: RPM | B5: Motor | C5: Load | D5: Accel. | E5: Line | F5: Stator | G5: Rotor
A6: Speed Increment | B6: Torque (%) | C6: Torque (%) | D6: Time (s) | E6: Amps | F6: kW / s | G6: kW / s
A7: 0~120 | B7: 204.6 | C7: 22.5 | D7: 0.282 | E7: 368.5 | F7: 46.1 | G7: 176.9
A8: 120~240 | B8: 172.1 | C8: 11.5 | D8: 0.319 | E8: 365.3 | F8: 51.4 | G8: 147.7
A9: 240~360 | B9: 153.0 | C9: 7.0 | D9: 0.351 | E9: 361.8 | F9: 55.5 | G9: 125.5
A10: 360~480 | B10: 142.4 | C10: 7.0 | D10: 0.379 | E10: 357.7 | F10: 58.6 | G10: 108.1
A11: 480~600 | B11: 136.8 | C11: 11.0 | D11: 0.407 | E11: 353.1 | F11: 61.6 | G11: 94.6
A12: 600~722 | B12: 135.0 | C12: 18.1 | D12: 0.445 | E12: 348.0 | F12: 65.5 | G12: 82.7
A13: 722~844 | B13: 136.4 | C13: 27.9 | D13: 0.479 | E13: 342.2 | F13: 68.4 | G13: 70.9
A14: 844~966 | B14: 144.3 | C14: 42.3 | D14: 0.510 | E14: 333.8 | F14: 70.1 | G14: 57.4
A15: 966~1027 | B15: 161.6 | C15: 56.7 | D15: 0.248 | E15: 323.5 | F15: 32.1 | G15: 40.2
A16: 1027~1087 | B16: 195.8 | C16: 69.0 | D16: 0.205 | E16: 307.1 | F16: 24.9 | G16: 28.1
... A19: 1190~1190 | B19: 99.8 | C19: 99.1 | D19: 0.381 | E19: 45.2 | F19: 1.7 | G19: 164.6
D21: Acceleration Time: 4.4 s
B22: Energy | D22: First Start | F22: Second Start
A23: Stator Winding Rise | B23: 564 kW / s | D23: 15°C | F23: 31°C
A24: Rotor Bar Rise | B24: 1045 kW / s | D24: 57°C | F24: 113°C
A25: End Ring Rise | B25: 88 kW / s | D25: 11°C | F25: 22°C
A27: Locked Rotor Thermal Capability
E28: Cold Condition
B29: Rate of Rise | D29: Power | E29: Rise Limit | F29: Max Time
A30: Stator Copper | B30: 5.6°C / s | D30: 207.8 kW | E30: 160°C | F30: 28.3 s
A31: Rotor Bar | B31: 33.6°C / s | D31: 619.5 kW | E31: 260°C | F31: 7.7 s
A32: Rotor ER | B32: 6.4°C / s | D32: 51.9 kW | E32: 180°C | F32: 28.1 s
E34: Hot Condition
B35: Hot Temp. | D35: Rise Limit | E35: Ambient | F35: Total | G35: Max.Time
A36: Stator Copper | B36: 95°C + | D36: 65°C + | E36: 40°C | F36: = 200°C | G36: 11.5 s
A37: Rotor Bar | B37: 133°C + | D37: 127°C + | E37: 40°C | F37: = 300°C | G37: 3.8 s
A38: Rotor ER | B38: 133°C + | D38: 47°C + | E38: 40°C | F38: = 220°C | G38: 7.3 s
A40: Cold Stall Time: | B40: 10.4 s | D40: Hot Stall Time: | F40: 2.7 s

Sheet STCurve
A2: TOSHIBA INTERNATIONAL CORPORATION
A3: Speed Torque/Current Curve
A6: Model #: | B6: ='Performance Data Sheet'!C17 -> GP-10013067 | E6: FLAmps: | F6: ='Performance Data Sheet'!I14 -> 106/61
A7: Enclosure: | B7: ='Performance Data Sheet'!F14 -> TEFC | C7: Voltage: | D7: ='Performance Data Sheet'!F13 & " V" -> 2300/4000 V | E7: Frame: | F7: ='Performance Data Sheet'!C14 -> 5011UZ
A8: Pole: | B8: 6 | C8: Frequency: | D8: 3 PH / 60 Hz | E8: Ins. Class: | F8: ='Performance Data Sheet'!M15 -> F
A9: HP: | B9: ='Performance Data Sheet'!C13 -> 400 | C9: Rotor Inertia: | D9: 221.5 lb-ft² | E9: Date: | F9: ='Performance Data Sheet'!K44 -> 43416
A10: FLRPM: | B10: ='Performance Data Sheet'!M14 -> 1180 | C10: Load Inertia: | D10: 2099.0 lb-ft² | E10: File: | F10: RF6400
B12: Locked Rotor Amps: | C12: ='Performance Data Sheet'!D22 & " A" -> 641/370 A | D12: Load Type: | E12: Fan / Pump
B13: Locked Rotor Torque: | C13: ='Performance Data Sheet'!H23/100 -> 2.25 | D13: Starting at: | E13: FV (V)
B14: Breakdown Torque: | C14: 2.75 | D14: Accel. Time: | E14: 4.4 (s)
B15: Rated Torque: | C15: ='Performance Data Sheet'!H22 & " lb-ft" -> 1780 lb-ft
A39: Comments: | B39: PROJECT | C39: ='Performance Data Sheet'!C10 -> 2111218.1 | E39: D.E.Curve #: | F39: =F10 -> RF6400
C43: Prepared by: | D43: ='Performance Data Sheet'!K42 -> Zichao Xie | E43: Checked by:
D53: Load
A54: 100 | B54: 0 | C54: 0.51738888 | D54: 100
A55: 99.14 | B55: 99.623999 | C55: 116.59449 | D55: 98.279999
A56: 95.7 | B56: 275 | C56: 373.54248 | D56: 88.925003
A57: 90.622222 | B57: 219.2183 | C57: 484.98694 | D57: 75.617775
A58: 85.544443 | B58: 172.47413 | C58: 521.98444 | D58: 62.41555
A59: 80.466667 | B59: 150.72316 | C59: 538.81573 | D59: 51.026669
A60: 70.311111 | B60: 137.79324 | C60: 555.58899 | D60: 33.528889
A61: 60.155556 | B61: 135.01411 | C61: 566.30707 | D61: 22.171112
A62: 50 | B62: 135 | C62: 574.83459 | D62: 14
A63: 39.999998 | B63: 138.5933 | C63: 582.89642 | D63: 7.9999995
A64: 30.000001 | B64: 146.12388 | C64: 590.01337 | D64: 5.9999995
A65: 19.999999 | B65: 159.96999 | C65: 596.15619 | D65: 8.000001
... A67: 0 | B67: 225 | C67: 606.55737 | D67: 30

Sheet Performance Data Sheet
A1: TOSHIBA INTERNATIONAL CORPORATION | J1: INDEX | L1: MPCF-1033
A2: Industrial Division / Houston Motor Plant | J2: SHEET NO. | L2: 1 of 1
J3: ISSUED | L3: 7/31/13
J4: SUPERSEDES | L4: 11/8/96
J5: REVISION | L5: 2
A6: SQUIRREL CAGE INDUCTION MOTOR | J6: WRITTEN BY | L6: MDC
A7: PERFORMANCE SPECIFICATIONS | J7: APPROVED BY | L7: PAA
B9: CUSTOMER: | C9: MATLOCK ELECTRIC
B10: TIC SR No.: | C10: 2111218.1
A12: MOTOR NAMEPLATE DATA
B13: H.P.: | C13: 400 | E13: VOLTS: | F13: 2300/4000 | H13: 3 PH / | I13: 60 Hz | L13: S. RPM: | M13: 1200
B14: FRAME: | C14: 5011UZ | E14: ENCL: | F14: TEFC | H14: FLAMPS: | I14: 106/61 | L14: FLRPM: | M14: 1180
B15: FORM: | C15: FCKW4 | E15: S.F.: | F15: 1.15 | H15: NEMA DESIGN: | I15: - | L15: INSUL CLASS: | M15: F
B16: TYPE: | C16: TIKK | E16: AMB.: | F16: 40°C | H16: CODE: | I16: H | L16: DUTY: | M16: Cont.
B17: MODEL No.: | C17: GP-10013067 | H17: kW: | I17: -
B18: NOM. EFF.: | C18: - | E18: MIN. EFF.: | F18: - | H18: P.F.: | I18: -
A21: AMPERAGE | E21: TORQUES | I21: **BEARINGS:
C22: LOCKED ROTOR: | D22: 641/370 | G22: FULL LOAD (lb-ft.): | H22: 1780 | K22: DRIVE END: | L22: REFER TO NP
G23: LOCKED ROTOR (%): | H23: 225 | K23: OPPOSITE DRIVE END: | L23: REFER TO NP
G24: BREAK DOWN (%): | H24: 275
A28: EFFICIENCY | H28: POWER FACTOR
C29: FULL LOAD: | D29: 94.8 | J29: FULL LOAD: | K29: 74.2
C30: 3/4 LOAD: | D30: 94.2 | J30: 3/4 LOAD: | K30: 67.3
C31: 1/2 LOAD: | D31: 92.5 | J31: 1/2 LOAD: | K31: 54.9
A35: ALL CHARACTERISTICS ARE AVERAGE EXPECTED VALUES BASED UPON RATED VOLTAGE,
A36: FREQUENCY AND SINEWAVE POWER INPUT.
A37: THE DECLARED LOCKED ROTOR CURRENT HAS A TOLERANCE OF 20%.
A38: * TEMPERATURE RISE WILL BE CONSISTENT WITH INSULATION, AMBIENT AND SERVICE FACTOR AS
A39: DEFINED BY NEMA-MG-12 OR -20.
A40: ** BEARINGS ARE THE ONLY RECOMMENDED SPARE PART(S).
J42: CERTIFIED BY: | K42: Zichao Xie
J44: DATE: | K44: 43416
A59: - | B59: 6205ZZ | D59: 1 | E59: -
A60: TEFC | B60: 6206UU | D60: 1.15 | E60: A
A61: ODP | B61: 6207ZZ | E61: B
B62: 6208UU
B63: 6211ZZ
B64: 6211C3
B65: 6211ZZC3
B66: 6305UUC3
...

Sheet Thermdam
A2: TOSHIBA INTERNATIONAL CORPORATION
A3: Thermal Limit & Acceleration Curves
A4: Design Values (For Reference Only)
A6: Model #: | B6: ='Performance Data Sheet'!C17 -> GP-10013067 | E6: FLAmps: | F6: ='Performance Data Sheet'!I14 -> 106/61
A7: Enclosure: | B7: ='Performance Data Sheet'!F14 -> TEFC | C7: Voltage: | D7: ='Performance Data Sheet'!F13 & " V" -> 2300/4000 V | E7: Frame: | F7: ='Performance Data Sheet'!C14 -> 5011UZ
A8: Pole: | B8: 6 | C8: Frequency: | D8: 3 PH / 60 Hz | E8: Ins. Class: | F8: ='Performance Data Sheet'!M15 -> F
A9: HP: | B9: ='Performance Data Sheet'!C13 -> 400 | C9: Rotor Inertia: | D9: 221.5 lb-ft² | E9: Date: | F9: ='Performance Data Sheet'!K44 -> 43416
A10: FLRPM: | B10: ='Performance Data Sheet'!M14 -> 1180 | C10: Load Inertia: | D10: 2099.0 lb-ft² | E10: File: | F10: RF6400
C12: ='Performance Data Sheet'!D22 & " A" -> 641/370 A
C13: ='Performance Data Sheet'!H23/100 -> 2.25
C15: ='Performance Data Sheet'!H22 & " lb-ft" -> 1780 lb-ft
A39: Comments: | B39: PROJECT | C39: ='Performance Data Sheet'!C10 -> 2111218.1 | E39: D.E.Curve #: | F39: =F10 -> RF6400
C43: Prepared by: | D43: ='Performance Data Sheet'!K42 -> Zichao Xie | E43: Checked by:
F50: =5252.1*B50/D53 -> #DIV/0!
D66: =D65/D64 -> #DIV/0!
A67: Current (%) | B67: Cold | C67: Hot | E67: CURRENT (%) | F67: Accel. Time
A68: 606.55738 | B68: 14.794942 | C68: 3.8497618 | E68: =A68 -> 606.55738 | F68: 0.0001
A69: 584.3738 | B69: =((A68/A69)^2)*B68 -> 15.939532 | C69: =((A68/A69)^2)*C68 -> 4.1475933 | E69: 604.09836 | F69: 0.28200001
A70: 562.18357 | B70: =((A68/A70)^2)*B68 -> 17.222681 | C70: =((A68/A70)^2)*C68 -> 4.4814787 | E70: 598.85246 | F70: 0.60100001
A71: 540 | B71: =((A68/A71)^2)*B68 -> 18.666785 | C71: =((A68/A71)^2)*C68 -> 4.8572462 | E71: 593.11475 | F71: 0.95200002
A72: =A71-100 -> 440 | B72: =((A68/A72)^2)*B68 -> 28.115881 | E72: 586.39344 | F72: 1.331
A73: =A72-100 -> 340 | B73: =((A68/A73)^2)*B68 -> 47.086805 | E73: 578.85246 | F73: 1.7379999
A74: 275 | B74: =((A68/A74)^2)*B68 -> 71.976656 | C74: =((A68/A74)^2)*C68 -> 18.728899 | E74: 570.4918 | F74: 2.1829998
A75: 180 | B75: =((A68/A75)^2)*B69 -> 180.99824 | C75: =((A68/A75)^2)*C68 -> 43.715216 | E75: 560.98361 | F75: 2.6619999
A76: 145 | B76: =((A68/A76)^2)*B68 -> 258.89344 | C76: =((A68/A76)^2)*C68 -> 67.366136 | E76: 547.21311 | F76: 3.1719999
A77: 125 | C77: =CEILING(C76*2,100) -> 200 | E77: 530.32787 | F77: 3.4199998
A78: 125 | C78: =2*C77 -> 400 | E78: 503.44262 | F78: 3.6249998
A79: 125 | C79: 10000 | E79: 429.34426 | F79: 3.7829998
E80: =A74 -> 275 | F80: 3.9709997
E81: =A77 -> 125 | F81: 4.3519998

Sheet Performance 4000V
A2: TOSHIBA INTERNATIONAL CORPORATION
A3: Performance Curve
A4: Design Values (For Reference Only)
A6: Model #: | B6: ='Performance Data Sheet'!C17 -> GP-10013067 | E6: FLAmps: | F6: 61 A
A7: Enclosure: | B7: ='Performance Data Sheet'!F14 -> TEFC | C7: Voltage: | D7: 4000 V | E7: Frame: | F7: ='Performance Data Sheet'!C14 -> 5011UZ
A8: Pole: | B8: 6 | C8: Frequency: | D8: 3 PH / 60 Hz | E8: Ins. Class: | F8: ='Performance Data Sheet'!M15 -> F
A9: HP: | B9: ='Performance Data Sheet'!C13 -> 400 | C9: Rotor Inertia: | D9: 221.5 lb-ft² | E9: Date: | F9: ='Performance Data Sheet'!K44 -> 43416
A10: FLRPM: | B10: ='Performance Data Sheet'!M14 -> 1180 | C10: Load Inertia: | D10: 2099.0 lb-ft² | E10: File: | F10: RF6400
B12: Locked Rotor Amps: | C12: 370 A | D12: Load Type: | E12: Fan / Pump
B13: Locked Rotor Torque: | C13: ='Performance Data Sheet'!H23/100 -> 2.25 | D13: Starting at: | E13: FV (V)
B14: Breakdown Torque: | C14: 2.75 | D14: Accel. Time: | E14: 4.4 (s)
B15: Rated Torque: | C15: ='Performance Data Sheet'!H22 & " lb-ft" -> 1780 lb-ft
A39: Comments: | B39: PROJECT | C39: ='Performance Data Sheet'!C10 -> 2111218.1 | E39: D.E.Curve #: | F39: =F10 -> RF6400
C43: Prepared by: | D43: ='Performance Data Sheet'!K42 -> Zichao Xie | E43: Checked by:
A53: Load | B53: Efficiency | C53: PF | D53: Amps | E53: RPM | F53: Input Watts
A54: 0 | D54: 31.642777 | E54: 100 | F54: =6105/8000 -> 0.763125
A55: 25 | B55: 87.040771 | C55: 33.715748 | D55: 36.696941 | E55: 67.704517 | F55: 10.714714
A56: 50 | B56: 92.515526 | C56: 54.859211 | D56: 42.437649 | E56: 61.933496 | F56: 20.16131
A57: 75 | B57: 94.191277 | C57: 67.266136 | D57: 50.991711 | E57: 56.002239 | F57: 29.703934
A58: 100 | B58: 94.843727 | C58: 74.193054 | D58: 61.217232 | E58: 49.873757 | F58: 39.332797
A59: 125 | B59: 95.049171 | C59: 77.892494 | D59: 72.729675 | E59: 43.705225 | F59: 49.059726

Sheet Performance 2300V
A2: TOSHIBA INTERNATIONAL CORPORATION
A3: Performance Curve
A4: Design Values (For Reference Only)
A6: Model #: | B6: ='Performance Data Sheet'!C17 -> GP-10013067 | E6: FLAmps: | F6: 106 A
A7: Enclosure: | B7: ='Performance Data Sheet'!F14 -> TEFC | C7: Voltage: | D7: 2300 V | E7: Frame: | F7: ='Performance Data Sheet'!C14 -> 5011UZ
A8: Pole: | B8: 6 | C8: Frequency: | D8: 3 PH / 60 Hz | E8: Ins. Class: | F8: ='Performance Data Sheet'!M15 -> F
A9: HP: | B9: ='Performance Data Sheet'!C13 -> 400 | C9: Rotor Inertia: | D9: 221.5 lb-ft² | E9: Date: | F9: ='Performance Data Sheet'!K44 -> 43416
A10: FLRPM: | B10: ='Performance Data Sheet'!M14 -> 1180 | C10: Load Inertia: | D10: N/A | E10: File: | F10: RF6400
B12: Locked Rotor Amps: | C12: 641 A | D12: Load Type: | E12: N/A
B13: Locked Rotor Torque: | C13: ='Performance Data Sheet'!H23/100 -> 2.25 | D13: Starting at: | E13: N/A
B14: Breakdown Torque: | C14: 2.75 | D14: Accel. Time: | E14: N/A
B15: Rated Torque: | C15: ='Performance Data Sheet'!H22 & " lb-ft" -> 1780 lb-ft
A39: Comments: | B39: PROJECT | C39: ='Performance Data Sheet'!C10 -> 2111218.1 | E39: D.E.Curve #: | F39: =F10 -> RF6400
C43: Prepared by: | D43: ='Performance Data Sheet'!K42 -> Zichao Xie | E43: Checked by:
A53: Load | B53: Efficiency | C53: PF | D53: Amps | E53: RPM | F53: Input Watts
A54: 0 | D54: 54.806897 | E54: 100 | F54: =6105/8000 -> 0.763125
A55: 25 | B55: 87.040771 | C55: 33.715748 | D55: 63.560967 | E55: 67.704517 | F55: 10.714714
A56: 50 | B56: 92.515526 | C56: 54.859211 | D56: 73.504164 | E56: 61.933496 | F56: 20.16131
A57: 75 | B57: 94.191277 | C57: 67.266136 | D57: 88.320234 | E57: 56.002239 | F57: 29.703934
A58: 100 | B58: 94.843727 | C58: 74.193054 | D58: 106.03136 | E58: 49.873757 | F58: 39.332797
A59: 125 | B59: 95.049171 | C59: 77.892494 | D59: 125.97149 | E59: 43.705225 | F59: 49.059726
