Workbook
Name Print_Area_MI: 'Performance Data Sheet'!$A$10:$N$42

Sheet DesignSheet
A1: TOSHIBA INTERNATIONAL CORPORATION | I1: Calc. Code: | J1: 2-2-2-0-1-2
A2: 3-PHASE SQUIRREL CAGE INDUCTION MOTOR DESIGN SHEET | J2: B.L.-1 P.F.-1
A3: File: | B3: G:\DESPRO\RATFILE\RF6500USS.rat | G3: Date: | H3: 43608 | I3: Time: | J3: 0.55914352
A4: Pole | B4: HP | C4: RPM | D4: Form | E4: Voltage | F4: Frequency | G4: Temperature | H4: FLSpeed | I4: FLSlip | J4: Frame
A5: 6 | B5: 500 | C5: 1200 | D5: FCKW | E5: 4000 | F5: 60 | G5: 105 | H5: 1191.2 / 1189.0 | I5: 0.0073 / 0.0092 | J5: 5811US
A6: Core Data | D6: Winding Data | E6: USA Wire Std | H6: Constant Data
B7: Primary | C7: Secondary | F7: Bar | G7: End Ring | H7: St. Slot Pitch | I7: 18.544108 | J7: LR Test Data
A8: Air Gap | B8: 1.4 | H8: Rt. Slot Pitch | I8: 22.868609 | J8: ES
A9: Space Fac. | B9: 0.93000001 | D9: Pitch | E9: 1 ~ 11 | F9: Cross Section Area | H9: Mean Value | I9: 20.706358 | J9: 858.97827
A10: Core Length | B10: 550 | C10: 550 | F10: UB: 432.9 | G10: UER: 2040.0 | H10: Eff.T.W.St. | I10: 10.741521 | J10: WS
A11: OD | B11: 610 | C11: 422.2 | D11: Coil Pitch | E11: 0.83325 | G11: ERT: 40.0 | H11: Eff.T.W.Rt. | I11: 22.868609 | J11: 22580.863
A12: ID | B12: 425 | C12: 155 | D12: Slot Fill | E12: - | G12: ERD1: 306.0 | H12: St.Carter Fac. | I12: 1.2718254 | J12: IS
A13: Core Depth | B13: 41.5 | C13: 88.6 | D13: Con./Slot | E13: 13 | G13: ERD2: 420.0 | H13: Rt.Carter Fac. | I13: 1 | J13: 67.981461
A14: Eff.Core L. | B14: 511.5 | C14: 511.5 | D14: Wire Size 1 | E14: (.102"x.144")x1 | H14: Carter Factor | I14: 1.2718254 | J14: Volts / Turn
A15: Slot Data | D15: Wire Size 2 | E15: (.102"x.162")x1 | H15: Short. Factor | I15: 0.96589165 | J15: 14.804287
A16: Number | B16: 72 | C16: 58 | D16: // Circuits | E16: 1 | H16: Distrib. Factor | I16: 0.95749474 | J16: AC
A17: Kind | B17: Open | C17: Dbl - Closed | D17: Connection | E17: Wye | H17: Wind. Factor | I17: 0.92483618 | J17: 476.57132
A18: Skew | B18: - | C18: 0.80000001 | D18: MCL | E18: 915 | F18: 590.25951 | H18: Reactance | I18: (Coeff.: 0.1171)
A19: Depth | B19: 51 | C19: 45 | D19: No.Cond./Ph. | E19: 312 | I19: Running | J19: Start
A20: Width | B20: 7.80 - 7.80 | D20: Res. (20°C) | E20: 0.25478474 | H20: Stator Slot | I20: 20.357693 | J20: 20.357693
A21: Opening | B21: 11.5 | C21: 0 | D21: (105°C) | E21: 0.33987984 | F21: 0.25588125 | G21: 0.039307969 | H21: Rotor Slot | I21: 43.756229 | J21: 23.790222
A22: Tip Depth | B22: 2.8299999 | C22: 0.69999999 | D22: Material | E22: CU | F22: AL | G22: AL | H22: Zigzag | I22: 7.5531363 | J22: 6.1741772
A23: T.Min.Wid. | B23: 7.0441074 | C23: 8.5 | D23: Spec.Resist. | E23: 1.742 | F23: 3.25 | G23: 3.25 | H23: Coil End | I23: 5.6983994 | J23: Skew R.: 0.57
A24: Low. R. | B24: 0 | C24: 1.5 | D24: Spec.Gravity | E24: 8.8900003 | F24: 2.6700001 | G24: 2.6700001 | H24: Belt Leakage | I24: 4.2412886 | J24: 3.7865417
A25: Up. R. | B25: - | C25: 1.5 | D25: Weight (kg) | H25: Total Resist. | I25: 0.63506907 | J25: 1.6286895
A26: Wedge Dep. | B26: 2.83 - 2.00 | C26: Magnetic | D26: Wire 1 | E26: 69.795891 | F26: 36.886523 | G26: 12.885045 | H26: Total React. | I26: 10.123663 | J26: 6.966495
A27: Duct | B27: - | C27: - | D27: Wire 2 | E27: 78.814486 | F27: - | G27: - | H27: Impedance | I27: 10.143563 | J27: 7.1543469
A28: Effective Depth (S=1) | D28: Magnetic Circuit Data | I28: Core Loss Data
B29: Res.= | C29: 44.254653 | E29: Length | F29: Section | G29: Density | H29: AT | I29: Volume | J29: Loss | M29: =RIGHT(F$41,SEARCH("/",F$41,1)-1) -> 1186.6 | N29: 125RPM
B30: Reac.= | C30: 44.287031 | D30: Primary Core | E30: 15.969749 | F30: 424.545 | G30: 14.153529 | H30: 223.45089 | I30: 37911.739 | J30: 2361.2312 | M30: =RIGHT(E$41,SEARCH("/",E$41,1)-1) -> 1189.0 | N30: 100RPM
A31: Excitation Data | D31: Tooth | E31: 5.1 | F31: 432.36731 | G31: 13.897466 | H31: 65.841305 | I31: 13230.44 | J31: 800.00721 | M31: =RIGHT(D$41,SEARCH("/",D$41,1)-1) -> 1191.3 | N31: 75RPM
A32: Excit.Amps | B32: 22.900 / 24.408 | D32: Second.Core | E32: 8.6969683 | F32: 906.378 | G32: 6.6294745 | H32: 14.350293 | I32: Total | J32: 3161.2384 | M32: =RIGHT(C$41,SEARCH("/",C$41,1)-1) -> 1193.4 | N32: 50RPM
A33: Core Loss | B33: 0.971 / 1.034 | C33: Flux / Pole | D33: Tooth | E33: 4.5 | F33: 420.2825 | G33: 14.297074 | H33: 65.814828 | I33: C.L.C. | J33: 1.75 / 0.93 | M33: =RIGHT(B$41,SEARCH("/",B$41,1)-1) -> 1195.6 | N33: 25RPM
A34: NoLoad | B34: 22.92 / 24.43 | C34: 6.0088098 | D34: Air Gap | E34: 0.14 | F34: 962.32637 | G34: 6.2440457 | H34: 695.64009 | I34: S.F.C. | J34: 6.0500002
A35: Load Characteristics | D35: Temp. Rise @ 100%: | E35: 79 / 79 | G35: No Load Loss | H35: 11162.0 / 7515.0 | I35: W.Loss | J35: 5532.2 / 2947.2
A36: Load (%) | B36: 25 | C36: 50 | D36: 75 | E36: 100 | F36: 125 | G36: Primary Loss | H36: 4712.2 / 5225.4 | I36: S.Loss | J36: 1199.0 / 638.7
A37: Current (A) | B37: 29.67 / 30.61 | C37: 39.98 / 41.24 | D37: 53.19 / 54.86 | E37: 67.98 / 70.12 | F37: 84.21 / 86.87 | G37: Second. Loss | H37: 2902.6 / 3442.9 | I37: Total C.Loss | J37: 6731.1 / 3586.0
A38: Efficiency | B38: 0.888 / 0.886 | C38: 0.935 / 0.933 | D38: 0.949 / 0.947 | E38: 0.954 / 0.953 | F38: 0.955 / 0.954 | G38: Frict.& Wind. | H38: 4030.0 / 3407.9 | I38: Stray Loss | J38: 2929.3 | L38: =LEFT(E38,SEARCH("/",E38,1)-1) -> 0.954 | M38: =RIGHT(E38,SEARCH("/",E38,1)-1) -> 0.953 | N38: =M38/L38 -> 0.99895178 | O38: Eff.
A39: P.F. | B39: 0.511 / 0.496 | C39: 0.720 / 0.699 | D39: 0.800 / 0.777 | E39: 0.8298 / 0.8060 | F39: 0.836 / 0.812 | G39: Starting Data | I39: Slip | J39: PF | L39: =LEFT(E39,SEARCH("/",E39,1)-1) -> 0.8298 | M39: =RIGHT(E39,SEARCH("/",E39,1)-1) -> 0.8060 | N39: =M39/L39 -> 0.97131839 | O39: PF.
A40: Slip | B40: 0.0018 / 0.0037 | C40: 0.0036 / 0.0055 | D40: 0.0054 / 0.0073 | E40: 0.0073 / 0.0092 | F40: 0.0093 / 0.0111 | G40: LRA | H40: 322.8 / 394.2 | L40: =LEFT(E37,SEARCH("/",E37,1)-1) -> 67.98 | M40: =RIGHT(E37,SEARCH("/",E37,1)-1) -> 70.12 | N40: =M40/L40 -> 1.0314798 | O40: Current
...

Sheet Data Sheet
A1: TOSHIBA INTERNATIONAL CORPORATION
A2: INDUCTION MOTOR DATA SHEET
A3: File: | B3: RF6500USS | I3: HRW / Model Number: | J3: 5006FTAL11E-A
A4: Type: TIKK - Form: FCKW - 6 Pole - 500 HP - 2300/4000 V - 60 Hz - 5811US - Class F | Q4: Motor Type Selection | T4: Electrical Steel Table
A5: Motor Parameters | F5: PERFORMANCE | J5: DESIGN | K5: TEST | Q5: EPACT | T5: M22 - 26Ga.
A6: Material | D6: M36 - 26Ga. | F6: NL & Impedance Test | Q6: EQP-III | T6: M36 - 26Ga.
A7: Air Gap | D7: 1.4 | F7: No load amps | J7: 24 | K7: - | Q7: Exp.Prf. | T7: NCB1 - 26Ga.
A8: Stack length | D8: 550 | F8: No load watts | J8: 7515 | K8: - | Q8: Exp.Prf.-EQPIII | T8: M43 - 26Ga.
A9: Number of turns per coil | D9: 6,7,7,6 | F9: Impedance amps | H9: 3 | I9: f | J9: 91 | K9: - | Q9: Prem. Eff. | T9: M45 - 26Ga.
A10: Wire 1 (size & number) | D10: (.102"x.144")x1 | F10: Impedance volts | H10: 3 | I10: f | J10: 1150 | K10: - | Q10: OWP | T10: M54 - 26Ga.
A11: Wire 2 (size & number) | D11: (.102"x.162")x1 | F11: Impedance watts | H11: 3 | I11: f | J11: 22581 | K11: - | Q11: Dry Kiln
A12: Slot fill - circle/square method (%) | D12: - | F12: Temperature Rise (°C)
A13: Connection | D13: 1 x D / 1 x Wye | G13: Winding | I13: 80/115 | J13: 79 / 104 | K13: -
A14: MCL | D14: 915 | G14: Frame | J14: - | K14: -
A15: Allowance for ins. depth | D15: 11.889601 | G15: Bearing PS/OS | J15: - | K15: -
A16: Allowance for ins. width | D16: 3.3276002 | G16: End Ring | J16: - | K16: -
A17: Slot/Wire arrangement | D17: 13 x 2 | F17: Nameplate Data
A18: Effective cross section for coil | D18: - | H18: FLC (A) | J18: 121 / 70
A19: Coil grouping | D19: - | H19: RPM | J19: 1190
A20: Coil pitch (slot number) | D20: 1 ~ 11 | H20: CODE | J20: F
A21: Method of coil connection | D21: - | H21: S. F. | J21: 1.15 | Q21: Method of Connection
A22: Resistance per phase @ 20 °C | D22: 0.25479999 | H22: DESIGN | J22: - | Q22: Skip
A23: Coil Weight | B23: Wire1 | D23: 153.6 | H23: Nom.Eff. (%): | J23: - | Q23: Adjacent
A24: (lbs.) | B24: Wire2 | D24: 173.4 | H24: Min.Eff. (%): | J24: - | Q24: -
A25: Current Densities (A/cm2) | E25: Bar / ER | H25: P.F. (%): | J25: -
A26: FL / LR | D26: 359 / 2021 | E26: 204 / 134
A27: Stator Slot Shape (Reference) | F27: Performance
H28: LRC (A) | I28: 417 | J28: 682 / 394 | K28: - | M28: =J28/J18 -> #VALUE!
H29: LRT (%) | I29: 60 | J29: 132 | K29: -
H30: BDT (%) | I30: 175 | J30: 215 | K30: -
H31: SLIP (%) | J31: 0.92 | K31: -
G32: IEEE-B | H32: Eff. (%) | J32: 95.3 | K32: -
A33: Rotor Slot Shape (Reference) | H33: PF (%) | J33: 80.6 | K33: -
F34: Losses (Watts) | H34: Primary | J34: 5225 | K34: -
H35: Secondary | J35: 3443 | K35: -
H36: Core | J36: 3586 | K36: -
H37: F & W | J37: 3408 | K37: -
H38: Stray | J38: 2929 | K38: -
A39: End Ring (Reference) | F39: Note | G39: Outer Fan: 550 mm Radial fan w/plate
G40: Rotor Skew, 0.8
...

Sheet LoginSheet
J1: P | K1: T | L1: L | M1: T
B2: PROJECT HISTORY | J2: E | K2: D | L2: I | M2: Y | N2: H
J3: R | L3: M | M3: P
J4: F | L4: I | M4: E
K5: C | L5: T | N5: I
J6: D | K6: U | M6: T | N6: N
J7: A | K7: R | L7: R | M7: E | N7: S
I8: S | J8: T | K8: V | L8: E | M8: S | N8: U
B9: DATE | C9: PROJECT | D9: SMART NUMBER | E9: QTY | F9: CUSTOMER | G9: REMARKS | H9: LIMIT CODE | I9: F | J9: A | K9: E | L9: V | M9: T | N9: L
B53: REVISION HISTORY
B54: REV | C54: REMARKS | I54: DATE | L54: INIT

Sheet StallTime
A1: Rating: | B1: 6 Pole - 500.0 HP - 1200 RPM - 4000 V - 60 Hz
A3: Starting Performance
D4: Load Type: Fan / Pump - 5126.4 lb-ft²
A5: RPM | B5: Motor | C5: Load | D5: Accel. | E5: Line | F5: Stator | G5: Rotor
A6: Speed Increment | B6: Torque (%) | C6: Torque (%) | D6: Time (s) | E6: Amps | F6: kW / s | G6: kW / s
A7: 0~120 | B7: 126.0 | C7: 22.5 | D7: 0.940 | E7: 390.7 | F7: 148.8 | G7: 415.4
A8: 120~240 | B8: 119.4 | C8: 11.5 | D8: 0.901 | E8: 383.8 | F8: 138.0 | G8: 336.5
A9: 240~360 | B9: 115.2 | C9: 7.0 | D9: 0.899 | E9: 376.3 | F9: 132.5 | G9: 285.7
A10: 360~480 | B10: 112.6 | C10: 7.0 | D10: 0.921 | E10: 368.1 | F10: 130.2 | G10: 248.9
A11: 480~600 | B11: 111.0 | C11: 11.0 | D11: 0.973 | E11: 359.5 | F11: 131.4 | G11: 221.5
A12: 600~720 | B12: 110.2 | C12: 18.0 | D12: 1.055 | E12: 350.1 | F12: 135.6 | G12: 198.2
A13: 720~840 | B13: 110.0 | C13: 27.5 | D13: 1.179 | E13: 340.2 | F13: 143.3 | G13: 176.4
A14: 840~960 | B14: 111.7 | C14: 41.5 | D14: 1.386 | E14: 329.2 | F14: 158.7 | G14: 155.5
A15: 960~1020 | B15: 117.7 | C15: 55.5 | D15: 0.782 | E15: 319.3 | F15: 83.3 | G15: 120.5
A16: 1020~1080 | B16: 135.4 | C16: 67.5 | D16: 0.716 | E16: 308.3 | F16: 72.6 | G16: 89.2
... A19: 1188~1191 | B19: 108.3 | C19: 99.0 | D19: 0.281 | E19: 53.0 | F19: 1.4 | G19: 30.4
D21: Acceleration Time: 11.0 s
B22: Energy | D22: First Start | F22: Second Start
A23: Stator Winding Rise | B23: 1356 kW / s | D23: 24°C | F23: 47°C
A24: Rotor Bar Rise | B24: 2059 kW / s | D24: 62°C | F24: 125°C
A25: End Ring Rise | B25: 316 kW / s | D25: 27°C | F25: 55°C
A27: Locked Rotor Thermal Capability
E28: Cold Condition
B29: Rate of Rise | D29: Power | E29: Rise Limit | F29: Max Time
A30: Stator Copper | B30: 3.3°C / s | D30: 191.2 kW | E30: 160°C | F30: 47.9 s
A31: Rotor Bar | B31: 12.7°C / s | D31: 420.3 kW | E31: 260°C | F31: 20.4 s
A32: Rotor ER | B32: 5.6°C / s | D32: 64.6 kW | E32: 180°C | F32: 32.2 s
E34: Hot Condition
B35: Hot Temp. | D35: Rise Limit | E35: Ambient | F35: Total | G35: Max.Time
A36: Stator Copper | B36: 79°C + | D36: 81°C + | E36: 40°C | F36: = 200°C | G36: 24.2 s
A37: Rotor Bar | B37: 108°C + | D37: 152°C + | E37: 40°C | F37: = 300°C | G37: 12.0 s
A38: Rotor ER | B38: 108°C + | D38: 72°C + | E38: 40°C | F38: = 220°C | G38: 12.9 s
A40: Cold Stall Time: | B40: 19.3 s | D40: Hot Stall Time: | F40: 7.7 s

Sheet MagNoise
A1: Magnetic Noise Verification
A3: Rating: | B3: 6 Pole - 500.0 HP - 1200 RPM - 4000 V - 60 Hz
A5: Electromagnetic Excitation Frequencies
B7: L = | C7: 0 | D7: L = | E7: + 1 | F7: L = | G7: - 1 | H7: Slip = | I7: 0 | J7: Slip = | K7: 0.007
A8: Mode A | B8: 8 | D8: 26 | F8: 10 | H8: 1280.0 Hz | J8: 1271.5 Hz
A9: Mode B | B9: 20 | D9: 38 | F9: 2 | H9: 1040.0 Hz | J9: 1031.5 Hz
A10: Mode C | B10: 14 | D10: 32 | F10: 4 | H10: 1160.0 Hz | J10: 1151.5 Hz
A12: Natural Frequencies of Stator Core
B14: Mode 0 = | D14: 2351.7 Hz | F14: Mode 6 = | H14: 3396.9 Hz
B15: Mode 2 = | D15: 264.0 Hz | F15: Mode 7 = | H15: 4675.4 Hz
B16: Mode 3 = | D16: 746.7 Hz | F16: Mode 8 = | H16: 6150.9 Hz
B17: Mode 4 = | D17: 1431.8 Hz | F17: Mode 9 = | H17: 7823.3 Hz
B18: Mode 5 = | D18: 2315.6 Hz | F18: Mode 10 = | H18: 9692.5 Hz
A20: Analysis Results
B22: No matching frequencies detected.

Sheet Performance Data Sheet
A1: TOSHIBA INTERNATIONAL CORPORATION | J1: INDEX | L1: MPCF-1033
A2: Industrial Division / Houston Motor Plant | J2: SHEET NO. | L2: 1 of 1
J3: ISSUED | L3: 7/31/13
J4: SUPERSEDES | L4: 11/8/96
J5: REVISION | L5: 2
A6: SQUIRREL CAGE INDUCTION MOTOR | J6: WRITTEN BY | L6: MDC
A7: PERFORMANCE SPECIFICATIONS | J7: APPROVED BY | L7: PAA
B9: CUSTOMER: | C9: -
B10: TIC SR No.: | C10: -
A12: MOTOR NAMEPLATE DATA
B13: H.P.: | C13: 500 | E13: VOLTS: | F13: 2300/4000 | H13: 3 PH / | I13: 60 Hz | L13: S. RPM: | M13: 1200
B14: FRAME: | C14: 5811US | E14: ENCL: | F14: TEFC | H14: FLAMPS: | I14: 121/70 | L14: FLRPM: | M14: 1190
B15: FORM: | C15: FCKW | E15: S.F.: | F15: 1.15 | H15: NEMA DESIGN: | I15: - | L15: INSUL CLASS: | M15: F
B16: TYPE: | C16: TIKK | E16: AMB.: | F16: 40°C | H16: CODE: | I16: F | L16: DUTY: | M16: Cont.
B17: MODEL No.: | C17: 5006FTAL11E-A | H17: kW: | I17: -
B18: NOM. EFF.: | C18: - | E18: MIN. EFF.: | F18: - | H18: P.F.: | I18: -
A21: AMPERAGE | E21: TORQUES | I21: **BEARINGS:
C22: LOCKED ROTOR: | D22: 682/394 | G22: FULL LOAD (lb-ft.): | H22: 2207 | K22: DRIVE END: | L22: REFER TO NP
G23: LOCKED ROTOR (%): | H23: 130 | K23: OPPOSITE DRIVE END: | L23: REFER TO NP
G24: BREAK DOWN (%): | H24: 215
A28: EFFICIENCY | H28: POWER FACTOR
C29: FULL LOAD: | D29: 95.3 | J29: FULL LOAD: | K29: 80.6
C30: 3/4 LOAD: | D30: 94.8 | J30: 3/4 LOAD: | K30: 77.7
C31: 1/2 LOAD: | D31: 93.4 | J31: 1/2 LOAD: | K31: 69.9
A35: ALL CHARACTERISTICS ARE AVERAGE EXPECTED VALUES BASED UPON RATED VOLTAGE,
A36: FREQUENCY AND SINEWAVE POWER INPUT.
A37: THE DECLARED LOCKED ROTOR CURRENT HAS A TOLERANCE OF 20%.
A38: * TEMPERATURE RISE WILL BE CONSISTENT WITH INSULATION, AMBIENT AND SERVICE FACTOR AS
A39: DEFINED BY NEMA-MG-12 OR -20.
A40: ** BEARINGS ARE THE ONLY RECOMMENDED SPARE PART(S).
J42: CERTIFIED BY: | K42: Zichao Xie
J44: DATE: | K44: 43608
A59: - | B59: 6205ZZ | D59: 1 | E59: -
A60: TEFC | B60: 6206UU | D60: 1.15 | E60: A
A61: ODP | B61: 6207ZZ | E61: B
B62: 6208UU
B63: 6211ZZ
B64: 6211C3
B65: 6211ZZC3
B66: 6305UUC3
...

Sheet STCurve
A2: TOSHIBA INTERNATIONAL CORPORATION
A3: Speed Torque/Current Curve
A6: Model #: | B6: ='Performance Data Sheet'!C17 -> 5006FTAL11E-A | E6: FLAmps: | F6: ='Performance Data Sheet'!I14 -> 121/70
A7: Enclosure: | B7: ='Performance Data Sheet'!F14 -> TEFC | C7: Voltage: | D7: ='Performance Data Sheet'!F13 & " V" -> 2300/4000 V | E7: Frame: | F7: ='Performance Data Sheet'!C14 -> 5811US
A8: Pole: | B8: 6 | C8: Frequency: | D8: 3 PH / 60 Hz | E8: Ins. Class: | F8: ='Performance Data Sheet'!M15 -> F
A9: HP: | B9: ='Performance Data Sheet'!C13 -> 500 | C9: Rotor Inertia: | D9: 373.2 lb-ft² | E9: Date: | F9: ='Performance Data Sheet'!K44 -> 43608
A10: FLRPM: | B10: ='Performance Data Sheet'!M14 -> 1190 | C10: Load Inertia: | D10: 5126.4 lb-ft² | E10: File: | F10: RF6500USS
B12: Locked Rotor Amps: | C12: ='Performance Data Sheet'!D22 & " A" -> 682/394 A | D12: Load Type: | E12: Fan / Pump
B13: Locked Rotor Torque: | C13: ='Performance Data Sheet'!H23/100 -> 1.3 | D13: Starting at: | E13: FV (V)
B14: Breakdown Torque: | C14: 2.15 | D14: Accel. Time: | E14: 11.0 (s)
B15: Rated Torque: | C15: ='Performance Data Sheet'!H22 & " lb-ft" -> 2207 lb-ft
A39: Comments: | B39: PROJECT | C39: ='Performance Data Sheet'!C10 -> - | E39: D.E.Curve #: | F39: =F10 -> RF6500USS
C43: Prepared by: | D43: ='Performance Data Sheet'!K42 -> Zichao Xie | E43: Checked by:
D53: Load
A54: 100 | B54: 0 | C54: 0.32744125 | D54: 100
A55: 99 | B55: 116.68075 | C55: 128.57436 | D55: 98
A56: 95 | B56: 215 | C56: 368.00668 | D56: 87
A57: 90 | B57: 148.66614 | C57: 430.56842 | D57: 74
A58: 84.999999 | B58: 122.13802 | C58: 450.33722 | D58: 61
A59: 80 | B59: 113.3121 | C59: 461.86069 | D59: 50
A60: 69.999999 | B60: 110.03264 | C60: 478.75156 | D60: 33
A61: 59.999999 | B61: 110 | C61: 493.22357 | D61: 22
A62: 50 | B62: 110.49625 | C62: 507.12366 | D62: 14
A63: 39.999998 | B63: 111.60128 | C63: 519.90558 | D63: 7.9999995
A64: 30.000001 | B64: 113.55299 | C64: 531.86322 | D64: 5.9999995
A65: 19.999999 | B65: 116.82707 | C65: 543.22675 | D65: 8.000001
... A67: 0 | B67: 130 | C67: 562.85712 | D67: 30

Sheet Thermdam
A2: TOSHIBA INTERNATIONAL CORPORATION
A3: Thermal Limit & Acceleration Curves
A4: Design Values (For Reference Only)
A6: Model #: | B6: ='Performance Data Sheet'!C17 -> 5006FTAL11E-A | E6: FLAmps: | F6: ='Performance Data Sheet'!I14 -> 121/70
A7: Enclosure: | B7: ='Performance Data Sheet'!F14 -> TEFC | C7: Voltage: | D7: ='Performance Data Sheet'!F13 & " V" -> 2300/4000 V | E7: Frame: | F7: ='Performance Data Sheet'!C14 -> 5811US
A8: Pole: | B8: 6 | C8: Frequency: | D8: 3 PH / 60 Hz | E8: Ins. Class: | F8: ='Performance Data Sheet'!M15 -> F
A9: HP: | B9: ='Performance Data Sheet'!C13 -> 500 | C9: Rotor Inertia: | D9: 373.2 lb-ft² | E9: Date: | F9: ='Performance Data Sheet'!K44 -> 43608
A10: FLRPM: | B10: ='Performance Data Sheet'!M14 -> 1190 | C10: Load Inertia: | D10: 5126.4 lb-ft² | E10: File: | F10: RF6500USS
C12: ='Performance Data Sheet'!D22 & " A" -> 682/394 A
C13: ='Performance Data Sheet'!H23/100 -> 1.3
C15: ='Performance Data Sheet'!H22 & " lb-ft" -> 2207 lb-ft
A39: Comments: | B39: PROJECT | C39: ='Performance Data Sheet'!C10 -> - | E39: D.E.Curve #: | F39: =F10 -> RF6500USS
C43: Prepared by: | D43: ='Performance Data Sheet'!K42 -> Zichao Xie | E43: Checked by:
F50: =5252.1*B50/D53 -> #DIV/0!
D66: =D65/D64 -> #DIV/0!
A67: Current (%) | B67: Cold | C67: Hot | E67: CURRENT (%) | F67: Accel. Time
A68: 562.85714 | B68: 27.554234 | C68: 11.065512 | E68: =A68 -> 562.85714 | F68: 0.0001
A69: 488.57886 | B69: =((A68/A69)^2)*B68 -> 36.569192 | C69: =((A68/A69)^2)*C68 -> 14.685831 | E69: 558.14286 | F69: 0.94
A70: 414.27829 | B70: =((A68/A70)^2)*B68 -> 50.862812 | C70: =((A68/A70)^2)*C68 -> 20.426009 | E70: 548.28571 | F70: 1.841
A71: 340 | B71: =((A68/A71)^2)*B68 -> 75.513895 | C71: =((A68/A71)^2)*C68 -> 30.325644 | E71: 537.57143 | F71: 2.74
A72: =A71-100 -> 240 | B72: =((A68/A72)^2)*B68 -> 151.55219 | E72: 525.85714 | F72: 3.661
A73: =A72-100 -> 140 | B73: =((A68/A73)^2)*B68 -> 445.37787 | E73: 513.57143 | F73: 4.6339998
A74: 215 | B74: =((A68/A74)^2)*B68 -> 188.846 | C74: =((A68/A74)^2)*C68 -> 75.838711 | E74: 500.14286 | F74: 5.6889997
A75: 180 | B75: =((A68/A75)^2)*B69 -> 357.57465 | C75: =((A68/A75)^2)*C68 -> 108.1989 | E75: 486 | F75: 6.8679996
A76: 145 | B76: =((A68/A76)^2)*B68 -> 415.19174 | C76: =((A68/A76)^2)*C68 -> 166.73695 | E76: 470.28571 | F76: 8.2539997
A77: 125 | C77: =CEILING(C76*2,100) -> 400 | E77: 456.14286 | F77: 9.0359993
A78: 125 | C78: =2*C77 -> 800 | E78: 440.42857 | F78: 9.7519989
A79: 125 | C79: 10000 | E79: 399.28571 | F79: 10.231998
E80: =A74 -> 215 | F80: 10.762999
E81: =A77 -> 125 | F81: 11.043999

Sheet Performance 4000V
A2: TOSHIBA INTERNATIONAL CORPORATION
A3: Performance Curve
A4: Design Values (For Reference Only)
A6: Model #: | B6: ='Performance Data Sheet'!C17 -> 5006FTAL11E-A | E6: FLAmps: | F6: 70
A7: Enclosure: | B7: ='Performance Data Sheet'!F14 -> TEFC | C7: Voltage: | D7: 4000 V | E7: Frame: | F7: ='Performance Data Sheet'!C14 -> 5811US
A8: Pole: | B8: 6 | C8: Frequency: | D8: 3 PH / 60 Hz | E8: Ins. Class: | F8: ='Performance Data Sheet'!M15 -> F
A9: HP: | B9: ='Performance Data Sheet'!C13 -> 500 | C9: Rotor Inertia: | D9: 373.2 lb-ft² | E9: Date: | F9: ='Performance Data Sheet'!K44 -> 43608
A10: FLRPM: | B10: ='Performance Data Sheet'!M14 -> 1190 | C10: Load Inertia: | D10: 5126.4 lb-ft² | E10: File: | F10: RF6500USS
B12: Locked Rotor Amps: | C12: 394 A | D12: Load Type: | E12: Fan / Pump
B13: Locked Rotor Torque: | C13: ='Performance Data Sheet'!H23/100 -> 1.3 | D13: Starting at: | E13: FV (V)
B14: Breakdown Torque: | C14: 2.15 | D14: Accel. Time: | E14: 11.0 (s)
B15: Rated Torque: | C15: ='Performance Data Sheet'!H22 & " lb-ft" -> 2207 lb-ft
A39: Comments: | B39: PROJECT | C39: ='Performance Data Sheet'!C10 -> - | E39: D.E.Curve #: | F39: =F10 -> RF6500USS
C43: Prepared by: | D43: ='Performance Data Sheet'!K42 -> Zichao Xie | E43: Checked by:
A53: Load | B53: Efficiency | C53: PF | D53: Amps | E53: RPM | F53: Input Watts
A54: 0 | D54: 23.642894 | E54: 100 | F54: =7515/10000 -> 0.7515
A55: 25 | B55: 88.687767 | C55: 49.625484 | D55: 30.60771 | E55: 82.935984 | F55: 10.523094
A56: 50 | B56: 93.4245 | C56: 69.921837 | D56: 41.243511 | E56: 72.392025 | F56: 19.97912
A57: 75 | B57: 94.831856 | C57: 77.67775 | D57: 54.861748 | E57: 61.556054 | F57: 29.523928
A58: 100 | B58: 95.337585 | C58: 80.60006 | D58: 70.122879 | E58: 50.137789 | F58: 39.156419
A59: 125 | B59: 95.443146 | C59: 81.240479 | D59: 86.866447 | E59: 38.349364 | F59: 48.891392

Sheet Performance 2300V
A2: TOSHIBA INTERNATIONAL CORPORATION
A3: Performance Curve
A4: Design Values (For Reference Only)
A6: Model #: | B6: ='Performance Data Sheet'!C17 -> 5006FTAL11E-A | E6: FLAmps: | F6: 121
A7: Enclosure: | B7: ='Performance Data Sheet'!F14 -> TEFC | C7: Voltage: | D7: 2300 V | E7: Frame: | F7: ='Performance Data Sheet'!C14 -> 5811US
A8: Pole: | B8: 6 | C8: Frequency: | D8: 3 PH / 60 Hz | E8: Ins. Class: | F8: ='Performance Data Sheet'!M15 -> F
A9: HP: | B9: ='Performance Data Sheet'!C13 -> 500 | C9: Rotor Inertia: | D9: 373.2 lb-ft² | E9: Date: | F9: ='Performance Data Sheet'!K44 -> 43608
A10: FLRPM: | B10: ='Performance Data Sheet'!M14 -> 1190 | C10: Load Inertia: | D10: 5126.4 lb-ft² | E10: File: | F10: RF6500USS
B12: Locked Rotor Amps: | C12: 682 A | D12: Load Type: | E12: Fan / Pump
B13: Locked Rotor Torque: | C13: ='Performance Data Sheet'!H23/100 -> 1.3 | D13: Starting at: | E13: FV (V)
B14: Breakdown Torque: | C14: 2.15 | D14: Accel. Time: | E14: 11.0 (s)
B15: Rated Torque: | C15: ='Performance Data Sheet'!H22 & " lb-ft" -> 2207 lb-ft
A39: Comments: | B39: PROJECT | C39: ='Performance Data Sheet'!C10 -> - | E39: D.E.Curve #: | F39: =F10 -> RF6500USS
C43: Prepared by: | D43: ='Performance Data Sheet'!K42 -> Zichao Xie | E43: Checked by:
A53: Load | B53: Efficiency | C53: PF | D53: Amps | E53: RPM | F53: Input Watts
A54: 0 | D54: 40.950694 | E54: 100 | F54: =7515/10000 -> 0.7515
A55: 25 | B55: 88.687767 | C55: 49.625484 | D55: 53.014109 | E55: 82.935984 | F55: 10.523094
A56: 50 | B56: 93.4245 | C56: 69.921837 | D56: 71.435857 | E56: 72.392025 | F56: 19.97912
A57: 75 | B57: 94.831856 | C57: 77.67775 | D57: 95.023334 | E57: 61.556054 | F57: 29.523928
A58: 100 | B58: 95.337585 | C58: 80.60006 | D58: 121 | E58: 50.137789 | F58: 39.156419
A59: 125 | B59: 95.443146 | C59: 81.240479 | D59: 150.4571 | E59: 38.349364 | F59: 48.891392
