Workbook
Name Print_Area_MI: 'Performance Data Sheet'!$A$10:$N$42

Sheet DesignSheet
A1: TOSHIBA INTERNATIONAL CORPORATION | I1: Calc. Code: | J1: 2-2-2-0-1-2
A2: 3-PHASE SQUIRREL CAGE INDUCTION MOTOR DESIGN SHEET | J2: B.L.-1 P.F.-1
A3: File: | B3: G:\Motor R&D\Active Projects\6810 Development\Electrical Design\2P\SERIES\DT2M90U.rat | G3: Date: | H3: 43151 | I3: Time: | J3: 0.36837963
A4: Pole | B4: HP | C4: RPM | D4: Form | E4: Voltage | F4: Frequency | G4: Temperature | H4: FLSpeed | I4: FLSlip | J4: Frame
A5: 2 | B5: 4500 | C5: 3600 | D5: DCW | E5: 4000 | F5: 60 | G5: 105 | H5: 3574.8 / 3581.6 | I5: 0.0070 / 0.0051 | J5: 6813USS
A6: Core Data | D6: Winding Data | E6: USA Wire Std | H6: Constant Data
B7: Primary | C7: Secondary | F7: Bar | G7: End Ring | H7: St. Slot Pitch | I7: 26.179917 | J7: LR Test Data
A8: Air Gap | B8: 3.5 | H8: Rt. Slot Pitch | I8: 30.254878 | J8: ES
A9: Space Fac. | B9: 0.93000001 | D9: Pitch | E9: 1 ~ 18 | F9: Cross Section Area | H9: Mean Value | I9: 28.217397 | J9: 739.22668
A10: Core Length | B10: 880 | C10: 880 | F10: UB: 322.1 | G10: UER: 3768.4 | H10: Eff.T.W.St. | I10: 17.127578 | J10: WS
A11: OD | B11: 815 | C11: 443 | D11: Coil Pitch | E11: 0.62956667 | H11: Eff.T.W.Rt. | I11: 29.859305 | J11: 147178.74
A12: ID | B12: 450 | C12: 170 | D12: Slot Fill | E12: - | F12: EBL: 62.5 | G12: ERD1: 328.0 | H12: St.Carter Fac. | I12: 1.5285241 | J12: IS
A13: Core Depth | B13: 109.5 | C13: 98.09 | D13: Con./Slot | E13: 10 | G13: ERT: 65.54 | H13: Rt.Carter Fac. | I13: 1.0132479 | J13: 528.9256
A14: Eff.Core L. | B14: 662.16003 | C14: 717.96002 | D14: Wire Size 1 | E14: (.081"x.258")x2 | G14: ERH: 57.50 | H14: Carter Factor | I14: 1.5487738 | J14: Volts / Turn
A15: Slot Data | D15: Wire Size 2 | E15: (.081"x.258")x2 | H15: Short. Factor | I15: 0.835433 | J15: 51.321528
A16: Number | B16: 54 | C16: 46 | D16: // Circuits | E16: 2 | H16: Distrib. Factor | I16: 0.95529271 | J16: AC
A17: Kind | B17: Open | C17: Trapeze | D17: Connection | E17: Wye | H17: Wind. Factor | I17: 0.79808305 | J17: 1010.1743
A18: Skew | B18: - | C18: 0 | D18: MCL | E18: 1747 | F18: 1070.537 | H18: Reactance | I18: (Coeff.: 0.0133)
A19: Depth | B19: 73 | C19: 38.41 | D19: No.Cond./Ph. | E19: 90 | I19: Running | J19: Start
A20: Width | B20: 17.30 - 17.30 | D20: Res. (20°C) | E20: 0.025989119 | H20: Stator Slot | I20: 14.993257 | J20: 14.993257
A21: Opening | B21: 17.299999 | C21: 3 | D21: (105°C) | E21: 0.034669178 | F21: 0.026501136 | G21: 0.0055189455 | H21: Rotor Slot | I21: 16.318153 | J21: 13.797791
A22: Tip Depth | B22: 13.15 | C22: 3 | D22: Material | E22: CU | F22: CU | G22: CU | H22: Zigzag | I22: 4.6907854 | J22: 3.940778
A23: T.Min.Wid. | B23: 8.8799171 | C23: 10.888422 | D23: Spec.Resist. | E23: 1.742 | F23: 1.742 | G23: 1.742 | H23: Coil End | I23: 20.574921 | J23: Skew R.: 0.00
A24: Low. R. | B24: 0 | C24: 0.80000001 | D24: Spec.Gravity | E24: 8.8900003 | F24: 8.8900003 | G24: 8.8900003 | H24: Belt Leakage | I24: 6.7857612 | J24: 5.7389827
A25: Up. R. | B25: - | C25: 5.7199998 | D25: Weight (kg) | H25: Total Resist. | I25: 0.06668926 | J25: 0.17536166
A26: Wedge Dep. | B26: 0.80 - 2.40 | C26: Normal | D26: Wire 1 | E26: 220.96346 | F26: 149.66178 | G26: 84.531503 | H26: Total React. | I26: 0.84577936 | J26: 0.78764349
A27: Duct | B27: 28 x 6 | C27: 18 x 6 | D27: Wire 2 | E27: 220.96346 | F27: - | G27: - | H27: Impedance | I27: 0.84840453 | J27: 0.80692869
A28: Effective Depth (S=1) | D28: Magnetic Circuit Data | I28: Core Loss Data
B29: Res.= | C29: 35.359193 | E29: Length | F29: Section | G29: Density | H29: AT | I29: Volume | J29: Loss | M29: =RIGHT(F$41,SEARCH("/",F$41,1)-1) -> 3575.1 | N29: 125RPM
B30: Reac.= | C30: 35.395463 | D30: Primary Core | E30: 64.009896 | F30: 1450.1305 | G30: 16.646011 | H30: 902.58455 | I30: 160702.86 | J30: 13016.974 | M30: =RIGHT(E$41,SEARCH("/",E$41,1)-1) -> 3581.6 | N30: 100RPM
A31: Excitation Data | D31: Tooth | E31: 7.3 | F31: 1587.5801 | G31: 15.204832 | H31: 70.062849 | I31: 23178.669 | J31: 1621.2973 | M31: =RIGHT(D$41,SEARCH("/",D$41,1)-1) -> 3588.2 | N31: 75RPM
A32: Excit.Amps | B32: 82.198 / 97.893 | D32: Second.Core | E32: 28.759686 | F32: 1815.338 | G32: 13.297187 | H32: 160.32632 | I32: Total | J32: 14638.272 | M32: =RIGHT(C$41,SEARCH("/",C$41,1)-1) -> 3594.5 | N32: 50RPM
A33: Core Loss | B33: 5.095 / 6.068 | C33: Flux / Pole | D33: Tooth | E33: 3.841 | F33: 1798.0139 | G33: 13.425307 | H33: 22.184568 | I33: C.L.C. | J33: 1.75 / 0.96 | M33: =RIGHT(B$41,SEARCH("/",B$41,1)-1) -> 3600.6 | N33: 25RPM
A34: NoLoad | B34: 82.36 / 98.08 | C34: 24.138888 | D34: Air Gap | E34: 0.35 | F34: 3386.4754 | G34: 7.128027 | H34: 1985.308 | I34: S.F.C. | J34: 6.0500002
A35: Load Characteristics | D35: Temp. Rise @ 100%: | E35: 75 / 73 | G35: No Load Loss | H35: 46560.9 / 45197.3 | I35: W.Loss | J35: 25617.0 / 13982.3
A36: Load (%) | B36: 25 | C36: 50 | D36: 75 | E36: 100 | F36: 125 | G36: Primary Loss | H36: 29097.4 / 31937.4 | I36: S.Loss | J36: 9717.1 / 5303.8
A37: Current (A) | B37: 157.51 / 164.80 | C37: 272.61 / 285.23 | D37: 397.83 / 416.24 | E37: 528.93 / 553.40 | F37: 665.82 / 696.63 | G37: Second. Loss | H37: 24429.0 / 16909.7 | I37: Total C.Loss | J37: 35334.1 / 19286.2
A38: Efficiency | B38: 0.944 / 0.936 | C38: 0.966 / 0.958 | D38: 0.971 / 0.963 | E38: 0.972 / 0.963 | F38: 0.970 / 0.962 | G38: Frict.& Wind. | H38: 10700.0 / 27352.0 | I38: Stray Loss | J38: 32227.684 | L38: =LEFT(E38,SEARCH("/",E38,1)-1) -> 0.972 | M38: =RIGHT(E38,SEARCH("/",E38,1)-1) -> 0.963 | N38: =M38/L38 -> 0.99074074 | O38: Eff.
A39: P.F. | B39: 0.815 / 0.786 | C39: 0.920 / 0.887 | D39: 0.941 / 0.907 | E39: 0.943 / 0.909 | F39: 0.937 / 0.904 | G39: Starting Data | I39: Slip | J39: PF | L39: =LEFT(E39,SEARCH("/",E39,1)-1) -> 0.943 | M39: =RIGHT(E39,SEARCH("/",E39,1)-1) -> 0.909 | N39: =M39/L39 -> 0.96394486 | O39: PF.
A40: Slip | B40: 0.0017 / -0.0002 | C40: 0.0034 / 0.0015 | D40: 0.0051 / 0.0033 | E40: 0.0070 / 0.0051 | F40: 0.0088 / 0.0069 | G40: LRA | H40: 2862.0 / 2825.6 | L40: =LEFT(E37,SEARCH("/",E37,1)-1) -> 528.93 | M40: =RIGHT(E37,SEARCH("/",E37,1)-1) -> 553.40 | N40: =M40/L40 -> 1.0462632 | O40: Current
...

Sheet Data Sheet
A1: TOSHIBA INTERNATIONAL CORPORATION
A2: INDUCTION MOTOR DATA SHEET
A3: File: | B3: DT2M90U | I3: HRW / Model Number: | J3: M903WTQL11F-C
A4: Type: TIKE - Form: DCW - 2 Pole - 4500 HP - 4000 V - 60 Hz - 6813USS - Class F | Q4: Motor Type Selection | T4: Electrical Steel Table
A5: Motor Parameters | F5: PERFORMANCE | J5: DESIGN | K5: TEST | Q5: EPACT | T5: M22 - 26Ga.
A6: Material | D6: M36 - 26Ga. | F6: NL & Impedance Test | Q6: EQP-III | T6: M36 - 26Ga.
A7: Air Gap | D7: 3.5 | F7: No load amps | J7: 98 | K7: - | Q7: Exp.Prf. | T7: NCB1 - 26Ga.
A8: Stack length | D8: 880 | F8: No load watts | J8: 45197 | K8: - | Q8: Exp.Prf.-EQPIII | T8: M43 - 26Ga.
A9: Number of turns per coil | D9: 5 | F9: Impedance amps | H9: 1 | I9: f | J9: 823 | K9: - | Q9: Prem. Eff. | T9: M45 - 26Ga.
A10: Wire 1 (size & number) | D10: (.081"x.258")x2 | F10: Impedance volts | H10: 1 | I10: f | J10: 1150 | K10: - | Q10: OWP | T10: M54 - 26Ga.
A11: Wire 2 (size & number) | D11: (.081"x.258")x2 | F11: Impedance watts | H11: 1 | I11: f | J11: 147179 | K11: - | Q11: Dry Kiln
A12: Slot fill - circle/square method (%) | D12: - | F12: Temperature Rise (°C)
A13: Connection | D13: 2 x Wye | G13: Winding | I13: 80/115 | J13: 75 / 99 | K13: -
A14: MCL | D14: 1747 | G14: Frame | J14: - | K14: -
A15: Allowance for ins. depth | D15: 14.702001 | G15: Bearing PS/OS | J15: - | K15: -
A16: Allowance for ins. width | D16: 3.7935998 | G16: End Ring | J16: - | K16: -
A17: Slot/Wire arrangement | D17: 20 x 2 | F17: Nameplate Data
A18: Effective cross section for coil | D18: - | H18: FLC (A) | J18: 553 | M18: =J18*6.5 -> 3594.5
A19: Coil grouping | D19: Interspersed | H19: RPM | J19: 3580
A20: Coil pitch (slot number) | D20: 1 ~ 18 | H20: CODE | J20: D
A21: Method of coil connection | D21: - | H21: S. F. | J21: 1.15 | Q21: Method of Connection
A22: Resistance per phase @ 20 °C | D22: 0.027 | H22: DESIGN | J22: - | Q22: Skip
A23: Coil Weight | B23: Wire1 | D23: 998 | H23: Nom.Eff. (%): | J23: - | Q23: Adjacent
A24: (lbs.) | B24: Wire2 | H24: Min.Eff. (%): | J24: - | Q24: -
A25: Current Densities (A/cm2) | E25: Bar / ER | H25: P.F. (%): | J25: -
A26: FL / LR | D26: 525 / 2683 | E26: 767 / 481
A27: Stator Slot Shape (Reference) | F27: Performance
H28: LRC (A) | I28: - | J28: 2826 | K28: - | M28: =(J28/J18)*100 -> 511.03074
H29: LRT (%) | I29: 60 | J29: 70 | K29: -
H30: BDT (%) | I30: 175 | J30: 177 | K30: -
H31: SLIP (%) | J31: 0.51 | K31: -
G32: IEEE-B | H32: Eff. (%) | J32: 96.3 | K32: -
A33: Rotor Slot Shape (Reference) | H33: PF (%) | J33: 90.9 | K33: -
F34: Losses (Watts) | H34: Primary | J34: 31937 | K34: -
H35: Secondary | J35: 16910 | K35: -
H36: Core | J36: 19286 | K36: -
H37: F & W | J37: 27352 | K37: -
H38: Stray | J38: 32228 | K38: -
A39: End Ring (Reference) | F39: Note | G39: BASE DT2M90U
H40: QC Limits: DT2M90U
...

Sheet LoginSheet
J1: P | K1: T | L1: L | M1: T
B2: PROJECT HISTORY | J2: E | K2: D | L2: I | M2: Y | N2: H
J3: R | L3: M | M3: P
J4: F | L4: I | M4: E
K5: C | L5: T | N5: I
J6: D | K6: U | M6: T | N6: N
J7: A | K7: R | L7: R | M7: E | N7: S
I8: S | J8: T | K8: V | L8: E | M8: S | N8: U
B9: DATE | C9: PROJECT | D9: SMART NUMBER | E9: QTY | F9: CUSTOMER | G9: REMARKS | H9: LIMIT CODE | I9: F | J9: A | K9: E | L9: V | M9: T | N9: L
B53: REVISION HISTORY
B54: REV | C54: REMARKS | I54: DATE | L54: INIT

Sheet Form
A1: Winding Data Calculation
C2: MCL: 1747.0
A3: Coil Resistance | D3: Lead Resistance
A4: 5T: | B4: 0.0059 ~ 0.0057 | D4: AWG. (4/0 x 2) x 3
D5: 0.00068/2 = 0.00034
A6: Coil Dimensions
A7: HM: | B7: 5T: 11.29 | C7: WM: | D7: 5T: 27.01 | E7: WT:
E8: 17.40 ~ 17.00
A9: Insulation Allowance | D9: Wire Weight
A10: Depth: | B10: 14.7 | D10: (.081"x.258")x 2: | F10: 499 lbs.
A11: Width: | B11: 3.79 | D11: (.081"x.258")x 2: | F11: 499 lbs.
A12: QC Resistance
A13: 1-2, 2-3, 3-1: | C13: 0.056 ~ 0.052

Sheet StallTime
A1: Rating: | B1: 2 Pole - 4500.0 HP - 3600 RPM - 4000 V - 60 Hz
A3: Starting Performance
D4: Load Type: Fan / Pump - 813.3 lb-ft²
A5: RPM | B5: Motor | C5: Load | D5: Accel. | E5: Line | F5: Stator | G5: Rotor
A6: Speed Increment | B6: Torque (%) | C6: Torque (%) | D6: Time (s) | E6: Amps | F6: kW / s | G6: kW / s
A7: 0~375 | B7: 71.1 | C7: 22.4 | D7: 0.575 | E7: 2820.1 | F7: 477.6 | G7: 1643.6
A8: 375~750 | B8: 71.2 | C8: 11.3 | D8: 0.467 | E8: 2807.3 | F8: 385.1 | G8: 1198.7
A9: 750~1125 | B9: 71.5 | C9: 7.0 | D9: 0.435 | E9: 2792.4 | F9: 354.7 | G9: 987.9
A10: 1125~1501 | B10: 71.9 | C10: 7.6 | D10: 0.436 | E10: 2774.9 | F10: 351.2 | G10: 863.2
A11: 1501~1876 | B11: 72.6 | C11: 12.3 | D11: 0.464 | E11: 2754.3 | F11: 369.4 | G11: 787.0
A12: 1876~2251 | B12: 73.8 | C12: 20.2 | D12: 0.522 | E12: 2730.1 | F12: 408.9 | G12: 736.3
A13: 2251~2626 | B13: 75.7 | C13: 31.4 | D13: 0.632 | E13: 2701.8 | F13: 485.4 | G13: 711.0
A14: 2626~3001 | B14: 79.4 | C14: 47.7 | D14: 0.883 | E14: 2663.8 | F14: 663.1 | G14: 740.2
A15: 3001~3189 | B15: 85.9 | C15: 63.9 | D15: 0.634 | E15: 2619.9 | F15: 459.7 | G15: 694.4
A16: 3189~3376 | B16: 99.5 | C16: 77.1 | D16: 0.625 | E16: 2548.3 | F16: 439.0 | G16: 517.4
... A18: 3564~3575 | B18: 139.0 | C18: 98.8 | D18: 0.020 | E18: 1408.7 | F18: 0.6 | G18: 34.9
D21: Acceleration Time: 6.0 s
B22: Energy | D22: First Start | F22: Second Start
A23: Stator Winding Rise | B23: 4568 kW / s | D23: 27°C | F23: 54°C
A24: Rotor Bar Rise | B24: 7498 kW / s | D24: 130°C | F24: 260°C
A25: End Ring Rise | B25: 1562 kW / s | D25: 48°C | F25: 96°C
A27: Locked Rotor Thermal Capability
E28: Cold Condition
B29: Rate of Rise | D29: Power | E29: Rise Limit | F29: Max Time
A30: Stator Copper | B30: 5.8°C / s | D30: 990.7 kW | E30: 160°C | F30: 27.5 s
A31: Rotor Bar | B31: 34.2°C / s | D31: 1972.7 kW | E31: 260°C | F31: 7.6 s
A32: Rotor ER | B32: 12.6°C / s | D32: 410.8 kW | E32: 180°C | F32: 14.3 s
E34: Hot Condition
B35: Hot Temp. | D35: Rise Limit | E35: Ambient | F35: Total | G35: Max.Time
A36: Stator Copper | B36: 75°C + | D36: 85°C + | E36: 40°C | F36: = 200°C | G36: 14.6 s
A37: Rotor Bar | B37: 101°C + | D37: 159°C + | E37: 40°C | F37: = 300°C | G37: 4.6 s
A38: Rotor ER | B38: 101°C + | D38: 79°C + | E38: 40°C | F38: = 220°C | G38: 6.2 s
A40: Cold Stall Time: | B40: 12.4 s | D40: Hot Stall Time: | F40: 5.4 s

Sheet Performance Data Sheet
A1: TOSHIBA INTERNATIONAL CORPORATION | J1: INDEX | L1: MPCF-1033
A2: Industrial Division / Houston Motor Plant | J2: SHEET NO. | L2: 1 of 1
J3: ISSUED | L3: 7/31/13
J4: SUPERSEDES | L4: 11/8/96
J5: REVISION | L5: 2
A6: SQUIRREL CAGE INDUCTION MOTOR | J6: WRITTEN BY | L6: MDC
A7: PERFORMANCE SPECIFICATIONS | J7: APPROVED BY | L7: PAA
B9: CUSTOMER: | C9: -
B10: TIC SR No.: | C10: -
A12: MOTOR NAMEPLATE DATA
B13: H.P.: | C13: 4500 | E13: VOLTS: | F13: 4000 | H13: 3 PH / | I13: 60 Hz | L13: S. RPM: | M13: 3600
B14: FRAME: | C14: 6813USS | E14: ENCL: | F14: WPII | H14: FLAMPS: | I14: 553 | L14: FLRPM: | M14: 3580
B15: FORM: | C15: DCKW4 | E15: S.F.: | F15: 1.15 | H15: NEMA DESIGN: | I15: - | L15: INSUL CLASS: | M15: F
B16: TYPE: | C16: TIKE | E16: AMB.: | F16: 40°C | H16: CODE: | I16: D | L16: DUTY: | M16: Cont.
B17: MODEL No.: | C17: QUOTE # 17548 | H17: kW: | I17: -
B18: NOM. EFF.: | C18: - | E18: MIN. EFF.: | F18: - | H18: P.F.: | I18: -
A21: AMPERAGE | E21: TORQUES | I21: **BEARINGS:
C22: LOCKED ROTOR: | D22: 2826 | G22: FULL LOAD (lb-ft.): | H22: 6602 | K22: DRIVE END: | L22: REFER TO NP
G23: LOCKED ROTOR (%): | H23: 71 | K23: OPPOSITE DRIVE END: | L23: REFER TO NP
G24: BREAK DOWN (%): | H24: 178
A28: EFFICIENCY | H28: POWER FACTOR
C29: FULL LOAD: | D29: 96.3 | J29: FULL LOAD: | K29: 90.9
C30: 3/4 LOAD: | D30: 96.2 | J30: 3/4 LOAD: | K30: 90.7
C31: 1/2 LOAD: | D31: 95.7 | J31: 1/2 LOAD: | K31: 88.7
A35: ALL CHARACTERISTICS ARE AVERAGE EXPECTED VALUES BASED UPON RATED VOLTAGE,
A36: FREQUENCY AND SINEWAVE POWER INPUT.
A37: THE DECLARED LOCKED ROTOR CURRENT HAS A TOLERANCE OF 20%.
A38: * TEMPERATURE RISE WILL BE CONSISTENT WITH INSULATION, AMBIENT AND SERVICE FACTOR AS
A39: DEFINED BY NEMA-MG-12 OR -20.
A40: ** BEARINGS ARE THE ONLY RECOMMENDED SPARE PART(S).
J42: CERTIFIED BY: | K42: Zichao Xie
J44: DATE: | K44: 43151
A59: - | B59: 6205ZZ | D59: 1 | E59: -
A60: TEFC | B60: 6206UU | D60: 1.15 | E60: A
A61: ODP | B61: 6207ZZ | E61: B
B62: 6208UU
B63: 6211ZZ
B64: 6211C3
B65: 6211ZZC3
B66: 6305UUC3
...

Sheet STCurve
A2: TOSHIBA INTERNATIONAL CORPORATION
A3: Speed Torque/Current Curve
A6: Model #: | B6: ='Performance Data Sheet'!C17 -> QUOTE # 17548 | E6: FLAmps: | F6: ='Performance Data Sheet'!I14 -> 553
A7: Enclosure: | B7: ='Performance Data Sheet'!F14 -> WPII | C7: Voltage: | D7: ='Performance Data Sheet'!F13 & " V" -> 4000 V | E7: Frame: | F7: ='Performance Data Sheet'!C14 -> 6813USS
A8: Pole: | B8: 2 | C8: Frequency: | D8: 3 PH / 60 Hz | E8: Ins. Class: | F8: ='Performance Data Sheet'!M15 -> F
A9: HP: | B9: ='Performance Data Sheet'!C13 -> 4500 | C9: Rotor Inertia: | D9: 705.5 lb-ft² | E9: Date: | F9: ='Performance Data Sheet'!K44 -> 43151
A10: FLRPM: | B10: ='Performance Data Sheet'!M14 -> 3580 | C10: Load Inertia: | D10: 813.3 lb-ft² | E10: File: | F10: DT2M90U
B12: Locked Rotor Amps: | C12: ='Performance Data Sheet'!D22 & " A" -> 2826 A | D12: Load Type: | E12: Fan / Pump
B13: Locked Rotor Torque: | C13: ='Performance Data Sheet'!H23/100 -> 0.71 | D13: Starting at: | E13: FV (V)
B14: Breakdown Torque: | C14: 1.78 | D14: Accel. Time: | E14: 6.0 (s)
B15: Rated Torque: | C15: ='Performance Data Sheet'!H22 & " lb-ft" -> 6602 lb-ft
A39: Comments: | B39: PROJECT | C39: ='Performance Data Sheet'!C10 -> - | E39: D.E.Curve #: | F39: =F10 -> DT2M90U
C43: Prepared by: | D43: ='Performance Data Sheet'!K42 -> Zichao Xie | E43: Checked by:
D53: Load
A54: 100 | B54: 0 | C54: 0.14892544 | D54: 100
A55: 99.8 | B55: 89.930042 | C55: 125.78457 | D55: 99.599998
A56: 99 | B56: 178 | C56: 383.68643 | D56: 98
A57: 93.789474 | B57: 108.9935 | C57: 451.71124 | D57: 83.852631
A58: 88.578947 | B58: 90.013691 | C58: 469.89957 | D58: 70.30526
A59: 83.368421 | B59: 81.847084 | C59: 477.61765 | D59: 57.410526
A60: 72.947368 | B60: 76.937716 | C60: 485.79959 | D60: 38.010525
A61: 62.526315 | B61: 74.550921 | C61: 491.34 | D61: 24.778948
A62: 52.105263 | B62: 73.095198 | C62: 496.0416 | D62: 15.68421
A63: 41.68421 | B63: 72.181219 | C63: 500.07462 | D63: 9.0105257
A64: 31.263161 | B64: 71.621274 | C64: 503.50104 | D64: 6.2526321
A65: 20.842105 | B65: 71.289878 | C65: 506.40765 | D65: 7.8315787
... A67: 0 | B67: 71 | C67: 511.03076 | D67: 30

Sheet Thermdam
A2: TOSHIBA INTERNATIONAL CORPORATION
A3: Thermal Limit & Acceleration Curves
A4: Design Values (For Reference Only)
A6: Model #: | B6: ='Performance Data Sheet'!C17 -> QUOTE # 17548 | E6: FLAmps: | F6: ='Performance Data Sheet'!I14 -> 553
A7: Enclosure: | B7: ='Performance Data Sheet'!F14 -> WPII | C7: Voltage: | D7: ='Performance Data Sheet'!F13 & " V" -> 4000 V | E7: Frame: | F7: ='Performance Data Sheet'!C14 -> 6813USS
A8: Pole: | B8: 2 | C8: Frequency: | D8: 3 PH / 60 Hz | E8: Ins. Class: | F8: ='Performance Data Sheet'!M15 -> F
A9: HP: | B9: ='Performance Data Sheet'!C13 -> 4500 | C9: Rotor Inertia: | D9: 705.5 lb-ft² | E9: Date: | F9: ='Performance Data Sheet'!K44 -> 43151
A10: FLRPM: | B10: ='Performance Data Sheet'!M14 -> 3580 | C10: Load Inertia: | D10: 813.3 lb-ft² | E10: File: | F10: DT2M90U
C12: ='Performance Data Sheet'!D22 & " A" -> 2826 A
C13: ='Performance Data Sheet'!H23/100 -> 0.71
C15: ='Performance Data Sheet'!H22 & " lb-ft" -> 6602 lb-ft
A39: Comments: | B39: PROJECT | C39: ='Performance Data Sheet'!C10 -> - | E39: D.E.Curve #: | F39: =F10 -> DT2M90U
C43: Prepared by: | D43: ='Performance Data Sheet'!K42 -> Zichao Xie | E43: Checked by:
F50: =5252.1*B50/D53 -> #DIV/0!
D66: =D65/D64 -> #DIV/0!
A67: Current (%) | B67: Cold | C67: Hot | E67: CURRENT (%) | F67: Accel. Time
A68: 511.03074 | B68: 17.767126 | C68: 7.7517986 | E68: =A68 -> 511.03074 | F68: 0.0001
A69: =FLOOR(A68,100) -> 500 | B69: =((A68/A69)^2)*B68 -> 18.559711 | C69: =((A68/A69)^2)*C68 -> 8.0976038 | E69: 509.96383 | F69: 0.57499999
A70: =A69-100 -> 400 | B70: =((A68/A70)^2)*B68 -> 28.999549 | C70: =((A68/A70)^2)*C68 -> 12.652506 | E70: 507.64919 | F70: 1.0419999
A71: =A70-100 -> 300 | B71: =((A68/A71)^2)*B68 -> 51.554753 | C71: =((A68/A71)^2)*C68 -> 22.493344 | E71: 504.95479 | F71: 1.4769999
A72: =A71-100 -> 200 | B72: =((A68/A72)^2)*B68 -> 115.9982 | E72: 501.79024 | F72: 1.9129999
A73: =A72-100 -> 100 | B73: =((A68/A73)^2)*B68 -> 463.99278 | E73: 498.0651 | F73: 2.3769999
A74: 178 | B74: =((A68/A74)^2)*B68 -> 146.44388 | C74: =((A68/A74)^2)*C68 -> 63.893478 | E74: 493.68897 | F74: 2.8989999
A75: 180 | B75: =((A68/A75)^2)*B69 -> 149.59609 | C75: =((A68/A75)^2)*C68 -> 62.481511 | E75: 488.57143 | F75: 3.5309999
A76: 145 | B76: =((A68/A76)^2)*B68 -> 220.68622 | C76: =((A68/A76)^2)*C68 -> 96.28542 | E76: 481.69982 | F76: 4.414
A77: 125 | C77: =CEILING(C76*2,100) -> 200 | E77: 473.7613 | F77: 5.0479999
A78: 125 | C78: =2*C77 -> 400 | E78: 460.81374 | F78: 5.6729999
A79: 125 | C79: 10000 | E79: 417.70344 | F79: 5.9389997
E80: =A77 -> 125 | F80: 5.9589996

Sheet Performance
A2: TOSHIBA INTERNATIONAL CORPORATION
A3: Performance Curve
A4: Design Values (For Reference Only)
A6: Model #: | B6: ='Performance Data Sheet'!C17 -> QUOTE # 17548 | E6: FLAmps: | F6: ='Performance Data Sheet'!I14 -> 553
A7: Enclosure: | B7: ='Performance Data Sheet'!F14 -> WPII | C7: Voltage: | D7: ='Performance Data Sheet'!F13 & " V" -> 4000 V | E7: Frame: | F7: ='Performance Data Sheet'!C14 -> 6813USS
A8: Pole: | B8: 2 | C8: Frequency: | D8: 3 PH / 60 Hz | E8: Ins. Class: | F8: ='Performance Data Sheet'!M15 -> F
A9: HP: | B9: ='Performance Data Sheet'!C13 -> 4500 | C9: Rotor Inertia: | D9: 705.5 lb-ft² | E9: Date: | F9: ='Performance Data Sheet'!K44 -> 43151
A10: FLRPM: | B10: ='Performance Data Sheet'!M14 -> 3580 | C10: Load Inertia: | D10: 813.3 lb-ft² | E10: File: | F10: DT2M90U
B12: Locked Rotor Amps: | C12: ='Performance Data Sheet'!D22 & " A" -> 2826 A | D12: Load Type: | E12: Fan / Pump
B13: Locked Rotor Torque: | C13: ='Performance Data Sheet'!H23/100 -> 0.71 | D13: Starting at: | E13: FV (V)
B14: Breakdown Torque: | C14: 1.78 | D14: Accel. Time: | E14: 6.0 (s)
B15: Rated Torque: | C15: ='Performance Data Sheet'!H22 & " lb-ft" -> 6602 lb-ft
A39: Comments: | B39: PROJECT | C39: ='Performance Data Sheet'!C10 -> - | E39: D.E.Curve #: | F39: =F10 -> DT2M90U
C43: Prepared by: | D43: ='Performance Data Sheet'!K42 -> Zichao Xie | E43: Checked by:
A53: Load | B53: Efficiency | C53: PF | D53: Amps | E53: RPM | F53: Input Watts
A54: 0 | D54: 86.168842 | E54: 100 | F54: =45197/100000 -> 0.45197
A55: 25 | B55: 93.493469 | C55: 78.549225 | D55: 164.80139 | E55: =AVERAGE(E54,E56) -> 91.36264 | F55: 8.9683113 | L55: 98.058888
A56: 50 | B56: 95.685478 | C56: 88.688095 | D56: 285.23489 | E56: 82.72528 | F56: 17.52572
A57: 75 | B57: 96.201012 | C57: 90.671097 | D57: 416.25244 | E57: 67.110444 | F57: 26.147704
A58: 100 | B58: 96.264557 | C58: 90.871307 | D58: 553.41486 | E58: 50.479111 | F58: 34.84059
A59: 125 | B59: 96.145889 | C59: 90.346931 | D59: 696.64252 | E59: 34.384138 | F59: 43.604496

Sheet MagNoise
A1: Magnetic Noise Verification
A3: Rating: | B3: 2 Pole - 4500.0 HP - 3600 RPM - 4000 V - 60 Hz
A5: Electromagnetic Excitation Frequencies
B7: L = | C7: 0 | D7: L = | E7: + 1 | F7: L = | G7: - 1 | H7: Slip = | I7: 0 | J7: Slip = | K7: 0.007
A8: Mode A | B8: 6 | D8: 12 | F8: 0 | H8: 2880.0 Hz | J8: 2860.7 Hz
A9: Mode B | B9: 10 | D9: 16 | F9: 4 | H9: 2640.0 Hz | J9: 2620.7 Hz
A10: Mode C | B10: 8 | D10: 14 | F10: 2 | H10: 2760.0 Hz | J10: 2740.7 Hz
A12: Natural Frequencies of Stator Core
B14: Mode 0 = | D14: 1483.0 Hz | F14: Mode 6 = | H14: 4554.3 Hz
B15: Mode 2 = | D15: 354.0 Hz | F15: Mode 7 = | H15: 6268.4 Hz
B16: Mode 3 = | D16: 1001.2 Hz | F16: Mode 8 = | H16: 8246.6 Hz
B17: Mode 4 = | D17: 1919.7 Hz | F17: Mode 9 = | H17: 10488.8 Hz
B18: Mode 5 = | D18: 3104.5 Hz | F18: Mode 10 = | H18: 12995.0 Hz
A20: Analysis Results
B22: No matching frequencies detected.
