Workbook
Name Print_Area_MI: 'Circuit Param.'!$A$8:$N$43
Name Print_Area_MI: 'PERFORMANCE data'!$A$10:$N$18
Name Print_Area_MI: 'Performance Data Sheet'!$A$10:$N$42
Name thermal: #REF!
Name transfer: #REF!
Name unit_sht: "unit_sht"
Name vassvelo: #REF!
Name velcoity: #REF!
Name viscosity: #REF!
Name vollheatre: #REF!
Name volumetri: #REF!
Name weight: #REF!
Name weights: #REF!

Sheet DesignSheet
A1: TOSHIBA INTERNATIONAL CORPORATION | I1: Calc. Code: | J1: 2-2-2-0-1-2
A2: 3-PHASE SQUIRREL CAGE INDUCTION MOTOR DESIGN SHEET | J2: B.L.-1 P.F.-1
A3: File: | B3: G:\DESPRO\RATFILE\DT2M35U_Rev1.rat | G3: Date: | H3: 43636 | I3: Time: | J3: 0.32313657
A4: Pole | B4: HP | C4: RPM | D4: Form | E4: Voltage | F4: Frequency | G4: Temperature | H4: FLSpeed | I4: FLSlip | J4: Frame
A5: 2 | B5: 1750 | C5: 3600 | D5: DCNW | E5: 4000 | F5: 60 | G5: 105 | H5: 3579.3 / 3583.7 | I5: 0.0058 / 0.0045 | J5: 5811/12UDZ
A6: Core Data | D6: Winding Data | E6: USA Wire Std | H6: Constant Data
B7: Primary | C7: Secondary | F7: Bar | G7: End Ring | H7: St. Slot Pitch | I7: 24.543672 | J7: LR Test Data
A8: Air Gap | B8: 3.3 | H8: Rt. Slot Pitch | I8: 30.456888 | J8: ES
A9: Space Fac. | B9: 0.93000001 | D9: Pitch | E9: 1 ~ 16 | F9: Cross Section Area | H9: Mean Value | I9: 27.50028 | J9: 652.10032
A10: Core Length | B10: 600 | C10: 600 | F10: UB: 304.0 | G10: UER: 1750.0 | H10: Eff.T.W.St. | I10: 14.338923 | J10: WS
A11: OD | B11: 670 | C11: 368.4 | D11: Coil Pitch | E11: 0.6249375 | H11: Eff.T.W.Rt. | I11: 30.038757 | J11: 56045.594
A12: ID | B12: 375 | C12: 185 | D12: Slot Fill | E12: - | F12: EBL: 50.0 | G12: ERD1: 281.0 | H12: St.Carter Fac. | I12: 1.1789163 | J12: IS
A13: Core Depth | B13: 85 | C13: 55.29 | D13: Con./Slot | E13: 18 | G13: ERT: 70.00 | H13: Rt.Carter Fac. | I13: 1.0139197 | J13: 213.61055
A14: Eff.Core L. | B14: 465 | C14: 474.30002 | D14: Wire Size 1 | E14: (.102"x.204")x2 | G14: ERH: 25.00 | H14: Carter Factor | I14: 1.1953266 | J14: Volts / Turn
A15: Slot Data | D15: Wire Size 2 | E15: - | H15: Short. Factor | I15: 0.8314146 | J15: 32.075955
A16: Number | B16: 48 | C16: 38 | D16: // Circuits | E16: 2 | H16: Distrib. Factor | I16: 0.95543647 | J16: AC
A17: Kind | B17: Open | C17: Trapeze | D17: Connection | E17: Wye | H17: Wind. Factor | I17: 0.79436384 | J17: 783.29557
A18: Skew | B18: - | C18: 0 | D18: MCL | E18: 1295 | F18: 770 | H18: Reactance | I18: (Coeff.: 0.0267)
A19: Depth | B19: 62.5 | C19: 36.41 | D19: No.Cond./Ph. | E19: 144 | I19: Running | J19: Start
A20: Width | B20: 10.20 - 10.20 | D20: Res. (20°C) | E20: 0.061920837 | H20: Stator Slot | I20: 18.533136 | J20: 18.533136
A21: Opening | B21: 14.5 | C21: 3 | D21: (105°C) | E21: 0.082601667 | F21: 0.061929911 | G21: 0.00683646 | H21: Rotor Slot | I21: 16.804136 | J21: 14.805407
A22: Tip Depth | B22: 2.8299999 | C22: 3 | D22: Material | E22: CU | F22: CU | G22: CU | H22: Zigzag | I22: 4.1274877 | J22: 3.632827
A23: T.Min.Wid. | B23: 10.043672 | C23: 10.31661 | D23: Spec.Resist. | E23: 1.742 | F23: 1.742 | G23: 1.742 | H23: Coil End | I23: 20.842818 | J23: Skew R.: 0.00
A24: Low. R. | B24: 0 | C24: 0.80000001 | D24: Spec.Gravity | E24: 8.8900003 | F24: 8.8900003 | G24: 8.8900003 | H24: Belt Leakage | I24: 7.1922227 | J24: 6.3205372
A25: Up. R. | B25: - | C25: 4.7199998 | D25: Weight (kg) | H25: Total Resist. | I25: 0.15136804 | J25: 0.40942544
A26: Wedge Dep. | B26: 2.83 - 2.00 | C26: Magnetic | D26: Wire 1 | E26: 260.9149 | F26: 86.265719 | G26: 26.449351 | H26: Total React. | I26: 1.8040236 | J26: 1.7143475
A27: Duct | B27: 10 x 10 | C27: 9 x 10 | D27: Wire 2 | E27: - | F27: - | G27: - | H27: Impedance | I27: 1.8103628 | J27: 1.7625597
A28: Effective Depth (S=1) | D28: Magnetic Circuit Data | I28: Core Loss Data
B29: Res.= | C29: 33.371993 | E29: Length | F29: Section | G29: Density | H29: AT | I29: Volume | J29: Loss | M29: =RIGHT(F$41,SEARCH("/",F$41,1)-1) -> 3578.3 | N29: 125RPM
B30: Reac.= | C30: 33.399129 | D30: Primary Core | E30: 52.621633 | F30: 790.5 | G30: 19.174499 | H30: 1317.9308 | I30: 72640.237 | J30: 7398.678 | M30: =RIGHT(E$41,SEARCH("/",E$41,1)-1) -> 3583.7 | N30: 100RPM
A31: Excitation Data | D31: Tooth | E31: 6.25 | F31: 1120.8738 | G31: 13.52288 | H31: 37.096951 | I31: 14010.922 | J31: 810.5182 | M31: =RIGHT(D$41,SEARCH("/",D$41,1)-1) -> 3588.9 | N31: 75RPM
A32: Excit.Amps | B32: 57.724 / 49.318 | D32: Second.Core | E32: 23.214779 | F32: 816.96597 | G32: 18.553333 | H32: 510.66298 | I32: Total | J32: 8209.1962 | M32: =RIGHT(C$41,SEARCH("/",C$41,1)-1) -> 3594.1 | N32: 50RPM
A33: Core Loss | B33: 2.322 / 1.984 | C33: Flux / Pole | D33: Tooth | E33: 3.641 | F33: 929.70201 | G33: 16.303548 | H33: 47.029102 | I33: C.L.C. | J33: 1.75 / 0.96 | M33: =RIGHT(B$41,SEARCH("/",B$41,1)-1) -> 3599.2 | N33: 25RPM
A34: NoLoad | B34: 57.77 / 49.36 | C34: 15.157442 | D34: Air Gap | E34: 0.33 | F34: 2488.6028 | G34: 6.0907436 | H34: 1599.4651 | I34: S.F.C. | J34: 6.0500002
A35: Load Characteristics | D35: Temp. Rise @ 100%: | E35: 74 / 74 | G35: No Load Loss | H35: 24005.0 / 20181.1 | I35: W.Loss | J35: 14366.1 / 7910.1
A36: Load (%) | B36: 25 | C36: 50 | D36: 75 | E36: 100 | F36: 125 | G36: Primary Loss | H36: 11307.2 / 21402.1 | I36: S.Loss | J36: 1740.0 / 958.0
A37: Current (A) | B37: 80.26 / 81.37 | C37: 118.73 / 120.38 | D37: 164.50 / 166.77 | E37: 213.61 / 216.57 | F37: 265.05 / 268.72 | G37: Second. Loss | H37: 7729.0 / 8502.1 | I37: Total C.Loss | J37: 16106.1 / 8868.1
A38: Efficiency | B38: 0.928 / 0.913 | C38: 0.958 / 0.942 | D38: 0.966 / 0.951 | E38: 0.969 / 0.953 | F38: 0.969 / 0.953 | G38: Frict.& Wind. | H38: 7280.0 / 10170.0 | I38: Stray Loss | J38: 15155.334 | L38: =LEFT(E38,SEARCH("/",E38,1)-1) -> 0.969 | M38: =RIGHT(E38,SEARCH("/",E38,1)-1) -> 0.953 | N38: =M38/L38 -> 0.98348813 | O38: Eff.
A39: P.F. | B39: 0.633 / 0.634 | C39: 0.828 / 0.830 | D39: 0.889 / 0.891 | E39: 0.9103 / 0.9128 | F39: 0.917 / 0.919 | G39: Starting Data | I39: Slip | J39: PF | L39: =LEFT(E39,SEARCH("/",E39,1)-1) -> 0.9103 | M39: =RIGHT(E39,SEARCH("/",E39,1)-1) -> 0.9128 | N39: =M39/L39 -> 1.0027463 | O39: PF.
A40: Slip | B40: 0.0014 / 0.0002 | C40: 0.0029 / 0.0016 | D40: 0.0043 / 0.0031 | E40: 0.0058 / 0.0045 | F40: 0.0072 / 0.0060 | G40: LRA | H40: 1310.3 / 1247.8 | L40: =LEFT(E37,SEARCH("/",E37,1)-1) -> 213.61 | M40: =RIGHT(E37,SEARCH("/",E37,1)-1) -> 216.57 | N40: =M40/L40 -> 1.013857 | O40: Current
...

Sheet Data Sheet
A1: TOSHIBA INTERNATIONAL CORPORATION
A2: INDUCTION MOTOR DATA SHEET
A3: File: | B3: DT2M35U_Rev1 | I3: HRW / Model Number: | J3: M353WTQL11F-C
A4: Type: TIKE - Form: DCNW - 2 Pole - 1750 HP - 4000 V - 60 Hz - 5811/12UDZ - Class F | Q4: Motor Type Selection | T4: Electrical Steel Table
A5: Motor Parameters | F5: PERFORMANCE | J5: DESIGN | K5: TEST | Q5: EPACT | T5: M22 - 26Ga.
A6: Material | D6: M22 - 26Ga. | F6: NL & Impedance Test | Q6: EQP-III | T6: M36 - 26Ga.
A7: Air Gap | D7: 3.3 | F7: No load amps | J7: 49 | K7: - | Q7: Exp.Prf. | T7: NCB1 - 26Ga.
A8: Stack length | D8: 600 | F8: No load watts | J8: 20181 | K8: - | Q8: Exp.Prf.-EQPIII | T8: M43 - 26Ga.
A9: Number of turns per coil | D9: 9 | F9: Impedance amps | H9: 3 | I9: f | J9: 377 | K9: - | Q9: Prem. Eff. | T9: M45 - 26Ga.
A10: Wire 1 (size & number) | D10: (.102"x.204")x2 | F10: Impedance volts | H10: 3 | I10: f | J10: 1150 | K10: - | Q10: OWP | T10: M54 - 26Ga.
A11: Wire 2 (size & number) | D11: - | F11: Impedance watts | H11: 3 | I11: f | J11: 56046 | K11: - | Q11: Dry Kiln
A12: Slot fill - circle/square method (%) | D12: - | F12: Temperature Rise (°C)
A13: Connection | D13: 2 x Wye | G13: Winding | I13: 80/115 | J13: 74 / 98 | K13: -
A14: MCL | D14: 1295 | G14: Frame | J14: - | K14: - | R14: =SQRT(1750/1400)*(6600/4000)*9 -> 16.602805 | T14: =SQRT(1750/1400) -> 1.118034 | U14: =6600/4000 -> 1.65 | V14: =T14*U14 -> 1.8447561 | W14: =9*V14 -> 16.602805
A15: Allowance for ins. depth | D15: 9.4356003 | G15: Bearing PS/OS | J15: - | K15: - | W15: =0.5*W14 -> 8.3014024
A16: Allowance for ins. width | D16: 3.7368 | G16: End Ring | J16: - | K16: -
A17: Slot/Wire arrangement | D17: 18 x 2 | F17: Nameplate Data
A18: Effective cross section for coil | D18: - | H18: FLC (A) | J18: 217 | M18: =J18*6.5 -> 1410.5
A19: Coil grouping | D19: - | H19: RPM | J19: 3585
A20: Coil pitch (slot number) | D20: 1 ~ 16 | H20: CODE | J20: E
A21: Method of coil connection | D21: - | H21: S. F. | J21: 1.15 | Q21: Method of Connection
A22: Resistance per phase @ 20 °C | D22: 0.061900001 | H22: DESIGN | J22: - | Q22: Skip
A23: Coil Weight | B23: Wire1 | D23: 574 | H23: Nom.Eff. (%): | J23: - | Q23: Adjacent
A24: (lbs.) | B24: Wire2 | D24: - | H24: Min.Eff. (%): | J24: - | Q24: -
A25: Current Densities (A/cm2) | E25: Bar / ER | H25: P.F. (%): | J25: -
A26: FL / LR | D26: 413 / 2375 | E26: 583 / 613
A27: Stator Slot Shape (Reference) | F27: Performance
H28: LRC (A) | I28: - | J28: 1248 | K28: - | M28: =(J28/J18) -> 5.7511521 | N28: =1365/217 -> 6.2903226
H29: LRT (%) | I29: 60 | J29: 73 | K29: -
H30: BDT (%) | I30: 175 | J30: 243 | K30: -
H31: SLIP (%) | J31: 0.45 | K31: -
G32: IEEE-B | H32: Eff. (%) | J32: 95.3 | K32: -
A33: Rotor Slot Shape (Reference) | H33: PF (%) | J33: 91.3 | K33: -
F34: Losses (Watts) | H34: Primary | J34: 21402 | K34: -
H35: Secondary | J35: 8502 | K35: -
H36: Core | J36: 8868 | K36: -
H37: F & W | J37: 10170 | K37: -
H38: Stray | J38: 15155 | K38: -
A39: End Ring (Reference) | F39: Note | G39: TOP HAT, WPII, Cu Bar, Sleeve Brg.
G40: F&W Losses for A/F.: 5000 W
...

Sheet LoginSheet
J1: P | K1: T | L1: L | M1: T
B2: PROJECT HISTORY | J2: E | K2: D | L2: I | M2: Y | N2: H
J3: R | L3: M | M3: P
J4: F | L4: I | M4: E
K5: C | L5: T | N5: I
J6: D | K6: U | M6: T | N6: N
J7: A | K7: R | L7: R | M7: E | N7: S
I8: S | J8: T | K8: V | L8: E | M8: S | N8: U
B9: DATE | C9: PROJECT | D9: SMART NUMBER | E9: QTY | F9: CUSTOMER | G9: REMARKS | H9: LIMIT CODE | I9: F | J9: A | K9: E | L9: V | M9: T | N9: L
B53: REVISION HISTORY
B54: REV | C54: REMARKS | I54: DATE | L54: INIT

Sheet StallTime
A1: Rating: | B1: 2 Pole - 1750.0 HP - 3600 RPM - 4000 V - 60 Hz
A3: Starting Performance
D4: Load Type: Fan / Pump - 501.8 lb-ft²
A5: RPM | B5: Motor | C5: Load | D5: Accel. | E5: Line | F5: Stator | G5: Rotor
A6: Speed Increment | B6: Torque (%) | C6: Torque (%) | D6: Time (s) | E6: Amps | F6: kW / s | G6: kW / s
A7: 0~365 | B7: 70.1 | C7: 22.5 | D7: 0.701 | E7: 1245.7 | F7: 270.5 | G7: 704.8
A8: 365~729 | B8: 70.5 | C8: 11.4 | D8: 0.566 | E8: 1240.8 | F8: 216.7 | G8: 513.4
A9: 729~1094 | B9: 71.2 | C9: 7.0 | D9: 0.521 | E9: 1234.9 | F9: 197.8 | G9: 422.4
A10: 1094~1458 | B10: 72.4 | C10: 7.2 | D10: 0.513 | E10: 1228.3 | F10: 192.8 | G10: 367.6
A11: 1458~1823 | B11: 74.3 | C11: 11.4 | D11: 0.532 | E11: 1220.8 | F11: 197.9 | G11: 332.7
A12: 1823~2187 | B12: 77.1 | C12: 18.7 | D12: 0.571 | E12: 1212.5 | F12: 209.7 | G12: 305.5
A13: 2187~2552 | B13: 81.7 | C13: 28.7 | D13: 0.631 | E13: 1203.2 | F13: 228.1 | G13: 280.6
A14: 2552~2916 | B14: 90.1 | C14: 43.4 | D14: 0.716 | E14: 1190.3 | F14: 254.7 | G14: 253.1
A15: 2916~3099 | B15: 104.5 | C15: 58.0 | D15: 0.359 | E15: 1173.5 | F15: 124.5 | G15: 187.6
A16: 3099~3281 | B16: 132.7 | C16: 70.4 | D16: 0.268 | E16: 1142.4 | F16: 90.0 | G16: 121.4
... A19: 3573~3579 | B19: 110.9 | C19: 99.2 | D19: 0.052 | E19: 219.8 | F19: 0.6 | G19: 28.8
D21: Acceleration Time: 5.7 s
B22: Energy | D22: First Start | F22: Second Start
A23: Stator Winding Rise | B23: 2056 kW / s | D23: 20°C | F23: 41°C
A24: Rotor Bar Rise | B24: 3266 kW / s | D24: 98°C | F24: 197°C
A25: End Ring Rise | B25: 360 kW / s | D25: 35°C | F25: 71°C
A27: Locked Rotor Thermal Capability
E28: Cold Condition
B29: Rate of Rise | D29: Power | E29: Rise Limit | F29: Max Time
A30: Stator Copper | B30: 4.9°C / s | D30: 494.5 kW | E30: 160°C | F30: 32.5 s
A31: Rotor Bar | B31: 24.8°C / s | D31: 823.0 kW | E31: 260°C | F31: 10.5 s
A32: Rotor ER | B32: 8.9°C / s | D32: 90.9 kW | E32: 180°C | F32: 20.2 s
E34: Hot Condition
B35: Hot Temp. | D35: Rise Limit | E35: Ambient | F35: Total | G35: Max.Time
A36: Stator Copper | B36: 98°C + | D36: 62°C + | E36: 40°C | F36: = 200°C | G36: 12.6 s
A37: Rotor Bar | B37: 138°C + | D37: 122°C + | E37: 40°C | F37: = 300°C | G37: 4.9 s
A38: Rotor ER | B38: 138°C + | D38: 42°C + | E38: 40°C | F38: = 220°C | G38: 4.7 s
A40: Cold Stall Time: | B40: 13.3 s | D40: Hot Stall Time: | F40: 3.1 s

Sheet Performance Data Sheet
A1: TOSHIBA INTERNATIONAL CORPORATION | J1: INDEX | L1: MPCF-1033
A2: Industrial Division / Houston Motor Plant | J2: SHEET NO. | L2: 1 of 1
J3: ISSUED | L3: 7/31/13
J4: SUPERSEDES | L4: 11/8/96
J5: REVISION | L5: 2
A6: SQUIRREL CAGE INDUCTION MOTOR | J6: WRITTEN BY | L6: MDC
A7: PERFORMANCE SPECIFICATIONS | J7: APPROVED BY | L7: PAA
B9: CUSTOMER:
B10: TIC SR No.: | C10: 2135527.1
A12: MOTOR NAMEPLATE DATA
B13: H.P.: | C13: 1750 | E13: VOLTS: | F13: 4000 | H13: 3 PH / | I13: 60 Hz | L13: S. RPM: | M13: 3600
B14: FRAME: | C14: 5812USS | E14: ENCL: | F14: WP-II | H14: FLAMPS: | I14: 217 | L14: FLRPM: | M14: 3585
B15: FORM: | C15: DCW4 | E15: S.F.: | F15: 1.0 | H15: NEMA DESIGN: | I15: - | L15: INSUL CLASS: | M15: F
B16: TYPE: | C16: TIKE | E16: AMB.: | F16: 40°C | H16: CODE: | I16: E | L16: DUTY: | M16: Cont.
B17: MODEL No.: | C17: WT-10019401 | H17: kW: | I17: -
B18: NOM. EFF.: | C18: - | E18: MIN. EFF.: | F18: - | H18: P.F.: | I18: -
A21: AMPERAGE | E21: TORQUES | I21: **BEARINGS:
C22: LOCKED ROTOR: | D22: 1248 | G22: FULL LOAD (lb-ft.): | H22: 2564 | K22: DRIVE END: | L22: REFER TO NP
G23: LOCKED ROTOR (%): | H23: 70 | K23: OPPOSITE DRIVE END: | L23: REFER TO NP
G24: BREAK DOWN (%): | H24: 240
A28: EFFICIENCY | H28: POWER FACTOR
C29: FULL LOAD: | D29: 95.3 | J29: FULL LOAD: | K29: 91.3
C30: 3/4 LOAD: | D30: 95 | J30: 3/4 LOAD: | K30: 89.1
C31: 1/2 LOAD: | D31: 94.2 | J31: 1/2 LOAD: | K31: 83
A35: ALL CHARACTERISTICS ARE AVERAGE EXPECTED VALUES BASED UPON RATED VOLTAGE,
A36: FREQUENCY AND SINEWAVE POWER INPUT.
A37: THE DECLARED LOCKED ROTOR CURRENT HAS A TOLERANCE OF 20%.
A38: * TEMPERATURE RISE WILL BE CONSISTENT WITH INSULATION, AMBIENT AND SERVICE FACTOR AS
A39: DEFINED BY NEMA-MG-12 OR -20.
A40: ** BEARINGS ARE THE ONLY RECOMMENDED SPARE PART(S).
J42: CERTIFIED BY: | K42: Zichao Xie
J44: DATE: | K44: 43636
A59: - | B59: 6205ZZ | D59: 1 | E59: -
A60: TEFC | B60: 6206UU | D60: 1.15 | E60: A
A61: ODP | B61: 6207ZZ | E61: B
B62: 6208UU
B63: 6211ZZ
B64: 6211C3
B65: 6211ZZC3
B66: 6305UUC3
...

Sheet STCurve
A2: TOSHIBA INTERNATIONAL CORPORATION
A3: Speed Torque/Current Curve
A6: Model #: | B6: ='Performance Data Sheet'!C17 -> WT-10019401 | E6: FLAmps: | F6: ='Performance Data Sheet'!I14 -> 217
A7: Enclosure: | B7: ='Performance Data Sheet'!F14 -> WP-II | C7: Voltage: | D7: ='Performance Data Sheet'!F13 & " V" -> 4000 V | E7: Frame: | F7: ='Performance Data Sheet'!C14 -> 5812USS
A8: Pole: | B8: 2 | C8: Frequency: | D8: 3 PH / 60 Hz | E8: Ins. Class: | F8: ='Performance Data Sheet'!M15 -> F
A9: HP: | B9: ='Performance Data Sheet'!C13 -> 1750 | C9: Rotor Inertia: | D9: 222.9 lb-ft² | E9: Date: | F9: ='Performance Data Sheet'!K44 -> 43636
A10: FLRPM: | B10: ='Performance Data Sheet'!M14 -> 3585 | C10: Load Inertia: | D10: 501.8 lb-ft² | E10: File: | F10: DT2M35U
B12: Locked Rotor Amps: | C12: ='Performance Data Sheet'!D22 & " A" -> 1248 A | D12: Load Type: | E12: Fan / Pump
B13: Locked Rotor Torque: | C13: ='Performance Data Sheet'!H23/100 -> 0.7 | D13: Starting at: | E13: FV (V)
B14: Breakdown Torque: | C14: 2.4 | D14: Accel. Time: | E14: 5.7 (s)
B15: Rated Torque: | C15: ='Performance Data Sheet'!H22 & " lb-ft" -> 2564 lb-ft
A39: Comments: | B39: PROJECT | C39: ='Performance Data Sheet'!C10 -> 2135527.1 | E39: D.E.Curve #: | F39: =F10 -> DT2M35U
C43: Prepared by: | D43: ='Performance Data Sheet'!K42 -> Zichao Xie | E43: Checked by:
D53: Load
A54: 100 | B54: 0 | C54: 0.26622248 | D54: 100
A55: 99.24 | B55: 121.79018 | C55: 144.80722 | D55: 98.480003
A56: 96.2 | B56: 240 | C56: 438.42398 | D56: 90.300003
A57: 91.136842 | B57: 152.18032 | C57: 516.21027 | D57: 76.955788
A58: 86.073683 | B58: 113.29606 | C58: 536.67682 | D58: 63.791576
A59: 81.010526 | B59: 95.624668 | C59: 544.85547 | D59: 52.22316
A60: 70.88421 | B60: 84.528217 | C60: 552.18231 | D60: 34.503159
A61: 60.757893 | B61: 78.903267 | C61: 556.75134 | D61: 22.833683
A62: 50.63158 | B62: 75.385045 | C62: 560.74725 | D62: 14.505264
A63: 40.50526 | B63: 73.116037 | C63: 564.39001 | D63: 8.3031559
A64: 30.37895 | B64: 71.682821 | C64: 567.6499 | D64: 6.0757899
A65: 20.252633 | B65: 70.806192 | C65: 570.52106 | D65: 7.9494734
... A67: 0 | B67: 70 | C67: 575.11517 | D67: 30

Sheet Thermdam
A2: TOSHIBA INTERNATIONAL CORPORATION
A3: Thermal Limit & Acceleration Curves
A4: Design Values (For Reference Only)
A6: Model #: | B6: ='Performance Data Sheet'!C17 -> WT-10019401 | E6: FLAmps: | F6: ='Performance Data Sheet'!I14 -> 217
A7: Enclosure: | B7: ='Performance Data Sheet'!F14 -> WP-II | C7: Voltage: | D7: ='Performance Data Sheet'!F13 & " V" -> 4000 V | E7: Frame: | F7: ='Performance Data Sheet'!C14 -> 5812USS
A8: Pole: | B8: 2 | C8: Frequency: | D8: 3 PH / 60 Hz | E8: Ins. Class: | F8: ='Performance Data Sheet'!M15 -> F
A9: HP: | B9: ='Performance Data Sheet'!C13 -> 1750 | C9: Rotor Inertia: | D9: 222.9 lb-ft² | E9: Date: | F9: ='Performance Data Sheet'!K44 -> 43636
A10: FLRPM: | B10: ='Performance Data Sheet'!M14 -> 3585 | C10: Load Inertia: | D10: 501.8 lb-ft² | E10: File: | F10: DT2M35U
C12: ='Performance Data Sheet'!D22 & " A" -> 1248 A
C13: ='Performance Data Sheet'!H23/100 -> 0.7
C15: ='Performance Data Sheet'!H22 & " lb-ft" -> 2564 lb-ft
A39: Comments: | B39: PROJECT | C39: ='Performance Data Sheet'!C10 -> 2135527.1 | E39: D.E.Curve #: | F39: =F10 -> DT2M35U
C43: Prepared by: | D43: ='Performance Data Sheet'!K42 -> Zichao Xie | E43: Checked by:
F50: =5252.1*B50/D53 -> #DIV/0!
D66: =D65/D64 -> #DIV/0!
A67: Current (%) | B67: Cold | C67: Hot | E67: CURRENT (%) | F67: Accel. Time
A68: 575.11521 | B68: 24 | C68: 12 | E68: =A68 -> 575.11521 | F68: 0.0001
A69: =A68-50 -> 525.11521 | B69: =((A68/A69)^2)*B68 -> 28.788017 | C69: =((A68/A69)^2)*C68 -> 14.394009 | E69: 574.0553 | F69: 0.70099998
A70: =A69-50 -> 475.11521 | B70: =((A68/A70)^2)*B68 -> 35.166009 | C70: =((A68/A70)^2)*C68 -> 17.583004 | E70: 571.79724 | F70: 1.267
A71: =A70-50 -> 425.11521 | B71: =((A68/A71)^2)*B68 -> 43.924585 | C71: =((A68/A71)^2)*C68 -> 21.962292 | E71: 569.07834 | F71: 1.788
A72: =A71-50 -> 375.11521 | B72: =((A68/A72)^2)*B68 -> 56.414612 | E72: 566.03687 | F72: 2.3009999
A73: =A72-100 -> 275.11521 | B73: =((A68/A73)^2)*B68 -> 104.87978 | E73: 562.58065 | F73: 2.8329999
A74: 240 | B74: =((A68/A74)^2)*B68 -> 137.81563 | C74: =((A68/A74)^2)*C68 -> 68.907813 | E74: 558.75576 | F74: 3.404
A75: 180 | B75: =((A68/A75)^2)*B69 -> 293.88434 | C75: =((A68/A75)^2)*C68 -> 122.50278 | E75: 554.47005 | F75: 4.0349998
A76: 145 | B76: =((A68/A76)^2)*B68 -> 377.5591 | C76: =((A68/A76)^2)*C68 -> 188.77955 | E76: 548.52535 | F76: 4.7509999
A77: 125 | C77: =CEILING(C76*2,100) -> 400 | E77: 540.78341 | F77: 5.1100001
A78: 125 | C78: =2*C77 -> 800 | E78: 526.45161 | F78: 5.3780003
A79: 125 | C79: 10000 | E79: 477.32719 | F79: 5.5270004
E80: =A74 -> 240 | F80: 5.6430006
E81: =A77 -> 125 | F81: 5.6950006

Sheet Performance
A2: TOSHIBA INTERNATIONAL CORPORATION
A3: Performance Curve
A4: Design Values (For Reference Only)
A6: Model #: | B6: ='Performance Data Sheet'!C17 -> WT-10019401 | E6: FLAmps: | F6: ='Performance Data Sheet'!I14 -> 217
A7: Enclosure: | B7: ='Performance Data Sheet'!F14 -> WP-II | C7: Voltage: | D7: ='Performance Data Sheet'!F13 & " V" -> 4000 V | E7: Frame: | F7: ='Performance Data Sheet'!C14 -> 5812USS
A8: Pole: | B8: 2 | C8: Frequency: | D8: 3 PH / 60 Hz | E8: Ins. Class: | F8: ='Performance Data Sheet'!M15 -> F
A9: HP: | B9: ='Performance Data Sheet'!C13 -> 1750 | C9: Rotor Inertia: | D9: 222.9 lb-ft² | E9: Date: | F9: ='Performance Data Sheet'!K44 -> 43636
A10: FLRPM: | B10: ='Performance Data Sheet'!M14 -> 3585 | C10: Load Inertia: | D10: 501.8 lb-ft² | E10: File: | F10: DT2M35U
B12: Locked Rotor Amps: | C12: ='Performance Data Sheet'!D22 & " A" -> 1248 A | D12: Load Type: | E12: Fan / Pump
B13: Locked Rotor Torque: | C13: ='Performance Data Sheet'!H23/100 -> 0.7 | D13: Starting at: | E13: FV (V)
B14: Breakdown Torque: | C14: 2.4 | D14: Accel. Time: | E14: 5.7 (s)
B15: Rated Torque: | C15: ='Performance Data Sheet'!H22 & " lb-ft" -> 2564 lb-ft
N36: SPEED | O36: KW
N37: =L43 - (L43-L44) / 10 * 0 -> 3600 | O37: =L45 / 10 * 10 -> 4000
N38: =L43 - (L43-L44) / 10 * 1 -> 3597 | O38: =L45 / 10 * 9 -> 3600
A39: Comments: | B39: PROJECT | C39: ='Performance Data Sheet'!C10 -> 2135527.1 | E39: D.E.Curve #: | F39: =F10 -> DT2M35U | N39: =L43 - (L43-L44) / 10 * 2 -> 3594 | O39: =L45 / 10 * 8 -> 3200
N40: =L43 - (L43-L44) / 10 * 3 -> 3591 | O40: =L45 / 10 * 7 -> 2800
N41: =L43 - (L43-L44) / 10 * 4 -> 3588 | O41: =L45 / 10 * 6 -> 2400
N42: =L43 - (L43-L44) / 10 * 5 -> 3585 | O42: =L45 / 10 * 5 -> 2000
C43: Prepared by: | D43: ='Performance Data Sheet'!K42 -> Zichao Xie | E43: Checked by: | K43: SYNC SPEED | L43: 3600 | N43: =L43 - (L43-L44) / 10 * 6 -> 3582 | O43: =L45 / 10 * 4 -> 1600
K44: NEW SPEED LOWER RANGE | L44: 3570 | N44: =L43 - (L43-L44) / 10 * 7 -> 3579 | O44: =L45 / 10 * 3 -> 1200
K45: NEW kW UPPER RANGE | L45: 4000 | N45: =L43 - (L43-L44) / 10 * 8 -> 3576 | O45: =L45 / 10 * 2 -> 800
N46: =L43 - (L43-L44) / 10 * 9 -> 3573 | O46: =L45 / 10 * 1 -> 400
N47: =L43 - (L43-L44) / 10 * 10 -> 3570 | O47: =L45 / 10 * 0 -> 0
A52: ADJUSTED
A53: Load | B53: Efficiency | C53: PF | D53: Amps | E53: RPM | F53: Input Watts
A54: 0 | D54: 49 | E54: 100 | F54: =20181/(L45*1000) * 100 -> 0.504525
A55: 25 | B55: 91.299995 | C55: 63.400002 | D55: 81.370003 | E55: =(1.00313303586994*B10-L44)/(L43-L44)*100 -> 87.439779 | F55: =357416.2/(L45*1000)*100 -> 8.935405
A56: 50 | B56: 94.199997 | C56: 83 | D56: 120.38 | E56: =(1.00210212909693*B10-L44)/(L43-L44)*100 -> 75.120443 | F56: =692234.2/(L45*1000)*100 -> 17.305855
A57: 75 | B57: 95.099998 | C57: 89.099998 | D57: 166.77 | E57: =(1.00105106454847*B10-L44)/(L43-L44)*100 -> 62.560221 | F57: =1029476/(L45*1000)*100 -> 25.7369
A58: 100 | B58: 95.300003 | C58: 91.279999 | D58: 216.57001 | E58: =(1*B10-L44)/(L43-L44)*100 -> 50 | F58: =1369603/(L45*1000)*100 -> 34.240075
A59: 125 | B59: 95.300003 | C59: 91.900002 | D59: 268.72 | E59: =(0.998908483699442*B10-L44)/(L43-L44)*100 -> 36.95638 | F59: =1710945/(L45*1000)*100 -> 42.773625
A62: ORIGINAL
A63: Load | B63: Efficiency | C63: PF | D63: Amps | E63: RPM | F63: Input Watts
A64: 0 | D64: 58.573286 | E64: 100 | F64: 24.40441
A65: 25 | B65: 91.256126 | C65: 63.424694 | D65: 81.376549 | E65: 97.736179 | F65: 8.9393414
A66: 50 | B66: 94.222824 | C66: 83.047455 | D66: 120.38358 | E66: 84.963588 | F66: 17.315756
A67: 75 | B67: 95.047791 | C67: 89.134956 | D67: 166.78265 | E67: 71.971716 | F67: 25.748197
A68: 100 | B68: 95.299606 | C68: 91.278976 | D68: 216.57974 | E68: 58.867057 | F68: 34.240216
A69: 125 | B69: 95.315567 | C69: 91.93895 | D69: 268.7363 | E69: 45.543731 | F69: 42.793101

Sheet Circuit Param.
A1: TOSHIBA INTERNATIONAL CORPORATION | J1: INDEX | L1: MPCF-1109
A2: Industrial Division / Houston Motor Plant | J2: SHEET NO. | L2: 1 of 1
J3: ISSUED | L3: 38309
A4: EQUIVALENT CIRCUIT DATA | J4: SUPERSEDES | L4: NEW
J5: REVISION | L5: REV. 0
J6: WRITTEN BY | L6: MDC
A7: All Values are Presented in Ohms/Phase, Equivalent Wye Connection. | J7: APPROVED BY | L7: Paul Anderson
B9: CUSTOMER: | C9: FLOWSERVE FSG CORPORATION
B10: TIC SR No.: | C10: 2135527.1
A12: MOTOR NAMEPLATE DATA
B13: H.P.: | C13: 1750 | E13: VOLTS: | F13: 4000 | H13: 3 PH / | I13: 60 Hz | L13: S. RPM: | M13: 3600
B14: FRAME: | C14: 5812USS | E14: ENCL: | F14: WP-II | H14: FLAMPS: | I14: 217 | L14: FLRPM: | M14: 3585
B15: FORM: | C15: DCNW | E15: S.F.: | F15: 1.0 | H15: NEMA DESIGN: | I15: - | L15: INSUL CLASS: | M15: F
B16: TYPE: | C16: TIKE | E16: AMB.: | F16: 40°C | H16: CODE: | I16: E | L16: DUTY: | M16: Cont.
B17: MODEL No.: | C17: WT-10019401 | H17: kW: | I17: -
B18: NOM. EFF.: | C18: - | E18: MIN. EFF.: | F18: - | H18: P.F.: | I18: -
A21: Primary Resistance (R1) : | F21: 0.342743
A22: Secondary Resistance (R2) : | F22: 0.229565
A23: Starting Resistance (R3) : | F23: 0.776549
A25: Primary Reactance (X1) : | F25: 2.871958
A26: Secondary Reactance (X2) : | F26: 2.451798
A27: Starting Reactance (X3) : | F27: 1.8443691
A29: Magnetizing Reactance (Xm) : | F29: 127.169663
A31: Transient Reactance : | F31: 5.27738
A32: Sub Transient Reactance : | F32: 3.91567
A33: Short Circuit Time Constant : | F33: 2.46335
A34: Sub Transient Time Constant : | F34: 0.01077
A35: Open Circuit Time Constant : | F35: 1.49776
I40: CERTIFIED BY: | J40: JERRY R
I42: DATE: | J42: 43747

Sheet PERFORMANCE data
A1: TOSHIBA INTERNATIONAL CORPORATION | J1: INDEX | L1: MPCF-1082
A2: Industrial Division / Houston Motor Plant | J2: SHEET NO. | L2: 1 of 1
J3: ISSUED | L3: 2/14/02
J4: SUPERSEDES | L4: NEW
J5: REVISION | L5: 0
A6: SQUIRREL CAGE INDUCTION MOTOR | J6: WRITTEN BY | L6: M. CAMPBELL
A7: API 541 PERFORMANCE SPECIFICATIONS | J7: APPROVED BY | L7: P.A.A
B9: CUSTOMER: | C9: FLOWSERVE FSG CORPORATION
B10: TIC SR No.: | C10: 2135527.1
A12: MOTOR NAMEPLATE DATA
B13: H.P.: | C13: 1750 | E13: VOLTS: | F13: 4000 | H13: 3 PH / | I13: 60 Hz | L13: S. RPM: | M13: 3600
B14: FRAME: | C14: 5812USS | E14: ENCL: | F14: WP-II | H14: FLAMPS: | I14: 217 | L14: FLRPM: | M14: 3585
B15: FORM: | C15: DCNW | E15: S.F.: | F15: 1.0 | H15: NEMA DESIGN: | I15: - | L15: INSUL CLASS: | M15: F
B16: TYPE: | C16: TIKE | E16: AMB.: | F16: 40°C | H16: CODE: | I16: E | L16: DUTY: | M16: Cont.
B17: MODEL No.: | C17: WT-10019401 | H17: kW: | I17: -
B18: NOM. EFF.: | C18: - | E18: MIN. EFF.: | F18: - | H18: P.F.: | I18: -
A20: LOCKED ROTOR DATA
D21: AMPS AT RATED VOLTAGE: | E21: 1248 | I21: POWER FACTOR: | J21: 21.3
D22: AMPS AT 80% VOLTAGE: | E22: 998
A24: TORQUE VALUES | H24: CURVE NUMBERS
E25: FULL LOAD (LB.FT): | F25: 2564 | J25: SPEED-TORQUE CURVE: | K25: DT2M35U
E26: LOCKED ROTOR TORQUE (% OF FLT): | F26: 70 | J26: SPEED-CURRENT CURVE: | K26: DT2M35U
E27: PULL UP TORQUE (% OF FLT): | F27: 70 | J27: ACCELERATION CURVE: | K27: DT2M35U
E28: BREAKDOWN TORQUE (% OF FLT): | F28: 240
A30: LOCKED ROTOR WITHSTAND TIMES
A31: COLD CONDITION | H31: HOT CONDITION
C32: 100% VOLTAGE: | D32: 24 | J32: 100% VOLTAGE: | K32: 12
C33: 90% VOLTAGE: | D33: 29 | J33: 90% VOLTAGE: | K33: 15
C34: 80% VOLTAGE: | D34: 38 | J34: 80% VOLTAGE: | K34: 19
C35: 70% VOLTAGE: | D35: 49 | J35: 70% VOLTAGE: | K35: 24
A37: DESIGN DATA
C38: MOTOR ROTOR wk2 (LB.FT2): | D38: 222.9 | J38: NO LOAD CURRENT: | K38: 49
C39: AIR GAP: | D39: 3.3 | J39: ACCELERATION TIME:
D40: LOAD CHARACTERISTICS
D41: LOAD | G41: 1/2 | H41: 3/4 | I41: FULL | J41: SF
D42: AMPS (A) | G42: 120 | H42: 167 | I42: 217 | J42: -
D43: EFFICIENCY (%) | G43: 94.2 | H43: 95.1 | I43: 95.3 | J43: -
D44: POWER FACTOR (%) | G44: 83 | H44: 89.1 | I44: 91.2 | J44: -
D45: GUARENTEED EFFICIENCY (%) | G45: - | H45: - | I45: - | J45: -
A46: EFFICIENCY TO BE DETERMINED BY IEEE 112, METHOD B
...
