Workbook
Name Print_Area_MI: 'Circuit Param'!$A$8:$N$43
Name Print_Area_MI: 'Performance API'!$A$10:$N$18
Name Print_Area_MI: 'Performance Data Sheet 2000HP'!$A$10:$N$42
Name thermal: #REF!
Name transfer: #REF!
Name unit_sht: "unit_sht"
Name vassvelo: #REF!
Name velcoity: #REF!
Name viscosity: #REF!
Name vollheatre: #REF!
Name volumetri: #REF!
Name weight: #REF!
Name weights: #REF!

Sheet DesignSheet
A1: TOSHIBA INTERNATIONAL CORPORATION | I1: Calc. Code: | J1: 2-2-2-0-1-2
A2: 3-PHASE SQUIRREL CAGE INDUCTION MOTOR DESIGN SHEET | J2: B.L.-1 P.F.-1
A3: File: | B3: G:\DESPRO\BASE MV DESIGNS\6800 FRAME\Electrical Design\2P\SERIES\DT2M40UEXP_ERchange.rat | G3: Date: | H3: 43872 | I3: Time: | J3: 0.66429398
A4: Pole | B4: HP | C4: RPM | D4: Form | E4: Voltage | F4: Frequency | G4: Temperature | H4: FLSpeed | I4: FLSlip | J4: Frame
A5: 2 | B5: 2000 | C5: 3600 | D5: DCNW | E5: 4000 | F5: 60 | G5: 105 | H5: 3574.7 / 3582.0 | I5: 0.0070 / 0.0050 | J5: 5811/12UDZ
A6: Core Data | D6: Winding Data | H6: Constant Data
B7: Primary | C7: Secondary | F7: Bar | G7: End Ring | H7: St. Slot Pitch | I7: 24.543672 | J7: LR Test Data
A8: Air Gap | B8: 3.3 | H8: Rt. Slot Pitch | I8: 30.456888 | J8: ES
A9: Space Fac. | B9: 0.93000001 | D9: Pitch | E9: 1 ~ 17 | F9: Cross Section Area | H9: Mean Value | I9: 27.50028 | J9: 689.32754
A10: Core Length | B10: 630 | C10: 630 | F10: UB: 304.0 | G10: UER: 1848.0 | H10: Eff.T.W.St. | I10: 14.338923 | J10: WS
A11: OD | B11: 670 | C11: 368.4 | D11: Coil Pitch | E11: 0.6666 | H11: Eff.T.W.Rt. | I11: 30.038757 | J11: 64148.413
A12: ID | B12: 375 | C12: 185 | D12: Slot Fill | E12: - | F12: EBL: 45.0 | G12: ERD1: 284.0 | H12: St.Carter Fac. | I12: 1.1789163 | J12: IS
A13: Core Depth | B13: 85 | C13: 55.29 | D13: Con./Slot | E13: 16 | G13: ERT: 44.00 | H13: Rt.Carter Fac. | I13: 1.0139197 | J13: 242.89896
A14: Eff.Core L. | B14: 507.78 | C14: 513.35999 | D14: Wire Size 1 | E14: (.114"x.204")x2 | G14: ERH: 42.00 | H14: Carter Factor | I14: 1.1953266 | J14: Volts / Turn
A15: Slot Data | D15: Wire Size 2 | E15: - | H15: Short. Factor | I15: 0.8659726 | J15: 36.085449
A16: Number | B16: 48 | C16: 38 | D16: // Circuits | E16: 2 | H16: Distrib. Factor | I16: 0.95543647 | J16: AC
A17: Kind | B17: Open | C17: Trapeze | D17: Connection | E17: Wye | H17: Wind. Factor | I17: 0.8273818 | J17: 791.72817
A18: Skew | B18: - | C18: 0 | D18: MCL | E18: 1360 | F18: 764 | H18: Reactance | I18: (Coeff.: 0.0252)
A19: Depth | B19: 62.5 | C19: 36.41 | D19: No.Cond./Ph. | E19: 128 | I19: Running | J19: Start
A20: Width | B20: 10.20 - 10.20 | D20: Res. (20°C) | E20: 0.052448755 | H20: Stator Slot | I20: 18.533136 | J20: 18.533136
A21: Opening | B21: 14.5 | C21: 3 | D21: (105°C) | E21: 0.069966021 | F21: 0.052670937 | G21: 0.02030813 | H21: Rotor Slot | I21: 16.804136 | J21: 14.805407
A22: Tip Depth | B22: 2.8299999 | C22: 3 | D22: Material | E22: CU | F22: CU | G22: CU | H22: Zigzag | I22: 4.1274877 | J22: 3.6161513
A23: T.Min.Wid. | B23: 10.043672 | C23: 10.31661 | D23: Spec.Resist. | E23: 1.742 | F23: 1.742 | G23: 1.742 | H23: Coil End | I23: 20.264389 | J23: Skew R.: 0.00
A24: Low. R. | B24: 0 | C24: 0.80000001 | D24: Spec.Gravity | E24: 8.8900003 | F24: 8.8900003 | G24: 8.8900003 | H24: Belt Leakage | I24: 7.1922227 | J24: 6.2915985
A25: Up. R. | B25: - | C25: 4.7199998 | D25: Weight (kg) | H25: Total Resist. | I25: 0.1429451 | J25: 0.36242101
A26: Wedge Dep. | B26: 2.83 - 2.00 | C26: Magnetic | D26: Wire 1 | E26: 268.43167 | F26: 82.979405 | G26: 33.959864 | H26: Total React. | I26: 1.6834958 | J26: 1.5979371
A27: Duct | B27: 14 x 6 | C27: 13 x 6 | D27: Wire 2 | E27: - | F27: - | G27: - | H27: Impedance | I27: 1.6895536 | J27: 1.6385213
A28: Effective Depth (S=1) | D28: Magnetic Circuit Data | I28: Core Loss Data
B29: Res.= | C29: 33.371993 | E29: Length | F29: Section | G29: Density | H29: AT | I29: Volume | J29: Loss | M29: =RIGHT(F$41,SEARCH("/",F$41,1)-1) -> 3575.5 | N29: 125RPM
B30: Reac.= | C30: 33.399129 | D30: Primary Core | E30: 52.621633 | F30: 863.226 | G30: 18.965636 | H30: 1262.6244 | I30: 79323.138 | J30: 7937.268 | M30: =RIGHT(E$41,SEARCH("/",E$41,1)-1) -> 3582.0 | N30: 100RPM
A31: Excitation Data | D31: Tooth | E31: 6.25 | F31: 1223.9941 | G31: 13.375579 | H31: 35.60322 | I31: 15299.927 | J31: 869.52023 | M31: =RIGHT(D$41,SEARCH("/",D$41,1)-1) -> 3588.4 | N31: 75RPM
A32: Excit.Amps | B32: 61.074 / 54.550 | D32: Second.Core | E32: 23.214779 | F32: 884.24546 | G32: 18.514803 | H32: 506.45274 | I32: Total | J32: 8806.7882 | M32: =RIGHT(C$41,SEARCH("/",C$41,1)-1) -> 3594.8 | N32: 50RPM
A33: Core Loss | B33: 2.492 / 2.226 | C33: Flux / Pole | D33: Tooth | E33: 3.641 | F33: 1006.2656 | G33: 16.26969 | H33: 46.616904 | I33: C.L.C. | J33: 1.75 / 1.04 | M33: =RIGHT(B$41,SEARCH("/",B$41,1)-1) -> 3601.0 | N33: 25RPM
A34: NoLoad | B34: 61.12 / 54.60 | C34: 16.37163 | D34: Air Gap | E34: 0.33 | F34: 2705.4316 | G34: 6.0513932 | H34: 1589.1314 | I34: S.F.C. | J34: 6.0500002
A35: Load Characteristics | D35: Temp. Rise @ 100%: | E35: 65 / 65 | G35: No Load Loss | H35: 25150.7 / 17700.0 | I35: W.Loss | J35: 15411.9 / 9180.4
A36: Load (%) | B36: 25 | C36: 50 | D36: 75 | E36: 100 | F36: 125 | G36: Primary Loss | H36: 12384.0 / 11262.0 | I36: S.Loss | J36: 1871.9 / 1115.1
A37: Current (A) | B37: 87.59 / 88.31 | C37: 132.95 / 134.04 | D37: 186.09 / 187.62 | E37: 242.90 / 244.89 | F37: 302.47 / 304.95 | G37: Second. Loss | H37: 10790.0 / 8317.0 | I37: Total C.Loss | J37: 17283.8 / 10295.5
A38: Efficiency | B38: 0.933 / 0.929 | C38: 0.961 / 0.956 | D38: 0.968 / 0.963 | E38: 0.970 / 0.965 | F38: 0.969 / 0.965 | G38: Frict.& Wind. | H38: 7280.0 / 6042.0 | I38: Stray Loss | J38: 17904 | L38: =LEFT(E38,SEARCH("/",E38,1)-1) -> 0.970 | M38: =RIGHT(E38,SEARCH("/",E38,1)-1) -> 0.965 | N38: =M38/L38 -> 0.99484536 | O38: Eff.
A39: P.F. | B39: 0.659 / 0.656 | C39: 0.843 / 0.840 | D39: 0.897 / 0.894 | E39: 0.914 / 0.911 | F39: 0.918 / 0.915 | G39: Starting Data | I39: Slip | J39: PF | L39: =LEFT(E39,SEARCH("/",E39,1)-1) -> 0.914 | M39: =RIGHT(E39,SEARCH("/",E39,1)-1) -> 0.911 | N39: =M39/L39 -> 0.99671772 | O39: PF.
A40: Slip | B40: 0.0018 / -0.0003 | C40: 0.0035 / 0.0015 | D40: 0.0052 / 0.0032 | E40: 0.0070 / 0.0050 | F40: 0.0088 / 0.0068 | G40: LRA | H40: 1409.5 / 1548.5 | L40: =LEFT(E37,SEARCH("/",E37,1)-1) -> 242.90 | M40: =RIGHT(E37,SEARCH("/",E37,1)-1) -> 244.89 | N40: =M40/L40 -> 1.0081927 | O40: Current
...

Sheet Data Sheet
A1: TOSHIBA INTERNATIONAL CORPORATION
A2: INDUCTION MOTOR DATA SHEET | L2: M401WTAL11E-CH
A3: File: | B3: DT2M40UEXP_ERchange | I3: HRW / Model Number: | L3: M403WTAL11E-CH
A4: Type: TIKE - Form: DCNW - 2 Pole - 2000 HP - 2300/4000 V - 60 Hz - 5811/12UDZ - Class F | Q4: Motor Type Selection | T4: Electrical Steel Table
A5: Motor Parameters | F5: PERFORMANCE | J5: DESIGN | K5: TEST | Q5: EPACT | T5: M22 - 26Ga.
A6: Material | D6: M22 - 26Ga. | F6: NL & Impedance Test 4000V 2300V | Q6: EQP-III | T6: M36 - 26Ga.
A7: Air Gap | D7: 3.3 | F7: No load amps | J7: 55 | K7: 95 | M7: 97 | Q7: Exp.Prf. | T7: NCB1 - 26Ga.
A8: Stack length | D8: 630 | F8: No load watts | J8: 17700 | K8: 17700 | M8: 19100 | Q8: Exp.Prf.-EQPIII | T8: M43 - 26Ga.
A9: Number of turns per coil | D9: 8 | F9: Impedance amps | H9: 3 | I9: f | J9: 405 | K9: 423 | M9: 445 | Q9: Prem. Eff. | T9: M45 - 26Ga.
A10: Wire 1 (size & number) | D10: (.114"x.204")x2 | F10: Impedance volts | H10: 3 | I10: f | J10: 1150 | K10: 460 | Q10: Standard Eff. | T10: M54 - 26Ga.
A11: Wire 2 (size & number) | D11: - | F11: Impedance watts | H11: 3 | I11: f | J11: 64148 | K11: 64148 | M11: 57903 | Q11: OWP | T11: TIPA Lam
A12: Slot fill - circle/square method (%) | D12: - | F12: Temperature Rise (°C) | Q12: Dry Kiln
A13: Connection | D13: 2 Delta / 2 x Wye | G13: Winding | I13: 80/115 | J13: 64.6 / 86 | K13: -
A14: MCL | D14: 1360 | G14: Frame | J14: - | K14: -
A15: Allowance for ins. depth | D15: 10.1404 | G15: Bearing PS/OS | J15: - | K15: -
A16: Allowance for ins. width | D16: 3.7368 | G16: End Ring | J16: - | K16: -
A17: Slot/Wire arrangement | D17: 16 x 2 | F17: Nameplate Data
A18: Effective cross section for coil | D18: - | H18: FLC (A) | J18: 424 / 245 | M18: =J18*6.5 -> #VALUE!
A19: Coil grouping | D19: - | H19: RPM | J19: 3582
A20: Coil pitch (slot number) | D20: 1 ~ 17 | H20: CODE | J20: F
A21: Method of coil connection | D21: - | H21: S. F. | J21: 1.15 | Q21: Method of Connection
A22: Resistance per phase @ 20 °C | D22: 0.0519 | H22: DESIGN | J22: - | Q22: Skip
A23: Coil Weight | B23: Wire1 | D23: 615.4 | H23: Nom.Eff. (%): | J23: - | Q23: Adjacent
A24: (lbs.) | B24: Wire2 | D24: - | H24: Min.Eff. (%): | J24: - | Q24: -
A25: Current Densities (A/cm2) | E25: Bar / ER | H25: P.F. (%): | J25: -
A26: FL / LR | D26: 424 / 2681 | E26: 616 / 613
A27: Stator Slot Shape (Reference) | F27: Performance
H28: LRC (A) | I28: - | J28: 2683 / 1549 | K28: - | M28: =(J28/J18)*100 -> #VALUE!
H29: LRT (%) | I29: 60 | J29: 139 | K29: -
H30: BDT (%) | I30: 175 | J30: 216 | K30: -
H31: SLIP (%) | J31: 0.5 | K31: -
G32: IEEE-B | H32: Eff. (%) | J32: 96.5 | K32: -
A33: Rotor Slot Shape (Reference) | H33: PF (%) | J33: 91.1 | K33: -
F34: Losses (Watts) | H34: Primary | J34: 11262 | K34: -
H35: Secondary | J35: 8317 | K35: -
H36: Core | J36: 10296 | K36: -
H37: F & W | J37: 6042 | K37: -
H38: Stray | J38: 17904 | K38: -
A39: End Ring (Reference) | F39: Note | G39: DT2M40U (ER at end of bar)
F40: LINK: | G40: DT2M40UEXP_ERchange.rat &
...

Sheet LoginSheet
J1: P | K1: T | L1: L | M1: T
B2: PROJECT HISTORY | J2: E | K2: D | L2: I | M2: Y | N2: H
J3: R | L3: M | M3: P
J4: F | L4: I | M4: E
K5: C | L5: T | N5: I
J6: D | K6: U | M6: T | N6: N
J7: A | K7: R | L7: R | M7: E | N7: S
I8: S | J8: T | K8: V | L8: E | M8: S | N8: U
B9: DATE | C9: PROJECT | D9: SMART NUMBER | E9: QTY | F9: CUSTOMER | G9: REMARKS | H9: LIMIT CODE | I9: F | J9: A | K9: E | L9: V | M9: T | N9: L
B53: REVISION HISTORY
B54: REV | C54: REMARKS | I54: DATE | L54: INIT

Sheet StallTime
A1: Rating: | B1: 2 Pole - 2000.0 HP - 3600 RPM - 4000 V - 60 Hz
A3: Starting Performance
D4: Load Type: Fan / Pump - 1096.1 lb-ft²
A5: RPM | B5: Motor | C5: Load | D5: Accel. | E5: Line | F5: Stator | G5: Rotor
A6: Speed Increment | B6: Torque (%) | C6: Torque (%) | D6: Time (s) | E6: Amps | F6: kW / s | G6: kW / s
A7: 0~375 | B7: 135.0 | C7: 22.4 | D7: 0.493 | E7: 1546.2 | F7: 248.1 | G7: 959.3
A8: 375~750 | B8: 135.0 | C8: 11.3 | D8: 0.448 | E8: 1540.0 | F8: 224.2 | G8: 782.2
A9: 750~1125 | B9: 135.0 | C9: 7.0 | D9: 0.433 | E9: 1532.6 | F9: 214.8 | G9: 668.0
A10: 1125~1501 | B10: 135.0 | C10: 7.6 | D10: 0.435 | E10: 1524.1 | F10: 213.6 | G10: 582.8
A11: 1501~1876 | B11: 135.0 | C11: 12.3 | D11: 0.452 | E11: 1514.3 | F11: 219.1 | G11: 513.4
A12: 1876~2251 | B12: 135.0 | C12: 20.2 | D12: 0.483 | E12: 1503.0 | F12: 231.0 | G12: 450.7
A13: 2251~2626 | B13: 135.1 | C13: 31.4 | D13: 0.535 | E13: 1489.6 | F13: 251.7 | G13: 390.4
A14: 2626~3001 | B14: 136.6 | C14: 47.7 | D14: 0.624 | E14: 1469.7 | F14: 287.8 | G14: 329.4
A15: 3001~3189 | B15: 141.3 | C15: 63.9 | D15: 0.358 | E15: 1443.1 | F15: 159.7 | G15: 237.3
A16: 3189~3376 | B16: 153.8 | C16: 77.1 | D16: 0.362 | E16: 1395.3 | F16: 155.1 | G16: 172.2
... A18: 3564~3575 | B18: 157.5 | C18: 98.8 | D18: 0.027 | E18: 733.0 | F18: 0.3 | G18: 20.6
D21: Acceleration Time: 4.9 s
B22: Energy | D22: First Start | F22: Second Start
A23: Stator Winding Rise | B23: 2315 kW / s | D23: 22°C | F23: 45°C
A24: Rotor Bar Rise | B24: 3745 kW / s | D24: 117°C | F24: 234°C
A25: End Ring Rise | B25: 1444 kW / s | D25: 110°C | F25: 221°C
A27: Locked Rotor Thermal Capability
E28: Cold Condition
B29: Rate of Rise | D29: Power | E29: Rise Limit | F29: Max Time
A30: Stator Copper | B30: 5.6°C / s | D30: 580.5 kW | E30: 160°C | F30: 28.5 s
A31: Rotor Bar | B31: 45.5°C / s | D31: 1453.7 kW | E31: 260°C | F31: 5.7 s
A32: Rotor ER | B32: 42.9°C / s | D32: 560.5 kW | E32: 180°C | F32: 4.2 s
E34: Hot Condition
B35: Hot Temp. | D35: Rise Limit | E35: Ambient | F35: Total | G35: Max.Time
A36: Stator Copper | B36: 65°C + | D36: 95°C + | E36: 40°C | F36: = 200°C | G36: 17.0 s
A37: Rotor Bar | B37: 85°C + | D37: 175°C + | E37: 40°C | F37: = 300°C | G37: 3.8 s
A38: Rotor ER | B38: 85°C + | D38: 95°C + | E38: 40°C | F38: = 220°C | G38: 2.2 s
A40: Cold Stall Time: | B40: 10.0 s | D40: Hot Stall Time: | F40: 5.3 s

Sheet Performance Data Sheet 2000HP
A1: TOSHIBA INTERNATIONAL CORPORATION | J1: INDEX | L1: MPCF-1033
A2: Industrial Division / Houston Motor Plant | J2: SHEET NO. | L2: 1 of 1
J3: ISSUED | L3: 7/31/13
J4: SUPERSEDES | L4: 11/8/96
J5: REVISION | L5: 2
A6: SQUIRREL CAGE INDUCTION MOTOR | J6: WRITTEN BY | L6: MDC
A7: PERFORMANCE SPECIFICATIONS | J7: APPROVED BY | L7: PAA
B9: CUSTOMER: | C9: HEARTLAND MOTORS INC
B10: TIC SR No.: | C10: 2374928.4
A12: MOTOR NAMEPLATE DATA
B13: H.P.: | C13: 2000 | E13: VOLTS: | F13: 4000 | H13: 3 PH / | I13: 60 Hz | L13: S. RPM: | M13: 3600
B14: FRAME: | C14: 5812USS | E14: ENCL: | F14: WP-II | H14: FLAMPS: | I14: 245 | L14: FLRPM: | M14: 3582
B15: FORM: | C15: DCW4 | E15: S.F.: | F15: 1.15 | H15: NEMA DESIGN: | I15: - | L15: INSUL CLASS: | M15: F
B16: TYPE: | C16: TIKE | E16: AMB.: | F16: 40°C | H16: CODE: | I16: F | L16: DUTY: | M16: Cont.
B17: MODEL No.: | C17: M401WTAL11E-CH | H17: kW: | I17: -
B18: NOM. EFF.: | C18: - | E18: MIN. EFF.: | F18: - | H18: P.F.: | I18: -
A21: AMPERAGE | E21: TORQUES | I21: **BEARINGS:
C22: LOCKED ROTOR: | D22: 1549 | G22: FULL LOAD (lb-ft.): | H22: 2932 | K22: DRIVE END: | L22: REFER TO NP
G23: LOCKED ROTOR (%): | H23: 135 | K23: OPPOSITE DRIVE END: | L23: REFER TO NP
G24: BREAK DOWN (%): | H24: 215
A28: EFFICIENCY | H28: POWER FACTOR
C29: FULL LOAD: | D29: 96.5 | J29: FULL LOAD: | K29: 91.1
C30: 3/4 LOAD: | D30: 96.3 | J30: 3/4 LOAD: | K30: 89.4
C31: 1/2 LOAD: | D31: 95.6 | J31: 1/2 LOAD: | K31: 84
A35: ALL CHARACTERISTICS ARE AVERAGE EXPECTED VALUES BASED UPON RATED VOLTAGE,
A36: FREQUENCY AND SINEWAVE POWER INPUT.
A37: THE DECLARED LOCKED ROTOR CURRENT HAS A TOLERANCE OF 20%.
A38: * TEMPERATURE RISE WILL BE CONSISTENT WITH INSULATION, AMBIENT AND SERVICE FACTOR AS
A39: DEFINED BY NEMA-MG-12 OR -20.
A40: ** BEARINGS ARE THE ONLY RECOMMENDED SPARE PART(S).
J42: CERTIFIED BY: | K42: JERRY R
J44: DATE: | K44: 45321
A59: - | B59: 6205ZZ | D59: 1 | E59: -
A60: TEFC | B60: 6206UU | D60: 1.15 | E60: A
A61: ODP | B61: 6207ZZ | E61: B
B62: 6208UU
B63: 6211ZZ
B64: 6211C3
B65: 6211ZZC3
B66: 6305UUC3
...

Sheet STCurve 2000HP
A2: TOSHIBA INTERNATIONAL CORPORATION
A3: Speed Torque/Current Curve
A6: Model #: | B6: ='Performance Data Sheet 2000HP'!C17 -> M401WTAL11E-CH | E6: FLAmps: | F6: ='Performance Data Sheet 2000HP'!I14 -> 245
A7: Enclosure: | B7: ='Performance Data Sheet 2000HP'!F14 -> WP-II | C7: Voltage: | D7: ='Performance Data Sheet 2000HP'!F13 & " V" -> 4000 V | E7: Frame: | F7: ='Performance Data Sheet 2000HP'!C14 -> 5812USS
A8: Pole: | B8: 2 | C8: Frequency: | D8: 3 PH / 60 Hz | E8: Ins. Class: | F8: ='Performance Data Sheet 2000HP'!M15 -> F
A9: HP: | B9: ='Performance Data Sheet 2000HP'!C13 -> 2000 | C9: Rotor Inertia: | D9: 241.3 lb-ft² | E9: Date: | F9: ='Performance Data Sheet 2000HP'!K44 -> 45321
A10: FLRPM: | B10: ='Performance Data Sheet 2000HP'!M14 -> 3582 | C10: Load Inertia: | D10: 365.0 lb-ft² | E10: File: | F10: DT2M40U
B12: Locked Rotor Amps: | C12: ='Performance Data Sheet 2000HP'!D22 & " A" -> 1549 A | D12: Load Type: | E12: Fan / Pump
B13: Locked Rotor Torque: | C13: ='Performance Data Sheet 2000HP'!H23/100 -> 1.35 | D13: Starting at: | E13: FV / 0.80 (V)
B14: Breakdown Torque: | C14: 2.15 | D14: Accel. Time: | E14: 2 / 4 (s)
B15: Rated Torque: | C15: ='Performance Data Sheet 2000HP'!H22 & " lb-ft" -> 2932 lb-ft
A39: Comments: | B39: PROJECT | C39: ='Performance Data Sheet 2000HP'!C10 -> 2374928.4 | E39: D.E.Curve #: | F39: =F10 -> DT2M40U
C43: Prepared by: | D43: ='Performance Data Sheet 2000HP'!K42 -> JERRY R | E43: Checked by:
D53: Load | E53: Torque 80% | F53: LRA 80%
A54: 100 | B54: 0 | C54: 0.249488 | D54: 100 | E54: 0 | F54: 48.899647
A55: 99.8 | B55: 95.374019 | C55: 141.25151 | D55: 99.599998 | E55: 61.039372 | F55: 113.00121
A56: 99 | B56: 215 | C56: 457.14865 | D56: 98 | E56: 137.6 | F56: 365.71893
A57: 93.789474 | B57: 162.97668 | C57: 555.70514 | D57: 83.852631 | E57: 104.30507 | F57: 444.56412
A58: 88.578947 | B58: 144.54089 | C58: 583.35394 | D58: 70.30526 | E58: 92.506175 | F58: 466.68317
A59: 83.368421 | B59: 138.02468 | C59: 594.72662 | D59: 57.410526 | E59: 88.335794 | F59: 475.78131
A60: 72.947368 | B60: 135.27364 | C60: 604.99084 | D60: 38.010525 | E60: 86.575139 | F60: 483.99268
A61: 62.526315 | B61: 135.01295 | C61: 611.02557 | D61: 24.778948 | E61: 86.408294 | F61: 488.82047
A62: 52.105263 | B62: 135.00927 | C62: 615.93848 | D62: 15.68421 | E62: 86.40594 | F62: 492.75079
A63: 41.68421 | B63: 135.00565 | C63: 620.21423 | D63: 9.0105257 | E63: 86.403616 | F63: 496.17139
A64: 31.263161 | B64: 135.00387 | C64: 623.93671 | D64: 6.2526321 | E64: 86.402473 | F64: 499.14938
A65: 20.842105 | B65: 135.00287 | C65: 627.1601 | D65: 7.8315787 | E65: 86.401839 | F65: 501.72809
... A67: 0 | B67: 135 | C67: 632.24487 | D67: 30 | E67: 86.400003 | F67: 505.7959

Sheet Thermdam 2000HP
A2: TOSHIBA INTERNATIONAL CORPORATION
A3: Thermal Limit & Acceleration Curves
A4: Design Values (For Reference Only)
A6: Model #: | B6: ='Performance Data Sheet 2000HP'!C17 -> M401WTAL11E-CH | E6: FLAmps: | F6: ='Performance Data Sheet 2000HP'!I14 -> 245
A7: Enclosure: | B7: ='Performance Data Sheet 2000HP'!F14 -> WP-II | C7: Voltage: | D7: ='Performance Data Sheet 2000HP'!F13 & " V" -> 4000 V | E7: Frame: | F7: ='Performance Data Sheet 2000HP'!C14 -> 5812USS
A8: Pole: | B8: 2 | C8: Frequency: | D8: 3 PH / 60 Hz | E8: Ins. Class: | F8: ='Performance Data Sheet 2000HP'!M15 -> F
A9: HP: | B9: ='Performance Data Sheet 2000HP'!C13 -> 2000 | C9: Rotor Inertia: | D9: 241.3 lb-ft² | E9: Date: | F9: ='Performance Data Sheet 2000HP'!K44 -> 45321
A10: FLRPM: | B10: ='Performance Data Sheet 2000HP'!M14 -> 3582 | C10: Load Inertia: | D10: 365.0 lb-ft² | E10: File: | F10: DT2M40U
C12: ='Performance Data Sheet 2000HP'!D22 & " A" -> 1549 A
C13: ='Performance Data Sheet 2000HP'!H23/100 -> 1.35
C15: ='Performance Data Sheet 2000HP'!H22 & " lb-ft" -> 2932 lb-ft
A39: Comments: | B39: PROJECT | C39: ='Performance Data Sheet 2000HP'!C10 -> 2374928.4 | E39: D.E.Curve #: | F39: =F10 -> DT2M40U
C43: Prepared by: | D43: ='Performance Data Sheet 2000HP'!K42 -> JERRY R | E43: Checked by:
F50: =5252.1*B50/D53 -> #DIV/0!
D66: =D65/D64 -> #DIV/0!
A67: Current (%) | B67: Cold | C67: Hot | E67: CURRENT (%) | F67: Accel. Time
A68: 632.2449 | B68: 14.235667 | C68: 7.4286679 | E68: 632.2449 | F68: 0.0001 | G68: =0.8*E68 -> 505.79592 | H68: 0.0001
A69: 600 | B69: 15.806874 | C69: 8.2485784 | E69: 631.10204 | F69: 0.190625 | G69: =0.8*E69 -> 504.88163 | H69: 0.3806543
A70: 500 | B70: 22.761898 | C70: 11.877953 | E70: 628.69388 | F70: 0.36250001 | G70: =0.8*E70 -> 502.9551 | H70: 0.72386721
A71: 400 | B71: 35.565466 | C71: 18.559301 | E71: 625.95918 | F71: 0.52968753 | G71: =0.8*E71 -> 500.76735 | H71: 1.0577198
A72: 300 | B72: 63.227494 | E72: 622.81633 | F72: 0.69687502 | G72: =0.8*E72 -> 498.25306 | H72: 1.3915723
A73: 200 | B73: 142.26186 | E73: 619.30612 | F73: 0.86874999 | G73: =0.8*E73 -> 495.4449 | H73: 1.7347851
A74: 215 | B74: 123.10383 | C74: 64.239875 | E74: 615.38776 | F74: 1.0515625 | G74: =0.8*E74 -> 492.3102 | H74: 2.0998388
A75: 180 | B75: 195.01663 | C75: 91.650872 | E75: 611.06122 | F75: 1.2562499 | G75: =0.8*E75 -> 488.84898 | H75: 2.5085741
A76: 145 | B76: 270.65277 | C76: 141.23606 | E76: 605.22449 | F76: 1.4921875 | G76: =0.8*E76 -> 484.17959 | H76: 2.9797119
A77: 125 | C77: 300 | E77: 597.83673 | F77: 1.6265625 | G77: =0.8*E77 -> 478.26939 | H77: 3.248042
A78: 125 | C78: 600 | E78: 584.36735 | F78: 1.7609375 | G78: =0.8*E78 -> 467.49388 | H78: 3.516372
A79: 125 | C79: 10000 | E79: 536.85714 | F79: 1.865625 | G79: =0.8*E79 -> 429.48571 | H79: 3.7254199
E80: 336.2449 | F80: 1.9578125 | G80: =0.8*E80 -> 268.99592 | H80: 3.9095069
E81: 120 | F81: 2.0031251 | G81: 120 | H81: 3.9999904

Sheet Performance 4000V 2000HP
A2: TOSHIBA INTERNATIONAL CORPORATION
A3: Performance Curve
A4: Design Values (For Reference Only)
A6: Model #: | B6: ='Performance Data Sheet 2000HP'!C17 -> M401WTAL11E-CH | E6: FLAmps: | F6: 245 A
A7: Enclosure: | B7: ='Performance Data Sheet 2000HP'!F14 -> WP-II | C7: Voltage: | D7: 4000 V | E7: Frame: | F7: ='Performance Data Sheet 2000HP'!C14 -> 5812USS
A8: Pole: | B8: 2 | C8: Frequency: | D8: 3 PH / 60 Hz | E8: Ins. Class: | F8: ='Performance Data Sheet 2000HP'!M15 -> F
A9: HP: | B9: ='Performance Data Sheet 2000HP'!C13 -> 2000 | C9: Rotor Inertia: | D9: 241.3 lb-ft² | E9: Date: | F9: ='Performance Data Sheet 2000HP'!K44 -> 45321
A10: FLRPM: | B10: ='Performance Data Sheet 2000HP'!M14 -> 3582 | C10: Load Inertia: | D10: 365.0 lb-ft² | E10: File: | F10: DT2M40U
B12: Locked Rotor Amps: | C12: 1549 A | D12: Load Type: | E12: Fan / Pump
B13: Locked Rotor Torque: | C13: ='Performance Data Sheet 2000HP'!H23/100 -> 1.35 | D13: Starting at: | E13: FV / 0.80 (V)
B14: Breakdown Torque: | C14: 2.15 | D14: Accel. Time: | E14: 2 / 4 (s)
B15: Rated Torque: | C15: ='Performance Data Sheet 2000HP'!H22 & " lb-ft" -> 2932 lb-ft
N36: SPEED | O36: KW
N37: =L43 - (L43-L44) / 10 * 0 -> 3600 | O37: =L45 / 10 * 10 -> 4000
N38: =L43 - (L43-L44) / 10 * 1 -> 3596 | O38: =L45 / 10 * 9 -> 3600
A39: Comments: | B39: PROJECT | C39: ='Performance Data Sheet 2000HP'!C10 -> 2374928.4 | E39: D.E.Curve #: | F39: =F10 -> DT2M40U | N39: =L43 - (L43-L44) / 10 * 2 -> 3592 | O39: =L45 / 10 * 8 -> 3200
N40: =L43 - (L43-L44) / 10 * 3 -> 3588 | O40: =L45 / 10 * 7 -> 2800
N41: =L43 - (L43-L44) / 10 * 4 -> 3584 | O41: =L45 / 10 * 6 -> 2400
N42: =L43 - (L43-L44) / 10 * 5 -> 3580 | O42: =L45 / 10 * 5 -> 2000
C43: Prepared by: | D43: ='Performance Data Sheet 2000HP'!K42 -> JERRY R | E43: Checked by: | K43: SYNC SPEED | L43: 3600 | N43: =L43 - (L43-L44) / 10 * 6 -> 3576 | O43: =L45 / 10 * 4 -> 1600
K44: NEW SPEED LOWER RANGE | L44: 3560 | N44: =L43 - (L43-L44) / 10 * 7 -> 3572 | O44: =L45 / 10 * 3 -> 1200
K45: NEW kW UPPER RANGE | L45: 4000 | N45: =L43 - (L43-L44) / 10 * 8 -> 3568 | O45: =L45 / 10 * 2 -> 800
N46: =L43 - (L43-L44) / 10 * 9 -> 3564 | O46: =L45 / 10 * 1 -> 400
N47: =L43 - (L43-L44) / 10 * 10 -> 3560 | O47: =L45 / 10 * 0 -> 0
A52: ADJUSTED
A53: Load | B53: Efficiency | C53: PF | D53: Amps | E53: RPM | F53: Input Watts
A54: 0 | D54: 55 | E54: 100 | F54: =17700/(L45*1000) * 100 -> 0.4425
A55: 25 | B55: 92.900002 | C55: 65.599998 | D55: 88.309998 | E55: =(1.003774*B10-L44)/(L43-L44)*100 -> 88.79617 | F55: =401360.3/(L45*1000)*100 -> 10.034007
A56: 50 | B56: 95.599998 | C56: 84 | D56: 134.03999 | E56: =(1.002542*B10-L44)/(L43-L44)*100 -> 77.76361 | F56: =780071.3/(L45*1000)*100 -> 19.501783
A57: 75 | B57: 96.300003 | C57: 89.400002 | D57: 187.62 | E57: =(1.001291*B10-L44)/(L43-L44)*100 -> 66.560905 | F57: =1162083/(L45*1000)*100 -> 29.052075
A58: 100 | B58: 96.5 | C58: 91.099998 | D58: 244.89 | E58: =(1*B10-L44)/(L43-L44)*100 -> 55 | F58: =1545646/(L45*1000)*100 -> 38.64115
A59: 125 | B59: 96.5 | C59: 91.5 | D59: 304.95001 | E59: =(0.9987289*B10-L44)/(L43-L44)*100 -> 43.6173 | F59: =1933172/(L45*1000)*100 -> 48.3293
A62: ORIGINAL
A63: Load | B63: Efficiency | C63: PF | D63: Amps | E63: RPM | F63: Input Watts
A64: 0 | D64: 61.625783 | E64: 100 | F64: 25.273271
A65: 25 | B65: 92.81942 | C65: 65.655029 | D65: 88.31028 | E65: 84.221277 | F65: 10.04216
A66: 50 | B66: 95.555931 | C66: 84.036896 | D66: 134.03569 | E66: 68.732291 | F66: 19.509148
A67: 75 | B67: 96.271759 | C67: 89.38517 | D67: 187.61821 | E67: 52.941234 | F67: 29.046134
A68: 100 | B68: 96.452888 | C68: 91.136108 | D68: 244.89075 | E68: 36.863495 | F68: 38.655449
A69: 125 | B69: 96.414482 | C69: 91.520805 | D69: 304.94815 | E69: 20.733088 | F69: 48.33856

Sheet Performance 2300V 2000HP
A2: TOSHIBA INTERNATIONAL CORPORATION
A3: Performance Curve
A4: Design Values (For Reference Only)
A6: Model #: | B6: ='Performance Data Sheet 2000HP'!C17 -> M401WTAL11E-CH | E6: FLAmps: | F6: 424 A
A7: Enclosure: | B7: ='Performance Data Sheet 2000HP'!F14 -> WP-II | C7: Voltage: | D7: 2300 V | E7: Frame: | F7: ='Performance Data Sheet 2000HP'!C14 -> 5812USS
A8: Pole: | B8: 2 | C8: Frequency: | D8: 3 PH / 60 Hz | E8: Ins. Class: | F8: ='Performance Data Sheet 2000HP'!M15 -> F
A9: HP: | B9: ='Performance Data Sheet 2000HP'!C13 -> 2000 | C9: Rotor Inertia: | D9: 241.3 lb-ft² | E9: Date: | F9: ='Performance Data Sheet 2000HP'!K44 -> 45321
A10: FLRPM: | B10: ='Performance Data Sheet 2000HP'!M14 -> 3582 | C10: Load Inertia: | D10: 365.0 lb-ft² | E10: File: | F10: DT2M40U
B12: Locked Rotor Amps: | C12: 2683 A | D12: Load Type: | E12: Fan / Pump
B13: Locked Rotor Torque: | C13: ='Performance Data Sheet 2000HP'!H23/100 -> 1.35 | D13: Starting at: | E13: FV / 0.80 (V)
B14: Breakdown Torque: | C14: 2.15 | D14: Accel. Time: | E14: 2 / 4 (s)
B15: Rated Torque: | C15: ='Performance Data Sheet 2000HP'!H22 & " lb-ft" -> 2932 lb-ft
N36: SPEED | O36: KW
N37: =L43 - (L43-L44) / 10 * 0 -> 3600 | O37: =L45 / 10 * 10 -> 4000
N38: =L43 - (L43-L44) / 10 * 1 -> 3596 | O38: =L45 / 10 * 9 -> 3600
A39: Comments: | B39: PROJECT | C39: ='Performance Data Sheet 2000HP'!C10 -> 2374928.4 | E39: D.E.Curve #: | F39: =F10 -> DT2M40U | N39: =L43 - (L43-L44) / 10 * 2 -> 3592 | O39: =L45 / 10 * 8 -> 3200
N40: =L43 - (L43-L44) / 10 * 3 -> 3588 | O40: =L45 / 10 * 7 -> 2800
N41: =L43 - (L43-L44) / 10 * 4 -> 3584 | O41: =L45 / 10 * 6 -> 2400
N42: =L43 - (L43-L44) / 10 * 5 -> 3580 | O42: =L45 / 10 * 5 -> 2000
C43: Prepared by: | D43: ='Performance Data Sheet 2000HP'!K42 -> JERRY R | E43: Checked by: | K43: SYNC SPEED | L43: 3600 | N43: =L43 - (L43-L44) / 10 * 6 -> 3576 | O43: =L45 / 10 * 4 -> 1600
K44: NEW SPEED LOWER RANGE | L44: 3560 | N44: =L43 - (L43-L44) / 10 * 7 -> 3572 | O44: =L45 / 10 * 3 -> 1200
K45: NEW kW UPPER RANGE | L45: 4000 | N45: =L43 - (L43-L44) / 10 * 8 -> 3568 | O45: =L45 / 10 * 2 -> 800
N46: =L43 - (L43-L44) / 10 * 9 -> 3564 | O46: =L45 / 10 * 1 -> 400
N47: =L43 - (L43-L44) / 10 * 10 -> 3560 | O47: =L45 / 10 * 0 -> 0
A52: ADJUSTED
A53: Load | B53: Efficiency | C53: PF | D53: Amps | E53: RPM | F53: Input Watts
A54: 0 | D54: 95.262794 | E54: 100 | F54: =17700/(L45*1000) * 100 -> 0.4425
A55: 25 | B55: 92.900002 | C55: 65.599998 | D55: 152.9574 | E55: =(1.003774*B10-L44)/(L43-L44)*100 -> 88.79617 | F55: =401360.3/(L45*1000)*100 -> 10.034007
A56: 50 | B56: 95.599998 | C56: 84 | D56: 232.16408 | E56: =(1.002542*B10-L44)/(L43-L44)*100 -> 77.76361 | F56: =780071.3/(L45*1000)*100 -> 19.501783
A57: 75 | B57: 96.300003 | C57: 89.400002 | D57: 324.96736 | E57: =(1.001291*B10-L44)/(L43-L44)*100 -> 66.560905 | F57: =1162083/(L45*1000)*100 -> 29.052075
A58: 100 | B58: 96.5 | C58: 91.099998 | D58: 424 | E58: =(1*B10-L44)/(L43-L44)*100 -> 55 | F58: =1545646/(L45*1000)*100 -> 38.64115
A59: 125 | B59: 96.5 | C59: 91.5 | D59: 528.18891 | E59: =(0.9987289*B10-L44)/(L43-L44)*100 -> 43.6173 | F59: =1933172/(L45*1000)*100 -> 48.3293
A62: ORIGINAL
A63: Load | B63: Efficiency | C63: PF | D63: Amps | E63: RPM | F63: Input Watts
A64: 0 | D64: 61.625783 | E64: 100 | F64: 25.273271
A65: 25 | B65: 92.81942 | C65: 65.655029 | D65: 88.31028 | E65: 84.221277 | F65: 10.04216
A66: 50 | B66: 95.555931 | C66: 84.036896 | D66: 134.03569 | E66: 68.732291 | F66: 19.509148
A67: 75 | B67: 96.271759 | C67: 89.38517 | D67: 187.61821 | E67: 52.941234 | F67: 29.046134
A68: 100 | B68: 96.452888 | C68: 91.136108 | D68: 244.89075 | E68: 36.863495 | F68: 38.655449
A69: 125 | B69: 96.414482 | C69: 91.520805 | D69: 304.94815 | E69: 20.733088 | F69: 48.33856

Sheet Circuit Param
A1: TOSHIBA INTERNATIONAL CORPORATION | J1: INDEX | L1: MPCF-1109
A2: Industrial Division / Houston Motor Plant | J2: SHEET NO. | L2: 1 of 1
J3: ISSUED | L3: 38309
A4: EQUIVALENT CIRCUIT DATA | J4: SUPERSEDES | L4: NEW
J5: REVISION | L5: REV. 0
J6: WRITTEN BY | L6: MDC
A7: All Values are Presented in Ohms/Phase, Equivalent Wye Connection. | J7: APPROVED BY | L7: Paul Anderson
B9: CUSTOMER: | C9: JOHNSON CONTROL INC
B10: TIC SR No.: | C10: 2177141.1
A12: MOTOR NAMEPLATE DATA
B13: H.P.: | C13: 2000 | E13: VOLTS: | F13: 4000 | H13: 3 PH / | I13: 60 Hz | L13: S. RPM: | M13: 3600
B14: FRAME: | C14: 5812UDZ | E14: ENCL: | F14: WP-II | H14: FLAMPS: | I14: 245 | L14: FLRPM: | M14: 3582
B15: FORM: | C15: DCNLW | E15: S.F.: | F15: 1.0 | H15: NEMA DESIGN: | I15: - | L15: INSUL CLASS: | M15: F
B16: TYPE: | C16: TIKE | E16: AMB.: | F16: 40°C | H16: CODE: | I16: F | L16: DUTY: | M16: Cont.
B17: MODEL No.: | C17: A1-10032592 | H17: kW: | I17: -
B18: NOM. EFF.: | C18: 96.2 | E18: MIN. EFF.: | F18: - | H18: P.F.: | I18: 91
A21: Primary Resistance (R1) : | G21: 0.0699
A22: Secondary Resistance (R2) : | G22: 0.0729
A23: Starting Secondary Resistance (R3) : | G23: 0.0292
A25: Primary Reactance (X1) : | G25: 1.031
A26: Secondary Reactance (X2) : | G26: 1.015
A27: Starting Secondary Reactance (X3) : | G27: 0.652
A29: Magnetizing Reactance (Xm) : | G29: 41.9
A31: Transient Reactance : | G31: 2.3
A32: Sub Transient Reactance : | G32: 1.7
A33: Short Circuit Time Constant : | G33: 1.051
A34: Sub Transient Time Constant : | G34: 0.011
A35: Open Circuit Time Constant : | G35: 1.56
I40: CERTIFIED BY: | J40: JERRY R
I42: DATE: | J42: 43977

Sheet Performance API
A1: TOSHIBA INTERNATIONAL CORPORATION | J1: INDEX | L1: MPCF-1082
A2: Industrial Division / Houston Motor Plant | J2: SHEET NO. | L2: 1 of 1
J3: ISSUED | L3: 2/14/02
J4: SUPERSEDES | L4: NEW
J5: REVISION | L5: 0
A6: SQUIRREL CAGE INDUCTION MOTOR | J6: WRITTEN BY | L6: M. CAMPBELL
A7: API 541 PERFORMANCE SPECIFICATIONS | J7: APPROVED BY | L7: P.A.A
B9: CUSTOMER: | C9: JOHNSON CONTROL INC
B10: TIC SR No.: | C10: 2177141.1
A12: MOTOR NAMEPLATE DATA
B13: H.P.: | C13: 2000 | E13: VOLTS: | F13: 4000 | H13: 3 PH / | I13: 60 Hz | L13: S. RPM: | M13: 3600
B14: FRAME: | C14: 5812UDZ | E14: ENCL: | F14: WP-II | H14: FLAMPS: | I14: 245 | L14: FLRPM: | M14: 3582
B15: FORM: | C15: DCNLW | E15: S.F.: | F15: 1.0 | H15: NEMA DESIGN: | I15: - | L15: INSUL CLASS: | M15: F
B16: TYPE: | C16: TIKE | E16: AMB.: | F16: 40°C | H16: CODE: | I16: F | L16: DUTY: | M16: Cont.
B17: MODEL No.: | C17: A1-10032592 | H17: kW: | I17: -
B18: NOM. EFF.: | C18: 96.2 | E18: MIN. EFF.: | F18: - | H18: P.F.: | I18: 91
A20: LOCKED ROTOR DATA
D21: AMPS AT RATED VOLTAGE: | E21: 1545 A | I21: POWER FACTOR: | J21: 0.223
D22: AMPS AT 80% VOLTAGE: | E22: 1226 A
A24: TORQUE VALUES | H24: CURVE NUMBERS
E25: FULL LOAD (LB.FT): | F25: 1549 | J25: SPEED-TORQUE CURVE: | K25: DT2M40U_REV4.
E26: LOCKED ROTOR TORQUE (% OF FLT): | F26: 135 | J26: SPEED-CURRENT CURVE: | K26: DT2M40U_REV4.
E27: PULL UP TORQUE (% OF FLT): | F27: 135 | J27: ACCELERATION CURVE: | K27: DT2M40U_REV4.
E28: BREAKDOWN TORQUE (% OF FLT): | F28: 215
A30: LOCKED ROTOR WITHSTAND TIMES
A31: COLD CONDITION | H31: HOT CONDITION
C32: 100% VOLTAGE: | D32: 14 (s) | J32: 100% VOLTAGE: | K32: 8 (s)
C33: 90% VOLTAGE: | D33: 17 (s) | J33: 90% VOLTAGE: | K33: 10 (s)
C34: 80% VOLTAGE: | D34: 22 (s) | J34: 80% VOLTAGE: | K34: 13 (s)
C35: 70% VOLTAGE: | D35: 28 (s) | J35: 70% VOLTAGE: | K35: 16 (s)
A37: DESIGN DATA
C38: MOTOR ROTOR wk2 (LB.FT2): | D38: 241.3 | J38: NO LOAD CURRENT: | K38: 56 A
C39: AIR GAP: | D39: 3.3 mm | J39: ACCELERATION TIME: | K39: 2 / 3 (s)
D40: LOAD CHARACTERISTICS
D41: LOAD | G41: 1/2 | H41: 3/4 | I41: FULL | J41: SF
D42: AMPS (A) | G42: 134 | H42: 188 | I42: 245 | J42: -
D43: EFFICIENCY (%) | G43: 95.6 | H43: 96.3 | I43: 96.5 | J43: -
D44: POWER FACTOR (%) | G44: 84 | H44: 89.4 | I44: 91.1 | J44: -
D45: GUARENTEED EFFICIENCY (%) | G45: - | H45: - | I45: - | J45: -
A46: EFFICIENCY TO BE DETERMINED BY IEEE 112, METHOD B
...

Sheet Performance Data Sheet 1750HP
A1: TOSHIBA INTERNATIONAL CORPORATION | J1: INDEX | L1: MPCF-1033
A2: Industrial Division / Houston Motor Plant | J2: SHEET NO. | L2: 1 of 1
J3: ISSUED | L3: 7/31/13
J4: SUPERSEDES | L4: 11/8/96
J5: REVISION | L5: 2
A6: SQUIRREL CAGE INDUCTION MOTOR | J6: WRITTEN BY | L6: MDC
A7: PERFORMANCE SPECIFICATIONS | J7: APPROVED BY | L7: PAA
B9: CUSTOMER: | C9: HEARTLAND MOTORS INC
B10: TIC SR No.: | C10: 2374928.4
A12: MOTOR NAMEPLATE DATA
B13: H.P.: | C13: 1750 | E13: VOLTS: | F13: 2300/4000 | H13: 3 PH / | I13: 60 Hz | L13: S. RPM: | M13: 3600
B14: FRAME: | C14: 5812USS | E14: ENCL: | F14: WP-II | H14: FLAMPS: | I14: 372/215 | L14: FLRPM: | M14: 3585
B15: FORM: | C15: DCKW4 | E15: S.F.: | F15: 1.15 | H15: NEMA DESIGN: | I15: - | L15: INSUL CLASS: | M15: F
B16: TYPE: | C16: TIKE | E16: AMB.: | F16: 40 | H16: CODE: | I16: G | L16: DUTY: | M16: Cont.
B17: MODEL No.: | C17: 3UKM40L1S50150 | H17: kW: | I17: -
B18: NOM. EFF.: | C18: - | E18: MIN. EFF.: | F18: - | H18: P.F.: | I18: -
A21: AMPERAGE | E21: TORQUES | I21: **BEARINGS:
C22: LOCKED ROTOR: | D22: 2683/1549 | G22: FULL LOAD (lb-ft.): | H22: 2564 | K22: DRIVE END:
G23: LOCKED ROTOR (%): | H23: 155 | K23: OPPOSITE DRIVE END:
G24: BREAK DOWN (%): | H24: 245
A28: EFFICIENCY | H28: POWER FACTOR
C29: FULL LOAD: | D29: 96.7 | J29: FULL LOAD: | K29: 90.5
C30: 3/4 LOAD: | D30: 96.4 | J30: 3/4 LOAD: | K30: 88
C31: 1/2 LOAD: | D31: 95.5 | J31: 1/2 LOAD: | K31: 81.4
A35: ALL CHARACTERISTICS ARE AVERAGE EXPECTED VALUES BASED UPON RATED VOLTAGE,
A36: FREQUENCY AND SINEWAVE POWER INPUT.
A37: THE DECLARED LOCKED ROTOR CURRENT HAS A TOLERANCE OF 20%.
A38: * TEMPERATURE RISE WILL BE CONSISTENT WITH INSULATION, AMBIENT AND SERVICE FACTOR AS
A39: DEFINED BY NEMA-MG-12 OR -20.
A40: ** BEARINGS ARE THE ONLY RECOMMENDED SPARE PART(S).
J42: CERTIFIED BY: | K42: Jerry R
J44: DATE: | K44: 45897
A59: - | B59: 6205ZZ | D59: 1 | E59: -
A60: TEFC | B60: 6206UU | D60: 1.15 | E60: A
A61: ODP | B61: 6207ZZ | E61: B
B62: 6208UU
B63: 6211ZZ
B64: 6211C3
B65: 6211ZZC3
B66: 6305UUC3
...

Sheet STCurve 1750HP
A2: TOSHIBA INTERNATIONAL CORPORATION
A3: Speed Torque/Current Curve
A6: Model #: | B6: ='Performance Data Sheet 1750HP'!C17 -> 3UKM40L1S50150 | E6: FLAmps: | F6: ='Performance Data Sheet 1750HP'!I14 & " A" -> 372/215 A
A7: Enclosure: | B7: ='Performance Data Sheet 1750HP'!F14 -> WP-II | C7: Voltage: | D7: ='Performance Data Sheet 1750HP'!F13 & " V" -> 2300/4000 V | E7: Frame: | F7: ='Performance Data Sheet 1750HP'!C14 -> 5812USS
A8: Pole: | B8: 2 | C8: Frequency: | D8: 3 PH / 60 Hz | E8: Ins. Class: | F8: F
A9: HP: | B9: 1750 | C9: Rotor Inertia: | D9: 241.3 lb-ft² | E9: Date: | F9: ='Performance Data Sheet 1750HP'!K44 -> 45897
A10: FLRPM: | B10: 3585 | C10: Load Inertia: | D10: 335.4 lb-ft² | E10: File: | F10: H110345
B12: Locked Rotor Amps: | C12: ='Performance Data Sheet 1750HP'!D22 & " A" -> 2683/1549 A | D12: Load Type: | E12: Fan / Pump
B13: Locked Rotor Torque: | C13: 1.55 | D13: Starting at: | E13: FV / 0.80 (V)
B14: Breakdown Torque: | C14: 2.45 | D14: Accel. Time: | E14: 2 / 4 (s)
B15: Rated Torque: | C15: 2564 lb-ft
A39: Comments: | B39: PROJECT | C39: ='Performance Data Sheet 1750HP'!C10 -> 2374928.4 | E39: D.E.Curve #: | F39: =F10 -> H110345
C43: Prepared by: | D43: ='Performance Data Sheet 1750HP'!K42 -> Jerry R | E43: Checked by:
D53: Load | E53: Torque 80% | F53: LRA 80%
A54: 100 | B54: 0 | C54: 0.28430027 | D54: 100 | E54: 0 | F54: 48.899647
A55: 99.2 | B55: 108.68202 | C55: 160.96101 | D55: 98.400002 | E55: 69.556496 | F55: 128.76881
A56: 96 | B56: 245 | C56: 520.93683 | D56: 89.75 | E56: 156.8 | F56: 416.74948
A57: 90.857143 | B57: 196.89108 | C57: 633.24542 | D57: 76.228569 | E57: 126.0103 | F57: 506.59634
A58: 85.714285 | B58: 169.10425 | C58: 664.7522 | D58: 62.85714 | E58: 108.22672 | F58: 531.80176
A59: 80.571428 | B59: 159.35079 | C59: 677.71179 | D59: 51.257141 | E59: 101.9845 | F59: 542.16943
A60: 70.285714 | B60: 155.30942 | C60: 689.40814 | D60: 33.485714 | E60: 99.39803 | F60: 551.52655
A61: 59.999999 | B61: 155 | C61: 696.28497 | D61: 22 | E61: 99.200003 | F61: 557.02802
A62: 50 | B62: 155.00001 | C62: 701.88336 | D62: 14 | E62: 99.200013 | F62: 561.50671
A63: 39.999998 | B63: 155.00182 | C63: 706.7558 | D63: 7.9999995 | E63: 99.201165 | F63: 565.40466
A64: 30.000001 | B64: 155.00254 | C64: 710.99762 | D64: 5.9999995 | E64: 99.201624 | F64: 568.7981
A65: 19.999999 | B65: 155.00583 | C65: 714.67084 | D65: 8.000001 | E65: 99.203733 | F65: 571.73669
... A67: 0 | B67: 155 | C67: 720.46509 | D67: 30 | E67: 99.200003 | F67: 576.37207

Sheet Thermdam 1750HP
A2: TOSHIBA INTERNATIONAL CORPORATION
A3: Thermal Limit & Acceleration Curves
A4: Design Values (For Reference Only)
A6: Model #: | B6: ='Performance Data Sheet 1750HP'!C17 -> 3UKM40L1S50150 | E6: FLAmps: | F6: ='Performance Data Sheet 1750HP'!I14 & " A" -> 372/215 A
A7: Enclosure: | B7: ='Performance Data Sheet 1750HP'!F14 -> WP-II | C7: Voltage: | D7: ='Performance Data Sheet 1750HP'!F13 & " V" -> 2300/4000 V | E7: Frame: | F7: ='Performance Data Sheet 1750HP'!C14 -> 5812USS
A8: Pole: | B8: 2 | C8: Frequency: | D8: 3 PH / 60 Hz | E8: Ins. Class: | F8: F
A9: HP: | B9: 1750 | C9: Rotor Inertia: | D9: 241.3 lb-ft² | E9: Date: | F9: ='Performance Data Sheet 1750HP'!K44 -> 45897
A10: FLRPM: | B10: 3585 | C10: Load Inertia: | D10: 335.4 lb-ft² | E10: File: | F10: H110345
A39: Comments: | B39: PROJECT | C39: ='Performance Data Sheet 1750HP'!C10 -> 2374928.4 | E39: D.E.Curve #: | F39: =F10 -> H110345
C43: Prepared by: | D43: ='Performance Data Sheet 1750HP'!K42 -> Jerry R | E43: Checked by:
F50: =5252.1*B50/D53 -> #DIV/0!
D66: =D65/D64 -> #DIV/0!
A67: Current (%) | B67: Cold | C67: Hot | E67: CURRENT (%) | F67: Accel. Time
A68: 720.46512 | B68: 14.318897 | C68: 9.2553765 | E68: =A68 -> 720.46512 | F68: 0.0001 | G68: =0.8*E68 -> 576.37209 | H68: =F68 -> 0.0001
A69: =FLOOR(A68,100) -> 700 | B69: =((A68/A69)^2)*B68 -> 15.168387 | C69: =((A68/A69)^2)*C68 -> 9.8044656 | E69: 719.16279 | F69: 0.198 | G69: =0.8*E69 -> 575.33023 | H69: =2*F69 -> 0.396
A70: =A69-100 -> 600 | B70: =((A68/A70)^2)*B68 -> 20.64586 | C70: =((A68/A70)^2)*C68 -> 13.344967 | E70: 716.27907 | F70: 0.38100001 | G70: =0.8*E70 -> 573.02326 | H70: =2*F70 -> 0.76200002
A71: =A70-100 -> 500 | B71: =((A68/A71)^2)*B68 -> 29.730038 | C71: =((A68/A71)^2)*C68 -> 19.216753 | E71: 712.83721 | F71: 0.55800003 | G71: =0.8*E71 -> 570.26977 | H71: =2*F71 -> 1.1160001
A72: =A71-100 -> 400 | B72: =((A68/A72)^2)*B68 -> 46.453184 | E72: 708.88372 | F72: 0.73500001 | G72: =0.8*E72 -> 567.10698 | H72: =2*F72 -> 1.47
A73: =A72-100 -> 300 | B73: =((A68/A73)^2)*B68 -> 82.583439 | E73: 704.32558 | F73: 0.917 | G73: =0.8*E73 -> 563.46047 | H73: =2*F73 -> 1.834
A74: 245 | B74: =((A68/A74)^2)*B68 -> 123.82356 | C74: =((A68/A74)^2)*C68 -> 80.036454 | E74: 699.06977 | F74: 1.109 | G74: =0.8*E74 -> 559.25581 | H74: =2*F74 -> 2.2179999
A75: 180 | B75: =((A68/A75)^2)*B69 -> 243.00785 | C75: =((A68/A75)^2)*C68 -> 148.27741 | E75: 692.83721 | F75: 1.321 | G75: =0.8*E75 -> 554.26977 | H75: =2*F75 -> 2.642
A76: 145 | B76: =((A68/A76)^2)*B68 -> 353.50818 | C76: =((A68/A76)^2)*C68 -> 228.49884 | E76: 683.5814 | F76: 1.556 | G76: =0.8*E76 -> 546.86512 | H76: =2*F76 -> 3.112
A77: 125 | C77: =CEILING(C76*2,100) -> 500 | E77: 671.2093 | F77: 1.682 | G77: =0.8*E77 -> 536.96744 | H77: =2*F77 -> 3.3640001
A78: 125 | C78: =2*C77 -> 1000 | E78: 648.97674 | F78: 1.801 | G78: =0.8*E78 -> 519.1814 | H78: =2*F78 -> 3.602
A79: 125 | C79: 10000 | E79: 577.06977 | F79: 1.899 | G79: =0.8*E79 -> 461.65581 | H79: =2*F79 -> 3.7980001
E80: 340.93023 | F80: 2 | G80: =0.8*E80 -> 272.74419 | H80: =2*F80 -> 4
E81: 120 | F81: 2 | G81: 120 | H81: =2*F81 -> 4 | J81: =2/2.1 -> 0.95238095

Sheet Performance 4000V 1750HP
A2: TOSHIBA INTERNATIONAL CORPORATION
A3: Performance Curve
A4: Design Values (For Reference Only)
A6: Model #: | B6: ='Performance Data Sheet 1750HP'!C17 -> 3UKM40L1S50150 | E6: FLAmps: | F6: 215 A
A7: Enclosure: | B7: ='Performance Data Sheet 1750HP'!F14 -> WP-II | C7: Voltage: | D7: 4000 V | E7: Frame: | F7: ='Performance Data Sheet 1750HP'!C14 -> 5812USS
A8: Pole: | B8: 2 | C8: Frequency: | D8: 3 PH / 60 Hz | E8: Ins. Class: | F8: F
A9: HP: | B9: 1750 | C9: Rotor Inertia: | D9: 241.3 lb-ft² | E9: Date: | F9: ='Performance Data Sheet 1750HP'!K44 -> 45897
A10: FLRPM: | B10: 3585 | C10: Load Inertia: | D10: 335.4 lb-ft² | E10: File: | F10: H110345
B12: Locked Rotor Amps: | C12: 1549 A | D12: Load Type: | E12: Fan / Pump
B13: Locked Rotor Torque: | C13: 1.55 | D13: Starting at: | E13: FV / 0.80 (V)
B14: Breakdown Torque: | C14: 2.45 | D14: Accel. Time: | E14: 2 / 4 (s)
B15: Rated Torque: | C15: 2564 lb-ft
A39: Comments: | B39: PROJECT | C39: ='Performance Data Sheet 1750HP'!C10 -> 2374928.4 | E39: D.E.Curve #: | F39: =F10 -> H110345
C43: Prepared by: | D43: ='Performance Data Sheet 1750HP'!K42 -> Jerry R | E43: Checked by:
A53: Load | B53: Efficiency | C53: PF | D53: Amps | E53: RPM | F53: Input Watts
A54: 0 | D54: 61.369053 | E54: 100 | F54: 0.4425
A55: 25 | B55: 92.355904 | C55: 68.734039 | D55: 74.101639 | E55: 100.90451 | F55: 8.8216046
A56: 50 | B56: 95.485092 | C56: 81.401321 | D56: 121.03956 | E56: 87.436669 | F56: 17.065015
A57: 75 | B57: 96.395592 | C57: 88.027298 | D57: 166.30722 | E57: 69.115227 | F57: 25.355744
A58: 100 | B58: 96.701775 | C58: 90.50338 | D58: 214.99341 | E58: 50.49648 | F58: 33.700614
A59: 125 | B59: 96.759094 | C59: 91.380302 | D59: 266.00513 | E59: 31.893702 | F59: 42.100816

Sheet Performance 2300V 1750HP
A2: TOSHIBA INTERNATIONAL CORPORATION
A3: Performance Curve
A4: Design Values (For Reference Only)
A6: Model #: | B6: ='Performance Data Sheet 1750HP'!C17 -> 3UKM40L1S50150 | E6: FLAmps: | F6: 372 A
A7: Enclosure: | B7: ='Performance Data Sheet 1750HP'!F14 -> WP-II | C7: Voltage: | D7: 2300 V | E7: Frame: | F7: ='Performance Data Sheet 1750HP'!C14 -> 5812USS
A8: Pole: | B8: 2 | C8: Frequency: | D8: 3 PH / 60 Hz | E8: Ins. Class: | F8: F
A9: HP: | B9: 1750 | C9: Rotor Inertia: | D9: 241.3 lb-ft² | E9: Date: | F9: ='Performance Data Sheet 1750HP'!K44 -> 45897
A10: FLRPM: | B10: 3585 | C10: Load Inertia: | D10: 335.4 lb-ft² | E10: File: | F10: H110345
B12: Locked Rotor Amps: | C12: 2683 A | D12: Load Type: | E12: Fan / Pump
B13: Locked Rotor Torque: | C13: 1.55 | D13: Starting at: | E13: FV / 0.80 (V)
B14: Breakdown Torque: | C14: 2.45 | D14: Accel. Time: | E14: 2 / 4 (s)
B15: Rated Torque: | C15: 2564 lb-ft
A39: Comments: | B39: PROJECT | C39: ='Performance Data Sheet 1750HP'!C10 -> 2374928.4 | E39: D.E.Curve #: | F39: =F10 -> H110345
C43: Prepared by: | D43: ='Performance Data Sheet 1750HP'!K42 -> Jerry R | E43: Checked by:
A53: Load | B53: Efficiency | C53: PF | D53: Amps | E53: RPM | F53: Input Watts
A54: 0 | D54: 61.369053 | E54: 100 | F54: 0.4425
A55: 25 | B55: 92.355904 | C55: 68.734039 | D55: 74.101639 | E55: 100.90451 | F55: 8.8216046
A56: 50 | B56: 95.485092 | C56: 81.401321 | D56: 121.03956 | E56: 87.436669 | F56: 17.065015
A57: 75 | B57: 96.395592 | C57: 88.027298 | D57: 166.30722 | E57: 69.115227 | F57: 25.355744
A58: 100 | B58: 96.701775 | C58: 90.50338 | D58: 214.99341 | E58: 50.49648 | F58: 33.700614
A59: 125 | B59: 96.759094 | C59: 91.380302 | D59: 266.00513 | E59: 31.893702 | F59: 42.100816
