Workbook

Sheet EqCircut
B1: .
A2: What is the % BDT before Correlation ? | E2: =LEFT(J6,SEARCH("/",J6,1)-1) -> 214.4 | H2: Voltage : | J2: =[1]DesignSheet!E5 -> 460 | L2: First Cycle Inrush
A3: What is the % BDT after Correlation ? | E3: =RIGHT(J6,SEARCH("/",J6,1)-2) -> 283.0 | H3: Frequency : | J3: =[1]DesignSheet!F5 -> 60 | L3: =1.25*SQRT(2)*(1+EXP((-PI()*D16)/D19)) -> 2.3499994
H4: No-Load Current: | J4: =[1]DesignSheet!B34 -> 77.45 / 107.93
A5: what are the No Load Amps? | D5: =RIGHT(J4,SEARCH("/",J4,1)-2) -> 07.93 | H5: Full Load Current: | J5: =[1]DesignSheet!E37 -> 277.74 / 295.13
H6: Breakdown Torque: | J6: =[1]DesignSheet!H45 -> 214.4 / 283.0
A7: What are the Full load Amps? | D7: =RIGHT(J5,SEARCH("/",J5,1)-2) -> 295.13 | H7: Wc: | J7: =[1]DesignSheet!J37 -> 4161.8 / 2057.4
H8: Wf: | J8: =[1]DesignSheet!H38 -> 980.0 / 979.7
A9: TOSHIBA INTERNATIONAL CORPORATION
A10: ALL VALUES ARE IN EQULIVALENT Y
D12: VALUE (OHMS) | F12: PER UNIT
A13: BASE IMPEDANCE PER UNIT | D13: =B49 -> 0.89987844 | F13: =D13/B49 -> 1
A14: PRIMARY REISTANCE (R1) | D14: =B50 -> 0.0051792472 | F14: =D14/B49 -> 0.0057554965
A15: SECONDARY RESISTANCE (R2) | D15: =B51 -> 0.0061107265 | F15: =D15/B49 -> 0.0067906133 | I15: Project or Lab:
A16: STARTING RESISTANCE (R3) | D16: =B52 -> 0.032670562 | F16: =D16/B49 -> 0.036305528 | I16: RF2500
A17: PRIMARY REACTANCE (X1) | D17: =B56 -> 0.052373753 | F17: =D17/B49 -> 0.05820092
A18: SECONDARY REACTANCE (X2) | D18: =B57 -> 0.12930062 | F18: =D18/B49 -> 0.14368676
A19: STARTING REACTANCE (X3) | D19: =B60 -> 0.092416131 | F19: =D19/B49 -> 0.10269846
A20: MAGNETIZING REACTANCE (XM) | D20: =B61 -> 33.490684 | F20: =D20/B49 -> 37.216898
A22: TRANSIENT REACTANCE (Xd') | D22: =B62 -> 0.18117709 | F22: =D22/B49 -> 0.20133507
A23: SUB TRANSIENT REACTANCE (Xd") | D23: =B63 -> 0.10618234 | F23: =D23/B49 -> 0.11799631
A24: SHORT CIRCUIT TIME CONSTANT | D24: =B64 -> 0.07882685 | F24: =D24/B49 -> 0.087597221
A25: SUB TRANSIENT TIME CONSTANT | D25: =B65 -> 0.010526515 | F25: =D25/B49 -> 0.011697708
A26: OPEN CIRCUIT TIME CONSTANT | D26: =B66 -> 14.593973 | F26: =D26/B49 -> 16.217716
A28: INDUCTANCES (HENRIES)
A29: STATOR INDUCTANCE (L1) | D29: =B67 -> 0.00013892569 | F29: =D29/B49 -> 0.00015438273
A30: ROTOR INDUCTANCE (L2) | D30: =B68 -> 0.00034298055 | F30: =D30/B49 -> 0.00038114098
A31: STARTING INDUCTANCE (L3) | D31: =B69 -> 0.0002451414 | F31: =D31/B49 -> 0.00027241613
A34: Rev.1 Added Starting Reactance. 11/18/04 MDC
A35: Rev.2 Corrections to calculations & added first cycle inrush 1/28/09 JR & MDC
A36: Rev.3 Corrected Calculation for R3 MDC 12/9/09
A37: Rev.4 Correction to short circuit time constant. | F37: Used to be "=(B57+((B56*B61)/(B56 * B61))/(B51*E41))" | L37: Z.X 10/25/2019
A38: Rev.5 Correction to short circuit time contstant. Used to be "=(B57+((B56*B61)/(B56+B61))/(B51*E41))" Z.X 12/14/2021
E40: 2*pi*f
B41: Jcon = | C41: =IF([1]DesignSheet!E17= "Delta", "3", "1") -> 3 | D41: Wo = | E41: =2*PI()*[1]DesignSheet!F5 -> 376.99112 | F41: Xcorr = | G41: =IF([1]DesignSheet!A5>4, ".5",".666666666666666666666666") -> .666666666666666666666666
B43: X BDT = | C43: =E3/E2 -> 1.3199627
A45: pacop = | B45: =[1]DesignSheet!I23*EqCircut!G41 -> 8.1768129 | D45: Xcorr * Coil End Reactance
A46: pacop2= | B46: =[1]DesignSheet!I23*(1-EqCircut!G41) -> 4.0884064 | D46: (1-Xcorr) * Coil End Reactance
A47: pac11p = | B47: =[1]DesignSheet!I23*EqCircut!G41 -> 8.1768129 | D47: Xcorr * Coil End Reactance
A48: pac12p = | B48: =B46 -> 4.0884064 | D48: (1-Xcorr) * Coil End Reactance
...
