Workbook
Name Print_Area_MI: 'Performance Data Sheet'!$A$10:$N$42

Sheet DesignSheet
A1: TOSHIBA INTERNATIONAL CORPORATION | I1: Calc. Code: | J1: 2-2-2-0-1-2
A2: 3-PHASE SQUIRREL CAGE INDUCTION MOTOR DESIGN SHEET | J2: B.L.-1 P.F.-1
A3: File: | B3: N:\Top_Hat_5812_Expansion\Electric\Series-Design\WPII\6pole\2T6800U.rat | G3: Date: | H3: 44866 | I3: Time: | J3: 0.45353009
A4: Pole | B4: HP | C4: RPM | D4: Form | E4: Voltage | F4: Frequency | G4: Temperature | H4: FLSpeed | I4: FLSlip | J4: Frame
A5: 6 | B5: 799.99998 | C5: 1200 | D5: DCKW | E5: 4000 | F5: 60 | G5: 105 | H5: 1185.5 / 1180.0 | I5: 0.0121 / 0.0167 | J5: 5811/12
A6: Core Data | D6: Winding Data | H6: Constant Data
B7: Primary | C7: Secondary | F7: Bar | G7: End Ring | H7: St. Slot Pitch | I7: 26.470805 | J7: LR Test Data
A8: Air Gap | B8: 1.6 | H8: Rt. Slot Pitch | I8: 33.794532 | J8: ES
A9: Space Fac. | B9: 0.93000001 | D9: Pitch | E9: 1 ~ 9 | F9: Cross Section Area | H9: Mean Value | I9: 30.132669 | J9: 547.14931
A10: Core Length | B10: 620 | C10: 620 | F10: UB: 356.6 | G10: UER: 1800.0 | H10: Eff.T.W.St. | I10: 16.816341 | J10: WS
A11: OD | B11: 670 | C11: 451.8 | D11: Coil Pitch | E11: 0.8888 | G11: ERT: 35.0 | H11: Eff.T.W.Rt. | I11: 33.794532 | J11: 33812.117
A12: ID | B12: 455 | C12: 270 | D12: Slot Fill | E12: - | G12: ERD1: 340.0 | H12: St.Carter Fac. | I12: 1.2392076 | J12: IS
A13: Core Depth | B13: 54.5 | C13: 60.199999 | D13: Con./Slot | E13: 26 | G13: ERD2: 450.0 | H13: Rt.Carter Fac. | I13: 1 | J13: 110.41961
A14: Eff.Core L. | B14: 455.70001 | C14: 455.70001 | D14: Wire Size 1 | E14: (.051"x.204")x1 | H14: Carter Factor | I14: 1.2392076 | J14: Volts / Turn
A15: Slot Data | D15: Wire Size 2 | E15: (.051"x.182")x1 | H15: Short. Factor | I15: 0.98478329 | J15: 19.739049
A16: Number | B16: 54 | C16: 42 | D16: // Circuits | E16: 2 | H16: Distrib. Factor | I16: 0.95963581 | J16: AC
A17: Kind | B17: Open | C17: Dbl - Closed | D17: Connection | E17: Wye | H17: Wind. Factor | I17: 0.94503331 | J17: 542.27854
A18: Skew | B18: - | C18: 0.80000001 | D18: MCL | E18: 1010 | F18: 655.53896 | H18: Reactance | I18: (Coeff.: 0.0820)
A19: Depth | B19: 53 | C19: 30.700001 | D19: No.Cond./Ph. | E19: 234 | I19: Running | J19: Start
A20: Width | B20: 9.65 - 9.65 | D20: Res. (20°C) | E20: 0.17037123 | H20: Stator Slot | I20: 16.998285 | J20: 16.998285
A21: Opening | B21: 13.8 | C21: 0 | D21: (105°C) | E21: 0.22727321 | F21: 0.27978909 | G21: 0.028362708 | H21: Rotor Slot | I21: 20.608599 | J21: 11.025116
A22: Tip Depth | B22: 2.8299999 | C22: 0.69999999 | D22: Material | E22: CU | F22: AL | G22: AL | H22: Zigzag | I22: 11.438048 | J22: 5.9109221
A23: T.Min.Wid. | B23: 12.670804 | C23: 17.5 | D23: Spec.Resist. | E23: 1.742 | F23: 3.25 | G23: 3.25 | H23: Coil End | I23: 5.2373659 | J23: Skew R.: 0.55
A24: Low. R. | B24: 0 | C24: 2 | D24: Spec.Gravity | E24: 8.8900003 | F24: 2.6700001 | G24: 2.6700001 | H24: Belt Leakage | I24: 3.7951759 | J24: 2.2209138
A25: Up. R. | B25: - | C25: 2 | D25: Weight (kg) | H25: Total Resist. | I25: 0.53542501 | J25: 0.92439735
A26: Wedge Dep. | B26: 2.83 - 2.00 | C26: Magnetic | D26: Wire 1 | E26: 80.721365 | F26: 24.814941 | G26: 12.694804 | H26: Total React. | I26: 5.3121657 | J26: 3.3719122
A27: Duct | B27: 13 x 10 | C27: 13 x 10 | D27: Wire 2 | E27: 71.59599 | F27: - | G27: - | H27: Impedance | I27: 5.3390808 | J27: 3.4963269
A28: Effective Depth (S=1) | D28: Magnetic Circuit Data | I28: Core Loss Data
B29: Res.= | C29: 29.993535 | E29: Length | F29: Section | G29: Density | H29: AT | I29: Volume | J29: Loss | M29: =RIGHT(F$41,SEARCH("/",F$41,1)-1) -> 1176.2 | N29: 125RPM | P29: Kline/in2
B30: Reac.= | C30: 29.998153 | D30: Primary Core | E30: 17.540544 | F30: 496.71301 | G30: 15.78481 | H30: 490.16191 | I30: 48023.422 | J30: 3569.1499 | M30: =RIGHT(E$41,SEARCH("/",E$41,1)-1) -> 1180.0 | N30: 100RPM | P30: =G30*6.4516 -> 101.83728
A31: Excitation Data | D31: Tooth | E31: 5.3 | F31: 519.6677 | G31: 15.087565 | H31: 109.06963 | I31: 16525.433 | J31: 1141.5103 | M31: =RIGHT(D$41,SEARCH("/",D$41,1)-1) -> 1183.7 | N31: 75RPM | P31: =G31*6.4516 -> 97.338937
A32: Excit.Amps | B32: 44.816 / 41.988 | D32: Second.Core | E32: 10.220639 | F32: 548.66281 | G32: 14.290235 | H32: 149.16927 | I32: Total | J32: 4710.6602 | M32: =RIGHT(C$41,SEARCH("/",C$41,1)-1) -> 1187.3 | N32: 50RPM | P32: =G32*6.4516 -> 92.194879
A33: Core Loss | B33: 1.074 / 1.007 | C33: Flux / Pole | D33: Tooth | E33: 3.0700001 | F33: 558.23251 | G33: 14.045259 | H33: 41.528309 | I33: C.L.C. | J33: 1.10 / 1.09 | M33: =RIGHT(B$41,SEARCH("/",B$41,1)-1) -> 1190.8 | N33: 25RPM | P33: =G33*6.4516 -> 90.614395
A34: NoLoad | B34: 44.83 / 42.00 | C34: 7.8405204 | D34: Air Gap | E34: 0.16 | F34: 942.02335 | G34: 8.3230637 | H34: 1059.7263 | I34: S.F.C. | J34: 6.0500002 | P34: =G34*6.4516 -> 53.697078
A35: Load Characteristics | D35: Temp. Rise @ 100%: | E35: 77 / 76 | G35: No Load Loss | H35: 10978.5 / 10857.4 | I35: W.Loss | J35: 5181.7 / 5145.6
A36: Load (%) | B36: 25 | C36: 50 | D36: 75 | E36: 100 | F36: 125 | G36: Primary Loss | H36: 8313.1 / 9021.3 | I36: S.Loss | J36: 2270.2 / 2254.4
A37: Current (A) | B37: 53.52 / 55.14 | C37: 68.13 / 70.20 | D37: 87.83 / 90.50 | E37: 110.42 / 113.78 | F37: 135.23 / 139.34 | G37: Second. Loss | H37: 7577.6 / 7823.6 | I37: Total C.Loss | J37: 7451.9 / 7400.0
A38: Efficiency | B38: 0.925 / 0.911 | C38: 0.954 / 0.940 | D38: 0.960 / 0.946 | E38: 0.961 / 0.946 | F38: 0.959 / 0.944 | G38: Frict.& Wind. | H38: 2500.0 / 2500.0 | I38: Stray Loss | J38: 7172.4282 | L38: =LEFT(E38,SEARCH("/",E38,1)-1) -> 0.961 | M38: =RIGHT(E38,SEARCH("/",E38,1)-1) -> 0.946 | N38: =M38/L38 -> 0.98439126 | O38: Eff.
A39: P.F. | B39: 0.435 / 0.429 | C39: 0.663 / 0.653 | D39: 0.766 / 0.755 | E39: 0.812 / 0.800 | F39: 0.831 / 0.819 | G39: Starting Data | I39: Slip | J39: PF | L39: =LEFT(E39,SEARCH("/",E39,1)-1) -> 0.812 | M39: =RIGHT(E39,SEARCH("/",E39,1)-1) -> 0.800 | N39: =M39/L39 -> 0.98522167 | O39: PF.
A40: Slip | B40: 0.0030 / 0.0076 | C40: 0.0059 / 0.0106 | D40: 0.0090 / 0.0136 | E40: 0.0121 / 0.0167 | F40: 0.0153 / 0.0199 | G40: LRA | H40: 660.5 / 729.2 | L40: =LEFT(E37,SEARCH("/",E37,1)-1) -> 110.42 | M40: 114 | N40: =M40/L40 -> 1.0324217 | O40: Current
...

Sheet Data Sheet
A1: TOSHIBA INTERNATIONAL CORPORATION
A2: INDUCTION MOTOR DATA SHEET
A3: File: | B3: 2T6800U | I3: HRW / Model Number: | J3: 8006WTAL11E-A
A4: Type: TIKK - Form: DCKW - 6 Pole - 800 HP - 4000 V - 60 Hz - 5811/12 - Class F | Q4: Motor Type Selection | T4: Electrical Steel Table
A5: Motor Parameters | F5: PERFORMANCE | J5: DESIGN | K5: TEST | Q5: EPACT | T5: M22 - 26Ga.
A6: Material | D6: NCB1 - 26Ga. | F6: NL & Impedance Test | Q6: EQP-III | T6: M36 - 26Ga.
A7: Air Gap | D7: 1.6 | F7: No load amps | J7: 42 | K7: - | Q7: Exp.Prf. | T7: NCB1 - 26Ga.
A8: Stack length | D8: 620 | F8: No load watts | J8: 10857 | K8: - | Q8: Exp.Prf.-EQPIII | T8: M43 - 26Ga.
A9: Number of turns per coil | D9: 13 | F9: Impedance amps | H9: 3 | I9: f | J9: 232 | K9: - | Q9: Prem. Eff. | T9: M45 - 26Ga.
A10: Wire 1 (size & number) | D10: (.051"x.204")x1 | F10: Impedance volts | H10: 3 | I10: f | J10: 1150 | K10: - | Q10: Standard Eff. | T10: M54 - 26Ga.
A11: Wire 2 (size & number) | D11: (.051"x.182")x1 | F11: Impedance watts | H11: 3 | I11: f | J11: 33812 | K11: - | Q11: OWP | T11: TIPA Lam
A12: Slot fill - circle/square method (%) | D12: - | F12: Temperature Rise (°C) | Q12: Dry Kiln
A13: Connection | D13: 2 x Wye | G13: Winding | I13: 80/115 | J13: 77 / 102 | K13: -
A14: MCL | D14: 1010 | G14: Frame | J14: - | K14: -
A15: Allowance for ins. depth | D15: 11.2896 | G15: Bearing PS/OS | J15: - | K15: -
A16: Allowance for ins. width | D16: 3.5956004 | G16: End Ring | J16: - | K16: -
A17: Slot/Wire arrangement | D17: 26 x 2 | F17: Nameplate Data
A18: Effective cross section for coil | D18: - | H18: FLC (A) | J18: 114
A19: Coil grouping | D19: - | H19: RPM | J19: 1180
A20: Coil pitch (slot number) | D20: 1 ~ 9 | H20: CODE | J20: H
A21: Method of coil connection | D21: - | H21: S. F. | J21: 1.15 | Q21: Method of Connection
A22: Resistance per phase @ 20 °C | D22: 0.17039999 | H22: DESIGN | Q22: Skip
A23: Coil Weight | B23: Wire1 | D23: 177.6 | H23: Nom.Eff. (%): | Q23: Adjacent
A24: (lbs.) | B24: Wire2 | D24: 157.5 | H24: Min.Eff. (%): | Q24: -
A25: Current Densities (A/cm2) | E25: Bar / ER | H25: P.F. (%): | J25: 80
A26: FL / LR | D26: 471 / 3012 | E26: 413 / 184
A27: Stator Slot Shape (Reference) | F27: Performance
H28: LRC (A) | I28: - | J28: 729 | K28: -
H29: LRT (%) | I29: 60 | J29: 149 | K29: -
H30: BDT (%) | I30: 175 | J30: 219 | K30: -
H31: SLIP (%) | J31: 1.67 | K31: -
G32: IEEE-B | H32: Eff. (%) | J32: 94.6 | K32: -
A33: Rotor Slot Shape (Reference) | H33: PF (%) | J33: 80 | K33: -
F34: Losses (Watts) | H34: Primary | J34: 9021 | K34: -
H35: Secondary | J35: 7824 | K35: -
H36: Core | J36: 7400 | K36: -
H37: F & W | J37: 2500 | K37: -
H38: Stray | J38: 7172 | K38: -
A39: End Ring (Reference) | F39: Note
F40: LINK: 2N6800U.RAT & 2N6800U(EST).dat
...

Sheet LoginSheet
J1: P | K1: T | L1: L | M1: T
B2: PROJECT HISTORY | J2: E | K2: D | L2: I | M2: Y | N2: H
J3: R | L3: M | M3: P
J4: F | L4: I | M4: E
K5: C | L5: T | N5: I
J6: D | K6: U | M6: T | N6: N
J7: A | K7: R | L7: R | M7: E | N7: S
I8: S | J8: T | K8: V | L8: E | M8: S | N8: U
B9: DATE | C9: PROJECT | D9: SMART NUMBER | E9: QTY | F9: CUSTOMER | G9: REMARKS | H9: LIMIT CODE | I9: F | J9: A | K9: E | L9: V | M9: T | N9: L
B53: REVISION HISTORY
B54: REV | C54: REMARKS | I54: DATE | L54: INIT

Sheet Performance Data Sheet
A1: TOSHIBA INTERNATIONAL CORPORATION | J1: INDEX | L1: MPCF-1033
A2: Industrial Division / Houston Motor Plant | J2: SHEET NO. | L2: 1 of 1
J3: ISSUED | L3: 7/31/13
J4: SUPERSEDES | L4: 11/8/96
J5: REVISION | L5: 2
A6: SQUIRREL CAGE INDUCTION MOTOR | J6: WRITTEN BY | L6: MDC
A7: PERFORMANCE SPECIFICATIONS | J7: APPROVED BY | L7: PAA
B9: CUSTOMER:
B10: TIC SR No.:
A12: MOTOR NAMEPLATE DATA
B13: H.P.: | C13: 800 | E13: VOLTS: | F13: 4000 | H13: 3 PH / | I13: 60 Hz | L13: S. RPM: | M13: 1200
B14: FRAME: | C14: 5812U | E14: ENCL: | F14: WP-II | H14: FLAMPS: | I14: 114 | L14: FLRPM: | M14: 1180
B15: FORM: | C15: DCKW | E15: S.F.: | F15: 1.15 | H15: NEMA DESIGN: | I15: - | L15: INSUL CLASS: | M15: F
B16: TYPE: | C16: TIKK | E16: AMB.: | F16: 40 | H16: CODE: | I16: H | L16: DUTY: | M16: Cont.
B17: MODEL No.: | C17: 8006WTAL11E-A | H17: kW: | I17: -
B18: NOM. EFF.: | C18: - | E18: MIN. EFF.: | F18: - | H18: P.F.: | I18: -
A21: AMPERAGE | E21: TORQUES | I21: **BEARINGS:
C22: LOCKED ROTOR: | D22: 730 | G22: FULL LOAD (lb-ft.): | H22: 3561 | K22: DRIVE END:
G23: LOCKED ROTOR (%): | H23: 150 | K23: OPPOSITE DRIVE END:
G24: BREAK DOWN (%): | H24: 220
A28: EFFICIENCY | H28: POWER FACTOR
C29: FULL LOAD: | D29: 94.6 | J29: FULL LOAD: | K29: 80
C30: 3/4 LOAD: | D30: 94.6 | J30: 3/4 LOAD: | K30: 75.4
C31: 1/2 LOAD: | D31: 93.9 | J31: 1/2 LOAD: | K31: 65.3
A35: ALL CHARACTERISTICS ARE AVERAGE EXPECTED VALUES BASED UPON RATED VOLTAGE,
A36: FREQUENCY AND SINEWAVE POWER INPUT.
A37: THE DECLARED LOCKED ROTOR CURRENT HAS A TOLERANCE OF 20%.
A38: * TEMPERATURE RISE WILL BE CONSISTENT WITH INSULATION, AMBIENT AND SERVICE FACTOR AS
A39: DEFINED BY NEMA-MG-12 OR -20.
A40: ** BEARINGS ARE THE ONLY RECOMMENDED SPARE PART(S).
J42: CERTIFIED BY: | K42: JERRY R
J44: DATE: | K44: 44866
A59: - | B59: 6205ZZ | D59: 1 | E59: -
A60: TEFC | B60: 6206UU | D60: 1.15 | E60: A
A61: ODP | B61: 6207ZZ | E61: B
B62: 6208UU
B63: 6211ZZ
B64: 6211C3
B65: 6211ZZC3
B66: 6305UUC3
...

Sheet STCurve
A2: TOSHIBA INTERNATIONAL CORPORATION
A3: Speed Torque/Current Curve
A6: Model #: | B6: ='Performance Data Sheet'!C17 -> 8006WTAL11E-A | E6: FLAmps: | F6: ='Performance Data Sheet'!I14 & " A" -> 114 A
A7: Enclosure: | B7: ='Performance Data Sheet'!F14 -> WP-II | C7: Voltage: | D7: ='Performance Data Sheet'!F13 & " V" -> 4000 V | E7: Frame: | F7: ='Performance Data Sheet'!C14 -> 5812U
A8: Pole: | B8: 6 | C8: Frequency: | D8: 3 PH / 60 Hz | E8: Ins. Class: | F8: F
A9: HP: | B9: 800 | C9: Rotor Inertia: | D9: 436.0 lb-ft² | E9: Date: | F9: ='Performance Data Sheet'!K44 -> 44866
A10: FLRPM: | B10: 1180 | C10: Load Inertia: | D10: N/A | E10: File: | F10: 2T6800U REV1.
B12: Locked Rotor Amps: | C12: ='Performance Data Sheet'!D22 & " A" -> 730 A | D12: Load Type: | E12: N/A
B13: Locked Rotor Torque: | C13: 1.5 | D13: Starting at: | E13: N/A
B14: Breakdown Torque: | C14: 2.2 | D14: Accel. Time: | E14: N/A
B15: Rated Torque: | C15: 3561 lb-ft
A39: Comments: | B39: PROJECT | C39: ='Performance Data Sheet'!C10 -> 0 | E39: D.E.Curve #: | F39: =F10 -> 2T6800U REV1.
C43: Prepared by: | D43: ='Performance Data Sheet'!K42 -> JERRY R | E43: Checked by:
A54: 100 | B54: 0 | C54: 0.39323348
A55: 99.6 | B55: 58.151262 | C55: 79.235596
A56: 98 | B56: 202.77836 | C56: 281.76608
A57: 96 | B57: 220 | C57: 409.13647
A58: 90 | B58: 154.53457 | C58: 464.34567
A59: 84 | B59: 129.86276 | C59: 493.02844
A60: 72 | B60: 111.69624 | C60: 524.26166
A61: 59.999999 | B61: 105 | C61: 544.41724
A62: 50 | B62: 105.2816 | C62: 561.41467
A63: 39.999998 | B63: 106.9094 | C63: 577.44714
A64: 30.000001 | B64: 110.6523 | C64: 593.25983
A65: 19.999999 | B65: 117.73691 | C65: 609.12592
... A67: 0 | B67: 150 | C67: 640.35089

Sheet Thermdam
A2: TOSHIBA INTERNATIONAL CORPORATION
A3: Thermal Limit & Acceleration Curves
A4: Design Values (For Reference Only)
A6: Model #: | B6: ='Performance Data Sheet'!C17 -> 8006WTAL11E-A | E6: FLAmps: | F6: ='Performance Data Sheet'!I14 & " A" -> 114 A
A7: Enclosure: | B7: ='Performance Data Sheet'!F14 -> WP-II | C7: Voltage: | D7: ='Performance Data Sheet'!F13 & " V" -> 4000 V | E7: Frame: | F7: ='Performance Data Sheet'!C14 -> 5812U
A8: Pole: | B8: 6 | C8: Frequency: | D8: 3 PH / 60 Hz | E8: Ins. Class: | F8: F
A9: HP: | B9: 800 | C9: Rotor Inertia: | D9: 436.0 lb-ft² | E9: Date: | F9: ='Performance Data Sheet'!K44 -> 44866
A10: FLRPM: | B10: 1180 | C10: Load Inertia: | D10: N/A | E10: File: | F10: 2T6800U REV1.
A39: Comments: | B39: PROJECT | C39: ='Performance Data Sheet'!C10 -> 0 | E39: D.E.Curve #: | F39: =F10 -> 2T6800U REV1.
C43: Prepared by: | D43: ='Performance Data Sheet'!K42 -> JERRY R | E43: Checked by:
F50: =5252.1*B50/D53 -> #DIV/0!
D66: =D65/D64 -> #DIV/0!
A67: Current (%) | B67: Cold | C67: Hot | E67: CURRENT (%) | F67: Accel. Time
A68: 640.35088 | B68: 13.088557 | C68: 5.4838307 | E68: =A68 -> 640.35088 | F68: 0.0001
A69: =FLOOR(A68,100) -> 600 | B69: =((A68/A69)^2)*B68 -> 14.908203 | C69: =((A68/A69)^2)*C68 -> 6.246224 | E69: 632.7193 | F69: 0.76700002
A70: =A69-100 -> 500 | B70: =((A68/A70)^2)*B68 -> 21.467812 | C70: =((A68/A70)^2)*C68 -> 8.9945625 | E70: 617.10526 | F70: 1.569
A71: =A70-100 -> 400 | B71: =((A68/A71)^2)*B68 -> 33.543457 | C71: =((A68/A71)^2)*C68 -> 14.054004 | E71: 601.22807 | F71: 2.4100001
A72: =A71-100 -> 300 | B72: =((A68/A72)^2)*B68 -> 59.632812 | E72: 585.35088 | F72: 3.2950001
A73: =A72-100 -> 200 | B73: =((A68/A73)^2)*B68 -> 134.17383 | E73: 569.47368 | F73: 4.243
A74: 220 | B74: =((A68/A74)^2)*B68 -> 110.88746 | C74: =((A68/A74)^2)*C68 -> 46.459517 | E74: 552.89474 | F74: 5.2779999
A75: 180 | B75: =((A68/A75)^2)*B69 -> 188.67585 | C75: =((A68/A75)^2)*C68 -> 69.402488 | E75: 534.29825 | F75: 6.645
A76: 145 | B76: =((A68/A76)^2)*B68 -> 255.26531 | C76: =((A68/A76)^2)*C68 -> 106.9508 | E76: 508.68421 | F76: 8.1230001
A77: 125 | C77: =CEILING(C76*2,100) -> 300 | E77: 478.68421 | F77: 8.8360004
A78: 125 | C78: =2*C77 -> 600 | E78: 436.75439 | F78: 9.349
A79: 125 | C79: 10000 | E79: 345.4386 | F79: 9.5010004
E80: 0 | F80: 9.6330004

Sheet Performance
A2: TOSHIBA INTERNATIONAL CORPORATION
A3: Performance Curve
A4: Design Values (For Reference Only)
A6: Model #: | B6: ='Performance Data Sheet'!C17 -> 8006WTAL11E-A | E6: FLAmps: | F6: ='Performance Data Sheet'!I14 & " A" -> 114 A
A7: Enclosure: | B7: ='Performance Data Sheet'!F14 -> WP-II | C7: Voltage: | D7: ='Performance Data Sheet'!F13 & " V" -> 4000 V | E7: Frame: | F7: ='Performance Data Sheet'!C14 -> 5812U
A8: Pole: | B8: 6 | C8: Frequency: | D8: 3 PH / 60 Hz | E8: Ins. Class: | F8: F
A9: HP: | B9: 800 | C9: Rotor Inertia: | D9: 436.0 lb-ft² | E9: Date: | F9: ='Performance Data Sheet'!K44 -> 44866
A10: FLRPM: | B10: 1180 | C10: Load Inertia: | D10: N/A | E10: File: | F10: 2T6800U REV1.
B12: Locked Rotor Amps: | C12: ='Performance Data Sheet'!D22 & " A" -> 730 A | D12: Load Type: | E12: N/A
B13: Locked Rotor Torque: | C13: 1.5 | D13: Starting at: | E13: N/A
B14: Breakdown Torque: | C14: 2.2 | D14: Accel. Time: | E14: N/A
B15: Rated Torque: | C15: 3561 lb-ft
A39: Comments: | B39: PROJECT | C39: ='Performance Data Sheet'!C10 -> 0 | E39: D.E.Curve #: | F39: =F10 -> 2T6800U REV1.
C43: Prepared by: | D43: ='Performance Data Sheet'!K42 -> JERRY R | E43: Checked by:
A53: Load | B53: Efficiency | C53: PF | D53: Amps | E53: RPM | F53: Input Watts
A54: 0 | D54: 46.281065 | E54: 100 | F54: 11.166435
A55: 25 | B55: 91.025444 | C55: 42.872284 | D55: 55.250427 | E55: 69.658612 | F55: 10.256523
A56: 50 | B56: 93.91655 | C56: 65.283279 | D56: 70.33329 | E56: 57.97386 | F56: 19.881575
A57: 75 | B57: 94.550369 | C57: 75.444885 | D57: 90.678291 | E57: 45.953465 | F57: 29.622456
A58: 100 | B58: 94.581635 | C58: 79.989708 | D58: 113.99721 | E58: 33.501321 | F58: 39.48355
A59: 125 | B59: 94.358612 | C59: 81.837059 | D59: 139.60905 | E59: 20.747956 | F59: 49.47109

Sheet StallTime
A1: Rating: | B1: 6 Pole - 800.0 HP - 1200 RPM - 4000 V - 60 Hz
A3: Starting Performance
D4: Load Type: Fan / Pump - 7757.5 lb-ft²
A5: RPM | B5: Motor | C5: Load | D5: Accel. | E5: Line | F5: Stator | G5: Rotor
A6: Speed Increment | B6: Torque (%) | C6: Torque (%) | D6: Time (s) | E6: Amps | F6: kW / s | G6: kW / s
A7: 0~120 | B7: 140.0 | C7: 22.5 | D7: 0.767 | E7: 721.3 | F7: 278.7 | G7: 620.4
A8: 120~240 | B8: 123.9 | C8: 11.5 | D8: 0.802 | E8: 703.5 | F8: 277.7 | G8: 506.0
A9: 240~360 | B9: 114.2 | C9: 7.0 | D9: 0.841 | E9: 685.4 | F9: 276.4 | G9: 427.0
A10: 360~480 | B10: 108.8 | C10: 7.0 | D10: 0.885 | E10: 667.3 | F10: 276.1 | G10: 369.8
A11: 480~600 | B11: 106.1 | C11: 11.0 | D11: 0.948 | E11: 649.2 | F11: 280.0 | G11: 327.8
A12: 600~720 | B12: 105.1 | C12: 18.0 | D12: 1.035 | E12: 630.3 | F12: 289.0 | G12: 293.7
A13: 720~864 | B13: 108.3 | C13: 29.2 | D13: 1.367 | E13: 609.1 | F13: 359.1 | G13: 258.0
A14: 864~1008 | B14: 120.8 | C14: 47.6 | D14: 1.478 | E14: 579.9 | F14: 359.9 | G14: 207.6
A15: 1008~1080 | B15: 142.2 | C15: 66.4 | D15: 0.713 | E15: 545.7 | F15: 153.7 | G15: 133.2
A16: 1080~1152 | B16: 187.3 | C16: 81.9 | D16: 0.513 | E16: 497.9 | F16: 98.0 | G16: 71.3
... A18: 1176~1186 | B18: 151.4 | C18: 97.2 | D18: 0.132 | E18: 205.8 | F18: 1.2 | G18: 22.0
D21: Acceleration Time: 9.6 s
B22: Energy | D22: First Start | F22: Second Start
A23: Stator Winding Rise | B23: 2672 kW / s | D23: 46°C | F23: 91°C
A24: Rotor Bar Rise | B24: 2972 kW / s | D24: 134°C | F24: 267°C
A25: End Ring Rise | B25: 301 kW / s | D25: 27°C | F25: 53°C
A27: Locked Rotor Thermal Capability
E28: Cold Condition
B29: Rate of Rise | D29: Power | E29: Rise Limit | F29: Max Time
A30: Stator Copper | B30: 7.4°C / s | D30: 436.2 kW | E30: 160°C | F30: 21.5 s
A31: Rotor Bar | B31: 36.6°C / s | D31: 812.8 kW | E31: 260°C | F31: 7.1 s
A32: Rotor ER | B32: 7.2°C / s | D32: 82.4 kW | E32: 180°C | F32: 24.8 s
E34: Hot Condition
B35: Hot Temp. | D35: Rise Limit | E35: Ambient | F35: Total | G35: Max.Time
A36: Stator Copper | B36: 77°C + | D36: 83°C + | E36: 40°C | F36: = 200°C | G36: 11.2 s
A37: Rotor Bar | B37: 105°C + | D37: 155°C + | E37: 40°C | F37: = 300°C | G37: 4.2 s
A38: Rotor ER | B38: 105°C + | D38: 75°C + | E38: 40°C | F38: = 220°C | G38: 10.4 s
A40: Cold Stall Time: | B40: 9.2 s | D40: Hot Stall Time: | F40: 3.8 s
