Workbook
Name Print_Area_MI: 'Performance Data Sheet'!$A$10:$N$42

Sheet DesignSheet
A1: TOSHIBA INTERNATIONAL CORPORATION | I1: Calc. Code: | J1: 2-2-2-0-1-2
A2: 3-PHASE SQUIRREL CAGE INDUCTION MOTOR DESIGN SHEET | J2: B.L.-1 P.F.-1
A3: File: | B3: G:\DESPRO\RAT FILES\1M4M20U.rat | G3: Date: | H3: 44676 | I3: Time: | J3: 0.53209491
A4: Pole | B4: HP | C4: RPM | D4: Form | E4: Voltage | F4: Frequency | G4: Temperature | H4: FLSpeed | I4: FLSlip | J4: Frame
A5: 4 | B5: 1000 | C5: 1800 | D5: FCNW4 | E5: 4000 | F5: 60 | G5: 105 | H5: 1781.4 / 1776.9 | I5: 0.0103 / 0.0129 | J5: 5812US
A6: Core Data | D6: Winding Data | H6: Constant Data
B7: Primary | C7: Secondary | F7: Bar | G7: End Ring | H7: St. Slot Pitch | I7: 22.252929 | J7: LR Test Data
A8: Air Gap | B8: 2.0999999 | H8: Rt. Slot Pitch | I8: 30.045024 | J8: ES
A9: Space Fac. | B9: 0.93000001 | D9: Pitch | E9: 1 ~ 14 | F9: Cross Section Area | H9: Mean Value | I9: 26.148977 | J9: 470.55359
A10: Core Length | B10: 620 | C10: 620 | F10: UB: 400.9 | G10: UER: 2750.0 | H10: Eff.T.W.St. | I10: 13.460342 | J10: WS
A11: OD | B11: 670 | C11: 420.8 | D11: Coil Pitch | E11: 0.86658 | G11: ERT: 40.0 | H11: Eff.T.W.Rt. | I11: 30.045024 | J11: 29329.435
A12: ID | B12: 425 | C12: 220 | D12: Slot Fill | E12: - | G12: ERD1: 280.0 | H12: St.Carter Fac. | I12: 1.2098288 | J12: IS
A13: Core Depth | B13: 65.5 | C13: 67.600001 | D13: Con./Slot | E13: 18 | G13: ERD2: 420.0 | H13: Rt.Carter Fac. | I13: 1 | J13: 122.91885
A14: Eff.Core L. | B14: 455.70001 | C14: 455.70001 | D14: Wire Size 1 | E14: (.081"x.162")x1 | H14: Carter Factor | I14: 1.2098288 | J14: Volts / Turn
A15: Slot Data | D15: Wire Size 2 | E15: (.081"x.182")x1 | H15: Short. Factor | I15: 0.97811905 | J15: 22.222222
A16: Number | B16: 60 | C16: 44 | D16: // Circuits | E16: 1 | H16: Distrib. Factor | I16: 0.956506 | J16: AC
A17: Kind | B17: Open | C17: Dbl - Closed | D17: Connection | E17: Delta | H17: Wind. Factor | I17: 0.93557674 | J17: 574.05821
A18: Skew | B18: - | C18: 0 | D18: MCL | E18: 1135 | F18: 660 | H18: Reactance | I18: (Coeff.: 0.1714)
A19: Depth | B19: 57 | C19: 32.799999 | D19: No.Cond./Ph. | E19: 360 | I19: Running | J19: Start
A20: Width | B20: 8.79 - 8.79 | D20: Res. (20°C) | E20: 0.41004333 | H20: Stator Slot | I20: 19.862488 | J20: 19.862488
A21: Opening | B21: 12.7 | C21: 0 | D21: (105°C) | E21: 0.54699296 | F21: 0.55483097 | G21: 0.083090814 | H21: Rotor Slot | I21: 19.530712 | J21: 8.4279757
A22: Tip Depth | B22: 2.8299999 | C22: 0.80000001 | D22: Material | E22: CU | F22: AL | G22: AL | H22: Zigzag | I22: 7.2139072 | J22: 4.6825833
A23: T.Min.Wid. | B23: 9.5529289 | C23: 14 | D23: Spec.Resist. | E23: 1.742 | F23: 3.25 | G23: 3.25 | H23: Coil End | I23: 11.437058 | J23: Skew R.: 0.00
A24: Low. R. | B24: 0 | C24: 2 | D24: Spec.Gravity | E24: 8.8900003 | F24: 2.6700001 | G24: 2.6700001 | H24: Belt Leakage | I24: 4.8766039 | J24: 3.2380432
A25: Up. R. | B25: - | C25: 2 | D25: Weight (kg) | H25: Total Resist. | I25: 1.1849147 | J25: 1.9410701
A26: Wedge Dep. | B26: 2.83 - 2.00 | C26: Magnetic | D26: Wire 1 | E26: 88.887189 | F26: 29.201788 | G26: 17.863182 | H26: Total React. | I26: 10.787666 | J26: 8.1567497
A27: Duct | B27: 13 x 10 | C27: 13 x 10 | D27: Wire 2 | E27: 100.27667 | F27: - | G27: - | H27: Impedance | I27: 10.852547 | J27: 8.3845282
A28: Effective Depth (S=1) | D28: Magnetic Circuit Data | I28: Core Loss Data
B29: Res.= | C29: 31.991072 | E29: Length | F29: Section | G29: Density | H29: AT | I29: Volume | J29: Loss | M29: =RIGHT(F$41,SEARCH("/",F$41,1)-1) -> 1772.1 | N29: 125RPM | P29: Kline/in2
B30: Reac.= | C30: 31.997448 | D30: Primary Core | E30: 26.310816 | F30: 596.96702 | G30: 14.935629 | H30: 296.78813 | I30: 56684.739 | J30: 3851.875 | M30: =RIGHT(E$41,SEARCH("/",E$41,1)-1) -> 1776.9 | N30: 100RPM | P30: =G30*6.4516 -> 96.358704
A31: Excitation Data | D31: Tooth | E31: 5.7 | F31: 652.99047 | G31: 13.654223 | H31: 48.40328 | I31: 14888.183 | J31: 874.85923 | M31: =RIGHT(D$41,SEARCH("/",D$41,1)-1) -> 1781.6 | N31: 75RPM | P31: =G31*6.4516 -> 88.091588
A32: Excit.Amps | B32: 17.935 / 17.300 | D32: Second.Core | E32: 13.94866 | F32: 616.10642 | G32: 14.471652 | H32: 137.1667 | I32: Total | J32: 4726.7342 | M32: =RIGHT(C$41,SEARCH("/",C$41,1)-1) -> 1786.2 | N32: 50RPM | P32: =G32*6.4516 -> 93.365311
A33: Core Loss | B33: 0.712 / 0.687 | C33: Flux / Pole | D33: Tooth | E33: 3.2799999 | F33: 701.77802 | G33: 12.704983 | H33: 22.081041 | I33: C.L.C. | J33: 1.50 / 0.74 | M33: =RIGHT(B$41,SEARCH("/",B$41,1)-1) -> 1790.8 | N33: 25RPM | P33: =G33*6.4516 -> 81.967469
A34: NoLoad | B34: 31.09 / 29.99 | C34: 8.9160778 | D34: Air Gap | E34: 0.20999999 | F34: 1351.9188 | G34: 6.5951284 | H34: 1102.1305 | I34: S.F.C. | J34: 6.0500002 | P34: =G34*6.4516 -> 42.549131
A35: Load Characteristics | D35: Temp. Rise @ 100%: | E35: 72 / 69 | G35: No Load Loss | H35: 12948.3 / 8568.6 | I35: W.Loss | J35: 7090.1 / 3475.0
A36: Load (%) | B36: 25 | C36: 50 | D36: 75 | E36: 100 | F36: 125 | G36: Primary Loss | H36: 8265.0 / 8692.4 | I36: S.Loss | J36: 1462.5 / 716.8
A37: Current (A) | B37: 44.70 / 45.96 | C37: 67.51 / 69.40 | D37: 94.26 / 96.89 | E37: 122.92 / 126.36 | F37: 153.04 / 157.33 | G37: Second. Loss | H37: 8004.0 / 9948.6 | I37: Total C.Loss | J37: 8552.6 / 4191.8
A38: Efficiency | B38: 0.930 / 0.914 | C38: 0.957 / 0.941 | D38: 0.963 / 0.947 | E38: 0.964 / 0.947 | F38: 0.962 / 0.946 | G38: Frict.& Wind. | H38: 4000.0 / 3854.1 | I38: Stray Loss | J38: 14709.664 | L38: =LEFT(E38,SEARCH("/",E38,1)-1) -> 0.964 | M38: =RIGHT(E38,SEARCH("/",E38,1)-1) -> 0.947 | N38: =M38/L38 -> 0.98236515 | O38: Eff.
A39: P.F. | B39: 0.647 / 0.641 | C39: 0.833 / 0.825 | D39: 0.890 / 0.880 | E39: 0.909 / 0.899 | F39: 0.914 / 0.905 | G39: Starting Data | I39: Slip | J39: PF | L39: =LEFT(E39,SEARCH("/",E39,1)-1) -> 0.909 | M39: =RIGHT(E39,SEARCH("/",E39,1)-1) -> 0.899 | N39: =M39/L39 -> 0.9889989 | O39: PF.
A40: Slip | B40: 0.0026 / 0.0051 | C40: 0.0051 / 0.0076 | D40: 0.0077 / 0.0102 | E40: 0.0103 / 0.0129 | F40: 0.0130 / 0.0155 | G40: LRA | H40: 826.3 / 968.0 | L40: =LEFT(E37,SEARCH("/",E37,1)-1) -> 122.92 | M40: =RIGHT(E37,SEARCH("/",E37,1)-1) -> 126.36 | N40: =M40/L40 -> 1.0279857 | O40: Current
...

Sheet Data Sheet
A1: TOSHIBA INTERNATIONAL CORPORATION
A2: INDUCTION MOTOR DATA SHEET
A3: File: | B3: 1M4M20U | I3: HRW / Model Number: | J3: M205TCAL11E-A
A4: Type: TIKK - Form: FCNW4 - 4 Pole - 1000 HP - 4000 V - 60 Hz - 5812US - Class F | Q4: Motor Type Selection | T4: Electrical Steel Table
A5: Motor Parameters | F5: PERFORMANCE | J5: DESIGN | K5: TEST | Q5: EPACT | T5: M22 - 26Ga.
A6: Material | D6: M22 - 26Ga. | F6: NL & Impedance Test | Q6: EQP-III | T6: M36 - 26Ga.
A7: Air Gap | D7: 2.0999999 | F7: No load amps | J7: 30 | K7: - | M7: =O7/N7*J7 -> 31.311475 | N7: 18.3 | O7: 19.1 | Q7: Exp.Prf. | T7: NCB1 - 26Ga.
A8: Stack length | D8: 620 | F8: No load watts | J8: 8569 | K8: - | M8: =O8/N8*J8 -> 12452.676 | N8: 6948 | O8: 10097 | Q8: Exp.Prf.-EQPIII | T8: M43 - 26Ga.
A9: Number of turns per coil | D9: 9 | F9: Impedance amps | H9: 3 | I9: f | J9: 300 | K9: - | M9: =O9/N9*J9 -> 277.7551 | N9: 147 | O9: 136.1 | Q9: Prem. Eff. | T9: M45 - 26Ga.
A10: Wire 1 (size & number) | D10: (.081"x.162")x1 | F10: Impedance volts | H10: 3 | I10: f | J10: 1150 | K10: - | M10: =O10/N10*J10 -> 1150 | N10: 1150 | O10: 1150 | Q10: Standard Eff. | T10: M54 - 26Ga.
A11: Wire 2 (size & number) | D11: (.081"x.182")x1 | F11: Impedance watts | H11: 3 | I11: f | J11: 29329 | K11: - | M11: =O11/N11*J11 -> 53634.303 | N11: 26365 | O11: 48214 | Q11: OWP | T11: TIPA Lam
A12: Slot fill - circle/square method (%) | D12: - | F12: Temperature Rise (°C) | Q12: Dry Kiln
A13: Connection | D13: 1 x Delta | G13: Winding | I13: 80/115 | J13: 72 / 95 | K13: -
A14: MCL | D14: 1135 | G14: Frame | J14: - | K14: -
A15: Allowance for ins. depth | D15: 13.5368 | G15: Bearing PS/OS | J15: - | K15: -
A16: Allowance for ins. width | D16: 3.5623999 | G16: End Ring | J16: - | K16: -
A17: Slot/Wire arrangement | D17: 18 x 2 | F17: Nameplate Data
A18: Effective cross section for coil | D18: - | H18: FLC (A) | J18: 126
A19: Coil grouping | D19: - | H19: RPM | J19: 1777
A20: Coil pitch (slot number) | D20: 1 ~ 14 | H20: CODE | J20: H
A21: Method of coil connection | D21: - | H21: S. F. | J21: 1.15 | Q21: Method of Connection
A22: Resistance per phase @ 20 °C | D22: 0.41 | H22: DESIGN | J22: - | Q22: Skip
A23: Coil Weight | B23: Wire1 | D23: 195.6 | H23: Nom.Eff. (%): | J23: 94.5 | Q23: Adjacent
A24: (lbs.) | B24: Wire2 | D24: 220.6 | H24: Min.Eff. (%): | J24: - | Q24: -
A25: Current Densities (A/cm2) | E25: Bar / ER | H25: P.F. (%): | J25: 89.5
A26: FL / LR | D26: 420 / 3227 | E26: 381 / 195
A27: Stator Slot Shape (Reference) | F27: Performance
H28: LRC (A) | I28: - | J28: 968 | K28: - | M28: =J28/J18 -> 7.6825397
H29: LRT (%) | I29: 60 | J29: 169 | K29: -
H30: BDT (%) | I30: 175 | J30: 267 | K30: -
H31: SLIP (%) | J31: 1.29 | K31: -
G32: IEEE-B | H32: Eff. (%) | J32: 94.7 | K32: -
A33: Rotor Slot Shape (Reference) | H33: PF (%) | J33: 89.9 | K33: -
F34: Losses (Watts) | H34: Primary | J34: 8692 | K34: -
H35: Secondary | J35: 9949 | K35: -
H36: Core | J36: 4192 | K36: -
H37: F & W | J37: 3854 | K37: -
H38: Stray | J38: 14710 | K38: -
A39: End Ring (Reference) | F39: Note | G39: TOP HAT TEAAC A/F BEARING
F40: LINK: | G40: AM4900G.rat & LAB 7930.dat
...

Sheet LoginSheet
J1: P | K1: T | L1: L | M1: T
B2: PROJECT HISTORY | J2: E | K2: D | L2: I | M2: Y | N2: H
J3: R | L3: M | M3: P
J4: F | L4: I | M4: E
K5: C | L5: T | N5: I
J6: D | K6: U | M6: T | N6: N
J7: A | K7: R | L7: R | M7: E | N7: S
I8: S | J8: T | K8: V | L8: E | M8: S | N8: U
B9: DATE | C9: PROJECT | D9: SMART NUMBER | E9: QTY | F9: CUSTOMER | G9: REMARKS | H9: LIMIT CODE | I9: F | J9: A | K9: E | L9: V | M9: T | N9: L
B53: REVISION HISTORY
B54: REV | C54: REMARKS | I54: DATE | L54: INIT

Sheet StallTime
A1: Rating: | B1: 4 Pole - 1000.0 HP - 1800 RPM - 4000 V - 60 Hz
A3: Starting Performance
D4: Load Type: Fan / Pump - 3393.3 lb-ft²
A5: RPM | B5: Motor | C5: Load | D5: Accel. | E5: Line | F5: Stator | G5: Rotor
A6: Speed Increment | B6: Torque (%) | C6: Torque (%) | D6: Time (s) | E6: Amps | F6: kW / s | G6: kW / s
A7: 0~188 | B7: 165.0 | C7: 22.3 | D7: 0.543 | E7: 964.2 | F7: 278.3 | G7: 598.6
A8: 188~376 | B8: 165.0 | C8: 11.3 | D8: 0.504 | E8: 956.1 | F8: 254.1 | G8: 497.5
A9: 376~564 | B9: 165.1 | C9: 7.0 | D9: 0.490 | E9: 947.1 | F9: 243.0 | G9: 427.8
A10: 564~752 | B10: 165.1 | C10: 7.7 | D10: 0.492 | E10: 937.1 | F10: 239.1 | G10: 372.9
A11: 752~940 | B11: 165.3 | C11: 12.4 | D11: 0.507 | E11: 925.3 | F11: 240.8 | G11: 325.7
A12: 940~1128 | B12: 166.2 | C12: 20.4 | D12: 0.531 | E12: 911.1 | F12: 245.3 | G12: 280.4
A13: 1128~1316 | B13: 169.9 | C13: 31.6 | D13: 0.560 | E13: 892.2 | F13: 250.0 | G13: 233.5
A14: 1316~1504 | B14: 181.2 | C14: 48.1 | D14: 0.582 | E14: 859.8 | F14: 247.0 | G14: 180.5
A15: 1504~1598 | B15: 201.7 | C15: 64.3 | D15: 0.282 | E15: 816.2 | F15: 108.5 | G15: 117.7
A16: 1598~1692 | B16: 239.3 | C16: 77.6 | D16: 0.240 | E16: 747.7 | F16: 82.6 | G16: 76.7
... A18: 1746~1781 | B18: 172.4 | C18: 95.7 | D18: 0.190 | E18: 301.5 | F18: 1.7 | G18: 17.0
D21: Acceleration Time: 5.1 s
B22: Energy | D22: First Start | F22: Second Start
A23: Stator Winding Rise | B23: 2226 kW / s | D23: 31°C | F23: 61°C
A24: Rotor Bar Rise | B24: 2764 kW / s | D24: 106°C | F24: 211°C
A25: End Ring Rise | B25: 414 kW / s | D25: 26°C | F25: 52°C
A27: Locked Rotor Thermal Capability
E28: Cold Condition
B29: Rate of Rise | D29: Power | E29: Rise Limit | F29: Max Time
A30: Stator Copper | B30: 8.3°C / s | D30: 605.4 kW | E30: 160°C | F30: 19.2 s
A31: Rotor Bar | B31: 40.9°C / s | D31: 1070.6 kW | E31: 260°C | F31: 6.4 s
A32: Rotor ER | B32: 10.0°C / s | D32: 160.3 kW | E32: 180°C | F32: 18.0 s
E34: Hot Condition
B35: Hot Temp. | D35: Rise Limit | E35: Ambient | F35: Total | G35: Max.Time
A36: Stator Copper | B36: 72°C + | D36: 88°C + | E36: 40°C | F36: = 200°C | G36: 10.6 s
A37: Rotor Bar | B37: 97°C + | D37: 163°C + | E37: 40°C | F37: = 300°C | G37: 4.0 s
A38: Rotor ER | B38: 97°C + | D38: 83°C + | E38: 40°C | F38: = 220°C | G38: 8.3 s
A40: Cold Stall Time: | B40: 8.6 s | D40: Hot Stall Time: | F40: 4.0 s

Sheet Performance Data Sheet
A1: TOSHIBA INTERNATIONAL CORPORATION | J1: INDEX | L1: MPCF-1033
A2: Industrial Division / Houston Motor Plant | J2: SHEET NO. | L2: 1 of 1
J3: ISSUED | L3: 7/31/13
J4: SUPERSEDES | L4: 11/8/96
J5: REVISION | L5: 2
A6: SQUIRREL CAGE INDUCTION MOTOR | J6: WRITTEN BY | L6: MDC
A7: PERFORMANCE SPECIFICATIONS | J7: APPROVED BY | L7: PAA
B9: CUSTOMER: | C9: -
B10: TIC SR No.: | C10: -
A12: MOTOR NAMEPLATE DATA
B13: H.P.: | C13: 1000 | E13: VOLTS: | F13: 4000 | H13: 3 PH / | I13: 60 Hz | L13: S. RPM: | M13: 1800
B14: FRAME: | C14: 5812US | E14: ENCL: | F14: TEAAC | H14: FLAMPS: | I14: 126 | L14: FLRPM: | M14: 1777
B15: FORM: | C15: FCNW4 | E15: S.F.: | F15: 1.15 | H15: NEMA DESIGN: | I15: - | L15: INSUL CLASS: | M15: F
B16: TYPE: | C16: TIKK | E16: AMB.: | F16: 40°C | H16: CODE: | I16: H | L16: DUTY: | M16: Cont.
B17: MODEL No.: | C17: M205TCAL11E-A | H17: kW: | I17: -
B18: NOM. EFF.: | C18: - | E18: MIN. EFF.: | F18: - | H18: P.F.: | I18: -
A21: AMPERAGE | E21: TORQUES | I21: **BEARINGS:
C22: LOCKED ROTOR: | D22: 968 | G22: FULL LOAD (lb-ft.): | H22: 2956 | K22: DRIVE END: | L22: REFER TO NP
G23: LOCKED ROTOR (%): | H23: 165 | K23: OPPOSITE DRIVE END: | L23: REFER TO NP
G24: BREAK DOWN (%): | H24: 265
A28: EFFICIENCY | H28: POWER FACTOR
C29: FULL LOAD: | D29: 94.7 | J29: FULL LOAD: | K29: 89.9
C30: 3/4 LOAD: | D30: 94.6 | J30: 3/4 LOAD: | K30: 88
C31: 1/2 LOAD: | D31: 94 | J31: 1/2 LOAD: | K31: 82.4
A35: ALL CHARACTERISTICS ARE AVERAGE EXPECTED VALUES BASED UPON RATED VOLTAGE,
A36: FREQUENCY AND SINEWAVE POWER INPUT.
A37: THE DECLARED LOCKED ROTOR CURRENT HAS A TOLERANCE OF 20%.
A38: * TEMPERATURE RISE WILL BE CONSISTENT WITH INSULATION, AMBIENT AND SERVICE FACTOR AS
A39: DEFINED BY NEMA-MG-12 OR -20.
A40: ** BEARINGS ARE THE ONLY RECOMMENDED SPARE PART(S).
J42: CERTIFIED BY: | K42: Zichao Xie
J44: DATE: | K44: 44676
A59: - | B59: 6205ZZ | D59: 1 | E59: -
A60: TEFC | B60: 6206UU | D60: 1.15 | E60: A
A61: ODP | B61: 6207ZZ | E61: B
B62: 6208UU
B63: 6211ZZ
B64: 6211C3
B65: 6211ZZC3
B66: 6305UUC3
...

Sheet STCurve
A2: TOSHIBA INTERNATIONAL CORPORATION
A3: Speed Torque/Current Curve
A6: Model #: | B6: ='Performance Data Sheet'!C17 -> M205TCAL11E-A | E6: FLAmps: | F6: ='Performance Data Sheet'!I14 -> 126
A7: Enclosure: | B7: ='Performance Data Sheet'!F14 -> TEAAC | C7: Voltage: | D7: ='Performance Data Sheet'!F13 & " V" -> 4000 V | E7: Frame: | F7: ='Performance Data Sheet'!C14 -> 5812US
A8: Pole: | B8: 4 | C8: Frequency: | D8: 3 PH / 60 Hz | E8: Ins. Class: | F8: ='Performance Data Sheet'!M15 -> F
A9: HP: | B9: ='Performance Data Sheet'!C13 -> 1000 | C9: Rotor Inertia: | D9: 346.3 lb-ft² | E9: Date: | F9: ='Performance Data Sheet'!K44 -> 44676
A10: FLRPM: | B10: ='Performance Data Sheet'!M14 -> 1777 | C10: Load Inertia: | D10: 3393.3 lb-ft² | E10: File: | F10: 1M4M20U
B12: Locked Rotor Amps: | C12: ='Performance Data Sheet'!D22 & " A" -> 968 A | D12: Load Type: | E12: Fan / Pump | I12: Note: this is AL rotor design but ST curve is not typical. | O12: Z.X 04/25/22
B13: Locked Rotor Torque: | C13: ='Performance Data Sheet'!H23/100 -> 1.65 | D13: Starting at: | E13: FV | I13: Neither DesPro calculation nor lab 7930 (correlated testing) displays any indication of pull up torque.
B14: Breakdown Torque: | C14: 2.65 | D14: Accel. Time: | E14: 5.1 (s)
B15: Rated Torque: | C15: ='Performance Data Sheet'!H22 & " lb-ft" -> 2956 lb-ft
A39: Comments: | B39: PROJECT | C39: ='Performance Data Sheet'!C10 -> - | E39: D.E.Curve #: | F39: =F10 -> 1M4M20U
C43: Prepared by: | D43: ='Performance Data Sheet'!K42 -> Zichao Xie | E43: Checked by:
D53: Load
A54: 100 | B54: 0 | C54: 0.24673161 | D54: 100
A55: 99.4 | B55: 70.315588 | C55: 96.301247 | D55: 98.800003
A56: 97 | B56: 244.73875 | C56: 382.33292 | D56: 92.5
A57: 94 | B57: 265 | C57: 556.77197 | D57: 84.400002
A58: 88.777778 | B58: 213.54896 | C58: 630.03052 | D58: 70.82222
A59: 83.555555 | B59: 189.7774 | C59: 665.52673 | D59: 57.822224
A60: 73.111111 | B60: 172.72154 | C60: 699.29321 | D60: 38.288887
A61: 62.666667 | B61: 167.04757 | C61: 716.86884 | D61: 24.933332
A62: 52.222222 | B62: 165.41161 | C62: 729.28705 | D62: 15.777778
A63: 41.777778 | B63: 165.1142 | C63: 739.49567 | D63: 9.0666666
A64: 31.333333 | B64: 165.08511 | C64: 747.92578 | D64: 6.2666664
A65: 20.888889 | B65: 165.04685 | C65: 755.43146 | D65: 7.8222222
... A67: 0 | B67: 165 | C67: 768.25397 | D67: 30

Sheet Thermdam
A2: TOSHIBA INTERNATIONAL CORPORATION
A3: Thermal Limit & Acceleration Curves
A4: Design Values (For Reference Only)
A6: Model #: | B6: ='Performance Data Sheet'!C17 -> M205TCAL11E-A | E6: FLAmps: | F6: ='Performance Data Sheet'!I14 -> 126
A7: Enclosure: | B7: ='Performance Data Sheet'!F14 -> TEAAC | C7: Voltage: | D7: ='Performance Data Sheet'!F13 & " V" -> 4000 V | E7: Frame: | F7: ='Performance Data Sheet'!C14 -> 5812US
A8: Pole: | B8: 4 | C8: Frequency: | D8: 3 PH / 60 Hz | E8: Ins. Class: | F8: ='Performance Data Sheet'!M15 -> F
A9: HP: | B9: ='Performance Data Sheet'!C13 -> 1000 | C9: Rotor Inertia: | D9: 346.3 lb-ft² | E9: Date: | F9: ='Performance Data Sheet'!K44 -> 44676
A10: FLRPM: | B10: ='Performance Data Sheet'!M14 -> 1777 | C10: Load Inertia: | D10: 3393.3 lb-ft² | E10: File: | F10: 1M4M20U
C12: ='Performance Data Sheet'!D22 & " A" -> 968 A
C13: ='Performance Data Sheet'!H23/100 -> 1.65
C15: ='Performance Data Sheet'!H22 & " lb-ft" -> 2956 lb-ft
A39: Comments: | B39: PROJECT | C39: ='Performance Data Sheet'!C10 -> - | E39: D.E.Curve #: | F39: =F10 -> 1M4M20U
C43: Prepared by: | D43: ='Performance Data Sheet'!K42 -> Zichao Xie | E43: Checked by:
F50: =5252.1*B50/D53 -> #DIV/0!
D66: =D65/D64 -> #DIV/0!
A67: Current (%) | B67: Cold | C67: Hot | E67: CURRENT (%) | F67: Accel. Time
A68: 768.25397 | B68: 12.307299 | C68: 5.6878383 | E68: =A68 -> 768.25397 | F68: 0.0001
A69: =FLOOR(A68,100) -> 700 | B69: =((A68/A69)^2)*B68 -> 14.824372 | C69: =((A68/A69)^2)*C68 -> 6.8511075 | E69: 765.2381 | F69: 0.54299998
A70: =A69-100 -> 600 | B70: =((A68/A70)^2)*B68 -> 20.177617 | C70: =((A68/A70)^2)*C68 -> 9.3251186 | E70: 758.80952 | F70: 1.0469999
A71: =A70-100 -> 500 | B71: =((A68/A71)^2)*B68 -> 29.055769 | C71: =((A68/A71)^2)*C68 -> 13.428171 | E71: 751.66667 | F71: 1.5369999
A72: =A71-100 -> 400 | B72: =((A68/A72)^2)*B68 -> 45.399639 | E72: 743.73016 | F72: 2.029
A73: =A72-100 -> 300 | B73: =((A68/A73)^2)*B68 -> 80.71047 | E73: 734.36508 | F73: 2.536
A74: 265 | B74: =((A68/A74)^2)*B68 -> 103.43812 | C74: =((A68/A74)^2)*C68 -> 47.804097 | E74: 723.09524 | F74: 3.0669999
A75: 180 | B75: =((A68/A75)^2)*B69 -> 270.04797 | C75: =((A68/A75)^2)*C68 -> 103.61243 | E75: 708.09524 | F75: 3.6269999
A76: 145 | B76: =((A68/A76)^2)*B68 -> 345.49071 | C76: =((A68/A76)^2)*C68 -> 159.66909 | E76: 682.38095 | F76: 4.2089996
A77: 125 | C77: =CEILING(C76*2,100) -> 400 | E77: 647.77778 | F77: 4.4909997
A78: 125 | C78: =2*C77 -> 800 | E78: 593.4127 | F78: 4.7309995
A79: 125 | C79: 10000 | E79: 469.52381 | F79: 4.8649993
E80: 238.60399 | F80: 5.0549994

Sheet Performance
A2: TOSHIBA INTERNATIONAL CORPORATION
A3: Performance Curve
A4: Design Values (For Reference Only)
A6: Model #: | B6: ='Performance Data Sheet'!C17 -> M205TCAL11E-A | E6: FLAmps: | F6: ='Performance Data Sheet'!I14 -> 126
A7: Enclosure: | B7: ='Performance Data Sheet'!F14 -> TEAAC | C7: Voltage: | D7: ='Performance Data Sheet'!F13 & " V" -> 4000 V | E7: Frame: | F7: ='Performance Data Sheet'!C14 -> 5812US
A8: Pole: | B8: 4 | C8: Frequency: | D8: 3 PH / 60 Hz | E8: Ins. Class: | F8: ='Performance Data Sheet'!M15 -> F
A9: HP: | B9: ='Performance Data Sheet'!C13 -> 1000 | C9: Rotor Inertia: | D9: 346.3 lb-ft² | E9: Date: | F9: ='Performance Data Sheet'!K44 -> 44676
A10: FLRPM: | B10: ='Performance Data Sheet'!M14 -> 1777 | C10: Load Inertia: | D10: 3393.3 lb-ft² | E10: File: | F10: 1M4M20U
B12: Locked Rotor Amps: | C12: ='Performance Data Sheet'!D22 & " A" -> 968 A | D12: Load Type: | E12: Fan / Pump
B13: Locked Rotor Torque: | C13: ='Performance Data Sheet'!H23/100 -> 1.65 | D13: Starting at: | E13: FV
B14: Breakdown Torque: | C14: 2.65 | D14: Accel. Time: | E14: 5.1 (s)
B15: Rated Torque: | C15: ='Performance Data Sheet'!H22 & " lb-ft" -> 2956 lb-ft
N36: SPEED | O36: KW
N37: =L43 - (L43-L44) / 10 * 0 -> 1800 | O37: =L45 / 10 * 10 -> 2000
N38: =L43 - (L43-L44) / 10 * 1 -> 1797 | O38: =L45 / 10 * 9 -> 1800
A39: Comments: | B39: PROJECT | C39: ='Performance Data Sheet'!C10 -> - | E39: D.E.Curve #: | F39: =F10 -> 1M4M20U | N39: =L43 - (L43-L44) / 10 * 2 -> 1794 | O39: =L45 / 10 * 8 -> 1600
N40: =L43 - (L43-L44) / 10 * 3 -> 1791 | O40: =L45 / 10 * 7 -> 1400
N41: =L43 - (L43-L44) / 10 * 4 -> 1788 | O41: =L45 / 10 * 6 -> 1200
N42: =L43 - (L43-L44) / 10 * 5 -> 1785 | O42: =L45 / 10 * 5 -> 1000
C43: Prepared by: | D43: ='Performance Data Sheet'!K42 -> Zichao Xie | E43: Checked by: | K43: SYNC SPEED | L43: 1800 | N43: =L43 - (L43-L44) / 10 * 6 -> 1782 | O43: =L45 / 10 * 4 -> 800
K44: NEW SPEED LOWER RANGE | L44: 1770 | N44: =L43 - (L43-L44) / 10 * 7 -> 1779 | O44: =L45 / 10 * 3 -> 600
K45: NEW kW UPPER RANGE | L45: 2000 | N45: =L43 - (L43-L44) / 10 * 8 -> 1776 | O45: =L45 / 10 * 2 -> 400
N46: =L43 - (L43-L44) / 10 * 9 -> 1773 | O46: =L45 / 10 * 1 -> 200
N47: =L43 - (L43-L44) / 10 * 10 -> 1770 | O47: =L45 / 10 * 0 -> 0
A52: ADJUSTED
A53: Load | B53: Efficiency | C53: PF | D53: Amps | E53: RPM | F53: Input Watts
A54: 0 | D54: 30 | E54: 100 | F54: =8569/(L45*1000) * 100 -> 0.42845
A55: 25 | B55: 91.399994 | C55: 64.099998 | D55: 45.959999 | E55: =(1.00974220013981*B10-L44)/(L43-L44)*100 -> 81.039632 | F55: =204107.3/(L45*1000)*100 -> 10.205365
A56: 50 | B56: 94.099998 | C56: 82.5 | D56: 69.400002 | E56: =(1.00654116895136*B10-L44)/(L43-L44)*100 -> 62.078857 | F56: =396674.3/(L45*1000)*100 -> 19.833715
A57: 75 | B57: 94.700005 | C57: 88 | D57: 96.889999 | E57: =(1.00334013776291*B10-L44)/(L43-L44)*100 -> 43.118083 | F57: =590720.8/(L45*1000)*100 -> 29.53604
A58: 100 | B58: 94.700005 | C58: 89.900002 | D58: 126.36 | E58: =(1*B10-L44)/(L43-L44)*100 -> 23.333333 | F58: =787027.5/(L45*1000)*100 -> 39.351375
A59: 125 | B59: 94.599998 | C59: 90.5 | D59: 157.33 | E59: =(0.996729381177019*B10-L44)/(L43-L44)*100 -> 3.9603678 | F59: =986462.9/(L45*1000)*100 -> 49.323145
A62: ORIGINAL
A63: Load | B63: Efficiency | C63: PF | D63: Amps | E63: RPM | F63: Input Watts
A64: 0 | D64: 31.958652 | E64: 100 | F64: 13.164425
A65: 25 | B65: 91.363091 | C65: 64.032677 | D65: 45.956451 | E65: 69.626744 | F65: 10.193563
A66: 50 | B66: 94.02092 | C66: 82.409798 | D66: 69.397781 | E66: 54.530996 | F66: 19.810814
A67: 75 | B67: 94.622643 | C67: 87.972618 | D67: 96.89415 | E67: 39.074643 | F67: 29.527247
A68: 100 | B68: 94.677879 | C68: 89.891525 | D68: 126.36058 | E68: 23.272124 | F68: 39.346693
A69: 125 | B69: 94.509926 | C69: 90.408096 | D69: 157.32735 | E69: 7.4602051 | F69: 49.270775

Sheet Sheet1
B2: SERNUM | C2: NLVA | D2: NLVB | E2: NLVC | F2: NLAA | G2: NLAB | H2: NLAC | I2: NLWR | J2: PFN | K2: VARN | L2: LRVA | M2: LRVB | N2: LRVC | O2: LRAA1 | P2: LRAA2 | Q2: LRAA3 | R2: LRWAVG | S2: PFL | T2: VARL | U2: LRSWINGMIN | V2: LRSWINGMAX
B3: 90103485 | C3: 4009 | D3: 4008 | E3: 4028 | F3: 28.58 | G3: 30.84 | H3: 30.29 | I3: 15812.91 | J3: 0.076 | K3: 207500 | L3: 1120 | M3: 1126 | N3: 1127 | O3: 194.4 | P3: 195.4 | Q3: 195.1 | R3: 71000 | S3: 0.19 | T3: 371000 | U3: 196.1 | V3: 194.8
B4: 90103484 | C4: 4065 | D4: 4064 | E4: 4084 | F4: 29.19 | G4: 31.26 | H4: 30.96 | I4: 13991.76 | J4: 0.068 | K4: 214000 | L4: 1110 | M4: 1116 | N4: 1117 | O4: 192.1 | P4: 193 | Q4: 192.9 | R4: 69000 | S4: 0.189 | T4: 366000 | U4: 193.4 | V4: 193
B5: 90103483 | C5: 4005 | D5: 3999 | E5: 4024 | F5: 28.57 | G5: 30.9 | H5: 30.14 | I5: 15928.24 | J5: 0.077 | K5: 206600 | L5: 1130 | M5: 1132 | N5: 1137 | O5: 198.1 | P5: 199.5 | Q5: 198.9 | R5: 73000 | S5: 0.19 | T5: 384000 | U5: 198.2 | V5: 198.2
B6: 71000920 | C6: 4015 | D6: 4012 | E6: 4032 | F6: 29.57 | G6: 30.55 | H6: 30.77 | I6: 14987.38 | J6: 0.072 | K6: 208500 | L6: 1127.2 | M6: 1131.2 | N6: 1133.7 | O6: 194 | P6: 193.6 | Q6: 193.8 | R6: 67700 | S6: 0.18 | T6: 372900 | U6: 193.5 | V6: 193.8
B7: 71000919 | C7: 4036 | D7: 4035 | E7: 4055 | F7: 29.23 | G7: 30.15 | H7: 30.63 | I7: 15149.56 | J7: 0.075 | K7: 208700 | L7: 1132.4 | M7: 1138.9 | N7: 1138.8 | O7: 194.4 | P7: 194.1 | Q7: 194.4 | R7: 68800 | S7: 0.182 | T7: 376000 | U7: 194.2 | V7: 194.6
B8: 70503158 | C8: 3982 | D8: 3992 | E8: 4010 | F8: 29.14 | G8: 30.92 | H8: 31.73 | I8: 14744.2 | J8: 0.07 | K8: 211400 | L8: 1099.7 | M8: 1109.9 | N8: 1110.4 | O8: 191.8 | P8: 191.4 | Q8: 193 | R8: 68900 | S8: 0.189 | T8: 362300 | U8: 191.4 | V8: 192.2
B9: 61202320 | C9: 4014 | D9: 4038 | E9: 4036 | F9: 29.23 | G9: 30.07 | H9: 30.93 | I9: 14179.37 | J9: 0.069 | K9: 208900 | L9: 1139.2 | M9: 1151.4 | N9: 1145 | O9: 196 | P9: 196 | Q9: 196.3 | R9: 72300 | S9: 0.188 | T9: 381900 | U9: 195.7 | V9: 196
B10: 61202319 | C10: 4050 | D10: 4070 | E10: 4069 | F10: 29.65 | G10: 30.73 | H10: 31.24 | I10: 14240.65 | J10: 0.069 | K10: 211600 | L10: 1116.8 | M10: 1126.1 | N10: 1120.6 | O10: 191.4 | P10: 190.8 | Q10: 191.8 | R10: 68100 | S10: 0.185 | T10: 364400 | U10: 190.5 | V10: 191.2
B11: 61202318 | C11: 4053 | D11: 4067 | E11: 4071 | F11: 29.92 | G11: 31.56 | H11: 31.56 | I11: 12865.4 | J11: 0.063 | K11: 218100 | L11: 1138.6 | M11: 1148.9 | N11: 1144.6 | O11: 197.9 | P11: 197.5 | Q11: 197.3 | R11: 72300 | S11: 0.185 | T11: 384300 | U11: 197.5 | V11: 197.9
B12: 61202318 | C12: 4041 | D12: 4061 | E12: 4059 | F12: 29.43 | G12: 30.5 | H12: 31.18 | I12: 14570.32 | J12: 0.07 | K12: 211500 | L12: 1136.8 | M12: 1149.2 | N12: 1143.7 | O12: 197.7 | P12: 196.7 | Q12: 197.3 | R12: 72000 | S12: 0.186 | T12: 382200 | U12: 195.3 | V12: 197
C14: Normalized QC test data
C15: 4000 | D15: 4000 | E15: 4000 | F15: 28.515839 | G15: 30.778443 | H15: 30.079444 | I15: 15694.977 | L15: 1150 | M15: 1150 | N15: 1150 | O15: 199.60714 | P15: 199.56483 | Q15: 199.08163 | R15: 74278.62
C16: 4000 | D16: 4000 | E16: 4000 | F16: 28.723247 | G16: 30.767717 | H16: 30.323213 | I16: 13507.971 | L16: 1150 | M16: 1150 | N16: 1150 | O16: 199.02252 | P16: 198.87993 | Q16: 198.59893 | R16: 73487.673
C17: 4000 | D17: 4000 | E17: 4000 | F17: 28.534332 | G17: 30.907727 | H17: 29.960239 | I17: 15854.168 | L17: 1150 | M17: 1150 | N17: 1150 | O17: 201.60619 | P17: 202.67226 | Q17: 201.17414 | R17: 75207.079
C18: 4000 | D18: 4000 | E18: 4000 | F18: 29.459527 | G18: 30.458624 | H18: 30.525794 | I18: 14841.083 | L18: 1150 | M18: 1150 | N18: 1150 | O18: 197.92406 | P18: 196.81754 | Q18: 196.5864 | R18: 70030.883
C19: 4000 | D19: 4000 | E19: 4000 | F19: 28.969277 | G19: 29.888476 | H19: 30.21455 | I19: 14836.361 | L19: 1150 | M19: 1150 | N19: 1150 | O19: 197.42141 | P19: 195.99175 | Q19: 196.31191 | R19: 70419.419
C20: 4000 | D20: 4000 | E20: 4000 | F20: 29.271723 | G20: 30.981964 | H20: 31.650873 | I20: 14783.596 | L20: 1150 | M20: 1150 | N20: 1150 | O20: 200.57288 | P20: 198.31516 | Q20: 199.88293 | R20: 74401.429
C21: 4000 | D21: 4000 | E21: 4000 | F21: 29.128052 | G21: 29.787023 | H21: 30.654113 | I21: 13973.672 | L21: 1150 | M21: 1150 | N21: 1150 | O21: 197.85815 | P21: 195.76168 | Q21: 197.15721 | R21: 72907.354
C22: 4000 | D22: 4000 | E22: 4000 | F22: 29.283951 | G22: 30.201474 | H22: 30.710248 | I22: 13802.449 | L22: 1150 | M22: 1150 | N22: 1150 | O22: 197.0899 | P22: 194.84948 | Q22: 196.83205 | R22: 71647.736
C23: 4000 | D23: 4000 | E23: 4000 | F23: 29.528744 | G23: 31.040079 | H23: 31.00958 | I23: 12465.425 | L23: 1150 | M23: 1150 | N23: 1150 | O23: 199.88143 | P23: 197.68909 | Q23: 198.23082 | R23: 73056.124
C24: 4000 | D24: 4000 | E24: 4000 | F24: 29.131403 | G24: 30.041862 | H24: 30.72678 | I24: 14187.079 | L24: 1150 | M24: 1150 | N24: 1150 | O24: 199.9956 | P24: 196.83693 | Q24: 198.38681 | R24: 72854.849
E26: NLV | H26: NLA | I26: NLW | N26: LRV | Q26: LRA | R26: LRW
E27: 4000 | H27: 30.041811 | I27: 14394.678 | N27: 1150 | Q27: 198.22428 | R27: 72829.117
