Workbook
Name Print_Area_MI: 'Performance Data Sheet'!$A$10:$N$42

Sheet DesignSheet
A1: TOSHIBA INTERNATIONAL CORPORATION | I1: Calc. Code: | J1: 2-2-2-0-1-2
A2: 3-PHASE SQUIRREL CAGE INDUCTION MOTOR DESIGN SHEET | J2: B.L.-1 P.F.-1
A3: File: | B3: M:\Active Projects\6800 Frame TEFC\Electrical Design\6P\SERIES DESIGN\CS6M20U.rat | G3: Date: | H3: 41899 | I3: Time: | J3: 0.57853009
A4: Pole | B4: HP | C4: RPM | D4: Form | E4: Voltage | F4: Frequency | G4: Temperature | H4: FLSpeed | I4: FLSlip | J4: Frame
A5: 6 | B5: 1000 | C5: 1200 | D5: FCW4 | E5: 4000 | F5: 60 | G5: 105 | H5: 1192.8 / 1191.4 | I5: 0.0060 / 0.0072 | J5: 6811US
A6: Core Data | D6: Winding Data | H6: Constant Data
B7: Primary | C7: Secondary | F7: Bar | G7: End Ring | H7: St. Slot Pitch | I7: 23.169226 | J7: LR Test Data
A8: Air Gap | B8: 2.0999999 | H8: Rt. Slot Pitch | I8: 28.534304 | J8: ES
A9: Space Fac. | B9: 0.93000001 | D9: Pitch | E9: 1 ~ 11 | F9: Cross Section Area | H9: Mean Value | I9: 25.851765 | J9: 813.41609
A10: Core Length | B10: 910 | C10: 910 | F10: UB: 420.0 | G10: UER: 1500.0 | H10: Eff.T.W.St. | I10: 13.501985 | J10: WS
A11: OD | B11: 770 | C11: 526.8 | D11: Coil Pitch | E11: 0.83325 | H11: Eff.T.W.Rt. | I11: 27.695073 | J11: 24138.105
A12: ID | B12: 531 | C12: 200 | D12: Slot Fill | E12: - | F12: EBL: 50.5 | G12: ERD1: 426.8 | H12: St.Carter Fac. | I12: 1.2383659 | J12: IS
A13: Core Depth | B13: 57.5 | C13: 124.85 | D13: Con./Slot | E13: 17 | G13: ERT: 30.00 | H13: Rt.Carter Fac. | I13: 1.0303025 | J13: 123.87341
A14: Eff.Core L. | B14: 846.29999 | C14: 846.29999 | D14: Wire Size 1 | E14: (.102"x.204")x2 | F14: (12 x 35) | G14: ERH: 50.00 | H14: Carter Factor | I14: 1.2758915 | J14: Volts / Turn
A15: Slot Data | D15: Wire Size 2 | E15: - | H15: Short. Factor | I15: 0.96589165 | J15: 22.64185
A16: Number | B16: 72 | C16: 58 | D16: // Circuits | E16: 2 | H16: Distrib. Factor | I16: 0.95749474 | J16: AC
A17: Kind | B17: Open | C17: Rectang | D17: Connection | E17: Wye | H17: Wind. Factor | I17: 0.92483618 | J17: 454.44934
A18: Skew | B18: - | C18: 0 | D18: MCL | E18: 1457 | F18: 1041 | H18: Reactance | I18: (Coeff.: 0.0828)
A19: Depth | B19: 62 | C19: 38.549999 | D19: No.Cond./Ph. | E19: 204 | I19: Running | J19: Start
A20: Width | B20: 9.67 - 9.67 | C20: 12.05 | D20: Res. (20°C) | E20: 0.098694801 | H20: Stator Slot | I20: 17.994585 | J20: 17.994585
A21: Opening | B21: 14.2 | C21: 3.5 | D21: (105°C) | E21: 0.1316577 | F21: 0.10704713 | G21: 0.014577153 | H21: Rotor Slot | I21: 19.290695 | J21: 13.827546
A22: Tip Depth | B22: 2.8299999 | C22: 3.5 | D22: Material | E22: CU | F22: Special | G22: Special | H22: Zigzag | I22: 5.7038312 | J22: 5.1596999
A23: T.Min.Wid. | B23: 8.9692268 | C23: 12.313919 | D23: Spec.Resist. | E23: 1.742 | F23: 1.724 | G23: 1.724 | H23: Coil End | I23: 5.1614134 | J23: Skew R.: 0.00
A24: Low. R. | B24: 0 | C24: 0.80000001 | D24: Spec.Gravity | E24: 8.8900003 | F24: 8.8900003 | G24: 8.8900003 | H24: Belt Leakage | I24: 3.5214855 | J24: 3.2578794
A25: Up. R. | B25: - | C25: 0.80000001 | D25: Weight (kg) | H25: Total Resist. | I25: 0.25328198 | J25: 0.52435541
A26: Wedge Dep. | B26: 0.80 - 3.20 | C26: Magnetic | D26: Wire 1 | E26: 415.8688 | F26: 231.9362 | G26: 40.615365 | H26: Total React. | I26: 4.2802992 | J26: 3.7548525
A27: Duct | B27: - | C27: - | D27: Wire 2 | E27: - | F27: - | G27: - | H27: Impedance | I27: 4.2877865 | J27: 3.7912881
A28: Effective Depth (S=1) | D28: Magnetic Circuit Data | I28: Core Loss Data
B29: Res.= | C29: 35.000968 | E29: Length | F29: Section | G29: Density | H29: AT | I29: Volume | J29: Loss
B30: Reac.= | C30: 35.035971 | D30: Primary Core | E30: 20.158536 | F30: 973.24499 | G30: 9.4425808 | H30: 70.428996 | I30: 108924.75 | J30: 3521.5791
A31: Excitation Data | D31: Tooth | E31: 6.2 | F31: 910.87879 | G31: 10.089097 | H31: 25.080404 | I31: 33884.691 | J31: 1219.5741
A32: Excit.Amps | B32: 26.740 / 31.968 | D32: Second.Core | E32: 11.773109 | F32: 2113.2111 | G32: 4.3488057 | H32: 12.085863 | I32: Total | J32: 4741.1532
A33: Core Loss | B33: 1.376 / 1.646 | C33: Flux / Pole | D33: Tooth | E33: 3.8549999 | F33: 1007.3894 | G33: 9.1225345 | H33: 12.429112 | I33: C.L.C. | J33: 1.75 / 0.84
A34: NoLoad | B34: 26.78 / 32.01 | C34: 9.1899445 | D34: Air Gap | E34: 0.20999999 | F34: 1982.9895 | G34: 4.6343889 | H34: 774.46582 | I34: S.F.C. | J34: 6.0500002
A35: Load Characteristics | D35: Temp. Rise @ 100%: | E35: 71 / 76 | G35: No Load Loss | H35: 24758.0 / 8517.8 | I35: W.Loss | J35: 8297.0 / 4000.3
A36: Load (%) | B36: 25 | C36: 50 | D36: 75 | E36: 100 | F36: 125 | G36: Primary Loss | H36: 6060.7 / 5925.6 | I36: S.Loss | J36: 1249.3 / 602.3
A37: Current (A) | B37: 42.56 / 43.47 | C37: 66.81 / 68.23 | D37: 94.42 / 96.44 | E37: 123.87 / 126.51 | F37: 155.17 / 158.48 | G37: Second. Loss | H37: 4731.7 / 5162.5 | I37: Total C.Loss | J37: 9546.3 / 4602.6
A38: Efficiency | B38: 0.880 / 0.887 | C38: 0.932 / 0.939 | D38: 0.948 / 0.956 | E38: 0.955 / 0.963 | F38: 0.958 / 0.966 | G38: Frict.& Wind. | H38: 15000.0 / 5091.8 | I38: Stray Loss | J38: 7633.3296
A39: P.F. | B39: 0.719 / 0.698 | C39: 0.865 / 0.840 | D39: 0.902 / 0.876 | E39: 0.910 / 0.883 | F39: 0.905 / 0.879 | G39: Starting Data | I39: Slip | J39: PF
A40: Slip | B40: 0.0015 / 0.0027 | C40: 0.0030 / 0.0042 | D40: 0.0044 / 0.0056 | E40: 0.0060 / 0.0072 | F40: 0.0076 / 0.0087 | G40: LRA | H40: 609.2 / 826.0
...

Sheet Data Sheet
A1: TOSHIBA INTERNATIONAL CORPORATION
A2: INDUCTION MOTOR DATA SHEET
A3: File: | B3: CS6M20U | I3: HRW / Model Number: | J3: M206FTQL11E-C
A4: Type: TIKE - Form: FCW4 - 6 Pole - 1000 HP - 2300 / 4000 V - 60 Hz - 6811US - Class F | Q4: Motor Type Selection | T4: Electrical Steel Table
A5: Motor Parameters | F5: PERFORMANCE | J5: DESIGN | K5: TEST | Q5: EPACT | T5: M22 - 26Ga.
A6: Material | D6: M36 - 26Ga. | F6: NL & Impedance Test | M6: CS6M20U | N6: CS6900U | Q6: EQP-III | T6: M36 - 26Ga.
A7: Air Gap | D7: 2.0999999 | F7: No load amps | J7: 55 / 32 | K7: 32.7 | M7: =O7/N7*J7 -> #VALUE! | N7: 28 | O7: 28.1 | Q7: Exp.Prf. | T7: NCB1 - 26Ga.
A8: Stack length | D8: 910 | F8: No load watts | J8: 10005 | K8: 12675 | M8: =O8/N8*J8 -> 12556.893 | N8: 8100 | O8: 10166 | Q8: Exp.Prf.-EQPIII | T8: M43 - 26Ga.
A9: Number of turns per coil | D9: 8,9,9,8 | F9: Impedance amps | H9: 3 | I9: f | J9: 220 / 175 | K9: 172.5 | M9: =O9/N9*J9 -> #VALUE! | N9: 150 | O9: 146 | Q9: Prem. Eff. | T9: M45 - 26Ga.
A10: Wire 1 (size & number) | D10: (.102"x.204")x2 | F10: Impedance volts | H10: 3 | I10: f | J10: 460 / 1150 | K10: 1150 | M10: =O10/N10*J10 -> #VALUE! | N10: 1150 | O10: 1150 | Q10: OWP | T10: M54 - 26Ga.
A11: Wire 2 (size & number) | D11: - | F11: Impedance watts | H11: 3 | I11: f | J11: 24138 | K11: 42294 | M11: =O11/N11*J11 -> 39004.036 | N11: 23128 | O11: 37372 | Q11: Dry Kiln
A12: Slot fill - circle/square method (%) | D12: - | F12: Temperature Rise (°C)
A13: Connection | D13: 2 x Delta / 2 x Wye | G13: Winding | I13: 80/115 | J13: 76 / 101 | K13: -
A14: MCL | D14: 1457 | G14: Frame | J14: - | K14: -
A15: Allowance for ins. depth | D15: 11.7264 | G15: Bearing PS/OS | J15: - | K15: -
A16: Allowance for ins. width | D16: 3.4367998 | G16: End Ring | J16: - | K16: -
A17: Slot/Wire arrangement | D17: 17 x 2 | F17: Nameplate Data
A18: Effective cross section for coil | D18: - | H18: FLC (A) | J18: 220 / 127 | M18: =J18*6.5 -> #VALUE!
A19: Coil grouping | D19: - | H19: RPM | J19: 1191
A20: Coil pitch (slot number) | D20: 1 ~ 11 | H20: CODE | J20: G
A21: Method of coil connection | D21: - | H21: S. F. | J21: 1.15 | Q21: Method of Connection
A22: Resistance per phase @ 20 °C | D22: 0.0995 | H22: DESIGN | J22: - | Q22: Skip
A23: Coil Weight | B23: Wire1 | D23: 938 | H23: Nom.Eff. (%): | Q23: Adjacent
A24: (lbs.) | B24: Wire2 | D24: - | H24: Min.Eff. (%): | Q24: -
A25: Current Densities (A/cm2) | E25: Bar / ER | H25: P.F. (%):
A26: FL / LR | D26: 241 / 1567 | E26: 270 / 234
A27: Stator Slot Shape (Reference) | F27: Performance
H28: LRC (A) | I28: - | J28: 1431 / 826 | K28: - | M28: =(J28/J18)*100 -> #VALUE!
H29: LRT (%) | I29: 60 | J29: 124 | K29: -
H30: BDT (%) | I30: 175 | J30: 274 | K30: -
H31: SLIP (%) | J31: 0.72 | K31: -
G32: IEEE-B | H32: Eff. (%) | J32: 96.3 | K32: -
A33: Rotor Slot Shape (Reference) | H33: PF (%) | J33: 88.3 | K33: -
F34: Losses (Watts) | H34: Primary | J34: 5926 | K34: -
H35: Secondary | J35: 5163 | K35: -
H36: Core | J36: 4603 | K36: -
H37: F & W | J37: 5092 | K37: -
H38: Stray | J38: 7633 | K38: -
A39: End Ring (Reference) | F39: Note | G39: Outer Fan OD: 610 mm
G40: QCLimits: CS6M20U
...

Sheet LoginSheet
J1: P | K1: T | L1: L | M1: T
B2: PROJECT HISTORY | J2: E | K2: D | L2: I | M2: Y | N2: H
J3: R | L3: M | M3: P
J4: F | L4: I | M4: E
K5: C | L5: T | N5: I
J6: D | K6: U | M6: T | N6: N
J7: A | K7: R | L7: R | M7: E | N7: S
I8: S | J8: T | K8: V | L8: E | M8: S | N8: U
B9: DATE | C9: PROJECT | D9: SMART NUMBER | E9: QTY | F9: CUSTOMER | G9: REMARKS | H9: LIMIT CODE | I9: F | J9: A | K9: E | L9: V | M9: T | N9: L
B53: REVISION HISTORY
B54: REV | C54: REMARKS | I54: DATE | L54: INIT

Sheet Form
A1: Winding Data Calculation
C2: MCL: 1457.0
A3: Coil Resistance | D3: Lead Resistance
A4: 8T: | B4: 0.0159 ~ 0.0153 | D4: AWG. 02 x 3
A5: 9T: | B5: 0.0179 ~ 0.0172 | D5: 0.00151
A6: Coil Dimensions
A7: HM: | B7: 8T: 22.33 | C7: WM: | D7: 8T: 10.76 | E7: WT:
B8: 9T: 25.12 | D8: 9T: 10.76 | E8: 14.30 ~ 13.90
A9: Insulation Allowance | D9: Wire Weight
A10: Depth: | B10: 11.73 | D10: (.102"x.204")x 2: | F10: 938 lbs.
A11: Width: | B11: 3.44
A12: QC Resistance
A13: 1-2, 2-3, 3-1: | C13: 0.208 ~ 0.196

Sheet Performance Data Sheet
A1: TOSHIBA INTERNATIONAL CORPORATION | J1: INDEX | L1: MPCF-1033
A2: Industrial Division / Houston Motor Plant | J2: SHEET NO. | L2: 1 of 1
J3: ISSUED | L3: 7/31/13
J4: SUPERSEDES | L4: 11/8/96
J5: REVISION | L5: 2
A6: SQUIRREL CAGE INDUCTION MOTOR | J6: WRITTEN BY | L6: MDC
A7: PERFORMANCE SPECIFICATIONS | J7: APPROVED BY | L7: PAA
B9: CUSTOMER: | C9: L&B ELECTRIC
B10: TIC SR No.: | C10: 2400576.1
A12: MOTOR NAMEPLATE DATA
B13: H.P.: | C13: 1000 | E13: VOLTS: | F13: 4000 | H13: 3 PH / | I13: 60 Hz | L13: S. RPM: | M13: 1200
B14: FRAME: | C14: 6811US | E14: ENCL: | F14: TEFC | H14: FLAMPS: | I14: 127 | L14: FLRPM: | M14: 1191
B15: FORM: | C15: FCW4 | E15: S.F.: | F15: 1.15 | H15: NEMA DESIGN: | I15: - | L15: INSUL CLASS: | M15: F
B16: TYPE: | C16: TIKE | E16: AMB.: | F16: 40 | H16: CODE: | I16: G | L16: DUTY: | M16: Cont.
B17: MODEL No.: | C17: GP-10185637 | H17: kW:
B18: NOM. EFF.: | C18: - | E18: MIN. EFF.: | F18: - | H18: P.F.: | I18: -
A21: AMPERAGE | E21: TORQUES | I21: **BEARINGS:
C22: LOCKED ROTOR: | D22: 826 | G22: FULL LOAD (lb-ft.): | H22: 4410 | K22: DRIVE END:
G23: LOCKED ROTOR (%): | H23: 120 | K23: OPPOSITE DRIVE END:
G24: BREAK DOWN (%): | H24: 270
A28: EFFICIENCY | H28: POWER FACTOR
C29: FULL LOAD: | D29: 96.3 | J29: FULL LOAD: | K29: 88.3
C30: 3/4 LOAD: | D30: 95.6 | J30: 3/4 LOAD: | K30: 87.5
C31: 1/2 LOAD: | D31: 93.9 | J31: 1/2 LOAD: | K31: 83.9
A35: ALL CHARACTERISTICS ARE AVERAGE EXPECTED VALUES BASED UPON RATED VOLTAGE,
A36: FREQUENCY AND SINEWAVE POWER INPUT.
A37: THE DECLARED LOCKED ROTOR CURRENT HAS A TOLERANCE OF 20%.
A38: * TEMPERATURE RISE WILL BE CONSISTENT WITH INSULATION, AMBIENT AND SERVICE FACTOR AS
A39: DEFINED BY NEMA-MG-12 OR -20.
A40: ** BEARINGS ARE THE ONLY RECOMMENDED SPARE PART(S).
J42: CERTIFIED BY: | K42: Jerry R
J44: DATE: | K44: 46147
A59: - | B59: 6205ZZ | D59: 1 | E59: -
A60: TEFC | B60: 6206UU | D60: 1.15 | E60: A
A61: ODP | B61: 6207ZZ | E61: B
B62: 6208UU
B63: 6211ZZ
B64: 6211C3
B65: 6211ZZC3
B66: 6305UUC3
...

Sheet STCurve
A2: TOSHIBA INTERNATIONAL CORPORATION
A3: Speed Torque/Current Curve
A6: Model #: | B6: ='Performance Data Sheet'!C17 -> GP-10185637 | E6: FLAmps: | F6: ='Performance Data Sheet'!I14 & " A" -> 127 A
A7: Enclosure: | B7: ='Performance Data Sheet'!F14 -> TEFC | C7: Voltage: | D7: ='Performance Data Sheet'!F13 & " V" -> 4000 V | E7: Frame: | F7: ='Performance Data Sheet'!C14 -> 6811US
A8: Pole: | B8: 6 | C8: Frequency: | D8: 3 PH / 60 Hz | E8: Ins. Class: | F8: F
A9: HP: | B9: 1000 | C9: Rotor Inertia: | D9: 1496.8 lb-ft² | E9: Date: | F9: ='Performance Data Sheet'!K44 -> 46147
A10: FLRPM: | B10: 1191 | C10: Load Inertia: | D10: N/A | E10: File: | F10: CS6M20U
B12: Locked Rotor Amps: | C12: ='Performance Data Sheet'!D22 & " A" -> 826 A | D12: Load Type: | E12: N/A
B13: Locked Rotor Torque: | C13: 1.2 | D13: Starting at: | E13: N/A
B14: Breakdown Torque: | C14: 2.7 | D14: Accel. Time: | E14: N/A
B15: Rated Torque: | C15: 4410 lb-ft
A39: Comments: | B39: PROJECT | C39: ='Performance Data Sheet'!C10 -> 2400576.1 | E39: D.E.Curve #: | F39: =F10 -> CS6M20U
C43: Prepared by: | D43: ='Performance Data Sheet'!K42 -> Jerry R | E43: Checked by: | F43: SH
D53: Load
A54: 100 | B54: 0 | C54: 0.36347422 | D54: 100
A55: 99 | B55: 175.03287 | C55: 179.87842 | D55: 98
A56: 95 | B56: 270 | C56: 485.13272 | D56: 87
A57: 90 | B57: 235.36225 | C57: 548.85297 | D57: 74
A58: 84.999999 | B58: 221.92533 | C58: 568.04523 | D58: 61
A59: 80 | B59: 221.24417 | C59: 579.27722 | D59: 50
A60: 69.999999 | B60: 220.42738 | C60: 596.09094 | D60: 33
A61: 59.999999 | B61: 220 | C61: 609.63556 | D61: 22
A62: 50 | B62: 220.55918 | C62: 620.65051 | D62: 14
A63: 39.999998 | B63: 221.11629 | C63: 629.37085 | D63: 7.9999995
A64: 30.000001 | B64: 221.53885 | C64: 636.35614 | D64: 5.9999995
A65: 19.999999 | B65: 222.06525 | C65: 641.92218 | D65: 8.000001
... A67: 0 | B67: 220 | C67: 650.39374 | D67: 30

Sheet Thermdam
A2: TOSHIBA INTERNATIONAL CORPORATION
A3: Thermal Limit & Acceleration Curves
A4: Design Values (For Reference Only)
A6: Model #: | B6: ='Performance Data Sheet'!C17 -> GP-10185637 | E6: FLAmps: | F6: ='Performance Data Sheet'!I14 & " A" -> 127 A
A7: Enclosure: | B7: ='Performance Data Sheet'!F14 -> TEFC | C7: Voltage: | D7: ='Performance Data Sheet'!F13 & " V" -> 4000 V | E7: Frame: | F7: ='Performance Data Sheet'!C14 -> 6811US
A8: Pole: | B8: 6 | C8: Frequency: | D8: 3 PH / 60 Hz | E8: Ins. Class: | F8: F
A9: HP: | B9: 1000 | C9: Rotor Inertia: | D9: 1496.8 lb-ft² | E9: Date: | F9: ='Performance Data Sheet'!K44 -> 46147
A10: FLRPM: | B10: 1191 | C10: Load Inertia: | D10: N/A | E10: File: | F10: CS6M20U
A39: Comments: | B39: PROJECT | C39: ='Performance Data Sheet'!C10 -> 2400576.1 | E39: D.E.Curve #: | F39: =F10 -> CS6M20U
C43: Prepared by: | D43: ='Performance Data Sheet'!K42 -> Jerry R | E43: Checked by:
F50: =5252.1*B50/D53 -> #DIV/0!
D66: =D65/D64 -> #DIV/0!
A67: Current (%) | B67: Cold | C67: Hot | E67: CURRENT (%) | F67: Accel. Time
A68: 650.3937 | B68: 35 | C68: 15 | E68: =A68 -> 650.3937 | F68: 0.0001
A69: 573.60348 | B69: =((A68/A69)^2)*B68 -> 44.998407 | C69: =((A68/A69)^2)*C68 -> 19.285032 | E69: 648.4252 | F69: 0.99000001
A70: 496.79022 | B70: =((A68/A70)^2)*B68 -> 59.989414 | C70: =((A68/A70)^2)*C68 -> 25.709749 | E70: 644.25197 | F70: 1.882
A71: 420 | B71: =((A68/A71)^2)*B68 -> 83.930946 | C71: =((A68/A71)^2)*C68 -> 35.970405 | E71: 639.13386 | F71: 2.7409999
A72: =A71-100 -> 320 | B72: =((A68/A72)^2)*B68 -> 144.58417 | E72: 632.83465 | F72: 3.6029999
A73: =A72-100 -> 220 | B73: =((A68/A73)^2)*B68 -> 305.89708 | E73: 625.03937 | F73: 4.4990001
A74: 274 | B74: =((A68/A74)^2)*B68 -> 197.20575 | C74: =((A68/A74)^2)*C68 -> 84.51675 | E74: 615.11811 | F74: 5.4570003
A75: 180 | B75: =((A68/A75)^2)*B69 -> 587.49582 | C75: =((A68/A75)^2)*C68 -> 195.83887 | E75: 602.83465 | F75: 6.5170002
A76: 120 | B76: =((A68/A76)^2)*B68 -> 1028.1541 | C76: =((A68/A76)^2)*C68 -> 440.63746 | E76: 587.6378 | F76: 7.7490001
A77: 110 | C77: =CEILING(C76*2,100) -> 900 | E77: 573.62205 | F77: 8.441
A78: 110 | C78: =2*C77 -> 1800 | E78: 558.4252 | F78: 9.092
A79: 110 | C79: 10000 | E79: 517.00787 | F79: 9.4790001
E80: 332.44094 | F80: 9.54
E81: 0 | F81: 9.5900002

Sheet Performance 4000V
A2: TOSHIBA INTERNATIONAL CORPORATION
A3: Performance Curve
A4: Design Values (For Reference Only)
A6: Model #: | B6: ='Performance Data Sheet'!C17 -> GP-10185637 | E6: FLAmps: | F6: 127 A
A7: Enclosure: | B7: ='Performance Data Sheet'!F14 -> TEFC | C7: Voltage: | D7: 4000 V | E7: Frame: | F7: ='Performance Data Sheet'!C14 -> 6811US
A8: Pole: | B8: 6 | C8: Frequency: | D8: 3 PH / 60 Hz | E8: Ins. Class: | F8: F
A9: HP: | B9: 1000 | C9: Rotor Inertia: | D9: 1496.8 lb-ft² | E9: Date: | F9: ='Performance Data Sheet'!K44 -> 46147
A10: FLRPM: | B10: 1191 | C10: Load Inertia: | D10: N/A | E10: File: | F10: CS6M20U
B12: Locked Rotor Amps: | C12: 826 A | D12: Load Type: | E12: N/A
B13: Locked Rotor Torque: | C13: 1.24 | D13: Starting at: | E13: N/A
B14: Breakdown Torque: | C14: 2.74 | D14: Accel. Time: | E14: N/A
B15: Rated Torque: | C15: 4410 lb-ft
A39: Comments: | B39: PROJECT | C39: ='Performance Data Sheet'!C10 -> 2400576.1 | E39: D.E.Curve #: | F39: =F10 -> CS6M20U
C43: Prepared by: | D43: ='Performance Data Sheet'!K42 -> Jerry R | E43: Checked by: | F43: SH
A53: Load | B53: Efficiency | C53: PF | D53: Amps | E53: RPM | F53: Input Watts
A54: 0 | D54: 27.452716 | E54: 100 | F54: 0.42589
A55: 25 | B55: 88.697624 | C55: 69.76754 | D55: 43.638073 | E55: 81.736063 | F55: 10.546221
A56: 50 | B56: 93.94413 | C56: 83.927727 | D56: 68.49926 | E56: 73.124158 | F56: 19.914491
A57: 75 | B57: 95.631531 | C57: 87.501419 | D57: 96.813522 | E57: 64.384164 | F57: 29.344655
A58: 100 | B58: 96.33889 | C58: 88.279587 | D58: 127.00741 | E58: 55.071094 | F58: 38.838925
A59: 125 | B59: 96.621429 | C59: 87.836372 | D59: 159.09375 | E59: 45.666171 | F59: 48.40669

Sheet Performance 2300V
A2: TOSHIBA INTERNATIONAL CORPORATION
A3: Performance Curve
A4: Design Values (For Reference Only)
A6: Model #: | B6: ='Performance Data Sheet'!C17 -> GP-10185637 | E6: FLAmps: | F6: 220 A
A7: Enclosure: | B7: ='Performance Data Sheet'!F14 -> TEFC | C7: Voltage: | D7: 2300 V | E7: Frame: | F7: ='Performance Data Sheet'!C14 -> 6811US
A8: Pole: | B8: 6 | C8: Frequency: | D8: 3 PH / 60 Hz | E8: Ins. Class: | F8: F
A9: HP: | B9: 1000 | C9: Rotor Inertia: | D9: 1496.8 lb-ft² | E9: Date: | F9: ='Performance Data Sheet'!K44 -> 46147
A10: FLRPM: | B10: 1191 | C10: Load Inertia: | D10: N/A | E10: File: | F10: CS6M20U
B12: Locked Rotor Amps: | C12: 1430 A | D12: Load Type: | E12: N/A
B13: Locked Rotor Torque: | C13: 1.2 | D13: Starting at: | E13: N/A
B14: Breakdown Torque: | C14: 2.7 | D14: Accel. Time: | E14: N/A
B15: Rated Torque: | C15: 4410 lb-ft
A39: Comments: | B39: PROJECT | C39: ='Performance Data Sheet'!C10 -> 2400576.1 | E39: D.E.Curve #: | F39: =F10 -> CS6M20U
C43: Prepared by: | D43: ='Performance Data Sheet'!K42 -> Jerry R | E43: Checked by: | F43: SH
A53: Load | B53: Efficiency | C53: PF | D53: Amps | E53: RPM | F53: Input Watts
A54: 0 | D54: 47.549498 | E54: 100 | F54: 0.42589
A55: 25 | B55: 88.697624 | C55: 69.76754 | D55: 75.58336 | E55: 81.736063 | F55: 10.546221
A56: 50 | B56: 93.94413 | C56: 83.927727 | D56: 118.6442 | E56: 73.124158 | F56: 19.914491
A57: 75 | B57: 95.631531 | C57: 87.501419 | D57: 167.68594 | E57: 64.384164 | F57: 29.344655
A58: 100 | B58: 96.33889 | C58: 88.279587 | D58: 219.98328 | E58: 55.071094 | F58: 38.838925
A59: 125 | B59: 96.621429 | C59: 87.836372 | D59: 275.55846 | E59: 45.666171 | F59: 48.40669

Sheet StallTime
A1: Rating: | B1: 6 Pole - 1000.0 HP - 1200 RPM - 4000 V - 60 Hz
A3: Starting Performance
D4: Load Type: Fan / Pump - 9409.0 lb-ft²
A5: RPM | B5: Motor | C5: Load | D5: Accel. | E5: Line | F5: Stator | G5: Rotor
A6: Speed Increment | B6: Torque (%) | C6: Torque (%) | D6: Time (s) | E6: Amps | F6: kW / s | G6: kW / s
A7: 0~125 | B7: 124.0 | C7: 22.4 | D7: 0.990 | E7: 823.5 | F7: 266.7 | G7: 851.6
A8: 125~250 | B8: 124.1 | C8: 11.3 | D8: 0.892 | E8: 818.2 | F8: 237.6 | G8: 687.9
A9: 250~375 | B9: 124.2 | C9: 7.0 | D9: 0.859 | E9: 811.7 | F9: 225.6 | G9: 585.9
A10: 375~500 | B10: 124.4 | C10: 7.6 | D10: 0.862 | E10: 803.7 | F10: 222.5 | G10: 511.1
A11: 500~625 | B11: 124.7 | C11: 12.3 | D11: 0.896 | E11: 793.8 | F11: 226.1 | G11: 451.4
A12: 625~750 | B12: 125.2 | C12: 20.2 | D12: 0.958 | E12: 781.2 | F12: 235.2 | G12: 397.9
A13: 750~875 | B13: 126.3 | C13: 31.4 | D13: 1.060 | E13: 765.6 | F13: 251.1 | G13: 346.3
A14: 875~1000 | B14: 129.4 | C14: 47.7 | D14: 1.232 | E14: 746.3 | F14: 278.8 | G14: 293.8
A15: 1000~1063 | B15: 136.5 | C15: 63.9 | D15: 0.692 | E15: 728.5 | F15: 148.0 | G15: 210.6
A16: 1063~1125 | B16: 154.4 | C16: 77.1 | D16: 0.651 | E16: 709.2 | F16: 133.8 | G16: 145.8
... A19: 1198~1200 | B19: 138.8 | C19: 99.8 | D19: 0.050 | E19: 131.2 | F19: 0.3 | G19: 19.1
D21: Acceleration Time: 9.6 s
B22: Energy | D22: First Start | F22: Second Start
A23: Stator Winding Rise | B23: 2309 kW / s | D23: 14°C | F23: 29°C
A24: Rotor Bar Rise | B24: 4024 kW / s | D24: 45°C | F24: 90°C
A25: End Ring Rise | B25: 548 kW / s | D25: 35°C | F25: 70°C
A27: Locked Rotor Thermal Capability
E28: Cold Condition
B29: Rate of Rise | D29: Power | E29: Rise Limit | F29: Max Time
A30: Stator Copper | B30: 2.0°C / s | D30: 322.4 kW | E30: 160°C | F30: 79.5 s
A31: Rotor Bar | B31: 9.1°C / s | D31: 814.2 kW | E31: 260°C | F31: 28.5 s
A32: Rotor ER | B32: 7.1°C / s | D32: 110.9 kW | E32: 180°C | F32: 25.4 s
E34: Hot Condition
B35: Hot Temp. | D35: Rise Limit | E35: Ambient | F35: Total | G35: Max.Time
A36: Stator Copper | B36: 76°C + | D36: 84°C + | E36: 40°C | F36: = 200°C | G36: 41.7 s
A37: Rotor Bar | B37: 103°C + | D37: 157°C + | E37: 40°C | F37: = 300°C | G37: 17.2 s
A38: Rotor ER | B38: 103°C + | D38: 77°C + | E38: 40°C | F38: = 220°C | G38: 10.9 s
A40: Cold Stall Time: | B40: 62.8 s | D40: Hot Stall Time: | F40: 26.8 s
