Workbook
Name Print_Area_MI: 'Circuit Param'!$A$8:$N$43
Name Print_Area_MI: 'Performance API'!$A$10:$N$18
Name Print_Area_MI: 'Performance Data Sheet'!$A$10:$N$42
Name thermal: #REF!
Name transfer: #REF!
Name unit_sht: "unit_sht"
Name vassvelo: #REF!
Name velcoity: #REF!
Name viscosity: #REF!
Name vollheatre: #REF!
Name volumetri: #REF!
Name weight: #REF!
Name weights: #REF!

Sheet DesignSheet
A1: TOSHIBA INTERNATIONAL CORPORATION | I1: Calc. Code: | J1: 2-2-2-0-1-2
A2: 3-PHASE SQUIRREL CAGE INDUCTION MOTOR DESIGN SHEET | J2: B.L.-1 P.F.-1
A3: File: | B3: G:\Top_Hat_5012\Electric\SERIES DESIGNS\Cu-Bar\WPII\4P\DT4450K.rat | G3: Date: | H3: 44021 | I3: Time: | J3: 0.62706019
A4: Pole | B4: HP | C4: RPM | D4: Form | E4: Voltage | F4: Frequency | G4: Temperature | H4: FLSpeed | I4: FLSlip | J4: Frame
A5: 4 | B5: 450.00002 | C5: 1800 | D5: DCKW | E5: 4000 | F5: 60 | G5: 105 | H5: 1777.1 / 1774.5 | I5: 0.0127 / 0.0142 | J5: 5011/12
A6: Core Data | D6: Winding Data | H6: Constant Data
B7: Primary | C7: Secondary | F7: Bar | G7: End Ring | H7: St. Slot Pitch | I7: 20.420335 | J7: LR Test Data
A8: Air Gap | B8: 1.7 | H8: Rt. Slot Pitch | I8: 27.603152 | J8: ES
A9: Space Fac. | B9: 0.93000001 | D9: Pitch | E9: 1 ~ 14 | F9: Cross Section Area | H9: Mean Value | I9: 24.011744 | J9: 755.84119
A10: Core Length | B10: 305 | C10: 305 | F10: UB: 200.0 | G10: UER: 1375.0 | H10: Eff.T.W.St. | I10: 12.416524 | J10: WS
A11: OD | B11: 590 | C11: 386.6 | D11: Coil Pitch | E11: 0.86658 | H11: Eff.T.W.Rt. | I11: 26.848829 | J11: 21198.658
A12: ID | B12: 390 | C12: 220 | D12: Slot Fill | E12: - | F12: EBL: 40.0 | G12: ERD1: 282.5 | H12: St.Carter Fac. | I12: 1.2245199 | J12: IS
A13: Core Depth | B13: 54 | C13: 56.250001 | D13: Con./Slot | E13: 21 | G13: ERT: 55.00 | H13: Rt.Carter Fac. | I13: 1.0280952 | J13: 58.462334
A14: Eff.Core L. | B14: 227.85001 | C14: 227.85001 | D14: Wire Size 1 | E14: (.057"x.162")x2 | F14: (8 x 25) | G14: ERH: 25.00 | H14: Carter Factor | I14: 1.2589231 | J14: Volts / Turn
A15: Slot Data | D15: Wire Size 2 | E15: - | H15: Short. Factor | I15: 0.97811905 | J15: 10.99747
A16: Number | B16: 60 | C16: 44 | D16: // Circuits | E16: 1 | H16: Distrib. Factor | I16: 0.956506 | J16: AC
A17: Kind | B17: Open | C17: Rectang | D17: Connection | E17: Wye | H17: Wind. Factor | I17: 0.93557674 | J17: 601.21884
A18: Skew | B18: - | C18: 0 | D18: MCL | E18: 780 | F18: 440 | H18: Reactance | I18: (Coeff.: 0.1167)
A19: Depth | B19: 46 | C19: 27.049999 | D19: No.Cond./Ph. | E19: 420 | I19: Running | J19: Start
A20: Width | B20: 8.00 - 8.00 | C20: 8.0500002 | D20: Res. (20°C) | E20: 0.50517069 | H20: Stator Slot | I20: 17.917881 | J20: 17.917881
A21: Opening | B21: 11.6 | C21: 3 | D21: (105°C) | E21: 0.67389174 | F21: 0.54525763 | G21: 0.031016243 | H21: Rotor Slot | I21: 18.340248 | J21: 13.927567
A22: Tip Depth | B22: 2.8299999 | C22: 2 | D22: Material | E22: CU | F22: CU | G22: CU | H22: Zigzag | I22: 7.4954615 | J22: 4.9915032
A23: T.Min.Wid. | B23: 8.8203344 | C23: 15.690769 | D23: Spec.Resist. | E23: 1.742 | F23: 1.742 | G23: 1.742 | H23: Coil End | I23: 21.097485 | J23: Skew R.: 0.00
A24: Low. R. | B24: 0 | C24: 0.80000001 | D24: Spec.Gravity | E24: 8.8900003 | F24: 8.8900003 | G24: 8.8900003 | H24: Belt Leakage | I24: 5.312369 | J24: 3.6120794
A25: Up. R. | B25: - | C25: 0.80000001 | D25: Weight (kg) | H25: Total Resist. | I25: 1.2501656 | J25: 2.0674491
A26: Wedge Dep. | B26: 2.40 - 2.00 | C26: Magnetic | D26: Wire 1 | E26: 98.700834 | F26: 38.724841 | G26: 23.617238 | H26: Total React. | I26: 8.1866827 | J26: 7.1725798
A27: Duct | B27: 6 x 10 | C27: 6 x 10 | D27: Wire 2 | E27: - | F27: - | G27: - | H27: Impedance | I27: 8.2815876 | J27: 7.4645996
A28: Effective Depth (S=1) | D28: Magnetic Circuit Data | I28: Core Loss Data
B29: Res.= | C29: 25.040984 | E29: Length | F29: Section | G29: Density | H29: AT | I29: Volume | J29: Loss | M29: =RIGHT(F$41,SEARCH("/",F$41,1)-1) -> 1768.5 | N29: 125RPM
B30: Reac.= | C30: 25.047422 | D30: Primary Core | E30: 23.169226 | F30: 246.07801 | G30: 17.931076 | H30: 648.88991 | I30: 20718.442 | J30: 1893.0555 | M30: =RIGHT(E$41,SEARCH("/",E$41,1)-1) -> 1774.5 | N30: 100RPM
A31: Excitation Data | D31: Tooth | E31: 4.6 | F31: 301.45699 | G31: 14.637058 | H31: 47.444895 | I31: 5546.8086 | J31: 364.78946 | M31: =RIGHT(D$41,SEARCH("/",D$41,1)-1) -> 1780.5 | N31: 75RPM
A32: Excit.Amps | B32: 19.215 / 16.458 | D32: Second.Core | E32: 13.057233 | F32: 256.33126 | G32: 17.213833 | H32: 298.1805 | I32: Total | J32: 2257.8449 | M32: =RIGHT(C$41,SEARCH("/",C$41,1)-1) -> 1786.2 | N32: 50RPM
A33: Core Loss | B33: 0.621 / 0.532 | C33: Flux / Pole | D33: Tooth | E33: 2.7049999 | F33: 393.2656 | G33: 11.220009 | H33: 12.230038 | I33: C.L.C. | J33: 1.50 / 1.23 | M33: =RIGHT(B$41,SEARCH("/",B$41,1)-1) -> 1791.8 | N33: 25RPM
A34: NoLoad | B34: 19.23 / 16.47 | C34: 4.4124435 | D34: Air Gap | E34: 0.17 | F34: 596.1026 | G34: 7.4021545 | H34: 1001.3769 | I34: S.F.C. | J34: 6.0500002
A35: Load Characteristics | D35: Temp. Rise @ 100%: | E35: 71 / 65 | G35: No Load Loss | H35: 6469.0 / 7538.1 | I35: W.Loss | J35: 3386.8 / 2787.5
A36: Load (%) | B36: 25 | C36: 50 | D36: 75 | E36: 100 | F36: 125 | G36: Primary Loss | H36: 6909.8 / 7200.1 | I36: S.Loss | J36: 922.6 / 759.4
A37: Current (A) | B37: 24.47 / 24.55 | C37: 33.66 / 33.78 | D37: 45.39 / 45.55 | E37: 58.46 / 58.66 | F37: 72.59 / 72.84 | G37: Second. Loss | H37: 4506.6 / 3658.5 | I37: Total C.Loss | J37: 4309.4 / 3546.8
A38: Efficiency | B38: 0.920 / 0.899 | C38: 0.949 / 0.927 | D38: 0.954 / 0.932 | E38: 0.953 / 0.931 | F38: 0.949 / 0.927 | G38: Frict.& Wind. | H38: 1600.0 / 4783.2 | I38: Stray Loss | J38: 5719.0176 | L38: =LEFT(E38,SEARCH("/",E38,1)-1) -> 0.953 | M38: =RIGHT(E38,SEARCH("/",E38,1)-1) -> 0.931 | N38: =M38/L38 -> 0.97691501 | O38: Eff.
A39: P.F. | B39: 0.538 / 0.549 | C39: 0.758 / 0.773 | D39: 0.839 / 0.856 | E39: 0.870 / 0.887 | F39: 0.880 / 0.897 | G39: Starting Data | I39: Slip | J39: PF | L39: =LEFT(E39,SEARCH("/",E39,1)-1) -> 0.870 | M39: =RIGHT(E39,SEARCH("/",E39,1)-1) -> 0.887 | N39: =M39/L39 -> 1.0195402 | O39: PF.
A40: Slip | B40: 0.0032 / 0.0046 | C40: 0.0063 / 0.0077 | D40: 0.0094 / 0.0109 | E40: 0.0127 / 0.0142 | F40: 0.0161 / 0.0175 | G40: LRA | H40: 309.4 / 352.8 | L40: =LEFT(E37,SEARCH("/",E37,1)-1) -> 58.46 | M40: =RIGHT(E37,SEARCH("/",E37,1)-1) -> 58.66 | N40: =M40/L40 -> 1.0034211 | O40: Current
...

Sheet Data Sheet
A1: TOSHIBA INTERNATIONAL CORPORATION
A2: INDUCTION MOTOR DATA SHEET
A3: File: | B3: DT4450K | I3: HRW / Model Number: | J3: 4504WTAK11F-C
A4: Type: TIKE - Form: DCKW - 4 Pole - 450 HP - 4000 V - 60 Hz - 5011/12 - Class F | Q4: Motor Type Selection | T4: Electrical Steel Table
A5: Motor Parameters | F5: PERFORMANCE | J5: DESIGN | K5: TEST | Q5: EPACT | T5: M22 - 26Ga.
A6: Material | D6: M22 - 26Ga. | F6: NL & Impedance Test | Q6: EQP-III | T6: M36 - 26Ga.
A7: Air Gap | D7: 1.7 | F7: No load amps | J7: 16.5 | K7: - | Q7: Exp.Prf. | T7: NCB1 - 26Ga.
A8: Stack length | D8: 305 | F8: No load watts | J8: 7538 | K8: - | Q8: Exp.Prf.-EQPIII | T8: M43 - 26Ga.
A9: Number of turns per coil | D9: 10,11 | F9: Impedance amps | H9: 3 | I9: f | J9: 89 | K9: - | Q9: Prem. Eff. | T9: M45 - 26Ga.
A10: Wire 1 (size & number) | D10: (.057"x.162")x2 | F10: Impedance volts | H10: 3 | I10: f | J10: 1150 | K10: - | Q10: Standard Eff. | T10: M54 - 26Ga.
A11: Wire 2 (size & number) | D11: - | F11: Impedance watts | H11: 3 | I11: f | J11: 21199 | K11: - | Q11: OWP | T11: TIPA Lam
A12: Slot fill - circle/square method (%) | D12: - | F12: Temperature Rise (°C) | J12: RM | L12: RTD 1.0SF | Q12: Dry Kiln
A13: Connection | D13: 1 x Wye | G13: Winding | I13: 80/115 | J13: 71 / 94 | K13: - | L13: =81.4/71.1*71 -> 81.285513
A14: MCL | D14: 780 | G14: Frame | J14: - | K14: -
A15: Allowance for ins. depth | D15: 8.5662003 | G15: Bearing PS/OS | J15: - | K15: -
A16: Allowance for ins. width | D16: 2.9704003 | G16: End Ring | J16: - | K16: -
A17: Slot/Wire arrangement | D17: 21 x 2 | F17: Nameplate Data
A18: Effective cross section for coil | D18: - | H18: FLC (A) | J18: 59 | M18: =J18*6.5 -> 383.5
A19: Coil grouping | D19: - | H19: RPM | J19: 1775
A20: Coil pitch (slot number) | D20: 1 ~ 14 | H20: CODE | J20: F
A21: Method of coil connection | D21: - | H21: S. F. | J21: 1.15 | Q21: Method of Connection
A22: Resistance per phase @ 20 °C | D22: 0.50520003 | H22: DESIGN | J22: B | Q22: Skip
A23: Coil Weight | B23: Wire1 | D23: 217.1 | H23: Nom.Eff. (%): | J23: - | Q23: Adjacent
A24: (lbs.) | B24: Wire2 | D24: - | H24: Min.Eff. (%): | J24: - | Q24: -
A25: Current Densities (A/cm2) | E25: Bar / ER | H25: P.F. (%): | J25: -
A26: FL / LR | D26: 519 / 3105 | E26: 686 / 351
A27: Stator Slot Shape (Reference) | F27: Performance
H28: LRC (A) | I28: 374 | J28: 353 | K28: - | M28: =(J28/J18)*100 -> 598.30508
H29: LRT (%) | I29: 80 | J29: 135 | K29: -
H30: BDT (%) | I30: 175 | J30: 275 | K30: -
H31: SLIP (%) | J31: 1.42 | K31: -
G32: IEEE-B | H32: Eff. (%) | J32: 93.1 | K32: -
A33: Rotor Slot Shape (Reference) | H33: PF (%) | J33: 88.7 | K33: -
F34: Losses (Watts) | H34: Primary | J34: 7200 | K34: -
H35: Secondary | J35: 3659 | K35: -
H36: Core | J36: 3547 | K36: -
H37: F & W | J37: 4783 | K37: -
H38: Stray | J38: 5719 | K38: -
A39: End Ring (Reference) | F39: Note
A45: Approved | D45: Design | E45: H. Yamaga
...

Sheet LoginSheet
J1: P | K1: T | L1: L | M1: T
B2: PROJECT HISTORY | J2: E | K2: D | L2: I | M2: Y | N2: H
J3: R | L3: M | M3: P
J4: F | L4: I | M4: E
K5: C | L5: T | N5: I
J6: D | K6: U | M6: T | N6: N
J7: A | K7: R | L7: R | M7: E | N7: S
I8: S | J8: T | K8: V | L8: E | M8: S | N8: U
B9: DATE | C9: PROJECT | D9: SMART NUMBER | E9: QTY | F9: CUSTOMER | G9: REMARKS | H9: LIMIT CODE | I9: F | J9: A | K9: E | L9: V | M9: T | N9: L
B53: REVISION HISTORY
B54: REV | C54: REMARKS | I54: DATE | L54: INIT

Sheet StallTime
A1: Rating: | B1: 4 Pole - 450.0 HP - 1800 RPM - 4000 V - 60 Hz
A3: Starting Performance
D4: Load Type: Fan / Pump - 152.4 lb-ft²
A5: RPM | B5: Motor | C5: Load | D5: Accel. | E5: Line | F5: Stator | G5: Rotor
A6: Speed Increment | B6: Torque (%) | C6: Torque (%) | D6: Time (s) | E6: Amps | F6: kW / s | G6: kW / s
A7: 0~186 | B7: 135.1 | C7: 22.4 | D7: 0.111 | E7: 351.5 | F7: 28.0 | G7: 60.6
A8: 186~372 | B8: 135.3 | C8: 11.3 | D8: 0.101 | E8: 348.3 | F8: 25.0 | G8: 49.4
A9: 372~558 | B9: 135.8 | C9: 7.0 | D9: 0.097 | E9: 344.8 | F9: 23.7 | G9: 42.2
A10: 558~744 | B10: 136.5 | C10: 7.5 | D10: 0.097 | E10: 340.8 | F10: 23.1 | G10: 36.8
A11: 744~930 | B11: 137.9 | C11: 12.1 | D11: 0.100 | E11: 336.2 | F11: 23.1 | G11: 32.3
A12: 930~1116 | B12: 140.5 | C12: 19.8 | D12: 0.104 | E12: 330.7 | F12: 23.4 | G12: 28.1
A13: 1116~1302 | B13: 146.4 | C13: 30.6 | D13: 0.108 | E13: 323.5 | F13: 23.5 | G13: 23.6
A14: 1302~1488 | B14: 160.6 | C14: 46.4 | D14: 0.110 | E14: 311.2 | F14: 22.6 | G14: 18.4
A15: 1488~1581 | B15: 184.6 | C15: 62.1 | D15: 0.051 | E15: 294.9 | F15: 9.5 | G15: 12.2
A16: 1581~1674 | B16: 236.7 | C16: 75.1 | D16: 0.039 | E16: 269.6 | F16: 6.4 | G16: 7.6
... A18: 1737~1777 | B18: 175.3 | C18: 94.9 | D18: 0.034 | E18: 110.2 | F18: 0.2 | G18: 2.0
D21: Acceleration Time: 1.0 s
B22: Energy | D22: First Start | F22: Second Start
A23: Stator Winding Rise | B23: 212 kW / s | D23: 6°C | F23: 11°C
A24: Rotor Bar Rise | B24: 302 kW / s | D24: 20°C | F24: 40°C
A25: End Ring Rise | B25: 17 kW / s | D25: 2°C | F25: 4°C
A27: Locked Rotor Thermal Capability
E28: Cold Condition
B29: Rate of Rise | D29: Power | E29: Rise Limit | F29: Max Time
A30: Stator Copper | B30: 7.8°C / s | D30: 296.6 kW | E30: 160°C | F30: 20.5 s
A31: Rotor Bar | B31: 28.8°C / s | D31: 428.8 kW | E31: 260°C | F31: 9.0 s
A32: Rotor ER | B32: 2.7°C / s | D32: 24.4 kW | E32: 180°C | F32: 67.1 s
E34: Hot Condition
B35: Hot Temp. | D35: Rise Limit | E35: Ambient | F35: Total | G35: Max.Time
A36: Stator Copper | B36: 71°C + | D36: 89°C + | E36: 40°C | F36: = 200°C | G36: 11.4 s
A37: Rotor Bar | B37: 95°C + | D37: 165°C + | E37: 40°C | F37: = 300°C | G37: 5.7 s
A38: Rotor ER | B38: 95°C + | D38: 85°C + | E38: 40°C | F38: = 220°C | G38: 31.6 s
A40: Cold Stall Time: | B40: 22.1 s | D40: Hot Stall Time: | F40: 10.4 s

Sheet Performance Data Sheet
A1: TOSHIBA INTERNATIONAL CORPORATION | J1: INDEX | L1: MPCF-1033
A2: Industrial Division / Houston Motor Plant | J2: SHEET NO. | L2: 1 of 1
J3: ISSUED | L3: 7/31/13
J4: SUPERSEDES | L4: 11/8/96
J5: REVISION | L5: 2
A6: SQUIRREL CAGE INDUCTION MOTOR | J6: WRITTEN BY | L6: MDC
A7: PERFORMANCE SPECIFICATIONS | J7: APPROVED BY | L7: PAA
B9: CUSTOMER: | C9: SULZER PUMPS MEXICO S.A. DE C.V.
B10: TIC SR No.: | C10: 2182344.3
A12: MOTOR NAMEPLATE DATA
B13: H.P.: | C13: 450 | E13: VOLTS: | F13: 4000 | H13: 3 PH / | I13: 60 Hz | L13: S. RPM: | M13: 1800
B14: FRAME: | C14: 5012US | E14: ENCL: | F14: WP-II | H14: FLAMPS: | I14: 59 | L14: FLRPM: | M14: 1775
B15: FORM: | C15: DCW4 | E15: S.F.: | F15: 1.0 | H15: NEMA DESIGN: | I15: B | L15: INSUL CLASS: | M15: F
B16: TYPE: | C16: TIKE | E16: AMB.: | F16: 40°C | H16: CODE: | I16: F | L16: DUTY: | M16: Cont.
B17: MODEL No.: | C17: A1-10033109 | H17: kW: | I17: 336
B18: NOM. EFF.: | C18: 93 | E18: MIN. EFF.: | F18: - | H18: P.F.: | I18: 88.5
A21: AMPERAGE | E21: TORQUES | I21: **BEARINGS:
C22: LOCKED ROTOR: | D22: 353 | G22: FULL LOAD (lb-ft.): | H22: 1332 | K22: DRIVE END: | L22: REFER TO NP
G23: LOCKED ROTOR (%): | H23: 135 | K23: OPPOSITE DRIVE END: | L23: REFER TO NP
G24: BREAK DOWN (%): | H24: 275
A28: EFFICIENCY | H28: POWER FACTOR
C29: FULL LOAD: | D29: 93.1 | J29: FULL LOAD: | K29: 88.7
C30: 3/4 LOAD: | D30: 93.2 | J30: 3/4 LOAD: | K30: 85.6
C31: 1/2 LOAD: | D31: 92.7 | J31: 1/2 LOAD: | K31: 77.3
A35: ALL CHARACTERISTICS ARE AVERAGE EXPECTED VALUES BASED UPON RATED VOLTAGE,
A36: FREQUENCY AND SINEWAVE POWER INPUT.
A37: THE DECLARED LOCKED ROTOR CURRENT HAS A TOLERANCE OF 20%.
A38: * TEMPERATURE RISE WILL BE CONSISTENT WITH INSULATION, AMBIENT AND SERVICE FACTOR AS
A39: DEFINED BY NEMA-MG-12 OR -20.
A40: ** BEARINGS ARE THE ONLY RECOMMENDED SPARE PART(S).
J42: CERTIFIED BY: | K42: Zichao Xie
J44: DATE: | K44: 44021
A59: - | B59: 6205ZZ | D59: 1 | E59: -
A60: TEFC | B60: 6206UU | D60: 1.15 | E60: A
A61: ODP | B61: 6207ZZ | E61: B
B62: 6208UU
B63: 6211ZZ
B64: 6211C3
B65: 6211ZZC3
B66: 6305UUC3
...

Sheet STCurve
A2: TOSHIBA INTERNATIONAL CORPORATION
A3: Speed Torque/Current Curve
A6: Model #: | B6: ='Performance Data Sheet'!C17 -> A1-10033109 | E6: FLAmps: | F6: ='Performance Data Sheet'!I14 -> 59
A7: Enclosure: | B7: ='Performance Data Sheet'!F14 -> WP-II | C7: Voltage: | D7: ='Performance Data Sheet'!F13 & " V" -> 4000 V | E7: Frame: | F7: ='Performance Data Sheet'!C14 -> 5012US
A8: Pole: | B8: 4 | C8: Frequency: | D8: 3 PH / 60 Hz | E8: Ins. Class: | F8: ='Performance Data Sheet'!M15 -> F
A9: HP: | B9: ='Performance Data Sheet'!C13 -> 450 | C9: Rotor Inertia: | D9: 123.4 lb-ft² | E9: Date: | F9: ='Performance Data Sheet'!K44 -> 44021
A10: FLRPM: | B10: ='Performance Data Sheet'!M14 -> 1775 | C10: Load Inertia: | D10: 152.4 lb-ft² | E10: File: | F10: DT4450K
B12: Locked Rotor Amps: | C12: ='Performance Data Sheet'!D22 & " A" -> 353 A | D12: Load Type: | E12: Fan / Pump
B13: Locked Rotor Torque: | C13: ='Performance Data Sheet'!H23/100 -> 1.35 | D13: Starting at: | E13: FV / 0.80 (V)
B14: Breakdown Torque: | C14: 2.75 | D14: Accel. Time: | E14: 1.0 / 1.8 (s)
B15: Rated Torque: | C15: ='Performance Data Sheet'!H22 & " lb-ft" -> 1332 lb-ft
A39: Comments: | B39: PROJECT | C39: ='Performance Data Sheet'!C10 -> 2182344.3 | E39: D.E.Curve #: | F39: =F10 -> DT4450K
C43: Prepared by: | D43: ='Performance Data Sheet'!K42 -> Zichao Xie | E43: Checked by:
D53: Load | E53: Torque 80% | F53: LRA 80%
A54: 100 | B54: 0 | C54: 0.27908942 | D54: 100 | E54: 0 | F54: 13.173021
A55: 99.3 | B55: 72.311682 | C55: 79.240234 | D55: 98.599998 | E55: 46.279479 | F55: 63.392189
A56: 96.5 | B56: 250.60271 | C56: 294.15884 | D56: 91.125 | E56: 160.38574 | F56: 235.32707
A57: 93 | B57: 275 | C57: 428.28452 | D57: 81.800003 | E57: 176.00001 | F57: 342.62762
A58: 87.833333 | B58: 198.44489 | C58: 485.64484 | D58: 68.366669 | E58: 127.00473 | F58: 388.51587
A59: 82.666667 | B59: 170.673 | C59: 513.91986 | D59: 55.866669 | E59: 109.23072 | F59: 411.13589
A60: 72.333333 | B60: 150.49269 | C60: 541.12219 | D60: 36.966667 | E60: 96.315325 | F60: 432.89777
A61: 62 | B61: 142.34381 | C61: 555.45764 | D61: 24.200001 | E61: 91.100042 | F61: 444.36612
A62: 51.666668 | B62: 138.7498 | C62: 565.6615 | D62: 15.333334 | E62: 88.799876 | F62: 452.52921
A63: 41.33333 | B63: 136.98821 | C63: 574.06726 | D63: 8.7999973 | E63: 87.672454 | F63: 459.25381
A64: 31 | B64: 136.03277 | C64: 581.21661 | D64: 6.1999998 | E64: 87.060969 | F64: 464.9733
A65: 20.666665 | B65: 135.49055 | C65: 587.56482 | D65: 7.8666668 | E65: 86.713958 | F65: 470.05185
... A67: 0 | B67: 135 | C67: 598.30505 | D67: 30 | E67: 86.400003 | F67: 478.64404

Sheet Thermdam
A2: TOSHIBA INTERNATIONAL CORPORATION
A3: Thermal Limit & Acceleration Curves
A4: Design Values (For Reference Only)
A6: Model #: | B6: ='Performance Data Sheet'!C17 -> A1-10033109 | E6: FLAmps: | F6: ='Performance Data Sheet'!I14 -> 59
A7: Enclosure: | B7: ='Performance Data Sheet'!F14 -> WP-II | C7: Voltage: | D7: ='Performance Data Sheet'!F13 & " V" -> 4000 V | E7: Frame: | F7: ='Performance Data Sheet'!C14 -> 5012US
A8: Pole: | B8: 4 | C8: Frequency: | D8: 3 PH / 60 Hz | E8: Ins. Class: | F8: ='Performance Data Sheet'!M15 -> F
A9: HP: | B9: ='Performance Data Sheet'!C13 -> 450 | C9: Rotor Inertia: | D9: 123.4 lb-ft² | E9: Date: | F9: ='Performance Data Sheet'!K44 -> 44021
A10: FLRPM: | B10: ='Performance Data Sheet'!M14 -> 1775 | C10: Load Inertia: | D10: 152.4 lb-ft² | E10: File: | F10: DT4450K
C12: ='Performance Data Sheet'!D22 & " A" -> 353 A
C13: ='Performance Data Sheet'!H23/100 -> 1.35
C15: ='Performance Data Sheet'!H22 & " lb-ft" -> 1332 lb-ft
A39: Comments: | B39: PROJECT | C39: ='Performance Data Sheet'!C10 -> 2182344.3 | E39: D.E.Curve #: | F39: =F10 -> DT4450K
C43: Prepared by: | D43: ='Performance Data Sheet'!K42 -> Zichao Xie | E43: Checked by:
F50: =5252.1*B50/D53 -> #DIV/0!
D66: =D65/D64 -> #DIV/0!
A67: Current (%) | B67: Cold | C67: Hot | E67: CURRENT (%) | F67: Accel. Time | I67: CURRENT (%) | J67: Accel. Time
A68: 598.30508 | B68: 31.614053 | C68: 14.881785 | E68: =A68 -> 598.30508 | F68: 0.0001 | I68: =E68 -> 598.30508 | J68: 0.0001
A69: 532.8766 | B69: =((A68/A69)^2)*B68 -> 39.854032 | C69: =((A68/A69)^2)*C68 -> 18.760617 | E69: 476.61017 | F69: 0.19499999 | I69: 595.76271 | J69: 0.111
A70: 467.42848 | B70: =((A68/A70)^2)*B68 -> 51.79588 | C70: =((A68/A70)^2)*C68 -> 24.382042 | E70: 472.37288 | F70: 0.361 | I70: 590.33898 | J70: 0.212
A71: 402 | B71: =((A68/A71)^2)*B68 -> 70.02828 | C71: =((A68/A71)^2)*C68 -> 32.964638 | E71: 467.45763 | F71: 0.51800001 | I71: 584.40678 | J71: 0.30899999
A72: =A71-100 -> 302 | B72: =((A68/A72)^2)*B68 -> 124.08283 | E72: 462.0339 | F72: 0.67500001 | I72: 577.62712 | J72: 0.40599999
A73: =A72-100 -> 202 | B73: =((A68/A73)^2)*B68 -> 277.34659 | E73: 455.9322 | F73: 0.83899999 | I73: 569.83051 | J73: 0.50599998
A74: 275 | B74: =((A68/A74)^2)*B68 -> 149.6443 | C74: =((A68/A74)^2)*C68 -> 70.442544 | E74: 448.47458 | F74: 1.018 | I74: 560.50847 | J74: 0.60999995
A75: 180 | B75: =((A68/A75)^2)*B69 -> 440.32429 | C75: =((A68/A75)^2)*C68 -> 164.42029 | E75: 438.64407 | F75: 1.217 | I75: 548.30508 | J75: 0.71799994
A76: 120 | B76: =((A68/A76)^2)*B68 -> 785.89237 | C76: =((A68/A76)^2)*C68 -> 369.94565 | E76: 422.0339 | F76: 1.439 | I76: 527.45763 | J76: 0.82799995
A77: 110 | C77: =CEILING(C76*2,100) -> 800 | E77: 399.83051 | F77: 1.551 | I77: 499.83051 | J77: 0.87899995
A78: 110 | C78: =2*C77 -> 1600 | E78: 365.59322 | F78: 1.633 | I78: 456.94915 | J78: 0.91799992
A79: 110 | C79: 10000 | E79: 288.98305 | F79: 1.6850001 | I79: 361.18644 | J79: 0.94199991
E80: =110.2/59*100 -> 186.77966 | F80: 1.761 | I80: =110.2/59*100 -> 186.77966 | J80: 0.97599989

Sheet Performance
A2: TOSHIBA INTERNATIONAL CORPORATION
A3: Performance Curve
A4: Design Values (For Reference Only)
A6: Model #: | B6: ='Performance Data Sheet'!C17 -> A1-10033109 | E6: FLAmps: | F6: ='Performance Data Sheet'!I14 -> 59
A7: Enclosure: | B7: ='Performance Data Sheet'!F14 -> WP-II | C7: Voltage: | D7: ='Performance Data Sheet'!F13 & " V" -> 4000 V | E7: Frame: | F7: ='Performance Data Sheet'!C14 -> 5012US
A8: Pole: | B8: 4 | C8: Frequency: | D8: 3 PH / 60 Hz | E8: Ins. Class: | F8: ='Performance Data Sheet'!M15 -> F
A9: HP: | B9: ='Performance Data Sheet'!C13 -> 450 | C9: Rotor Inertia: | D9: 123.4 lb-ft² | E9: Date: | F9: ='Performance Data Sheet'!K44 -> 44021
A10: FLRPM: | B10: ='Performance Data Sheet'!M14 -> 1775 | C10: Load Inertia: | D10: 152.4 lb-ft² | E10: File: | F10: DT4450K
B12: Locked Rotor Amps: | C12: ='Performance Data Sheet'!D22 & " A" -> 353 A | D12: Load Type: | E12: Fan / Pump
B13: Locked Rotor Torque: | C13: ='Performance Data Sheet'!H23/100 -> 1.35 | D13: Starting at: | E13: FV / 0.80 (V)
B14: Breakdown Torque: | C14: 2.75 | D14: Accel. Time: | E14: 1.0 / 1.8 (s)
B15: Rated Torque: | C15: ='Performance Data Sheet'!H22 & " lb-ft" -> 1332 lb-ft
N36: SPEED | O36: KW
N37: =L43 - (L43-L44) / 10 * 0 -> 1800 | O37: =L45 / 10 * 10 -> 1000
N38: =L43 - (L43-L44) / 10 * 1 -> 1796 | O38: =L45 / 10 * 9 -> 900
A39: Comments: | B39: PROJECT | C39: ='Performance Data Sheet'!C10 -> 2182344.3 | E39: D.E.Curve #: | F39: =F10 -> DT4450K | N39: =L43 - (L43-L44) / 10 * 2 -> 1792 | O39: =L45 / 10 * 8 -> 800
N40: =L43 - (L43-L44) / 10 * 3 -> 1788 | O40: =L45 / 10 * 7 -> 700
N41: =L43 - (L43-L44) / 10 * 4 -> 1784 | O41: =L45 / 10 * 6 -> 600
N42: =L43 - (L43-L44) / 10 * 5 -> 1780 | O42: =L45 / 10 * 5 -> 500
C43: Prepared by: | D43: ='Performance Data Sheet'!K42 -> Zichao Xie | E43: Checked by: | K43: SYNC SPEED | L43: 1800 | N43: =L43 - (L43-L44) / 10 * 6 -> 1776 | O43: =L45 / 10 * 4 -> 400
K44: NEW SPEED LOWER RANGE | L44: 1760 | N44: =L43 - (L43-L44) / 10 * 7 -> 1772 | O44: =L45 / 10 * 3 -> 300
K45: NEW kW UPPER RANGE | L45: 1000 | N45: =L43 - (L43-L44) / 10 * 8 -> 1768 | O45: =L45 / 10 * 2 -> 200
N46: =L43 - (L43-L44) / 10 * 9 -> 1764 | O46: =L45 / 10 * 1 -> 100
N47: =L43 - (L43-L44) / 10 * 10 -> 1760 | O47: =L45 / 10 * 0 -> 0
A52: ADJUSTED
A53: Load | B53: Efficiency | C53: PF | D53: Amps | E53: RPM | F53: Input Watts
A54: 0 | D54: 16.5 | E54: 100 | F54: =7538/(L45*1000) * 100 -> 0.7538
A55: 25 | B55: 89.900002 | C55: 54.900002 | D55: 24.549999 | E55: =(1.010793*B10-L44)/(L43-L44)*100 -> 85.393938 | F55: =93377.98/(L45*1000)*100 -> 9.337798
A56: 50 | B56: 92.699997 | C56: 77.300003 | D56: 33.779999 | E56: =(1.007279*B10-L44)/(L43-L44)*100 -> 69.800563 | F56: =180908.8/(L45*1000)*100 -> 18.09088
A57: 75 | B57: 93.199997 | C57: 85.599998 | D57: 45.549999 | E57: =(1.003702*B10-L44)/(L43-L44)*100 -> 53.927625 | F57: =270136.2/(L45*1000)*100 -> 27.01362
A58: 100 | B58: 93.099998 | C58: 88.700005 | D58: 58.66 | E58: =(1*B10-L44)/(L43-L44)*100 -> 37.5 | F58: =360484.3/(L45*1000)*100 -> 36.04843
A59: 125 | B59: 92.699997 | C59: 89.700005 | D59: 72.839996 | E59: =(0.9962348*B10-L44)/(L43-L44)*100 -> 20.791925 | F59: =452671.3/(L45*1000)*100 -> 45.26713
A62: ORIGINAL
A63: Load | B63: Efficiency | C63: PF | D63: Amps | E63: RPM | F63: Input Watts
A64: 0 | D64: 16.52226 | E64: 100 | F64: 6.6175219
A65: 25 | B65: 89.872696 | C65: 54.862991 | D65: 24.550358 | E65: 79.07498 | F65: 9.3313654
A66: 50 | B66: 92.694069 | C66: 77.32225 | D66: 33.77837 | E66: 65.166958 | F66: 18.094686
A67: 75 | B67: 93.188255 | C67: 85.558144 | D67: 45.547424 | E67: 50.845733 | F67: 26.998091
A68: 100 | B68: 93.060173 | C68: 88.697426 | D68: 58.661102 | E68: 36.006404 | F68: 36.047
A69: 125 | B69: 92.661766 | C69: 89.672081 | D69: 72.841225 | E69: 20.987557 | F69: 45.25248

Sheet Circuit Param
A1: TOSHIBA INTERNATIONAL CORPORATION | J1: INDEX | L1: MPCF-1109
A2: Industrial Division / Houston Motor Plant | J2: SHEET NO. | L2: 1 of 1
J3: ISSUED | L3: 38309
A4: EQUIVALENT CIRCUIT DATA | J4: SUPERSEDES | L4: NEW
J5: REVISION | L5: REV. 0
J6: WRITTEN BY | L6: MDC
A7: All Values are Presented in Ohms/Phase, Equivalent Wye Connection. | J7: APPROVED BY | L7: Paul Anderson
B9: CUSTOMER: | C9: SULZER PUMPS MEXICO S.A. DE C.V.
B10: TIC SR No.: | C10: 2182344.3
A12: MOTOR NAMEPLATE DATA
B13: H.P.: | C13: 450 | E13: VOLTS: | F13: 4000 | H13: 3 PH / | I13: 60 Hz | L13: S. RPM: | M13: 1800
B14: FRAME: | C14: 5012US | E14: ENCL: | F14: WP-II | H14: FLAMPS: | I14: 59 | L14: FLRPM: | M14: 1775
B15: FORM: | C15: DCW4 | E15: S.F.: | F15: 1.0 | H15: NEMA DESIGN: | I15: B | L15: INSUL CLASS: | M15: F
B16: TYPE: | C16: TIKE | E16: AMB.: | F16: 40°C | H16: CODE: | I16: F | L16: DUTY: | M16: Cont.
B17: MODEL No.: | C17: A1-10033109 | H17: kW: | I17: 336
B18: NOM. EFF.: | C18: 93 | E18: MIN. EFF.: | F18: - | H18: P.F.: | I18: 88.5
A21: Primary Resistance (R1) : | G21: 0.67389174
A22: Secondary Resistance (R2) : | G22: 0.57627387
A23: Starting Secondary Resistance (R3) : | G23: 1.3935574
A25: Primary Reactance (X1) : | G25: 4.0112664
A26: Secondary Reactance (X2) : | G26: 3.3205343
A27: Starting Secondary Reactance (X3) : | G27: 2.9039498
A29: Magnetizing Reactance (Xm) : | G29: 140.21864
A31: Transient Reactance : | G31: 7.2549858
A32: Sub Transient Reactance : | G32: 5.5434891
A33: Short Circuit Time Constant : | G33: 3.3384846
A34: Sub Transient Time Constant : | G34: 0.0089413101
A35: Open Circuit Time Constant : | G35: 0.66070929
I40: CERTIFIED BY: | J40: Zichao Xie
I42: DATE: | J42: 44021

Sheet Performance API
A1: TOSHIBA INTERNATIONAL CORPORATION | J1: INDEX | L1: MPCF-1082
A2: Industrial Division / Houston Motor Plant | J2: SHEET NO. | L2: 1 of 1
J3: ISSUED | L3: 2/14/02
J4: SUPERSEDES | L4: NEW
J5: REVISION | L5: 0
A6: SQUIRREL CAGE INDUCTION MOTOR | J6: WRITTEN BY | L6: M. CAMPBELL
A7: API 541 PERFORMANCE SPECIFICATIONS | J7: APPROVED BY | L7: P.A.A
B9: CUSTOMER: | C9: SULZER PUMPS MEXICO S.A. DE C.V.
B10: TIC SR No.: | C10: 2182344.3
A12: MOTOR NAMEPLATE DATA
B13: H.P.: | C13: 450 | E13: VOLTS: | F13: 4000 | H13: 3 PH / | I13: 60 Hz | L13: S. RPM: | M13: 1800
B14: FRAME: | C14: 5012US | E14: ENCL: | F14: WP-II | H14: FLAMPS: | I14: 59 | L14: FLRPM: | M14: 1775
B15: FORM: | C15: DCW4 | E15: S.F.: | F15: 1.0 | H15: NEMA DESIGN: | I15: B | L15: INSUL CLASS: | M15: F
B16: TYPE: | C16: TIKE | E16: AMB.: | F16: 40°C | H16: CODE: | I16: F | L16: DUTY: | M16: Cont.
B17: MODEL No.: | C17: A1-10033109 | H17: kW: | I17: 336
B18: NOM. EFF.: | C18: 93 | E18: MIN. EFF.: | F18: - | H18: P.F.: | I18: 88.5
A20: LOCKED ROTOR DATA
D21: AMPS AT RATED VOLTAGE: | E21: 353 A | I21: POWER FACTOR: | J21: 0.262
D22: AMPS AT 80% VOLTAGE: | E22: 276 A
A24: TORQUE VALUES | H24: CURVE NUMBERS
E25: FULL LOAD (LB.FT): | F25: 1332 | J25: SPEED-TORQUE CURVE: | K25: DT4450K
E26: LOCKED ROTOR TORQUE (% OF FLT): | F26: 135 | J26: SPEED-CURRENT CURVE: | K26: DT4450K
E27: PULL UP TORQUE (% OF FLT): | F27: 135 | J27: ACCELERATION CURVE: | K27: DT4450K
E28: BREAKDOWN TORQUE (% OF FLT): | F28: 275
A30: LOCKED ROTOR WITHSTAND TIMES
A31: COLD CONDITION | H31: HOT CONDITION
C32: 100% VOLTAGE: | D32: 31 (s) | J32: 100% VOLTAGE: | K32: 14 (s)
C33: 90% VOLTAGE: | D33: 39 (s) | J33: 90% VOLTAGE: | K33: 18 (s)
C34: 80% VOLTAGE: | D34: 49 (s) | J34: 80% VOLTAGE: | K34: 23 (s)
C35: 70% VOLTAGE: | D35: 64 (s) | J35: 70% VOLTAGE: | K35: 30 (s)
A37: DESIGN DATA
C38: MOTOR ROTOR wk2 (LB.FT2): | D38: 123.4 | J38: NO LOAD CURRENT: | K38: 16.47 A
C39: AIR GAP: | D39: 1.7 mm | J39: ACCELERATION TIME: | K39: 1 / 2 (s)
D40: LOAD CHARACTERISTICS
D41: LOAD | G41: 1/2 | H41: 3/4 | I41: FULL | J41: SF
D42: AMPS (A) | G42: 33.78 | H42: 45.55 | I42: 58.66 | J42: -
D43: EFFICIENCY (%) | G43: 92.7 | H43: 93.2 | I43: 93.1 | J43: -
D44: POWER FACTOR (%) | G44: 77.3 | H44: 85.6 | I44: 88.7 | J44: -
D45: GUARENTEED EFFICIENCY (%) | G45: - | H45: - | I45: - | J45: -
A46: EFFICIENCY TO BE DETERMINED BY IEEE 112, METHOD B
...
