Workbook
Name Print_Area_MI: 'Circuit Param.'!$A$8:$N$43
Name Print_Area_MI: 'PERFORMANCE data'!$A$10:$N$18
Name Print_Area_MI: 'Performance Data Sheet'!$A$10:$N$42

Sheet DesignSheet
A1: TOSHIBA INTERNATIONAL CORPORATION | I1: Calc. Code: | J1: 2-2-2-0-1-2
A2: 3-PHASE SQUIRREL CAGE INDUCTION MOTOR DESIGN SHEET | J2: B.L.-1 P.F.-1
A3: File: | B3: N:\DESPRO\RAT FILES\DT4700K.rat | G3: Date: | H3: 44046 | I3: Time: | J3: 0.46304398
A4: Pole | B4: HP | C4: RPM | D4: Form | E4: Voltage | F4: Frequency | G4: Temperature | H4: FLSpeed | I4: FLSlip | J4: Frame
A5: 4 | B5: 700.00002 | C5: 1800 | D5: DCKW | E5: 4000 | F5: 60 | G5: 105 | H5: 1776.4 / 1773.9 | I5: 0.0131 / 0.0145 | J5: 5011/12
A6: Core Data | D6: Winding Data | H6: Constant Data
B7: Primary | C7: Secondary | F7: Bar | G7: End Ring | H7: St. Slot Pitch | I7: 20.420335 | J7: LR Test Data
A8: Air Gap | B8: 1.7 | H8: Rt. Slot Pitch | I8: 27.603152 | J8: ES
A9: Space Fac. | B9: 0.93000001 | D9: Pitch | E9: 1 ~ 14 | F9: Cross Section Area | H9: Mean Value | I9: 24.011744 | J9: 725.39813
A10: Core Length | B10: 530 | C10: 530 | F10: UB: 200.0 | G10: UER: 1375.0 | H10: Eff.T.W.St. | I10: 12.416524 | J10: WS
A11: OD | B11: 590 | C11: 386.6 | D11: Coil Pitch | E11: 0.86658 | H11: Eff.T.W.Rt. | I11: 26.848829 | J11: 29663.967
A12: ID | B12: 390 | C12: 220 | D12: Slot Fill | E12: - | F12: EBL: 40.0 | G12: ERD1: 282.5 | H12: St.Carter Fac. | I12: 1.2245199 | J12: IS
A13: Core Depth | B13: 54 | C13: 56.250001 | D13: Con./Slot | E13: 14 | G13: ERT: 55.00 | H13: Rt.Carter Fac. | I13: 1.0280952 | J13: 86.228142
A14: Eff.Core L. | B14: 390.60001 | C14: 390.60001 | D14: Wire Size 1 | E14: (.081"x.162")x2 | F14: (8 x 25) | G14: ERH: 25.00 | H14: Carter Factor | I14: 1.2589231 | J14: Volts / Turn
A15: Slot Data | D15: Wire Size 2 | E15: - | H15: Short. Factor | I15: 0.97811905 | J15: 16.496205
A16: Number | B16: 60 | C16: 44 | D16: // Circuits | E16: 1 | H16: Distrib. Factor | I16: 0.956506 | J16: AC
A17: Kind | B17: Open | C17: Rectang | D17: Connection | E17: Wye | H17: Wind. Factor | I17: 0.93557674 | J17: 591.17247
A18: Skew | B18: - | C18: 0 | D18: MCL | E18: 1005 | F18: 665 | H18: Reactance | I18: (Coeff.: 0.0889)
A19: Depth | B19: 46 | C19: 27.049999 | D19: No.Cond./Ph. | E19: 280 | I19: Running | J19: Start
A20: Width | B20: 8.00 - 8.00 | C20: 8.0500002 | D20: Res. (20°C) | E20: 0.30048615 | H20: Stator Slot | I20: 17.917881 | J20: 17.917881
A21: Opening | B21: 11.6 | C21: 3 | D21: (105°C) | E21: 0.40084499 | F21: 0.36625892 | G21: 0.013784997 | H21: Rotor Slot | I21: 18.340248 | J21: 13.927567
A22: Tip Depth | B22: 2.8299999 | C22: 2 | D22: Material | E22: CU | F22: CU | G22: CU | H22: Zigzag | I22: 7.4954615 | J22: 4.9136882
A23: T.Min.Wid. | B23: 8.8203344 | C23: 15.690769 | D23: Spec.Resist. | E23: 1.742 | F23: 1.742 | G23: 1.742 | H23: Coil End | I23: 12.306866 | J23: Skew R.: 0.00
A24: Low. R. | B24: 0 | C24: 0.80000001 | D24: Spec.Gravity | E24: 8.8900003 | F24: 8.8900003 | G24: 8.8900003 | H24: Belt Leakage | I24: 5.312369 | J24: 3.5774839
A25: Up. R. | B25: - | C25: 0.80000001 | D25: Weight (kg) | H25: Total Resist. | I25: 0.78088892 | J25: 1.3298723
A26: Wedge Dep. | B26: 2.40 - 2.00 | C26: Magnetic | D26: Wire 1 | E26: 122.43199 | F26: 56.327042 | G26: 23.617238 | H26: Total React. | I26: 5.4559937 | J26: 4.6715236
A27: Duct | B27: 11 x 10 | C27: 11 x 10 | D27: Wire 2 | E27: - | F27: - | G27: - | H27: Impedance | I27: 5.5115929 | J27: 4.8571277
A28: Effective Depth (S=1) | D28: Magnetic Circuit Data | I28: Core Loss Data
B29: Res.= | C29: 25.040984 | E29: Length | F29: Section | G29: Density | H29: AT | I29: Volume | J29: Loss | M29: =RIGHT(F$41,SEARCH("/",F$41,1)-1) -> 1767.7 | N29: 125RPM
B30: Reac.= | C30: 25.047422 | D30: Primary Core | E30: 23.169226 | F30: 421.84801 | G30: 15.689692 | H30: 330.98783 | I30: 35517.329 | J30: 2613.964 | M30: =RIGHT(E$41,SEARCH("/",E$41,1)-1) -> 1773.9 | N30: 100RPM
A31: Excitation Data | D31: Tooth | E31: 4.6 | F31: 516.7834 | G31: 12.807426 | H31: 31.781077 | I31: 9508.8146 | J31: 503.70764 | M31: =RIGHT(D$41,SEARCH("/",D$41,1)-1) -> 1780.1 | N31: 75RPM
A32: Excit.Amps | B32: 20.099 / 17.215 | D32: Second.Core | E32: 13.057233 | F32: 439.42501 | G32: 15.062104 | H32: 153.12999 | I32: Total | J32: 3117.6716 | M32: =RIGHT(C$41,SEARCH("/",C$41,1)-1) -> 1786.0 | N32: 50RPM
A33: Core Loss | B33: 0.842 / 0.721 | C33: Flux / Pole | D33: Tooth | E33: 2.7049999 | F33: 674.1696 | G33: 9.8175078 | H33: 8.2252353 | I33: C.L.C. | J33: 1.50 / 1.23 | M33: =RIGHT(B$41,SEARCH("/",B$41,1)-1) -> 1791.7 | N33: 25RPM
A34: NoLoad | B34: 20.12 / 17.23 | C34: 6.6186653 | D34: Air Gap | E34: 0.17 | F34: 1021.8902 | G34: 6.4768852 | H34: 876.20482 | I34: S.F.C. | J34: 6.0500002
A35: Load Characteristics | D35: Temp. Rise @ 100%: | E35: 75 / 71 | G35: No Load Loss | H35: 7804.1 / 9093.9 | I35: W.Loss | J35: 4676.5 / 3849.0
A36: Load (%) | B36: 25 | C36: 50 | D36: 75 | E36: 100 | F36: 125 | G36: Primary Loss | H36: 8941.2 / 9316.9 | I36: S.Loss | J36: 1163.4 / 957.5
A37: Current (A) | B37: 29.68 / 29.69 | C37: 46.16 / 46.18 | D37: 65.45 / 65.47 | E37: 86.23 / 86.27 | F37: 108.36 / 108.40 | G37: Second. Loss | H37: 7227.7 / 5867.5 | I37: Total C.Loss | J37: 5839.9 / 4806.5
A38: Efficiency | B38: 0.937 / 0.918 | C38: 0.958 / 0.939 | D38: 0.960 / 0.941 | E38: 0.958 / 0.939 | F38: 0.954 / 0.935 | G38: Frict.& Wind. | H38: 1600.0 / 4783.2 | I38: Stray Loss | J38: 9172.166 | L38: =LEFT(E38,SEARCH("/",E38,1)-1) -> 0.958 | M38: =RIGHT(E38,SEARCH("/",E38,1)-1) -> 0.939 | N38: =M38/L38 -> 0.98016701 | O38: Eff.
A39: P.F. | B39: 0.678 / 0.691 | C39: 0.852 / 0.869 | D39: 0.899 / 0.917 | E39: 0.912 / 0.930 | F39: 0.912 / 0.930 | G39: Starting Data | I39: Slip | J39: PF | L39: =LEFT(E39,SEARCH("/",E39,1)-1) -> 0.912 | M39: =RIGHT(E39,SEARCH("/",E39,1)-1) -> 0.930 | N39: =M39/L39 -> 1.0197368 | O39: PF.
A40: Slip | B40: 0.0032 / 0.0046 | C40: 0.0064 / 0.0078 | D40: 0.0096 / 0.0110 | E40: 0.0131 / 0.0145 | F40: 0.0165 / 0.0179 | G40: LRA | H40: 475.5 / 542.3 | L40: =LEFT(E37,SEARCH("/",E37,1)-1) -> 86.23 | M40: 86 | N40: =M40/L40 -> 0.99733271 | O40: Current
...

Sheet Data Sheet
A1: TOSHIBA INTERNATIONAL CORPORATION
A2: INDUCTION MOTOR DATA SHEET
A3: File: | B3: DT4700K | I3: HRW / Model Number: | J3: 7004WTAK11F-C
A4: Type: TIKE - Form: DCKW - 4 Pole - 700 HP - 4000 V - 60 Hz - 5011/12 - Class F | Q4: Motor Type Selection | T4: Electrical Steel Table
A5: Motor Parameters | F5: PERFORMANCE | J5: DESIGN | K5: TEST | Q5: EPACT | T5: M22 - 26Ga.
A6: Material | D6: M22 - 26Ga. | F6: NL & Impedance Test | Q6: EQP-III | T6: M36 - 26Ga.
A7: Air Gap | D7: 1.7 | F7: No load amps | J7: 17.2 | K7: - | Q7: Exp.Prf. | T7: NCB1 - 26Ga.
A8: Stack length | D8: 530 | F8: No load watts | J8: 9094 | K8: - | Q8: Exp.Prf.-EQPIII | T8: M43 - 26Ga.
A9: Number of turns per coil | D9: 7 | F9: Impedance amps | H9: 3 | I9: f | J9: 137 | K9: - | Q9: Prem. Eff. | T9: M45 - 26Ga.
A10: Wire 1 (061-0014-07) | D10: (.081"x.162")x2 | F10: Impedance volts | H10: 3 | I10: f | J10: 1150 | K10: - | Q10: Standard Eff. | T10: M54 - 26Ga.
A11: Wire 2 (size & number) | D11: - | F11: Impedance watts | H11: 3 | I11: f | J11: 29664 | K11: - | Q11: OWP | T11: TIPA Lam
A12: Slot fill - circle/square method (%) | D12: - | F12: Temperature Rise (°C) | Q12: Dry Kiln
A13: Connection | D13: 1 x Wye | G13: Winding | I13: 80/115 | J13: 75 / 99 | K13: -
A14: MCL | D14: 1005 | G14: Frame | J14: - | K14: -
A15: Allowance for ins. depth | D15: 11.566401 | G15: Bearing PS/OS | J15: - | K15: -
A16: Allowance for ins. width | D16: 2.9704003 | G16: End Ring | J16: - | K16: -
A17: Slot/Wire arrangement | D17: 14 x 2 | F17: Nameplate Data
A18: Effective cross section for coil | D18: - | H18: FLC (A) | J18: 86 | M18: =J18*6.5 -> 559
A19: Coil grouping | D19: - | H19: RPM | J19: 1770
A20: Coil pitch (slot number) | D20: 1 ~ 14 | H20: CODE | J20: F
A21: Method of coil connection | D21: - | H21: S. F. | J21: 1.15 | Q21: Method of Connection
A22: Resistance per phase @ 20 °C | D22: 0.30050001 | H22: DESIGN | J22: - | Q22: Skip
A23: Coil Weight | B23: Wire1 | D23: 269.4 | H23: Nom.Eff. (%): | J23: - | Q23: Adjacent
A24: (lbs.) | B24: Wire2 | D24: - | H24: Min.Eff. (%): | J24: - | Q24: -
A25: Current Densities (A/cm2) | E25: Bar / ER | H25: P.F. (%): | J25: -
A26: FL / LR | D26: 529 / 3334 | E26: 711 / 364
A27: Stator Slot Shape (Reference) | F27: Performance
H28: LRC (A) | I28: - | J28: 542 | K28: - | M28: =(J28/J18)*100 -> 630.23256
H29: LRT (%) | I29: 60 | J29: 137 | K29: -
H30: BDT (%) | I30: 175 | J30: 274 | K30: -
H31: SLIP (%) | J31: 1.45 | K31: -
G32: IEEE-B | H32: Eff. (%) | J32: 93.9 | K32: -
A33: Rotor Slot Shape (Reference) | H33: PF (%) | J33: 93 | K33: -
F34: Losses (Watts) | H34: Primary | J34: 9317 | K34: -
H35: Secondary | J35: 5868 | K35: -
H36: Core | J36: 4807 | K36: -
H37: F & W | J37: 4783 | K37: -
H38: Stray | J38: 9172 | K38: -
A39: End Ring (Reference) | F39: Note | G39: DT4700K
F40: LINK: H202029_800HP_4000V(Cu).rat &
...

Sheet StallTime
A1: Rating: | B1: 4 Pole - 700.0 HP - 1800 RPM - 4000 V - 60 Hz
A3: Starting Performance
D4: Load Type: Fan / Pump - 611.1 lb-ft²
A5: RPM | B5: Motor | C5: Load | D5: Accel. | E5: Line | F5: Stator | G5: Rotor
A6: Speed Increment | B6: Torque (%) | C6: Torque (%) | D6: Time (s) | E6: Amps | F6: kW / s | G6: kW / s
A7: 0~180 | B7: 135.0 | C7: 22.5 | D7: 0.207 | E7: 539.4 | F7: 73.0 | G7: 157.2
A8: 180~360 | B8: 135.0 | C8: 11.5 | D8: 0.188 | E8: 533.9 | F8: 65.2 | G8: 128.9
A9: 360~540 | B9: 135.0 | C9: 7.0 | D9: 0.182 | E9: 527.8 | F9: 61.6 | G9: 110.6
A10: 540~720 | B10: 135.0 | C10: 7.0 | D10: 0.182 | E10: 520.9 | F10: 60.1 | G10: 96.7
A11: 720~900 | B11: 135.0 | C11: 11.0 | D11: 0.187 | E11: 513.1 | F11: 60.3 | G11: 85.6
A12: 900~1080 | B12: 135.0 | C12: 18.0 | D12: 0.199 | E12: 503.9 | F12: 61.9 | G12: 75.6
A13: 1080~1296 | B13: 138.9 | C13: 29.2 | D13: 0.254 | E13: 492.2 | F13: 76.1 | G13: 64.5
A14: 1296~1512 | B14: 153.2 | C14: 47.6 | D14: 0.264 | E14: 473.1 | F14: 74.9 | G14: 49.6
A15: 1512~1620 | B15: 177.6 | C15: 66.4 | D15: 0.125 | E15: 448.0 | F15: 32.0 | G15: 30.8
A16: 1620~1728 | B16: 230.8 | C16: 81.9 | D16: 0.094 | E16: 409.6 | F16: 21.3 | G16: 16.9
... A18: 1764~1776 | B18: 173.1 | C18: 97.2 | D18: 0.021 | E18: 165.3 | F18: 0.2 | G18: 5.6
D21: Acceleration Time: 1.9 s
B22: Energy | D22: First Start | F22: Second Start
A23: Stator Winding Rise | B23: 592 kW / s | D23: 13°C | F23: 25°C
A24: Rotor Bar Rise | B24: 800 kW / s | D24: 37°C | F24: 74°C
A25: End Ring Rise | B25: 30 kW / s | D25: 3°C | F25: 7°C
A27: Locked Rotor Thermal Capability
E28: Cold Condition
B29: Rate of Rise | D29: Power | E29: Rise Limit | F29: Max Time
A30: Stator Copper | B30: 8.9°C / s | D30: 421.3 kW | E30: 160°C | F30: 17.9 s
A31: Rotor Bar | B31: 31.3°C / s | D31: 679.4 kW | E31: 260°C | F31: 8.3 s
A32: Rotor ER | B32: 2.8°C / s | D32: 25.6 kW | E32: 180°C | F32: 64.0 s
E34: Hot Condition
B35: Hot Temp. | D35: Rise Limit | E35: Ambient | F35: Total | G35: Max.Time
A36: Stator Copper | B36: 75°C + | D36: 85°C + | E36: 40°C | F36: = 200°C | G36: 9.5 s
A37: Rotor Bar | B37: 101°C + | D37: 159°C + | E37: 40°C | F37: = 300°C | G37: 5.1 s
A38: Rotor ER | B38: 101°C + | D38: 79°C + | E38: 40°C | F38: = 220°C | G38: 27.9 s
A40: Cold Stall Time: | B40: 19.0 s | D40: Hot Stall Time: | F40: 8.3 s

Sheet Performance Data Sheet
A1: TOSHIBA INTERNATIONAL CORPORATION | J1: INDEX | L1: MPCF-1033
A2: Industrial Division / Houston Motor Plant | J2: SHEET NO. | L2: 1 of 1
J3: ISSUED | L3: 7/31/13
J4: SUPERSEDES | L4: 11/8/96
J5: REVISION | L5: 2
A6: SQUIRREL CAGE INDUCTION MOTOR | J6: WRITTEN BY | L6: MDC
A7: PERFORMANCE SPECIFICATIONS | J7: APPROVED BY | L7: PAA
B9: CUSTOMER: | C9: SULZER PUMPS MEXICO S.A. DE C.V.
B10: TIC SR No.: | C10: 2182344.8
A12: MOTOR NAMEPLATE DATA
B13: H.P.: | C13: 700 | E13: VOLTS: | F13: 4000 | H13: 3 PH / | I13: 60 Hz | L13: S. RPM: | M13: 1800
B14: FRAME: | C14: 5012US | E14: ENCL: | F14: WP-II | H14: FLAMPS: | I14: 86 | L14: FLRPM: | M14: 1770
B15: FORM: | C15: DCKW | E15: S.F.: | F15: 1.0 | H15: NEMA DESIGN: | I15: - | L15: INSUL CLASS: | M15: F
B16: TYPE: | C16: TIKE | E16: AMB.: | F16: 40°C | H16: CODE: | I16: F | L16: DUTY: | M16: Cont.
B17: MODEL No.: | C17: A1-10033114 | H17: kW: | I17: -
B18: NOM. EFF.: | C18: 93.6 | E18: MIN. EFF.: | F18: - | H18: P.F.: | I18: 93
A21: AMPERAGE | E21: TORQUES | I21: **BEARINGS:
A22: LOCKED ROTOR: | D22: 542 | G22: FULL LOAD (lb-ft.): | H22: 2077 | K22: DRIVE END:
G23: LOCKED ROTOR (%): | H23: 135 | K23: OPPOSITE DRIVE END:
G24: BREAK DOWN (%): | H24: 270
A28: EFFICIENCY | H28: POWER FACTOR
C29: FULL LOAD: | D29: 93.9 | J29: FULL LOAD: | K29: 93
C30: 3/4 LOAD: | D30: 94.1 | J30: 3/4 LOAD: | K30: 91.7
C31: 1/2 LOAD: | D31: 93.9 | J31: 1/2 LOAD: | K31: 86.9
A35: ALL CHARACTERISTICS ARE AVERAGE EXPECTED VALUES BASED UPON RATED VOLTAGE,
A36: FREQUENCY AND SINEWAVE POWER INPUT.
A37: THE DECLARED LOCKED ROTOR CURRENT HAS A TOLERANCE OF 20%
A38: * TEMPERATURE RISE WILL BE CONSISTENT WITH INSULATION, AMBIENT AND SERVICE FACTOR AS
A39: DEFINED BY NEMA-MG-12 OR -20
A40: ** BEARINGS ARE THE ONLY RECOMMENDED SPARE PART(S).
J42: CERTIFIED BY: | K42: JERRY R
J44: DATE: | K44: 44046
A59: - | B59: 6205ZZ | D59: 1 | E59: -
A60: TEFC | B60: 6206UU | D60: 1.15 | E60: A
A61: ODP | B61: 6207ZZ | E61: B
B62: 6208UU
B63: 6211ZZ
B64: 6211C3
B65: 6211ZZC3
B66: 6305UUC3
...

Sheet STCurve
A2: TOSHIBA INTERNATIONAL CORPORATION
A3: Speed Torque/Current Curve
A6: Model #: | B6: ='Performance Data Sheet'!C17 -> A1-10033114 | E6: FLAmps: | F6: ='Performance Data Sheet'!I14 & " A" -> 86 A
A7: Enclosure: | B7: ='Performance Data Sheet'!F14 -> WP-II | C7: Voltage: | D7: ='Performance Data Sheet'!F13 & " V" -> 4000 V | E7: Frame: | F7: ='Performance Data Sheet'!C14 -> 5012US
A8: Pole: | B8: 4 | C8: Frequency: | D8: 3 PH / 60 Hz | E8: Ins. Class: | F8: F
A9: HP: | B9: 700 | C9: Rotor Inertia: | D9: 211.5 lb-ft² | E9: Date: | F9: ='Performance Data Sheet'!K44 -> 44046
A10: FLRPM: | B10: 1770 | C10: Load Inertia: | D10: 611.1 lb-ft² | E10: File: | F10: DT4700K
B12: Locked Rotor Amps: | C12: ='Performance Data Sheet'!D22 & " A" -> 542 A | D12: Load Type: | E12: Fan / Pump
B13: Locked Rotor Torque: | C13: 1.35 | D13: Starting at: | E13: FV / 0.80 (V)
B14: Breakdown Torque: | C14: 2.7 | D14: Accel. Time: | E14: 2 / 4 (s)
B15: Rated Torque: | C15: 2077 lb-ft
A39: Comments: | B39: PROJECT | C39: ='Performance Data Sheet'!C10 -> 2182344.8 | E39: D.E.Curve #: | F39: =F10 -> DT4700K
C43: Prepared by: | D43: ='Performance Data Sheet'!K42 -> JERRY R | E43: Checked by:
D53: Load | E53: Torque 80% | F53: LRA 80%
A54: 100 | B54: 0 | C54: 0.23391755 | D54: 100 | E54: 0 | F54: 16.093527
A55: 99.6 | B55: 70.859573 | C55: 78.313164 | D55: 99.199997 | E55: 45.350128 | F55: 62.650532
A56: 98 | B56: 246.17748 | C56: 306.16116 | D56: 95.25 | E56: 157.5536 | F56: 244.92894
A57: 96 | B57: 270 | C57: 446.44354 | D57: 89.75 | E57: 172.80001 | F57: 357.15485
A58: 90 | B58: 191.64405 | C58: 506.09784 | D58: 74 | E58: 122.6522 | F58: 404.87827
A59: 84 | B59: 163.56349 | C59: 535.70178 | D59: 58.799999 | E59: 104.68064 | F59: 428.56143
A60: 72 | B60: 142.81362 | C60: 564.48969 | D60: 36.400002 | E60: 91.400716 | F60: 451.59177
A61: 59.999999 | B61: 135 | C61: 580.18549 | D61: 22 | E61: 86.400003 | F61: 464.14841
A62: 50 | B62: 135.00016 | C62: 591.72455 | D62: 14 | E62: 86.40011 | F62: 473.37964
A63: 39.999998 | B63: 135.00074 | C63: 601.4245 | D63: 7.9999995 | E63: 86.400471 | F63: 481.13962
A64: 30.000001 | B64: 135.00104 | C64: 609.98889 | D64: 5.9999995 | E64: 86.400667 | F64: 487.99112
A65: 19.999999 | B65: 135.00141 | C65: 617.47632 | D65: 8.000001 | E65: 86.400901 | F65: 493.98105
... A67: 0 | B67: 135 | C67: 630.2326 | D67: 30 | E67: 86.400003 | F67: 504.1861

Sheet Thermdam
A2: TOSHIBA INTERNATIONAL CORPORATION
A3: Thermal Limit & Acceleration Curves
A4: Design Values (For Reference Only)
A6: Model #: | B6: ='Performance Data Sheet'!C17 -> A1-10033114 | E6: FLAmps: | F6: ='Performance Data Sheet'!I14 & " A" -> 86 A
A7: Enclosure: | B7: ='Performance Data Sheet'!F14 -> WP-II | C7: Voltage: | D7: ='Performance Data Sheet'!F13 & " V" -> 4000 V | E7: Frame: | F7: ='Performance Data Sheet'!C14 -> 5012US
A8: Pole: | B8: 4 | C8: Frequency: | D8: 3 PH / 60 Hz | E8: Ins. Class: | F8: F
A9: HP: | B9: 700 | C9: Rotor Inertia: | D9: 211.5 lb-ft² | E9: Date: | F9: ='Performance Data Sheet'!K44 -> 44046
A10: FLRPM: | B10: 1770 | C10: Load Inertia: | D10: 611.1 lb-ft² | E10: File: | F10: DT4700K
A39: Comments: | B39: PROJECT | C39: ='Performance Data Sheet'!C10 -> 2182344.8 | E39: D.E.Curve #: | F39: =F10 -> DT4700K
C43: Prepared by: | D43: ='Performance Data Sheet'!K42 -> JERRY R | E43: Checked by:
F50: =5252.1*B50/D53 -> #DIV/0!
D66: =D65/D64 -> #DIV/0!
A67: Current (%) | B67: Cold | C67: Hot | E67: CURRENT (%) | F67: Accel. Time
A68: 630.23256 | B68: 24 | C68: 12 | E68: =A68 -> 630.23256 | F68: 0.0001 | G68: =0.8*E68 -> 504.18605 | H68: =F68 -> 0.0001
A69: 556.82905 | B69: =((A68/A69)^2)*B68 -> 30.744621 | C69: =((A68/A69)^2)*C68 -> 15.372311 | E69: 627.2093 | F69: 0.21439673 | G69: =0.8*E69 -> 501.76744 | H69: =2*F69 -> 0.42879347
A70: 483.40351 | B70: =((A68/A70)^2)*B68 -> 40.79372 | C70: =((A68/A70)^2)*C68 -> 20.39686 | E70: 620.81395 | F70: 0.40911455 | G70: =0.8*E70 -> 496.65116 | H70: =2*F70 -> 0.81822909
A71: 410 | B71: =((A68/A71)^2)*B68 -> 56.708113 | C71: =((A68/A71)^2)*C68 -> 28.354057 | E71: 613.72093 | F71: 0.59761796 | G71: =0.8*E71 -> 490.97674 | H71: =2*F71 -> 1.1952359
A72: =A71-100 -> 310 | B72: =((A68/A72)^2)*B68 -> 99.194941 | E72: 605.69767 | F72: 0.78612135 | G72: =0.8*E72 -> 484.55814 | H72: =2*F72 -> 1.5722427
A73: =A72-100 -> 210 | B73: =((A68/A73)^2)*B68 -> 216.1595 | E73: 596.62791 | F73: 0.9798034 | G73: =0.8*E73 -> 477.30233 | H73: =2*F73 -> 1.9596068
A74: 270 | B74: =((A68/A74)^2)*B68 -> 130.76315 | C74: =((A68/A74)^2)*C68 -> 65.381577 | E74: 585.93023 | F74: 1.1859143 | G74: =0.8*E74 -> 468.74419 | H74: =2*F74 -> 2.3718285
A75: 180 | B75: =((A68/A75)^2)*B69 -> 376.89972 | C75: =((A68/A75)^2)*C68 -> 147.10855 | E75: 572.32558 | F75: 1.4489904 | G75: =0.8*E75 -> 457.86047 | H75: =2*F75 -> 2.8979808
A76: 145 | B76: =((A68/A76)^2)*B68 -> 453.39519 | C76: =((A68/A76)^2)*C68 -> 226.69759 | E76: 550.11628 | F76: 1.722424 | G76: =0.8*E76 -> 440.09302 | H76: =2*F76 -> 3.4448479
A77: 125 | C77: =CEILING(C76*2,100) -> 500 | E77: 520.93023 | F77: 1.8518906 | G77: =0.8*E77 -> 416.74419 | H77: =2*F77 -> 3.7037812
A78: 125 | C78: =2*C77 -> 1000 | E78: 476.27907 | F78: 1.9492495 | G78: =0.8*E78 -> 381.02326 | H78: =2*F78 -> 3.8984989
A79: 125 | C79: 10000 | E79: 376.27907 | F79: 1.97825 | G79: =0.8*E79 -> 301.02326 | H79: =2*F79 -> 3.9565
E80: 110 | F80: 2.0000004 | G80: 110 | H80: =2*F80 -> 4.0000008

Sheet Performance
A2: TOSHIBA INTERNATIONAL CORPORATION
A3: Performance Curve
A4: Design Values (For Reference Only)
A6: Model #: | B6: ='Performance Data Sheet'!C17 -> A1-10033114 | E6: FLAmps: | F6: ='Performance Data Sheet'!I14 & " A" -> 86 A
A7: Enclosure: | B7: ='Performance Data Sheet'!F14 -> WP-II | C7: Voltage: | D7: ='Performance Data Sheet'!F13 & " V" -> 4000 V | E7: Frame: | F7: ='Performance Data Sheet'!C14 -> 5012US
A8: Pole: | B8: 4 | C8: Frequency: | D8: 3 PH / 60 Hz | E8: Ins. Class: | F8: F
A9: HP: | B9: 700 | C9: Rotor Inertia: | D9: 211.5 lb-ft² | E9: Date: | F9: ='Performance Data Sheet'!K44 -> 44046
A10: FLRPM: | B10: 1770 | C10: Load Inertia: | D10: 611.1 lb-ft² | E10: File: | F10: DT4700K
B12: Locked Rotor Amps: | C12: ='Performance Data Sheet'!D22 & " A" -> 542 A | D12: Load Type: | E12: Fan / Pump
B13: Locked Rotor Torque: | C13: 1.35 | D13: Starting at: | E13: FV / 0.80 (V)
B14: Breakdown Torque: | C14: 2.7 | D14: Accel. Time: | E14: 2 / 4 (s)
B15: Rated Torque: | C15: 2077 lb-ft
A39: Comments: | B39: PROJECT | C39: ='Performance Data Sheet'!C10 -> 2182344.8 | E39: D.E.Curve #: | F39: =F10 -> DT4700K
C43: Prepared by: | D43: ='Performance Data Sheet'!K42 -> JERRY R | E43: Checked by:
A53: Load | B53: Efficiency | C53: PF | D53: Amps | E53: RPM | F53: Input Watts
A54: 0 | D54: 20.062594 | E54: 100 | F54: 2
A55: 25 | B55: 91.807617 | C55: 69.120232 | D55: 29.598408 | E55: 69.508761 | F55: 10.124029
A56: 50 | B56: 93.886055 | C56: 86.911942 | D56: 46.036438 | E56: 55.26299 | F56: 19.799809
A57: 75 | B57: 94.144783 | C57: 91.699837 | D57: 65.269249 | E57: 40.614873 | F57: 29.618089
A58: 100 | B58: 93.901184 | C58: 93.039253 | D58: 85.995331 | E58: 25.05243 | F58: 39.593228
A59: 125 | B59: 93.464287 | C59: 92.981834 | D59: 108.06334 | E59: 9.7586988 | F59: 49.722886

Sheet Circuit Param.
A1: TOSHIBA INTERNATIONAL CORPORATION | J1: INDEX | L1: MPCF-1109
A2: Industrial Division / Houston Motor Plant | J2: SHEET NO. | L2: 1 of 1
J3: ISSUED | L3: 38309
A4: EQUIVALENT CIRCUIT DATA | J4: SUPERSEDES | L4: NEW
J5: REVISION | L5: REV. 0
J6: WRITTEN BY | L6: MDC
A7: All Values are Presented in Ohms/Phase, Equivalent Wye Connection. | J7: APPROVED BY | L7: Paul Anderson
B9: CUSTOMER: | C9: SULZER PUMPS MEXICO S.A. DE C.V.
B10: TIC SR No.: | C10: 2182344.8
A12: MOTOR NAMEPLATE DATA
B13: H.P.: | C13: 700 | E13: VOLTS: | F13: 4000 | H13: 3 PH / | I13: 60 Hz | L13: S. RPM: | M13: 1800
B14: FRAME: | C14: 5012US | E14: ENCL: | F14: WP-II | H14: FLAMPS: | I14: 86 | L14: FLRPM: | M14: 1770
B15: FORM: | C15: DCKW | E15: S.F.: | F15: 1.0 | H15: NEMA DESIGN: | I15: - | L15: INSUL CLASS: | M15: F
B16: TYPE: | C16: TIKE | E16: AMB.: | F16: 40°C | H16: CODE: | I16: F | L16: DUTY: | M16: Cont.
B17: MODEL No.: | C17: A1-10033114 | H17: kW: | I17: -
B18: NOM. EFF.: | C18: 93.6 | E18: MIN. EFF.: | F18: - | H18: P.F.: | I18: 93
A21: Primary Resistance (R1) : | F21: 0.4008
A22: Secondary Resistance (R2) : | F22: 0.380
A23: Starting Resistance (R3) : | F23: 0.929
A25: Primary Reactance (X1) : | F25: 2.62
A26: Secondary Reactance (X2) : | F26: 2.33
A27: Starting Reactance (X3) : | F27: 1.95
A29: Magnetizing Reactance (Xm) : | F29: 135.8
A31: Transient Reactance : | F31: 4.92
A32: Sub Transient Reactance : | F32: 3.68
A33: Short Circuit Time Constant : | F33: 2.33
A34: Sub Transient Time Constant : | F34: 0.0091
A35: Open Circuit Time Constant : | F35: 0.964
I40: CERTIFIED BY: | J40: JERRY R
I42: DATE: | J42: 44046

Sheet PERFORMANCE data
A1: TOSHIBA INTERNATIONAL CORPORATION | J1: INDEX | L1: MPCF-1082
A2: Industrial Division / Houston Motor Plant | J2: SHEET NO. | L2: 1 of 1
J3: ISSUED | L3: 2/14/02
J4: SUPERSEDES | L4: NEW
J5: REVISION | L5: 0
A6: SQUIRREL CAGE INDUCTION MOTOR | J6: WRITTEN BY | L6: M. CAMPBELL
A7: API 541 PERFORMANCE SPECIFICATIONS | J7: APPROVED BY | L7: P.A.A
B9: CUSTOMER: | C9: SULZER PUMPS MEXICO S.A. DE C.V.
B10: TIC SR No.: | C10: 2182344.8
A12: MOTOR NAMEPLATE DATA
B13: H.P.: | C13: 700 | E13: VOLTS: | F13: 4000 | H13: 3 PH / | I13: 60 Hz | L13: S. RPM: | M13: 1800
B14: FRAME: | C14: 5012US | E14: ENCL: | F14: WP-II | H14: FLAMPS: | I14: 86 | L14: FLRPM: | M14: 1770
B15: FORM: | C15: DCKW | E15: S.F.: | F15: 1.0 | H15: NEMA DESIGN: | I15: - | L15: INSUL CLASS: | M15: F
B16: TYPE: | C16: TIKE | E16: AMB.: | F16: 40°C | H16: CODE: | I16: F | L16: DUTY: | M16: Cont.
B17: MODEL No.: | C17: A1-10033114 | H17: kW: | I17: -
B18: NOM. EFF.: | C18: 93.6 | E18: MIN. EFF.: | F18: - | H18: P.F.: | I18: 93
A20: LOCKED ROTOR DATA
D21: AMPS AT RATED VOLTAGE: | E21: 542 | I21: POWER FACTOR: | J21: 25.8
D22: AMPS AT 80% VOLTAGE: | E22: 423
A24: TORQUE VALUES | H24: CURVE NUMBERS
E25: FULL LOAD (LB.FT): | F25: 2077 | J25: SPEED-TORQUE CURVE: | K25: DT4700K
E26: LOCKED ROTOR TORQUE (% OF FLT): | F26: 135 | J26: SPEED-CURRENT CURVE: | K26: DT4700K
E27: PULL UP TORQUE (% OF FLT): | F27: 135 | J27: ACCELERATION CURVE: | K27: DT4700K
E28: BREAKDOWN TORQUE (% OF FLT): | F28: 270
A30: LOCKED ROTOR WITHSTAND TIMES
A31: COLD CONDITION | H31: HOT CONDITION
C32: 100% VOLTAGE: | D32: 24 | J32: 100% VOLTAGE: | K32: 12
C33: 90% VOLTAGE: | D33: 30 | J33: 90% VOLTAGE: | K33: 15
C34: 80% VOLTAGE: | D34: 38 | J34: 80% VOLTAGE: | K34: 19
C35: 70% VOLTAGE: | D35: 49 | J35: 70% VOLTAGE: | K35: 25
A37: DESIGN DATA
C38: MOTOR ROTOR wk2 (LB.FT2): | D38: 211.5 | J38: NO LOAD CURRENT: | K38: 17
C39: AIR GAP: | D39: 1.7 | J39: ACCELERATION TIME: | K39: 2 / 4
D40: LOAD CHARACTERISTICS
D41: LOAD | G41: 1/2 | H41: 3/4 | I41: FULL | J41: SF
D42: AMPS (A) | G42: 46.1 | H42: 65.5 | I42: 86 | J42: -
D43: EFFICIENCY (%) | G43: 93.9 | H43: 94.1 | I43: 93.9 | J43: -
D44: POWER FACTOR (%) | G44: 86.9 | H44: 91.7 | I44: 93 | J44: -
D45: GUARENTEED EFFICIENCY (%) | G45: - | H45: - | I45: - | J45: -
A46: EFFICIENCY TO BE DETERMINED BY IEEE 112, METHOD B
...
