Workbook
Name Print_Area_MI: 'Performance Data Sheet'!$A$10:$N$42

Sheet DesignSheet
A1: TOSHIBA INTERNATIONAL CORPORATION | I1: Calc. Code: | J1: 2-2-2-0-1-2
A2: 3-PHASE SQUIRREL CAGE INDUCTION MOTOR DESIGN SHEET | J2: B.L.-1 P.F.-1
A3: File: | B3: G:\DESPRO\RAT FILES\DT4M30U_ERchange.rat | G3: Date: | H3: 44473 | I3: Time: | J3: 0.65065972
A4: Pole | B4: HP | C4: RPM | D4: Form | E4: Voltage | F4: Frequency | G4: Temperature | H4: FLSpeed | I4: FLSlip | J4: Frame
A5: 4 | B5: 1500 | C5: 1800 | D5: DCW4 | E5: 4000 | F5: 60 | G5: 105 | H5: 1784.7 / 1788.6 | I5: 0.0085 / 0.0063 | J5: 5811/12
A6: Core Data | D6: Winding Data | H6: Constant Data
B7: Primary | C7: Secondary | F7: Bar | G7: End Ring | H7: St. Slot Pitch | I7: 22.252929 | J7: LR Test Data
A8: Air Gap | B8: 2.0999999 | H8: Rt. Slot Pitch | I8: 30.045024 | J8: ES
A9: Space Fac. | B9: 0.93000001 | D9: Pitch | E9: 1 ~ 14 | F9: Cross Section Area | H9: Mean Value | I9: 26.148977 | J9: 725.15334
A10: Core Length | B10: 620 | C10: 620 | F10: UB: 345.0 | G10: UER: 1824.0 | H10: Eff.T.W.St. | I10: 13.460342 | J10: WS
A11: OD | B11: 670 | C11: 420.8 | D11: Coil Pitch | E11: 0.86658 | H11: Eff.T.W.Rt. | I11: 29.414491 | J11: 53711.686
A12: ID | B12: 425 | C12: 220 | D12: Slot Fill | E12: - | F12: EBL: 45.0 | G12: ERD1: 342.8 | H12: St.Carter Fac. | I12: 1.2098288 | J12: IS
A13: Core Depth | B13: 65.5 | C13: 63.350001 | D13: Con./Slot | E13: 18 | G13: ERT: 48.00 | H13: Rt.Carter Fac. | I13: 1.0214361 | J13: 188.07933
A14: Eff.Core L. | B14: 455.70001 | C14: 455.70001 | D14: Wire Size 1 | E14: (.081"x.162")x1 | F14: (10 x 35) | G14: ERH: 38.00 | H14: Carter Factor | I14: 1.2357629 | J14: Volts / Turn
A15: Slot Data | D15: Wire Size 2 | E15: (.081"x.182")x1 | H15: Short. Factor | I15: 0.97811905 | J15: 25.660764
A16: Number | B16: 60 | C16: 44 | D16: // Circuits | E16: 2 | H16: Distrib. Factor | I16: 0.956506 | J16: AC
A17: Kind | B17: Open | C17: Rectang | D17: Connection | E17: Wye | H17: Wind. Factor | I17: 0.93557674 | J17: 760.67018
A18: Skew | B18: - | C18: 0 | D18: MCL | E18: 1135 | F18: 758 | H18: Reactance | I18: (Coeff.: 0.0429)
A19: Depth | B19: 57 | C19: 37.049999 | D19: No.Cond./Ph. | E19: 180 | I19: Running | J19: Start
A20: Width | B20: 8.79 - 8.79 | C20: 10.05 | D20: Res. (20°C) | E20: 0.10251083 | H20: Stator Slot | I20: 19.604923 | J20: 19.604923
A21: Opening | B21: 12.7 | C21: 3 | D21: (105°C) | E21: 0.13674824 | F21: 0.10042372 | G21: 0.015977099 | H21: Rotor Slot | I21: 19.673128 | J21: 12.498244
A22: Tip Depth | B22: 2.8299999 | C22: 2 | D22: Material | E22: CU | F22: CU | G22: CU | H22: Zigzag | I22: 6.699286 | J22: 4.1079082
A23: T.Min.Wid. | B23: 9.5529289 | C23: 14.70888 | D23: Spec.Resist. | E23: 1.742 | F23: 1.742 | G23: 1.742 | H23: Coil End | I23: 11.437058 | J23: Skew R.: 0.00
A24: Low. R. | B24: 0 | C24: 0.80000001 | D24: Spec.Gravity | E24: 8.8900003 | F24: 8.8900003 | G24: 8.8900003 | H24: Belt Leakage | I24: 4.7742621 | J24: 3.1450258
A25: Up. R. | B25: - | C25: 0.80000001 | D25: Weight (kg) | H25: Total Resist. | I25: 0.25314906 | J25: 0.50613385
A26: Wedge Dep. | B26: 2.40 - 2.00 | C26: Magnetic | D26: Wire 1 | E26: 88.887189 | F26: 108.76987 | G26: 38.894228 | H26: Total React. | I26: 2.6655366 | J26: 2.1677785
A27: Duct | B27: 13 x 10 | C27: 13 x 10 | D27: Wire 2 | E27: 100.27667 | F27: - | G27: - | H27: Impedance | I27: 2.6775305 | J27: 2.2260807
A28: Effective Depth (S=1) | D28: Magnetic Circuit Data | I28: Core Loss Data
B29: Res.= | C29: 35.001719 | E29: Length | F29: Section | G29: Density | H29: AT | I29: Volume | J29: Loss | M29: =RIGHT(F$41,SEARCH("/",F$41,1)-1) -> 1784.7 | N29: 125RPM | P29: Kline/in2
B30: Reac.= | C30: 35.036186 | D30: Primary Core | E30: 26.310816 | F30: 596.96702 | G30: 17.246684 | H30: 606.65357 | I30: 56684.739 | J30: 4862.8758 | M30: =RIGHT(E$41,SEARCH("/",E$41,1)-1) -> 1788.6 | N30: 100RPM | P30: =G30*6.4516 -> 111.26871
A31: Excitation Data | D31: Tooth | E31: 5.7 | F31: 652.99047 | G31: 15.767001 | H31: 83.445922 | I31: 14888.183 | J31: 1104.4833 | M31: =RIGHT(D$41,SEARCH("/",D$41,1)-1) -> 1792.6 | N31: 75RPM | P31: =G31*6.4516 -> 101.72238
A32: Excit.Amps | B32: 53.470 / 48.449 | D32: Second.Core | E32: 13.614866 | F32: 577.37192 | G32: 17.832009 | H32: 370.98836 | I32: Total | J32: 5967.3591 | M32: =RIGHT(C$41,SEARCH("/",C$41,1)-1) -> 1796.5 | N32: 50RPM | P32: =G32*6.4516 -> 115.04499
A33: Core Loss | B33: 1.599 / 1.449 | C33: Flux / Pole | D33: Tooth | E33: 3.7049999 | F33: 737.31207 | G33: 13.963832 | H33: 33.805318 | I33: C.L.C. | J33: 1.50 / 0.84 | M33: =RIGHT(B$41,SEARCH("/",B$41,1)-1) -> 1800.2 | N33: 25RPM | P33: =G33*6.4516 -> 90.089056
A34: NoLoad | B34: 53.49 / 48.47 | C34: 10.295702 | D34: Air Gap | E34: 0.20999999 | F34: 1323.547 | G34: 7.7788711 | H34: 1299.9491 | I34: S.F.C. | J34: 6.0500002 | P34: =G34*6.4516 -> 50.186165
A35: Load Characteristics | D35: Temp. Rise @ 100%: | E35: 90 / 85 | G35: No Load Loss | H35: 13968.2 / 10312.0 | I35: W.Loss | J35: 8951.0 / 5019.7
A36: Load (%) | B36: 25 | C36: 50 | D36: 75 | E36: 100 | F36: 125 | G36: Primary Loss | H36: 14511.9 / 14895.7 | I36: S.Loss | J36: 2137.9 / 1198.9
A37: Current (A) | B37: 71.45 / 71.94 | C37: 104.35 / 105.07 | D37: 144.36 / 145.36 | E37: 188.08 / 189.38 | F37: 234.86 / 236.48 | G37: Second. Loss | H37: 9907.9 / 7201.2 | I37: Total C.Loss | J37: 11088.9 / 6218.6
A38: Efficiency | B38: 0.947 / 0.941 | C38: 0.966 / 0.960 | D38: 0.970 / 0.963 | E38: 0.969 / 0.962 | F38: 0.966 / 0.960 | G38: Frict.& Wind. | H38: 2000.0 / 2758.0 | I38: Stray Loss | J38: 12858.128 | L38: =LEFT(E38,SEARCH("/",E38,1)-1) -> 0.969 | M38: =RIGHT(E38,SEARCH("/",E38,1)-1) -> 0.962 | N38: =M38/L38 -> 0.99277606 | O38: Eff.
A39: P.F. | B39: 0.597 / 0.596 | C39: 0.801 / 0.801 | D39: 0.865 / 0.865 | E39: 0.887 / 0.886 | F39: 0.890 / 0.890 | G39: Starting Data | I39: Slip | J39: PF | L39: =LEFT(E39,SEARCH("/",E39,1)-1) -> 0.887 | M39: =RIGHT(E39,SEARCH("/",E39,1)-1) -> 0.886 | N39: =M39/L39 -> 0.9988726 | O39: PF.
A40: Slip | B40: 0.0021 / -0.0001 | C40: 0.0042 / 0.0020 | D40: 0.0063 / 0.0041 | E40: 0.0085 / 0.0063 | F40: 0.0107 / 0.0085 | G40: LRA | H40: 1037.5 / 1258.9 | L40: =LEFT(E37,SEARCH("/",E37,1)-1) -> 188.08 | M40: =RIGHT(E37,SEARCH("/",E37,1)-1) -> 189.38 | N40: =M40/L40 -> 1.006912 | O40: Current
...

Sheet Data Sheet
A1: TOSHIBA INTERNATIONAL CORPORATION
A2: INDUCTION MOTOR DATA SHEET
A3: File: | B3: DT4M30U_ERchange | I3: HRW / Model Number: | J3: M305WTAL11E-C
A4: Type: TIKE - Form: DCW4 - 4 Pole - 1500 HP - 4000 V - 60 Hz - 5811/12 - Class F | Q4: Motor Type Selection | T4: Electrical Steel Table
A5: Motor Parameters | F5: PERFORMANCE | J5: DESIGN | K5: TEST | Q5: EPACT | T5: M22 - 26Ga.
A6: Material | D6: M22 - 26Ga. | F6: NL & Impedance Test | Q6: EQP-III | T6: M36 - 26Ga.
A7: Air Gap | D7: 2.0999999 | F7: No load amps | J7: 49 | K7: - | Q7: Exp.Prf. | T7: NCB1 - 26Ga.
A8: Stack length | D8: 620 | F8: No load watts | J8: 10312 | K8: - | Q8: Exp.Prf.-EQPIII | T8: M43 - 26Ga.
A9: Number of turns per coil | D9: 9 | F9: Impedance amps | H9: 3 | I9: f | J9: 298 | K9: - | Q9: Prem. Eff. | T9: M45 - 26Ga.
A10: Wire 1 (size & number) | D10: (.081"x.162")x1 | F10: Impedance volts | H10: 3 | I10: f | J10: 1150 | K10: - | Q10: Standard Eff. | T10: M54 - 26Ga.
A11: Wire 2 (size & number) | D11: (.081"x.182")x1 | F11: Impedance watts | H11: 3 | I11: f | J11: 53712 | K11: - | Q11: OWP | T11: TIPA Lam
A12: Slot fill - circle/square method (%) | D12: - | F12: Temperature Rise (°C) | Q12: Dry Kiln
A13: Connection | D13: 2 x Wye | G13: Winding | I13: 80/115 | J13: 90 / - | K13: -
A14: MCL | D14: 1135 | G14: Frame | J14: - | K14: -
A15: Allowance for ins. depth | D15: 13.5368 | G15: Bearing PS/OS | J15: - | K15: -
A16: Allowance for ins. width | D16: 3.5623999 | G16: End Ring | J16: - | K16: -
A17: Slot/Wire arrangement | D17: 18 x 2 | F17: Nameplate Data
A18: Effective cross section for coil | D18: - | H18: FLC (A) | J18: 189 | M18: =J18*6.5 -> 1228.5
A19: Coil grouping | D19: - | H19: RPM | J19: 1789
A20: Coil pitch (slot number) | D20: 1 ~ 14 | H20: CODE | J20: G
A21: Method of coil connection | D21: - | H21: S. F. | J21: 1 | Q21: Method of Connection
A22: Resistance per phase @ 20 °C | D22: 0.1025 | H22: DESIGN | J22: - | Q22: Skip
A23: Coil Weight | B23: Wire1 | D23: 195.6 | H23: Nom.Eff. (%): | J23: 96.2 | Q23: Adjacent
A24: (lbs.) | B24: Wire2 | D24: 220.6 | H24: Min.Eff. (%): | J24: - | Q24: -
A25: Current Densities (A/cm2) | E25: Bar / ER | H25: P.F. (%): | J25: 88.5
A26: FL / LR | D26: 545 / 3630 | E26: 564 / 375
A27: Stator Slot Shape (Reference) | F27: Performance
H28: LRC (A) | I28: - | J28: 1259 | K28: - | M28: =(J28/J18)*100 -> 666.13757
H29: LRT (%) | I29: 60 | J29: 137 | K29: -
H30: BDT (%) | I30: 175 | J30: 265 | K30: -
H31: SLIP (%) | J31: 0.63 | K31: -
G32: IEEE-B | H32: Eff. (%) | J32: 96.2 | K32: -
A33: Rotor Slot Shape (Reference) | H33: PF (%) | J33: 88.6 | K33: -
F34: Losses (Watts) | H34: Primary | J34: 14896 | K34: -
H35: Secondary | J35: 7201 | K35: -
H36: Core | J36: 6219 | K36: -
H37: F & W | J37: 2758 | K37: -
H38: Stray | J38: 12858 | K38: -
A39: End Ring (Reference) | F39: Note
F40: LINK: | G40: H080104 ER_end of bar.rat with H080104_LAB 3095, 3134_RM.dat
...

Sheet LoginSheet
J1: P | K1: T | L1: L | M1: T
B2: PROJECT HISTORY | J2: E | K2: D | L2: I | M2: Y | N2: H
J3: R | L3: M | M3: P
J4: F | L4: I | M4: E
K5: C | L5: T | N5: I
J6: D | K6: U | M6: T | N6: N
J7: A | K7: R | L7: R | M7: E | N7: S
I8: S | J8: T | K8: V | L8: E | M8: S | N8: U
B9: DATE | C9: PROJECT | D9: SMART NUMBER | E9: QTY | F9: CUSTOMER | G9: REMARKS | H9: LIMIT CODE | I9: F | J9: A | K9: E | L9: V | M9: T | N9: L
B53: REVISION HISTORY
B54: REV | C54: REMARKS | I54: DATE | L54: INIT

Sheet StallTime
A1: Rating: | B1: 4 Pole - 1500.0 HP - 1800 RPM - 4000 V - 60 Hz
A3: Starting Performance
D4: Load Type: Fan / Pump - 4712.0 lb-ft²
A5: RPM | B5: Motor | C5: Load | D5: Accel. | E5: Line | F5: Stator | G5: Rotor
A6: Speed Increment | B6: Torque (%) | C6: Torque (%) | D6: Time (s) | E6: Amps | F6: kW / s | G6: kW / s
A7: 0~180 | B7: 135.1 | C7: 22.5 | D7: 0.595 | E7: 1253.9 | F7: 387.0 | G7: 821.0
A8: 180~360 | B8: 135.3 | C8: 11.5 | D8: 0.541 | E8: 1242.8 | F8: 346.3 | G8: 673.0
A9: 360~540 | B9: 135.8 | C9: 7.0 | D9: 0.520 | E9: 1229.5 | F9: 326.5 | G9: 576.3
A10: 540~720 | B10: 136.5 | C10: 7.0 | D10: 0.518 | E10: 1213.1 | F10: 317.1 | G10: 503.7
A11: 720~900 | B11: 137.8 | C11: 11.0 | D11: 0.529 | E11: 1192.6 | F11: 314.3 | G11: 444.0
A12: 900~1080 | B12: 139.7 | C12: 18.0 | D12: 0.551 | E12: 1167.2 | F12: 315.2 | G12: 389.7
A13: 1080~1260 | B13: 143.0 | C13: 27.5 | D13: 0.580 | E13: 1135.9 | F13: 316.6 | G13: 334.2
A14: 1260~1440 | B14: 150.2 | C14: 41.5 | D14: 0.617 | E14: 1095.1 | F14: 316.4 | G14: 274.3
A15: 1440~1530 | B15: 163.6 | C15: 55.5 | D15: 0.310 | E15: 1053.7 | F15: 146.1 | G15: 196.6
A16: 1530~1620 | B16: 190.6 | C16: 67.5 | D16: 0.272 | E16: 1001.6 | F16: 119.8 | G16: 143.6
... A19: 1782~1785 | B19: 102.6 | C19: 99.0 | D19: 0.281 | E19: 164.4 | F19: 4.1 | G19: 169.8
D21: Acceleration Time: 5.8 s
B22: Energy | D22: First Start | F22: Second Start
A23: Stator Winding Rise | B23: 3061 kW / s | D23: 42°C | F23: 84°C
A24: Rotor Bar Rise | B24: 4068 kW / s | D24: 97°C | F24: 194°C
A25: End Ring Rise | B25: 647 kW / s | D25: 43°C | F25: 86°C
A27: Locked Rotor Thermal Capability
E28: Cold Condition
B29: Rate of Rise | D29: Power | E29: Rise Limit | F29: Max Time
A30: Stator Copper | B30: 11.2°C / s | D30: 813.2 kW | E30: 160°C | F30: 14.3 s
A31: Rotor Bar | B31: 31.1°C / s | D31: 1303.3 kW | E31: 260°C | F31: 8.4 s
A32: Rotor ER | B32: 13.8°C / s | D32: 207.4 kW | E32: 180°C | F32: 13.0 s
E34: Hot Condition
B35: Hot Temp. | D35: Rise Limit | E35: Ambient | F35: Total | G35: Max.Time
A36: Stator Copper | B36: 90°C + | D36: 70°C + | E36: 40°C | F36: = 200°C | G36: 6.3 s
A37: Rotor Bar | B37: 125°C + | D37: 135°C + | E37: 40°C | F37: = 300°C | G37: 4.3 s
A38: Rotor ER | B38: 125°C + | D38: 55°C + | E38: 40°C | F38: = 220°C | G38: 4.0 s
A40: Cold Stall Time: | B40: 15.8 s | D40: Hot Stall Time: | F40: 4.8 s

Sheet MagNoise
A1: Magnetic Noise Verification
A3: Rating: | B3: 4 Pole - 1500.0 HP - 1800 RPM - 4000 V - 60 Hz
A5: Electromagnetic Excitation Frequencies
B7: L = | C7: 0 | D7: L = | E7: + 1 | F7: L = | G7: - 1 | H7: Slip = | I7: 0 | J7: Slip = | K7: 0.008
A8: Mode A | B8: 12 | D8: 24 | F8: 0 | H8: 1440.0 Hz | J8: 1428.8 Hz
A9: Mode B | B9: 20 | D9: 32 | F9: 8 | H9: 1200.0 Hz | J9: 1188.8 Hz
A10: Mode C | B10: 16 | D10: 28 | F10: 4 | H10: 1320.0 Hz | J10: 1308.8 Hz
A12: Natural Frequencies of Stator Core
B14: Mode 0 = | D14: 1663.1 Hz | F14: Mode 6 = | H14: 3565.6 Hz
B15: Mode 2 = | D15: 277.1 Hz | F15: Mode 7 = | H15: 4907.6 Hz
B16: Mode 3 = | D16: 783.8 Hz | F16: Mode 8 = | H16: 6456.4 Hz
B17: Mode 4 = | D17: 1502.9 Hz | F17: Mode 9 = | H17: 8211.8 Hz
B18: Mode 5 = | D18: 2430.6 Hz | F18: Mode 10 = | H18: 10174.0 Hz
A20: Analysis Results
B22: Matching frequencies detected!!!
B23: Please check slot combination!!!

Sheet Performance Data Sheet
A1: TOSHIBA INTERNATIONAL CORPORATION | J1: INDEX | L1: MPCF-1033
A2: Industrial Division / Houston Motor Plant | J2: SHEET NO. | L2: 1 of 1
J3: ISSUED | L3: 7/31/13
J4: SUPERSEDES | L4: 11/8/96
J5: REVISION | L5: 2
A6: SQUIRREL CAGE INDUCTION MOTOR | J6: WRITTEN BY | L6: MDC
A7: PERFORMANCE SPECIFICATIONS | J7: APPROVED BY | L7: PAA
B9: CUSTOMER: | C9: -
B10: TIC SR No.: | C10: -
A12: MOTOR NAMEPLATE DATA
B13: H.P.: | C13: 1500 | E13: VOLTS: | F13: 4000 | H13: 3 PH / | I13: 60 Hz | L13: S. RPM: | M13: 1800
B14: FRAME: | C14: 5812US | E14: ENCL: | F14: WP-II | H14: FLAMPS: | I14: 189 | L14: FLRPM: | M14: 1789
B15: FORM: | C15: DCW4 | E15: S.F.: | F15: 1.0 | H15: NEMA DESIGN: | I15: - | L15: INSUL CLASS: | M15: F
B16: TYPE: | C16: TIKE | E16: AMB.: | F16: 40°C | H16: CODE: | I16: G | L16: DUTY: | M16: Cont.
B17: MODEL No.: | C17: M305WTAL11E-C | H17: kW: | I17: -
B18: NOM. EFF.: | C18: - | E18: MIN. EFF.: | F18: - | H18: P.F.: | I18: -
A21: AMPERAGE | E21: TORQUES | I21: **BEARINGS:
C22: LOCKED ROTOR: | D22: 1259 | G22: FULL LOAD (lb-ft.): | H22: 4404 | K22: DRIVE END: | L22: REFER TO NP
G23: LOCKED ROTOR (%): | H23: 135 | K23: OPPOSITE DRIVE END: | L23: REFER TO NP
G24: BREAK DOWN (%): | H24: 265
A28: EFFICIENCY | H28: POWER FACTOR
C29: FULL LOAD: | D29: 96.2 | J29: FULL LOAD: | K29: 88.6
C30: 3/4 LOAD: | D30: 96.3 | J30: 3/4 LOAD: | K30: 86.4
C31: 1/2 LOAD: | D31: 95.9 | J31: 1/2 LOAD: | K31: 80
A35: ALL CHARACTERISTICS ARE AVERAGE EXPECTED VALUES BASED UPON RATED VOLTAGE,
A36: FREQUENCY AND SINEWAVE POWER INPUT.
A37: THE DECLARED LOCKED ROTOR CURRENT HAS A TOLERANCE OF 20%.
A38: * TEMPERATURE RISE WILL BE CONSISTENT WITH INSULATION, AMBIENT AND SERVICE FACTOR AS
A39: DEFINED BY NEMA-MG-12 OR -20.
A40: ** BEARINGS ARE THE ONLY RECOMMENDED SPARE PART(S).
J42: CERTIFIED BY: | K42: Zichao Xie
J44: DATE: | K44: 44473
A59: - | B59: 6205ZZ | D59: 1 | E59: -
A60: TEFC | B60: 6206UU | D60: 1.15 | E60: A
A61: ODP | B61: 6207ZZ | E61: B
B62: 6208UU
B63: 6211ZZ
B64: 6211C3
B65: 6211ZZC3
B66: 6305UUC3
...

Sheet STCurve
A2: TOSHIBA INTERNATIONAL CORPORATION
A3: Speed Torque/Current Curve
A6: Model #: | B6: ='Performance Data Sheet'!C17 -> M305WTAL11E-C | E6: FLAmps: | F6: ='Performance Data Sheet'!I14 -> 189
A7: Enclosure: | B7: ='Performance Data Sheet'!F14 -> WP-II | C7: Voltage: | D7: ='Performance Data Sheet'!F13 & " V" -> 4000 V | E7: Frame: | F7: ='Performance Data Sheet'!C14 -> 5812US
A8: Pole: | B8: 4 | C8: Frequency: | D8: 3 PH / 60 Hz | E8: Ins. Class: | F8: ='Performance Data Sheet'!M15 -> F
A9: HP: | B9: ='Performance Data Sheet'!C13 -> 1500 | C9: Rotor Inertia: | D9: 346.3 lb-ft² | E9: Date: | F9: ='Performance Data Sheet'!K44 -> 44473
A10: FLRPM: | B10: ='Performance Data Sheet'!M14 -> 1789 | C10: Load Inertia: | D10: 4712.0 lb-ft² | E10: File: | F10: DT4M30U
B12: Locked Rotor Amps: | C12: ='Performance Data Sheet'!D22 & " A" -> 1259 A | D12: Load Type: | E12: Fan / Pump
B13: Locked Rotor Torque: | C13: ='Performance Data Sheet'!H23/100 -> 1.35 | D13: Starting at: | E13: FV (V)
B14: Breakdown Torque: | C14: 2.65 | D14: Accel. Time: | E14: 5.8 (s)
B15: Rated Torque: | C15: ='Performance Data Sheet'!H22 & " lb-ft" -> 4404 lb-ft
A39: Comments: | B39: PROJECT | C39: ='Performance Data Sheet'!C10 -> - | E39: D.E.Curve #: | F39: =F10 -> DT4M30U
C43: Prepared by: | D43: ='Performance Data Sheet'!K42 -> Zichao Xie | E43: Checked by:
D53: Load
A54: 100 | B54: 0 | C54: 0.28303823 | D54: 100
A55: 99 | B55: 105.17016 | C55: 120.4818 | D55: 98
A56: 95 | B56: 265 | C56: 405.32623 | D56: 87
A57: 90 | B57: 209.12168 | C57: 511.89905 | D57: 74
A58: 84.999999 | B58: 172.0414 | C58: 547.99274 | D58: 61
A59: 80 | B59: 155.1725 | C59: 567.07477 | D59: 50
A60: 69.999999 | B60: 145.14624 | C60: 591.78046 | D60: 33
A61: 59.999999 | B61: 140.91642 | C61: 610.18982 | D61: 22
A62: 50 | B62: 138.50369 | C62: 624.99493 | D62: 14
A63: 39.999998 | B63: 137.00332 | C63: 637.03632 | D63: 7.9999995
A64: 30.000001 | B64: 136.06538 | C64: 646.66931 | D64: 5.9999995
A65: 19.999999 | B65: 135.49711 | C65: 654.35309 | D65: 8.000001
... A67: 0 | B67: 135 | C67: 666.13757 | D67: 30

Sheet Thermdam
A2: TOSHIBA INTERNATIONAL CORPORATION
A3: Thermal Limit & Acceleration Curves
A4: Design Values (For Reference Only)
A6: Model #: | B6: ='Performance Data Sheet'!C17 -> M305WTAL11E-C | E6: FLAmps: | F6: ='Performance Data Sheet'!I14 -> 189
A7: Enclosure: | B7: ='Performance Data Sheet'!F14 -> WP-II | C7: Voltage: | D7: ='Performance Data Sheet'!F13 & " V" -> 4000 V | E7: Frame: | F7: ='Performance Data Sheet'!C14 -> 5812US
A8: Pole: | B8: 4 | C8: Frequency: | D8: 3 PH / 60 Hz | E8: Ins. Class: | F8: ='Performance Data Sheet'!M15 -> F
A9: HP: | B9: ='Performance Data Sheet'!C13 -> 1500 | C9: Rotor Inertia: | D9: 346.3 lb-ft² | E9: Date: | F9: ='Performance Data Sheet'!K44 -> 44473
A10: FLRPM: | B10: ='Performance Data Sheet'!M14 -> 1789 | C10: Load Inertia: | D10: 4712.0 lb-ft² | E10: File: | F10: DT4M30U
C12: ='Performance Data Sheet'!D22 & " A" -> 1259 A
C13: ='Performance Data Sheet'!H23/100 -> 1.35
C15: ='Performance Data Sheet'!H22 & " lb-ft" -> 4404 lb-ft
A39: Comments: | B39: PROJECT | C39: ='Performance Data Sheet'!C10 -> - | E39: D.E.Curve #: | F39: =F10 -> DT4M30U
C43: Prepared by: | D43: ='Performance Data Sheet'!K42 -> Zichao Xie | E43: Checked by:
F50: =5252.1*B50/D53 -> #DIV/0!
D66: =D65/D64 -> #DIV/0!
A67: Current (%) | B67: Cold | C67: Hot | E67: CURRENT (%) | F67: Accel. Time
A68: 666.13757 | B68: 22.555087 | C68: 6.8749128 | E68: =A68 -> 666.13757 | F68: 0.0001
A69: 604.09792 | B69: =((A68/A69)^2)*B68 -> 27.425698 | C69: =((A68/A69)^2)*C68 -> 8.3595014 | E69: 663.43915 | F69: 0.59500003
A70: 542.03965 | B70: =((A68/A70)^2)*B68 -> 34.065145 | C70: =((A68/A70)^2)*C68 -> 10.383241 | E70: 657.56614 | F70: 1.136
A71: 480 | B71: =((A68/A71)^2)*B68 -> 43.440007 | C71: =((A68/A71)^2)*C68 -> 13.24075 | E71: 650.5291 | F71: 1.656
A72: =A71-100 -> 380 | B72: =((A68/A72)^2)*B68 -> 69.311479 | E72: 641.85185 | F72: 2.174
A73: =A72-100 -> 280 | B73: =((A68/A73)^2)*B68 -> 127.66043 | E73: 631.00529 | F73: 2.7030001
A74: 265 | B74: =((A68/A74)^2)*B68 -> 142.52157 | C74: =((A68/A74)^2)*C68 -> 43.441349 | E74: 617.56614 | F74: 3.2540002
A75: 180 | B75: =((A68/A75)^2)*B69 -> 375.61292 | C75: =((A68/A75)^2)*C68 -> 94.156441 | E75: 601.00529 | F75: 3.8340001
A76: 120 | B76: =((A68/A76)^2)*B68 -> 695.04011 | C76: =((A68/A76)^2)*C68 -> 211.85199 | E76: 579.41799 | F76: 4.4510002
A77: 110 | C77: =CEILING(C76*2,100) -> 500 | E77: 557.51323 | F77: 4.7610002
A78: 110 | C78: =2*C77 -> 1000 | E78: 529.94709 | F78: 5.033
A79: 110 | C79: 10000 | E79: 458.62434 | F79: 5.2470002
E80: 262.91005 | F80: 5.5370002
E81: 86.809589 | F81: 5.8180003

Sheet Performance
A2: TOSHIBA INTERNATIONAL CORPORATION
A3: Performance Curve
A4: Design Values (For Reference Only)
A6: Model #: | B6: ='Performance Data Sheet'!C17 -> M305WTAL11E-C | E6: FLAmps: | F6: ='Performance Data Sheet'!I14 -> 189
A7: Enclosure: | B7: ='Performance Data Sheet'!F14 -> WP-II | C7: Voltage: | D7: ='Performance Data Sheet'!F13 & " V" -> 4000 V | E7: Frame: | F7: ='Performance Data Sheet'!C14 -> 5812US
A8: Pole: | B8: 4 | C8: Frequency: | D8: 3 PH / 60 Hz | E8: Ins. Class: | F8: ='Performance Data Sheet'!M15 -> F
A9: HP: | B9: ='Performance Data Sheet'!C13 -> 1500 | C9: Rotor Inertia: | D9: 346.3 lb-ft² | E9: Date: | F9: ='Performance Data Sheet'!K44 -> 44473
A10: FLRPM: | B10: ='Performance Data Sheet'!M14 -> 1789 | C10: Load Inertia: | D10: 4712.0 lb-ft² | E10: File: | F10: DT4M30U
B12: Locked Rotor Amps: | C12: ='Performance Data Sheet'!D22 & " A" -> 1259 A | D12: Load Type: | E12: Fan / Pump
B13: Locked Rotor Torque: | C13: ='Performance Data Sheet'!H23/100 -> 1.35 | D13: Starting at: | E13: FV (V)
B14: Breakdown Torque: | C14: 2.65 | D14: Accel. Time: | E14: 5.8 (s)
B15: Rated Torque: | C15: ='Performance Data Sheet'!H22 & " lb-ft" -> 4404 lb-ft
N36: SPEED | O36: KW
N37: =L43 - (L43-L44) / 10 * 0 -> 1800 | O37: =L45 / 10 * 10 -> 4000
N38: =L43 - (L43-L44) / 10 * 1 -> 1798 | O38: =L45 / 10 * 9 -> 3600
A39: Comments: | B39: PROJECT | C39: ='Performance Data Sheet'!C10 -> - | E39: D.E.Curve #: | F39: =F10 -> DT4M30U | N39: =L43 - (L43-L44) / 10 * 2 -> 1796 | O39: =L45 / 10 * 8 -> 3200
N40: =L43 - (L43-L44) / 10 * 3 -> 1794 | O40: =L45 / 10 * 7 -> 2800
N41: =L43 - (L43-L44) / 10 * 4 -> 1792 | O41: =L45 / 10 * 6 -> 2400
N42: =L43 - (L43-L44) / 10 * 5 -> 1790 | O42: =L45 / 10 * 5 -> 2000
C43: Prepared by: | D43: ='Performance Data Sheet'!K42 -> Zichao Xie | E43: Checked by: | K43: SYNC SPEED | L43: 1800 | N43: =L43 - (L43-L44) / 10 * 6 -> 1788 | O43: =L45 / 10 * 4 -> 1600
K44: NEW SPEED LOWER RANGE | L44: 1780 | N44: =L43 - (L43-L44) / 10 * 7 -> 1786 | O44: =L45 / 10 * 3 -> 1200
K45: NEW kW UPPER RANGE | L45: 4000 | N45: =L43 - (L43-L44) / 10 * 8 -> 1784 | O45: =L45 / 10 * 2 -> 800
N46: =L43 - (L43-L44) / 10 * 9 -> 1782 | O46: =L45 / 10 * 1 -> 400
N47: =L43 - (L43-L44) / 10 * 10 -> 1780 | O47: =L45 / 10 * 0 -> 0
A52: ADJUSTED
A53: Load | B53: Efficiency | C53: PF | D53: Amps | E53: RPM | F53: Input Watts
A54: 0 | D54: 49 | E54: 100 | F54: =10312/(L45*1000) * 100 -> 0.2578
A55: 25 | B55: 94.099998 | C55: 59.600002 | D55: 71.940002 | E55: =(1.00466180314159*B10-L44)/(L43-L44)*100 -> 86.699829 | F55: =297055.3/(L45*1000)*100 -> 7.4263825
A56: 50 | B56: 96 | C56: 80.099998 | D56: 105.07 | E56: =(1.00313466190959*B10-L44)/(L43-L44)*100 -> 73.039551 | F56: =583085/(L45*1000)*100 -> 14.577125
A57: 75 | B57: 96.300003 | C57: 86.5 | D57: 145.36 | E57: =(1.00160752067758*B10-L44)/(L43-L44)*100 -> 59.379272 | F57: =871127.4/(L45*1000)*100 -> 21.778185
A58: 100 | B58: 96.200005 | C58: 88.599998 | D58: 189.38 | E58: =(1*B10-L44)/(L43-L44)*100 -> 45 | F58: =1162488/(L45*1000)*100 -> 29.0622
A59: 125 | B59: 96 | C59: 89 | D59: 236.48 | E59: =(0.998432737279032*B10-L44)/(L43-L44)*100 -> 30.980835 | F59: =1458160/(L45*1000)*100 -> 36.454
A62: ORIGINAL
A63: Load | B63: Efficiency | C63: PF | D63: Amps | E63: RPM | F63: Input Watts
A64: 0 | D64: 53.863335 | E64: 100 | F64: 14.049113
A65: 25 | B65: 94.037468 | C65: 59.59935 | D65: 71.938278 | E65: 101.04171 | F65: 7.4259065
A66: 50 | B66: 95.931236 | C66: 80.004021 | D66: 105.06562 | E66: 82.353499 | F66: 14.558625
A67: 75 | B67: 96.258209 | C67: 86.444702 | D67: 145.3609 | E67: 63.166837 | F67: 21.763757
A68: 100 | B68: 96.162354 | C68: 88.558449 | D68: 189.37708 | E68: 43.223981 | F68: 29.047268
A69: 125 | B69: 95.894333 | C69: 88.895721 | D69: 236.48232 | E69: 23.385277 | F69: 36.410566
