Workbook
Name Print_Area_MI: 'Circuit Param'!$A$8:$N$43
Name Print_Area_MI: 'Performance API'!$A$10:$N$18
Name Print_Area_MI: 'Performance Data Sheet'!$A$10:$N$42
Name thermal: #REF!
Name transfer: #REF!
Name unit_sht: "unit_sht"
Name vassvelo: #REF!
Name velcoity: #REF!
Name viscosity: #REF!
Name vollheatre: #REF!
Name volumetri: #REF!
Name weight: #REF!
Name weights: #REF!

Sheet DesignSheet 0.8V
A1: TOSHIBA INTERNATIONAL CORPORATION | I1: Calc. Code: | J1: 2-2-2-0-1-2
A2: 3-PHASE SQUIRREL CAGE INDUCTION MOTOR DESIGN SHEET | J2: B.L.-1 P.F.-1
A3: File: | B3: N:\DESPRO\BASE MV DESIGNS\6800 FRAME\Electrical Design\4P\SERIES DESIGNS\DT4M80U.rat | G3: Date: | H3: 45392 | I3: Time: | J3: 0.35114583
A4: Pole | B4: HP | C4: RPM | D4: Form | E4: Voltage | F4: Frequency | G4: Temperature | H4: FLSpeed | I4: FLSlip | J4: Frame
A5: 4 | B5: 4000 | C5: 1800 | D5: DCW4 | E5: 3200 | F5: 60 | G5: 105 | H5: 1781.9 / 1783.1 | I5: 0.0101 / 0.0094 | J5: 450-1600
A6: Core Data | D6: Winding Data | H6: Constant Data
B7: Primary | C7: Secondary | F7: Bar | G7: End Ring | H7: St. Slot Pitch | I7: 23.125593 | J7: LR Test Data
A8: Air Gap | B8: 3.3099999 | H8: Rt. Slot Pitch | I8: 28.349058 | J8: ES
A9: Space Fac. | B9: 0.93000001 | D9: Pitch | E9: 1 ~ 16 | F9: Cross Section Area | H9: Mean Value | I9: 25.737326 | J9: 949.8987
A10: Core Length | B10: 1110 | C10: 1110 | F10: UB: 420.0 | G10: UER: 3750.0 | H10: Eff.T.W.St. | I10: 15.409848 | J10: WS
A11: OD | B11: 815 | C11: 523.38 | D11: Coil Pitch | E11: 0.83325 | H11: Eff.T.W.Rt. | I11: 27.246163 | J11: 153933.23
A12: ID | B12: 530 | C12: 300 | D12: Slot Fill | E12: - | F12: EBL: 50.5 | G12: ERD1: 423.4 | H12: St.Carter Fac. | I12: 1.5007022 | J12: IS
A13: Core Depth | B13: 66.5 | C13: 71.140001 | D13: Con./Slot | E13: 16 | G13: ERT: 75.00 | H13: Rt.Carter Fac. | I13: 1.0404789 | J13: 617.37146
A14: Eff.Core L. | B14: 881.64001 | C14: 881.64001 | D14: Wire Size 1 | E14: (.128"x.204")x1 | F14: (12 x 35) | G14: ERH: 50.00 | H14: Carter Factor | I14: 1.561449 | J14: Volts / Turn
A15: Slot Data | D15: Wire Size 2 | E15: (.128"x.229")x1 | H15: Short. Factor | I15: 0.96589165 | J15: 38.491147
A16: Number | B16: 72 | C16: 58 | D16: // Circuits | E16: 4 | H16: Distrib. Factor | I16: 0.9559695 | J16: AC
A17: Kind | B17: Open | C17: Rectang | D17: Connection | E17: Wye | H17: Wind. Factor | I17: 0.92336296 | J17: 1067.8584
A18: Skew | B18: - | C18: 0 | D18: MCL | E18: 1792 | F18: 1286 | H18: Reactance | I18: (Coeff.: 0.0191)
A19: Depth | B19: 76 | C19: 40.549999 | D19: No.Cond./Ph. | E19: 96 | I19: Running | J19: Start
A20: Width | B20: 15.20 - 15.20 | C20: 12.05 | D20: Res. (20°C) | E20: 0.021616559 | H20: Stator Slot | I20: 14.760527 | J20: 14.760527
A21: Opening | B21: 15.2 | C21: 5 | D21: (105°C) | E21: 0.028836235 | F21: 0.029191919 | G21: 0.0026723179 | H21: Rotor Slot | I21: 20.271383 | J21: 14.808235
A22: Tip Depth | B22: 3.6500001 | C22: 5.5 | D22: Material | E22: CU | F22: Special | G22: Special | H22: Zigzag | I22: 4.4184256 | J22: 4.0861726
A23: T.Min.Wid. | B23: 7.9255934 | C23: 11.912209 | D23: Spec.Resist. | E23: 1.742 | F23: 1.724 | G23: 1.724 | H23: Coil End | I23: 9.2659512 | J23: Skew R.: 0.00
A24: Low. R. | B24: 0 | C24: 0.80000001 | D24: Spec.Gravity | E24: 8.8900003 | F24: 8.8900003 | G24: 8.8900003 | H24: Belt Leakage | I24: 3.2736441 | J24: 3.086755
A25: Up. R. | B25: - | C25: 0.80000001 | D25: Weight (kg) | H25: Total Resist. | I25: 0.060700472 | J25: 0.13462262
A26: Wedge Dep. | B26: 1.20 - 0.50 | C26: Normal | D26: Wire 1 | E26: 299.08932 | F26: 294.73872 | G26: 99.984177 | H26: Total React. | I26: 0.99354398 | J26: 0.87808764
A27: Duct | B27: 27 x 6 | C27: 27 x 6 | D27: Wire 2 | E27: 336.97801 | F27: - | G27: - | H27: Impedance | I27: 0.99539649 | J27: 0.88834745
A28: Effective Depth (S=1) | D28: Magnetic Circuit Data | I28: Core Loss Data
B29: Res.= | C29: 35.000968 | E29: Length | F29: Section | G29: Density | H29: AT | I29: Volume | J29: Loss | M29: =RIGHT(F$41,SEARCH("/",F$41,1)-1) -> 1777.9 | N29: 125RPM | P29: Kline/in2
B30: Reac.= | C30: 35.035971 | D30: Primary Core | E30: 32.004948 | F30: 1172.5812 | G30: 13.344775 | H30: 252.46864 | I30: 137865.07 | J30: 7805.8898 | M30: =RIGHT(E$41,SEARCH("/",E$41,1)-1) -> 1783.1 | N30: 100RPM | P30: =G30*6.4516 -> 86.09515
A31: Excitation Data | D31: Tooth | E31: 7.6 | F31: 1257.7536 | G31: 12.441095 | H31: 47.810285 | I31: 38235.711 | J31: 1932.4312 | M31: =RIGHT(D$41,SEARCH("/",D$41,1)-1) -> 1788.1 | N31: 75RPM | P31: =G31*6.4516 -> 80.264968
A32: Excit.Amps | B32: 87.185 / 78.507 | D32: Second.Core | E32: 17.36828 | F32: 1254.3974 | G32: 12.474382 | H32: 110.20744 | I32: Total | J32: 9738.321 | M32: =RIGHT(C$41,SEARCH("/",C$41,1)-1) -> 1792.7 | N32: 50RPM | P32: =G32*6.4516 -> 80.479722
A33: Core Loss | B33: 3.922 / 3.532 | C33: Flux / Pole | D33: Tooth | E33: 4.0549999 | F33: 1522.8306 | G33: 10.275491 | H33: 14.027569 | I33: C.L.C. | J33: 1.75 / 0.83 | M33: =RIGHT(B$41,SEARCH("/",B$41,1)-1) -> 1797.0 | N33: 25RPM | P33: =G33*6.4516 -> 66.293361
A34: NoLoad | B34: 87.27 / 78.59 | C34: 15.647832 | D34: Air Gap | E34: 0.33099999 | F34: 2527.2366 | G34: 6.1916768 | H34: 1630.8979 | I34: S.F.C. | J34: 6.0500002 | P34: =G34*6.4516 -> 39.946222
A35: Load Characteristics | D35: Temp. Rise @ 100%: | E35: 105 / 98 | G35: No Load Loss | H35: 31253.0 / 18481.6 | I35: W.Loss | J35: 17042.1 / 8036.7
A36: Load (%) | B36: 25 | C36: 50 | D36: 75 | E36: 100 | F36: 125 | G36: Primary Loss | H36: 32972.6 / 36184.3 | I36: S.Loss | J36: 4718.0 / 2224.9
A37: Current (A) | B37: 172.80 / 180.17 | C37: 306.48 / 319.55 | D37: 454.66 / 474.05 | E37: 617.37 / 643.69 | F37: 801.36 / 835.52 | G37: Second. Loss | H37: 32528.3 / 29621.1 | I37: Total C.Loss | J37: 21760.0 / 10261.6
A38: Efficiency | B38: 0.955 / 0.944 | C38: 0.970 / 0.959 | D38: 0.972 / 0.960 | E38: 0.970 / 0.958 | F38: 0.966 / 0.955 | G38: Frict.& Wind. | H38: 9000.0 / 8017.0 | I38: Stray Loss | J38: 45185.477 | L38: =LEFT(E38,SEARCH("/",E38,1)-1) -> 0.970 | M38: =RIGHT(E38,SEARCH("/",E38,1)-1) -> 0.958 | N38: =M38/L38 -> 0.98762887 | O38: Eff.
A39: P.F. | B39: 0.815 / 0.792 | C39: 0.905 / 0.879 | D39: 0.913 / 0.887 | E39: 0.899 / 0.873 | F39: 0.869 / 0.844 | G39: Starting Data | I39: Slip | J39: PF | L39: =LEFT(E39,SEARCH("/",E39,1)-1) -> 0.899 | M39: =RIGHT(E39,SEARCH("/",E39,1)-1) -> 0.873 | N39: =M39/L39 -> 0.97107898 | O39: PF.
A40: Slip | B40: 0.0024 / 0.0017 | C40: 0.0048 / 0.0040 | D40: 0.0073 / 0.0066 | E40: 0.0101 / 0.0094 | F40: 0.0130 / 0.0123 | G40: LRA | H40: 2079.8 / 2251.8 | L40: =LEFT(E37,SEARCH("/",E37,1)-1) -> 617.37 | M40: =RIGHT(E37,SEARCH("/",E37,1)-1) -> 643.69 | N40: =M40/L40 -> 1.0426325 | O40: Current
...

Sheet DesignSheet
A1: TOSHIBA INTERNATIONAL CORPORATION | I1: Calc. Code: | J1: 2-2-2-0-1-2
A2: 3-PHASE SQUIRREL CAGE INDUCTION MOTOR DESIGN SHEET | J2: B.L.-1 P.F.-1
A3: File: | B3: M:\Active Projects\6810 Development\Electrical Design\4P\SERIES DESIGNS\DT4M80U.rat | G3: Date: | H3: 41885 | I3: Time: | J3: 0.44773148
A4: Pole | B4: HP | C4: RPM | D4: Form | E4: Voltage | F4: Frequency | G4: Temperature | H4: FLSpeed | I4: FLSlip | J4: Frame
A5: 4 | B5: 4000 | C5: 1800 | D5: DCW4 | E5: 4000 | F5: 60 | G5: 105 | H5: 1788.9 / 1790.2 | I5: 0.0061 / 0.0054 | J5: 450-1600
A6: Core Data | D6: Winding Data | H6: Constant Data
B7: Primary | C7: Secondary | F7: Bar | G7: End Ring | H7: St. Slot Pitch | I7: 23.125593 | J7: LR Test Data
A8: Air Gap | B8: 3.3099999 | H8: Rt. Slot Pitch | I8: 28.349058 | J8: ES
A9: Space Fac. | B9: 0.93000001 | D9: Pitch | E9: 1 ~ 16 | F9: Cross Section Area | H9: Mean Value | I9: 25.737326 | J9: 750.59353
A10: Core Length | B10: 1110 | C10: 1110 | F10: UB: 420.0 | G10: UER: 3750.0 | H10: Eff.T.W.St. | I10: 15.409848 | J10: WS
A11: OD | B11: 815 | C11: 523.38 | D11: Coil Pitch | E11: 0.83325 | H11: Eff.T.W.Rt. | I11: 27.246163 | J11: 97875.382
A12: ID | B12: 530 | C12: 300 | D12: Slot Fill | E12: - | F12: EBL: 50.5 | G12: ERD1: 423.4 | H12: St.Carter Fac. | I12: 1.5007022 | J12: IS
A13: Core Depth | B13: 66.5 | C13: 71.140001 | D13: Con./Slot | E13: 16 | G13: ERT: 75.00 | H13: Rt.Carter Fac. | I13: 1.0404789 | J13: 492.28555
A14: Eff.Core L. | B14: 881.64001 | C14: 881.64001 | D14: Wire Size 1 | E14: (.128"x.204")x1 | F14: (12 x 35) | G14: ERH: 50.00 | H14: Carter Factor | I14: 1.561449 | J14: Volts / Turn
A15: Slot Data | D15: Wire Size 2 | E15: (.128"x.229")x1 | H15: Short. Factor | I15: 0.96589165 | J15: 48.113932
A16: Number | B16: 72 | C16: 58 | D16: // Circuits | E16: 4 | H16: Distrib. Factor | I16: 0.9559695 | J16: AC
A17: Kind | B17: Open | C17: Rectang | D17: Connection | E17: Wye | H17: Wind. Factor | I17: 0.92336296 | J17: 851.49912
A18: Skew | B18: - | C18: 0 | D18: MCL | E18: 1792 | F18: 1286 | H18: Reactance | I18: (Coeff.: 0.0191)
A19: Depth | B19: 76 | C19: 40.549999 | D19: No.Cond./Ph. | E19: 96 | I19: Running | J19: Start
A20: Width | B20: 15.20 - 15.20 | C20: 12.05 | D20: Res. (20°C) | E20: 0.021616559 | H20: Stator Slot | I20: 14.760527 | J20: 14.760527
A21: Opening | B21: 15.2 | C21: 5 | D21: (105°C) | E21: 0.028836235 | F21: 0.029191919 | G21: 0.0026723179 | H21: Rotor Slot | I21: 20.271383 | J21: 14.808235
A22: Tip Depth | B22: 3.6500001 | C22: 5.5 | D22: Material | E22: CU | F22: Special | G22: Special | H22: Zigzag | I22: 4.4184256 | J22: 3.8419955
A23: T.Min.Wid. | B23: 7.9255934 | C23: 11.912209 | D23: Spec.Resist. | E23: 1.742 | F23: 1.724 | G23: 1.724 | H23: Coil End | I23: 9.2659512 | J23: Skew R.: 0.00
A24: Low. R. | B24: 0 | C24: 0.80000001 | D24: Spec.Gravity | E24: 8.8900003 | F24: 8.8900003 | G24: 8.8900003 | H24: Belt Leakage | I24: 3.2736441 | J24: 2.919122
A25: Up. R. | B25: - | C25: 0.80000001 | D25: Weight (kg) | H25: Total Resist. | I25: 0.060700472 | J25: 0.13462262
A26: Wedge Dep. | B26: 1.20 - 0.50 | C26: Normal | D26: Wire 1 | E26: 299.08932 | F26: 294.73872 | G26: 99.984177 | H26: Total React. | I26: 0.99354398 | J26: 0.86996406
A27: Duct | B27: 27 x 6 | C27: 27 x 6 | D27: Wire 2 | E27: 336.97801 | F27: - | G27: - | H27: Impedance | I27: 0.99539649 | J27: 0.88031852
A28: Effective Depth (S=1) | D28: Magnetic Circuit Data | I28: Core Loss Data
B29: Res.= | C29: 35.000968 | E29: Length | F29: Section | G29: Density | H29: AT | I29: Volume | J29: Loss
B30: Reac.= | C30: 35.035971 | D30: Primary Core | E30: 32.004948 | F30: 1172.5812 | G30: 16.680968 | H30: 623.1465 | I30: 137865.07 | J30: 11205.122
A31: Excitation Data | D31: Tooth | E31: 7.6 | F31: 1257.7536 | G31: 15.551368 | H31: 103.91935 | I31: 38235.711 | J31: 2773.9475
A32: Excit.Amps | B32: 128.720 / 115.907 | D32: Second.Core | E32: 17.36828 | F32: 1254.3974 | G32: 15.592977 | H32: 240.6348 | I32: Total | J32: 13979.07
A33: Core Loss | B33: 4.664 / 4.200 | C33: Flux / Pole | D33: Tooth | E33: 4.0549999 | F33: 1522.8306 | G33: 12.844364 | H33: 28.277494 | I33: C.L.C. | J33: 1.75 / 0.83
A34: NoLoad | B34: 128.80 / 115.98 | C34: 19.55979 | D34: Air Gap | E34: 0.33099999 | F34: 2527.2366 | G34: 7.7395957 | H34: 2038.6223 | I34: S.F.C. | J34: 6.0500002
A35: Load Characteristics | D35: Temp. Rise @ 100%: | E35: 64 / 66 | G35: No Load Loss | H35: 42420.1 / 25085.3 | I35: W.Loss | J35: 24463.4 / 11536.5
A36: Load (%) | B36: 25 | C36: 50 | D36: 75 | E36: 100 | F36: 125 | G36: Primary Loss | H36: 20965.0 / 23007.0 | I36: S.Loss | J36: 7882.2 / 3717.1
A37: Current (A) | B37: 179.94 / 185.98 | C37: 270.03 / 279.10 | D37: 376.97 / 389.64 | E37: 492.29 / 508.82 | F37: 614.49 / 635.13 | G37: Second. Loss | H37: 18952.5 / 17258.7 | I37: Total C.Loss | J37: 32345.6 / 15253.6
A38: Efficiency | B38: 0.943 / 0.940 | C38: 0.967 / 0.963 | D38: 0.973 / 0.969 | E38: 0.974 / 0.971 | F38: 0.974 / 0.970 | G38: Frict.& Wind. | H38: 9000.0 / 8017.0 | I38: Stray Loss | J38: 26327.264
A39: P.F. | B39: 0.635 / 0.616 | C39: 0.825 / 0.801 | D39: 0.881 / 0.855 | E39: 0.898 / 0.872 | F39: 0.900 / 0.874 | G39: Starting Data | I39: Slip | J39: PF
A40: Slip | B40: 0.0015 / 0.0008 | C40: 0.0030 / 0.0023 | D40: 0.0046 / 0.0039 | E40: 0.0061 / 0.0054 | F40: 0.0077 / 0.0070 | G40: LRA | H40: 2623.4 / 2840.4
...

Sheet Data Sheet
A1: TOSHIBA INTERNATIONAL CORPORATION
A2: INDUCTION MOTOR DATA SHEET
A3: File: | B3: DT4M80U | I3: HRW / Model Number: | J3: M805WTQL11E-C
A4: Type: TIKE - Form: DCW4 - 4 Pole - 4000 HP -2300/4000 V - 60 Hz - 450-1600 - Class F | Q4: Motor Type Selection | T4: Electrical Steel Table
A5: Motor Parameters | F5: PERFORMANCE | J5: DESIGN | K5: TEST | Q5: EPACT | T5: M22 - 26Ga.
A6: Material | D6: M36 - 26Ga. | F6: NL & Impedance Test | Q6: EQP-III | T6: M36 - 26Ga.
A7: Air Gap | D7: 3.3099999 | F7: No load amps | J7: 116 | K7: - | Q7: Exp.Prf. | T7: NCB1 - 26Ga.
A8: Stack length | D8: 1110 | F8: No load watts | J8: 24169 | K8: - | Q8: Exp.Prf.-EQPIII | T8: M43 - 26Ga.
A9: Number of turns per coil | D9: 8 | F9: Impedance amps | H9: 3 | I9: f | J9: 754 | K9: - | Q9: Prem. Eff. | T9: M45 - 26Ga.
A10: Wire 1 (size & number) | D10: (.128"x.204")x1 | F10: Impedance volts | H10: 3 | I10: f | J10: 1150 | K10: - | Q10: OWP | T10: M54 - 26Ga.
A11: Wire 2 (size & number) | D11: (.128"x.229")x1 | F11: Impedance watts | H11: 3 | I11: f | J11: 97875 | K11: - | Q11: Dry Kiln
A12: Slot fill - circle/square method (%) | D12: - | F12: Temperature Rise (°C)
A13: Connection | D13: 4D / 4Y | G13: Winding | I13: 80/115 | J13: 66 / 86 | K13: -
A14: MCL | D14: 1792 | G14: Frame | J14: - | K14: -
A15: Allowance for ins. depth | D15: 17.130798 | G15: Bearing PS/OS | J15: - | K15: -
A16: Allowance for ins. width | D16: 3.8017998 | G16: End Ring | J16: - | K16: - | P16: 884/509
A17: Slot/Wire arrangement | D17: 16 x 2 | F17: Nameplate Data
A18: Effective cross section for coil | D18: - | H18: FLC (A) | J18: 884 / 509 | M18: =J18*6.5 -> #VALUE!
A19: Coil grouping | D19: - | H19: RPM | J19: 1790
A20: Coil pitch (slot number) | D20: 1 ~ 16 | H20: CODE | J20: E
A21: Method of coil connection | D21: - | H21: S. F. | J21: 1.15 | Q21: Method of Connection
A22: Resistance per phase @ 20 °C | D22: 0.0222 | H22: DESIGN | J22: - | Q22: Skip
A23: Coil Weight | B23: Wire1 | D23: 682 | H23: Nom.Eff. (%): | Q23: Adjacent
A24: (lbs.) | B24: Wire2 | D24: 765 | H24: Min.Eff. (%): | Q24: -
A25: Current Densities (A/cm2) | E25: Bar / ER | H25: P.F. (%):
A26: FL / LR | D26: 367 / 2048 | E26: 502 / 260
A27: Stator Slot Shape (Reference) | F27: Performance
H28: LRC (A) | I28: - | J28: 4897 / 2840 | K28: - | M28: =(J28/J18)*100 -> #VALUE! | P28: 4897/2840
H29: LRT (%) | I29: 60 | J29: 125 | K29: -
H30: BDT (%) | I30: 175 | J30: 209 | K30: -
H31: SLIP (%) | J31: 0.54 | K31: -
G32: IEEE-B | H32: Eff. (%) | J32: 97.1 | K32: -
A33: Rotor Slot Shape (Reference) | H33: PF (%) | J33: 87.2 | K33: -
F34: Losses (Watts) | H34: Primary | J34: 23007 | K34: -
H35: Secondary | J35: 17259 | K35: -
H36: Core | J36: 15254 | K36: -
H37: F & W | J37: 8017 | K37: -
H38: Stray | J38: 26327 | K38: -
A39: End Ring (Reference) | F39: Note
G41: QC limits: DT4M80U
...

Sheet Performance Data Sheet
A1: TOSHIBA INTERNATIONAL CORPORATION | J1: INDEX | L1: MPCF-1033
A2: Industrial Division / Houston Motor Plant | J2: SHEET NO. | L2: 1 of 1
J3: ISSUED | L3: 7/31/13
J4: SUPERSEDES | L4: 11/8/96
J5: REVISION | L5: 2
A6: SQUIRREL CAGE INDUCTION MOTOR | J6: WRITTEN BY | L6: MDC
A7: PERFORMANCE SPECIFICATIONS | J7: APPROVED BY | L7: PAA
B9: CUSTOMER: | C9: CARRONADE
B10: TIC SR No.: | C10: 2326400.3
A12: MOTOR NAMEPLATE DATA
B13: H.P.: | C13: 4000 | E13: VOLTS: | F13: 4000 | H13: 3 PH / | I13: 60 Hz | L13: S. RPM: | M13: 1800
B14: FRAME: | C14: 450-1600 | E14: ENCL: | F14: WP-II | H14: FLAMPS: | I14: 509 | L14: FLRPM: | M14: 1790
B15: FORM: | C15: DCW4 | E15: S.F.: | F15: 1.0 | H15: NEMA DESIGN: | I15: - | L15: INSUL CLASS: | M15: F
B16: TYPE: | C16: TIKE | E16: AMB.: | F16: 40 | H16: CODE: | I16: E | L16: DUTY: | M16: Cont.
B17: MODEL No.: | C17: A1-10137478 | H17: kW: | I17: -
B18: NOM. EFF.: | C18: 96.2 | E18: MIN. EFF.: | F18: - | H18: P.F.: | I18: 87..0
A21: AMPERAGE | E21: TORQUES | I21: **BEARINGS:
C22: LOCKED ROTOR: | D22: 2840 | G22: FULL LOAD (lb-ft.): | H22: 11736 | K22: DRIVE END:
G23: LOCKED ROTOR (%): | H23: 125 | K23: OPPOSITE DRIVE END:
G24: BREAK DOWN (%): | H24: 205
A28: EFFICIENCY | H28: POWER FACTOR
C29: FULL LOAD: | D29: 97.1 | J29: FULL LOAD: | K29: 87.2
C30: 3/4 LOAD: | D30: 96.9 | J30: 3/4 LOAD: | K30: 85.5
C31: 1/2 LOAD: | D31: 96.3 | J31: 1/2 LOAD: | K31: 80.1
A35: ALL CHARACTERISTICS ARE AVERAGE EXPECTED VALUES BASED UPON RATED VOLTAGE,
A36: FREQUENCY AND SINEWAVE POWER INPUT.
A37: THE DECLARED LOCKED ROTOR CURRENT HAS A TOLERANCE OF 20%.
A38: * TEMPERATURE RISE WILL BE CONSISTENT WITH INSULATION, AMBIENT AND SERVICE FACTOR AS
A39: DEFINED BY NEMA-MG-12 OR -20.
A40: ** BEARINGS ARE THE ONLY RECOMMENDED SPARE PART(S).
J42: CERTIFIED BY: | K42: Jerry R
J44: DATE: | K44: 44971
A59: - | B59: 6205ZZ | D59: 1 | E59: -
A60: TEFC | B60: 6206UU | D60: 1.15 | E60: A
A61: ODP | B61: 6207ZZ | E61: B
B62: 6208UU
B63: 6211ZZ
B64: 6211C3
B65: 6211ZZC3
B66: 6305UUC3
...

Sheet STCurve
A2: TOSHIBA INTERNATIONAL CORPORATION
A3: Speed Torque/Current Curve
A6: Model #: | B6: M805WTQL11E-C | E6: FLAmps: | F6: ='Performance Data Sheet'!I14 & " A" -> 509 A
A7: Enclosure: | B7: ='Performance Data Sheet'!F14 -> WP-II | C7: Voltage: | D7: ='Performance Data Sheet'!F13 & " V" -> 4000 V | E7: Frame: | F7: ='Performance Data Sheet'!C14 -> 450-1600
A8: Pole: | B8: 4 | C8: Frequency: | D8: 3 PH / 60 Hz | E8: Ins. Class: | F8: F
A9: HP: | B9: 4000 | C9: Rotor Inertia: | D9: 1603.6 lb-ft² | E9: Date: | F9: ='Performance Data Sheet'!K44 -> 44971
A10: FLRPM: | B10: 1790 | C10: Load Inertia: | D10: N/A | E10: File: | F10: DT4M80U
B12: Locked Rotor Amps: | C12: ='Performance Data Sheet'!D22 & " A" -> 2840 A | D12: Load Type: | E12: N/A
B13: Locked Rotor Torque: | C13: 1.25 | D13: Starting at: | E13: N/A
B14: Breakdown Torque: | C14: 2.05 | D14: Accel. Time: | E14: N/A
B15: Rated Torque: | C15: 11736 lb-ft
A39: Comments: | B39: PROJECT | C39: ='Performance Data Sheet'!C10 -> 2326400.3 | E39: D.E.Curve #:
C43: Prepared by: | D43: ='Performance Data Sheet'!K42 -> Jerry R | E43: Checked by:
D53: Load
A54: 100 | B54: 0 | C54: 0.25305375 | D54: 100 | E54: =0.64*B54 -> 0 | F54: =0.8*C54 -> 0.202443
A55: 99.8 | B55: 117.81515 | C55: 140.0363 | D55: 99.599998 | E55: =0.64*B55 -> 75.401696 | F55: =0.8*C55 -> 112.02904
A56: 99 | B56: 205 | C56: 402.8515 | D56: 98 | E56: =0.64*B56 -> 131.2 | F56: =0.8*C56 -> 322.2812
A57: 93.789474 | B57: 148.61202 | C57: 465.93875 | D57: 83.852631 | E57: =0.64*B57 -> 95.111691 | F57: =0.8*C57 -> 372.751
A58: 88.578947 | B58: 131.95522 | C58: 484.88403 | D58: 70.30526 | E58: =0.64*B58 -> 84.451342 | F58: =0.8*C58 -> 387.90723
A59: 83.368421 | B59: 126.84344 | C59: 495.44305 | D59: 57.410526 | E59: =0.64*B59 -> 81.179804 | F59: =0.8*C59 -> 396.35444
A60: 72.947368 | B60: 125.1472 | C60: 510.49695 | D60: 38.010525 | E60: =0.64*B60 -> 80.094209 | F60: =0.8*C60 -> 408.39756
A61: 62.526315 | B61: 125.10324 | C61: 522.35211 | D61: 24.778948 | E61: =0.64*B61 -> 80.066076 | F61: =0.8*C61 -> 417.88169
A62: 52.105263 | B62: 125.07053 | C62: 531.95154 | D62: 15.68421 | E62: =0.64*B62 -> 80.045137 | F62: =0.8*C62 -> 425.56123
A63: 41.68421 | B63: 125.04836 | C63: 539.56793 | D63: 9.0105257 | E63: =0.64*B63 -> 80.030951 | F63: =0.8*C63 -> 431.65435
A64: 31.263161 | B64: 125.0283 | C64: 545.6297 | D64: 6.2526321 | E64: =0.64*B64 -> 80.018114 | F64: =0.8*C64 -> 436.50376
A65: 20.842105 | B65: 125.01583 | C65: 550.51709 | D65: 7.8315787 | E65: =0.64*B65 -> 80.010133 | F65: =0.8*C65 -> 440.41367
... A67: 0 | B67: 125 | C67: 557.95679 | D67: 30 | E67: =0.64*B67 -> 80 | F67: =0.8*C67 -> 446.36543

Sheet Thermdam
A2: TOSHIBA INTERNATIONAL CORPORATION
A3: Thermal Limit & Acceleration Curves
A4: Design Values (For Reference Only)
A6: Model #: | B6: M805WTQL11E-C | E6: FLAmps: | F6: ='Performance Data Sheet'!I14 & " A" -> 509 A
A7: Enclosure: | B7: ='Performance Data Sheet'!F14 -> WP-II | C7: Voltage: | D7: ='Performance Data Sheet'!F13 & " V" -> 4000 V | E7: Frame: | F7: ='Performance Data Sheet'!C14 -> 450-1600
A8: Pole: | B8: 4 | C8: Frequency: | D8: 3 PH / 60 Hz | E8: Ins. Class: | F8: F
A9: HP: | B9: 4000 | C9: Rotor Inertia: | D9: 1603.6 lb-ft² | E9: Date: | F9: ='Performance Data Sheet'!K44 -> 44971
A10: FLRPM: | B10: 1790 | C10: Load Inertia: | D10: N/A | E10: File: | F10: DT4M80U
A39: Comments: | C39: ='Performance Data Sheet'!C10 -> 2326400.3 | E39: D.E.Curve #:
C43: Prepared by: | D43: ='Performance Data Sheet'!K42 -> Jerry R | E43: Checked by:
F50: =5252.1*B50/D53 -> #DIV/0!
D66: =D65/D64 -> #DIV/0!
A67: Current (%) | B67: Cold | C67: Hot | E67: CURRENT (%) | F67: Accel. Time
A68: 557.95678 | B68: 35 | C68: 15 | E68: =A68 -> 557.95678 | F68: 0.0001
A69: 478.64578 | B69: =((A68/A69)^2)*B68 -> 47.559873 | C69: =((A68/A69)^2)*C68 -> 20.382803 | E69: 556.24754 | F69: 0.55699998
A70: 399.31099 | B70: =((A68/A70)^2)*B68 -> 68.335539 | C70: =((A68/A70)^2)*C68 -> 29.28666 | E70: 552.53438 | F70: 1.0599999
A71: 320 | B71: =((A68/A71)^2)*B68 -> 106.40676 | C71: =((A68/A71)^2)*C68 -> 45.602895 | E71: 548.07466 | F71: 1.545
A72: =A71-100 -> 220 | B72: =((A68/A72)^2)*B68 -> 225.12504 | E72: 542.59332 | F72: 2.0320001
A73: =A72-100 -> 120 | B73: =((A68/A73)^2)*B68 -> 756.67026 | E73: 535.75639 | F73: 2.539
A74: 209 | B74: =((A68/A74)^2)*B68 -> 249.44602 | C74: =((A68/A74)^2)*C68 -> 106.90544 | E74: 527.15128 | F74: 3.0840001
A75: 180 | B75: =((A68/A75)^2)*B69 -> 456.97957 | C75: =((A68/A75)^2)*C68 -> 144.12767 | E75: 516.42436 | F75: 3.694
A76: 120 | B76: =((A68/A76)^2)*B68 -> 756.67026 | C76: =((A68/A76)^2)*C68 -> 324.28726 | E76: 502.9666 | F76: 4.4239998
A77: 110 | C77: =CEILING(C76*2,100) -> 700 | E77: 490.15717 | F77: 4.8609996
A78: 110 | C78: =2*C77 -> 1400 | E78: 475.40275 | F78: 5.3129997
A79: 110 | C79: 10000 | E79: 434.40079 | F79: 5.6379995
E80: 271.43418 | F80: 5.7059994
E81: 0 | F81: 5.8269992

Sheet Performance 4000V
A2: TOSHIBA INTERNATIONAL CORPORATION
A3: Performance Curve
A4: Design Values (For Reference Only)
A6: Model #: | B6: ='[1]Performance Data Sheet'!C17 -> TIR 42934 | E6: FLAmps: | F6: 509 A
A7: Enclosure: | B7: ='[1]Performance Data Sheet'!F14 -> WP-II | C7: Voltage: | D7: 4000 V | E7: Frame: | F7: ='[1]Performance Data Sheet'!C14 -> 450-1600
A8: Pole: | B8: 4 | C8: Frequency: | D8: 3 PH / 60 Hz | E8: Ins. Class: | F8: F
A9: HP: | B9: 4000 | C9: Rotor Inertia: | D9: 1603.6 lb-ft² | E9: Date: | F9: ='[1]Performance Data Sheet'!K44 -> 44971
A10: FLRPM: | B10: 1790 | C10: Load Inertia: | D10: N/A | E10: File: | F10: H23005
B12: Locked Rotor Amps: | C12: 2840 A | D12: Load Type: | E12: N/A
B13: Locked Rotor Torque: | C13: 1.25 | D13: Starting at: | E13: N/A
B14: Breakdown Torque: | C14: 2.05 | D14: Accel. Time: | E14: N/A
B15: Rated Torque: | C15: 11736 lb-ft
A39: Comments: | B39: PROJECT | C39: ='Performance Data Sheet'!C10 -> 2326400.3 | E39: D.E.Curve #:
C43: Prepared by: | D43: ='Performance Data Sheet'!K42 -> Jerry R | E43: Checked by:
A53: Load | B53: Efficiency | C53: PF | D53: Amps | E53: RPM | F53: Input Watts
A54: 0 | D54: 116 | E54: 100 | F54: 0.33256
A55: 25 | B55: 94 | C55: 61.6 | D55: 185 | E55: 88.242845 | F55: 9.9433019
A56: 50 | B56: 96.3 | C56: 80.1 | D56: 279 | E56: 75.754127 | F56: 19.36677
A57: 75 | B57: 96.9 | C57: 85.5 | D57: 389 | E57: 63.026299 | F57: 28.84366
A58: 100 | B58: 97.1 | C58: 87.2 | D58: 509 | E58: 50.117962 | F58: 38.37786
A59: 125 | B59: 97 | C59: 87.4 | D59: 635 | E59: 36.903451 | F59: 47.970537

Sheet Performance 2300V
A2: TOSHIBA INTERNATIONAL CORPORATION
A3: Performance Curve
A4: Design Values (For Reference Only)
A6: Model #: | B6: ='[1]Performance Data Sheet'!C17 -> TIR 42934 | E6: FLAmps: | F6: 884 A
A7: Enclosure: | B7: ='[1]Performance Data Sheet'!F14 -> WP-II | C7: Voltage: | D7: 2300 V | E7: Frame: | F7: ='[1]Performance Data Sheet'!C14 -> 450-1600
A8: Pole: | B8: 4 | C8: Frequency: | D8: 3 PH / 60 Hz | E8: Ins. Class: | F8: F
A9: HP: | B9: 4000 | C9: Rotor Inertia: | D9: 1603.6 lb-ft² | E9: Date: | F9: ='[1]Performance Data Sheet'!K44 -> 44971
A10: FLRPM: | B10: 1790 | C10: Load Inertia: | D10: N/A | E10: File: | F10: H23005
B12: Locked Rotor Amps: | C12: 4897 A | D12: Load Type: | E12: N/A
B13: Locked Rotor Torque: | C13: 1.35 | D13: Starting at: | E13: N/A
B14: Breakdown Torque: | C14: 2.25 | D14: Accel. Time: | E14: N/A
B15: Rated Torque: | C15: 11736 lb-ft
A39: Comments: | B39: PROJECT | C39: ='Performance Data Sheet'!C10 -> 2326400.3 | E39: D.E.Curve #:
C43: Prepared by: | D43: ='Performance Data Sheet'!K42 -> Jerry R | E43: Checked by:
A53: Load | B53: Efficiency | C53: PF | D53: Amps | E53: RPM | F53: Input Watts
A54: 0 | D54: 199 | E54: 100 | F54: 0.33256
A55: 25 | B55: 94 | C55: 61.6 | D55: 321 | E55: 88.242845 | F55: 9.9433019
A56: 50 | B56: 96.3 | C56: 80.1 | D56: 484 | E56: 75.754127 | F56: 19.36677
A57: 75 | B57: 96.9 | C57: 85.5 | D57: 676 | E57: 63.026299 | F57: 28.84366
A58: 100 | B58: 97.1 | C58: 87.2 | D58: 884 | E58: 50.117962 | F58: 38.37786
A59: 125 | B59: 97 | C59: 87.4 | D59: 1104 | E59: 36.903451 | F59: 47.970537

Sheet Circuit Param
A1: TOSHIBA INTERNATIONAL CORPORATION | J1: INDEX | L1: MPCF-1109
A2: Industrial Division / Houston Motor Plant | J2: SHEET NO. | L2: 1 of 1
J3: ISSUED | L3: 38309
A4: EQUIVALENT CIRCUIT DATA | J4: SUPERSEDES | L4: NEW
J5: REVISION | L5: REV. 0
J6: WRITTEN BY | L6: MDC
A7: All Values are Presented in Ohms/Phase, Equivalent Wye Connection. | J7: APPROVED BY | L7: Paul Anderson
B9: CUSTOMER: | C9: CARRONADE
B10: TIC SR No.: | C10: 2326400.3
A12: MOTOR NAMEPLATE DATA
B13: H.P.: | C13: 4000 | E13: VOLTS: | F13: 4000 | H13: 3 PH / | I13: 60 Hz | L13: S. RPM: | M13: 1800
B14: FRAME: | C14: 450-1600 | E14: ENCL: | F14: WP-II | H14: FLAMPS: | I14: 509 | L14: FLRPM: | M14: 1790
B15: FORM: | C15: DCW4 | E15: S.F.: | F15: 1.0 | H15: NEMA DESIGN: | I15: - | L15: INSUL CLASS: | M15: F
B16: TYPE: | C16: TIKE | E16: AMB.: | F16: 40 | H16: CODE: | I16: E | L16: DUTY: | M16: Cont.
B17: MODEL No.: | C17: A1-10137478 | H17: kW: | I17: -
B18: NOM. EFF.: | C18: 96.2 | E18: MIN. EFF.: | F18: - | H18: P.F.: | I18: 87..0
A21: Primary Resistance (R1) : | G21: 0.029
A22: Secondary Resistance (R2) : | G22: 0.032
A23: Starting Secondary Resistance (R3) : | G23: 0.106
A25: Primary Reactance (X1) : | G25: 0.557
A26: Secondary Reactance (X2) : | G26: 0.611
A27: Starting Secondary Reactance (X3) : | G27: 0.404
A29: Magnetizing Reactance (Xm) : | G29: 19.9
A31: Transient Reactance : | G31: 1.15
A32: Sub Transient Reactance : | G32: 0.797
A33: Short Circuit Time Constant : | G33: 0.096
A34: Sub Transient Time Constant : | G34: 0.017
A35: Open Circuit Time Constant : | G35: 1.708
I40: CERTIFIED BY: | J40: JERRY R
I42: DATE: | J42: 47218

Sheet Performance API
A1: TOSHIBA INTERNATIONAL CORPORATION | J1: INDEX | L1: MPCF-1082
A2: Industrial Division / Houston Motor Plant | J2: SHEET NO. | L2: 1 of 1
J3: ISSUED | L3: 2/14/02
J4: SUPERSEDES | L4: NEW
J5: REVISION | L5: 0
A6: SQUIRREL CAGE INDUCTION MOTOR | J6: WRITTEN BY | L6: M. CAMPBELL
A7: API 541 PERFORMANCE SPECIFICATIONS | J7: APPROVED BY | L7: P.A.A
B9: CUSTOMER: | C9: CARRONADE
B10: TIC SR No.: | C10: 2326400.3
A12: MOTOR NAMEPLATE DATA
B13: H.P.: | C13: 4000 | E13: VOLTS: | F13: 4000 | H13: 3 PH / | I13: 60 Hz | L13: S. RPM: | M13: 1800
B14: FRAME: | C14: 450-1600 | E14: ENCL: | F14: WP-II | H14: FLAMPS: | I14: 509 | L14: FLRPM: | M14: 1790
B15: FORM: | C15: DCW4 | E15: S.F.: | F15: 1.0 | H15: NEMA DESIGN: | I15: - | L15: INSUL CLASS: | M15: F
B16: TYPE: | C16: TIKE | E16: AMB.: | F16: 40 | H16: CODE: | I16: E | L16: DUTY: | M16: Cont.
B17: MODEL No.: | C17: A1-10137478 | H17: kW: | I17: -
B18: NOM. EFF.: | C18: 96.2 | E18: MIN. EFF.: | F18: - | H18: P.F.: | I18: 87..0
A20: LOCKED ROTOR DATA
D21: AMPS AT RATED VOLTAGE: | E21: 2840 A | I21: POWER FACTOR: | J21: 0.216
D22: AMPS AT 80% VOLTAGE: | E22: 2252 A
A24: TORQUE VALUES | H24: CURVE NUMBERS
E25: FULL LOAD (LB.FT): | F25: 11736 | J25: SPEED-TORQUE CURVE: | K25: DT4M80U
E26: LOCKED ROTOR TORQUE (% OF FLT): | F26: 125 | J26: SPEED-CURRENT CURVE: | K26: DT4M80U
E27: PULL UP TORQUE (% OF FLT): | F27: 125 | J27: ACCELERATION CURVE: | K27: -
E28: BREAKDOWN TORQUE (% OF FLT): | F28: 205
A30: LOCKED ROTOR WITHSTAND TIMES
A31: COLD CONDITION | H31: HOT CONDITION
C32: 100% VOLTAGE: | D32: 35 (s) | J32: 100% VOLTAGE: | K32: 15 (s)
C33: 90% VOLTAGE: | D33: 43 (s) | J33: 90% VOLTAGE: | K33: 18 (s)
C34: 80% VOLTAGE: | D34: 54 (s) | J34: 80% VOLTAGE: | K34: 23 (s)
C35: 70% VOLTAGE: | D35: 71 (s) | J35: 70% VOLTAGE: | K35: 30 (s)
A37: DESIGN DATA
C38: MOTOR ROTOR wk2 (LB.FT2): | D38: 1603.6 | J38: NO LOAD CURRENT: | K38: 116 A
C39: AIR GAP: | D39: 3.31 mm | J39: ACCELERATION TIME: | K39: -
D40: LOAD CHARACTERISTICS
D41: LOAD | G41: 1/2 | H41: 3/4 | I41: FULL | J41: SF
D42: AMPS (A) | G42: 279.1 | H42: 389.6 | I42: 508.8 | J42: -
D43: EFFICIENCY (%) | G43: 96.3 | H43: 96.9 | I43: 97.1 | J43: -
D44: POWER FACTOR (%) | G44: 80.1 | H44: 85.5 | I44: 87.2 | J44: -
D45: GUARENTEED EFFICIENCY (%) | G45: - | H45: - | I45: - | J45: -
A46: EFFICIENCY TO BE DETERMINED BY IEEE 112
...

Sheet StallTime
A1: Rating: | B1: 4 Pole - 4000.0 HP - 1800 RPM - 4000 V - 60 Hz
A3: Starting Performance
D4: Load Type: Fan / Pump - 9415.0 lb-ft²
A5: RPM | B5: Motor | C5: Load | D5: Accel. | E5: Line | F5: Stator | G5: Rotor
A6: Speed Increment | B6: Torque (%) | C6: Torque (%) | D6: Time (s) | E6: Amps | F6: kW / s | G6: kW / s
A7: 0~188 | B7: 125.0 | C7: 22.4 | D7: 0.557 | E7: 2831.3 | F7: 388.9 | G7: 1948.5
A8: 188~375 | B8: 125.0 | C8: 11.3 | D8: 0.503 | E8: 2812.4 | F8: 346.7 | G8: 1575.1
A9: 375~563 | B9: 125.0 | C9: 7.0 | D9: 0.485 | E9: 2789.7 | F9: 329.2 | G9: 1341.3
A10: 563~750 | B10: 125.0 | C10: 7.6 | D10: 0.487 | E10: 2761.8 | F10: 325.0 | G10: 1170.8
A11: 750~938 | B11: 125.1 | C11: 12.3 | D11: 0.507 | E11: 2727.0 | F11: 331.1 | G11: 1034.8
A12: 938~1125 | B12: 125.1 | C12: 20.2 | D12: 0.545 | E12: 2683.2 | F12: 345.7 | G12: 913.3
A13: 1125~1313 | B13: 125.1 | C13: 31.4 | D13: 0.610 | E13: 2628.6 | F13: 373.2 | G13: 800.2
A14: 1313~1501 | B14: 126.0 | C14: 47.7 | D14: 0.730 | E14: 2560.1 | F14: 426.6 | G14: 691.5
A15: 1501~1594 | B15: 129.4 | C15: 63.9 | D15: 0.437 | E15: 2494.9 | F15: 240.2 | G15: 515.1
A16: 1594~1688 | B16: 140.3 | C16: 77.1 | D16: 0.452 | E16: 2419.8 | F16: 238.4 | G16: 381.4
... A19: 1796~1800 | B19: 108.9 | C19: 99.8 | D19: 0.121 | E19: 684.2 | F19: 2.7 | G19: 127.2
D21: Acceleration Time: 5.8 s
B22: Energy | D22: First Start | F22: Second Start
A23: Stator Winding Rise | B23: 3531 kW / s | D23: 14°C | F23: 29°C
A24: Rotor Bar Rise | B24: 9820 kW / s | D24: 87°C | F24: 173°C
A25: End Ring Rise | B25: 899 kW / s | D25: 23°C | F25: 47°C
A27: Locked Rotor Thermal Capability
E28: Cold Condition
B29: Rate of Rise | D29: Power | E29: Rise Limit | F29: Max Time
A30: Stator Copper | B30: 3.3°C / s | D30: 808.0 kW | E30: 160°C | F30: 48.5 s
A31: Rotor Bar | B31: 30.1°C / s | D31: 3417.2 kW | E31: 260°C | F31: 8.6 s
A32: Rotor ER | B32: 8.1°C / s | D32: 312.8 kW | E32: 180°C | F32: 22.2 s
E34: Hot Condition
B35: Hot Temp. | D35: Rise Limit | E35: Ambient | F35: Total | G35: Max.Time
A36: Stator Copper | B36: 66°C + | D36: 94°C + | E36: 40°C | F36: = 200°C | G36: 28.5 s
A37: Rotor Bar | B37: 88°C + | D37: 172°C + | E37: 40°C | F37: = 300°C | G37: 5.7 s
A38: Rotor ER | B38: 88°C + | D38: 92°C + | E38: 40°C | F38: = 220°C | G38: 11.4 s
A40: Cold Stall Time: | B40: 27.9 s | D40: Hot Stall Time: | F40: 14.3 s

Sheet MagNoise
A1: Magnetic Noise Verification
A3: Rating: | B3: 4 Pole - 4000.0 HP - 1800 RPM - 4000 V - 60 Hz
A5: Electromagnetic Excitation Frequencies
B7: L = | C7: 0 | D7: L = | E7: + 1 | F7: L = | G7: - 1 | H7: Slip = | I7: 0 | J7: Slip = | K7: 0.006
A8: Mode A | B8: 10 | D8: 22 | F8: 2 | H8: 1860.0 Hz | J8: 1849.3 Hz
A9: Mode B | B9: 18 | D9: 30 | F9: 6 | H9: 1620.0 Hz | J9: 1609.3 Hz
A10: Mode C | B10: 14 | D10: 26 | F10: 2 | H10: 1740.0 Hz | J10: 1729.3 Hz
A12: Natural Frequencies of Stator Core
B14: Mode 0 = | D14: 1283.2 Hz | F14: Mode 6 = | H14: 2255.8 Hz
B15: Mode 2 = | D15: 175.3 Hz | F15: Mode 7 = | H15: 3104.8 Hz
B16: Mode 3 = | D16: 495.9 Hz | F16: Mode 8 = | H16: 4084.6 Hz
B17: Mode 4 = | D17: 950.8 Hz | F17: Mode 9 = | H17: 5195.2 Hz
B18: Mode 5 = | D18: 1537.7 Hz | F18: Mode 10 = | H18: 6436.5 Hz
A20: Analysis Results
B22: No matching frequencies detected.

Sheet Form
A1: Winding Data Calculation
C2: MCL: 1792.0
A3: Coil Resistance | D3: Lead Resistance
A4: 8T: | B4: 0.0145 ~ 0.0140 | D4: AWG. (4/0 x 2) x 3
D5: 0.00063
A6: Coil Dimensions
A7: HM: | B7: 8T: 27.61 | C7: WM: | D7: 8T: 11.40 | E7: WT:
E8: 15.30 ~ 14.90
A9: Insulation Allowance | D9: Wire Weight
A10: Depth: | B10: 17.13 | D10: (.128"x.204")x 1: | F10: 682 lbs.
A11: Width: | B11: 3.80 | D11: (.128"x.229")x 1: | F11: 765 lbs.
A12: QC Resistance
A13: 1-2, 2-3, 3-1: | C13: 0.046 ~ 0.043
