Workbook
Name Print_Area_MI: 'Performance Data Sheet'!$A$10:$N$42
Name Print_Area_MI: #REF!

Sheet DesignSheet
A1: TOSHIBA INTERNATIONAL CORPORATION | I1: Calc. Code: | J1: 2-2-2-0-1-2
A2: 3-PHASE SQUIRREL CAGE INDUCTION MOTOR DESIGN SHEET | J2: B.L.-1 P.F.-1
A3: File: | B3: G:\DESPRO\RAT FILES\DT8M30U.rat | G3: Date: | H3: 44685 | I3: Time: | J3: 0.40446759
A4: Pole | B4: HP | C4: RPM | D4: Form | E4: Voltage | F4: Frequency | G4: Temperature | H4: FLSpeed | I4: FLSlip | J4: Frame
A5: 8 | B5: 1500 | C5: 900 | D5: DCW4 | E5: 4000 | F5: 60 | G5: 105 | H5: 895.5 / 889.0 | I5: 0.0050 / 0.0122 | J5: 6813US
A6: Core Data | D6: Winding Data | H6: Constant Data
B7: Primary | C7: Secondary | F7: Bar | G7: End Ring | H7: St. Slot Pitch | I7: 26.398083 | J7: LR Test Data
A8: Air Gap | B8: 1.9 | H8: Rt. Slot Pitch | I8: 33.727213 | J8: ES
A9: Space Fac. | B9: 0.93000001 | D9: Pitch | E9: 1 ~ 9 | F9: Cross Section Area | H9: Mean Value | I9: 30.062648 | J9: 736.85403
A10: Core Length | B10: 994 | C10: 994 | F10: UB: 585.0 | G10: UER: 1500.0 | H10: Eff.T.W.St. | I10: 16.407303 | J10: WS
A11: OD | B11: 815 | C11: 601.2 | D11: Coil Pitch | E11: 0.8888 | H11: Eff.T.W.Rt. | I11: 32.815701 | J11: 45765.294
A12: ID | B12: 605 | C12: 300 | D12: Slot Fill | E12: - | F12: EBL: 50.5 | G12: ERD1: 501.0 | H12: St.Carter Fac. | I12: 1.230773 | J12: IS
A13: Core Depth | B13: 49 | C13: 103.05 | D13: Con./Slot | E13: 14 | G13: ERT: 30.00 | H13: Rt.Carter Fac. | I13: 1.0277767 | J13: 197.05067
A14: Eff.Core L. | B14: 762.59998 | C14: 762.59998 | D14: Wire Size 1 | E14: (.102"x.204")x2 | F14: (13 x 45) | G14: ERH: 50.00 | H14: Carter Factor | I14: 1.2649597 | J14: Volts / Turn
A15: Slot Data | D15: Wire Size 2 | E15: - | H15: Short. Factor | I15: 0.98478329 | J15: 27.493676
A16: Number | B16: 72 | C16: 56 | D16: // Circuits | E16: 2 | H16: Distrib. Factor | I16: 0.95963581 | J16: AC
A17: Kind | B17: Open | C17: Rectang | D17: Connection | E17: Wye | H17: Wind. Factor | I17: 0.94503331 | J17: 522.5208
A18: Skew | B18: - | C18: 0 | D18: MCL | E18: 1464 | F18: 1125 | H18: Reactance | I18: (Coeff.: 0.0530)
A19: Depth | B19: 56 | C19: 47.549999 | D19: No.Cond./Ph. | E19: 168 | I19: Running | J19: Start
A20: Width | B20: 9.99 - 9.99 | C20: 13.05 | D20: Res. (20°C) | E20: 0.081668563 | H20: Stator Slot | I20: 17.612171 | J20: 17.612171
A21: Opening | B21: 14.4 | C21: 3.5 | D21: (105°C) | E21: 0.1089449 | F21: 0.061961845 | G21: 0.0069914427 | H21: Rotor Slot | I21: 18.881342 | J21: 11.114194
A22: Tip Depth | B22: 2.8299999 | C22: 2.5 | D22: Material | E22: CU | F22: CU | G22: CU | H22: Zigzag | I22: 8.4518557 | J22: 5.5005231
A23: T.Min.Wid. | B23: 11.998083 | C23: 15.347759 | D23: Spec.Resist. | E23: 1.742 | F23: 1.742 | G23: 1.742 | H23: Coil End | I23: 3.771624 | J23: Skew R.: 0.00
A24: Low. R. | B24: 0 | C24: 0.80000001 | D24: Spec.Gravity | E24: 8.8900003 | F24: 8.8900003 | G24: 8.8900003 | H24: Belt Leakage | I24: 3.1222732 | J24: 2.2685725
A25: Up. R. | B25: - | C25: 0.80000001 | D25: Weight (kg) | H25: Total Resist. | I25: 0.17789818 | J25: 0.39287931
A26: Wedge Dep. | B26: 2.83 - 0.50 | C26: Magnetic | D26: Wire 1 | E26: 344.1256 | F26: 336.37805 | G26: 46.178769 | H26: Total React. | I26: 2.7492304 | J26: 2.1229677
A27: Duct | B27: 29 x 6 | C27: 29 x 6 | D27: Wire 2 | E27: - | F27: - | G27: - | H27: Impedance | I27: 2.7549801 | J27: 2.1590149
A28: Effective Depth (S=1) | D28: Magnetic Circuit Data | I28: Core Loss Data
B29: Res.= | C29: 44.881217 | E29: Length | F29: Section | G29: Density | H29: AT | I29: Volume | J29: Loss | M29: =RIGHT(F$41,SEARCH("/",F$41,1)-1) -> 887.8 | N29: 125RPM | P29: Kline/in2
B30: Reac.= | C30: 45.001599 | D30: Primary Core | E30: 16.002474 | F30: 747.34798 | G30: 14.612637 | H30: 257.40905 | I30: 89923.074 | J30: 5897.873 | M30: =RIGHT(E$41,SEARCH("/",E$41,1)-1) -> 889.0 | N30: 100RPM | P30: =G30*6.4516 -> 94.27489
A31: Excitation Data | D31: Tooth | E31: 5.6 | F31: 823.47641 | G31: 13.261734 | H31: 58.734689 | I31: 36891.743 | J31: 2067.7861 | M31: =RIGHT(D$41,SEARCH("/",D$41,1)-1) -> 890.2 | N31: 75RPM | P31: =G31*6.4516 -> 85.559401
A32: Excit.Amps | B32: 69.019 / 72.655 | D32: Second.Core | E32: 9.9372419 | F32: 1571.7186 | G32: 6.9482699 | H32: 17.880434 | I32: Total | J32: 7965.6591 | M32: =RIGHT(C$41,SEARCH("/",C$41,1)-1) -> 891.3 | N32: 50RPM | P32: =G32*6.4516 -> 44.827458
A33: Core Loss | B33: 2.435 / 2.563 | C33: Flux / Pole | D33: Tooth | E33: 4.7549999 | F33: 819.29406 | G33: 13.329433 | H33: 51.012909 | I33: C.L.C. | J33: 1.75 / 1.02 | M33: =RIGHT(B$41,SEARCH("/",B$41,1)-1) -> 892.1 | N33: 25RPM | P33: =G33*6.4516 -> 85.996167
A34: NoLoad | B34: 69.06 / 72.70 | C34: 10.920725 | D34: Air Gap | E34: 0.19 | F34: 1540.1111 | G34: 7.0908684 | H34: 1072.1203 | I34: S.F.C. | J34: 6.0500002 | P34: =G34*6.4516 -> 45.747447
A35: Load Characteristics | D35: Temp. Rise @ 100%: | E35: 65 / 65 | G35: No Load Loss | H35: 23052.9 / 16200.0 | I35: W.Loss | J35: 13939.9 / 8094.4
A36: Load (%) | B36: 25 | C36: 50 | D36: 75 | E36: 100 | F36: 125 | G36: Primary Loss | H36: 12690.7 / 13305.0 | I36: S.Loss | J36: 2945.9 / 1710.6
A37: Current (A) | B37: 75.96 / 78.75 | C37: 116.03 / 120.30 | D37: 154.29 / 159.97 | E37: 197.05 / 204.30 | F37: 243.40 / 252.36 | G37: Second. Loss | H37: 5832.4 / 13428.0 | I37: Total C.Loss | J37: 16885.8 / 9805.0
A38: Efficiency | B38: 0.921 / 0.909 | C38: 0.953 / 0.941 | D38: 0.963 / 0.951 | E38: 0.966 / 0.954 | F38: 0.966 / 0.954 | G38: Frict.& Wind. | H38: 5000.0 / 4487.0 | I38: Stray Loss | J38: 13428.001 | L38: =LEFT(E38,SEARCH("/",E38,1)-1) -> 0.966 | M38: =RIGHT(E38,SEARCH("/",E38,1)-1) -> 0.954 | N38: =M38/L38 -> 0.98757764 | O38: Eff.
A39: P.F. | B39: 0.577 / 0.564 | C39: 0.730 / 0.713 | D39: 0.815 / 0.797 | E39: 0.849 / 0.829 | F39: 0.859 / 0.839 | G39: Starting Data | I39: Slip | J39: PF | L39: =LEFT(E39,SEARCH("/",E39,1)-1) -> 0.849 | M39: =RIGHT(E39,SEARCH("/",E39,1)-1) -> 0.829 | N39: =M39/L39 -> 0.97644287 | O39: PF.
A40: Slip | B40: 0.0015 / 0.0088 | C40: 0.0025 / 0.0097 | D40: 0.0037 / 0.0109 | E40: 0.0050 / 0.0122 | F40: 0.0063 / 0.0135 | G40: LRA | H40: 1069.7 / 1413.8 | L40: =LEFT(E37,SEARCH("/",E37,1)-1) -> 197.05 | M40: =RIGHT(E37,SEARCH("/",E37,1)-1) -> 204.30 | N40: =M40/L40 -> 1.0367927 | O40: Current
...

Sheet Data Sheet
A1: TOSHIBA INTERNATIONAL CORPORATION
A2: INDUCTION MOTOR DATA SHEET
A3: File: | B3: DT8M30U | I3: HRW / Model Number: | J3: M308WTQL11E-C
A4: Type: TIKE - Form: DCW4 - 8 Pole - 1500 HP - 2300/4000 V - 60 Hz - 6813US - Class F | Q4: Motor Type Selection | T4: Electrical Steel Table
A5: Motor Parameters | F5: PERFORMANCE | J5: DESIGN | K5: TEST | Q5: EPACT | T5: M22 - 26Ga.
A6: Material | D6: M36 - 26Ga. | F6: NL & Impedance Test | K6: Lab# 1086 | Q6: EQP-III | T6: M36 - 26Ga.
A7: Air Gap | D7: 1.9 | F7: No load amps | J7: 73 | K7: 72.79 | Q7: Exp.Prf. | T7: NCB1 - 26Ga.
A8: Stack length | D8: 994 | F8: No load watts | J8: 16200 | K8: 16200 | Q8: Exp.Prf.-EQPIII | T8: M43 - 26Ga.
A9: Number of turns per coil | D9: 7 | F9: Impedance amps | H9: 1 | I9: f | J9: 308 | K9: 206.3 | Q9: Prem. Eff. | T9: M45 - 26Ga.
A10: Wire 1 (size & number) | D10: (.102"x.204")x2 | F10: Impedance volts | H10: 1 | I10: f | J10: 1150 | K10: 904 | Q10: Standard Eff. | T10: M54 - 26Ga.
A11: Wire 2 (size & number) | D11: - | F11: Impedance watts | H11: 1 | I11: f | J11: 45765 | K11: 42000 | Q11: OWP | T11: TIPA Lam
A12: Slot fill - circle/square method (%) | D12: - | F12: Temperature Rise (°C) | K12: RM | L12: RTD | Q12: Dry Kiln
A13: Connection | D13: 2 x Delta / 2 x Wye | G13: Winding | I13: 80/115 | J13: 65 / 86 | K13: 64.6/85.4 | L13: 87.2/115
A14: MCL | D14: 1464 | G14: Frame | J14: - | K14: 34.7/
A15: Allowance for ins. depth | D15: 14.0988 | G15: Bearing PS/OS | J15: - | K15: 36.2/43.5
A16: Allowance for ins. width | D16: 3.6367996 | G16: End Ring | J16: - | K16: -
A17: Slot/Wire arrangement | D17: 14 x 2 | F17: Nameplate Data
A18: Effective cross section for coil | D18: - | H18: FLC (A) | J18: 353 / 204 | K18: 205 | M18: =J18*6.5 -> #VALUE!
A19: Coil grouping | D19: - | H19: RPM | J19: 889 | K19: 889
A20: Coil pitch (slot number) | D20: 1 ~ 9 | H20: CODE | J20: H | K20: H
A21: Method of coil connection | D21: - | H21: S. F. | J21: 1.15 | K21: 1.15 | N21: =SQRT(3)*204 -> 353.33836 | Q21: Method of Connection
A22: Resistance per phase @ 20 °C | D22: 0.081699997 | H22: DESIGN | J22: - | Q22: Skip
A23: Coil Weight | B23: Wire1 | D23: 757.1 | H23: Nom.Eff. (%): | J23: 95.4 | Q23: Adjacent
A24: (lbs.) | B24: Wire2 | D24: - | H24: Min.Eff. (%): | J24: - | Q24: -
A25: Current Densities (A/cm2) | E25: Bar / ER | H25: P.F. (%): | J25: 82.5
A26: FL / LR | D26: 389 / 2696 | E26: 253 / 222
A27: Stator Slot Shape (Reference) | F27: Performance
H28: LRC (A) | I28: - | J28: 2449 / 1414 | K28: 1413.8 | M28: =(J28/J18)*100 -> #VALUE!
H29: LRT (%) | I29: 60 | J29: 140 | K29: 140
H30: BDT (%) | I30: 175 | J30: 240 | K30: 240
H31: SLIP (%) | J31: 1.22 | K31: 1.19
G32: IEEE-B | H32: Eff. (%) | J32: 95.4 | K32: 95.3
A33: Rotor Slot Shape (Reference) | H33: PF (%) | J33: 82.9 | K33: 82.9
F34: Losses (Watts) | H34: Primary | J34: 13305 | K34: 13305
H35: Secondary | J35: 13428 | K35: 13428
H36: Core | J36: 9805 | K36: 9805
H37: F & W | J37: 4487 | K37: 4487
H38: Stray(Assumed 1.2%) | J38: 13428 | K38: 13428
A39: End Ring (Reference) | F39: Note
F40: LINK: | G40: DT8M30U.rat with DT8M30U_lab#1086_RM.dat
...

Sheet LoginSheet
J1: P | K1: T | L1: L | M1: T
B2: PROJECT HISTORY | J2: E | K2: D | L2: I | M2: Y | N2: H
J3: R | L3: M | M3: P
J4: F | L4: I | M4: E
K5: C | L5: T | N5: I
J6: D | K6: U | M6: T | N6: N
J7: A | K7: R | L7: R | M7: E | N7: S
I8: S | J8: T | K8: V | L8: E | M8: S | N8: U
B9: DATE | C9: PROJECT | D9: SMART NUMBER | E9: QTY | F9: CUSTOMER | G9: REMARKS | H9: LIMIT CODE | I9: F | J9: A | K9: E | L9: V | M9: T | N9: L
B53: REVISION HISTORY
B54: REV | C54: REMARKS | I54: DATE | L54: INIT

Sheet StallTime
A1: Rating: | B1: 8 Pole - 1500.0 HP - 900 RPM - 4000 V - 60 Hz
A3: Starting Performance
D4: Load Type: Fan / Pump - 27349.5 lb-ft²
A5: RPM | B5: Motor | C5: Load | D5: Accel. | E5: Line | F5: Stator | G5: Rotor
A6: Speed Increment | B6: Torque (%) | C6: Torque (%) | D6: Time (s) | E6: Amps | F6: kW / s | G6: kW / s
A7: 0~93 | B7: 140.0 | C7: 22.4 | D7: 0.862 | E7: 1409.4 | F7: 563.5 | G7: 1199.1
A8: 93~186 | B8: 140.1 | C8: 11.3 | D8: 0.787 | E8: 1399.3 | F8: 507.8 | G8: 982.2
A9: 186~279 | B9: 140.2 | C9: 7.0 | D9: 0.761 | E9: 1387.4 | F9: 483.4 | G9: 841.1
A10: 279~371 | B10: 140.5 | C10: 7.5 | D10: 0.762 | E10: 1372.4 | F10: 474.8 | G10: 733.4
A11: 371~464 | B11: 141.1 | C11: 12.0 | D11: 0.785 | E11: 1352.7 | F11: 477.6 | G11: 644.9
A12: 464~557 | B12: 142.1 | C12: 19.7 | D12: 0.828 | E12: 1326.7 | F12: 487.3 | G12: 563.6
A13: 557~650 | B13: 143.7 | C13: 30.4 | D13: 0.895 | E13: 1291.5 | F13: 503.5 | G13: 483.3
A14: 650~743 | B14: 146.3 | C14: 46.2 | D14: 1.012 | E14: 1241.9 | F14: 534.3 | G14: 404.2
A15: 743~789 | B15: 150.7 | C15: 61.8 | D15: 0.570 | E15: 1194.2 | F15: 274.2 | G15: 293.0
A16: 789~836 | B16: 160.8 | C16: 74.7 | D16: 0.589 | E16: 1150.4 | F16: 266.0 | G16: 221.0
... A19: 896~900 | B19: 135.0 | C19: 99.6 | D19: 0.111 | E19: 271.3 | F19: 1.5 | G19: 24.2
D21: Acceleration Time: 8.5 s
B22: Energy | D22: First Start | F22: Second Start
A23: Stator Winding Rise | B23: 4803 kW / s | D23: 36°C | F23: 73°C
A24: Rotor Bar Rise | B24: 5877 kW / s | D24: 45°C | F24: 91°C
A25: End Ring Rise | B25: 663 kW / s | D25: 37°C | F25: 75°C
A27: Locked Rotor Thermal Capability
E28: Cold Condition
B29: Rate of Rise | D29: Power | E29: Rise Limit | F29: Max Time
A30: Stator Copper | B30: 5.7°C / s | D30: 754.2 kW | E30: 160°C | F30: 28.1 s
A31: Rotor Bar | B31: 10.9°C / s | D31: 1407.8 kW | E31: 260°C | F31: 23.9 s
A32: Rotor ER | B32: 8.9°C / s | D32: 158.8 kW | E32: 180°C | F32: 20.1 s
E34: Hot Condition
B35: Hot Temp. | D35: Rise Limit | E35: Ambient | F35: Total | G35: Max.Time
A36: Stator Copper | B36: 65°C + | D36: 95°C + | E36: 40°C | F36: = 200°C | G36: 16.7 s
A37: Rotor Bar | B37: 86°C + | D37: 174°C + | E37: 40°C | F37: = 300°C | G37: 16.0 s
A38: Rotor ER | B38: 86°C + | D38: 94°C + | E38: 40°C | F38: = 220°C | G38: 10.5 s
A40: Cold Stall Time: | B40: 42.6 s | D40: Hot Stall Time: | F40: 22.2 s

Sheet Performance Data Sheet
A1: TOSHIBA INTERNATIONAL CORPORATION | J1: INDEX | L1: MPCF-1033
A2: Industrial Division / Houston Motor Plant | J2: SHEET NO. | L2: 1 of 1
J3: ISSUED | L3: 7/31/13
J4: SUPERSEDES | L4: 11/8/96
J5: REVISION | L5: 2
A6: SQUIRREL CAGE INDUCTION MOTOR | J6: WRITTEN BY | L6: MDC
A7: PERFORMANCE SPECIFICATIONS | J7: APPROVED BY | L7: PAA
B9: CUSTOMER: | C9: -
B10: TIC SR No.: | C10: -
A12: MOTOR NAMEPLATE DATA
B13: H.P.: | C13: 1500 | E13: VOLTS: | F13: 4000 | H13: 3 PH / | I13: 60 Hz | L13: S. RPM: | M13: 900
B14: FRAME: | C14: 6813US | E14: ENCL: | F14: WP-II | H14: FLAMPS: | I14: 204 | L14: FLRPM: | M14: 889
B15: FORM: | C15: DCW4 | E15: S.F.: | F15: 1.15 | H15: NEMA DESIGN: | I15: - | L15: INSUL CLASS: | M15: F
B16: TYPE: | C16: TIKE | E16: AMB.: | F16: 40°C | H16: CODE: | I16: H | L16: DUTY: | M16: Cont.
B17: MODEL No.: | C17: M308WTQL11E-C | H17: kW: | I17: -
B18: NOM. EFF.: | C18: - | E18: MIN. EFF.: | F18: - | H18: P.F.: | I18: -
A21: AMPERAGE | E21: TORQUES | I21: **BEARINGS:
C22: LOCKED ROTOR: | D22: 1414 | G22: FULL LOAD (lb-ft.): | H22: 8862 | K22: DRIVE END: | L22: REFER TO NP
G23: LOCKED ROTOR (%): | H23: 140 | K23: OPPOSITE DRIVE END: | L23: REFER TO NP
G24: BREAK DOWN (%): | H24: 240
A28: EFFICIENCY | H28: POWER FACTOR
C29: FULL LOAD: | D29: 95.4 | J29: FULL LOAD: | K29: 82.9
C30: 3/4 LOAD: | D30: 95.1 | J30: 3/4 LOAD: | K30: 79.7
C31: 1/2 LOAD: | D31: 94.1 | J31: 1/2 LOAD: | K31: 71.3
A35: ALL CHARACTERISTICS ARE AVERAGE EXPECTED VALUES BASED UPON RATED VOLTAGE,
A36: FREQUENCY AND SINEWAVE POWER INPUT.
A37: THE DECLARED LOCKED ROTOR CURRENT HAS A TOLERANCE OF 20%.
A38: * TEMPERATURE RISE WILL BE CONSISTENT WITH INSULATION, AMBIENT AND SERVICE FACTOR AS
A39: DEFINED BY NEMA-MG-12 OR -20.
A40: ** BEARINGS ARE THE ONLY RECOMMENDED SPARE PART(S).
J42: CERTIFIED BY: | K42: JERRY R
J44: DATE: | K44: 45156
A59: - | B59: 6205ZZ | D59: 1 | E59: -
A60: TEFC | B60: 6206UU | D60: 1.15 | E60: A
A61: ODP | B61: 6207ZZ | E61: B
B62: 6208UU
B63: 6211ZZ
B64: 6211C3
B65: 6211ZZC3
B66: 6305UUC3
...

Sheet STCurve
A2: TOSHIBA INTERNATIONAL CORPORATION
A3: Speed Torque/Current Curve
A6: Model #: | B6: ='Performance Data Sheet'!C17 -> M308WTQL11E-C | E6: FLAmps: | F6: ='Performance Data Sheet'!I14 -> 204
A7: Enclosure: | B7: ='Performance Data Sheet'!F14 -> WP-II | C7: Voltage: | D7: ='Performance Data Sheet'!F13 & " V" -> 4000 V | E7: Frame: | F7: ='Performance Data Sheet'!C14 -> 6813US
A8: Pole: | B8: 8 | C8: Frequency: | D8: 3 PH / 60 Hz | E8: Ins. Class: | F8: ='Performance Data Sheet'!M15 -> F
A9: HP: | B9: ='Performance Data Sheet'!C13 -> 1500 | C9: Rotor Inertia: | D9: 2224.3 lb-ft² | E9: Date: | F9: ='Performance Data Sheet'!K44 -> 45156
A10: FLRPM: | B10: ='Performance Data Sheet'!M14 -> 889 | C10: Load Inertia: | D10: N/A | E10: File: | F10: DT8M30U
B12: Locked Rotor Amps: | C12: ='Performance Data Sheet'!D22 & " A" -> 1414 A | D12: Load Type: | E12: N/A
B13: Locked Rotor Torque: | C13: ='Performance Data Sheet'!H23/100 -> 1.4 | D13: Starting at: | E13: N/A
B14: Breakdown Torque: | C14: 2.4 | D14: Accel. Time: | E14: N/A
B15: Rated Torque: | C15: ='Performance Data Sheet'!H22 & " lb-ft" -> 8862 lb-ft
A39: Comments: | B39: PROJECT | C39: ='Performance Data Sheet'!C10 -> - | E39: D.E.Curve #: | F39: =F10 -> DT8M30U
C43: Prepared by: | D43: ='Performance Data Sheet'!K42 -> JERRY R | E43: Checked by:
D53: Load
A54: 100 | B54: 0 | C54: 0.33853829 | D54: 100
A55: 99.6 | B55: 169.97 | C55: 196.92267 | D55: 99.199997
A56: 98 | B56: 240 | C56: 491.444 | D56: 95.25
A57: 92.842105 | B57: 168.19493 | C57: 551.61359 | D57: 81.389473
A58: 87.68421 | B58: 153.38442 | C58: 576.26697 | D58: 67.978951
A59: 82.526316 | B59: 148.0063 | C59: 594.52789 | D59: 55.557896
A60: 72.210526 | B60: 144.68834 | C60: 623.02362 | D60: 36.757896
A61: 61.894736 | B61: 142.66957 | C61: 643.1153 | D61: 24.084209
A62: 51.578948 | B62: 141.43126 | C62: 657.60925 | D62: 15.263159
A63: 41.263157 | B63: 140.73385 | C63: 668.5719 | D63: 8.7578945
A64: 30.947369 | B64: 140.34985 | C64: 676.88013 | D64: 6.1894736
A65: 20.631576 | B65: 140.14472 | C65: 683.27991 | D65: 7.8736849
... A67: 0 | B67: 140 | C67: 693.13727 | D67: 30

Sheet Thermdam
A2: TOSHIBA INTERNATIONAL CORPORATION
A3: Thermal Limit & Acceleration Curves
A4: Design Values (For Reference Only)
A6: Model #: | B6: ='Performance Data Sheet'!C17 -> M308WTQL11E-C | E6: FLAmps: | F6: ='Performance Data Sheet'!I14 -> 204
A7: Enclosure: | B7: ='Performance Data Sheet'!F14 -> WP-II | C7: Voltage: | D7: ='Performance Data Sheet'!F13 & " V" -> 4000 V | E7: Frame: | F7: ='Performance Data Sheet'!C14 -> 6813US
A8: Pole: | B8: 8 | C8: Frequency: | D8: 3 PH / 60 Hz | E8: Ins. Class: | F8: ='Performance Data Sheet'!M15 -> F
A9: HP: | B9: ='Performance Data Sheet'!C13 -> 1500 | C9: Rotor Inertia: | D9: 2224.3 lb-ft² | E9: Date: | F9: ='Performance Data Sheet'!K44 -> 45156
A10: FLRPM: | B10: ='Performance Data Sheet'!M14 -> 889 | C10: Load Inertia: | D10: 27349.5 lb-ft² | E10: File: | F10: DT8M30U
C12: ='Performance Data Sheet'!D22 & " A" -> 1414 A
C13: ='Performance Data Sheet'!H23/100 -> 1.4
C15: ='Performance Data Sheet'!H22 & " lb-ft" -> 8862 lb-ft
A39: Comments: | B39: PROJECT | C39: ='Performance Data Sheet'!C10 -> - | E39: D.E.Curve #: | F39: =F10 -> DT8M30U
C43: Prepared by: | D43: ='Performance Data Sheet'!K42 -> JERRY R | E43: Checked by:
F50: =5252.1*B50/D53 -> #DIV/0!
D66: =D65/D64 -> #DIV/0!
A67: Current (%) | B67: Cold | C67: Hot | E67: CURRENT (%) | F67: Accel. Time
A68: 693.13725 | B68: 35 | C68: 15 | E68: =A68 -> 693.13725 | F68: 0.0001
A69: =FLOOR(A68,100) -> 600 | B69: =((A68/A69)^2)*B68 -> 46.709372 | C69: =((A68/A69)^2)*C68 -> 20.018302 | E69: 690.88235 | F69: 0.86199999
A70: =A69-100 -> 500 | B70: =((A68/A70)^2)*B68 -> 67.261496 | C70: =((A68/A70)^2)*C68 -> 28.826355 | E70: 685.93137 | F70: 1.6489999
A71: =A70-100 -> 400 | B71: =((A68/A71)^2)*B68 -> 105.09609 | C71: =((A68/A71)^2)*C68 -> 45.04118 | E71: 680.09804 | F71: 2.4099998
A72: =A71-100 -> 300 | B72: =((A68/A72)^2)*B68 -> 186.83749 | E72: 672.7451 | F72: 3.1719999
A73: =A72-100 -> 200 | B73: =((A68/A73)^2)*B68 -> 420.38435 | E73: 663.08824 | F73: 3.957
A74: 240 | B74: =((A68/A74)^2)*B68 -> 291.93357 | C74: =((A68/A74)^2)*C68 -> 125.11439 | E74: 650.34314 | F74: 4.7849998
A75: 180 | B75: =((A68/A75)^2)*B69 -> 692.62394 | C75: =((A68/A75)^2)*C68 -> 222.42558 | E75: 633.08824 | F75: 5.6799998
A76: 145 | B76: =((A68/A76)^2)*B68 -> 799.77997 | C76: =((A68/A76)^2)*C68 -> 342.76284 | E76: 608.77451 | F76: 6.6919999
A77: 125 | C77: =CEILING(C76*2,100) -> 700 | E77: 585.39216 | F77: 7.2620001
A78: 125 | C78: =2*C77 -> 1400 | E78: 563.92157 | F78: 7.8510003
A79: 125 | C79: 10000 | E79: 521.51961 | F79: 8.2890005
E80: 344.16667 | F80: 8.4350004
E81: 132.79491 | F81: 8.5460005

Sheet Performance 4000V
A2: TOSHIBA INTERNATIONAL CORPORATION
A3: Performance Curve
A4: Design Values (For Reference Only)
A6: Model #: | B6: ='Performance Data Sheet'!C17 -> M308WTQL11E-C | E6: FLAmps: | F6: 204 A
A7: Enclosure: | B7: ='Performance Data Sheet'!F14 -> WP-II | C7: Voltage: | D7: 4000V | E7: Frame: | F7: ='Performance Data Sheet'!C14 -> 6813US
A8: Pole: | B8: 8 | C8: Frequency: | D8: 3 PH / 60 Hz | E8: Ins. Class: | F8: ='Performance Data Sheet'!M15 -> F
A9: HP: | B9: ='Performance Data Sheet'!C13 -> 1500 | C9: Rotor Inertia: | D9: 2224.3 lb-ft² | E9: Date: | F9: ='Performance Data Sheet'!K44 -> 45156
A10: FLRPM: | B10: ='Performance Data Sheet'!M14 -> 889 | C10: Load Inertia: | D10: N/A | E10: File: | F10: DT8M30U
B12: Locked Rotor Amps: | C12: 1414 A | D12: Load Type: | E12: N/A
B13: Locked Rotor Torque: | C13: ='Performance Data Sheet'!H23/100 -> 1.4 | D13: Starting at: | E13: N/A
B14: Breakdown Torque: | C14: 2.4 | D14: Accel. Time: | E14: N/A
B15: Rated Torque: | C15: ='Performance Data Sheet'!H22 & " lb-ft" -> 8862 lb-ft
N36: SPEED | O36: KW
N37: =L43 - (L43-L44) / 10 * 0 -> 900 | O37: =L45 / 10 * 10 -> 4000
N38: =L43 - (L43-L44) / 10 * 1 -> 898 | O38: =L45 / 10 * 9 -> 3600
A39: Comments: | B39: PROJECT | C39: ='Performance Data Sheet'!C10 -> - | E39: D.E.Curve #: | F39: =F10 -> DT8M30U | N39: =L43 - (L43-L44) / 10 * 2 -> 896 | O39: =L45 / 10 * 8 -> 3200
N40: =L43 - (L43-L44) / 10 * 3 -> 894 | O40: =L45 / 10 * 7 -> 2800
N41: =L43 - (L43-L44) / 10 * 4 -> 892 | O41: =L45 / 10 * 6 -> 2400
N42: =L43 - (L43-L44) / 10 * 5 -> 890 | O42: =L45 / 10 * 5 -> 2000
C43: Prepared by: | D43: ='Performance Data Sheet'!K42 -> JERRY R | E43: Checked by: | K43: SYNC SPEED | L43: 900 | N43: =L43 - (L43-L44) / 10 * 6 -> 888 | O43: =L45 / 10 * 4 -> 1600
K44: NEW SPEED LOWER RANGE | L44: 880 | N44: =L43 - (L43-L44) / 10 * 7 -> 886 | O44: =L45 / 10 * 3 -> 1200
K45: NEW kW UPPER RANGE | L45: 4000 | N45: =L43 - (L43-L44) / 10 * 8 -> 884 | O45: =L45 / 10 * 2 -> 800
N46: =L43 - (L43-L44) / 10 * 9 -> 882 | O46: =L45 / 10 * 1 -> 400
N47: =L43 - (L43-L44) / 10 * 10 -> 880 | O47: =L45 / 10 * 0 -> 0
A52: ADJUSTED
A53: Load | B53: Efficiency | C53: PF | D53: Amps | E53: RPM | F53: Input Watts
A54: 0 | D54: 73 | E54: 100 | F54: =16200/(L45*1000) * 100 -> 0.405
A55: 25 | B55: 90.900002 | C55: 56.400002 | D55: 78.75 | E55: =(1.00852384449258*B10-L44)/(L43-L44)*100 -> 82.888489 | F55: =307716.2/(L45*1000)*100 -> 7.692905
A56: 50 | B56: 94.099998 | C56: 71.300003 | D56: 120.3 | E56: =(1.00632417590868*B10-L44)/(L43-L44)*100 -> 73.110962 | F56: =594259/(L45*1000)*100 -> 14.856475
A57: 75 | B57: 95.099998 | C57: 79.699997 | D57: 159.97 | E57: =(1.00329960585981*B10-L44)/(L43-L44)*100 -> 59.666748 | F57: =883318.8/(L45*1000)*100 -> 22.08297
A58: 100 | B58: 95.400002 | C58: 82.900002 | D58: 204.3 | E58: =(1*B10-L44)/(L43-L44)*100 -> 45 | F58: =1173393/(L45*1000)*100 -> 29.334825
A59: 125 | B59: 95.400002 | C59: 83.900002 | D59: 252.36 | E59: =(0.996700394140186*B10-L44)/(L43-L44)*100 -> 30.333252 | F59: =1466909/(L45*1000)*100 -> 36.672725
A62: ORIGINAL
A63: Load | B63: Efficiency | C63: PF | D63: Amps | E63: RPM | F63: Input Watts
A64: 0 | D64: 71.603287 | E64: 100 | F64: 23.337203
A65: 25 | B65: 90.945473 | C65: 56.361832 | D65: 78.75354 | E65: 60.337126 | F65: 7.6878175
A66: 50 | B66: 94.148621 | C66: 71.282204 | D66: 120.30154 | E66: 56.097385 | F66: 14.852522
A67: 75 | B67: 95.090591 | C67: 79.614891 | D67: 159.96527 | E67: 50.526025 | F67: 22.05809
A68: 100 | B68: 95.391449 | C68: 82.85408 | D68: 204.30214 | E68: 44.754428 | F68: 29.318025
A69: 125 | B69: 95.411255 | C69: 83.828072 | D69: 252.35806 | E69: 38.844309 | F69: 36.639925

Sheet Performance 2300V
A2: TOSHIBA INTERNATIONAL CORPORATION
A3: Performance Curve
A4: Design Values (For Reference Only)
A6: Model #: | B6: ='Performance Data Sheet'!C17 -> M308WTQL11E-C | E6: FLAmps: | F6: 353 A
A7: Enclosure: | B7: ='Performance Data Sheet'!F14 -> WP-II | C7: Voltage: | D7: 2300 V | E7: Frame: | F7: ='Performance Data Sheet'!C14 -> 6813US
A8: Pole: | B8: 8 | C8: Frequency: | D8: 3 PH / 60 Hz | E8: Ins. Class: | F8: ='Performance Data Sheet'!M15 -> F
A9: HP: | B9: ='Performance Data Sheet'!C13 -> 1500 | C9: Rotor Inertia: | D9: 2224.3 lb-ft² | E9: Date: | F9: ='Performance Data Sheet'!K44 -> 45156
A10: FLRPM: | B10: ='Performance Data Sheet'!M14 -> 889 | C10: Load Inertia: | D10: N/A | E10: File: | F10: DT8M30U
B12: Locked Rotor Amps: | C12: 2449 A | D12: Load Type: | E12: N/A
B13: Locked Rotor Torque: | C13: ='Performance Data Sheet'!H23/100 -> 1.4 | D13: Starting at: | E13: N/A
B14: Breakdown Torque: | C14: 2.4 | D14: Accel. Time: | E14: N/A
B15: Rated Torque: | C15: ='Performance Data Sheet'!H22 & " lb-ft" -> 8862 lb-ft
N36: SPEED | O36: KW
N37: =L43 - (L43-L44) / 10 * 0 -> 900 | O37: =L45 / 10 * 10 -> 4000
N38: =L43 - (L43-L44) / 10 * 1 -> 898 | O38: =L45 / 10 * 9 -> 3600
A39: Comments: | B39: PROJECT | C39: ='Performance Data Sheet'!C10 -> - | E39: D.E.Curve #: | F39: =F10 -> DT8M30U | N39: =L43 - (L43-L44) / 10 * 2 -> 896 | O39: =L45 / 10 * 8 -> 3200
N40: =L43 - (L43-L44) / 10 * 3 -> 894 | O40: =L45 / 10 * 7 -> 2800
N41: =L43 - (L43-L44) / 10 * 4 -> 892 | O41: =L45 / 10 * 6 -> 2400
N42: =L43 - (L43-L44) / 10 * 5 -> 890 | O42: =L45 / 10 * 5 -> 2000
C43: Prepared by: | D43: ='Performance Data Sheet'!K42 -> JERRY R | E43: Checked by: | K43: SYNC SPEED | L43: 900 | N43: =L43 - (L43-L44) / 10 * 6 -> 888 | O43: =L45 / 10 * 4 -> 1600
K44: NEW SPEED LOWER RANGE | L44: 880 | N44: =L43 - (L43-L44) / 10 * 7 -> 886 | O44: =L45 / 10 * 3 -> 1200
K45: NEW kW UPPER RANGE | L45: 4000 | N45: =L43 - (L43-L44) / 10 * 8 -> 884 | O45: =L45 / 10 * 2 -> 800
N46: =L43 - (L43-L44) / 10 * 9 -> 882 | O46: =L45 / 10 * 1 -> 400
N47: =L43 - (L43-L44) / 10 * 10 -> 880 | O47: =L45 / 10 * 0 -> 0
A52: ADJUSTED
A53: Load | B53: Efficiency | C53: PF | D53: Amps | E53: RPM | F53: Input Watts
A54: 0 | D54: 126.43971 | E54: 100 | F54: =16200/(L45*1000) * 100 -> 0.405
A55: 25 | B55: 90.900002 | C55: 56.400002 | D55: 136.399 | E55: =(1.00852384449258*B10-L44)/(L43-L44)*100 -> 82.888489 | F55: =307716.2/(L45*1000)*100 -> 7.692905
A56: 50 | B56: 94.099998 | C56: 71.300003 | D56: 208.36572 | E56: =(1.00632417590868*B10-L44)/(L43-L44)*100 -> 73.110962 | F56: =594259/(L45*1000)*100 -> 14.856475
A57: 75 | B57: 95.099998 | C57: 79.699997 | D57: 277.07617 | E57: =(1.00329960585981*B10-L44)/(L43-L44)*100 -> 59.666748 | F57: =883318.8/(L45*1000)*100 -> 22.08297
A58: 100 | B58: 95.400002 | C58: 82.900002 | D58: 353 | E58: =(1*B10-L44)/(L43-L44)*100 -> 45 | F58: =1173393/(L45*1000)*100 -> 29.334825
A59: 125 | B59: 95.400002 | C59: 83.900002 | D59: 437.10034 | E59: =(0.996700394140186*B10-L44)/(L43-L44)*100 -> 30.333252 | F59: =1466909/(L45*1000)*100 -> 36.672725
A62: ORIGINAL
A63: Load | B63: Efficiency | C63: PF | D63: Amps | E63: RPM | F63: Input Watts
A64: 0 | D64: 71.603287 | E64: 100 | F64: 23.337203
A65: 25 | B65: 90.945473 | C65: 56.361832 | D65: 78.75354 | E65: 60.337126 | F65: 7.6878175
A66: 50 | B66: 94.148621 | C66: 71.282204 | D66: 120.30154 | E66: 56.097385 | F66: 14.852522
A67: 75 | B67: 95.090591 | C67: 79.614891 | D67: 159.96527 | E67: 50.526025 | F67: 22.05809
A68: 100 | B68: 95.391449 | C68: 82.85408 | D68: 204.30214 | E68: 44.754428 | F68: 29.318025
A69: 125 | B69: 95.411255 | C69: 83.828072 | D69: 252.35806 | E69: 38.844309 | F69: 36.639925
