Workbook
Name Print_Area_MI: 'Performance Data Sheet'!$A$10:$N$42

Sheet DesignSheet
A1: TOSHIBA INTERNATIONAL CORPORATION | I1: Calc. Code: | J1: 2-2-2-0-1-2
A2: 3-PHASE SQUIRREL CAGE INDUCTION MOTOR DESIGN SHEET | J2: B.L.-1 P.F.-1
A3: File: | B3: N:\DESPRO\RAT FILES\1T2700K_REV1.rat | G3: Date: | H3: 44670 | I3: Time: | J3: 0.35722222
A4: Pole | B4: HP | C4: RPM | D4: Form | E4: Voltage | F4: Frequency | G4: Temperature | H4: FLSpeed | I4: FLSlip | J4: Frame
A5: 2 | B5: 700.00002 | C5: 3600 | D5: DCKW | E5: 4000 | F5: 60 | G5: 105 | H5: 3567.1 / 3559.9 | I5: 0.0091 / 0.0111 | J5: 5012
A6: Core Data | D6: Winding Data | H6: Constant Data
B7: Primary | C7: Secondary | F7: Bar | G7: End Ring | H7: St. Slot Pitch | I7: 25.431919 | J7: LR Test Data
A8: Air Gap | B8: 2.9000001 | H8: Rt. Slot Pitch | I8: 30.879982 | J8: ES
A9: Space Fac. | B9: 0.93000001 | D9: Pitch | E9: 1 ~ 14 | F9: Cross Section Area | H9: Mean Value | I9: 28.15595 | J9: 539.54893
A10: Core Length | B10: 452 | C10: 452 | F10: UB: 417.4 | G10: UER: 2800.0 | H10: Eff.T.W.St. | I10: 18.247458 | J10: WS
A11: OD | B11: 590 | C11: 334.2 | D11: Coil Pitch | E11: 0.61898571 | G11: ERT: 70.0 | H11: Eff.T.W.Rt. | I11: 30.879982 | J11: 26267.149
A12: ID | B12: 340 | C12: 155 | D12: Slot Fill | E12: - | G12: ERD1: 246.2 | H12: St.Carter Fac. | I12: 1.3937239 | J12: IS
A13: Core Depth | B13: 68 | C13: 54.6 | D13: Con./Slot | E13: 18 | G13: ERD2: 332.2 | H13: Rt.Carter Fac. | I13: 1 | J13: 87.453346
A14: Eff.Core L. | B14: 353.39999 | C14: 360.84 | D14: Wire Size 1 | E14: (.081"x.204")x1 | H14: Carter Factor | I14: 1.3937239 | J14: Volts / Turn
A15: Slot Data | D15: Wire Size 2 | E15: (.081"x.182")x1 | H15: Short. Factor | I15: 0.82618353 | J15: 18.329117
A16: Number | B16: 42 | C16: 34 | D16: // Circuits | E16: 1 | H16: Distrib. Factor | I16: 0.95564622 | J16: AC
A17: Kind | B17: Open | C17: Dbl - Closed | D17: Connection | E17: Wye | H17: Wind. Factor | I17: 0.78953916 | J17: 618.97029
A18: Skew | B18: - | C18: 0 | D18: MCL | E18: 1042 | F18: 522 | H18: Reactance | I18: (Coeff.: 0.0702)
A19: Depth | B19: 57 | C19: 35 | D19: No.Cond./Ph. | E19: 252 | I19: Running | J19: Start
A20: Width | B20: 14.00 - 14.00 | D20: Res. (20°C) | E20: 0.23393302 | H20: Stator Slot | I20: 11.786048 | J20: 11.786048
A21: Opening | B21: 14 | C21: 0 | D21: (105°C) | E21: 0.31206389 | F21: 0.19034278 | G21: 0.078464405 | H21: Rotor Slot | I21: 29.345665 | J21: 14.921493
A22: Tip Depth | B22: 2.8299999 | C22: 1 | D22: Material | E22: CU | F22: AL | G22: AL | H22: Zigzag | I22: 7.0829816 | J22: 6.3129973
A23: T.Min.Wid. | B23: 11.431919 | C23: 11 | D23: Spec.Resist. | E23: 1.742 | F23: 3.25 | G23: 3.25 | H23: Coil End | I23: 20.325076 | J23: Skew R.: 0.00
A24: Low. R. | B24: 0 | C24: 2 | D24: Spec.Gravity | E24: 8.8900003 | F24: 2.6700001 | G24: 2.6700001 | H24: Belt Leakage | I24: 5.8606569 | J24: 5.2704008
A25: Up. R. | B25: - | C25: 2 | D25: Weight (kg) | H25: Total Resist. | I25: 0.58087111 | J25: 1.1448243
A26: Wedge Dep. | B26: 1.20 - 2.40 | C26: Normal | D26: Wire 1 | E26: 72.493425 | F26: 17.127408 | G26: 14.007365 | H26: Total React. | I26: 5.2205882 | J26: 4.1097279
A27: Duct | B27: 9 x 8 | C27: 8 x 8 | D27: Wire 2 | E27: 64.442115 | F27: - | G27: - | H27: Impedance | I27: 5.2528043 | J27: 4.2662024
A28: Effective Depth (S=1) | D28: Magnetic Circuit Data | I28: Core Loss Data
B29: Res.= | C29: 33.987912 | E29: Length | F29: Section | G29: Density | H29: AT | I29: Volume | J29: Loss | M29: =RIGHT(F$41,SEARCH("/",F$41,1)-1) -> 3551.4 | N29: 125RPM | P29: Kline/in2
B30: Reac.= | C30: 33.996545 | D30: Primary Core | E30: 46.338453 | F30: 480.62399 | G30: 18.131269 | H30: 929.53908 | I30: 39409.004 | J30: 3666.1741 | M30: =RIGHT(E$41,SEARCH("/",E$41,1)-1) -> 3559.9 | N30: 100RPM | P30: =G30*6.4516 -> 116.9757
A31: Excitation Data | D31: Tooth | E31: 5.7 | F31: 848.40843 | G31: 10.271377 | H31: 14.827702 | I31: 9671.8561 | J31: 358.35396 | M31: =RIGHT(D$41,SEARCH("/",D$41,1)-1) -> 3568.3 | N31: 75RPM | P31: =G31*6.4516 -> 66.266816
A32: Excit.Amps | B32: 23.786 / 20.977 | D32: Second.Core | E32: 20.750202 | F32: 580.47127 | G32: 15.012496 | H32: 188.66038 | I32: Total | J32: 4024.528 | M32: =RIGHT(C$41,SEARCH("/",C$41,1)-1) -> 3576.5 | N32: 50RPM | P32: =G32*6.4516 -> 96.854621
A33: Core Loss | B33: 1.106 / 0.975 | C33: Flux / Pole | D33: Tooth | E33: 3.5 | F33: 674.77079 | G33: 12.914493 | H33: 17.617192 | I33: C.L.C. | J33: 1.50 / 0.99 | M33: =RIGHT(B$41,SEARCH("/",B$41,1)-1) -> 3584.5 | N33: 25RPM | P33: =G33*6.4516 -> 83.319145
A34: NoLoad | B34: 23.81 / 21.00 | C34: 8.7143229 | D34: Air Gap | E34: 0.29000001 | F34: 1471.4751 | G34: 5.9221683 | H34: 1366.6876 | I34: S.F.C. | J34: 6.0500002 | P34: =G34*6.4516 -> 38.207461
A35: Load Characteristics | D35: Temp. Rise @ 100%: | E35: 51 / 48 | G35: No Load Loss | H35: 11067.2 / 8766.7 | I35: W.Loss | J35: 6036.8 / 3993.9
A36: Load (%) | B36: 25 | C36: 50 | D36: 75 | E36: 100 | F36: 125 | G36: Primary Loss | H36: 7160.1 / 7568.9 | I36: S.Loss | J36: 1633.4 / 1080.7
A37: Current (A) | B37: 33.37 / 35.02 | C37: 48.87 / 51.28 | D37: 67.41 / 70.74 | E37: 87.45 / 91.77 | F37: 108.61 / 113.97 | G37: Second. Loss | H37: 4971.2 / 5855.3 | I37: Total C.Loss | J37: 7670.2 / 5074.6
A38: Efficiency | B38: 0.916 / 0.900 | C38: 0.949 / 0.933 | D38: 0.958 / 0.941 | E38: 0.959 / 0.943 | F38: 0.958 / 0.942 | G38: Frict.& Wind. | H38: 3000.0 / 3271.9 | I38: Stray Loss | J38: 9929.6426 | L38: =LEFT(E38,SEARCH("/",E38,1)-1) -> 0.959 | M38: =RIGHT(E38,SEARCH("/",E38,1)-1) -> 0.943 | N38: =M38/L38 -> 0.98331595 | O38: Eff.
A39: P.F. | B39: 0.616 / 0.598 | C39: 0.812 / 0.788 | D39: 0.876 / 0.849 | E39: 0.899 / 0.871 | F39: 0.906 / 0.878 | G39: Starting Data | I39: Slip | J39: PF | L39: =LEFT(E39,SEARCH("/",E39,1)-1) -> 0.899 | M39: =RIGHT(E39,SEARCH("/",E39,1)-1) -> 0.871 | N39: =M39/L39 -> 0.96885428 | O39: PF.
A40: Slip | B40: 0.0023 / 0.0043 | C40: 0.0045 / 0.0065 | D40: 0.0068 / 0.0088 | E40: 0.0091 / 0.0111 | F40: 0.0115 / 0.0135 | G40: LRA | H40: 541.3 / 537.3 | L40: =LEFT(E37,SEARCH("/",E37,1)-1) -> 87.45 | M40: =RIGHT(E37,SEARCH("/",E37,1)-1) -> 91.77 | N40: =M40/L40 -> 1.0493997 | O40: Current
...

Sheet Data Sheet
A1: TOSHIBA INTERNATIONAL CORPORATION
A2: INDUCTION MOTOR DATA SHEET
A3: File: | B3: 1T2700K_REV1 | I3: HRW / Model Number: | J3: 7003WTAK11F-A
A4: Type: TIKK - Form: DCKW - 2 Pole - 700 HP - 2300 / 4000 V - 60 Hz - 5012 - Class F | Q4: Motor Type Selection | T4: Electrical Steel Table
A5: Motor Parameters | F5: PERFORMANCE | J5: DESIGN | K5: TEST | Q5: EPACT | T5: M22 - 26Ga.
A6: Material | D6: M22 - 26Ga. | F6: NL & Impedance Test | Q6: EQP-III | T6: M36 - 26Ga.
A7: Air Gap | D7: 2.9000001 | F7: No load amps | J7: 36 / 21 | K7: - | Q7: Exp.Prf. | T7: NCB1 - 26Ga.
A8: Stack length | D8: 452 | F8: No load watts | J8: 8610 | K8: - | Q8: Exp.Prf.-EQPIII | T8: M43 - 26Ga.
A9: Number of turns per coil | D9: 9 | F9: Impedance amps | H9: 3 | I9: f | J9: 92 | K9: - | Q9: Prem. Eff. | T9: M45 - 26Ga.
A10: Wire 1 (size & number) | D10: (.081"x.204")x1 | F10: Impedance volts | H10: 3 | I10: f | J10: 929 | K10: - | Q10: OWP | T10: M54 - 26Ga.
A11: Wire 2 (size & number) | D11: (.081"x.182")x1 | F11: Impedance watts | H11: 3 | I11: f | J11: 28135 | K11: - | Q11: Dry Kiln
A12: Slot fill - circle/square method (%) | D12: - | F12: Temperature Rise (°C)
A13: Connection | D13: 1D / 1Y | G13: Winding | I13: 80/115 | J13: 46 / 61 | K13: -
A14: MCL | D14: 1042 [1071 (1.03)] | G14: Frame | J14: - | K14: -
A15: Allowance for ins. depth | D15: 8.9647999 | G15: Bearing PS/OS | J15: - | K15: -
A16: Allowance for ins. width | D16: 3.2368 | G16: End Ring | J16: - | K16: -
A17: Slot/Wire arrangement | D17: 18 x 2 | F17: Nameplate Data
A18: Effective cross section for coil | D18: - | H18: FLC (A) | J18: 159 / 92
A19: Coil grouping | D19: - | H19: RPM | J19: 3560
A20: Coil pitch (slot number) | D20: 1 ~ 14 | H20: CODE | J20: F
A21: Method of coil connection | D21: Adjacent | H21: S. F. | J21: 1.15 | Q21: Method of Connection
A22: Resistance per phase @ 20 °C | D22: 0.199 [0.2357 (1.03)] | H22: DESIGN | Q22: Skip
A23: Coil Weight | B23: Wire1 | D23: 370 | H23: Nom.Eff. (%): | Q23: Adjacent
A24: (lbs.) | B24: Wire2 | D24: - | H24: Min.Eff. (%): | Q24: -
A25: Current Densities (A/cm2) | E25: Bar / ER | H25: P.F. (%):
A26: FL / LR | D26: 393 / 2302 | E26: 346 / 279
A27: Stator Slot Shape (Reference) | F27: Performance
H28: LRC (A) | I28: - | J28: 934/ 539 | K28: -
H29: LRT (%) | I29: 60 | J29: 120 | K29: -
H30: BDT (%) | I30: 175 | J30: 255 | K30: -
H31: SLIP (%) | J31: 1.11 | K31: -
G32: IEEE-B | H32: Eff. (%) | J32: 94.5 | K32: -
A33: Rotor Slot Shape (Reference) | H33: PF (%) | J33: 87.1 | K33: -
F34: Losses (Watts) | H34: Primary | J34: 6316 | K34: -
H35: Secondary | J35: 5821 | K35: -
H36: Core | J36: 5075 | K36: -
H37: F & W (A/F Brg) | J37: 3272 | K37: -
H38: Stray | J38: 9872 | K38: -
A39: End Ring (Reference) | F39: Note
F40: LINK: 1T2700K_REV1.RAT & DAT
...

Sheet LoginSheet
J1: P | K1: T | L1: L | M1: T
B2: PROJECT HISTORY | J2: E | K2: D | L2: I | M2: Y | N2: H
J3: R | L3: M | M3: P
J4: F | L4: I | M4: E
K5: C | L5: T | N5: I
J6: D | K6: U | M6: T | N6: N
J7: A | K7: R | L7: R | M7: E | N7: S
I8: S | J8: T | K8: V | L8: E | M8: S | N8: U
B9: DATE | C9: PROJECT | D9: SMART NUMBER | E9: QTY | F9: CUSTOMER | G9: REMARKS | H9: LIMIT CODE | I9: F | J9: A | K9: E | L9: V | M9: T | N9: L
B53: REVISION HISTORY
B54: REV | C54: REMARKS | I54: DATE | L54: INIT

Sheet Form
A1: Winding Data Calculation
C2: MCL: 1042.0
A3: Coil Resistance | D3: Lead Resistance
A4: 9T: | B4: 0.01443 ~ 0.01387 | D4: AWG. 02 x 6
D5: 0.00125
A6: Coil Dimensions
A7: HM: | B7: 9T: 22.60 | C7: WM: | D7: 9T: 10.76 | E7: WT:
E8: 14.10 ~ 13.70
A9: Insulation Allowance | D9: Wire Weight
A10: Depth: | B10: 8.96 | D10: (.091"x.204")x 2: | F10: 370 lbs.
A11: Width: | B11: 3.24
A12: QC Resistance
A13: 1-4, 2-5, 3-6: | C13: 0.205 ~ 0.193

Sheet Performance Data Sheet
A1: TOSHIBA INTERNATIONAL CORPORATION | J1: INDEX | L1: MPCF-1033
A2: Industrial Division / Houston Motor Plant | J2: SHEET NO. | L2: 1 of 1
J3: ISSUED | L3: 7/31/13
J4: SUPERSEDES | L4: 11/8/96
J5: REVISION | L5: 2
A6: SQUIRREL CAGE INDUCTION MOTOR | J6: WRITTEN BY | L6: MDC
A7: PERFORMANCE SPECIFICATIONS | J7: APPROVED BY | L7: PAA
B9: CUSTOMER: | C9: -
B10: TIC SR No.: | C10: -
A12: MOTOR NAMEPLATE DATA
B13: H.P.: | C13: 700 | E13: VOLTS: | F13: 4000 | H13: 3 PH / | I13: 60 Hz | L13: S. RPM: | M13: 3600
B14: FRAME: | C14: 5012USS | E14: ENCL: | F14: WP-II | H14: FLAMPS: | I14: 92 | L14: FLRPM: | M14: 3560
B15: FORM: | C15: DCKW | E15: S.F.: | F15: 1.15 | H15: NEMA DESIGN: | I15: - | L15: INSUL CLASS: | M15: F
B16: TYPE: | C16: TKKH | E16: AMB.: | F16: 40°C | H16: CODE: | I16: F | L16: DUTY: | M16: Cont.
B17: MODEL No.: | C17: 7003WTAK11F-A | H17: kW: | I17: -
B18: NOM. EFF.: | C18: - | E18: MIN. EFF.: | F18: - | H18: P.F.: | I18: -
A21: AMPERAGE | E21: TORQUES | I21: **BEARINGS:
C22: LOCKED ROTOR: | D22: 539 | G22: FULL LOAD (lb-ft.): | H22: 1033 | K22: DRIVE END: | L22: REFER TO NP
G23: LOCKED ROTOR (%): | H23: 120 | K23: OPPOSITE DRIVE END: | L23: REFER TO NP
G24: BREAK DOWN (%): | H24: 255
A28: EFFICIENCY | H28: POWER FACTOR
C29: FULL LOAD: | D29: 94.5 | J29: FULL LOAD: | K29: 87.1
C30: 3/4 LOAD: | D30: 94.3 | J30: 3/4 LOAD: | K30: 84.8
C31: 1/2 LOAD: | D31: 93.5 | J31: 1/2 LOAD: | K31: 78.7
A35: ALL CHARACTERISTICS ARE AVERAGE EXPECTED VALUES BASED UPON RATED VOLTAGE,
A36: FREQUENCY AND SINEWAVE POWER INPUT.
A37: THE DECLARED LOCKED ROTOR CURRENT HAS A TOLERANCE OF 20%.
A38: * TEMPERATURE RISE WILL BE CONSISTENT WITH INSULATION, AMBIENT AND SERVICE FACTOR AS
A39: DEFINED BY NEMA-MG-12 OR -20.
A40: ** BEARINGS ARE THE ONLY RECOMMENDED SPARE PART(S).
J42: CERTIFIED BY: | K42: Jerry R
J44: DATE: | K44: 44669
A59: - | B59: 6205ZZ | D59: 1 | E59: -
A60: TEFC | B60: 6206UU | D60: 1.15 | E60: A
A61: ODP | B61: 6207ZZ | E61: B
B62: 6208UU
B63: 6211ZZ
B64: 6211C3
B65: 6211ZZC3
B66: 6305UUC3
...

Sheet STCurve
A2: TOSHIBA INTERNATIONAL CORPORATION
A3: Speed Torque/Current Curve
A6: Model #: | B6: ='Performance Data Sheet'!C17 -> 7003WTAK11F-A | E6: FLAmps: | F6: ='Performance Data Sheet'!I14 & " A" -> 92 A
A7: Enclosure: | B7: ='Performance Data Sheet'!F14 -> WP-II | C7: Voltage: | D7: ='Performance Data Sheet'!F13 & " V" -> 4000 V | E7: Frame: | F7: ='Performance Data Sheet'!C14 -> 5012USS
A8: Pole: | B8: 2 | C8: Frequency: | D8: 3 PH / 60 Hz | E8: Ins. Class: | F8: F
A9: HP: | B9: 700 | C9: Rotor Inertia: | D9: 114.9 lb-ft² | E9: Date: | F9: ='Performance Data Sheet'!K44 -> 44669
A10: FLRPM: | B10: 3560 | C10: Load Inertia: | D10: N/A | E10: File: | F10: 1T2700K_REV1
B12: Locked Rotor Amps: | C12: ='Performance Data Sheet'!D22 & " A" -> 539 A | D12: Load Type: | E12: N/A
B13: Locked Rotor Torque: | C13: 1.2 | D13: Starting at: | E13: N/A
B14: Breakdown Torque: | C14: 2.55 | D14: Accel. Time: | E14: N/A
B15: Rated Torque: | C15: 1033 lb-ft
A39: Comments: | B39: PROJECT | C39: ='Performance Data Sheet'!J38 -> 0 | E39: D.E.Curve #: | F39: =F10 -> 1T2700K_REV1
C43: Prepared by: | D43: ='Performance Data Sheet'!K42 -> Jerry R | E43: Checked by:
D53: Load | E53: Torque 80% | F53: LRA 80%
A54: 100 | B54: 0 | C54: 0.25882441 | D54: 100 | E54: 0 | F54: 19.049477
A55: 99.78 | B55: 80.860025 | C55: 86.287926 | D55: 99.559998 | E55: 51.750417 | F55: 69.030342
A56: 98.9 | B56: 255 | C56: 326.34964 | D56: 97.724998 | E56: 163.2 | F56: 261.07971
A57: 93.466666 | B57: 164.03672 | C57: 451.32635 | D57: 83.013336 | E57: 104.98351 | F57: 361.0611
A58: 88.033333 | B58: 120.3232 | C58: 498.27145 | D58: 68.886665 | E58: 77.006853 | F58: 398.61716
A59: 82.599999 | B59: 96.275754 | C59: 520.03491 | D59: 55.719997 | E59: 61.616486 | F59: 416.02792
A60: 71.733332 | B60: 79.420712 | C60: 540.53699 | D60: 35.946663 | E60: 50.829259 | F60: 432.4296
A61: 60.866666 | B61: 72.805962 | C61: 551.46869 | D61: 22.953333 | E61: 46.595817 | F61: 441.17496
A62: 50 | B62: 70 | C62: 559.42175 | D62: 14 | E62: 44.800001 | F62: 447.53741
A63: 39.999998 | B63: 72.466424 | C63: 566.09692 | D63: 7.9999995 | E63: 46.378512 | F63: 452.87753
A64: 30.000001 | B64: 77.111075 | C64: 571.76538 | D64: 5.9999995 | E64: 49.35109 | F64: 457.41232
A65: 19.999999 | B65: 85.17959 | C65: 576.89709 | D65: 8.000001 | E65: 54.514938 | F65: 461.51767
... A67: 0 | B67: 120 | C67: 585.86957 | D67: 30 | E67: 76.800002 | F67: 468.69565

Sheet Thermdam
A2: TOSHIBA INTERNATIONAL CORPORATION
A3: Thermal Limit & Acceleration Curves
A4: Design Values (For Reference Only)
A6: Model #: | B6: ='Performance Data Sheet'!C17 -> 7003WTAK11F-A | E6: FLAmps: | F6: ='Performance Data Sheet'!I14 & " A" -> 92 A
A7: Enclosure: | B7: ='Performance Data Sheet'!F14 -> WP-II | C7: Voltage: | D7: ='Performance Data Sheet'!F13 & " V" -> 4000 V | E7: Frame: | F7: ='Performance Data Sheet'!C14 -> 5012USS
A8: Pole: | B8: 2 | C8: Frequency: | D8: 3 PH / 60 Hz | E8: Ins. Class: | F8: F
A9: HP: | B9: 700 | C9: Rotor Inertia: | D9: 114.9 lb-ft² | E9: Date: | F9: ='Performance Data Sheet'!K44 -> 44669
A10: FLRPM: | B10: 3560 | C10: Load Inertia: | D10: N/A | E10: File: | F10: 1T2700K_REV1
A39: Comments: | B39: PROJECT | C39: ='Performance Data Sheet'!J38 -> 0 | E39: D.E.Curve #: | F39: =F10 -> 1T2700K_REV1
C43: Prepared by: | D43: ='Performance Data Sheet'!K42 -> Jerry R | E43: Checked by:
F50: =5252.1*B50/D53 -> #DIV/0!
D66: =D65/D64 -> #DIV/0!
A67: Current (%) | B67: Cold | C67: Hot | E67: CURRENT (%) | F67: Accel. Time
A68: 585.86957 | B68: 24.9 | C68: 16.6 | E68: =A68 -> 585.86957 | F68: 0.0001
A69: 493.92224 | B69: =((A68/A69)^2)*B68 -> 35.033543 | C69: =((A68/A69)^2)*C68 -> 23.355695 | E69: 466.95652 | F69: 0.87800002
A70: 401.94733 | B70: =((A68/A70)^2)*B68 -> 52.900885 | C70: =((A68/A70)^2)*C68 -> 35.267256 | E70: 463.36957 | F70: 1.758
A71: 310 | B71: =((A68/A71)^2)*B68 -> 88.93605 | C71: =((A68/A71)^2)*C68 -> 59.2907 | E71: 459.45652 | F71: 2.6849999
A72: =A71-100 -> 210 | B72: =((A68/A72)^2)*B68 -> 193.80395 | E72: 455.1087 | F72: 3.7029998
A73: =A72-100 -> 110 | B73: =((A68/A73)^2)*B68 -> 706.34334 | E73: 450.21739 | F73: 4.9059997
A74: 255 | B74: =((A68/A74)^2)*B68 -> 131.43798 | C74: =((A68/A74)^2)*C68 -> 87.625317 | E74: 444.34783 | F74: 6.5689998
A75: 180 | B75: =((A68/A75)^2)*B69 -> 371.1427 | C75: =((A68/A75)^2)*C68 -> 175.85914 | E75: 436.84783 | F75: 8.9130001
A76: 120 | B76: =((A68/A76)^2)*B68 -> 593.52461 | C76: =((A68/A76)^2)*C68 -> 395.68307 | E76: 424.23913 | F76: 13.263
A77: 110 | C77: =CEILING(C76*2,100) -> 800 | E77: 407.28261 | F77: 16.495001
A78: 110 | C78: =2*C77 -> 1600 | E78: 379.8913 | F78: 18.003
A79: 110 | C79: 10000 | E79: 311.08696 | F79: 18.521
E80: 0 | F80: 18.545

Sheet Performance 4000V
A2: TOSHIBA INTERNATIONAL CORPORATION
A3: Performance Curve
A4: Design Values (For Reference Only)
A6: Model #: | B6: ='Performance Data Sheet'!C17 -> 7003WTAK11F-A | E6: FLAmps: | F6: ='Performance Data Sheet'!I14 & " A" -> 92 A
A7: Enclosure: | B7: ='Performance Data Sheet'!F14 -> WP-II | C7: Voltage: | D7: ='Performance Data Sheet'!F13 & " V" -> 4000 V | E7: Frame: | F7: ='Performance Data Sheet'!C14 -> 5012USS
A8: Pole: | B8: 2 | C8: Frequency: | D8: 3 PH / 60 Hz | E8: Ins. Class: | F8: F
A9: HP: | B9: 700 | C9: Rotor Inertia: | D9: 114.9 lb-ft² | E9: Date: | F9: ='Performance Data Sheet'!K44 -> 44669
A10: FLRPM: | B10: 3560 | C10: Load Inertia: | D10: N/A | E10: File: | F10: 1T2700K_REV1
B12: Locked Rotor Amps: | C12: ='Performance Data Sheet'!D22 & " A" -> 539 A | D12: Load Type: | E12: N/A
B13: Locked Rotor Torque: | C13: 1.2 | D13: Starting at: | E13: N/A
B14: Breakdown Torque: | C14: 2.55 | D14: Accel. Time: | E14: N/A
B15: Rated Torque: | C15: 1033 lb-ft
A39: Comments: | B39: PROJECT | C39: ='Performance Data Sheet'!J38 -> 0 | E39: D.E.Curve #: | F39: =F10 -> 1T2700K_REV1
C43: Prepared by: | D43: ='Performance Data Sheet'!K42 -> Jerry R | E43: Checked by:
A53: Load | B53: Efficiency | C53: PF | D53: Amps | E53: RPM | F53: Input Watts
A54: 0 | D54: 24.752413 | E54: 100 | F54: =8959/14000 -> 0.63992857
A55: 25 | B55: 90.2 | C55: 59.7 | D55: 35 | E55: 79.554946 | F55: 10.371961
A56: 50 | B56: 93.5 | C56: 78.7 | D56: 51.2 | E56: 71.545912 | F56: 20.017785
A57: 75 | B57: 94.3 | C57: 84.8 | D57: 70.6 | E57: 63.328295 | F57: 29.770102
A58: 100 | B58: 94.5 | C58: 87.1 | D58: 92 | E58: 54.935468 | F58: 39.633748
A59: 125 | B59: 94.4 | C59: 87.8 | D59: 113.6 | E59: 46.426155 | F59: 49.613831

Sheet Performance 2300V
A2: TOSHIBA INTERNATIONAL CORPORATION
A3: Performance Curve
A4: Design Values (For Reference Only)
A6: Model #: | B6: ='Performance Data Sheet'!C17 -> 7003WTAK11F-A | E6: FLAmps: | F6: 159 A
A7: Enclosure: | B7: ='Performance Data Sheet'!F14 -> WP-II | C7: Voltage: | D7: 2300V | E7: Frame: | F7: ='Performance Data Sheet'!C14 -> 5012USS
A8: Pole: | B8: 2 | C8: Frequency: | D8: 3 PH / 60 Hz | E8: Ins. Class: | F8: F
A9: HP: | B9: 700 | C9: Rotor Inertia: | D9: 114.9 lb-ft² | E9: Date: | F9: ='Performance Data Sheet'!K44 -> 44669
A10: FLRPM: | B10: 3560 | C10: Load Inertia: | D10: N/A | E10: File: | F10: 1T2700K_REV1
B12: Locked Rotor Amps: | C12: 934 A | D12: Load Type: | E12: N/A
B13: Locked Rotor Torque: | C13: 1.2 | D13: Starting at: | E13: N/A
B14: Breakdown Torque: | C14: 2.55 | D14: Accel. Time: | E14: N/A
B15: Rated Torque: | C15: 1033 lb-ft
A39: Comments: | B39: PROJECT | C39: ='Performance Data Sheet'!J38 -> 0 | E39: D.E.Curve #: | F39: =F10 -> 1T2700K_REV1
C43: Prepared by: | D43: ='Performance Data Sheet'!K42 -> Jerry R | E43: Checked by:
A53: Load | B53: Efficiency | C53: PF | D53: Amps | E53: RPM | F53: Input Watts
A54: 0 | D54: 42.872438 | E54: 100 | F54: =8959/14000 -> 0.63992857
A55: 25 | B55: 90.2 | C55: 59.7 | D55: 60.621778 | E55: 79.554946 | F55: 10.371961
A56: 50 | B56: 93.5 | C56: 78.7 | D56: 88.681001 | E56: 71.545912 | F56: 20.017785
A57: 75 | B57: 94.3 | C57: 84.8 | D57: 122.28279 | E57: 63.328295 | F57: 29.770102
A58: 100 | B58: 94.5 | C58: 87.1 | D58: 159 | E58: 54.935468 | F58: 39.633748
A59: 125 | B59: 94.4 | C59: 87.8 | D59: 196.76097 | E59: 46.426155 | F59: 49.613831

Sheet StallTime
A1: Rating: | B1: 2 Pole - 700.0 HP - 3600 RPM - 4000 V - 60 Hz
A3: Starting Performance
D4: Load Type: Fan / Pump - 252.0 lb-ft²
A5: RPM | B5: Motor | C5: Load | D5: Accel. | E5: Line | F5: Stator | G5: Rotor
A6: Speed Increment | B6: Torque (%) | C6: Torque (%) | D6: Time (s) | E6: Amps | F6: kW / s | G6: kW / s
A7: 0~360 | B7: 69.9 | C7: 22.5 | D7: 0.878 | E7: 429.6 | F7: 128.1 | G7: 395.6
A8: 360~720 | B8: 58.8 | C8: 11.5 | D8: 0.880 | E8: 426.3 | F8: 126.5 | G8: 293.0
A9: 720~1080 | B9: 51.9 | C9: 7.0 | D9: 0.927 | E9: 422.7 | F9: 131.1 | G9: 237.1
A10: 1080~1440 | B10: 47.9 | C10: 7.0 | D10: 1.018 | E10: 418.7 | F10: 141.4 | G10: 206.2
A11: 1440~1800 | B11: 45.6 | C11: 11.0 | D11: 1.203 | E11: 414.2 | F11: 163.9 | G11: 196.4
A12: 1800~2191 | B12: 45.7 | C12: 18.5 | D12: 1.663 | E12: 408.8 | F12: 221.2 | G12: 201.1
A13: 2191~2582 | B13: 48.7 | C13: 29.4 | D13: 2.344 | E13: 401.9 | F13: 303.0 | G13: 230.7
A14: 2582~2974 | B14: 56.2 | C14: 45.8 | D14: 4.350 | E14: 390.3 | F14: 540.1 | G14: 337.3
A15: 2974~3169 | B15: 69.3 | C15: 62.3 | D15: 3.232 | E15: 374.7 | F15: 371.4 | G15: 373.9
A16: 3169~3365 | B16: 91.0 | C16: 75.9 | D16: 1.508 | E16: 349.5 | F16: 159.1 | G16: 150.0
... A18: 3560~3567 | B18: 131.6 | C18: 98.6 | D18: 0.024 | E18: 151.9 | F18: 0.2 | G18: 11.0
D21: Acceleration Time: 18.5 s
B22: Energy | D22: First Start | F22: Second Start
A23: Stator Winding Rise | B23: 2331 kW / s | D23: 37°C | F23: 74°C
A24: Rotor Bar Rise | B24: 1891 kW / s | D24: 123°C | F24: 247°C
A25: End Ring Rise | B25: 780 kW / s | D25: 62°C | F25: 124°C
A27: Locked Rotor Thermal Capability
E28: Cold Condition
B29: Rate of Rise | D29: Power | E29: Rise Limit | F29: Max Time
A30: Stator Copper | B30: 3.9°C / s | D30: 246.3 kW | E30: 160°C | F30: 40.9 s
A31: Rotor Bar | B31: 28.9°C / s | D31: 443.7 kW | E31: 260°C | F31: 9.0 s
A32: Rotor ER | B32: 14.6°C / s | D32: 182.9 kW | E32: 180°C | F32: 12.3 s
E34: Hot Condition
B35: Hot Temp. | D35: Rise Limit | E35: Ambient | F35: Total | G35: Max.Time
A36: Stator Copper | B36: 46°C + | D36: 114°C + | E36: 40°C | F36: = 200°C | G36: 29.1 s
A37: Rotor Bar | B37: 58°C + | D37: 202°C + | E37: 40°C | F37: = 300°C | G37: 7.0 s
A38: Rotor ER | B38: 58°C + | D38: 122°C + | E38: 40°C | F38: = 220°C | G38: 8.4 s
A40: Cold Stall Time: | B40: 24.9 s | D40: Hot Stall Time: | F40: 16.6 s
