Workbook
Name Print_Area_MI: 'Performance Data Sheet'!$A$10:$N$42

Sheet DesignSheet
A1: TOSHIBA INTERNATIONAL CORPORATION | I1: Calc. Code: | J1: 2-2-2-0-1-2
A2: 3-PHASE SQUIRREL CAGE INDUCTION MOTOR DESIGN SHEET | J2: B.L.-1 P.F.-1
A3: File: | B3: N:\DESPRO\RAT FILES\1T2900K.rat | G3: Date: | H3: 44851 | I3: Time: | J3: 0.53466435
A4: Pole | B4: HP | C4: RPM | D4: Form | E4: Voltage | F4: Frequency | G4: Temperature | H4: FLSpeed | I4: FLSlip | J4: Frame
A5: 2 | B5: 900.00003 | C5: 3600 | D5: DCKW | E5: 4000 | F5: 60 | G5: 105 | H5: 3562.7 / 3556.5 | I5: 0.0104 / 0.0121 | J5: 5012
A6: Core Data | D6: Winding Data | H6: Constant Data
B7: Primary | C7: Secondary | F7: Bar | G7: End Ring | H7: St. Slot Pitch | I7: 25.431919 | J7: LR Test Data
A8: Air Gap | B8: 2.9000001 | H8: Rt. Slot Pitch | I8: 30.879982 | J8: ES
A9: Space Fac. | B9: 0.93000001 | D9: Pitch | E9: 1 ~ 14 | F9: Cross Section Area | H9: Mean Value | I9: 28.15595 | J9: 614.78377
A10: Core Length | B10: 530 | C10: 530 | F10: UB: 417.4 | G10: UER: 2800.0 | H10: Eff.T.W.St. | I10: 18.247458 | J10: WS
A11: OD | B11: 590 | C11: 334.2 | D11: Coil Pitch | E11: 0.61898571 | G11: ERT: 70.0 | H11: Eff.T.W.Rt. | I11: 30.879982 | J11: 35681.917
A12: ID | B12: 340 | C12: 155 | D12: Slot Fill | E12: - | G12: ERD1: 246.2 | H12: St.Carter Fac. | I12: 1.3937239 | J12: IS
A13: Core Depth | B13: 68 | C13: 54.6 | D13: Con./Slot | E13: 16 | G13: ERD2: 332.2 | H13: Rt.Carter Fac. | I13: 1 | J13: 110.03891
A14: Eff.Core L. | B14: 431.51999 | C14: 418.5 | D14: Wire Size 1 | E14: (.102"x.204")x1 | H14: Carter Factor | I14: 1.3937239 | J14: Volts / Turn
A15: Slot Data | D15: Wire Size 2 | E15: (.102"x.182")x1 | H15: Short. Factor | I15: 0.82618353 | J15: 20.620257
A16: Number | B16: 42 | C16: 34 | D16: // Circuits | E16: 1 | H16: Distrib. Factor | I16: 0.95564622 | J16: AC
A17: Kind | B17: Open | C17: Dbl - Closed | D17: Connection | E17: Wye | H17: Wind. Factor | I17: 0.78953916 | J17: 692.28852
A18: Skew | B18: - | C18: 0 | D18: MCL | E18: 1120 | F18: 600 | H18: Reactance | I18: (Coeff.: 0.0677)
A19: Depth | B19: 57 | C19: 35 | D19: No.Cond./Ph. | E19: 224 | I19: Running | J19: Start
A20: Width | B20: 14.00 - 14.00 | D20: Res. (20°C) | E20: 0.17634253 | H20: Stator Slot | I20: 11.786048 | J20: 11.786048
A21: Opening | B21: 14 | C21: 0 | D21: (105°C) | E21: 0.23523886 | F21: 0.17286702 | G21: 0.061996567 | H21: Rotor Slot | I21: 27.797115 | J21: 14.951472
A22: Tip Depth | B22: 2.8299999 | C22: 1 | D22: Material | E22: CU | F22: AL | G22: AL | H22: Zigzag | I22: 7.0829816 | J22: 6.3395672
A23: T.Min.Wid. | B23: 11.431919 | C23: 11 | D23: Spec.Resist. | E23: 1.742 | F23: 3.25 | G23: 3.25 | H23: Coil End | I23: 16.645536 | J23: Skew R.: 0.00
A24: Low. R. | B24: 0 | C24: 2 | D24: Spec.Gravity | E24: 8.8900003 | F24: 2.6700001 | G24: 2.6700001 | H24: Belt Leakage | I24: 5.8606569 | J24: 5.3001741
A25: Up. R. | B25: - | C25: 2 | D25: Weight (kg) | H25: Total Resist. | I25: 0.47010243 | J25: 0.98227787
A26: Wedge Dep. | B26: 1.20 - 2.40 | C26: Normal | D26: Wire 1 | E26: 87.755162 | F26: 20.083022 | G26: 14.007365 | H26: Total React. | I26: 4.6828022 | J26: 3.7212131
A27: Duct | B27: 11 x 6 | C27: 10 x 8 | D27: Wire 2 | E27: 78.06838 | F27: - | G27: - | H27: Impedance | I27: 4.7063398 | J27: 3.8486748
A28: Effective Depth (S=1) | D28: Magnetic Circuit Data | I28: Core Loss Data
B29: Res.= | C29: 33.987912 | E29: Length | F29: Section | G29: Density | H29: AT | I29: Volume | J29: Loss | M29: =RIGHT(F$41,SEARCH("/",F$41,1)-1) -> 3547.0 | N29: 125RPM | P29: Kline/in2
B30: Reac.= | C30: 33.996545 | D30: Primary Core | E30: 46.338453 | F30: 586.86719 | G30: 16.704995 | H30: 663.18841 | I30: 48120.468 | J30: 3920.1696 | M30: =RIGHT(E$41,SEARCH("/",E$41,1)-1) -> 3556.5 | N30: 100RPM | P30: =G30*6.4516 -> 107.77394
A31: Excitation Data | D31: Tooth | E31: 5.7 | F31: 1035.9513 | G31: 9.4633917 | H31: 11.565048 | I31: 11809.845 | J31: 383.18102 | M31: =RIGHT(D$41,SEARCH("/",D$41,1)-1) -> 3566.3 | N31: 75RPM | P31: =G31*6.4516 -> 61.054018
A32: Excit.Amps | B32: 22.840 / 20.714 | D32: Second.Core | E32: 20.750202 | F32: 673.227 | G32: 14.562121 | H32: 165.91205 | I32: Total | J32: 4303.3506 | M32: =RIGHT(C$41,SEARCH("/",C$41,1)-1) -> 3575.6 | N32: 50RPM | P32: =G32*6.4516 -> 93.948982
A33: Core Loss | B33: 1.183 / 1.073 | C33: Flux / Pole | D33: Tooth | E33: 3.5 | F33: 782.595 | G33: 12.527058 | H33: 16.016242 | I33: C.L.C. | J33: 1.50 / 0.85 | M33: =RIGHT(B$41,SEARCH("/",B$41,1)-1) -> 3584.6 | N33: 25RPM | P33: =G33*6.4516 -> 80.81957
A34: NoLoad | B34: 22.87 / 20.74 | C34: 9.8036132 | D34: Air Gap | E34: 0.29000001 | F34: 1751.2086 | G34: 5.5981985 | H34: 1291.9235 | I34: S.F.C. | J34: 6.0500002 | P34: =G34*6.4516 -> 36.117337
A35: Load Characteristics | D35: Temp. Rise @ 100%: | E35: 68 / 66 | G35: No Load Loss | H35: 11483.4 / 7333.8 | I35: W.Loss | J35: 6455.0 / 3654.8
A36: Load (%) | B36: 25 | C36: 50 | D36: 75 | E36: 100 | F36: 125 | G36: Primary Loss | H36: 8545.2 / 9113.6 | I36: S.Loss | J36: 1752.4 / 992.2
A37: Current (A) | B37: 36.58 / 38.03 | C37: 58.51 / 60.82 | D37: 83.46 / 86.76 | E37: 110.04 / 114.39 | F37: 138.09 / 143.55 | G37: Second. Loss | H37: 7332.7 / 8546.8 | I37: Total C.Loss | J37: 8207.4 / 4646.9
A38: Efficiency | B38: 0.931 / 0.914 | C38: 0.957 / 0.940 | D38: 0.962 / 0.945 | E38: 0.962 / 0.945 | F38: 0.960 / 0.943 | G38: Frict.& Wind. | H38: 3000.0 / 2460.4 | I38: Stray Loss | J38: 14026.813 | L38: =LEFT(E38,SEARCH("/",E38,1)-1) -> 0.962 | M38: =RIGHT(E38,SEARCH("/",E38,1)-1) -> 0.945 | N38: =M38/L38 -> 0.98232848 | O38: Eff.
A39: P.F. | B39: 0.712 / 0.697 | C39: 0.866 / 0.848 | D39: 0.905 / 0.886 | E39: 0.915 / 0.896 | F39: 0.914 / 0.895 | G39: Starting Data | I39: Slip | J39: PF | L39: =LEFT(E39,SEARCH("/",E39,1)-1) -> 0.915 | M39: =RIGHT(E39,SEARCH("/",E39,1)-1) -> 0.896 | N39: =M39/L39 -> 0.97923497 | O39: PF.
A40: Slip | B40: 0.0025 / 0.0043 | C40: 0.0051 / 0.0068 | D40: 0.0076 / 0.0094 | E40: 0.0104 / 0.0121 | F40: 0.0130 / 0.0147 | G40: LRA | H40: 600.1 / 602.6 | L40: =LEFT(E37,SEARCH("/",E37,1)-1) -> 110.04 | M40: 114 | N40: =M40/L40 -> 1.0359869 | O40: Current
...

Sheet Data Sheet
A1: TOSHIBA INTERNATIONAL CORPORATION
A2: INDUCTION MOTOR DATA SHEET
A3: File: | B3: 1T2900K | I3: HRW / Model Number: | J3: 9003WTAK11F-A1
A4: Type: TIKK - Form: DCKW - 2 Pole - 900 HP - 2300 / 4000 V - 60 Hz - 5012 - Class F | Q4: Motor Type Selection | T4: Electrical Steel Table
A5: Motor Parameters | F5: PERFORMANCE | J5: DESIGN | K5: TEST | Q5: EPACT | T5: M22 - 26Ga.
A6: Material | D6: M22 - 26Ga. | F6: NL & Impedance Test | Q6: EQP-III | T6: M36 - 26Ga.
A7: Air Gap | D7: 2.9000001 | F7: No load amps | J7: 36 / 21 | K7: - | Q7: Exp.Prf. | T7: NCB1 - 26Ga.
A8: Stack length | D8: 530 | F8: No load watts | J8: 7334 | K8: - | Q8: Exp.Prf.-EQPIII | T8: M43 - 26Ga.
A9: Number of turns per coil | D9: 8 | F9: Impedance amps | H9: 3 | I9: f | J9: 247 / 206 | K9: - | Q9: Prem. Eff. | T9: M45 - 26Ga.
A10: Wire 1 (size & number) | D10: (.102"x.204")x1 | F10: Impedance volts | H10: 3 | I10: f | J10: 460 / 1150 | K10: - | Q10: Standard Eff. | T10: M54 - 26Ga.
A11: Wire 2 (size & number) | D11: (.102"x.182")x1 | F11: Impedance watts | H11: 3 | I11: f | J11: 35682 | K11: - | Q11: OWP | T11: TIPA Lam
A12: Slot fill - circle/square method (%) | D12: - | F12: Temperature Rise (°C) | Q12: Dry Kiln
A13: Connection | D13: 1D / 1Y | G13: Winding | I13: 80/115 | J13: 68 / 90 | K13: -
A14: MCL | D14: 1120 | G14: Frame | J14: - | K14: -
A15: Allowance for ins. depth | D15: 9.5172005 | G15: Bearing PS/OS | J15: - | K15: -
A16: Allowance for ins. width | D16: 3.7956002 | G16: End Ring | J16: - | K16: -
A17: Slot/Wire arrangement | D17: 16 x 2 | F17: Nameplate Data
A18: Effective cross section for coil | D18: - | H18: FLC (A) | J18: 197 / 114
A19: Coil grouping | D19: - | H19: RPM | J19: 3555
A20: Coil pitch (slot number) | D20: 1 ~ 14 | H20: CODE | J20: E
A21: Method of coil connection | D21: - | H21: S. F. | J21: 1.15 | Q21: Method of Connection
A22: Resistance per phase @ 20 °C | D22: 0.1763 | H22: DESIGN | Q22: Skip
A23: Coil Weight | B23: Wire1 | D23: 193.1 | H23: Nom.Eff. (%): | Q23: Adjacent
A24: (lbs.) | B24: Wire2 | D24: 171.8 | H24: Min.Eff. (%): | Q24: -
A25: Current Densities (A/cm2) | E25: Bar / ER | H25: P.F. (%): | J25: 89.5
A26: FL / LR | D26: 462 / 2444 | E26: 396 / 320
A27: Stator Slot Shape (Reference) | F27: Performance
H28: LRC (A) | I28: - | J28: 1044/ 603 | K28: -
H29: LRT (%) | I29: 60 | J29: 105 | K29: -
H30: BDT (%) | I30: 175 | J30: 227 | K30: -
H31: SLIP (%) | J31: 1.21 | K31: -
G32: IEEE-B | H32: Eff. (%) | J32: 94.5 | K32: -
A33: Rotor Slot Shape (Reference) | H33: PF (%) | J33: 89.6 | K33: -
F34: Losses (Watts) | H34: Primary | J34: 9114 | K34: -
H35: Secondary | J35: 8547 | K35: -
H36: Core | J36: 4647 | K36: -
H37: F & W | J37: 2460 | K37: -
H38: Stray | J38: 14027 | K38: -
A39: End Ring (Reference) | F39: Note
G40: QC Limits: 1T2900K
...

Sheet LoginSheet
J1: P | K1: T | L1: L | M1: T
B2: PROJECT HISTORY | J2: E | K2: D | L2: I | M2: Y | N2: H
J3: R | L3: M | M3: P
J4: F | L4: I | M4: E
K5: C | L5: T | N5: I
J6: D | K6: U | M6: T | N6: N
J7: A | K7: R | L7: R | M7: E | N7: S
I8: S | J8: T | K8: V | L8: E | M8: S | N8: U
B9: DATE | C9: PROJECT | D9: SMART NUMBER | E9: QTY | F9: CUSTOMER | G9: REMARKS | H9: LIMIT CODE | I9: F | J9: A | K9: E | L9: V | M9: T | N9: L
B53: REVISION HISTORY
B54: REV | C54: REMARKS | I54: DATE | L54: INIT

Sheet Performance Data Sheet
A1: TOSHIBA INTERNATIONAL CORPORATION | J1: INDEX | L1: MPCF-1033
A2: Industrial Division / Houston Motor Plant | J2: SHEET NO. | L2: 1 of 1
J3: ISSUED | L3: 7/31/13
J4: SUPERSEDES | L4: 11/8/96
J5: REVISION | L5: 2
A6: SQUIRREL CAGE INDUCTION MOTOR | J6: WRITTEN BY | L6: MDC
A7: PERFORMANCE SPECIFICATIONS | J7: APPROVED BY | L7: PAA
B9: CUSTOMER:
B10: TIC SR No.: | C10: QUOTE 32309
A12: MOTOR NAMEPLATE DATA
B13: H.P.: | C13: 900 | E13: VOLTS: | F13: 2300/4000 | H13: 3 PH / | I13: 60 Hz | L13: S. RPM: | M13: 3600
B14: FRAME: | C14: 5012USS | E14: ENCL: | F14: WP-I | H14: FLAMPS: | I14: 197/114 | L14: FLRPM: | M14: 3555
B15: FORM: | C15: DCKW | E15: S.F.: | F15: 1.15 | H15: NEMA DESIGN: | I15: - | L15: INSUL CLASS: | M15: F
B16: TYPE: | C16: TIKK | E16: AMB.: | F16: 40°C | H16: CODE: | I16: E | L16: DUTY: | M16: Cont.
B17: MODEL No.: | C17: QUOTE 32309 | H17: kW:
B18: NOM. EFF.: | E18: MIN. EFF.: | H18: P.F.:
A21: AMPERAGE | E21: TORQUES | I21: **BEARINGS:
C22: LOCKED ROTOR: | D22: 1044/603 | G22: FULL LOAD (lb-ft.): | H22: 1330 | K22: DRIVE END: | L22: REFER TO NP
G23: LOCKED ROTOR (%): | H23: 105 | K23: OPPOSITE DRIVE END: | L23: REFER TO NP
G24: BREAK DOWN (%): | H24: 225
A28: EFFICIENCY | H28: POWER FACTOR
C29: FULL LOAD: | D29: 94.5 | J29: FULL LOAD: | K29: 89.6
C30: 3/4 LOAD: | D30: 94.5 | J30: 3/4 LOAD: | K30: 88.6
C31: 1/2 LOAD: | D31: 94 | J31: 1/2 LOAD: | K31: 84.8
A35: ALL CHARACTERISTICS ARE AVERAGE EXPECTED VALUES BASED UPON RATED VOLTAGE,
A36: FREQUENCY AND SINEWAVE POWER INPUT.
A37: THE DECLARED LOCKED ROTOR CURRENT HAS A TOLERANCE OF 20%.
A38: * TEMPERATURE RISE WILL BE CONSISTENT WITH INSULATION, AMBIENT AND SERVICE FACTOR AS
A39: DEFINED BY NEMA-MG-12 OR -20.
A40: ** BEARINGS ARE THE ONLY RECOMMENDED SPARE PART(S).
J42: CERTIFIED BY: | K42: JERRY R
J44: DATE: | K44: 44851
A59: - | B59: 6205ZZ | D59: 1 | E59: -
A60: TEFC | B60: 6206UU | D60: 1.15 | E60: A
A61: ODP | B61: 6207ZZ | E61: B
B62: 6208UU
B63: 6211ZZ
B64: 6211C3
B65: 6211ZZC3
B66: 6305UUC3
...

Sheet STCurve
A2: TOSHIBA INTERNATIONAL CORPORATION
A3: Speed Torque/Current Curve
A6: Model #: | B6: ='Performance Data Sheet'!C17 -> QUOTE 32309 | E6: FLAmps: | F6: ='Performance Data Sheet'!I14 & " A" -> 197/114 A
A7: Enclosure: | B7: ='Performance Data Sheet'!F14 -> WP-I | C7: Voltage: | D7: ='Performance Data Sheet'!F13 & " V" -> 2300/4000 V | E7: Frame: | F7: ='Performance Data Sheet'!C14 -> 5012USS
A8: Pole: | B8: 2 | C8: Frequency: | D8: 3 PH / 60 Hz | E8: Ins. Class: | F8: F
A9: HP: | B9: 900 | C9: Rotor Inertia: | D9: 133.2 lb-ft² | E9: Date: | F9: ='Performance Data Sheet'!K44 -> 44851
A10: FLRPM: | B10: 3555 | C10: Load Inertia: | D10: N/A | E10: File: | F10: 1T2900K REV1
B12: Locked Rotor Amps: | C12: ='Performance Data Sheet'!D22 & " A" -> 1044/603 A | D12: Load Type: | E12: N/A
B13: Locked Rotor Torque: | C13: 1.05 | D13: Starting at: | E13: N/A
B14: Breakdown Torque: | C14: 2.25 | D14: Accel. Time: | E14: N/A
B15: Rated Torque: | C15: 1330 lb-ft
A39: Comments: | B39: PROJECT | C39: ='Performance Data Sheet'!C10 -> QUOTE 32309 | E39: D.E.Curve #: | F39: =F10 -> 1T2900K REV1
C43: Prepared by: | D43: ='Performance Data Sheet'!K42 -> JERRY R | E43: Checked by:
A54: 100 | B54: 0 | C54: 0.2006181
A55: 99.2 | B55: 73.21923 | C55: 79.415154
A56: 96 | B56: 225 | C56: 299.70627
A57: 90.857143 | B57: 171.82636 | C57: 409.80865
A58: 85.714285 | B58: 123.22373 | C58: 450.24554
A59: 80.571428 | B59: 97.564851 | C59: 468.88885
A60: 70.285714 | B60: 79.878042 | C60: 486.64703
A61: 59.999999 | B61: 73.5 | C61: 496.38989
A62: 50 | B62: 73.837936 | C62: 503.66296
A63: 39.999998 | B63: 75.147653 | C63: 509.85635
A64: 30.000001 | B64: 77.919082 | C64: 515.40192
A65: 19.999999 | B65: 82.902451 | C65: 520.29999
... A67: 0 | B67: 105 | C67: 528.94739

Sheet Thermdam
A2: TOSHIBA INTERNATIONAL CORPORATION
A3: Thermal Limit Curve
A4: Design Values (For Reference Only)
A6: Model #: | B6: ='Performance Data Sheet'!C17 -> QUOTE 32309 | E6: FLAmps: | F6: ='Performance Data Sheet'!I14 & " A" -> 197/114 A
A7: Enclosure: | B7: ='Performance Data Sheet'!F14 -> WP-I | C7: Voltage: | D7: ='Performance Data Sheet'!F13 & " V" -> 2300/4000 V | E7: Frame: | F7: ='Performance Data Sheet'!C14 -> 5012USS
A8: Pole: | B8: 2 | C8: Frequency: | D8: 3 PH / 60 Hz | E8: Ins. Class: | F8: F
A9: HP: | B9: 900 | C9: Rotor Inertia: | D9: 133.2 lb-ft² | E9: Date: | F9: ='Performance Data Sheet'!K44 -> 44851
A10: FLRPM: | B10: 3555 | C10: Load Inertia: | D10: N/A | E10: File: | F10: 1T2900K REV1
A39: Comments: | B39: PROJECT | C39: ='Performance Data Sheet'!C10 -> QUOTE 32309 | E39: D.E.Curve #: | F39: =F10 -> 1T2900K REV1
C43: Prepared by: | D43: ='Performance Data Sheet'!K42 -> JERRY R | E43: Checked by:
F50: =5252.1*B50/D53 -> #DIV/0!
D66: =D65/D64 -> #DIV/0!
A67: Current (%) | B67: Cold | C67: Hot | E67: CURRENT (%) | F67: Accel. Time
A68: 528.94737 | B68: 13.129311 | C68: 6.5169784 | E68: =A68 -> 528.94737 | F68: 0.0001
A69: 459.30521 | B69: =((A68/A69)^2)*B68 -> 17.412619 | C69: =((A68/A69)^2)*C68 -> 8.6430785 | E69: 526.84211 | F69: 0.39399999
A70: 389.64216 | B70: =((A68/A70)^2)*B68 -> 24.19552 | C70: =((A68/A70)^2)*C68 -> 12.009898 | E70: 522.54386 | F70: 0.78799999
A71: 320 | B71: =((A68/A71)^2)*B68 -> 35.872933 | C71: =((A68/A71)^2)*C68 -> 17.8062 | E71: 517.89474 | F71: 1.194
A72: =A71-100 -> 220 | B72: =((A68/A72)^2)*B68 -> 75.896454 | E72: 512.63158 | F72: 1.623
A73: =A72-100 -> 120 | B73: =((A68/A73)^2)*B68 -> 255.09641 | E73: 506.75439 | F73: 2.092
A74: 225 | B74: =((A68/A74)^2)*B68 -> 72.560758 | C74: =((A68/A74)^2)*C68 -> 36.016886 | E74: 500 | F74: 2.6270001
A75: 180 | B75: =((A68/A75)^2)*B69 -> 150.36405 | C75: =((A68/A75)^2)*C68 -> 56.276385 | E75: 491.49123 | F75: 3.2540002
A76: 145 | B76: =((A68/A76)^2)*B68 -> 174.71526 | C76: =((A68/A76)^2)*C68 -> 86.723181 | E76: 477.80702 | F76: 3.9150002
A77: 125 | C77: =CEILING(C76*2,100) -> 200 | E77: 459.5614 | F77: 4.2030001
A78: 125 | C78: =2*C77 -> 400 | E78: 430 | F78: 4.4000001
A79: 125 | C79: 10000 | E79: 354.73684 | F79: 4.533
E80: 0 | F80: 4.6620002

Sheet Performance 4000V
A2: TOSHIBA INTERNATIONAL CORPORATION
A3: Performance Curve
A4: Design Values (For Reference Only)
A6: Model #: | B6: ='Performance Data Sheet'!C17 -> QUOTE 32309 | E6: FLAmps: | F6: 114 A
A7: Enclosure: | B7: ='Performance Data Sheet'!F14 -> WP-I | C7: Voltage: | D7: 4000 V | E7: Frame: | F7: ='Performance Data Sheet'!C14 -> 5012USS
A8: Pole: | B8: 2 | C8: Frequency: | D8: 3 PH / 60 Hz | E8: Ins. Class: | F8: F
A9: HP: | B9: 900 | C9: Rotor Inertia: | D9: 133.2 lb-ft² | E9: Date: | F9: ='Performance Data Sheet'!K44 -> 44851
A10: FLRPM: | B10: 3555 | C10: Load Inertia: | D10: N/A | E10: File: | F10: 1T2900K REV1
B12: Locked Rotor Amps: | C12: 603 A | D12: Load Type: | E12: N/A
B13: Locked Rotor Torque: | C13: 1.05 | D13: Starting at: | E13: N/A
B14: Breakdown Torque: | C14: 2.25 | D14: Accel. Time: | E14: N/A
B15: Rated Torque: | C15: 1330 lb-ft
A39: Comments: | B39: PROJECT | C39: ='Performance Data Sheet'!C10 -> QUOTE 32309 | E39: D.E.Curve #: | F39: =F10 -> 1T2900K REV1
C43: Prepared by: | D43: ='Performance Data Sheet'!K42 -> JERRY R | E43: Checked by:
A53: Load | B53: Efficiency | C53: PF | D53: Amps | E53: RPM | F53: Input Watts
A54: 0 | D54: 23.693801 | E54: 100 | F54: 2
A55: 25 | B55: 91.416275 | C55: 69.679375 | D55: 37.899303 | E55: 82.939901 | F55: 10.164145
A56: 50 | B56: 93.978996 | C56: 84.760628 | D56: 60.612751 | E56: 73.888071 | F56: 19.773955
A57: 75 | B57: 94.521675 | C57: 88.614799 | D57: 86.465446 | E57: 64.61812 | F57: 29.490642
A58: 100 | B58: 94.517563 | C58: 89.619064 | D58: 114.00031 | E58: 54.813881 | F58: 39.322563
A59: 125 | B59: 94.297409 | C59: 89.475594 | D59: 143.06212 | E59: 45.344792 | F59: 49.267964

Sheet Performance 2300V
A2: TOSHIBA INTERNATIONAL CORPORATION
A3: Performance Curve
A4: Design Values (For Reference Only)
A6: Model #: | B6: ='Performance Data Sheet'!C17 -> QUOTE 32309 | E6: FLAmps: | F6: 197 A
A7: Enclosure: | B7: ='Performance Data Sheet'!F14 -> WP-I | C7: Voltage: | D7: 2300 V | E7: Frame: | F7: ='Performance Data Sheet'!C14 -> 5012USS
A8: Pole: | B8: 2 | C8: Frequency: | D8: 3 PH / 60 Hz | E8: Ins. Class: | F8: F
A9: HP: | B9: 900 | C9: Rotor Inertia: | D9: 133.2 lb-ft² | E9: Date: | F9: ='Performance Data Sheet'!K44 -> 44851
A10: FLRPM: | B10: 3555 | C10: Load Inertia: | D10: N/A | E10: File: | F10: 1T2900K REV1
B12: Locked Rotor Amps: | C12: 1044 A | D12: Load Type: | E12: N/A
B13: Locked Rotor Torque: | C13: 1.05 | D13: Starting at: | E13: N/A
B14: Breakdown Torque: | C14: 2.25 | D14: Accel. Time: | E14: N/A
B15: Rated Torque: | C15: 1330 lb-ft
A39: Comments: | B39: PROJECT | C39: ='Performance Data Sheet'!C10 -> QUOTE 32309 | E39: D.E.Curve #: | F39: =F10 -> 1T2900K REV1
C43: Prepared by: | D43: ='Performance Data Sheet'!K42 -> JERRY R | E43: Checked by:
A53: Load | B53: Efficiency | C53: PF | D53: Amps | E53: RPM | F53: Input Watts
A54: 0 | D54: 23.693801 | E54: 100 | F54: 2
A55: 25 | B55: 91.416275 | C55: 69.679375 | D55: 37.899303 | E55: 82.939901 | F55: 10.164145
A56: 50 | B56: 93.978996 | C56: 84.760628 | D56: 60.612751 | E56: 73.888071 | F56: 19.773955
A57: 75 | B57: 94.521675 | C57: 88.614799 | D57: 86.465446 | E57: 64.61812 | F57: 29.490642
A58: 100 | B58: 94.517563 | C58: 89.619064 | D58: 114.00031 | E58: 54.813881 | F58: 39.322563
A59: 125 | B59: 94.297409 | C59: 89.475594 | D59: 143.06212 | E59: 45.344792 | F59: 49.267964

Sheet StallTime
A1: Rating: | B1: 2 Pole - 900.0 HP - 3600 RPM - 4000 V - 60 Hz
A3: Starting Performance
D4: Load Type: Fan / Pump - 204.9 lb-ft²
A5: RPM | B5: Motor | C5: Load | D5: Accel. | E5: Line | F5: Stator | G5: Rotor
A6: Speed Increment | B6: Torque (%) | C6: Torque (%) | D6: Time (s) | E6: Amps | F6: kW / s | G6: kW / s
A7: 0~360 | B7: 98.2 | C7: 22.5 | D7: 0.394 | E7: 600.6 | F7: 101.0 | G7: 331.3
A8: 360~720 | B8: 87.1 | C8: 11.5 | D8: 0.394 | E8: 595.7 | F8: 99.6 | G8: 259.7
A9: 720~1080 | B9: 80.4 | C9: 7.0 | D9: 0.406 | E9: 590.4 | F9: 100.8 | G9: 215.8
A10: 1080~1440 | B10: 76.5 | C10: 7.0 | D10: 0.429 | E10: 584.4 | F10: 104.5 | G10: 187.5
A11: 1440~1800 | B11: 74.5 | C11: 11.0 | D11: 0.469 | E11: 577.7 | F11: 111.9 | G11: 169.6
A12: 1800~2160 | B12: 73.7 | C12: 18.0 | D12: 0.535 | E12: 570.0 | F12: 124.5 | G12: 158.3
A13: 2160~2530 | B13: 76.7 | C13: 27.7 | D13: 0.627 | E13: 560.3 | F13: 141.7 | G13: 143.6
A14: 2530~2901 | B14: 88.7 | C14: 42.4 | D14: 0.661 | E14: 544.7 | F14: 143.5 | G14: 122.2
A15: 2901~3086 | B15: 110.4 | C15: 57.1 | D15: 0.288 | E15: 523.9 | F15: 58.0 | G15: 85.0
A16: 3086~3271 | B16: 147.5 | C16: 69.5 | D16: 0.197 | E16: 490.2 | F16: 36.5 | G16: 53.9
... A18: 3456~3563 | B18: 162.5 | C18: 94.1 | D18: 0.129 | E18: 216.1 | F18: 1.2 | G18: 8.2
D21: Acceleration Time: 4.7 s
B22: Energy | D22: First Start | F22: Second Start
A23: Stator Winding Rise | B23: 1044 kW / s | D23: 16°C | F23: 33°C
A24: Rotor Bar Rise | B24: 1301 kW / s | D24: 72°C | F24: 145°C
A25: End Ring Rise | B25: 467 kW / s | D25: 37°C | F25: 74°C
A27: Locked Rotor Thermal Capability
E28: Cold Condition
B29: Rate of Rise | D29: Power | E29: Rise Limit | F29: Max Time
A30: Stator Copper | B30: 4.7°C / s | D30: 299.1 kW | E30: 160°C | F30: 34.2 s
A31: Rotor Bar | B31: 28.9°C / s | D31: 518.9 kW | E31: 260°C | F31: 9.0 s
A32: Rotor ER | B32: 14.8°C / s | D32: 186.1 kW | E32: 180°C | F32: 12.1 s
E34: Hot Condition
B35: Hot Temp. | D35: Rise Limit | E35: Ambient | F35: Total | G35: Max.Time
A36: Stator Copper | B36: 68°C + | D36: 92°C + | E36: 40°C | F36: = 200°C | G36: 19.6 s
A37: Rotor Bar | B37: 91°C + | D37: 169°C + | E37: 40°C | F37: = 300°C | G37: 5.9 s
A38: Rotor ER | B38: 91°C + | D38: 89°C + | E38: 40°C | F38: = 220°C | G38: 6.0 s
A40: Cold Stall Time: | B40: 9.2 s | D40: Hot Stall Time: | F40: 4.6 s
