Workbook
Name Print_Area_MI: 'Performance Data Sheet'!$A$10:$N$42

Sheet DesignSheet
A1: TOSHIBA INTERNATIONAL CORPORATION | I1: Calc. Code: | J1: 2-2-2-0-1-2
A2: 3-PHASE SQUIRREL CAGE INDUCTION MOTOR DESIGN SHEET | J2: B.L.-1 P.F.-1
A3: File: | B3: M:\Active Projects\MV Special Opportunity\2P 900HP 5012 WPII\1T2M20F.rat | G3: Date: | H3: 43216 | I3: Time: | J3: 0.60493056
A4: Pole | B4: HP | C4: RPM | D4: Form | E4: Voltage | F4: Frequency | G4: Temperature | H4: FLSpeed | I4: FLSlip | J4: Frame
A5: 2 | B5: 1000 | C5: 3600 | D5: DCKW | E5: 4000 | F5: 60 | G5: 105 | H5: 3567.2 / 3564.0 | I5: 0.0091 / 0.0100 | J5: 5012
A6: Core Data | D6: Winding Data | H6: Constant Data
B7: Primary | C7: Secondary | F7: Bar | G7: End Ring | H7: St. Slot Pitch | I7: 25.431919 | J7: LR Test Data
A8: Air Gap | B8: 2.9000001 | H8: Rt. Slot Pitch | I8: 30.879982 | J8: ES
A9: Space Fac. | B9: 0.93000001 | D9: Pitch | E9: 1 ~ 14 | F9: Cross Section Area | H9: Mean Value | I9: 28.15595 | J9: 558.25288
A10: Core Length | B10: 565 | C10: 565 | F10: UB: 417.4 | G10: UER: 2800.0 | H10: Eff.T.W.St. | I10: 18.247458 | J10: WS
A11: OD | B11: 590 | C11: 334.2 | D11: Coil Pitch | E11: 0.61898571 | G11: ERT: 70.0 | H11: Eff.T.W.Rt. | I11: 30.879982 | J11: 36094.477
A12: ID | B12: 340 | C12: 155 | D12: Slot Fill | E12: - | G12: ERD1: 246.2 | H12: St.Carter Fac. | I12: 1.3937239 | J12: IS
A13: Core Depth | B13: 68 | C13: 54.6 | D13: Con./Slot | E13: 14 | G13: ERD2: 332.2 | H13: Rt.Carter Fac. | I13: 1 | J13: 122.99626
A14: Eff.Core L. | B14: 464.07001 | C14: 451.05002 | D14: Wire Size 1 | E14: (.114"x.182")x1 | H14: Carter Factor | I14: 1.3937239 | J14: Volts / Turn
A15: Slot Data | D15: Wire Size 2 | E15: (.114"x.204")x1 | H15: Short. Factor | I15: 0.82618353 | J15: 23.566008
A16: Number | B16: 42 | C16: 34 | D16: // Circuits | E16: 1 | H16: Distrib. Factor | I16: 0.95564622 | J16: AC
A17: Kind | B17: Open | C17: Dbl - Closed | D17: Connection | E17: Wye | H17: Wind. Factor | I17: 0.78953916 | J17: 677.08129
A18: Skew | B18: - | C18: 0 | D18: MCL | E18: 1155 | F18: 635 | H18: Reactance | I18: (Coeff.: 0.0557)
A19: Depth | B19: 57 | C19: 35 | D19: No.Cond./Ph. | E19: 196 | I19: Running | J19: Start
A20: Width | B20: 14.00 - 14.00 | D20: Res. (20°C) | E20: 0.1445004 | H20: Stator Slot | I20: 11.786048 | J20: 11.786048
A21: Opening | B21: 14 | C21: 0 | D21: (105°C) | E21: 0.19276182 | F21: 0.14007179 | G21: 0.047466122 | H21: Rotor Slot | I21: 28.194939 | J21: 14.779838
A22: Tip Depth | B22: 2.8299999 | C22: 1 | D22: Material | E22: CU | F22: AL | G22: AL | H22: Zigzag | I22: 7.0829816 | J22: 6.1762691
A23: T.Min.Wid. | B23: 11.431919 | C23: 11 | D23: Spec.Resist. | E23: 1.742 | F23: 3.25 | G23: 3.25 | H23: Coil End | I23: 15.478014 | J23: Skew R.: 0.00
A24: Low. R. | B24: 0 | C24: 2 | D24: Spec.Gravity | E24: 8.8900003 | F24: 2.6700001 | G24: 2.6700001 | H24: Belt Leakage | I24: 5.8606569 | J24: 5.1709008
A25: Up. R. | B25: - | C25: 2 | D25: Weight (kg) | H25: Total Resist. | I25: 0.38029975 | J25: 0.79530859
A26: Wedge Dep. | B26: 1.20 - 2.40 | C26: Normal | D26: Wire 1 | E26: 77.500452 | F26: 21.40926 | G26: 14.007365 | H26: Total React. | I26: 3.8128076 | J26: 2.9726815
A27: Duct | B27: 11 x 6 | C27: 10 x 8 | D27: Wire 2 | E27: 87.26959 | F27: - | G27: - | H27: Impedance | I27: 3.8317268 | J27: 3.0772312
A28: Effective Depth (S=1) | D28: Magnetic Circuit Data | I28: Core Loss Data
B29: Res.= | C29: 33.987912 | E29: Length | F29: Section | G29: Density | H29: AT | I29: Volume | J29: Loss
B30: Reac.= | C30: 33.996545 | D30: Primary Core | E30: 46.338453 | F30: 631.13521 | G30: 17.752344 | H30: 853.19872 | I30: 51750.246 | J30: 4652.331
A31: Excitation Data | D31: Tooth | E31: 5.7 | F31: 1114.0943 | G31: 10.056716 | H31: 13.915524 | I31: 12700.675 | J31: 454.74689
A32: Excit.Amps | B32: 30.016 / 28.318 | D32: Second.Core | E32: 20.750202 | F32: 725.58913 | G32: 15.441424 | H32: 212.69907 | I32: Total | J32: 5107.0779
A33: Core Loss | B33: 1.416 / 1.336 | C33: Flux / Pole | D33: Tooth | E33: 3.5 | F33: 843.46353 | G33: 13.283478 | H33: 19.43819 | I33: C.L.C. | J33: 1.50 / 0.91
A34: NoLoad | B34: 30.05 / 28.35 | C34: 11.204129 | D34: Air Gap | E34: 0.29000001 | F34: 1885.3274 | G34: 5.942803 | H34: 1371.4496 | I34: S.F.C. | J34: 6.0500002
A35: Load Characteristics | D35: Temp. Rise @ 100%: | E35: 65 / 65 | G35: No Load Loss | H35: 13213.3 / 9000.0 | I35: W.Loss | J35: 7660.6 / 4632.4
A36: Load (%) | B36: 25 | C36: 50 | D36: 75 | E36: 100 | F36: 125 | G36: Primary Loss | H36: 8748.3 / 9083.6 | I36: S.Loss | J36: 2162.1 / 1307.5
A37: Current (A) | B37: 44.14 / 45.91 | C37: 67.20 / 69.90 | D37: 94.15 / 97.92 | E37: 123.00 / 127.92 | F37: 153.36 / 159.50 | G37: Second. Loss | H37: 7071.9 / 7715.6 | I37: Total C.Loss | J37: 9822.7 / 5939.9
A38: Efficiency | B38: 0.929 / 0.912 | C38: 0.957 / 0.940 | D38: 0.963 / 0.946 | E38: 0.964 / 0.947 | F38: 0.962 / 0.945 | G38: Frict.& Wind. | H38: 3000.0 / 2691.9 | I38: Stray Loss | J38: 16491.5
A39: P.F. | B39: 0.657 / 0.643 | C39: 0.837 / 0.820 | D39: 0.891 / 0.872 | E39: 0.908 / 0.889 | F39: 0.912 / 0.893 | G39: Starting Data | I39: Slip | J39: PF
A40: Slip | B40: 0.0023 / 0.0032 | C40: 0.0045 / 0.0054 | D40: 0.0068 / 0.0077 | E40: 0.0091 / 0.0100 | F40: 0.0114 / 0.0123 | G40: LRA | H40: 750.5 / 771.5
...

Sheet Data Sheet
A1: TOSHIBA INTERNATIONAL CORPORATION
A2: INDUCTION MOTOR DATA SHEET
A3: File: | B3: 1T2M20K | I3: HRW / Model Number: | J3: M203WTAK11F-A1
A4: Type: TIKK - Form: DCKW - 2 Pole - 1000 HP - 2300 / 4000 V - 60 Hz - 5012 - Class F | L4: LAB 3191 | Q4: Motor Type Selection | T4: Electrical Steel Table
A5: Motor Parameters | F5: PERFORMANCE | J5: DESIGN | K5: TEST | L5: DMM000014 | Q5: EPACT | T5: M22 - 26Ga.
A6: Material | D6: M22 - 26Ga. | F6: NL & Impedance Test | L6: NRK 5066 EPOXY RESIN | Q6: EQP-III | T6: M36 - 26Ga.
A7: Air Gap | D7: 2.9000001 | F7: No load amps | J7: 48 / 28 | K7: - | L7: 28.5 | Q7: Exp.Prf. | T7: NCB1 - 26Ga.
A8: Stack length | D8: 565 | F8: No load watts | J8: 8969 | K8: - | L8: 8614 | Q8: Exp.Prf.-EQPIII | T8: M43 - 26Ga.
A9: Number of turns per coil | D9: 7 | F9: Impedance amps | H9: 3 | I9: f | J9: 253 | K9: - | Q9: Prem. Eff. | T9: M45 - 26Ga.
A10: Wire 1 (size & number) | D10: (.114"x.182")x1 | F10: Impedance volts | H10: 3 | I10: f | J10: 1150 | K10: - | Q10: OWP | T10: M54 - 26Ga.
A11: Wire 2 (size & number) | D11: (.114"x.204")x1 | F11: Impedance watts | H11: 3 | I11: f | J11: 36094 | K11: - | Q11: Dry Kiln
A12: Slot fill - circle/square method (%) | D12: - | F12: Temperature Rise (°C)
A13: Connection | D13: 1D / 1Y | G13: Winding | I13: 80/115 | J13: 65 / 86 | K13: - | L13: 59 / 78
A14: MCL | D14: 1155 | G14: Frame | J14: - | K14: -
A15: Allowance for ins. depth | D15: 10.8316 | G15: Bearing PS/OS | J15: - | K15: -
A16: Allowance for ins. width | D16: 3.7956002 | G16: End Ring | J16: - | K16: -
A17: Slot/Wire arrangement | D17: 14 x 2 | F17: Nameplate Data
A18: Effective cross section for coil | D18: - | H18: FLC (A) | J18: 222 / 128 | L18: 127.4
A19: Coil grouping | D19: - | H19: RPM | J19: 3560 | L19: 3565
A20: Coil pitch (slot number) | D20: 1 ~ 14 | H20: CODE | J20: F
A21: Method of coil connection | D21: - | H21: S. F. | J21: 1.15 | Q21: Method of Connection
A22: Resistance per phase @ 20 °C | D22: 0.1435 | H22: DESIGN | J22: - | Q22: Skip
A23: Coil Weight | B23: Wire1 | D23: 178 | H23: Nom.Eff. (%): | Q23: Adjacent
A24: (lbs.) | B24: Wire2 | D24: 200 | H24: Min.Eff. (%): | Q24: -
A25: Current Densities (A/cm2) | E25: Bar / ER | H25: P.F. (%):
A26: FL / LR | D26: 469 / 2829 | E26: 381 / 308
A27: Stator Slot Shape (Reference) | F27: Performance
H28: LRC (A) | I28: - | J28: 1337/ 772 | K28: - | L28: 799.6
H29: LRT (%) | I29: 60 | J29: 120 | K29: - | L29: 117.7
H30: BDT (%) | I30: 175 | J30: 250 | K30: - | L30: 274.2
H31: SLIP (%) | J31: 1 | K31: -
G32: IEEE-B | H32: Eff. (%) | J32: 94.7 | K32: - | L32: 95.6
A33: Rotor Slot Shape (Reference) | H33: PF (%) | J33: 88.9 | K33: - | L33: 88.7
F34: Losses (Watts) | H34: Primary | J34: 9084 | K34: - | L34: 8790
H35: Secondary | J35: 7716 | K35: - | L35: 7279.6
H36: Core | J36: 5940 | K36: - | L36: 5887.1
H37: F & W | J37: 2692 | K37: - | L37: 2727.5
H38: Stray | J38: 16492 | K38: - | L38: 9861
A39: End Ring (Reference) | F39: Note
G40: QC Limits: 1T2M20K
...

Sheet LoginSheet
J1: P | K1: T | L1: L | M1: T
B2: PROJECT HISTORY | J2: E | K2: D | L2: I | M2: Y | N2: H
J3: R | L3: M | M3: P
J4: F | L4: I | M4: E
K5: C | L5: T | N5: I
J6: D | K6: U | M6: T | N6: N
J7: A | K7: R | L7: R | M7: E | N7: S
I8: S | J8: T | K8: V | L8: E | M8: S | N8: U
B9: DATE | C9: PROJECT | D9: SMART NUMBER | E9: QTY | F9: CUSTOMER | G9: REMARKS | H9: LIMIT CODE | I9: F | J9: A | K9: E | L9: V | M9: T | N9: L
B53: REVISION HISTORY
B54: REV | C54: REMARKS | I54: DATE | L54: INIT

Sheet StallTime
A1: Rating: | B1: 2 Pole - 1000.0 HP - 3600 RPM - 4000 V - 60 Hz
A3: Starting Performance
D4: Load Type: Fan / Pump - 334.0 lb-ft²
A5: RPM | B5: Motor | C5: Load | D5: Accel. | E5: Line | F5: Stator | G5: Rotor
A6: Speed Increment | B6: Torque (%) | C6: Torque (%) | D6: Time (s) | E6: Amps | F6: kW / s | G6: kW / s
A7: 0~360 | B7: 115.3 | C7: 22.5 | D7: 0.409 | E7: 768.9 | F7: 140.9 | G7: 407.1
A8: 360~720 | B8: 107.7 | C8: 11.5 | D8: 0.394 | E8: 762.5 | F8: 133.8 | G8: 325.5
A9: 720~1080 | B9: 103.4 | C9: 7.0 | D9: 0.394 | E9: 755.4 | F9: 131.1 | G9: 274.2
A10: 1080~1440 | B10: 101.1 | C10: 7.0 | D10: 0.403 | E10: 747.7 | F10: 131.8 | G10: 238.5
A11: 1440~1800 | B11: 100.2 | C11: 11.0 | D11: 0.425 | E11: 738.9 | F11: 136.0 | G11: 212.6
A12: 1800~2192 | B12: 100.8 | C12: 18.5 | D12: 0.502 | E12: 728.9 | F12: 156.5 | G12: 191.3
A13: 2192~2584 | B13: 103.8 | C13: 29.5 | D13: 0.556 | E13: 716.4 | F13: 168.3 | G13: 168.3
A14: 2584~2976 | B14: 112.7 | C14: 45.9 | D14: 0.618 | E14: 696.2 | F14: 179.9 | G14: 141.1
A15: 2976~3172 | B15: 129.2 | C15: 62.5 | D15: 0.310 | E15: 669.6 | F15: 83.6 | G15: 97.6
A16: 3172~3368 | B16: 157.4 | C16: 76.2 | D16: 0.254 | E16: 626.6 | F16: 63.3 | G16: 64.0
... A18: 3564~3567 | B18: 175.0 | C18: 98.8 | D18: 0.004 | E18: 276.7 | F18: 0.0 | G18: 9.4
D21: Acceleration Time: 4.4 s
B22: Energy | D22: First Start | F22: Second Start
A23: Stator Winding Rise | B23: 1360 kW / s | D23: 21°C | F23: 43°C
A24: Rotor Bar Rise | B24: 1612 kW / s | D24: 84°C | F24: 168°C
A25: End Ring Rise | B25: 546 kW / s | D25: 44°C | F25: 87°C
A27: Locked Rotor Thermal Capability
E28: Cold Condition
B29: Rate of Rise | D29: Power | E29: Rise Limit | F29: Max Time
A30: Stator Copper | B30: 6.3°C / s | D30: 397.8 kW | E30: 160°C | F30: 25.5 s
A31: Rotor Bar | B31: 34.9°C / s | D31: 668.6 kW | E31: 260°C | F31: 7.5 s
A32: Rotor ER | B32: 18.1°C / s | D32: 226.6 kW | E32: 180°C | F32: 10.0 s
E34: Hot Condition
B35: Hot Temp. | D35: Rise Limit | E35: Ambient | F35: Total | G35: Max.Time
A36: Stator Copper | B36: 65°C + | D36: 95°C + | E36: 40°C | F36: = 200°C | G36: 15.2 s
A37: Rotor Bar | B37: 86°C + | D37: 174°C + | E37: 40°C | F37: = 300°C | G37: 5.0 s
A38: Rotor ER | B38: 86°C + | D38: 94°C + | E38: 40°C | F38: = 220°C | G38: 5.2 s
A40: Cold Stall Time: | B40: 7.3 s | D40: Hot Stall Time: | F40: 3.8 s

Sheet Form
A1: Winding Data Calculation
C2: MCL: 1155.0
A3: Coil Resistance | D3: Lead Resistance
A4: 7T: | B4: 0.0103 ~ 0.0099 | D4: AWG. 02 x 6
D5: 0.00130
A6: Coil Dimensions
A7: HM: | B7: 7T: 21.67 | C7: WM: | D7: 7T: 10.20 | E7: WT:
E8: 14.10 ~ 13.70
A9: Insulation Allowance | D9: Wire Weight
A10: Depth: | B10: 10.83 | D10: (.114"x.182")x 1: | F10: 178 lbs.
A11: Width: | B11: 3.80 | D11: (.114"x.204")x 1: | F11: 200 lbs.
A12: QC Resistance
A13: 1-4, 2-5, 3-6: | C13: 0.148 ~ 0.139

Sheet MagNoise
A1: Magnetic Noise Verification
A3: Rating: | B3: 2 Pole - 1000.0 HP - 3600 RPM - 4000 V - 60 Hz
A5: Electromagnetic Excitation Frequencies
B7: L = | C7: 0 | D7: L = | E7: + 1 | F7: L = | G7: - 1 | H7: Slip = | I7: 0 | J7: Slip = | K7: 0.009
A8: Mode A | B8: 6 | D8: 12 | F8: 0 | H8: 2160.0 Hz | J8: 2141.4 Hz
A9: Mode B | B9: 10 | D9: 16 | F9: 4 | H9: 1920.0 Hz | J9: 1901.4 Hz
A10: Mode C | B10: 8 | D10: 14 | F10: 2 | H10: 2040.0 Hz | J10: 2021.4 Hz
A12: Natural Frequencies of Stator Core
B14: Mode 0 = | D14: 2747.0 Hz | F14: Mode 6 = | H14: 7080.6 Hz
B15: Mode 2 = | D15: 550.3 Hz | F15: Mode 7 = | H15: 9745.5 Hz
B16: Mode 3 = | D16: 1556.5 Hz | F16: Mode 8 = | H16: 12821.0 Hz
B17: Mode 4 = | D17: 2984.5 Hz | F17: Mode 9 = | H17: 16307.0 Hz
B18: Mode 5 = | D18: 4826.6 Hz | F18: Mode 10 = | H18: 20203.4 Hz
A20: Analysis Results
B22: No matching frequencies detected.

Sheet Performance Data Sheet
A1: TOSHIBA INTERNATIONAL CORPORATION | J1: INDEX | L1: MPCF-1033
A2: Industrial Division / Houston Motor Plant | J2: SHEET NO. | L2: 1 of 1
J3: ISSUED | L3: 7/31/13
J4: SUPERSEDES | L4: 11/8/96
J5: REVISION | L5: 2
A6: SQUIRREL CAGE INDUCTION MOTOR | J6: WRITTEN BY | L6: MDC
A7: PERFORMANCE SPECIFICATIONS | J7: APPROVED BY | L7: PAA
B9: CUSTOMER: | C9: DYKMAN
B10: TIC SR No.: | C10: 2361573.1
A12: MOTOR NAMEPLATE DATA
B13: H.P.: | C13: 1000 | E13: VOLTS: | F13: 2300/4000 | H13: 3 PH / | I13: 60 Hz | L13: S. RPM: | M13: 3600
B14: FRAME: | C14: 5012USS | E14: ENCL: | F14: WP-II | H14: FLAMPS: | I14: 222/128 | L14: FLRPM: | M14: 3564
B15: FORM: | C15: DCKW | E15: S.F.: | F15: 1.15 | H15: NEMA DESIGN: | I15: B | L15: INSUL CLASS: | M15: F
B16: TYPE: | C16: TIKK | E16: AMB.: | F16: 40°C | H16: CODE: | I16: F | L16: DUTY: | M16: Cont.
B17: MODEL No.: | C17: WT-10163712 | H17: kW: | I17: -
B18: NOM. EFF.: | E18: MIN. EFF.: | H18: P.F.:
A21: AMPERAGE | E21: TORQUES | I21: **BEARINGS:
C22: LOCKED ROTOR: | D22: 1337/772 | G22: FULL LOAD (lb-ft.): | H22: 1474 | K22: DRIVE END: | L22: REFER TO NP
G23: LOCKED ROTOR (%): | H23: 120 | K23: OPPOSITE DRIVE END: | L23: REFER TO NP
G24: BREAK DOWN (%): | H24: 250
A28: EFFICIENCY | H28: POWER FACTOR
C29: FULL LOAD: | D29: 94.7 | J29: FULL LOAD: | K29: 88.9
C30: 3/4 LOAD: | D30: 94.6 | J30: 3/4 LOAD: | K30: 87.2
C31: 1/2 LOAD: | D31: 94 | J31: 1/2 LOAD: | K31: 82
A35: ALL CHARACTERISTICS ARE AVERAGE EXPECTED VALUES BASED UPON RATED VOLTAGE,
A36: FREQUENCY AND SINEWAVE POWER INPUT.
A37: THE DECLARED LOCKED ROTOR CURRENT HAS A TOLERANCE OF 20%.
A38: * TEMPERATURE RISE WILL BE CONSISTENT WITH INSULATION, AMBIENT AND SERVICE FACTOR AS
A39: DEFINED BY NEMA-MG-12 OR -20.
A40: ** BEARINGS ARE THE ONLY RECOMMENDED SPARE PART(S).
J42: CERTIFIED BY: | K42: JERRY R
J44: DATE: | K44: 45737
A59: - | B59: 6205ZZ | D59: 1 | E59: -
A60: TEFC | B60: 6206UU | D60: 1.15 | E60: A
A61: ODP | B61: 6207ZZ | E61: B
B62: 6208UU
B63: 6211ZZ
B64: 6211C3
B65: 6211ZZC3
B66: 6305UUC3
...

Sheet STCurve
A2: TOSHIBA INTERNATIONAL CORPORATION
A3: Speed Torque/Current Curve
A6: Model #: | B6: ='Performance Data Sheet'!C17 -> WT-10163712 | E6: FLAmps: | F6: ='Performance Data Sheet'!I14 & " A" -> 222/128 A
A7: Enclosure: | B7: ='Performance Data Sheet'!F14 -> WP-II | C7: Voltage: | D7: ='Performance Data Sheet'!F13 & " V" -> 2300/4000 V | E7: Frame: | F7: ='Performance Data Sheet'!C14 -> 5012USS
A8: Pole: | B8: 2 | C8: Frequency: | D8: 3 PH / 60 Hz | E8: Ins. Class: | F8: F
A9: HP: | B9: 1000 | C9: Rotor Inertia: | D9: 143.6 lb-ft² | E9: Date: | F9: ='Performance Data Sheet'!K44 -> 45737
A10: FLRPM: | B10: 3560 | C10: Load Inertia: | D10: N/A | E10: File: | F10: 1T2M20K
B12: Locked Rotor Amps: | C12: ='Performance Data Sheet'!D22 & " A" -> 1337/772 A | D12: Load Type: | E12: N/A
B13: Locked Rotor Torque: | C13: 1.2 | D13: Starting at: | E13: N/A
B14: Breakdown Torque: | C14: 2.5 | D14: Accel. Time: | E14: N/A
B15: Rated Torque: | C15: 1475 lb-ft
A39: Comments: | B39: PROJECT | C39: ='Performance Data Sheet'!C10 -> 2361573.1 | E39: D.E.Curve #: | F39: =F10 -> 1T2M20K
C43: Prepared by: | D43: ='Performance Data Sheet'!K42 -> JERRY R | E43: Checked by:
D53: Load
A54: 100 | B54: 0 | C54: 0.23475848 | D54: 100 | E54: =0.64*B54 -> 0 | F54: =0.8*C54 -> 0.18780679
A55: 99.8 | B55: 81.557143 | C55: 90.803345 | D55: 99.599998 | E55: =0.64*B55 -> 52.196572 | F55: =0.8*C55 -> 72.642676
A56: 99 | B56: 250 | C56: 341.52548 | D56: 98 | E56: =0.64*B56 -> 160 | F56: =0.8*C56 -> 273.22039
A57: 93.555555 | B57: 175.85059 | C57: 466.62973 | D57: 83.244446 | E57: =0.64*B57 -> 112.54437 | F57: =0.8*C57 -> 373.30378
A58: 88.11111 | B58: 138.95503 | C58: 512.41797 | D58: 69.088882 | E58: =0.64*B58 -> 88.931222 | F58: =0.8*C58 -> 409.93438
A59: 82.666667 | B59: 119.35002 | C59: 533.76691 | D59: 55.866669 | E59: =0.64*B59 -> 76.384015 | F59: =0.8*C59 -> 427.01353
A60: 71.777776 | B60: 106.11773 | C60: 554.0553 | D60: 36.022221 | E60: =0.64*B60 -> 67.915348 | F60: =0.8*C60 -> 443.24424
A61: 60.888889 | B61: 101.56817 | C61: 565.26575 | D61: 22.977777 | E61: =0.64*B61 -> 65.003631 | F61: =0.8*C61 -> 452.2126
A62: 50 | B62: 100 | C62: 573.68317 | D62: 14 | E62: =0.64*B62 -> 64 | F62: =0.8*C62 -> 458.94653
A63: 39.999998 | B63: 100.38477 | C63: 580.87811 | D63: 7.9999995 | E63: =0.64*B63 -> 64.24625 | F63: =0.8*C63 -> 464.70249
A64: 30.000001 | B64: 101.86343 | C64: 587.33551 | D64: 5.9999995 | E64: =0.64*B64 -> 65.192598 | F64: =0.8*C64 -> 469.86841
A65: 19.999999 | B65: 104.94455 | C65: 593.03967 | D65: 8.000001 | E65: =0.64*B65 -> 67.164512 | F65: =0.8*C65 -> 474.43174
... A67: 0 | B67: 120 | C67: 603.125 | D67: 30 | E67: =0.64*B67 -> 76.8 | F67: =0.8*C67 -> 482.5

Sheet Thermdam
A2: TOSHIBA INTERNATIONAL CORPORATION
A3: Thermal Limit & Acceleration Curves
A4: Design Values (For Reference Only)
A6: Model #: | B6: ='Performance Data Sheet'!C17 -> WT-10163712 | E6: FLAmps: | F6: ='Performance Data Sheet'!I14 & " A" -> 222/128 A
A7: Enclosure: | B7: ='Performance Data Sheet'!F14 -> WP-II | C7: Voltage: | D7: ='Performance Data Sheet'!F13 & " V" -> 2300/4000 V | E7: Frame: | F7: ='Performance Data Sheet'!C14 -> 5012USS
A8: Pole: | B8: 2 | C8: Frequency: | D8: 3 PH / 60 Hz | E8: Ins. Class: | F8: F
A9: HP: | B9: 1000 | C9: Rotor Inertia: | D9: 143.6 lb-ft² | E9: Date: | F9: ='Performance Data Sheet'!K44 -> 45737
A10: FLRPM: | B10: 3560 | C10: Load Inertia: | D10: N/A | E10: File: | F10: 1T2M20K
A39: Comments: | B39: PROJECT | C39: ='Performance Data Sheet'!C10 -> 2361573.1 | E39: D.E.Curve #: | F39: =F10 -> 1T2M20K
C43: Prepared by: | D43: ='Performance Data Sheet'!K42 -> JERRY R | E43: Checked by:
F50: =5252.1*B50/D53 -> #DIV/0!
D66: =D65/D64 -> #DIV/0!
A67: Current (%) | B67: Cold | C67: Hot | E67: CURRENT (%) | F67: Accel. Time
A68: 603.125 | B68: 10.394771 | C68: 5.4243548 | E68: =A68 -> 603.125 | F68: 0.0001
A69: =FLOOR(A68,100) -> 600 | B69: =((A68/A69)^2)*B68 -> 10.503332 | C69: =((A68/A69)^2)*C68 -> 5.4810056 | E69: 600.70312 | F69: 0.40900001
A70: =A69-100 -> 500 | B70: =((A68/A70)^2)*B68 -> 15.124798 | C70: =((A68/A70)^2)*C68 -> 7.8926481 | E70: 595.70312 | F70: 0.80300003
A71: =A70-100 -> 400 | B71: =((A68/A71)^2)*B68 -> 23.632498 | C71: =((A68/A71)^2)*C68 -> 12.332263 | E71: 590.15625 | F71: 1.197
A72: =A71-100 -> 300 | B72: =((A68/A72)^2)*B68 -> 42.013329 | E72: 584.14062 | F72: 1.6
A73: =A72-100 -> 200 | B73: =((A68/A73)^2)*B68 -> 94.529991 | E73: 577.26562 | F73: 2.0250001
A74: 250 | B74: =((A68/A74)^2)*B68 -> 60.499194 | C74: =((A68/A74)^2)*C68 -> 31.570592 | E74: 569.45312 | F74: 2.5270002
A75: 180 | B75: =((A68/A75)^2)*B69 -> 117.92252 | C75: =((A68/A75)^2)*C68 -> 60.900062 | E75: 559.6875 | F75: 3.0830002
A76: 120 | B76: =((A68/A76)^2)*B68 -> 262.58331 | C76: =((A68/A76)^2)*C68 -> 137.02514 | E76: 543.90625 | F76: 3.7010002
A77: 110 | C77: =CEILING(C76*2,100) -> 300 | E77: 523.125 | F77: 4.0110002
A78: 110 | C78: =2*C77 -> 600 | E78: 489.53125 | F78: 4.2650003
A79: 110 | C79: 10000 | E79: 404.0625 | F79: 4.4340005
E80: 0 | F80: 4.4380007

Sheet Performance 4000V
A2: TOSHIBA INTERNATIONAL CORPORATION
A3: Performance Curve
A4: Design Values (For Reference Only)
A6: Model #: | B6: ='Performance Data Sheet'!C17 -> WT-10163712 | E6: FLAmps: | F6: 128 A
A7: Enclosure: | B7: ='Performance Data Sheet'!F14 -> WP-II | C7: Voltage: | D7: 4000V | E7: Frame: | F7: ='Performance Data Sheet'!C14 -> 5012USS
A8: Pole: | B8: 2 | C8: Frequency: | D8: 3 PH / 60 Hz | E8: Ins. Class: | F8: F
A9: HP: | B9: 1000 | C9: Rotor Inertia: | D9: 143.6 lb-ft² | E9: Date: | F9: ='Performance Data Sheet'!K44 -> 45737
A10: FLRPM: | B10: 3560 | C10: Load Inertia: | D10: N/A | E10: File: | F10: 1T2M20K
B12: Locked Rotor Amps: | C12: 772 A | D12: Load Type: | E12: N/A
B13: Locked Rotor Torque: | C13: 1.2 | D13: Starting at: | E13: N/A
B14: Breakdown Torque: | C14: 2.5 | D14: Accel. Time: | E14: N/A
B15: Rated Torque: | C15: 1475 lb-ft
N36: SPEED | O36: KW
N37: =L43 - (L43-L44) / 10 * 0 -> 3600 | O37: =L45 / 10 * 10 -> 2000
N38: =L43 - (L43-L44) / 10 * 1 -> 3595 | O38: =L45 / 10 * 9 -> 1800
A39: Comments: | B39: PROJECT | C39: ='Performance Data Sheet'!C10 -> 2361573.1 | E39: D.E.Curve #: | F39: =F10 -> 1T2M20K | N39: =L43 - (L43-L44) / 10 * 2 -> 3590 | O39: =L45 / 10 * 8 -> 1600
N40: =L43 - (L43-L44) / 10 * 3 -> 3585 | O40: =L45 / 10 * 7 -> 1400
N41: =L43 - (L43-L44) / 10 * 4 -> 3580 | O41: =L45 / 10 * 6 -> 1200
N42: =L43 - (L43-L44) / 10 * 5 -> 3575 | O42: =L45 / 10 * 5 -> 1000
C43: Prepared by: | D43: ='Performance Data Sheet'!K42 -> JERRY R | E43: Checked by: | K43: SYNC SPEED | L43: 3600 | N43: =L43 - (L43-L44) / 10 * 6 -> 3570 | O43: =L45 / 10 * 4 -> 800
K44: NEW SPEED LOWER RANGE | L44: 3550 | N44: =L43 - (L43-L44) / 10 * 7 -> 3565 | O44: =L45 / 10 * 3 -> 600
K45: NEW kW UPPER RANGE | L45: 2000 | N45: =L43 - (L43-L44) / 10 * 8 -> 3560 | O45: =L45 / 10 * 2 -> 400
N46: =L43 - (L43-L44) / 10 * 9 -> 3555 | O46: =L45 / 10 * 1 -> 200
N47: =L43 - (L43-L44) / 10 * 10 -> 3550 | O47: =L45 / 10 * 0 -> 0
A52: ADJUSTED
A53: Load | B53: Efficiency | C53: PF | D53: Amps | E53: RPM | F53: Input Watts
A54: 0 | D54: 28 | E54: 100 | F54: =9000/(L45*1000) * 100 -> 0.45
A55: 25 | B55: 91.199997 | C55: 64.300003 | D55: 45.91 | E55: =(1.007607*B10-L44)/(L43-L44)*100 -> 74.16184 | F55: =204521.5/(L45*1000)*100 -> 10.226075
A56: 50 | B56: 94 | C56: 82 | D56: 69.900002 | E56: =(1.005143*B10-L44)/(L43-L44)*100 -> 56.61816 | F56: =397110.8/(L45*1000)*100 -> 19.85554
A57: 75 | B57: 94.599998 | C57: 87.199997 | D57: 97.919998 | E57: =(1.002618*B10-L44)/(L43-L44)*100 -> 38.64016 | F57: =591573.2/(L45*1000)*100 -> 29.57866
A58: 100 | B58: 94.700005 | C58: 88.900002 | D58: 127.92 | E58: =(1*B10-L44)/(L43-L44)*100 -> 20 | F58: =787881.4/(L45*1000)*100 -> 39.39407
A59: 125 | B59: 94.5 | C59: 89.300003 | D59: 159.5 | E59: =(0.9974132*B10-L44)/(L43-L44)*100 -> 1.581984 | F59: =986808.3/(L45*1000)*100 -> 49.340415
A62: ORIGINAL
A63: Load | B63: Efficiency | C63: PF | D63: Amps | E63: RPM | F63: Input Watts
A64: 0 | D64: 31.251048 | E64: 100 | F64: 13.454629
A65: 25 | B65: 91.240883 | C65: 64.290955 | D65: 45.903999 | E65: 77.291646 | F65: 10.222998
A66: 50 | B66: 93.971985 | C66: 81.995407 | D66: 69.892715 | E66: 61.286287 | F66: 19.851774
A67: 75 | B67: 94.610947 | C67: 87.203964 | D67: 97.911461 | E67: 44.880058 | F67: 29.576558
A68: 100 | B68: 94.690392 | C68: 88.923943 | D68: 127.91611 | E68: 28.029061 | F68: 39.402322
A69: 125 | B69: 94.539886 | C69: 89.287598 | D69: 159.49742 | E69: 11.206406 | F69: 49.331316

Sheet Performance 2300V
A2: TOSHIBA INTERNATIONAL CORPORATION
A3: Performance Curve
A4: Design Values (For Reference Only)
A6: Model #: | B6: ='Performance Data Sheet'!C17 -> WT-10163712 | E6: FLAmps: | F6: 222 A
A7: Enclosure: | B7: ='Performance Data Sheet'!F14 -> WP-II | C7: Voltage: | D7: 2300 V | E7: Frame: | F7: ='Performance Data Sheet'!C14 -> 5012USS
A8: Pole: | B8: 2 | C8: Frequency: | D8: 3 PH / 60 Hz | E8: Ins. Class: | F8: F
A9: HP: | B9: 1000 | C9: Rotor Inertia: | D9: 143.6 lb-ft² | E9: Date: | F9: ='Performance Data Sheet'!K44 -> 45737
A10: FLRPM: | B10: 3560 | C10: Load Inertia: | D10: N/A | E10: File: | F10: 1T2M20K
B12: Locked Rotor Amps: | C12: 1337 A | D12: Load Type: | E12: N/A
B13: Locked Rotor Torque: | C13: 1.2 | D13: Starting at: | E13: N/A
B14: Breakdown Torque: | C14: 2.5 | D14: Accel. Time: | E14: N/A
B15: Rated Torque: | C15: 1475 lb-ft
N36: SPEED | O36: KW
N37: =L43 - (L43-L44) / 10 * 0 -> 3600 | O37: =L45 / 10 * 10 -> 2000
N38: =L43 - (L43-L44) / 10 * 1 -> 3595 | O38: =L45 / 10 * 9 -> 1800
A39: Comments: | B39: PROJECT | C39: ='Performance Data Sheet'!C10 -> 2361573.1 | E39: D.E.Curve #: | F39: =F10 -> 1T2M20K | N39: =L43 - (L43-L44) / 10 * 2 -> 3590 | O39: =L45 / 10 * 8 -> 1600
N40: =L43 - (L43-L44) / 10 * 3 -> 3585 | O40: =L45 / 10 * 7 -> 1400
N41: =L43 - (L43-L44) / 10 * 4 -> 3580 | O41: =L45 / 10 * 6 -> 1200
N42: =L43 - (L43-L44) / 10 * 5 -> 3575 | O42: =L45 / 10 * 5 -> 1000
C43: Prepared by: | D43: ='Performance Data Sheet'!K42 -> JERRY R | E43: Checked by: | K43: SYNC SPEED | L43: 3600 | N43: =L43 - (L43-L44) / 10 * 6 -> 3570 | O43: =L45 / 10 * 4 -> 800
K44: NEW SPEED LOWER RANGE | L44: 3550 | N44: =L43 - (L43-L44) / 10 * 7 -> 3565 | O44: =L45 / 10 * 3 -> 600
K45: NEW kW UPPER RANGE | L45: 2000 | N45: =L43 - (L43-L44) / 10 * 8 -> 3560 | O45: =L45 / 10 * 2 -> 400
N46: =L43 - (L43-L44) / 10 * 9 -> 3555 | O46: =L45 / 10 * 1 -> 200
N47: =L43 - (L43-L44) / 10 * 10 -> 3550 | O47: =L45 / 10 * 0 -> 0
A52: ADJUSTED
A53: Load | B53: Efficiency | C53: PF | D53: Amps | E53: RPM | F53: Input Watts
A54: 0 | D54: 48.497423 | E54: 100 | F54: =9000/(L45*1000) * 100 -> 0.45
A55: 25 | B55: 91.199997 | C55: 64.300003 | D55: 79.518452 | E55: =(1.007607*B10-L44)/(L43-L44)*100 -> 74.16184 | F55: =204521.5/(L45*1000)*100 -> 10.226075
A56: 50 | B56: 94 | C56: 82 | D56: 121.07035 | E56: =(1.005143*B10-L44)/(L43-L44)*100 -> 56.61816 | F56: =397110.8/(L45*1000)*100 -> 19.85554
A57: 75 | B57: 94.599998 | C57: 87.199997 | D57: 169.60241 | E57: =(1.002618*B10-L44)/(L43-L44)*100 -> 38.64016 | F57: =591573.2/(L45*1000)*100 -> 29.57866
A58: 100 | B58: 94.700005 | C58: 88.900002 | D58: 222 | E58: =(1*B10-L44)/(L43-L44)*100 -> 20 | F58: =787881.4/(L45*1000)*100 -> 39.39407
A59: 125 | B59: 94.5 | C59: 89.300003 | D59: 276.2621 | E59: =(0.9974132*B10-L44)/(L43-L44)*100 -> 1.581984 | F59: =986808.3/(L45*1000)*100 -> 49.340415
A62: ORIGINAL
A63: Load | B63: Efficiency | C63: PF | D63: Amps | E63: RPM | F63: Input Watts
A64: 0 | D64: 31.251048 | E64: 100 | F64: 13.454629
A65: 25 | B65: 91.240883 | C65: 64.290955 | D65: 45.903999 | E65: 77.291646 | F65: 10.222998
A66: 50 | B66: 93.971985 | C66: 81.995407 | D66: 69.892715 | E66: 61.286287 | F66: 19.851774
A67: 75 | B67: 94.610947 | C67: 87.203964 | D67: 97.911461 | E67: 44.880058 | F67: 29.576558
A68: 100 | B68: 94.690392 | C68: 88.923943 | D68: 127.91611 | E68: 28.029061 | F68: 39.402322
A69: 125 | B69: 94.539886 | C69: 89.287598 | D69: 159.49742 | E69: 11.206406 | F69: 49.331316
