Workbook
Name Print_Area_MI: #REF!

Sheet DesignSheet
A1: TOSHIBA INTERNATIONAL CORPORATION | I1: Calc. Code: | J1: 2-2-2-0-1-2
A2: 3-PHASE SQUIRREL CAGE INDUCTION MOTOR DESIGN SHEET | J2: B.L.-1 P.F.-1
A3: File: | B3: N:\DESPRO\RATFILE\1T2M35U.rat | G3: Date: | H3: 40914 | I3: Time: | J3: 0.32585648
A4: Pole | B4: HP | C4: RPM | D4: Form | E4: Voltage | F4: Frequency | G4: Temperature | H4: FLSpeed | I4: FLSlip | J4: Frame
A5: 2 | B5: 1750 | C5: 3600 | D5: DCW4 | E5: 4000 | F5: 60 | G5: 105 | H5: 3569.4 / 3570.0 | I5: 0.0085 / 0.0083 | J5: 5811/12UDZ
A6: Core Data | D6: Winding Data | H6: Constant Data
B7: Primary | C7: Secondary | F7: Bar | G7: End Ring | H7: St. Slot Pitch | I7: 24.543672 | J7: LR Test Data
A8: Air Gap | B8: 3.3 | H8: Rt. Slot Pitch | I8: 30.456888 | J8: ES
A9: Space Fac. | B9: 0.93000001 | D9: Pitch | E9: 1 ~ 16 | F9: Cross Section Area | H9: Mean Value | I9: 27.50028 | J9: 667.7756
A10: Core Length | B10: 600 | C10: 600 | F10: UB: 406.6 | G10: UER: 3370.3 | H10: Eff.T.W.St. | I10: 14.338923 | J10: WS
A11: OD | B11: 670 | C11: 368.4 | D11: Coil Pitch | E11: 0.6249375 | G11: ERT: 85.0 | H11: Eff.T.W.Rt. | I11: 30.456888 | J11: 70159.625
A12: ID | B12: 375 | C12: 185 | D12: Slot Fill | E12: - | G12: ERD1: 281.0 | H12: St.Carter Fac. | I12: 1.1789163 | J12: IS
A13: Core Depth | B13: 85 | C13: 54.7 | D13: Con./Slot | E13: 18 | G13: ERD2: 367.0 | H13: Rt.Carter Fac. | I13: 1 | J13: 218.85289
A14: Eff.Core L. | B14: 465 | C14: 474.30002 | D14: Wire Size 1 | E14: (.102"x.204")x2 | H14: Carter Factor | I14: 1.1789163 | J14: Volts / Turn
A15: Slot Data | D15: Wire Size 2 | E15: - | H15: Short. Factor | I15: 0.8314146 | J15: 32.075955
A16: Number | B16: 48 | C16: 38 | D16: // Circuits | E16: 2 | H16: Distrib. Factor | I16: 0.95543647 | J16: AC
A17: Kind | B17: Open | C17: Dbl - Closed | D17: Connection | E17: Wye | H17: Wind. Factor | I17: 0.79436384 | J17: 802.51888
A18: Skew | B18: - | C18: 0 | D18: MCL | E18: 1295 | F18: 685 | H18: Reactance | I18: (Coeff.: 0.0267)
A19: Depth | B19: 62.5 | C19: 37 | D19: No.Cond./Ph. | E19: 144 | I19: Running | J19: Start
A20: Width | B20: 10.20 - 10.20 | D20: Res. (20°C) | E20: 0.061920837 | H20: Stator Slot | I20: 18.533136 | J20: 18.533136
A21: Opening | B21: 14.5 | C21: 0 | D21: (105°C) | E21: 0.082601667 | F21: 0.075841568 | G21: 0.024038006 | H21: Rotor Slot | I21: 40.807228 | J21: 19.660299
A22: Tip Depth | B22: 2.8299999 | C22: 1.9 | D22: Material | E22: CU | F22: AL | G22: AL | H22: Zigzag | I22: 4.3345351 | J22: 3.9067316
A23: T.Min.Wid. | B23: 10.043672 | C23: 11 | D23: Spec.Resist. | E23: 1.742 | F23: 3.25 | G23: 3.25 | H23: Coil End | I23: 20.842818 | J23: Skew R.: 0.00
A24: Low. R. | B24: 0 | C24: 2 | D24: Spec.Gravity | E24: 8.8900003 | F24: 2.6700001 | G24: 2.6700001 | H24: Belt Leakage | I24: 7.2923365 | J24: 6.6345811
A25: Up. R. | B25: - | C25: 2 | D25: Weight (kg) | H25: Total Resist. | I25: 0.18248124 | J25: 0.48827156
A26: Wedge Dep. | B26: 2.83 - 2.00 | C26: Magnetic | D26: Wire 1 | E26: 260.9149 | F26: 24.749654 | G26: 18.629805 | H26: Total React. | I26: 2.453748 | J26: 1.8578984
A27: Duct | B27: 10 x 10 | C27: 9 x 10 | D27: Wire 2 | E27: - | F27: - | G27: - | H27: Impedance | I27: 2.4605241 | J27: 1.9209882
A28: Effective Depth (S=1) | D28: Magnetic Circuit Data | I28: Core Loss Data
B29: Res.= | C29: 35.085827 | E29: Length | F29: Section | G29: Density | H29: AT | I29: Volume | J29: Loss
B30: Reac.= | C30: 35.095949 | D30: Primary Core | E30: 52.621633 | F30: 790.5 | G30: 19.174499 | H30: 1317.9308 | I30: 72640.237 | J30: 7398.678
A31: Excitation Data | D31: Tooth | E31: 6.25 | F31: 1120.8738 | G31: 13.52288 | H31: 37.096951 | I31: 14010.922 | J31: 810.5182
A32: Excit.Amps | B32: 57.385 / 66.946 | D32: Second.Core | E32: 23.122102 | F32: 811.36923 | G32: 18.681312 | H32: 522.70237 | I32: Total | J32: 8209.1962
A33: Core Loss | B33: 2.314 / 2.700 | C33: Flux / Pole | D33: Tooth | E33: 3.7 | F33: 991.28704 | G33: 15.290669 | H33: 36.3731 | I33: C.L.C. | J33: 1.75 / 1.59
A34: NoLoad | B34: 57.43 / 67.00 | C34: 15.157442 | D34: Air Gap | E34: 0.33 | F34: 2523.2435 | G34: 6.007126 | H34: 1577.5066 | I34: S.F.C. | J34: 6.0500002
A35: Load Characteristics | D35: Temp. Rise @ 100%: | E35: 78 / 76 | G35: No Load Loss | H35: 22663.3 / 22696.2 | I35: W.Loss | J35: 14366.1 / 13042.7
A36: Load (%) | B36: 25 | C36: 50 | D36: 75 | E36: 100 | F36: 125 | G36: Primary Loss | H36: 11869.0 / 12437.8 | I36: S.Loss | J36: 1685.5 / 1530.3
A37: Current (A) | B37: 81.47 / 83.38 | C37: 121.18 / 124.03 | D37: 168.16 / 172.11 | E37: 218.85 / 224.00 | F37: 272.50 / 278.91 | G37: Second. Loss | H37: 11563.3 / 9773.0 | I37: Total C.Loss | J37: 16051.6 / 14573.0
A38: Efficiency | B38: 0.931 / 0.920 | C38: 0.959 / 0.947 | D38: 0.966 / 0.954 | E38: 0.967 / 0.956 | F38: 0.966 / 0.955 | G38: Frict.& Wind. | H38: 6000.0 / 7275.0 | I38: Stray Loss | J38: 16201.134
A39: P.F. | B39: 0.621 / 0.614 | C39: 0.811 / 0.802 | D39: 0.870 / 0.860 | E39: 0.890 / 0.880 | F39: 0.894 / 0.884 | G39: Starting Data | I39: Slip | J39: PF
A40: Slip | B40: 0.0021 / 0.0020 | C40: 0.0042 / 0.0040 | D40: 0.0063 / 0.0062 | E40: 0.0085 / 0.0083 | F40: 0.0107 / 0.0105 | G40: LRA | H40: 1202.2 / 1550.9
...

Sheet Data Sheet
A1: TOSHIBA INTERNATIONAL CORPORATION
A2: INDUCTION MOTOR DATA SHEET
A3: File: | B3: 1T2M35U | I3: HRW / Model Number: | J3: M403WTQL11F-A | L3: BASE : M353WTQL11F-A
A4: Type: TIKK - Form: DCW4 - 2 Pole -2000 HP - 4000 V - 60 Hz - 5811/12UDZ - Class F | P4: Motor Type Selection | S4: Electrical Steel Table
A5: Motor Parameters | F5: PERFORMANCE | J5: DESIGN | P5: EPACT | S5: M22 - 26Ga.
A6: Material | D6: M22 - 26Ga. | F6: NL & Impedance Test | P6: EQP-III | S6: M36 - 26Ga.
A7: Air Gap | D7: 3.3 | F7: No load amps | J7: 67 | K7: - | P7: Exp.Prf. | S7: NCB1 - 26Ga.
A8: Stack length | D8: 600 | F8: No load watts | J8: 22696 | K8: - | P8: Exp.Prf.-EQPIII | S8: M43 - 26Ga.
A9: Number of turns per coil | D9: 9 | F9: Impedance amps | H9: 3 | I9: f | J9: 377 | K9: - | P9: Prem. Eff. | S9: M45 - 26Ga.
A10: Wire 1 (061-0023-04) | D10: (.102"x.204")x2 | F10: Impedance volts | H10: 3 | I10: f | J10: 1150 | K10: - | P10: OWP | S10: M54 - 26Ga.
A11: Wire 2 (size & number) | D11: - | F11: Impedance watts | H11: 3 | I11: f | J11: 70160 | K11: - | P11: Dry Kiln
A12: Slot fill - circle/square method (%) | D12: - | F12: Temperature Rise (°C)
A13: Connection | D13: 2 x Wye | G13: Winding | I13: 80/115 | J13: 102 | K13: -
A14: MCL | D14: 1295 | G14: Frame | J14: - | K14: -
A15: Allowance for ins. depth | D15: 9.4356003 | G15: Bearing PS/OS | J15: - | K15: -
A16: Allowance for ins. width | D16: 3.7368 | G16: End Ring | J16: - | K16: -
A17: Slot/Wire arrangement | D17: 18 x 2 | F17: Nameplate Data
A18: Effective cross section for coil | D18: - | H18: FLC (A) | J18: 256
A19: Coil grouping | D19: - | H19: RPM | J19: 2565
A20: Coil pitch (slot number) | D20: 1 ~ 16 (intersperce One Coil) | H20: CODE | J20: F
A21: Method of coil connection | D21: Adjacent | H21: S. F. | J21: 1.0 | P21: Method of Connection
A22: Resistance per phase @ 20 °C | D22: 0.0624 | H22: DESIGN | J22: - | P22: Skip
A23: Coil Weight | B23: Wire1 | D23: 589 | H23: Nom.Eff. (%): | J23: - | P23: Adjacent
A24: (lbs.) | B24: Wire2 | D24: - | H24: Min.Eff. (%): | J24: - | P24: -
A25: Current Densities (A/cm2) | E25: Bar / ER | H25: P.F. (%): | J25: -
A26: FL / LR | D26: 427 / 2957 | E26: 447 / 326
A27: Stator Slot Shape (Reference) | F27: Performance
H28: LRC (A) | I28: - | J28: 1551
H29: LRT (%) | I29: 60 | J29: 179
H30: BDT (%) | I30: 175 | J30: 218
H31: SLIP (%) | J31: 0.97
G32: IEEE-B | H32: Eff. (%) | J32: 95.3
A33: Rotor Slot Shape (Reference) | H33: PF (%) | J33: 88.1
F34: Losses (Watts) | H34: Primary | J34: 16209
H35: Secondary | J35: 13064
H36: Core | J36: 14738
H37: F & W | J37: 7275
H38: Stray | J38: 21657
F39: Note | G39: Top Hat WPII. Sleeve Bearing | M39: NOTE: 2000HP IS NOT SUITABLE FOR ASD DUTY
G40: F&W Losses for A/F: 5000 W | M40: NOT SUITABLE FOR HAZARDOUS LOCATION
...

Sheet LoginSheet
J1: P | K1: T | L1: L | M1: T
B2: PROJECT HISTORY | J2: E | K2: D | L2: I | M2: Y | N2: H
J3: R | L3: M | M3: P
J4: F | L4: I | M4: E
K5: C | L5: T | N5: I
J6: D | K6: U | M6: T | N6: N
J7: A | K7: R | L7: R | M7: E | N7: S
I8: S | J8: T | K8: V | L8: E | M8: S | N8: U
B9: DATE | C9: PROJECT | D9: SMART NUMBER | E9: QTY | F9: CUSTOMER | G9: REMARKS | H9: LIMIT CODE | I9: F | J9: A | K9: E | L9: V | M9: T | N9: L
B37: REVISION HISTORY
B38: REV | C38: REMARKS | I38: DATE | L38: INIT

Sheet StallTime
A1: Rating: | B1: 2 Pole - 2000.0 HP - 3600 RPM - 4000 V - 60 Hz
A3: Starting Performance
D4: Load Type: Fan / Pump - 1096.0 lb-ft²
A5: RPM | B5: Motor | C5: Load | D5: Accel. | E5: Line | F5: Stator | G5: Rotor
A6: Speed Increment | B6: Torque (%) | C6: Torque (%) | D6: Time (s) | E6: Amps | F6: kW / s | G6: kW / s
A7: 0~360 | B7: 161.9 | C7: 22.5 | D7: 0.376 | E7: 1477.2 | F7: 195.3 | G7: 953.0
A8: 360~720 | B8: 149.0 | C8: 11.5 | D8: 0.381 | E8: 1466.9 | F8: 195.5 | G8: 786.9
A9: 720~1080 | B9: 141.5 | C9: 7.0 | D9: 0.389 | E9: 1455.3 | F9: 196.8 | G9: 670.4
A10: 1080~1440 | B10: 137.4 | C10: 7.0 | D10: 0.401 | E10: 1442.5 | F10: 199.7 | G10: 582.2
A11: 1440~1800 | B11: 135.5 | C11: 11.0 | D11: 0.421 | E11: 1428.0 | F11: 205.3 | G11: 512.3
A12: 1800~2160 | B12: 135.1 | C12: 18.0 | D12: 0.447 | E12: 1411.4 | F12: 213.5 | G12: 450.4
A13: 2160~2520 | B13: 135.3 | C13: 27.5 | D13: 0.486 | E13: 1391.3 | F13: 226.2 | G13: 392.3
A14: 2520~2880 | B14: 138.5 | C14: 41.5 | D14: 0.540 | E14: 1360.7 | F14: 243.4 | G14: 327.2
A15: 2880~3060 | B15: 147.8 | C15: 55.5 | D15: 0.284 | E15: 1321.2 | F15: 120.8 | G15: 239.7
A16: 3060~3240 | B16: 168.4 | C16: 67.5 | D16: 0.259 | E16: 1255.8 | F16: 104.0 | G16: 179.0
... A18: 3420~3565 | B18: 155.0 | C18: 92.5 | D18: 0.336 | E18: 597.6 | F18: 5.1 | G18: 25.8
D21: Acceleration Time: 4.5 s
B22: Energy | D22: First Start | F22: Second Start
A23: Stator Winding Rise | B23: 1984 kW / s | D23: 18°C | F23: 37°C
A24: Rotor Bar Rise | B24: 3981 kW / s | D24: 180°C | F24: 359°C
A25: End Ring Rise | B25: 1262 kW / s | D25: 76°C | F25: 151°C
A27: Locked Rotor Thermal Capability
E28: Cold Condition
B29: Rate of Rise | D29: Power | E29: Rise Limit | F29: Max Time
A30: Stator Copper | B30: 6.3°C / s | D30: 680.4 kW | E30: 160°C | F30: 25.5 s
A31: Rotor Bar | B31: 86.9°C / s | D31: 1926.0 kW | E31: 260°C | F31: 3.0 s
A32: Rotor ER | B32: 36.6°C / s | D32: 610.4 kW | E32: 180°C | F32: 4.9 s
E34: Hot Condition
B35: Hot Temp. | D35: Rise Limit | E35: Ambient | F35: Total | G35: Max.Time
A36: Stator Copper | B36: 105°C + | D36: 55°C + | E36: 40°C | F36: = 200°C | G36: 8.8 s
A37: Rotor Bar | B37: 149°C + | D37: 111°C + | E37: 40°C | F37: = 300°C | G37: 1.3 s
A38: Rotor ER | B38: 149°C + | D38: 31°C + | E38: 40°C | F38: = 220°C | G38: 0.8 s
A40: Cold Stall Time: | B40: 15.0 s | D40: Hot Stall Time: | F40: 7.0 s

Sheet Form
A1: Winding Data Calculation
C2: MCL: 1295.0 | E2: 2 Wye Connection
A3: Coil Resistance | D3: Lead Resistance
A4: 9T: | B4: 0.0159 ~ 0.0153 | D4: AWG. 3/0 x 3
D5: 0.00058
A6: Coil Dimensions
A7: HM: | B7: 9T: 25.12 | C7: WM: | D7: 9T: 10.76 | E7: WT:
E8: 14.60 ~ 14.20
A9: Insulation Allowance | D9: Wire Weight
A10: Depth: | B10: 9.44 | D10: (.102"x.204")x 2: | F10: 589 lbs.
A11: Width: | B11: 3.74
A12: QC Resistance
A13: 1-2, 2-3, 3-1: | C13: 0.130 ~ 0.122

Sheet Performance Data Sheet
A1: TOSHIBA INTERNATIONAL CORPORATION | J1: INDEX | L1: MPCF-1033
A2: Industrial Division / Houston Motor Plant | J2: SHEET NO. | L2: 1 of 1
J3: ISSUED | L3: 7/31/13
J4: SUPERSEDES | L4: 11/8/96
J5: REVISION | L5: 2
A6: SQUIRREL CAGE INDUCTION MOTOR | J6: WRITTEN BY | L6: MDC
A7: PERFORMANCE SPECIFICATIONS | J7: APPROVED BY | L7: PAA
B9: CUSTOMER: | C9: DYKMAN ELECTRICAL
B10: TIC SR No.: | C10: 2213503.1
A12: MOTOR NAMEPLATE DATA
B13: H.P.: | C13: 2000 | E13: VOLTS: | F13: 4000 | H13: 3 PH / | I13: 60 Hz | L13: S. RPM: | M13: 3600
B14: FRAME: | C14: 5811USS | E14: ENCL: | F14: WP-II | H14: FLAMPS: | I14: 256 | L14: FLRPM: | M14: 3565
B15: FORM: | C15: DCW4 | E15: S.F.: | F15: 1.0 | H15: NEMA DESIGN: | I15: - | L15: INSUL CLASS: | M15: F
B16: TYPE: | C16: TIKK | E16: AMB.: | F16: 40°C | H16: CODE: | I16: F | L16: DUTY: | M16: Cont.
B17: MODEL No.: | C17: WT-10035612 | H17: kW: | I17: -
B18: NOM. EFF.: | C18: - | E18: MIN. EFF.: | F18: - | H18: P.F.: | I18: -
A21: AMPERAGE | E21: TORQUES | I21: **BEARINGS:
C22: LOCKED ROTOR: | D22: 1551 | G22: FULL LOAD (lb-ft.): | H22: 2946 | K22: DRIVE END:
G23: LOCKED ROTOR (%): | H23: 175 | K23: OPPOSITE DRIVE END:
G24: BREAK DOWN (%): | H24: 215
A28: EFFICIENCY | H28: POWER FACTOR
C29: FULL LOAD: | D29: 95.3 | J29: FULL LOAD: | K29: 88.1
C30: 3/4 LOAD: | D30: 95.3 | J30: 3/4 LOAD: | K30: 86.9
C31: 1/2 LOAD: | D31: 94.8 | J31: 1/2 LOAD: | K31: 82.3
A35: ALL CHARACTERISTICS ARE AVERAGE EXPECTED VALUES BASED UPON RATED VOLTAGE,
A36: FREQUENCY AND SINEWAVE POWER INPUT.
A37: THE DECLARED LOCKED ROTOR CURRENT HAS A TOLERANCE OF 20%
A38: * TEMPERATURE RISE WILL BE CONSISTENT WITH INSULATION, AMBIENT AND SERVICE FACTOR AS
A39: DEFINED BY NEMA-MG-12 OR -20
A40: ** BEARINGS ARE THE ONLY RECOMMENDED SPARE PART(S).
J42: CERTIFIED BY: | K42: JERRY R
J44: DATE: | K44: 44286
A59: - | B59: 6205ZZ | D59: 1 | E59: -
A60: TEFC | B60: 6206UU | D60: 1.15 | E60: A
A61: ODP | B61: 6207ZZ | E61: B
B62: 6208UU
B63: 6211ZZ
B64: 6211C3
B65: 6211ZZC3
B66: 6305UUC3
...

Sheet STCurve
A2: TOSHIBA INTERNATIONAL CORPORATION
A3: Speed Torque/Current Curve
A6: Model #: | B6: ='Performance Data Sheet'!C17 -> WT-10035612 | E6: FLAmps: | F6: ='Performance Data Sheet'!I14 -> 256
A7: Enclosure: | B7: ='Performance Data Sheet'!F14 -> WP-II | C7: Voltage: | D7: ='Performance Data Sheet'!F13 & " V" -> 4000 V | E7: Frame: | F7: ='Performance Data Sheet'!C14 -> 5811USS
A8: Pole: | B8: 2 | C8: Frequency: | D8: 3 PH / 60 Hz | E8: Ins. Class: | F8: ='Performance Data Sheet'!M15 -> F
A9: HP: | B9: ='Performance Data Sheet'!C13 -> 2000 | C9: Rotor Inertia: | D9: 222.9 lb-ft² | E9: Date: | F9: ='Performance Data Sheet'!K44 -> 44286
A10: FLRPM: | B10: ='Performance Data Sheet'!M14 -> 3565 | C10: Load Inertia: | D10: N/A | E10: File: | F10: H0102822
B12: Locked Rotor Amps: | C12: ='Performance Data Sheet'!D22 & " A" -> 1551 A | D12: Load Type: | E12: N/A
B13: Locked Rotor Torque: | C13: ='Performance Data Sheet'!H23/100 -> 1.75 | D13: Starting at: | E13: N/A
B14: Breakdown Torque: | C14: 2.15 | D14: Accel. Time: | E14: N/A
B15: Rated Torque: | C15: ='Performance Data Sheet'!H22 & " lb-ft" -> 2946 lb-ft
A39: Comments: | B39: PROJECT | C39: ='Performance Data Sheet'!C10 -> 2213503.1 | E39: D.E.Curve #: | F39: =F10 -> H0102822
C43: Prepared by: | D43: ='Performance Data Sheet'!K42 -> JERRY R | E43: Checked by:
D53: Load
A54: 100 | B54: 0 | C54: 0.22434406 | D54: 100
A55: 99.2 | B55: 78.014385 | C55: 106.41207 | D55: 98.400002
A56: 96 | B56: 215 | C56: 379.18821 | D56: 89.75
A57: 90.888889 | B57: 183.76142 | C57: 493.50242 | D57: 76.311111
A58: 85.777777 | B58: 152.31825 | C58: 530.93615 | D58: 63.022221
A59: 80.666666 | B59: 138.22012 | C59: 547.75137 | D59: 51.466663
A60: 70.444444 | B60: 130.68567 | C60: 563.8011 | D60: 33.755554
A61: 60.22222 | B61: 130.20571 | C61: 573.11589 | D61: 22.244442
A62: 50 | B62: 130 | C62: 580.42875 | D62: 14
A63: 39.999998 | B63: 131.49283 | C63: 586.83759 | D63: 7.9999995
A64: 30.000001 | B64: 135.09953 | C64: 592.36847 | D64: 5.9999995
A65: 19.999999 | B65: 142.05586 | C65: 597.38207 | D65: 8.000001
... A67: 0 | B67: 175 | C67: 605.80163 | D67: 30

Sheet Thermdam
A2: TOSHIBA INTERNATIONAL CORPORATION
A3: Thermal Limit & Acceleration Curves
A4: Design Values (For Reference Only)
A6: Model #: | B6: ='Performance Data Sheet'!C17 -> WT-10035612 | E6: FLAmps: | F6: ='Performance Data Sheet'!I14 -> 256
A7: Enclosure: | B7: ='Performance Data Sheet'!F14 -> WP-II | C7: Voltage: | D7: ='Performance Data Sheet'!F13 & " V" -> 4000 V | E7: Frame: | F7: ='Performance Data Sheet'!C14 -> 5811USS
A8: Pole: | B8: 2 | C8: Frequency: | D8: 3 PH / 60 Hz | E8: Ins. Class: | F8: ='Performance Data Sheet'!M15 -> F
A9: HP: | B9: ='Performance Data Sheet'!C13 -> 2000 | C9: Rotor Inertia: | D9: 222.9 lb-ft² | E9: Date: | F9: ='Performance Data Sheet'!K44 -> 44286
A10: FLRPM: | B10: ='Performance Data Sheet'!M14 -> 3565 | C10: Load Inertia: | D10: N/A | E10: File: | F10: H0102822
C12: ='Performance Data Sheet'!D22 & " A" -> 1551 A
C13: ='Performance Data Sheet'!H23/100 -> 1.75
C15: ='Performance Data Sheet'!H22 & " lb-ft" -> 2946 lb-ft
A39: Comments: | B39: PROJECT | C39: ='Performance Data Sheet'!C10 -> 2213503.1 | E39: D.E.Curve #: | F39: =F10 -> H0102822
C43: Prepared by: | D43: ='Performance Data Sheet'!K42 -> JERRY R | E43: Checked by:
F50: =5252.1*B50/D53 -> #DIV/0!
D66: =D65/D64 -> #DIV/0!
A67: Current (%) | B67: Cold | C67: Hot | E67: CURRENT (%) | F67: Accel. Time
A68: 605.80163 | B68: 4.5874756 | C68: 2 | E68: =A68 -> 605.80163 | F68: 0.0001
A69: 563.59101 | B69: =((A68/A69)^2)*B68 -> 5.300374 | C69: =((A68/A69)^2)*C68 -> 2.3108021 | E69: 603.83749 | F69: 0.368
A70: 521.36773 | B70: =((A68/A70)^2)*B68 -> 6.1936453 | C70: =((A68/A70)^2)*C68 -> 2.7002412 | E70: 599.63963 | F70: 0.75099999
A71: 479.15712 | B71: =((A68/A71)^2)*B68 -> 7.3329503 | C71: =((A68/A71)^2)*C68 -> 3.1969436 | E71: 594.86407 | F71: 1.1489999
A72: 380.56512 | B72: =((A68/A72)^2)*B68 -> 11.624564 | E72: 589.58786 | F72: 1.5639999
A73: 281.97312 | B73: =((A68/A73)^2)*B68 -> 21.174795 | E73: 583.61843 | F73: 2.0009999
A74: 211.9728 | B74: =((A68/A74)^2)*B68 -> 37.469195 | C74: =((A68/A74)^2)*C68 -> 16.335431 | E74: 576.7632 | F74: 2.4789999
A75: 177.4656 | B75: =((A68/A75)^2)*B69 -> 61.764513 | C75: =((A68/A75)^2)*C68 -> 23.305719 | E75: 568.4445 | F75: 3.0019999
A76: 118.3104 | B76: =((A68/A76)^2)*B68 -> 120.27872 | C76: =((A68/A76)^2)*C68 -> 52.437867 | E76: 555.77389 | F76: 3.5849998
A77: 110 | C77: =CEILING(C76*2,100) -> 200 | E77: 539.32905 | F77: 3.8889997
A78: 110 | C78: =2*C77 -> 400 | E78: 512.21625 | F78: 4.1609998
A79: 110 | C79: 10000 | E79: 436.34663 | F79: 4.3909998
E80: =A77 -> 110 | F80: 4.6399999

Sheet Performance
A2: TOSHIBA INTERNATIONAL CORPORATION
A3: Performance Curve
A4: Design Values (For Reference Only)
A6: Model #: | B6: ='Performance Data Sheet'!C17 -> WT-10035612 | E6: FLAmps: | F6: ='Performance Data Sheet'!I14 -> 256
A7: Enclosure: | B7: ='Performance Data Sheet'!F14 -> WP-II | C7: Voltage: | D7: ='Performance Data Sheet'!F13 & " V" -> 4000 V | E7: Frame: | F7: ='Performance Data Sheet'!C14 -> 5811USS
A8: Pole: | B8: 2 | C8: Frequency: | D8: 3 PH / 60 Hz | E8: Ins. Class: | F8: ='Performance Data Sheet'!M15 -> F
A9: HP: | B9: ='Performance Data Sheet'!C13 -> 2000 | C9: Rotor Inertia: | D9: 222.9 lb-ft² | E9: Date: | F9: ='Performance Data Sheet'!K44 -> 44286
A10: FLRPM: | B10: ='Performance Data Sheet'!M14 -> 3565 | C10: Load Inertia: | D10: N/A | E10: File: | F10: H0102822
B12: Locked Rotor Amps: | C12: ='Performance Data Sheet'!D22 & " A" -> 1551 A | D12: Load Type: | E12: N/A
B13: Locked Rotor Torque: | C13: ='Performance Data Sheet'!H23/100 -> 1.75 | D13: Starting at: | E13: N/A
B14: Breakdown Torque: | C14: 2.15 | D14: Accel. Time: | E14: N/A
B15: Rated Torque: | C15: ='Performance Data Sheet'!H22 & " lb-ft" -> 2946 lb-ft
N36: SPEED | O36: KW
N37: =L43 - (L43-L44) / 10 * 0 -> 3600 | O37: =L45 / 10 * 10 -> 4000
N38: =L43 - (L43-L44) / 10 * 1 -> 3595 | O38: =L45 / 10 * 9 -> 3600
A39: Comments: | B39: PROJECT | C39: ='Performance Data Sheet'!C10 -> 2213503.1 | E39: D.E.Curve #: | F39: =F10 -> H0102822 | N39: =L43 - (L43-L44) / 10 * 2 -> 3590 | O39: =L45 / 10 * 8 -> 3200
N40: =L43 - (L43-L44) / 10 * 3 -> 3585 | O40: =L45 / 10 * 7 -> 2800
N41: =L43 - (L43-L44) / 10 * 4 -> 3580 | O41: =L45 / 10 * 6 -> 2400
N42: =L43 - (L43-L44) / 10 * 5 -> 3575 | O42: =L45 / 10 * 5 -> 2000
C43: Prepared by: | D43: ='Performance Data Sheet'!K42 -> JERRY R | E43: Checked by: | K43: SYNC SPEED | L43: 3600 | N43: =L43 - (L43-L44) / 10 * 6 -> 3570 | O43: =L45 / 10 * 4 -> 1600
K44: NEW SPEED LOWER RANGE | L44: 3550 | N44: =L43 - (L43-L44) / 10 * 7 -> 3565 | O44: =L45 / 10 * 3 -> 1200
K45: NEW kW UPPER RANGE | L45: 4000 | N45: =L43 - (L43-L44) / 10 * 8 -> 3560 | O45: =L45 / 10 * 2 -> 800
N46: =L43 - (L43-L44) / 10 * 9 -> 3555 | O46: =L45 / 10 * 1 -> 400
N47: =L43 - (L43-L44) / 10 * 10 -> 3550 | O47: =L45 / 10 * 0 -> 0
A52: ADJUSTED
A53: Load | B53: Efficiency | C53: PF | D53: Amps | E53: RPM | F53: Input Watts
A54: 0 | D54: 69 | E54: 100 | F54: =22917/(L45*1000) * 100 -> 0.572925
A55: 25 | B55: 92.5 | C55: 65.599998 | D55: 88.790001 | E55: =(1.00739*B10-L44)/(L43-L44)*100 -> 82.6907 | F55: =403541.8/(L45*1000)*100 -> 10.088545
A56: 50 | B56: 94.800003 | C56: 82.300003 | D56: 137.92999 | E56: =(1.005018*B10-L44)/(L43-L44)*100 -> 65.77834 | F56: =786464.6/(L45*1000)*100 -> 19.661615
A57: 75 | B57: 95.300003 | C57: 86.900002 | D57: 194.92999 | E57: =(1.002592*B10-L44)/(L43-L44)*100 -> 48.48096 | F57: =1173597/(L45*1000)*100 -> 29.339925
A58: 100 | B58: 95.300003 | C58: 88.099998 | D58: 256.25 | E58: =(1*B10-L44)/(L43-L44)*100 -> 30 | F58: =1564085/(L45*1000)*100 -> 39.102125
A59: 125 | B59: 95.200005 | C59: 88 | D59: 321.60001 | E59: =(0.9974908*B10-L44)/(L43-L44)*100 -> 12.109404 | F59: =1960737/(L45*1000)*100 -> 49.018425
A62: ORIGINAL
A63: Load | B63: Efficiency | C63: PF | D63: Amps | E63: RPM | F63: Input Watts
A64: 0 | D64: 59.06889 | E64: 100 | F64: 22.971263
A65: 25 | B65: 92.44912 | C65: 65.512634 | D65: 88.78933 | E65: 84.139203 | F65: 10.074737
A66: 50 | B66: 94.780937 | C66: 82.271057 | D66: 137.92741 | E66: 66.973166 | F66: 19.653756
A67: 75 | B67: 95.283188 | C67: 86.859558 | D67: 194.9288 | E67: 49.376035 | F67: 29.325236
A68: 100 | B68: 95.293762 | C68: 88.089439 | D68: 256.24789 | E68: 30.605991 | F68: 39.095976
A69: 125 | B69: 95.107727 | C69: 87.906914 | D69: 321.60281 | E69: 12.394616 | F69: 48.965563
