Workbook
Name Print_Area_MI: 'Performance Data Sheet'!$A$10:$N$42

Sheet DesignSheet
A1: TOSHIBA INTERNATIONAL CORPORATION | I1: Calc. Code: | J1: 2-2-2-0-1-2
A2: 3-PHASE SQUIRREL CAGE INDUCTION MOTOR DESIGN SHEET | J2: B.L.-1 P.F.-1
A3: File: | B3: N:\DESPRO\RAT FILES\1T2M30U.rat | G3: Date: | H3: 44704 | I3: Time: | J3: 0.51128472
A4: Pole | B4: HP | C4: RPM | D4: Form | E4: Voltage | F4: Frequency | G4: Temperature | H4: FLSpeed | I4: FLSlip | J4: Frame
A5: 2 | B5: 1500 | C5: 3600 | D5: DCW4 | E5: 4000 | F5: 60 | G5: 105 | H5: 3569.1 / 3569.1 | I5: 0.0086 / 0.0086 | J5: 5811/12UDZ
A6: Core Data | D6: Winding Data | H6: Constant Data
B7: Primary | C7: Secondary | F7: Bar | G7: End Ring | H7: St. Slot Pitch | I7: 24.543672 | J7: LR Test Data
A8: Air Gap | B8: 3.3 | H8: Rt. Slot Pitch | I8: 30.456888 | J8: ES
A9: Space Fac. | B9: 0.93000001 | D9: Pitch | E9: 1 ~ 16 | F9: Cross Section Area | H9: Mean Value | I9: 27.50028 | J9: 682.37121
A10: Core Length | B10: 555 | C10: 555 | F10: UB: 406.6 | G10: UER: 3370.3 | H10: Eff.T.W.St. | I10: 14.338923 | J10: WS
A11: OD | B11: 670 | C11: 368.4 | D11: Coil Pitch | E11: 0.6249375 | G11: ERT: 85.0 | H11: Eff.T.W.Rt. | I11: 30.456888 | J11: 61004.959
A12: ID | B12: 375 | C12: 185 | D12: Slot Fill | E12: - | G12: ERD1: 281.0 | H12: St.Carter Fac. | I12: 1.1789163 | J12: IS
A13: Core Depth | B13: 85 | C13: 54.7 | D13: Con./Slot | E13: 20 | G13: ERD2: 367.0 | H13: Rt.Carter Fac. | I13: 1 | J13: 186.90283
A14: Eff.Core L. | B14: 441.75 | C14: 441.75 | D14: Wire Size 1 | E14: (.081"x.204")x2 | H14: Carter Factor | I14: 1.1789163 | J14: Volts / Turn
A15: Slot Data | D15: Wire Size 2 | E15: - | H15: Short. Factor | I15: 0.8314146 | J15: 28.868359
A16: Number | B16: 48 | C16: 38 | D16: // Circuits | E16: 2 | H16: Distrib. Factor | I16: 0.95543647 | J16: AC
A17: Kind | B17: Open | C17: Dbl - Closed | D17: Connection | E17: Wye | H17: Wind. Factor | I17: 0.79436384 | J17: 761.51129
A18: Skew | B18: - | C18: 0 | D18: MCL | E18: 1250 | F18: 640 | H18: Reactance | I18: (Coeff.: 0.0313)
A19: Depth | B19: 62.5 | C19: 37 | D19: No.Cond./Ph. | E19: 160 | I19: Running | J19: Start
A20: Width | B20: 10.20 - 10.20 | D20: Res. (20°C) | E20: 0.084141611 | H20: Stator Slot | I20: 18.533136 | J20: 18.533136
A21: Opening | B21: 14.5 | C21: 0 | D21: (105°C) | E21: 0.11224392 | F21: 0.087480582 | G21: 0.029676551 | H21: Rotor Slot | I21: 41.600204 | J21: 19.930725
A22: Tip Depth | B22: 2.8299999 | C22: 1.9 | D22: Material | E22: CU | F22: AL | G22: AL | H22: Zigzag | I22: 4.3345351 | J22: 3.9824762
A23: T.Min.Wid. | B23: 10.043672 | C23: 11 | D23: Spec.Resist. | E23: 1.742 | F23: 3.25 | G23: 3.25 | H23: Coil End | I23: 21.939808 | J23: Skew R.: 0.00
A24: Low. R. | B24: 0 | C24: 2 | D24: Spec.Gravity | E24: 8.8900003 | F24: 2.6700001 | G24: 2.6700001 | H24: Belt Leakage | I24: 7.2923365 | J24: 6.756261
A25: Up. R. | B25: - | C25: 2 | D25: Weight (kg) | H25: Total Resist. | I25: 0.22940105 | J25: 0.58211946
A26: Wedge Dep. | B26: 2.83 - 2.00 | C26: Magnetic | D26: Wire 1 | E26: 220.86167 | F26: 22.89343 | G26: 18.629805 | H26: Total React. | I26: 2.9370952 | J26: 2.2282481
A27: Duct | B27: 8 x 10 | C27: 8 x 10 | D27: Wire 2 | E27: - | F27: - | G27: - | H27: Impedance | I27: 2.9460402 | J27: 2.3030312
A28: Effective Depth (S=1) | D28: Magnetic Circuit Data | I28: Core Loss Data
B29: Res.= | C29: 35.085827 | E29: Length | F29: Section | G29: Density | H29: AT | I29: Volume | J29: Loss | M29: =RIGHT(F$41,SEARCH("/",F$41,1)-1) -> 3561.1 | N29: 125RPM | P29: Kline/in2
B30: Reac.= | C30: 35.095949 | D30: Primary Core | E30: 52.621633 | F30: 750.975 | G30: 18.165315 | H30: 1063.5919 | I30: 69008.225 | J30: 6439.2955 | M30: =RIGHT(E$41,SEARCH("/",E$41,1)-1) -> 3569.1 | N30: 100RPM | P30: =G30*6.4516 -> 117.19535
A31: Excitation Data | D31: Tooth | E31: 6.25 | F31: 1064.8301 | G31: 12.81115 | H31: 30.641059 | I31: 13310.376 | J31: 705.41875 | M31: =RIGHT(D$41,SEARCH("/",D$41,1)-1) -> 3577.1 | N31: 75RPM | P31: =G31*6.4516 -> 82.652415
A32: Excit.Amps | B32: 45.718 / 40.822 | D32: Second.Core | E32: 23.122102 | F32: 755.687 | G32: 18.052047 | H32: 455.69376 | I32: Total | J32: 7144.7142 | M32: =RIGHT(C$41,SEARCH("/",C$41,1)-1) -> 3584.9 | N32: 50RPM | P32: =G32*6.4516 -> 116.46459
A33: Core Loss | B33: 2.011 / 1.796 | C33: Flux / Pole | D33: Tooth | E33: 3.7 | F33: 923.2575 | G33: 14.775615 | H33: 31.450103 | I33: C.L.C. | J33: 1.75 / 0.66 | M33: =RIGHT(B$41,SEARCH("/",B$41,1)-1) -> 3592.4 | N33: 25RPM | P33: =G33*6.4516 -> 95.326359
A34: NoLoad | B34: 45.76 / 40.86 | C34: 13.641698 | D34: Air Gap | E34: 0.33 | F34: 2373.3479 | G34: 5.7478711 | H34: 1509.4247 | I34: S.F.C. | J34: 6.0500002 | P34: =G34*6.4516 -> 37.082965
A35: Load Characteristics | D35: Temp. Rise @ 100%: | E35: 65 / 63 | G35: No Load Loss | H35: 20477.6 / 12007.1 | I35: W.Loss | J35: 12503.2 / 4694.4
A36: Load (%) | B36: 25 | C36: 50 | D36: 75 | E36: 100 | F36: 125 | G36: Primary Loss | H36: 11762.9 / 10701.7 | I36: S.Loss | J36: 1446.7 / 543.2
A37: Current (A) | B37: 67.29 / 69.22 | C37: 102.23 / 105.16 | D37: 143.04 / 147.14 | E37: 186.90 / 192.26 | F37: 233.34 / 240.03 | G37: Second. Loss | H37: 10069.1 / 10006.6 | I37: Total C.Loss | J37: 13950.0 / 5237.6
A38: Efficiency | B38: 0.927 / 0.914 | C38: 0.956 / 0.943 | D38: 0.964 / 0.950 | E38: 0.965 / 0.951 | F38: 0.964 / 0.950 | G38: Frict.& Wind. | H38: 6000.0 / 5497.9 | I38: Stray Loss | J38: 25854.428 | L38: =LEFT(E38,SEARCH("/",E38,1)-1) -> 0.965 | M38: =RIGHT(E38,SEARCH("/",E38,1)-1) -> 0.951 | N38: =M38/L38 -> 0.98549223 | O38: Eff.
A39: P.F. | B39: 0.647 / 0.638 | C39: 0.826 / 0.815 | D39: 0.879 / 0.867 | E39: 0.895 / 0.883 | F39: 0.898 / 0.885 | G39: Starting Data | I39: Slip | J39: PF | L39: =LEFT(E39,SEARCH("/",E39,1)-1) -> 0.895 | M39: =RIGHT(E39,SEARCH("/",E39,1)-1) -> 0.883 | N39: =M39/L39 -> 0.98659218 | O39: PF.
A40: Slip | B40: 0.0021 / 0.0021 | C40: 0.0042 / 0.0042 | D40: 0.0064 / 0.0063 | E40: 0.0086 / 0.0086 | F40: 0.0108 / 0.0108 | G40: LRA | H40: 1002.8 / 1144.2 | L40: =LEFT(E37,SEARCH("/",E37,1)-1) -> 186.90 | M40: 192 | N40: =M40/L40 -> 1.0272873 | O40: Current
...

Sheet Data Sheet
A1: TOSHIBA INTERNATIONAL CORPORATION
A2: INDUCTION MOTOR DATA SHEET
A3: File: | B3: 1T2M30U | I3: HRW / Model Number:
A4: Type: TIKK - Form: DCW4 - 2 Pole - 1500 HP -2300 / 4000 V - 60 Hz - 5811/12UDZ - Class F | Q4: Motor Type Selection | T4: Electrical Steel Table
A5: Motor Parameters | F5: PERFORMANCE | J5: DESIGN | K5: TEST | Q5: EPACT | T5: M22 - 26Ga.
A6: Material | F6: NL & Impedance Test | Q6: EQP-III | T6: M36 - 26Ga.
A7: Air Gap | D7: 3.3 | F7: No load amps | J7: 41 | K7: - | Q7: Exp.Prf. | T7: NCB1 - 26Ga.
A8: Stack length | D8: 555 | F8: No load watts | J8: 12007 | K8: - | Q8: Exp.Prf.-EQPIII | T8: M43 - 26Ga.
A9: Number of turns per coil | D9: 10 | F9: Impedance amps | H9: 3 | I9: f | J9: 315 | K9: - | Q9: Prem. Eff. | T9: M45 - 26Ga.
A10: Wire 1 (size & number) | D10: (.081"x.204")x2 | F10: Impedance volts | H10: 3 | I10: f | J10: 1150 | K10: - | Q10: Standard Eff. | T10: M54 - 26Ga.
A11: Wire 2 (size & number) | D11: - | F11: Impedance watts | H11: 3 | I11: f | J11: 61005 | K11: - | Q11: OWP | T11: TIPA Lam
A12: Slot fill - circle/square method (%) | D12: - | F12: Temperature Rise (°C) | Q12: Dry Kiln
A13: Connection | D13: 2 x Delta / 2 x Wye | G13: Winding | I13: 80/115 | J13: 65 / 86 | K13: -
A14: MCL | D14: 1250 | G14: Frame | J14: - | K14: -
A15: Allowance for ins. depth | D15: 14.522 | G15: Bearing PS/OS | J15: - | K15: -
A16: Allowance for ins. width | D16: 3.7368 | G16: End Ring | J16: - | K16: -
A17: Slot/Wire arrangement | D17: 20 x 2 | F17: Nameplate Data
A18: Effective cross section for coil | D18: - | H18: FLC (A) | J18: 333 / 192
A19: Coil grouping | D19: - | H19: RPM | J19: 3565
A20: Coil pitch (slot number) | D20: 1 ~ 16 | H20: CODE | J20: F
A21: Method of coil connection | D21: - | H21: S. F. | J21: 1.15 | Q21: Method of Connection
A22: Resistance per phase @ 20 °C | D22: 0.084100001 | H22: DESIGN | J22: - | Q22: Skip
A23: Coil Weight | B23: Wire1 | D23: 485.9 | H23: Nom.Eff. (%): | J23: - | Q23: Adjacent
A24: (lbs.) | B24: Wire2 | D24: - | H24: Min.Eff. (%): | J24: - | Q24: -
A25: Current Densities (A/cm2) | E25: Bar / ER | H25: P.F. (%): | J25: -
A26: FL / LR | D26: 464 / 2765 | E26: 430 / 314
A27: Stator Slot Shape (Reference) | F27: Performance
H28: LRC (A) | I28: - | J28: 1981 / 1144 | K28: -
H29: LRT (%) | I29: 60 | J29: 138 | K29: -
H30: BDT (%) | I30: 175 | J30: 266 | K30: -
H31: SLIP (%) | J31: 0.86 | K31: -
G32: IEEE-B | H32: Eff. (%) | J32: 95.1 | K32: -
A33: Rotor Slot Shape (Reference) | H33: PF (%) | J33: 88.3 | K33: -
F34: Losses (Watts) | H34: Primary | J34: 10702 | K34: -
H35: Secondary | J35: 10007 | K35: -
H36: Core | J36: 5238 | K36: -
H37: F & W | J37: 5498 | K37: -
H38: Stray | J38: 25854 | K38: -
A39: End Ring (Reference) | F39: Note | G39: 1T2M30U
F40: LINK: | G40: H010234.rat & lab 9510.dat -> Run 1T2M30U.rat
...

Sheet LoginSheet
J1: P | K1: T | L1: L | M1: T
B2: PROJECT HISTORY | J2: E | K2: D | L2: I | M2: Y | N2: H
J3: R | L3: M | M3: P
J4: F | L4: I | M4: E
K5: C | L5: T | N5: I
J6: D | K6: U | M6: T | N6: N
J7: A | K7: R | L7: R | M7: E | N7: S
I8: S | J8: T | K8: V | L8: E | M8: S | N8: U
B9: DATE | C9: PROJECT | D9: SMART NUMBER | E9: QTY | F9: CUSTOMER | G9: REMARKS | H9: LIMIT CODE | I9: F | J9: A | K9: E | L9: V | M9: T | N9: L
B53: REVISION HISTORY
B54: REV | C54: REMARKS | I54: DATE | L54: INIT

Sheet StallTime
A1: Rating: | B1: 2 Pole - 1500.0 HP - 3600 RPM - 4000 V - 60 Hz
A3: Starting Performance
D4: Load Type: Fan / Pump - 300.6 lb-ft²
A5: RPM | B5: Motor | C5: Load | D5: Accel. | E5: Line | F5: Stator | G5: Rotor
A6: Speed Increment | B6: Torque (%) | C6: Torque (%) | D6: Time (s) | E6: Amps | F6: kW / s | G6: kW / s
A7: 0~360 | B7: 125.8 | C7: 22.5 | D7: 0.261 | E7: 1140.3 | F7: 114.9 | G7: 474.1
A8: 360~720 | B8: 111.2 | C8: 11.5 | D8: 0.270 | E8: 1132.4 | F8: 117.5 | G8: 381.9
A9: 720~1080 | B9: 102.8 | C9: 7.0 | D9: 0.281 | E9: 1123.5 | F9: 120.5 | G9: 320.6
A10: 1080~1440 | B10: 98.1 | C10: 7.0 | D10: 0.296 | E10: 1113.7 | F10: 124.6 | G10: 277.9
A11: 1440~1800 | B11: 95.8 | C11: 11.0 | D11: 0.318 | E11: 1102.6 | F11: 131.4 | G11: 247.8
A12: 1800~2160 | B12: 95.1 | C12: 18.0 | D12: 0.349 | E12: 1089.8 | F12: 141.4 | G12: 223.9
A13: 2160~2530 | B13: 97.4 | C13: 27.7 | D13: 0.397 | E13: 1074.3 | F13: 157.0 | G13: 197.8
A14: 2530~2901 | B14: 107.6 | C14: 42.4 | D14: 0.425 | E14: 1050.8 | F14: 162.5 | G14: 165.1
A15: 2901~3086 | B15: 127.6 | C15: 57.1 | D15: 0.196 | E15: 1020.3 | F15: 71.0 | G15: 115.4
A16: 3086~3271 | B16: 165.4 | C16: 69.5 | D16: 0.144 | E16: 970.2 | F16: 49.1 | G16: 75.5
... A18: 3456~3569 | B18: 182.5 | C18: 94.1 | D18: 0.096 | E18: 463.7 | F18: 1.2 | G18: 9.3
D21: Acceleration Time: 3.1 s
B22: Energy | D22: First Start | F22: Second Start
A23: Stator Winding Rise | B23: 1219 kW / s | D23: 14°C | F23: 29°C
A24: Rotor Bar Rise | B24: 1891 kW / s | D24: 92°C | F24: 185°C
A25: End Ring Rise | B25: 642 kW / s | D25: 38°C | F25: 77°C
A27: Locked Rotor Thermal Capability
E28: Cold Condition
B29: Rate of Rise | D29: Power | E29: Rise Limit | F29: Max Time
A30: Stator Copper | B30: 6.0°C / s | D30: 513.7 kW | E30: 160°C | F30: 26.5 s
A31: Rotor Bar | B31: 55.0°C / s | D31: 1128.0 kW | E31: 260°C | F31: 4.7 s
A32: Rotor ER | B32: 22.9°C / s | D32: 382.7 kW | E32: 180°C | F32: 7.8 s
E34: Hot Condition
B35: Hot Temp. | D35: Rise Limit | E35: Ambient | F35: Total | G35: Max.Time
A36: Stator Copper | B36: 68°C + | D36: 92°C + | E36: 40°C | F36: = 200°C | G36: 15.2 s
A37: Rotor Bar | B37: 91°C + | D37: 169°C + | E37: 40°C | F37: = 300°C | G37: 3.1 s
A38: Rotor ER | B38: 91°C + | D38: 89°C + | E38: 40°C | F38: = 220°C | G38: 3.9 s
A40: Cold Stall Time: | B40: 5.0 s | D40: Hot Stall Time: | F40: 2.5 s

Sheet Performance Data Sheet
A1: TOSHIBA INTERNATIONAL CORPORATION | J1: INDEX | L1: MPCF-1033
A2: Industrial Division / Houston Motor Plant | J2: SHEET NO. | L2: 1 of 1
J3: ISSUED | L3: 7/31/13
J4: SUPERSEDES | L4: 11/8/96
J5: REVISION | L5: 2
A6: SQUIRREL CAGE INDUCTION MOTOR | J6: WRITTEN BY | L6: MDC
A7: PERFORMANCE SPECIFICATIONS | J7: APPROVED BY | L7: PAA
B9: CUSTOMER: | C9: BARR THORP ELECTRICAL
B10: TIC SR No.: | C10: 2257472.1
A12: MOTOR NAMEPLATE DATA
B13: H.P.: | C13: 1500 | E13: VOLTS: | F13: 2300/4000 | H13: 3 PH / | I13: 60 Hz | L13: S. RPM: | M13: 3600
B14: FRAME: | C14: 5812UZ | E14: ENCL: | F14: WP-II | H14: FLAMPS: | I14: 333/192 | L14: FLRPM: | M14: 3570
B15: FORM: | C15: DCW4 | E15: S.F.: | F15: 1.15 | H15: NEMA DESIGN: | I15: - | L15: INSUL CLASS: | M15: F
B16: TYPE: | C16: TIKK | E16: AMB.: | F16: 40°C | H16: CODE: | I16: F | L16: DUTY: | M16: Cont.
B17: MODEL No.: | C17: WT-10126293 | H17: kW: | I17: -
B18: NOM. EFF.: | C18: - | E18: MIN. EFF.: | F18: - | H18: P.F.: | I18: -
A21: AMPERAGE | E21: TORQUES | I21: **BEARINGS:
C22: LOCKED ROTOR: | D22: 1981/1144 | G22: FULL LOAD (lb-ft.): | H22: 2207 | K22: DRIVE END: | L22: REFER TO NP
G23: LOCKED ROTOR (%): | H23: 135 | K23: OPPOSITE DRIVE END: | L23: REFER TO NP
G24: BREAK DOWN (%): | H24: 265
A28: EFFICIENCY | H28: POWER FACTOR
C29: FULL LOAD: | D29: 95.1 | J29: FULL LOAD: | K29: 88.3
C30: 3/4 LOAD: | D30: 95 | J30: 3/4 LOAD: | K30: 86.7
C31: 1/2 LOAD: | D31: 94.2 | J31: 1/2 LOAD: | K31: 81.5
A35: ALL CHARACTERISTICS ARE AVERAGE EXPECTED VALUES BASED UPON RATED VOLTAGE,
A36: FREQUENCY AND SINEWAVE POWER INPUT.
A37: THE DECLARED LOCKED ROTOR CURRENT HAS A TOLERANCE OF 20%.
A38: * TEMPERATURE RISE WILL BE CONSISTENT WITH INSULATION, AMBIENT AND SERVICE FACTOR AS
A39: DEFINED BY NEMA-MG-12 OR -20.
A40: ** BEARINGS ARE THE ONLY RECOMMENDED SPARE PART(S).
J42: CERTIFIED BY: | K42: JERRY R
J44: DATE: | K44: 44704
A59: - | B59: 6205ZZ | D59: 1 | E59: -
A60: TEFC | B60: 6206UU | D60: 1.15 | E60: A
A61: ODP | B61: 6207ZZ | E61: B
B62: 6208UU
B63: 6211ZZ
B64: 6211C3
B65: 6211ZZC3
B66: 6305UUC3
...

Sheet STCurve
A2: TOSHIBA INTERNATIONAL CORPORATION
A3: Speed Torque/Current Curve
A6: Model #: | B6: ='Performance Data Sheet'!C17 -> WT-10126293 | E6: FLAmps: | F6: ='Performance Data Sheet'!I14 & " A" -> 333/192 A
A7: Enclosure: | B7: ='Performance Data Sheet'!F14 -> WP-II | C7: Voltage: | D7: ='Performance Data Sheet'!F13 & " V" -> 2300/4000 V | E7: Frame: | F7: ='Performance Data Sheet'!C14 -> 5812UZ
A8: Pole: | B8: 2 | C8: Frequency: | D8: 3 PH / 60 Hz | E8: Ins. Class: | F8: F
A9: HP: | B9: 1500 | C9: Rotor Inertia: | D9: 207.6 lb-ft² | E9: Date: | F9: ='Performance Data Sheet'!K44 -> 44704
A10: FLRPM: | B10: 3565 | C10: Load Inertia: | D10: 300.6 lb-ft² | E10: File: | F10: 1T2M30U
B12: Locked Rotor Amps: | C12: ='Performance Data Sheet'!D22 & " A" -> 1981/1144 A | D12: Load Type: | E12: N/A
B13: Locked Rotor Torque: | C13: 1.35 | D13: Starting at: | E13: N/A
B14: Breakdown Torque: | C14: 2.65 | D14: Accel. Time: | E14: N/A
B15: Rated Torque: | C15: 2210 lb-ft
A39: Comments: | B39: PROJECT | C39: ='Performance Data Sheet'!C10 -> 2257472.1 | E39: D.E.Curve #: | F39: =F10 -> 1T2M30U
C43: Prepared by: | D43: ='Performance Data Sheet'!K42 -> JERRY R | E43: Checked by:
D53: Load
A54: 100 | B54: 0 | C54: 0.23834619 | D54: 100
A55: 99.2 | B55: 98.233673 | C55: 106.45194 | D55: 98.400002
A56: 96 | B56: 265 | C56: 376.59369 | D56: 89.75
A57: 90.857143 | B57: 191.10022 | C57: 487.29529 | D57: 76.228569
A58: 85.714285 | B58: 139.75764 | C58: 523.31464 | D58: 62.85714
A59: 80.571428 | B59: 115.39021 | C59: 539.5119 | D59: 51.257141
A60: 70.285714 | B60: 99.825147 | C60: 555.02039 | D60: 33.485714
A61: 59.999999 | B61: 95 | C61: 564.04816 | D61: 22
A62: 50 | B62: 95.155073 | C62: 571.14337 | D62: 14
A63: 39.999998 | B63: 96.521074 | C63: 577.36597 | D63: 7.9999995
A64: 30.000001 | B64: 99.699771 | C64: 582.73663 | D64: 5.9999995
A65: 19.999999 | B65: 105.80343 | C65: 587.61163 | D65: 8.000001
... A67: 0 | B67: 135 | C67: 595.83337 | D67: 30

Sheet Thermdam
A2: TOSHIBA INTERNATIONAL CORPORATION
A3: Thermal Limit Curve
A4: Design Values (For Reference Only)
A6: Model #: | B6: ='Performance Data Sheet'!C17 -> WT-10126293 | E6: FLAmps: | F6: ='Performance Data Sheet'!I14 & " A" -> 333/192 A
A7: Enclosure: | B7: ='Performance Data Sheet'!F14 -> WP-II | C7: Voltage: | D7: ='Performance Data Sheet'!F13 & " V" -> 2300/4000 V | E7: Frame: | F7: ='Performance Data Sheet'!C14 -> 5812UZ
A8: Pole: | B8: 2 | C8: Frequency: | D8: 3 PH / 60 Hz | E8: Ins. Class: | F8: F
A9: HP: | B9: 1500 | C9: Rotor Inertia: | D9: 207.6 lb-ft² | E9: Date: | F9: ='Performance Data Sheet'!K44 -> 44704
A10: FLRPM: | B10: 3565 | C10: Load Inertia: | D10: 300.6 lb-ft² | E10: File: | F10: 1T2M30U
A39: Comments: | B39: PROJECT | C39: ='Performance Data Sheet'!C10 -> 2257472.1 | E39: D.E.Curve #: | F39: =F10 -> 1T2M30U
C43: Prepared by: | D43: ='Performance Data Sheet'!K42 -> JERRY R | E43: Checked by:
F50: =5252.1*B50/D53 -> #DIV/0!
D66: =D65/D64 -> #DIV/0!
A67: Current (%) | B67: Cold | C67: Hot | E67: CURRENT (%) | F67: Accel. Time
A68: 595.83333 | B68: 7.0958887 | C68: 3.5221767 | E68: =A68 -> 595.83333 | F68: 0.0001
A69: 523.22948 | B69: =((A68/A69)^2)*B68 -> 9.2017826 | C69: =((A68/A69)^2)*C68 -> 4.5674765 | E69: 593.90625 | F69: 0.26100001
A70: 450.60385 | B70: =((A68/A70)^2)*B68 -> 12.406994 | C70: =((A68/A70)^2)*C68 -> 6.1584432 | E70: 589.79167 | F70: 0.53100002
A71: 378 | B71: =((A68/A71)^2)*B68 -> 17.630831 | C71: =((A68/A71)^2)*C68 -> 8.751392 | E71: 585.15625 | F71: 0.81200004
A72: =A71-100 -> 278 | B72: =((A68/A72)^2)*B68 -> 32.596186 | E72: 580.05208 | F72: 1.108
A73: =A72-100 -> 178 | B73: =((A68/A73)^2)*B68 -> 79.509016 | E73: 574.27083 | F73: 1.426
A74: 265 | B74: =((A68/A74)^2)*B68 -> 35.872747 | C74: =((A68/A74)^2)*C68 -> 17.806107 | E74: 567.60417 | F74: 1.775
A75: 180 | B75: =((A68/A75)^2)*B69 -> 100.82693 | C75: =((A68/A75)^2)*C68 -> 38.593639 | E75: 559.53125 | F75: 2.1719999
A76: 145 | B76: =((A68/A76)^2)*B68 -> 119.81754 | C76: =((A68/A76)^2)*C68 -> 59.473669 | E76: 547.29167 | F76: 2.5969999
A77: 125 | C77: =CEILING(C76*2,100) -> 200 | E77: 531.40625 | F77: 2.793
A78: 125 | C78: =2*C77 -> 400 | E78: 505.3125 | F78: 2.937
A79: 125 | C79: 10000 | E79: 431.92708 | F79: 3.0320001
E80: 0 | F80: 3.128

Sheet Performance 4000V
A2: TOSHIBA INTERNATIONAL CORPORATION
A3: Performance Curve
A4: Design Values (For Reference Only)
A6: Model #: | B6: ='Performance Data Sheet'!C17 -> WT-10126293 | E6: FLAmps: | F6: 192 A
A7: Enclosure: | B7: ='Performance Data Sheet'!F14 -> WP-II | C7: Voltage: | D7: 4000V | E7: Frame: | F7: ='Performance Data Sheet'!C14 -> 5812UZ
A8: Pole: | B8: 2 | C8: Frequency: | D8: 3 PH / 60 Hz | E8: Ins. Class: | F8: F
A9: HP: | B9: 1500 | C9: Rotor Inertia: | D9: 207.6 lb-ft² | E9: Date: | F9: ='Performance Data Sheet'!K44 -> 44704
A10: FLRPM: | B10: 3565 | C10: Load Inertia: | D10: 300.6 lb-ft² | E10: File: | F10: 1T2M30U
B12: Locked Rotor Amps: | C12: 1144 A | D12: Load Type: | E12: N/A
B13: Locked Rotor Torque: | C13: 1.35 | D13: Starting at: | E13: N/A
B14: Breakdown Torque: | C14: 2.65 | D14: Accel. Time: | E14: N/A
B15: Rated Torque: | C15: 2210 lb-ft
A39: Comments: | B39: PROJECT | C39: ='Performance Data Sheet'!C10 -> 2257472.1 | E39: D.E.Curve #: | F39: =F10 -> 1T2M30U
C43: Prepared by: | D43: ='Performance Data Sheet'!K42 -> JERRY R | E43: Checked by:
A53: Load | B53: Efficiency | C53: PF | D53: Amps | E53: RPM | F53: Input Watts
A54: 0 | D54: 47.011784 | E54: 100 | F54: 2
A55: 25 | B55: 91.374359 | C55: 63.851986 | D55: 69.12397 | E55: 83.550865 | F55: 7.644533
A56: 50 | B56: 94.24321 | C56: 81.494247 | D56: 105.02203 | E56: 64.740837 | F56: 14.823654
A57: 75 | B57: 94.959595 | C57: 86.709793 | D57: 146.94055 | E57: 45.409295 | F57: 22.067731
A58: 100 | B58: 95.097885 | C58: 88.34935 | D58: 192.00528 | E58: 25.40054 | F58: 29.380855
A59: 125 | B59: 94.99736 | C59: 88.551178 | D59: 239.71297 | E59: 5.4099067 | F59: 36.764932

Sheet Performance 2300V
A2: TOSHIBA INTERNATIONAL CORPORATION
A3: Performance Curve
A4: Design Values (For Reference Only)
A6: Model #: | B6: ='Performance Data Sheet'!C17 -> WT-10126293 | E6: FLAmps: | F6: 333 A
A7: Enclosure: | B7: ='Performance Data Sheet'!F14 -> WP-II | C7: Voltage: | D7: 2300 V | E7: Frame: | F7: ='Performance Data Sheet'!C14 -> 5812UZ
A8: Pole: | B8: 2 | C8: Frequency: | D8: 3 PH / 60 Hz | E8: Ins. Class: | F8: F
A9: HP: | B9: 1500 | C9: Rotor Inertia: | D9: 207.6 lb-ft² | E9: Date: | F9: ='Performance Data Sheet'!K44 -> 44704
A10: FLRPM: | B10: 3565 | C10: Load Inertia: | D10: 300.6 lb-ft² | E10: File: | F10: 1T2M30U
B12: Locked Rotor Amps: | C12: 1981 A | D12: Load Type: | E12: N/A
B13: Locked Rotor Torque: | C13: 1.35 | D13: Starting at: | E13: N/A
B14: Breakdown Torque: | C14: 2.65 | D14: Accel. Time: | E14: N/A
B15: Rated Torque: | C15: 2210 lb-ft
A39: Comments: | B39: PROJECT | C39: ='Performance Data Sheet'!C10 -> 2257472.1 | E39: D.E.Curve #: | F39: =F10 -> 1T2M30U
C43: Prepared by: | D43: ='Performance Data Sheet'!K42 -> JERRY R | E43: Checked by:
A53: Load | B53: Efficiency | C53: PF | D53: Amps | E53: RPM | F53: Input Watts
A54: 0 | D54: 81.426798 | E54: 100 | F54: 2
A55: 25 | B55: 91.374359 | C55: 63.851986 | D55: 119.72623 | E55: 83.550865 | F55: 7.644533
A56: 50 | B56: 94.24321 | C56: 81.494247 | D56: 181.9035 | E56: 64.740837 | F56: 14.823654
A57: 75 | B57: 94.959595 | C57: 86.709793 | D57: 254.5085 | E57: 45.409295 | F57: 22.067731
A58: 100 | B58: 95.097885 | C58: 88.34935 | D58: 332.5629 | E58: 25.40054 | F58: 29.380855
A59: 125 | B59: 94.99736 | C59: 88.551178 | D59: 415.19504 | E59: 5.4099067 | F59: 36.764932
